[META]
version=2.0
spawnOnBlockType=2
spawnSunlight=True
spawnDarkness=True
spawnWater=False
spawnLava=False
underFill=False
randomRotation=True
dig=True
tree=False
branch=False
needsFoundation=True
rarity=100
collisionPercentage=20
spawnElevationMin=0
spawnElevationMax=200
spawnInBiome=Custom
[DATA]
-7,-3,-6:17.14
-4,-2,-6:17.14
-3,-2,-6:17.14
1,1,-6:17.14
1,2,-6:17.14
-1,6,-6:17.14
-6,7,-6:17.14
-3,-4,-5:17.14
-8,-3,-5:17.14
-6,-3,-5:17.14
-4,-3,-5:17.14
-3,-3,-5:17.14
-8,-2,-5:17.14
-7,-2,-5:17.14
-6,-2,-5:17.14
-4,-2,-5:17.14
-3,-2,-5:17.14
-2,-2,-5:17.14
-8,-1,-5:17.14
-7,-1,-5:17.14
-6,-1,-5:17.14
-3,-1,-5:17.14
-2,-1,-5:17.14
0,0,-5:17.14
1,0,-5:17.14
0,1,-5:17.14
1,1,-5:17.14
2,1,-5:17.14
1,2,-5:17.14
-6,5,-5:17.14
-1,5,-5:17.14
-5,6,-5:17.14
-1,6,-5:17.14
-7,7,-5:17.14
-6,7,-5:17.14
-5,7,-5:17.14
-4,-4,-4:17.14
-3,-4,-4:17.14
-2,-4,-4:17.14
-4,-3,-4:17.14
-3,-3,-4:17.14
-2,-3,-4:17.14
-7,-2,-4:17.14
-3,-2,-4:17.14
-2,-2,-4:17.14
-7,-1,-4:17.14
-3,-1,-4:17.14
-2,-1,-4:17.14
-7,0,-4:17.14
1,0,-4:17.14
2,0,-4:17.14
-7,1,-4:17.14
0,1,-4:17.14
1,1,-4:17.14
2,1,-4:17.14
1,2,-4:17.14
2,2,-4:17.14
0,3,-4:17.14
1,3,-4:17.14
-7,5,-4:17.14
-6,5,-4:17.14
-5,5,-4:17.14
-2,5,-4:17.14
-6,6,-4:17.14
-5,6,-4:17.14
-4,6,-4:17.14
-3,6,-4:17.14
-2,6,-4:17.14
-1,6,-4:17.14
0,6,-4:17.14
-6,7,-4:17.14
-5,7,-4:17.14
-2,7,-4:17.14
-1,7,-4:17.14
-3,-4,-3:17.14
-3,-3,-3:17.14
-4,-2,-3:17.14
-3,-2,-3:17.14
-8,-1,-3:17.14
-7,-1,-3:17.14
-6,-1,-3:17.14
-3,-1,-3:17.14
-7,0,-3:17.14
-6,0,-3:17.14
1,1,-3:17.14
2,1,-3:17.14
-1,2,-3:17.14
0,2,-3:17.14
1,2,-3:17.14
1,3,-3:17.14
-6,4,-3:17.14
-7,5,-3:17.14
-6,5,-3:17.14
-4,5,-3:17.14
-3,5,-3:17.14
-2,5,-3:17.14
-1,5,-3:17.14
-7,6,-3:17.14
-6,6,-3:17.14
-5,6,-3:17.14
-4,6,-3:17.14
-3,6,-3:17.14
-2,6,-3:17.14
-1,6,-3:17.14
-6,7,-3:17.14
-4,7,-3:17.14
-3,7,-3:17.14
-2,7,-3:17.14
-1,7,-3:17.14
-3,-4,-2:17.14
-4,-3,-2:17.14
-3,-3,-2:17.14
-2,-3,-2:17.14
-7,-2,-2:17.14
-4,-2,-2:17.14
-3,-2,-2:17.14
-2,-2,-2:17.14
-7,-1,-2:17.14
-6,-1,-2:17.14
-7,0,-2:17.14
-6,0,-2:17.14
-7,1,-2:17.14
0,2,-2:17.14
1,2,-2:17.14
-1,3,-2:17.14
0,3,-2:17.14
1,3,-2:17.14
-7,4,-2:17.14
-6,4,-2:17.14
-5,4,-2:17.14
-7,5,-2:17.14
-6,5,-2:17.14
-5,5,-2:17.14
-4,5,-2:17.14
-3,5,-2:17.14
-2,5,-2:17.14
-6,6,-2:17.14
-4,6,-2:17.14
-3,6,-2:17.14
-2,6,-2:17.14
-3,7,-2:17.14
-2,7,-2:17.14
-4,-4,-1:17.14
-3,-4,-1:17.14
-5,-3,-1:17.14
-4,-3,-1:17.14
-3,-3,-1:17.14
-2,-3,-1:17.14
-5,-2,-1:17.14
-4,-2,-1:17.14
-3,-2,-1:17.14
-7,-1,-1:17.14
-6,-1,-1:17.14
-5,-1,-1:17.14
-8,0,-1:17.14
-6,0,-1:17.14
-5,0,-1:17.14
-7,1,-1:17.14
-6,1,-1:17.14
-2,1,-1:17.14
-1,1,-1:17.14
0,1,-1:17.14
1,1,-1:17.14
-1,2,-1:17.14
0,2,-1:17.14
1,2,-1:17.14
2,2,-1:17.14
-7,3,-1:17.14
-6,3,-1:17.14
-5,3,-1:17.14
0,3,-1:17.14
1,3,-1:17.14
-6,4,-1:17.14
-5,4,-1:17.14
-1,4,-1:17.14
0,4,-1:17.14
-7,5,-1:17.14
-6,5,-1:17.14
-5,5,-1:17.14
-3,5,-1:17.14
-1,5,-1:17.14
-5,6,-1:17.14
-4,6,-1:17.14
-3,6,-1:17.14
-2,6,-1:17.14
-1,6,-1:17.14
-3,7,-1:17.14
-2,7,-1:17.14
-6,-4,0:17.14
-5,-4,0:17.14
-4,-4,0:17.14
-3,-4,0:17.14
-7,-3,0:17.14
-6,-3,0:17.14
-5,-3,0:17.14
-4,-3,0:17.14
-3,-3,0:17.14
-2,-3,0:17.14
-1,-3,0:17.14
-7,-2,0:17.14
-6,-2,0:17.14
-5,-2,0:17.14
-4,-2,0:17.14
-3,-2,0:17.14
-2,-2,0:17.14
-1,-2,0:17.14
0,-2,0:17.14
-8,-1,0:17.14
-7,-1,0:17.14
-6,-1,0:17.14
-5,-1,0:17.14
-4,-1,0:17.14
-3,-1,0:17.14
-2,-1,0:17.14
-1,-1,0:17.14
0,-1,0:17.14
-8,0,0:17.14
-7,0,0:17.14
-6,0,0:17.14
-5,0,0:17.14
-4,0,0:17.14
-3,0,0:17.14
-2,0,0:17.14
-1,0,0:17.14
0,0,0:17.14
1,0,0:17.14
-9,1,0:17.14
-8,1,0:17.14
-7,1,0:17.14
-6,1,0:17.14
-5,1,0:17.14
-4,1,0:17.14
-3,1,0:17.14
-2,1,0:17.14
-1,1,0:17.14
0,1,0:17.14
1,1,0:17.14
2,1,0:17.14
-9,2,0:17.14
-8,2,0:17.14
-7,2,0:17.14
-6,2,0:17.14
-5,2,0:17.14
-4,2,0:17.14
-3,2,0:17.14
-2,2,0:17.14
-1,2,0:17.14
0,2,0:17.14
1,2,0:17.14
2,2,0:17.14
-9,3,0:17.14
-8,3,0:17.14
-7,3,0:17.14
-6,3,0:17.14
-5,3,0:17.14
-4,3,0:17.14
-3,3,0:17.14
-2,3,0:17.14
-1,3,0:17.14
0,3,0:17.14
1,3,0:17.14
2,3,0:17.14
-8,4,0:17.14
-7,4,0:17.14
-6,4,0:17.14
-5,4,0:17.14
-4,4,0:17.14
-3,4,0:17.14
-2,4,0:17.14
-1,4,0:17.14
0,4,0:17.14
1,4,0:17.14
-8,5,0:17.14
-7,5,0:17.14
-6,5,0:17.14
-5,5,0:17.14
-4,5,0:17.14
-3,5,0:17.14
-2,5,0:17.14
-1,5,0:17.14
0,5,0:17.14
1,5,0:17.14
-7,6,0:17.14
-6,6,0:17.14
-5,6,0:17.14
-4,6,0:17.14
-3,6,0:17.14
-2,6,0:17.14
-1,6,0:17.14
0,6,0:17.14
-7,7,0:17.14
-6,7,0:17.14
-5,7,0:17.14
-4,7,0:17.14
-3,7,0:17.14
-2,7,0:17.14
-1,7,0:17.14
-6,-4,1:17.14
-5,-4,1:17.14
-4,-4,1:17.14
-3,-4,1:17.14
-6,-3,1:17.14
-4,-3,1:17.14
-3,-3,1:17.14
-2,-3,1:17.14
-1,-3,1:17.14
0,-3,1:17.14
-7,-2,1:17.14
-4,-2,1:17.14
0,-2,1:17.14
-8,-1,1:17.14
-7,-1,1:17.14
0,-1,1:17.14
1,-1,1:17.14
-8,0,1:17.14
-7,0,1:17.14
1,0,1:17.14
-9,1,1:17.14
-8,1,1:17.14
-7,1,1:17.14
-1,1,1:17.14
0,1,1:17.14
1,1,1:17.14
2,1,1:17.14
-8,2,1:17.14
0,2,1:17.14
2,2,1:17.14
-8,3,1:17.14
-7,3,1:17.14
-5,3,1:17.14
1,3,1:17.14
-7,4,1:17.14
-6,4,1:17.14
-1,4,1:17.14
0,4,1:17.14
1,4,1:17.14
-7,5,1:17.14
-6,5,1:17.14
-5,5,1:17.14
0,5,1:17.14
-6,6,1:17.14
-5,6,1:17.14
-4,6,1:17.14
-3,6,1:17.14
-2,6,1:17.14
-1,6,1:17.14
0,6,1:17.14
-6,7,1:17.14
-5,7,1:17.14
-4,7,1:17.14
-3,7,1:17.14
-2,7,1:17.14
-1,7,1:17.14
-5,-4,2:17.14
-4,-4,2:17.14
-3,-4,2:17.14
-6,-3,2:17.14
-3,-3,2:17.14
-2,-3,2:17.14
-1,-3,2:17.14
0,-3,2:17.14
-7,-2,2:17.14
-6,-2,2:17.14
0,-2,2:17.14
-7,-1,2:17.14
0,-1,2:17.14
1,-1,2:17.14
-8,0,2:17.14
-7,0,2:17.14
1,0,2:17.14
-8,1,2:17.14
1,1,2:17.14
2,1,2:17.14
-8,2,2:17.14
1,2,2:17.14
2,2,2:17.14
-7,3,2:17.14
1,3,2:17.14
-7,4,2:17.14
-6,4,2:17.14
0,4,2:17.14
-6,5,2:17.14
-1,5,2:17.14
0,5,2:17.14
-6,6,2:17.14
-5,6,2:17.14
-4,6,2:17.14
-3,6,2:17.14
-2,6,2:17.14
-1,6,2:17.14
-5,-4,3:17.14
-4,-4,3:17.14
-6,-3,3:17.14
-5,-3,3:17.14
-4,-3,3:17.14
-3,-3,3:17.14
-2,-3,3:17.14
-1,-3,3:17.14
-6,-2,3:17.14
-1,-2,3:17.14
0,-2,3:17.14
-7,-1,3:17.14
-6,-1,3:17.14
0,-1,3:17.14
-7,0,3:17.14
0,0,3:17.14
1,0,3:17.14
-8,1,3:17.14
-7,1,3:17.14
1,1,3:17.14
-7,2,3:17.14
1,2,3:17.14
-7,3,3:17.14
-6,3,3:17.14
0,3,3:17.14
1,3,3:17.14
-6,4,3:17.14
0,4,3:17.14
-6,5,3:17.14
-5,5,3:17.14
-4,5,3:17.14
-3,5,3:17.14
-2,5,3:17.14
-1,5,3:17.14
-3,6,3:17.14
-2,6,3:17.14
-1,6,3:17.14
-5,-3,4:17.14
-4,-3,4:17.14
-3,-3,4:17.14
-2,-3,4:17.14
-6,-2,4:17.14
-2,-2,4:17.14
-1,-2,4:17.14
-6,-1,4:17.14
0,-1,4:17.14
-7,0,4:17.14
0,0,4:17.14
-7,1,4:17.14
1,1,4:17.14
-7,2,4:17.14
-6,2,4:17.14
0,2,4:17.14
1,2,4:17.14
-6,3,4:17.14
0,3,4:17.14
-6,4,4:17.14
-5,4,4:17.14
-1,4,4:17.14
0,4,4:17.14
-5,5,4:17.14
-4,5,4:17.14
-3,5,4:17.14
-2,5,4:17.14
-1,5,4:17.14
-5,-3,5:17.14
-4,-3,5:17.14
-6,-2,5:17.14
-5,-2,5:17.14
-4,-2,5:17.14
-3,-2,5:17.14
-2,-2,5:17.14
-1,-2,5:17.14
-6,-1,5:17.14
-1,-1,5:17.14
0,-1,5:17.14
-7,0,5:17.14
-6,0,5:17.14
0,0,5:17.14
-7,1,5:17.14
-6,1,5:17.14
0,1,5:17.14
-6,2,5:17.14
0,2,5:17.14
-6,3,5:17.14
-1,3,5:17.14
0,3,5:17.14
-5,4,5:17.14
-1,4,5:17.14
-5,5,5:17.14
-4,5,5:17.14
-3,5,5:17.14
-2,5,5:17.14
-1,5,5:17.14
-5,-2,6:17.14
-4,-2,6:17.14
-3,-2,6:17.14
-2,-2,6:17.14
-1,-2,6:17.14
-6,-1,6:17.14
-5,-1,6:17.14
-1,-1,6:17.14
0,-1,6:17.14
-6,0,6:17.14
0,0,6:17.14
-6,1,6:17.14
0,1,6:17.14
-6,2,6:17.14
0,2,6:17.14
-5,3,6:17.14
-1,3,6:17.14
-5,4,6:17.14
-4,4,6:17.14
-3,4,6:17.14
-2,4,6:17.14
-1,4,6:17.14
-4,-3,7:17.14
-3,-3,7:17.14
-2,-3,7:17.14
-1,-3,7:17.14
-5,-2,7:17.14
-4,-2,7:17.14
-2,-2,7:17.14
-1,-2,7:17.14
0,-2,7:17.14
-5,-1,7:17.14
0,-1,7:17.14
-6,0,7:17.14
-5,0,7:17.14
0,0,7:17.14
1,0,7:17.14
-6,1,7:17.14
0,1,7:17.14
-6,2,7:17.14
-5,2,7:17.14
-1,2,7:17.14
0,2,7:17.14
-5,3,7:17.14
-1,3,7:17.14
-5,4,7:17.14
-4,4,7:17.14
-3,4,7:17.14
-2,4,7:17.14
-1,4,7:17.14
-4,-3,8:17.14
-3,-3,8:17.14
-2,-3,8:17.14
-1,-3,8:17.14
-4,-2,8:17.14
-1,-2,8:17.14
0,-2,8:17.14
-5,-1,8:17.14
0,-1,8:17.14
-5,0,8:17.14
0,0,8:17.14
1,0,8:17.14
-5,1,8:17.14
0,1,8:17.14
-5,2,8:17.14
-1,2,8:17.14
0,2,8:17.14
-5,3,8:17.14
-4,3,8:17.14
-3,3,8:17.14
-2,3,8:17.14
-1,3,8:17.14
-4,-3,9:17.14
-3,-3,9:17.14
-2,-3,9:17.14
-1,-3,9:17.14
-4,-2,9:17.14
0,-2,9:17.14
-5,-1,9:17.14
-4,-1,9:17.14
0,-1,9:17.14
1,-1,9:17.14
-5,0,9:17.14
0,0,9:17.14
1,0,9:17.14
-5,1,9:17.14
-4,1,9:17.14
0,1,9:17.14
-4,2,9:17.14
-1,2,9:17.14
-4,3,9:17.14
-3,3,9:17.14
-2,3,9:17.14
-1,3,9:17.14
-1,-4,10:17.14
-3,-3,10:17.14
-2,-3,10:17.14
-1,-3,10:17.14
0,-3,10:17.14
-4,-2,10:17.14
0,-2,10:17.14
1,-2,10:17.14
-4,-1,10:17.14
1,-1,10:17.14
-5,0,10:17.14
-4,0,10:17.14
0,0,10:17.14
1,0,10:17.14
-4,1,10:17.14
-1,1,10:17.14
0,1,10:17.14
-4,2,10:17.14
-3,2,10:17.14
-2,2,10:17.14
-1,2,10:17.14
0,-4,11:17.14
1,-4,11:17.14
-3,-3,11:17.14
-2,-3,11:17.14
-1,-3,11:17.14
0,-3,11:17.14
1,-3,11:17.14
2,-3,11:17.14
-4,-2,11:17.14
-3,-2,11:17.14
1,-2,11:17.14
2,-2,11:17.14
-4,-1,11:17.14
0,-1,11:17.14
1,-1,11:17.14
2,-1,11:17.14
-4,0,11:17.14
0,0,11:17.14
-4,1,11:17.14
-3,1,11:17.14
-2,1,11:17.14
-1,1,11:17.14
0,1,11:17.14
-3,2,11:17.14
-2,2,11:17.14
-1,2,11:17.14
1,-4,12:17.14
2,-4,12:17.14
-1,-3,12:17.14
0,-3,12:17.14
1,-3,12:17.14
2,-3,12:17.14
3,-3,12:17.14
4,-3,12:17.14
-3,-2,12:17.14
-2,-2,12:17.14
-1,-2,12:17.14
3,-2,12:17.14
-4,-1,12:17.14
-3,-1,12:17.14
0,-1,12:17.14
1,-1,12:17.14
2,-1,12:17.14
3,-1,12:17.14
-6,0,12:17.14
-5,0,12:17.14
-4,0,12:17.14
-1,0,12:17.14
0,0,12:17.14
-5,1,12:17.14
-4,1,12:17.14
-3,1,12:17.14
-2,1,12:17.14
-1,1,12:17.14
-5,2,12:17.14
-4,2,12:17.14
-3,2,12:17.14
2,-4,13:17.14
3,-4,13:17.14
4,-4,13:17.14
1,-3,13:17.14
2,-3,13:17.14
4,-3,13:17.14
5,-3,13:17.14
-1,-2,13:17.14
0,-2,13:17.14
1,-2,13:17.14
3,-2,13:17.14
4,-2,13:17.14
5,-2,13:17.14
-3,-1,13:17.14
-2,-1,13:17.14
-1,-1,13:17.14
0,-1,13:17.14
1,-1,13:17.14
2,-1,13:17.14
3,-1,13:17.14
-6,0,13:17.14
-5,0,13:17.14
-4,0,13:17.14
-3,0,13:17.14
-2,0,13:17.14
-1,0,13:17.14
-7,1,13:17.14
-6,1,13:17.14
-4,1,13:17.14
-3,1,13:17.14
-6,2,13:17.14
-5,2,13:17.14
-4,2,13:17.14
3,-4,14:17.14
4,-4,14:17.14
5,-4,14:17.14
2,-3,14:17.14
3,-3,14:17.14
5,-3,14:17.14
6,-3,14:17.14
0,-2,14:17.14
1,-2,14:17.14
2,-2,14:17.14
3,-2,14:17.14
4,-2,14:17.14
5,-2,14:17.14
6,-2,14:17.14
-1,-1,14:17.14
0,-1,14:17.14
1,-1,14:17.14
-6,0,14:17.14
-5,0,14:17.14
-4,0,14:17.14
-3,0,14:17.14
-2,0,14:17.14
-8,1,14:17.14
-7,1,14:17.14
-6,1,14:17.14
-4,1,14:17.14
-8,2,14:17.14
-7,2,14:17.14
-6,2,14:17.14
-5,2,14:17.14
-7,3,14:17.14
-11,9,14:100.0
4,-4,15:17.14
5,-4,15:17.14
6,-4,15:17.14
-3,-3,15:100.0
3,-3,15:17.14
4,-3,15:17.14
6,-3,15:17.14
-4,-2,15:100.0
1,-2,15:17.14
2,-2,15:17.14
3,-2,15:17.14
4,-2,15:17.14
5,-2,15:17.14
6,-2,15:17.14
-5,-1,15:100.0
-9,1,15:100.0
-8,1,15:17.14
-7,1,15:17.14
-6,1,15:17.14
-5,1,15:17.14
-4,1,15:17.14
-9,2,15:17.14
-8,2,15:17.14
-7,2,15:17.14
-6,2,15:17.14
-5,2,15:17.14
-9,3,15:100.0
-8,3,15:17.14
-7,3,15:17.14
-9,4,15:100.0
-10,5,15:100.0
-9,5,15:100.0
-10,6,15:100.0
-11,7,15:100.0
-10,7,15:100.0
-12,8,15:100.0
-11,8,15:100.0
-10,8,15:100.0
-9,8,15:100.0
-12,9,15:100.0
-11,9,15:159.4
-10,9,15:100.0
-9,9,15:100.0
-12,10,15:100.0
-11,10,15:100.0
-10,10,15:100.0
-9,10,15:100.0
-12,11,15:100.0
-11,11,15:100.0
-10,11,15:100.0
-12,12,15:100.0
-11,12,15:100.0
-10,12,15:100.0
-12,13,15:100.0
-11,13,15:100.0
-12,14,15:100.0
-11,14,15:100.0
-11,-7,16:100.0
-10,-7,16:100.0
-9,-7,16:100.0
-8,-7,16:100.0
-14,-5,16:100.0
-16,-4,16:100.0
-15,-4,16:100.0
-14,-4,16:100.0
-13,-4,16:100.0
5,-4,16:17.14
6,-4,16:17.14
-16,-3,16:100.0
-15,-3,16:100.0
-14,-3,16:100.0
-13,-3,16:100.0
-3,-3,16:159.4
3,-3,16:17.14
4,-3,16:17.14
5,-3,16:17.14
6,-3,16:17.14
7,-3,16:17.14
-17,-2,16:100.0
-16,-2,16:100.0
-15,-2,16:100.0
-14,-2,16:100.0
-13,-2,16:100.0
-4,-2,16:159.4
3,-2,16:17.14
4,-2,16:17.14
-18,-1,16:100.0
-17,-1,16:100.0
-16,-1,16:100.0
-15,-1,16:100.0
-14,-1,16:100.0
-13,-1,16:100.0
-5,-1,16:159.4
-4,-1,16:100.0
-18,0,16:100.0
-17,0,16:100.0
-15,0,16:100.0
-14,0,16:100.0
-13,0,16:100.0
-12,0,16:100.0
-11,0,16:100.0
-6,0,16:100.0
-5,0,16:100.0
-19,1,16:100.0
-18,1,16:100.0
-17,1,16:100.0
-16,1,16:100.0
-15,1,16:100.0
-14,1,16:100.0
-13,1,16:100.0
-12,1,16:100.0
-11,1,16:100.0
-10,1,16:100.0
-9,1,16:159.4
-6,1,16:159.4
-20,2,16:100.0
-19,2,16:100.0
-18,2,16:100.0
-17,2,16:100.0
-16,2,16:100.0
-15,2,16:100.0
-14,2,16:100.0
-13,2,16:100.0
-11,2,16:100.0
-10,2,16:100.0
-9,2,16:17.14
-8,2,16:17.14
-7,2,16:17.14
-6,2,16:17.14
-20,3,16:100.0
-19,3,16:100.0
-18,3,16:100.0
-17,3,16:100.0
-16,3,16:100.0
-15,3,16:100.0
-14,3,16:100.0
-13,3,16:100.0
-9,3,16:17.14
-8,3,16:17.14
-7,3,16:17.14
-20,4,16:100.0
-18,4,16:100.0
-17,4,16:100.0
-16,4,16:100.0
-15,4,16:100.0
-14,4,16:100.0
-13,4,16:100.0
-9,4,16:159.4
-19,5,16:100.0
-18,5,16:100.0
-17,5,16:100.0
-16,5,16:100.0
-15,5,16:100.0
-14,5,16:100.0
-13,5,16:100.0
-10,5,16:159.4
-19,6,16:100.0
-18,6,16:100.0
-17,6,16:100.0
-16,6,16:100.0
-15,6,16:100.0
-14,6,16:100.0
-13,6,16:100.0
-11,6,16:100.0
-10,6,16:159.4
-18,7,16:100.0
-17,7,16:100.0
-16,7,16:100.0
-15,7,16:100.0
-14,7,16:100.0
-13,7,16:100.0
-12,7,16:100.0
-11,7,16:159.4
-17,8,16:100.0
-16,8,16:100.0
-15,8,16:100.0
-14,8,16:100.0
-13,8,16:100.0
-12,8,16:159.4
-11,8,16:159.4
-17,9,16:100.0
-16,9,16:100.0
-15,9,16:100.0
-14,9,16:100.0
-13,9,16:100.0
-12,9,16:159.4
-11,9,16:159.4
-17,10,16:100.0
-16,10,16:100.0
-15,10,16:100.0
-14,10,16:100.0
-13,10,16:100.0
-12,10,16:159.4
-11,10,16:159.4
-16,11,16:100.0
-15,11,16:100.0
-14,11,16:100.0
-13,11,16:100.0
-12,11,16:159.4
-15,12,16:100.0
-14,12,16:100.0
-13,12,16:100.0
-14,13,16:100.0
-13,13,16:100.0
-11,-7,17:159.4
-10,-7,17:159.4
-9,-7,17:159.4
-8,-7,17:159.4
-13,-6,17:100.0
-12,-6,17:100.0
-11,-6,17:100.0
-10,-6,17:100.0
-9,-6,17:100.0
-8,-6,17:100.0
-14,-5,17:159.4
-12,-5,17:100.0
-11,-5,17:100.0
-10,-5,17:100.0
-9,-5,17:100.0
-8,-5,17:100.0
-7,-5,17:100.0
-6,-5,17:100.0
6,-5,17:17.14
-16,-4,17:159.4
-15,-4,17:159.4
-14,-4,17:159.4
-13,-4,17:159.4
-12,-4,17:100.0
-11,-4,17:100.0
-10,-4,17:100.0
-9,-4,17:100.0
-8,-4,17:100.0
-7,-4,17:100.0
-6,-4,17:100.0
-5,-4,17:100.0
4,-4,17:17.14
5,-4,17:17.14
6,-4,17:17.14
7,-4,17:17.14
-16,-3,17:159.4
-15,-3,17:159.4
-14,-3,17:159.4
-13,-3,17:159.4
-12,-3,17:100.0
-10,-3,17:100.0
-8,-3,17:100.0
-7,-3,17:100.0
-6,-3,17:100.0
-5,-3,17:100.0
-4,-3,17:100.0
-3,-3,17:159.4
4,-3,17:17.14
5,-3,17:17.14
6,-3,17:17.14
7,-3,17:17.14
-17,-2,17:159.4
-16,-2,17:159.4
-15,-2,17:159.4
-14,-2,17:159.4
-13,-2,17:159.4
-10,-2,17:100.0
-7,-2,17:100.0
-6,-2,17:100.0
-5,-2,17:100.0
-4,-2,17:159.4
-3,-2,17:100.0
-2,-2,17:100.0
-18,-1,17:82.0
-17,-1,17:82.0
-16,-1,17:82.0
-15,-1,17:159.4
-14,-1,17:159.4
-13,-1,17:159.4
-10,-1,17:100.0
-6,-1,17:100.0
-5,-1,17:159.4
-4,-1,17:159.4
-3,-1,17:100.0
-2,-1,17:100.0
-1,-1,17:100.0
-18,0,17:82.0
-17,0,17:82.0
-15,0,17:159.4
-14,0,17:159.4
-13,0,17:159.4
-12,0,17:159.4
-10,0,17:100.0
-6,0,17:159.4
-5,0,17:159.4
-4,0,17:100.0
-3,0,17:100.0
-2,0,17:100.0
-19,1,17:159.4
-18,1,17:82.0
-17,1,17:82.0
-16,1,17:82.0
-15,1,17:159.4
-14,1,17:159.4
-13,1,17:159.4
-12,1,17:159.4
-11,1,17:159.4
-10,1,17:100.0
-7,1,17:100.0
-6,1,17:159.4
-5,1,17:100.0
-4,1,17:100.0
-3,1,17:100.0
-2,1,17:100.0
-1,1,17:100.0
-19,2,17:159.4
-18,2,17:159.4
-17,2,17:159.4
-16,2,17:159.4
-15,2,17:159.4
-14,2,17:159.4
-13,2,17:159.4
-11,2,17:159.4
-10,2,17:159.4
-9,2,17:17.14
-8,2,17:159.4
-7,2,17:159.4
-5,2,17:100.0
-4,2,17:100.0
-3,2,17:100.0
-2,2,17:100.0
-1,2,17:100.0
0,2,17:100.0
-20,3,17:159.4
-19,3,17:159.4
-18,3,17:159.4
-17,3,17:159.4
-16,3,17:159.4
-15,3,17:159.4
-14,3,17:159.4
-13,3,17:159.4
-10,3,17:17.14
-9,3,17:17.14
-8,3,17:17.14
-4,3,17:100.0
-3,3,17:100.0
-2,3,17:100.0
-1,3,17:100.0
0,3,17:100.0
-18,4,17:159.4
-17,4,17:159.4
-16,4,17:159.4
-15,4,17:159.4
-14,4,17:159.4
-13,4,17:159.4
-10,4,17:100.0
-9,4,17:17.14
-4,4,17:100.0
-3,4,17:100.0
-2,4,17:100.0
-1,4,17:100.0
0,4,17:100.0
-19,5,17:159.4
-18,5,17:159.4
-17,5,17:159.4
-16,5,17:159.4
-15,5,17:82.0
-14,5,17:159.4
-13,5,17:159.4
-10,5,17:159.4
-4,5,17:100.0
-3,5,17:100.0
-2,5,17:100.0
-1,5,17:100.0
0,5,17:100.0
-18,6,17:159.4
-17,6,17:159.4
-16,6,17:82.0
-15,6,17:82.0
-14,6,17:82.0
-13,6,17:159.4
-11,6,17:159.4
-8,6,17:100.0
-4,6,17:100.0
-3,6,17:100.0
-2,6,17:100.0
-1,6,17:100.0
-18,7,17:159.4
-17,7,17:159.4
-16,7,17:159.4
-15,7,17:82.0
-14,7,17:159.4
-13,7,17:159.4
-12,7,17:100.0
-11,7,17:159.4
-8,7,17:100.0
-7,7,17:100.0
-3,7,17:100.0
-2,7,17:100.0
-1,7,17:100.0
0,7,17:100.0
-17,8,17:159.4
-16,8,17:159.4
-15,8,17:159.4
-14,8,17:159.4
-13,8,17:159.4
-12,8,17:159.4
-7,8,17:100.0
-6,8,17:100.0
-3,8,17:100.0
-2,8,17:100.0
-1,8,17:100.0
0,8,17:100.0
-16,9,17:159.4
-15,9,17:159.4
-14,9,17:159.4
-13,9,17:159.4
-12,9,17:159.4
-5,9,17:100.0
-3,9,17:100.0
-2,9,17:100.0
-1,9,17:100.0
-16,10,17:159.4
-15,10,17:159.4
-14,10,17:159.4
-13,10,17:159.4
-4,10,17:100.0
-3,10,17:100.0
-2,10,17:100.0
-1,10,17:100.0
-15,11,17:159.4
-14,11,17:159.4
-13,11,17:159.4
-12,11,17:100.0
-11,11,17:100.0
-10,11,17:100.0
-9,11,17:100.0
-8,11,17:100.0
-7,11,17:100.0
-6,11,17:100.0
-5,11,17:100.0
-3,11,17:100.0
-2,11,17:100.0
-1,11,17:100.0
-15,12,17:159.4
-14,12,17:159.4
-13,12,17:159.4
-12,12,17:100.0
-11,12,17:100.0
-10,12,17:100.0
-9,12,17:100.0
-8,12,17:100.0
-7,12,17:100.0
-6,12,17:100.0
-5,12,17:100.0
-4,12,17:100.0
-3,12,17:100.0
-2,12,17:100.0
-1,12,17:100.0
-12,13,17:100.0
-11,13,17:100.0
-10,13,17:100.0
-9,13,17:100.0
-8,13,17:100.0
-7,13,17:100.0
-6,13,17:100.0
-5,13,17:100.0
-4,13,17:100.0
-3,13,17:100.0
-12,14,17:100.0
-11,14,17:100.0
-10,14,17:100.0
-9,14,17:100.0
-8,14,17:100.0
-7,14,17:100.0
-4,14,17:100.0
-12,15,17:100.0
-11,15,17:100.0
-10,-7,18:159.4
-9,-7,18:159.4
-12,-6,18:159.4
-11,-6,18:82.0
-10,-6,18:159.4
-9,-6,18:159.4
-8,-6,18:159.4
-12,-5,18:82.0
-11,-5,18:82.0
-10,-5,18:82.0
-9,-5,18:159.4
-8,-5,18:159.4
-7,-5,18:159.4
-6,-5,18:159.4
6,-5,18:17.14
7,-5,18:17.14
-14,-4,18:159.4
-13,-4,18:159.4
-12,-4,18:159.4
-11,-4,18:82.0
-10,-4,18:159.4
-9,-4,18:159.4
-8,-4,18:159.4
-7,-4,18:159.4
-6,-4,18:159.4
-5,-4,18:159.4
5,-4,18:17.14
6,-4,18:17.14
7,-4,18:17.14
8,-4,18:100.0
-14,-3,18:159.4
-13,-3,18:159.4
-12,-3,18:159.4
-11,-3,18:100.0
-10,-3,18:159.4
-9,-3,18:100.0
-8,-3,18:159.4
-7,-3,18:159.4
-6,-3,18:159.4
-5,-3,18:159.4
-4,-3,18:159.4
-15,-2,18:159.4
-14,-2,18:159.4
-13,-2,18:159.4
-12,-2,18:100.0
-11,-2,18:100.0
-10,-2,18:159.4
-9,-2,18:100.0
-7,-2,18:159.4
-6,-2,18:159.4
-5,-2,18:159.4
-4,-2,18:159.4
-3,-2,18:159.4
-15,-1,18:159.4
-14,-1,18:159.4
-13,-1,18:159.4
-12,-1,18:100.0
-11,-1,18:100.0
-10,-1,18:159.4
-9,-1,18:100.0
-8,-1,18:100.0
-7,-1,18:100.0
-6,-1,18:159.4
-5,-1,18:159.4
-4,-1,18:159.4
-3,-1,18:159.4
-2,-1,18:159.4
-15,0,18:159.4
-14,0,18:159.4
-13,0,18:159.4
-12,0,18:100.0
-11,0,18:100.0
-10,0,18:159.4
-9,0,18:100.0
-8,0,18:100.0
-7,0,18:100.0
-6,0,18:159.4
-5,0,18:159.4
-4,0,18:159.4
-3,0,18:159.4
-2,0,18:159.4
-16,1,18:159.4
-15,1,18:159.4
-14,1,18:159.4
-13,1,18:159.4
-12,1,18:100.0
-11,1,18:100.0
-10,1,18:159.4
-9,1,18:100.0
-8,1,18:100.0
-7,1,18:159.4
-6,1,18:100.0
-5,1,18:159.4
-4,1,18:159.4
-3,1,18:159.4
-2,1,18:159.4
-1,1,18:159.4
-16,2,18:159.4
-15,2,18:159.4
-14,2,18:159.4
-13,2,18:100.0
-12,2,18:100.0
-11,2,18:159.4
-10,2,18:100.0
-9,2,18:100.0
-8,2,18:159.4
-7,2,18:100.0
-6,2,18:100.0
-5,2,18:159.4
-4,2,18:159.4
-3,2,18:159.4
-2,2,18:159.4
-1,2,18:159.4
-17,3,18:159.4
-16,3,18:159.4
-15,3,18:159.4
-14,3,18:159.4
-13,3,18:100.0
-12,3,18:100.0
-11,3,18:100.0
-10,3,18:17.14
-9,3,18:17.14
-8,3,18:159.4
-7,3,18:100.0
-6,3,18:100.0
-5,3,18:100.0
-4,3,18:159.4
-3,3,18:159.4
-2,3,18:159.4
-1,3,18:159.4
-17,4,18:159.4
-16,4,18:159.4
-15,4,18:159.4
-14,4,18:159.4
-13,4,18:159.4
-11,4,18:17.14
-10,4,18:17.14
-9,4,18:100.0
-8,4,18:100.0
-6,4,18:100.0
-5,4,18:100.0
-4,4,18:159.4
-3,4,18:159.4
-2,4,18:159.4
-1,4,18:159.4
-16,5,18:82.0
-15,5,18:82.0
-14,5,18:82.0
-13,5,18:100.0
-12,5,18:100.0
-11,5,18:100.0
-10,5,18:159.4
-9,5,18:100.0
-8,5,18:100.0
-7,5,18:100.0
-6,5,18:100.0
-5,5,18:100.0
-4,5,18:159.4
-3,5,18:159.4
-2,5,18:159.4
-1,5,18:159.4
-16,6,18:82.0
-15,6,18:82.0
-14,6,18:82.0
-13,6,18:159.4
-12,6,18:100.0
-11,6,18:159.4
-10,6,18:100.0
-9,6,18:100.0
-8,6,18:159.4
-7,6,18:100.0
-6,6,18:100.0
-5,6,18:100.0
-4,6,18:159.4
-3,6,18:159.4
-2,6,18:159.4
-1,6,18:159.4
-15,7,18:82.0
-14,7,18:82.0
-13,7,18:159.4
-12,7,18:159.4
-11,7,18:100.0
-10,7,18:100.0
-9,7,18:100.0
-8,7,18:159.4
-7,7,18:159.4
-6,7,18:100.0
-5,7,18:100.0
-4,7,18:100.0
-3,7,18:159.4
-2,7,18:159.4
-1,7,18:159.4
-14,8,18:159.4
-13,8,18:159.4
-12,8,18:159.4
-11,8,18:100.0
-10,8,18:100.0
-9,8,18:100.0
-8,8,18:100.0
-7,8,18:159.4
-6,8,18:159.4
-5,8,18:100.0
-4,8,18:100.0
-3,8,18:159.4
-2,8,18:159.4
-1,8,18:159.4
-14,9,18:159.4
-13,9,18:159.4
-12,9,18:159.4
-11,9,18:100.0
-10,9,18:100.0
-9,9,18:100.0
-8,9,18:100.0
-7,9,18:100.0
-6,9,18:100.0
-5,9,18:159.4
-4,9,18:100.0
-3,9,18:159.4
-2,9,18:159.4
-1,9,18:159.4
-13,10,18:159.4
-12,10,18:100.0
-11,10,18:100.0
-10,10,18:100.0
-9,10,18:100.0
-8,10,18:100.0
-7,10,18:100.0
-6,10,18:100.0
-5,10,18:100.0
-4,10,18:159.4
-3,10,18:159.4
-2,10,18:159.4
-1,10,18:159.4
-12,11,18:159.4
-11,11,18:82.0
-10,11,18:82.0
-9,11,18:82.0
-8,11,18:159.4
-7,11,18:159.4
-6,11,18:159.4
-5,11,18:159.4
-3,11,18:82.0
-2,11,18:82.0
-1,11,18:159.4
-12,12,18:159.4
-11,12,18:159.4
-10,12,18:82.0
-9,12,18:159.4
-8,12,18:159.4
-7,12,18:159.4
-6,12,18:159.4
-5,12,18:159.4
-4,12,18:82.0
-3,12,18:82.0
-2,12,18:82.0
-1,12,18:159.4
-12,13,18:159.4
-11,13,18:159.4
-10,13,18:159.4
-9,13,18:159.4
-8,13,18:159.4
-7,13,18:159.4
-6,13,18:159.4
-5,13,18:159.4
-4,13,18:82.0
-3,13,18:82.0
-12,14,18:159.4
-11,14,18:159.4
-10,14,18:159.4
-9,14,18:159.4
-8,14,18:159.4
-7,14,18:159.4
-4,14,18:159.4
-12,15,18:159.4
-11,15,18:159.4
7,-6,19:17.14
-11,-5,19:82.0
-10,-5,19:82.0
-9,-5,19:159.4
6,-5,19:17.14
7,-5,19:17.14
8,-5,19:17.14
-12,-4,19:82.0
-11,-4,19:82.0
-10,-4,19:82.0
-9,-4,19:159.4
-8,-4,19:159.4
6,-4,19:17.14
7,-4,19:17.14
8,-4,19:159.4
-12,-3,19:159.4
-11,-3,19:159.4
-10,-3,19:159.4
-9,-3,19:159.4
-8,-3,19:159.4
-7,-3,19:159.4
-12,-2,19:159.4
-11,-2,19:159.4
-10,-2,19:159.4
-9,-2,19:159.4
-7,-2,19:159.4
-6,-2,19:159.4
-12,-1,19:159.4
-11,-1,19:159.4
-10,-1,19:159.4
-9,-1,19:159.4
-8,-1,19:159.4
-7,-1,19:159.4
-6,-1,19:159.4
-5,-1,19:159.4
-13,0,19:159.4
-12,0,19:159.4
-11,0,19:159.4
-10,0,19:159.4
-9,0,19:159.4
-8,0,19:159.4
-7,0,19:159.4
-6,0,19:159.4
-5,0,19:159.4
-4,0,19:159.4
-13,1,19:159.4
-12,1,19:159.4
-11,1,19:159.4
-10,1,19:159.4
-9,1,19:159.4
-8,1,19:159.4
-7,1,19:159.4
-6,1,19:159.4
-5,1,19:159.4
-4,1,19:159.4
-3,1,19:159.4
-14,2,19:159.4
-13,2,19:159.4
-12,2,19:159.4
-11,2,19:159.4
-10,2,19:159.4
-9,2,19:159.4
-8,2,19:159.4
-7,2,19:159.4
-6,2,19:159.4
-5,2,19:159.4
-4,2,19:159.4
-3,2,19:159.4
-17,3,19:159.4
-14,3,19:159.4
-13,3,19:159.4
-12,3,19:159.4
-11,3,19:159.4
-10,3,19:17.14
-9,3,19:159.4
-8,3,19:159.4
-7,3,19:159.4
-6,3,19:159.4
-5,3,19:159.4
-4,3,19:159.4
-3,3,19:159.4
-16,4,19:159.4
-15,4,19:159.4
-14,4,19:159.4
-13,4,19:159.4
-12,4,19:17.14
-11,4,19:17.14
-10,4,19:17.14
-9,4,19:159.4
-8,4,19:159.4
-6,4,19:159.4
-5,4,19:159.4
-4,4,19:159.4
-3,4,19:159.4
-14,5,19:159.4
-13,5,19:159.4
-12,5,19:159.4
-11,5,19:159.4
-10,5,19:159.4
-9,5,19:159.4
-8,5,19:159.4
-7,5,19:159.4
-6,5,19:159.4
-5,5,19:159.4
-4,5,19:159.4
-3,5,19:159.4
-13,6,19:159.4
-12,6,19:159.4
-11,6,19:159.4
-10,6,19:159.4
-9,6,19:159.4
-8,6,19:159.4
-7,6,19:159.4
-6,6,19:159.4
-5,6,19:159.4
-4,6,19:159.4
-3,6,19:159.4
-13,7,19:159.4
-12,7,19:159.4
-11,7,19:159.4
-10,7,19:159.4
-9,7,19:159.4
-8,7,19:159.4
-7,7,19:159.4
-6,7,19:159.4
-5,7,19:159.4
-4,7,19:159.4
-3,7,19:159.4
-12,8,19:159.4
-11,8,19:159.4
-10,8,19:159.4
-9,8,19:159.4
-8,8,19:159.4
-7,8,19:159.4
-6,8,19:159.4
-5,8,19:159.4
-4,8,19:159.4
-3,8,19:159.4
-13,9,19:159.4
-12,9,19:159.4
-11,9,19:159.4
-10,9,19:159.4
-9,9,19:159.4
-8,9,19:159.4
-7,9,19:159.4
-6,9,19:159.4
-5,9,19:159.4
-4,9,19:159.4
-3,9,19:159.4
-12,10,19:159.4
-11,10,19:82.0
-10,10,19:82.0
-9,10,19:82.0
-8,10,19:159.4
-7,10,19:159.4
-6,10,19:159.4
-5,10,19:159.4
-4,10,19:159.4
-3,10,19:159.4
-12,11,19:159.4
-11,11,19:82.0
-10,11,19:82.0
-9,11,19:82.0
-8,11,19:159.4
-7,11,19:159.4
-6,11,19:159.4
-5,11,19:159.4
-3,11,19:82.0
-2,11,19:159.4
-12,12,19:159.4
-11,12,19:82.0
-10,12,19:82.0
-9,12,19:82.0
-8,12,19:159.4
-7,12,19:159.4
7,-6,20:17.14
6,-5,20:17.14
7,-5,20:17.14
8,-5,20:17.14
-9,-4,20:159.4
6,-4,20:17.14
7,-4,20:17.14
8,-4,20:159.4
9,-4,20:100.0
-10,-3,20:159.4
-11,-2,20:159.4
-10,-2,20:159.4
-9,-2,20:159.4
-12,-1,20:159.4
-11,-1,20:159.4
-10,-1,20:159.4
-9,-1,20:159.4
-8,-1,20:159.4
-12,0,20:159.4
-11,0,20:159.4
-10,0,20:159.4
-9,0,20:159.4
-8,0,20:159.4
-7,0,20:159.4
-12,1,20:159.4
-11,1,20:159.4
-10,1,20:159.4
-9,1,20:159.4
-8,1,20:159.4
-7,1,20:159.4
-12,2,20:100.0
-11,2,20:100.0
-10,2,20:100.0
-9,2,20:159.4
-8,2,20:159.4
-7,2,20:159.4
-6,2,20:159.4
-12,3,20:159.4
-11,3,20:159.4
-10,3,20:159.4
-9,3,20:100.0
-8,3,20:159.4
-7,3,20:159.4
-6,3,20:159.4
-15,4,20:159.4
-14,4,20:82.0
-13,4,20:82.0
-12,4,20:100.0
-11,4,20:17.14
-10,4,20:159.4
-9,4,20:100.0
-8,4,20:159.4
-6,4,20:159.4
-12,5,20:159.4
-11,5,20:159.4
-10,5,20:159.4
-9,5,20:159.4
-8,5,20:159.4
-7,5,20:159.4
-6,5,20:159.4
-5,5,20:159.4
-12,6,20:100.0
-11,6,20:159.4
-10,6,20:159.4
-9,6,20:159.4
-8,6,20:159.4
-7,6,20:159.4
-6,6,20:159.4
-5,6,20:159.4
-12,7,20:159.4
-11,7,20:159.4
-10,7,20:159.4
-9,7,20:159.4
-8,7,20:159.4
-7,7,20:159.4
-6,7,20:159.4
-5,7,20:159.4
-12,8,20:159.4
-11,8,20:159.4
-10,8,20:159.4
-9,8,20:159.4
-8,8,20:159.4
-7,8,20:159.4
-6,8,20:159.4
-5,8,20:159.4
-13,9,20:159.4
-12,9,20:159.4
-11,9,20:159.4
-10,9,20:159.4
-9,9,20:159.4
-8,9,20:159.4
-7,9,20:159.4
-6,9,20:159.4
-5,9,20:159.4
-4,9,20:159.4
-12,10,20:159.4
-11,10,20:159.4
-4,10,20:159.4
7,-6,21:17.14
8,-6,21:17.14
6,-5,21:17.14
7,-5,21:17.14
8,-5,21:17.14
7,-4,21:17.14
8,-4,21:159.4
9,-4,21:159.4
-10,-3,21:159.4
-10,-2,21:159.4
-10,-1,21:159.4
-10,0,21:159.4
-11,1,21:159.4
-10,1,21:159.4
-12,2,21:159.4
-11,2,21:159.4
-10,2,21:159.4
-9,2,21:159.4
-12,3,21:82.0
-11,3,21:159.4
-10,3,21:159.4
-9,3,21:159.4
-8,3,21:159.4
-13,4,21:82.0
-12,4,21:82.0
-11,4,21:17.14
-10,4,21:159.4
-9,4,21:159.4
-8,4,21:159.4
-12,5,21:82.0
-11,5,21:159.4
-10,5,21:159.4
-9,5,21:159.4
-8,5,21:159.4
-12,6,21:159.4
-11,6,21:159.4
-10,6,21:159.4
-9,6,21:159.4
-8,6,21:159.4
-11,7,21:159.4
-10,7,21:159.4
-9,7,21:159.4
-8,7,21:159.4
-7,7,21:159.4
-6,8,21:159.4
-12,9,21:159.4
-5,9,21:159.4
7,-6,22:17.14
8,-6,22:17.14
7,-5,22:17.14
8,-5,22:17.14
9,-5,22:100.0
9,-4,22:159.4
-10,-1,22:159.4
-10,0,22:159.4
-10,1,22:159.4
13,1,22:100.0
-11,2,22:159.4
-10,2,22:159.4
14,2,22:100.0
-11,3,22:159.4
15,3,22:100.0
-11,4,22:159.4
16,4,22:100.0
-10,5,22:159.4
-9,5,22:159.4
-9,6,22:159.4
-8,6,22:159.4
-8,7,22:159.4
-7,7,22:159.4
-6,8,22:159.4
-5,11,22:100.0
-4,12,22:100.0
-2,13,22:100.0
-1,13,22:100.0
-1,14,22:100.0
8,-24,23:100.0
4,-23,23:100.0
5,-23,23:100.0
6,-23,23:100.0
7,-23,23:100.0
13,-23,23:100.0
0,-22,23:100.0
1,-22,23:100.0
14,-22,23:100.0
15,-22,23:100.0
-1,-21,23:100.0
15,-21,23:100.0
16,-21,23:100.0
17,-21,23:100.0
-6,-20,23:100.0
17,-20,23:100.0
18,-20,23:100.0
19,-20,23:100.0
-7,-19,23:100.0
18,-19,23:100.0
19,-19,23:100.0
20,-19,23:100.0
20,-18,23:100.0
21,-18,23:100.0
24,-18,23:100.0
-8,-17,23:100.0
21,-17,23:100.0
22,-17,23:100.0
23,-17,23:100.0
24,-17,23:100.0
24,-16,23:100.0
-9,-15,23:100.0
25,-15,23:100.0
-10,-14,23:100.0
-10,-13,23:100.0
27,-13,23:100.0
-11,-12,23:100.0
-12,-11,23:100.0
-11,-11,23:100.0
27,-11,23:100.0
27,-10,23:100.0
27,-9,23:100.0
28,-9,23:100.0
27,-8,23:100.0
28,-8,23:100.0
8,-7,23:100.0
27,-7,23:100.0
28,-7,23:100.0
7,-6,23:17.14
8,-6,23:17.14
27,-6,23:100.0
28,-6,23:100.0
-12,-5,23:100.0
7,-5,23:17.14
8,-5,23:17.14
9,-5,23:159.4
26,-5,23:100.0
27,-5,23:100.0
28,-5,23:100.0
-12,-4,23:100.0
9,-4,23:159.4
10,-4,23:100.0
26,-4,23:100.0
27,-4,23:100.0
28,-4,23:100.0
-12,-3,23:100.0
26,-3,23:100.0
27,-3,23:100.0
28,-3,23:100.0
-12,-2,23:100.0
26,-2,23:100.0
27,-2,23:100.0
28,-2,23:100.0
-12,-1,23:100.0
-11,-1,23:100.0
26,-1,23:100.0
27,-1,23:100.0
12,0,23:100.0
26,0,23:100.0
27,0,23:100.0
28,0,23:100.0
-11,1,23:100.0
13,1,23:159.4
25,1,23:100.0
26,1,23:100.0
27,1,23:100.0
28,1,23:100.0
-11,2,23:159.4
14,2,23:159.4
23,2,23:100.0
24,2,23:100.0
25,2,23:100.0
26,2,23:100.0
27,2,23:100.0
28,2,23:100.0
-11,3,23:159.4
15,3,23:159.4
25,3,23:100.0
26,3,23:100.0
27,3,23:100.0
-11,4,23:159.4
15,4,23:100.0
16,4,23:159.4
25,4,23:100.0
26,4,23:100.0
27,4,23:100.0
-10,5,23:159.4
16,5,23:100.0
17,5,23:100.0
25,5,23:100.0
26,5,23:100.0
-10,6,23:100.0
-8,6,23:159.4
25,6,23:100.0
-10,7,23:100.0
-8,7,23:159.4
24,7,23:100.0
25,7,23:100.0
-10,8,23:100.0
-9,8,23:100.0
24,8,23:100.0
-8,9,23:100.0
-7,9,23:100.0
-6,10,23:100.0
-5,10,23:100.0
23,10,23:100.0
-5,11,23:159.4
-3,11,23:100.0
22,11,23:100.0
23,11,23:100.0
-3,12,23:100.0
-2,12,23:100.0
20,12,23:100.0
21,12,23:100.0
22,12,23:100.0
-2,13,23:159.4
-1,13,23:159.4
0,13,23:100.0
16,13,23:100.0
17,13,23:100.0
18,13,23:100.0
0,14,23:100.0
1,14,23:100.0
2,14,23:100.0
12,14,23:100.0
13,14,23:100.0
15,14,23:100.0
16,14,23:100.0
0,15,23:100.0
1,15,23:100.0
5,-23,24:159.4
6,-23,24:159.4
7,-23,24:159.4
8,-23,24:100.0
9,-23,24:100.0
10,-23,24:100.0
11,-23,24:100.0
12,-23,24:100.0
1,-22,24:159.4
2,-22,24:100.0
3,-22,24:100.0
4,-22,24:100.0
5,-22,24:100.0
6,-22,24:100.0
7,-22,24:100.0
8,-22,24:100.0
9,-22,24:100.0
10,-22,24:100.0
11,-22,24:100.0
12,-22,24:100.0
13,-22,24:100.0
14,-22,24:159.4
-2,-21,24:100.0
-1,-21,24:159.4
0,-21,24:100.0
1,-21,24:100.0
2,-21,24:100.0
3,-21,24:100.0
4,-21,24:100.0
5,-21,24:100.0
6,-21,24:100.0
7,-21,24:100.0
8,-21,24:100.0
9,-21,24:100.0
10,-21,24:100.0
11,-21,24:100.0
12,-21,24:100.0
13,-21,24:100.0
14,-21,24:100.0
15,-21,24:159.4
16,-21,24:159.4
-6,-20,24:159.4
-5,-20,24:100.0
-4,-20,24:100.0
-3,-20,24:100.0
-2,-20,24:100.0
-1,-20,24:100.0
0,-20,24:100.0
1,-20,24:100.0
2,-20,24:100.0
3,-20,24:100.0
4,-20,24:100.0
5,-20,24:100.0
6,-20,24:100.0
7,-20,24:100.0
8,-20,24:100.0
9,-20,24:100.0
10,-20,24:100.0
11,-20,24:100.0
12,-20,24:100.0
13,-20,24:100.0
14,-20,24:100.0
15,-20,24:100.0
16,-20,24:100.0
17,-20,24:159.4
-7,-19,24:159.4
-6,-19,24:100.0
-5,-19,24:100.0
-4,-19,24:100.0
-3,-19,24:100.0
-2,-19,24:100.0
-1,-19,24:100.0
0,-19,24:100.0
1,-19,24:100.0
2,-19,24:100.0
3,-19,24:100.0
4,-19,24:100.0
5,-19,24:100.0
6,-19,24:100.0
7,-19,24:100.0
8,-19,24:100.0
9,-19,24:100.0
10,-19,24:100.0
11,-19,24:100.0
12,-19,24:100.0
13,-19,24:100.0
14,-19,24:100.0
15,-19,24:100.0
16,-19,24:100.0
17,-19,24:100.0
18,-19,24:159.4
19,-19,24:159.4
-7,-18,24:100.0
-6,-18,24:100.0
-4,-18,24:100.0
-3,-18,24:100.0
-2,-18,24:100.0
-1,-18,24:100.0
0,-18,24:100.0
1,-18,24:100.0
2,-18,24:100.0
3,-18,24:100.0
4,-18,24:100.0
5,-18,24:100.0
6,-18,24:100.0
7,-18,24:100.0
8,-18,24:100.0
9,-18,24:100.0
10,-18,24:100.0
11,-18,24:100.0
12,-18,24:100.0
13,-18,24:100.0
14,-18,24:100.0
15,-18,24:100.0
16,-18,24:100.0
17,-18,24:100.0
18,-18,24:100.0
19,-18,24:100.0
20,-18,24:159.4
-8,-17,24:159.4
-7,-17,24:100.0
-6,-17,24:100.0
-5,-17,24:100.0
-4,-17,24:100.0
-3,-17,24:100.0
-2,-17,24:100.0
-1,-17,24:100.0
0,-17,24:100.0
1,-17,24:100.0
2,-17,24:100.0
3,-17,24:100.0
4,-17,24:100.0
5,-17,24:100.0
6,-17,24:100.0
7,-17,24:100.0
8,-17,24:100.0
9,-17,24:100.0
10,-17,24:100.0
11,-17,24:100.0
12,-17,24:100.0
13,-17,24:100.0
14,-17,24:100.0
15,-17,24:100.0
16,-17,24:100.0
17,-17,24:100.0
18,-17,24:100.0
19,-17,24:100.0
20,-17,24:100.0
21,-17,24:159.4
22,-17,24:159.4
-8,-16,24:100.0
-7,-16,24:100.0
-6,-16,24:100.0
-5,-16,24:100.0
-4,-16,24:100.0
-3,-16,24:100.0
0,-16,24:100.0
1,-16,24:100.0
2,-16,24:100.0
3,-16,24:100.0
4,-16,24:100.0
5,-16,24:100.0
6,-16,24:100.0
7,-16,24:100.0
8,-16,24:100.0
9,-16,24:100.0
10,-16,24:100.0
11,-16,24:100.0
12,-16,24:100.0
13,-16,24:100.0
14,-16,24:100.0
15,-16,24:100.0
16,-16,24:100.0
17,-16,24:100.0
18,-16,24:100.0
19,-16,24:100.0
20,-16,24:100.0
21,-16,24:100.0
22,-16,24:100.0
23,-16,24:100.0
24,-16,24:159.4
-9,-15,24:159.4
-8,-15,24:100.0
-7,-15,24:100.0
-6,-15,24:100.0
-5,-15,24:100.0
-4,-15,24:100.0
-2,-15,24:100.0
2,-15,24:100.0
3,-15,24:100.0
4,-15,24:100.0
5,-15,24:100.0
6,-15,24:100.0
7,-15,24:100.0
8,-15,24:100.0
9,-15,24:100.0
10,-15,24:100.0
11,-15,24:100.0
12,-15,24:100.0
13,-15,24:100.0
14,-15,24:100.0
15,-15,24:100.0
16,-15,24:100.0
17,-15,24:100.0
18,-15,24:100.0
19,-15,24:100.0
20,-15,24:100.0
21,-15,24:100.0
22,-15,24:100.0
23,-15,24:100.0
24,-15,24:100.0
25,-15,24:159.4
-9,-14,24:100.0
-8,-14,24:100.0
-7,-14,24:100.0
-6,-14,24:100.0
-5,-14,24:100.0
-4,-14,24:100.0
-1,-14,24:100.0
4,-14,24:100.0
5,-14,24:100.0
6,-14,24:100.0
7,-14,24:100.0
8,-14,24:100.0
9,-14,24:100.0
10,-14,24:100.0
11,-14,24:100.0
12,-14,24:100.0
13,-14,24:100.0
14,-14,24:100.0
15,-14,24:100.0
16,-14,24:100.0
17,-14,24:100.0
18,-14,24:100.0
19,-14,24:100.0
20,-14,24:100.0
21,-14,24:100.0
22,-14,24:100.0
23,-14,24:100.0
24,-14,24:100.0
25,-14,24:100.0
-10,-13,24:159.4
-9,-13,24:100.0
-8,-13,24:100.0
-7,-13,24:100.0
-6,-13,24:100.0
-5,-13,24:100.0
-4,-13,24:100.0
-3,-13,24:100.0
0,-13,24:100.0
7,-13,24:100.0
8,-13,24:100.0
9,-13,24:100.0
10,-13,24:100.0
11,-13,24:100.0
12,-13,24:100.0
13,-13,24:100.0
14,-13,24:100.0
15,-13,24:100.0
16,-13,24:100.0
17,-13,24:100.0
18,-13,24:100.0
19,-13,24:100.0
20,-13,24:100.0
21,-13,24:100.0
22,-13,24:100.0
23,-13,24:100.0
24,-13,24:100.0
25,-13,24:100.0
26,-13,24:100.0
-10,-12,24:100.0
-9,-12,24:100.0
-8,-12,24:100.0
-7,-12,24:100.0
-6,-12,24:100.0
-5,-12,24:100.0
-4,-12,24:100.0
-3,-12,24:100.0
8,-12,24:100.0
9,-12,24:100.0
10,-12,24:100.0
11,-12,24:100.0
12,-12,24:100.0
21,-12,24:100.0
22,-12,24:100.0
23,-12,24:100.0
24,-12,24:100.0
25,-12,24:100.0
26,-12,24:100.0
-11,-11,24:159.4
-10,-11,24:100.0
-9,-11,24:100.0
-8,-11,24:100.0
-7,-11,24:100.0
-6,-11,24:100.0
-5,-11,24:100.0
-4,-11,24:100.0
-3,-11,24:100.0
-2,-11,24:100.0
2,-11,24:100.0
8,-11,24:100.0
23,-11,24:100.0
24,-11,24:100.0
25,-11,24:100.0
26,-11,24:100.0
27,-11,24:159.4
-11,-10,24:100.0
-10,-10,24:100.0
-9,-10,24:100.0
-8,-10,24:100.0
-7,-10,24:100.0
-6,-10,24:100.0
-5,-10,24:100.0
-4,-10,24:100.0
-3,-10,24:100.0
-2,-10,24:100.0
3,-10,24:100.0
8,-10,24:100.0
22,-10,24:100.0
23,-10,24:100.0
24,-10,24:100.0
25,-10,24:100.0
26,-10,24:100.0
27,-10,24:159.4
-12,-9,24:100.0
-11,-9,24:100.0
-10,-9,24:100.0
-9,-9,24:100.0
-8,-9,24:100.0
-7,-9,24:100.0
-6,-9,24:100.0
-5,-9,24:100.0
-4,-9,24:100.0
-3,-9,24:100.0
-2,-9,24:100.0
3,-9,24:100.0
4,-9,24:100.0
8,-9,24:100.0
21,-9,24:100.0
22,-9,24:100.0
23,-9,24:100.0
24,-9,24:100.0
25,-9,24:100.0
26,-9,24:100.0
27,-9,24:159.4
-11,-8,24:100.0
-10,-8,24:100.0
-9,-8,24:100.0
-8,-8,24:100.0
-7,-8,24:100.0
-6,-8,24:100.0
-5,-8,24:100.0
-4,-8,24:100.0
-3,-8,24:100.0
-1,-8,24:100.0
4,-8,24:100.0
5,-8,24:100.0
8,-8,24:100.0
20,-8,24:100.0
21,-8,24:100.0
22,-8,24:100.0
23,-8,24:100.0
24,-8,24:100.0
25,-8,24:100.0
26,-8,24:100.0
27,-8,24:159.4
-12,-7,24:100.0
-11,-7,24:100.0
-10,-7,24:100.0
-9,-7,24:100.0
-8,-7,24:100.0
-7,-7,24:100.0
-5,-7,24:100.0
-4,-7,24:100.0
-3,-7,24:100.0
-2,-7,24:100.0
-1,-7,24:100.0
8,-7,24:159.4
12,-7,24:100.0
19,-7,24:100.0
20,-7,24:100.0
21,-7,24:100.0
22,-7,24:100.0
23,-7,24:100.0
24,-7,24:100.0
25,-7,24:100.0
26,-7,24:100.0
27,-7,24:159.4
28,-7,24:159.4
-12,-6,24:100.0
-11,-6,24:100.0
-10,-6,24:100.0
-9,-6,24:100.0
-8,-6,24:100.0
-7,-6,24:100.0
-6,-6,24:100.0
-5,-6,24:100.0
-4,-6,24:100.0
-3,-6,24:100.0
-2,-6,24:100.0
-1,-6,24:100.0
0,-6,24:100.0
7,-6,24:17.14
8,-6,24:17.14
10,-6,24:100.0
11,-6,24:100.0
18,-6,24:100.0
19,-6,24:100.0
20,-6,24:100.0
21,-6,24:100.0
22,-6,24:100.0
23,-6,24:100.0
24,-6,24:100.0
25,-6,24:100.0
26,-6,24:100.0
27,-6,24:159.4
28,-6,24:159.4
-12,-5,24:159.4
-11,-5,24:100.0
-10,-5,24:100.0
-9,-5,24:100.0
-8,-5,24:100.0
-7,-5,24:100.0
-6,-5,24:100.0
-5,-5,24:100.0
-4,-5,24:100.0
-3,-5,24:100.0
-2,-5,24:100.0
-1,-5,24:100.0
6,-5,24:100.0
7,-5,24:17.14
8,-5,24:17.14
9,-5,24:159.4
10,-5,24:100.0
18,-5,24:100.0
19,-5,24:100.0
20,-5,24:100.0
21,-5,24:100.0
22,-5,24:100.0
23,-5,24:100.0
24,-5,24:100.0
25,-5,24:100.0
26,-5,24:82.0
27,-5,24:159.4
28,-5,24:159.4
-12,-4,24:159.4
-11,-4,24:100.0
-10,-4,24:100.0
-9,-4,24:100.0
-8,-4,24:100.0
-7,-4,24:100.0
-6,-4,24:100.0
-5,-4,24:100.0
-4,-4,24:100.0
-3,-4,24:100.0
-2,-4,24:100.0
-1,-4,24:100.0
5,-4,24:100.0
6,-4,24:100.0
10,-4,24:159.4
11,-4,24:100.0
12,-4,24:100.0
17,-4,24:100.0
18,-4,24:100.0
19,-4,24:100.0
20,-4,24:100.0
21,-4,24:100.0
22,-4,24:100.0
23,-4,24:100.0
24,-4,24:100.0
25,-4,24:100.0
26,-4,24:82.0
27,-4,24:159.4
28,-4,24:159.4
-12,-3,24:159.4
-11,-3,24:100.0
-10,-3,24:100.0
-9,-3,24:100.0
-8,-3,24:100.0
-7,-3,24:100.0
-6,-3,24:100.0
-5,-3,24:100.0
-4,-3,24:100.0
-3,-3,24:100.0
-2,-3,24:100.0
4,-3,24:100.0
13,-3,24:100.0
14,-3,24:100.0
16,-3,24:100.0
17,-3,24:100.0
18,-3,24:100.0
19,-3,24:100.0
20,-3,24:100.0
21,-3,24:100.0
22,-3,24:100.0
23,-3,24:100.0
24,-3,24:100.0
25,-3,24:100.0
26,-3,24:82.0
27,-3,24:159.4
28,-3,24:159.4
-11,-2,24:100.0
-10,-2,24:100.0
-9,-2,24:100.0
-7,-2,24:100.0
-6,-2,24:100.0
-5,-2,24:100.0
-4,-2,24:100.0
-3,-2,24:100.0
10,-2,24:100.0
17,-2,24:100.0
18,-2,24:100.0
19,-2,24:100.0
20,-2,24:100.0
21,-2,24:100.0
22,-2,24:100.0
23,-2,24:100.0
24,-2,24:100.0
25,-2,24:100.0
26,-2,24:159.4
27,-2,24:159.4
28,-2,24:159.4
-11,-1,24:159.4
-10,-1,24:100.0
-9,-1,24:100.0
-8,-1,24:100.0
-7,-1,24:100.0
-6,-1,24:100.0
-5,-1,24:100.0
-4,-1,24:100.0
-3,-1,24:100.0
11,-1,24:100.0
17,-1,24:100.0
18,-1,24:100.0
19,-1,24:100.0
20,-1,24:100.0
21,-1,24:100.0
22,-1,24:100.0
23,-1,24:100.0
24,-1,24:100.0
25,-1,24:100.0
26,-1,24:159.4
27,-1,24:159.4
28,-1,24:159.4
-11,0,24:100.0
-10,0,24:100.0
-9,0,24:100.0
-8,0,24:100.0
-7,0,24:100.0
-6,0,24:100.0
-5,0,24:100.0
-4,0,24:100.0
-2,0,24:100.0
12,0,24:159.4
17,0,24:100.0
18,0,24:100.0
19,0,24:100.0
20,0,24:100.0
21,0,24:100.0
22,0,24:100.0
23,0,24:100.0
24,0,24:100.0
25,0,24:100.0
26,0,24:159.4
27,0,24:159.4
28,0,24:159.4
-11,1,24:159.4
-9,1,24:100.0
-8,1,24:100.0
-7,1,24:100.0
-6,1,24:100.0
-5,1,24:100.0
-4,1,24:100.0
-3,1,24:100.0
-2,1,24:100.0
13,1,24:159.4
18,1,24:100.0
19,1,24:100.0
20,1,24:100.0
21,1,24:100.0
22,1,24:100.0
23,1,24:100.0
24,1,24:100.0
25,1,24:159.4
26,1,24:159.4
27,1,24:159.4
-11,2,24:159.4
-10,2,24:100.0
-8,2,24:100.0
-7,2,24:100.0
-6,2,24:100.0
-5,2,24:100.0
13,2,24:100.0
14,2,24:159.4
18,2,24:100.0
19,2,24:100.0
20,2,24:100.0
21,2,24:100.0
22,2,24:100.0
23,2,24:159.4
24,2,24:159.4
25,2,24:159.4
26,2,24:159.4
27,2,24:159.4
-11,3,24:159.4
-10,3,24:100.0
-9,3,24:100.0
-8,3,24:100.0
-7,3,24:100.0
14,3,24:100.0
15,3,24:159.4
18,3,24:100.0
19,3,24:100.0
20,3,24:100.0
21,3,24:100.0
22,3,24:100.0
23,3,24:100.0
24,3,24:100.0
25,3,24:159.4
26,3,24:159.4
-10,4,24:100.0
4,4,24:100.0
5,4,24:100.0
6,4,24:100.0
7,4,24:100.0
8,4,24:100.0
15,4,24:159.4
16,4,24:159.4
19,4,24:100.0
20,4,24:100.0
21,4,24:100.0
22,4,24:100.0
23,4,24:100.0
24,4,24:100.0
25,4,24:159.4
26,4,24:159.4
-10,5,24:159.4
-8,5,24:100.0
-7,5,24:100.0
-1,5,24:100.0
0,5,24:100.0
1,5,24:100.0
2,5,24:100.0
3,5,24:100.0
4,5,24:100.0
5,5,24:100.0
6,5,24:100.0
7,5,24:100.0
8,5,24:100.0
9,5,24:100.0
10,5,24:100.0
16,5,24:159.4
17,5,24:159.4
19,5,24:100.0
20,5,24:100.0
21,5,24:100.0
22,5,24:100.0
23,5,24:100.0
24,5,24:100.0
25,5,24:159.4
-10,6,24:159.4
-6,6,24:100.0
-5,6,24:100.0
-4,6,24:100.0
-3,6,24:100.0
-2,6,24:100.0
-1,6,24:100.0
0,6,24:100.0
1,6,24:100.0
2,6,24:100.0
3,6,24:100.0
4,6,24:100.0
5,6,24:100.0
6,6,24:100.0
7,6,24:100.0
8,6,24:100.0
9,6,24:100.0
10,6,24:100.0
11,6,24:100.0
12,6,24:100.0
17,6,24:100.0
18,6,24:100.0
19,6,24:100.0
20,6,24:100.0
21,6,24:100.0
22,6,24:100.0
23,6,24:100.0
24,6,24:100.0
25,6,24:159.4
-10,7,24:159.4
-9,7,24:100.0
-7,7,24:100.0
-6,7,24:100.0
-5,7,24:100.0
-4,7,24:100.0
-3,7,24:100.0
-2,7,24:100.0
-1,7,24:100.0
0,7,24:100.0
1,7,24:100.0
2,7,24:100.0
3,7,24:100.0
4,7,24:100.0
5,7,24:100.0
6,7,24:100.0
7,7,24:100.0
8,7,24:100.0
9,7,24:100.0
10,7,24:100.0
11,7,24:100.0
12,7,24:100.0
13,7,24:100.0
14,7,24:100.0
15,7,24:100.0
18,7,24:100.0
19,7,24:100.0
20,7,24:100.0
21,7,24:100.0
22,7,24:100.0
23,7,24:100.0
24,7,24:159.4
-9,8,24:159.4
-8,8,24:100.0
-7,8,24:100.0
-6,8,24:100.0
-5,8,24:100.0
-4,8,24:100.0
-3,8,24:100.0
-2,8,24:100.0
-1,8,24:100.0
0,8,24:100.0
1,8,24:100.0
2,8,24:100.0
3,8,24:100.0
4,8,24:100.0
5,8,24:100.0
6,8,24:100.0
7,8,24:100.0
8,8,24:100.0
9,8,24:100.0
10,8,24:100.0
11,8,24:100.0
12,8,24:100.0
13,8,24:100.0
14,8,24:100.0
15,8,24:100.0
16,8,24:100.0
17,8,24:100.0
19,8,24:100.0
20,8,24:100.0
21,8,24:100.0
22,8,24:100.0
23,8,24:100.0
24,8,24:159.4
-8,9,24:159.4
-7,9,24:159.4
-6,9,24:100.0
-5,9,24:100.0
-4,9,24:100.0
-3,9,24:100.0
-2,9,24:100.0
-1,9,24:100.0
0,9,24:100.0
1,9,24:100.0
2,9,24:100.0
3,9,24:100.0
4,9,24:100.0
5,9,24:100.0
6,9,24:100.0
7,9,24:100.0
8,9,24:100.0
9,9,24:100.0
10,9,24:100.0
11,9,24:100.0
12,9,24:100.0
13,9,24:100.0
14,9,24:100.0
15,9,24:100.0
16,9,24:100.0
17,9,24:100.0
18,9,24:100.0
19,9,24:100.0
20,9,24:100.0
21,9,24:100.0
22,9,24:100.0
23,9,24:100.0
-6,10,24:159.4
-5,10,24:159.4
-4,10,24:100.0
-3,10,24:100.0
-2,10,24:100.0
-1,10,24:100.0
0,10,24:100.0
1,10,24:100.0
2,10,24:100.0
3,10,24:100.0
4,10,24:100.0
5,10,24:100.0
6,10,24:100.0
7,10,24:100.0
8,10,24:100.0
9,10,24:100.0
10,10,24:100.0
11,10,24:100.0
12,10,24:100.0
13,10,24:100.0
14,10,24:100.0
15,10,24:100.0
16,10,24:100.0
17,10,24:100.0
18,10,24:100.0
19,10,24:100.0
20,10,24:100.0
21,10,24:100.0
22,10,24:100.0
23,10,24:159.4
-3,11,24:159.4
-2,11,24:100.0
-1,11,24:100.0
0,11,24:100.0
1,11,24:100.0
2,11,24:100.0
3,11,24:100.0
4,11,24:100.0
5,11,24:100.0
6,11,24:100.0
7,11,24:100.0
8,11,24:100.0
9,11,24:100.0
10,11,24:100.0
11,11,24:100.0
12,11,24:100.0
13,11,24:100.0
14,11,24:100.0
15,11,24:100.0
16,11,24:100.0
17,11,24:100.0
18,11,24:100.0
19,11,24:100.0
20,11,24:100.0
21,11,24:100.0
22,11,24:159.4
-2,12,24:159.4
-1,12,24:100.0
0,12,24:100.0
1,12,24:100.0
2,12,24:100.0
3,12,24:100.0
4,12,24:100.0
5,12,24:100.0
6,12,24:100.0
7,12,24:100.0
8,12,24:100.0
9,12,24:100.0
10,12,24:100.0
11,12,24:100.0
12,12,24:100.0
13,12,24:100.0
14,12,24:100.0
15,12,24:100.0
16,12,24:100.0
17,12,24:100.0
18,12,24:100.0
19,12,24:100.0
20,12,24:159.4
21,12,24:159.4
0,13,24:159.4
1,13,24:100.0
2,13,24:100.0
3,13,24:100.0
4,13,24:100.0
5,13,24:100.0
6,13,24:100.0
7,13,24:100.0
8,13,24:100.0
9,13,24:100.0
10,13,24:100.0
11,13,24:100.0
12,13,24:100.0
13,13,24:100.0
14,13,24:100.0
15,13,24:100.0
16,13,24:159.4
17,13,24:159.4
18,13,24:159.4
2,14,24:159.4
3,14,24:100.0
4,14,24:100.0
5,14,24:100.0
6,14,24:100.0
7,14,24:100.0
8,14,24:100.0
9,14,24:100.0
10,14,24:100.0
11,14,24:100.0
12,14,24:159.4
13,14,24:159.4
14,14,24:100.0
15,14,24:159.4
4,15,24:100.0
5,15,24:100.0
6,15,24:100.0
7,15,24:100.0
5,-22,25:159.4
6,-22,25:159.4
7,-22,25:159.4
9,-22,25:159.4
-1,-21,25:159.4
0,-21,25:159.4
1,-21,25:159.4
2,-21,25:159.4
3,-21,25:159.4
4,-21,25:159.4
5,-21,25:159.4
6,-21,25:159.4
7,-21,25:159.4
8,-21,25:159.4
9,-21,25:159.4
10,-21,25:159.4
11,-21,25:159.4
12,-21,25:159.4
13,-21,25:159.4
15,-21,25:159.4
-5,-20,25:159.4
-4,-20,25:159.4
-3,-20,25:159.4
-2,-20,25:159.4
-1,-20,25:159.4
0,-20,25:159.4
1,-20,25:159.4
2,-20,25:159.4
3,-20,25:159.4
4,-20,25:159.4
5,-20,25:159.4
6,-20,25:159.4
7,-20,25:159.4
8,-20,25:159.4
9,-20,25:159.4
10,-20,25:159.4
11,-20,25:159.4
12,-20,25:159.4
13,-20,25:159.4
14,-20,25:159.4
15,-20,25:159.4
16,-20,25:159.4
-6,-19,25:159.4
-5,-19,25:159.4
-4,-19,25:159.4
-3,-19,25:159.4
-2,-19,25:159.4
-1,-19,25:159.4
0,-19,25:82.0
1,-19,25:82.0
2,-19,25:82.0
3,-19,25:159.4
4,-19,25:159.4
5,-19,25:159.4
6,-19,25:159.4
7,-19,25:159.4
8,-19,25:159.4
9,-19,25:159.4
10,-19,25:159.4
11,-19,25:159.4
12,-19,25:82.0
13,-19,25:82.0
14,-19,25:82.0
15,-19,25:159.4
16,-19,25:159.4
17,-19,25:159.4
-7,-18,25:159.4
-6,-18,25:159.4
-5,-18,25:100.0
-4,-18,25:159.4
-3,-18,25:159.4
-2,-18,25:159.4
-1,-18,25:82.0
0,-18,25:82.0
1,-18,25:82.0
2,-18,25:82.0
3,-18,25:82.0
4,-18,25:159.4
5,-18,25:159.4
6,-18,25:159.4
7,-18,25:159.4
8,-18,25:159.4
9,-18,25:159.4
10,-18,25:159.4
11,-18,25:82.0
12,-18,25:82.0
13,-18,25:82.0
14,-18,25:82.0
15,-18,25:82.0
16,-18,25:159.4
17,-18,25:159.4
18,-18,25:159.4
19,-18,25:159.4
20,-18,25:159.4
-7,-17,25:159.4
-6,-17,25:159.4
-5,-17,25:159.4
-4,-17,25:159.4
-3,-17,25:159.4
-2,-17,25:159.4
-1,-17,25:82.0
0,-17,25:82.0
1,-17,25:82.0
2,-17,25:82.0
3,-17,25:82.0
4,-17,25:159.4
5,-17,25:159.4
6,-17,25:159.4
7,-17,25:159.4
8,-17,25:159.4
9,-17,25:159.4
10,-17,25:159.4
11,-17,25:82.0
12,-17,25:82.0
13,-17,25:82.0
14,-17,25:82.0
15,-17,25:82.0
16,-17,25:159.4
17,-17,25:159.4
18,-17,25:159.4
19,-17,25:159.4
20,-17,25:159.4
21,-17,25:159.4
-8,-16,25:159.4
-7,-16,25:159.4
-6,-16,25:159.4
-5,-16,25:159.4
-4,-16,25:159.4
-3,-16,25:159.4
-2,-16,25:100.0
0,-16,25:82.0
1,-16,25:82.0
2,-16,25:82.0
3,-16,25:82.0
4,-16,25:159.4
5,-16,25:159.4
6,-16,25:159.4
7,-16,25:159.4
8,-16,25:159.4
9,-16,25:159.4
10,-16,25:159.4
11,-16,25:82.0
12,-16,25:82.0
13,-16,25:82.0
14,-16,25:82.0
15,-16,25:82.0
16,-16,25:159.4
17,-16,25:159.4
18,-16,25:159.4
19,-16,25:159.4
20,-16,25:159.4
21,-16,25:159.4
22,-16,25:159.4
23,-16,25:159.4
-8,-15,25:159.4
-7,-15,25:159.4
-6,-15,25:159.4
-5,-15,25:159.4
-4,-15,25:159.4
-3,-15,25:100.0
-2,-15,25:159.4
2,-15,25:82.0
3,-15,25:159.4
4,-15,25:159.4
5,-15,25:159.4
6,-15,25:159.4
7,-15,25:159.4
8,-15,25:159.4
9,-15,25:159.4
10,-15,25:159.4
11,-15,25:159.4
12,-15,25:82.0
13,-15,25:82.0
14,-15,25:82.0
15,-15,25:159.4
16,-15,25:159.4
17,-15,25:159.4
18,-15,25:159.4
19,-15,25:159.4
20,-15,25:159.4
21,-15,25:159.4
22,-15,25:159.4
23,-15,25:159.4
24,-15,25:159.4
-9,-14,25:159.4
-8,-14,25:159.4
-7,-14,25:159.4
-6,-14,25:159.4
-5,-14,25:159.4
-4,-14,25:159.4
-3,-14,25:100.0
-2,-14,25:100.0
-1,-14,25:159.4
0,-14,25:100.0
1,-14,25:100.0
2,-14,25:100.0
3,-14,25:100.0
4,-14,25:159.4
5,-14,25:159.4
6,-14,25:159.4
7,-14,25:159.4
8,-14,25:159.4
9,-14,25:159.4
10,-14,25:159.4
11,-14,25:159.4
12,-14,25:159.4
13,-14,25:159.4
14,-14,25:159.4
15,-14,25:159.4
16,-14,25:159.4
17,-14,25:159.4
18,-14,25:159.4
19,-14,25:159.4
20,-14,25:159.4
21,-14,25:159.4
22,-14,25:159.4
23,-14,25:159.4
24,-14,25:159.4
25,-14,25:159.4
-9,-13,25:159.4
-8,-13,25:159.4
-7,-13,25:159.4
-6,-13,25:82.0
-5,-13,25:82.0
-4,-13,25:82.0
-3,-13,25:159.4
-2,-13,25:100.0
-1,-13,25:100.0
0,-13,25:159.4
1,-13,25:100.0
2,-13,25:100.0
3,-13,25:100.0
4,-13,25:100.0
5,-13,25:100.0
6,-13,25:100.0
7,-13,25:159.4
8,-13,25:159.4
9,-13,25:159.4
10,-13,25:159.4
11,-13,25:159.4
12,-13,25:159.4
13,-13,25:159.4
14,-13,25:159.4
15,-13,25:159.4
16,-13,25:159.4
17,-13,25:159.4
18,-13,25:159.4
19,-13,25:159.4
20,-13,25:159.4
21,-13,25:159.4
22,-13,25:159.4
23,-13,25:159.4
24,-13,25:159.4
25,-13,25:159.4
26,-13,25:159.4
-10,-12,25:159.4
-9,-12,25:159.4
-8,-12,25:159.4
-7,-12,25:82.0
-6,-12,25:82.0
-5,-12,25:82.0
-4,-12,25:82.0
-3,-12,25:82.0
-2,-12,25:100.0
-1,-12,25:100.0
0,-12,25:100.0
1,-12,25:100.0
2,-12,25:100.0
3,-12,25:100.0
4,-12,25:100.0
5,-12,25:100.0
6,-12,25:100.0
7,-12,25:100.0
8,-12,25:159.4
9,-12,25:159.4
10,-12,25:159.4
11,-12,25:159.4
12,-12,25:159.4
13,-12,25:100.0
14,-12,25:100.0
15,-12,25:100.0
21,-12,25:159.4
22,-12,25:159.4
23,-12,25:159.4
24,-12,25:159.4
25,-12,25:159.4
26,-12,25:159.4
-10,-11,25:159.4
-9,-11,25:159.4
-8,-11,25:159.4
-7,-11,25:82.0
-6,-11,25:82.0
-5,-11,25:82.0
-4,-11,25:82.0
-3,-11,25:82.0
-2,-11,25:159.4
-1,-11,25:100.0
0,-11,25:100.0
1,-11,25:100.0
2,-11,25:159.4
3,-11,25:100.0
4,-11,25:100.0
5,-11,25:100.0
6,-11,25:100.0
7,-11,25:100.0
8,-11,25:159.4
9,-11,25:100.0
10,-11,25:100.0
11,-11,25:100.0
12,-11,25:100.0
13,-11,25:100.0
14,-11,25:100.0
15,-11,25:100.0
16,-11,25:100.0
17,-11,25:100.0
23,-11,25:159.4
24,-11,25:159.4
25,-11,25:159.4
26,-11,25:159.4
-10,-10,25:159.4
-9,-10,25:159.4
-8,-10,25:159.4
-7,-10,25:82.0
-6,-10,25:82.0
-5,-10,25:82.0
-4,-10,25:82.0
-3,-10,25:82.0
-2,-10,25:159.4
-1,-10,25:100.0
0,-10,25:100.0
1,-10,25:100.0
2,-10,25:100.0
3,-10,25:159.4
4,-10,25:100.0
5,-10,25:100.0
6,-10,25:100.0
7,-10,25:100.0
8,-10,25:159.4
9,-10,25:100.0
10,-10,25:100.0
11,-10,25:100.0
12,-10,25:100.0
13,-10,25:100.0
14,-10,25:100.0
15,-10,25:100.0
16,-10,25:100.0
17,-10,25:100.0
18,-10,25:100.0
19,-10,25:100.0
22,-10,25:159.4
23,-10,25:159.4
24,-10,25:159.4
25,-10,25:159.4
26,-10,25:159.4
-11,-9,25:159.4
-10,-9,25:159.4
-9,-9,25:159.4
-8,-9,25:159.4
-7,-9,25:159.4
-6,-9,25:82.0
-5,-9,25:82.0
-4,-9,25:82.0
-3,-9,25:159.4
-2,-9,25:159.4
-1,-9,25:100.0
0,-9,25:100.0
1,-9,25:100.0
2,-9,25:100.0
3,-9,25:159.4
4,-9,25:159.4
5,-9,25:100.0
6,-9,25:100.0
7,-9,25:100.0
8,-9,25:159.4
9,-9,25:100.0
10,-9,25:100.0
11,-9,25:100.0
12,-9,25:100.0
13,-9,25:100.0
14,-9,25:100.0
15,-9,25:100.0
16,-9,25:100.0
17,-9,25:100.0
18,-9,25:100.0
19,-9,25:100.0
21,-9,25:159.4
22,-9,25:159.4
23,-9,25:159.4
24,-9,25:159.4
25,-9,25:159.4
26,-9,25:159.4
-11,-8,25:159.4
-10,-8,25:159.4
-9,-8,25:159.4
-8,-8,25:159.4
-7,-8,25:159.4
-6,-8,25:159.4
-5,-8,25:159.4
-4,-8,25:159.4
-3,-8,25:159.4
-1,-8,25:159.4
0,-8,25:100.0
1,-8,25:100.0
2,-8,25:100.0
3,-8,25:100.0
4,-8,25:159.4
5,-8,25:159.4
6,-8,25:100.0
7,-8,25:100.0
8,-8,25:159.4
9,-8,25:100.0
10,-8,25:100.0
11,-8,25:100.0
12,-8,25:100.0
13,-8,25:100.0
14,-8,25:100.0
15,-8,25:100.0
16,-8,25:100.0
17,-8,25:100.0
18,-8,25:100.0
19,-8,25:100.0
20,-8,25:159.4
21,-8,25:159.4
22,-8,25:159.4
23,-8,25:159.4
24,-8,25:159.4
25,-8,25:159.4
26,-8,25:159.4
-11,-7,25:159.4
-10,-7,25:159.4
-9,-7,25:159.4
-8,-7,25:159.4
-7,-7,25:159.4
-6,-7,25:100.0
-5,-7,25:159.4
-4,-7,25:159.4
-3,-7,25:159.4
-2,-7,25:159.4
-1,-7,25:159.4
0,-7,25:100.0
1,-7,25:100.0
2,-7,25:100.0
3,-7,25:100.0
4,-7,25:100.0
5,-7,25:100.0
6,-7,25:100.0
7,-7,25:100.0
8,-7,25:17.14
9,-7,25:100.0
10,-7,25:100.0
11,-7,25:100.0
12,-7,25:159.4
13,-7,25:100.0
14,-7,25:100.0
15,-7,25:100.0
16,-7,25:100.0
17,-7,25:100.0
18,-7,25:100.0
19,-7,25:159.4
20,-7,25:159.4
21,-7,25:159.4
22,-7,25:159.4
23,-7,25:159.4
24,-7,25:159.4
25,-7,25:159.4
26,-7,25:159.4
-11,-6,25:159.4
-10,-6,25:159.4
-9,-6,25:159.4
-8,-6,25:159.4
-7,-6,25:159.4
-6,-6,25:159.4
-5,-6,25:159.4
-4,-6,25:159.4
-3,-6,25:159.4
-2,-6,25:159.4
-1,-6,25:159.4
0,-6,25:159.4
1,-6,25:100.0
2,-6,25:100.0
3,-6,25:100.0
4,-6,25:100.0
5,-6,25:100.0
6,-6,25:100.0
7,-6,25:100.0
8,-6,25:17.14
9,-6,25:17.14
10,-6,25:159.4
11,-6,25:159.4
12,-6,25:100.0
13,-6,25:100.0
14,-6,25:100.0
15,-6,25:100.0
16,-6,25:100.0
17,-6,25:100.0
18,-6,25:159.4
19,-6,25:159.4
20,-6,25:159.4
21,-6,25:159.4
22,-6,25:159.4
23,-6,25:82.0
24,-6,25:82.0
25,-6,25:82.0
26,-6,25:159.4
27,-6,25:159.4
-11,-5,25:159.4
-10,-5,25:159.4
-9,-5,25:159.4
-8,-5,25:159.4
-7,-5,25:159.4
-6,-5,25:159.4
-5,-5,25:159.4
-4,-5,25:159.4
-3,-5,25:159.4
-2,-5,25:159.4
-1,-5,25:159.4
0,-5,25:100.0
1,-5,25:100.0
2,-5,25:100.0
3,-5,25:100.0
4,-5,25:100.0
5,-5,25:100.0
6,-5,25:159.4
7,-5,25:159.4
8,-5,25:17.14
9,-5,25:159.4
10,-5,25:159.4
11,-5,25:100.0
12,-5,25:100.0
13,-5,25:100.0
14,-5,25:100.0
15,-5,25:100.0
16,-5,25:100.0
17,-5,25:100.0
18,-5,25:159.4
19,-5,25:159.4
20,-5,25:159.4
21,-5,25:159.4
22,-5,25:82.0
23,-5,25:82.0
24,-5,25:82.0
25,-5,25:82.0
26,-5,25:82.0
27,-5,25:159.4
-11,-4,25:159.4
-10,-4,25:159.4
-9,-4,25:159.4
-8,-4,25:159.4
-7,-4,25:159.4
-6,-4,25:159.4
-5,-4,25:159.4
-4,-4,25:159.4
-3,-4,25:159.4
-2,-4,25:159.4
-1,-4,25:159.4
0,-4,25:100.0
1,-4,25:100.0
2,-4,25:100.0
3,-4,25:100.0
4,-4,25:100.0
5,-4,25:159.4
6,-4,25:159.4
7,-4,25:100.0
8,-4,25:100.0
9,-4,25:100.0
10,-4,25:100.0
11,-4,25:159.4
12,-4,25:159.4
13,-4,25:100.0
14,-4,25:100.0
15,-4,25:100.0
16,-4,25:100.0
17,-4,25:159.4
18,-4,25:159.4
19,-4,25:159.4
20,-4,25:159.4
21,-4,25:159.4
22,-4,25:82.0
23,-4,25:82.0
24,-4,25:82.0
25,-4,25:82.0
26,-4,25:82.0
27,-4,25:159.4
-11,-3,25:159.4
-10,-3,25:159.4
-9,-3,25:159.4
-8,-3,25:159.4
-7,-3,25:159.4
-6,-3,25:159.4
-5,-3,25:159.4
-4,-3,25:159.4
-3,-3,25:159.4
-2,-3,25:159.4
-1,-3,25:100.0
0,-3,25:100.0
1,-3,25:100.0
2,-3,25:100.0
3,-3,25:100.0
4,-3,25:159.4
5,-3,25:100.0
6,-3,25:100.0
7,-3,25:100.0
8,-3,25:100.0
9,-3,25:100.0
10,-3,25:100.0
11,-3,25:100.0
12,-3,25:100.0
13,-3,25:159.4
14,-3,25:159.4
15,-3,25:100.0
16,-3,25:159.4
17,-3,25:159.4
18,-3,25:159.4
19,-3,25:159.4
20,-3,25:159.4
21,-3,25:159.4
22,-3,25:82.0
23,-3,25:82.0
24,-3,25:82.0
25,-3,25:82.0
26,-3,25:82.0
-11,-2,25:159.4
-10,-2,25:159.4
-9,-2,25:159.4
-8,-2,25:100.0
-7,-2,25:82.0
-6,-2,25:82.0
-5,-2,25:159.4
-4,-2,25:159.4
-3,-2,25:159.4
-2,-2,25:100.0
-1,-2,25:100.0
0,-2,25:100.0
1,-2,25:100.0
2,-2,25:100.0
3,-2,25:100.0
4,-2,25:100.0
5,-2,25:100.0
6,-2,25:100.0
7,-2,25:100.0
8,-2,25:100.0
9,-2,25:100.0
10,-2,25:159.4
11,-2,25:100.0
12,-2,25:100.0
13,-2,25:100.0
14,-2,25:100.0
15,-2,25:100.0
16,-2,25:100.0
17,-2,25:159.4
18,-2,25:159.4
19,-2,25:159.4
20,-2,25:159.4
21,-2,25:159.4
22,-2,25:159.4
23,-2,25:82.0
24,-2,25:82.0
25,-2,25:82.0
26,-2,25:159.4
-11,-1,25:159.4
-10,-1,25:159.4
-9,-1,25:82.0
-8,-1,25:82.0
-7,-1,25:82.0
-6,-1,25:82.0
-5,-1,25:82.0
-4,-1,25:159.4
-3,-1,25:159.4
-2,-1,25:100.0
-1,-1,25:100.0
0,-1,25:100.0
1,-1,25:100.0
2,-1,25:100.0
3,-1,25:100.0
4,-1,25:100.0
5,-1,25:100.0
6,-1,25:100.0
7,-1,25:100.0
8,-1,25:100.0
9,-1,25:100.0
10,-1,25:100.0
11,-1,25:159.4
12,-1,25:100.0
13,-1,25:100.0
14,-1,25:100.0
15,-1,25:100.0
16,-1,25:100.0
17,-1,25:159.4
18,-1,25:159.4
19,-1,25:159.4
20,-1,25:159.4
21,-1,25:159.4
22,-1,25:159.4
23,-1,25:159.4
24,-1,25:159.4
25,-1,25:159.4
-10,0,25:159.4
-9,0,25:82.0
-8,0,25:82.0
-7,0,25:82.0
-6,0,25:82.0
-5,0,25:82.0
-4,0,25:159.4
-3,0,25:100.0
-2,0,25:159.4
-1,0,25:100.0
0,0,25:100.0
1,0,25:100.0
2,0,25:100.0
3,0,25:100.0
4,0,25:100.0
5,0,25:100.0
6,0,25:100.0
7,0,25:100.0
8,0,25:100.0
9,0,25:100.0
10,0,25:100.0
11,0,25:100.0
12,0,25:159.4
13,0,25:100.0
14,0,25:100.0
15,0,25:100.0
16,0,25:100.0
17,0,25:159.4
18,0,25:159.4
19,0,25:159.4
20,0,25:159.4
21,0,25:159.4
22,0,25:159.4
23,0,25:159.4
24,0,25:159.4
25,0,25:159.4
26,0,25:159.4
-10,1,25:159.4
-9,1,25:82.0
-8,1,25:82.0
-7,1,25:82.0
-6,1,25:82.0
-5,1,25:82.0
-4,1,25:159.4
-3,1,25:159.4
-2,1,25:159.4
-1,1,25:100.0
0,1,25:100.0
1,1,25:100.0
2,1,25:100.0
3,1,25:100.0
4,1,25:100.0
5,1,25:100.0
6,1,25:100.0
7,1,25:100.0
8,1,25:100.0
9,1,25:100.0
10,1,25:100.0
11,1,25:100.0
12,1,25:100.0
13,1,25:159.4
14,1,25:100.0
15,1,25:100.0
16,1,25:100.0
17,1,25:100.0
18,1,25:159.4
19,1,25:159.4
20,1,25:159.4
21,1,25:159.4
22,1,25:159.4
23,1,25:159.4
24,1,25:159.4
25,1,25:159.4
26,1,25:159.4
-10,2,25:159.4
-9,2,25:159.4
-8,2,25:82.0
-7,2,25:82.0
-6,2,25:82.0
-5,2,25:159.4
-4,2,25:100.0
-3,2,25:100.0
-2,2,25:100.0
-1,2,25:100.0
0,2,25:100.0
1,2,25:100.0
2,2,25:100.0
3,2,25:100.0
4,2,25:100.0
5,2,25:100.0
6,2,25:100.0
7,2,25:100.0
8,2,25:100.0
9,2,25:100.0
10,2,25:100.0
11,2,25:100.0
12,2,25:100.0
13,2,25:159.4
14,2,25:159.4
15,2,25:100.0
16,2,25:100.0
17,2,25:100.0
18,2,25:159.4
19,2,25:159.4
20,2,25:159.4
21,2,25:159.4
22,2,25:159.4
23,2,25:159.4
24,2,25:159.4
25,2,25:159.4
26,2,25:159.4
-10,3,25:159.4
-9,3,25:159.4
-8,3,25:159.4
-7,3,25:159.4
-6,3,25:100.0
-5,3,25:100.0
-4,3,25:100.0
-3,3,25:100.0
-2,3,25:100.0
-1,3,25:100.0
0,3,25:100.0
1,3,25:100.0
2,3,25:100.0
3,3,25:100.0
4,3,25:100.0
5,3,25:100.0
6,3,25:100.0
7,3,25:100.0
8,3,25:100.0
9,3,25:100.0
10,3,25:100.0
11,3,25:100.0
12,3,25:100.0
13,3,25:100.0
14,3,25:159.4
15,3,25:159.4
16,3,25:100.0
17,3,25:100.0
18,3,25:159.4
19,3,25:159.4
20,3,25:159.4
21,3,25:159.4
22,3,25:159.4
23,3,25:159.4
24,3,25:159.4
25,3,25:159.4
26,3,25:159.4
-10,4,25:159.4
-9,4,25:100.0
-8,4,25:100.0
-7,4,25:100.0
-6,4,25:100.0
-5,4,25:100.0
-4,4,25:100.0
-3,4,25:100.0
-2,4,25:100.0
-1,4,25:100.0
0,4,25:100.0
1,4,25:100.0
2,4,25:100.0
3,4,25:100.0
4,4,25:159.4
5,4,25:159.4
6,4,25:159.4
7,4,25:159.4
8,4,25:159.4
9,4,25:100.0
10,4,25:100.0
11,4,25:100.0
12,4,25:100.0
13,4,25:100.0
14,4,25:100.0
15,4,25:159.4
16,4,25:159.4
17,4,25:100.0
18,4,25:100.0
19,4,25:159.4
20,4,25:159.4
21,4,25:159.4
22,4,25:159.4
23,4,25:159.4
24,4,25:159.4
25,4,25:159.4
-10,5,25:159.4
-9,5,25:100.0
-8,5,25:159.4
-7,5,25:159.4
-6,5,25:100.0
-5,5,25:100.0
-4,5,25:100.0
-3,5,25:100.0
-2,5,25:100.0
-1,5,25:159.4
0,5,25:159.4
1,5,25:159.4
2,5,25:159.4
3,5,25:82.0
4,5,25:82.0
5,5,25:82.0
6,5,25:159.4
7,5,25:159.4
8,5,25:159.4
9,5,25:159.4
10,5,25:159.4
11,5,25:100.0
12,5,25:100.0
13,5,25:100.0
14,5,25:100.0
15,5,25:100.0
16,5,25:159.4
17,5,25:159.4
18,5,25:100.0
19,5,25:159.4
20,5,25:159.4
21,5,25:159.4
22,5,25:159.4
23,5,25:159.4
24,5,25:159.4
25,5,25:159.4
-9,6,25:100.0
-8,6,25:100.0
-7,6,25:100.0
-6,6,25:159.4
-5,6,25:159.4
-4,6,25:159.4
-3,6,25:159.4
-2,6,25:159.4
-1,6,25:159.4
0,6,25:159.4
1,6,25:159.4
2,6,25:159.4
3,6,25:82.0
4,6,25:82.0
5,6,25:82.0
6,6,25:159.4
7,6,25:159.4
8,6,25:159.4
9,6,25:159.4
10,6,25:159.4
11,6,25:159.4
12,6,25:159.4
13,6,25:100.0
14,6,25:100.0
15,6,25:100.0
16,6,25:100.0
17,6,25:159.4
18,6,25:159.4
19,6,25:159.4
20,6,25:159.4
21,6,25:159.4
22,6,25:82.0
23,6,25:159.4
24,6,25:159.4
-9,7,25:159.4
-8,7,25:100.0
-7,7,25:159.4
-6,7,25:159.4
-5,7,25:159.4
-4,7,25:159.4
-3,7,25:159.4
-2,7,25:159.4
-1,7,25:159.4
0,7,25:159.4
1,7,25:159.4
2,7,25:159.4
3,7,25:82.0
4,7,25:82.0
5,7,25:82.0
6,7,25:159.4
7,7,25:159.4
8,7,25:159.4
9,7,25:159.4
10,7,25:159.4
11,7,25:159.4
12,7,25:159.4
13,7,25:159.4
14,7,25:159.4
15,7,25:159.4
16,7,25:100.0
17,7,25:100.0
18,7,25:159.4
19,7,25:159.4
20,7,25:159.4
21,7,25:82.0
22,7,25:82.0
23,7,25:82.0
24,7,25:159.4
-9,8,25:159.4
-8,8,25:159.4
-7,8,25:159.4
-6,8,25:159.4
-5,8,25:159.4
-4,8,25:159.4
-3,8,25:159.4
-2,8,25:159.4
-1,8,25:159.4
0,8,25:159.4
1,8,25:159.4
2,8,25:159.4
3,8,25:159.4
4,8,25:159.4
5,8,25:159.4
6,8,25:159.4
7,8,25:159.4
8,8,25:159.4
9,8,25:159.4
10,8,25:159.4
11,8,25:159.4
12,8,25:159.4
13,8,25:159.4
14,8,25:159.4
15,8,25:159.4
16,8,25:159.4
17,8,25:159.4
18,8,25:100.0
19,8,25:159.4
20,8,25:159.4
21,8,25:159.4
22,8,25:82.0
23,8,25:159.4
-7,9,25:159.4
-6,9,25:159.4
-5,9,25:159.4
-4,9,25:159.4
-3,9,25:159.4
-2,9,25:82.0
-1,9,25:82.0
0,9,25:82.0
1,9,25:159.4
2,9,25:159.4
3,9,25:159.4
4,9,25:159.4
5,9,25:159.4
6,9,25:159.4
7,9,25:159.4
8,9,25:159.4
9,9,25:159.4
10,9,25:82.0
11,9,25:159.4
12,9,25:159.4
13,9,25:159.4
14,9,25:159.4
15,9,25:159.4
16,9,25:159.4
17,9,25:159.4
18,9,25:159.4
19,9,25:159.4
20,9,25:159.4
21,9,25:159.4
22,9,25:159.4
23,9,25:159.4
-5,10,25:159.4
-4,10,25:159.4
-3,10,25:159.4
-2,10,25:82.0
-1,10,25:82.0
0,10,25:82.0
1,10,25:159.4
2,10,25:159.4
3,10,25:159.4
4,10,25:159.4
5,10,25:159.4
6,10,25:159.4
7,10,25:159.4
8,10,25:159.4
9,10,25:82.0
10,10,25:82.0
11,10,25:82.0
12,10,25:159.4
13,10,25:159.4
14,10,25:159.4
15,10,25:159.4
16,10,25:82.0
17,10,25:82.0
18,10,25:82.0
19,10,25:159.4
20,10,25:159.4
21,10,25:159.4
22,10,25:159.4
-3,11,25:159.4
-2,11,25:82.0
-1,11,25:82.0
0,11,25:82.0
1,11,25:159.4
2,11,25:159.4
3,11,25:82.0
4,11,25:82.0
5,11,25:82.0
6,11,25:159.4
7,11,25:159.4
8,11,25:159.4
9,11,25:159.4
10,11,25:82.0
11,11,25:159.4
12,11,25:159.4
13,11,25:159.4
14,11,25:159.4
15,11,25:159.4
16,11,25:82.0
17,11,25:82.0
18,11,25:82.0
19,11,25:159.4
20,11,25:159.4
21,11,25:159.4
-1,12,25:159.4
0,12,25:159.4
1,12,25:159.4
2,12,25:159.4
3,12,25:82.0
4,12,25:82.0
5,12,25:82.0
6,12,25:159.4
7,12,25:159.4
8,12,25:159.4
9,12,25:159.4
10,12,25:159.4
11,12,25:159.4
12,12,25:159.4
13,12,25:159.4
14,12,25:159.4
15,12,25:159.4
16,12,25:82.0
17,12,25:82.0
18,12,25:82.0
19,12,25:159.4
1,13,25:159.4
2,13,25:159.4
3,13,25:82.0
4,13,25:82.0
5,13,25:82.0
6,13,25:159.4
7,13,25:159.4
8,13,25:159.4
9,13,25:159.4
10,13,25:159.4
11,13,25:159.4
12,13,25:159.4
13,13,25:159.4
14,13,25:159.4
15,13,25:159.4
16,13,25:159.4
7,14,25:159.4
8,14,25:159.4
9,14,25:159.4
10,14,25:159.4
-4,-19,26:159.4
-3,-19,26:159.4
-2,-19,26:159.4
-1,-19,26:159.4
-5,-18,26:159.4
-4,-18,26:159.4
-3,-18,26:159.4
-2,-18,26:159.4
-1,-18,26:82.0
0,-18,26:82.0
1,-18,26:82.0
2,-18,26:82.0
3,-18,26:82.0
4,-18,26:159.4
5,-18,26:159.4
6,-18,26:159.4
7,-18,26:159.4
8,-18,26:159.4
9,-18,26:159.4
10,-18,26:159.4
11,-18,26:82.0
12,-18,26:82.0
-6,-17,26:159.4
-5,-17,26:159.4
-4,-17,26:159.4
-3,-17,26:159.4
-2,-17,26:159.4
-1,-17,26:82.0
0,-17,26:82.0
1,-17,26:82.0
2,-17,26:82.0
3,-17,26:82.0
4,-17,26:159.4
5,-17,26:159.4
6,-17,26:159.4
7,-17,26:159.4
8,-17,26:159.4
9,-17,26:159.4
10,-17,26:159.4
11,-17,26:82.0
12,-17,26:82.0
13,-17,26:82.0
14,-17,26:82.0
15,-17,26:82.0
-6,-16,26:159.4
-5,-16,26:159.4
-4,-16,26:159.4
-3,-16,26:159.4
-2,-16,26:159.4
-1,-16,26:100.0
0,-16,26:82.0
1,-16,26:82.0
2,-16,26:82.0
3,-16,26:82.0
4,-16,26:159.4
5,-16,26:159.4
6,-16,26:159.4
7,-16,26:159.4
8,-16,26:159.4
9,-16,26:159.4
10,-16,26:159.4
11,-16,26:82.0
12,-16,26:82.0
13,-16,26:82.0
14,-16,26:82.0
15,-16,26:82.0
16,-16,26:159.4
17,-16,26:159.4
18,-16,26:159.4
-6,-15,26:159.4
-5,-15,26:159.4
-4,-15,26:159.4
-3,-15,26:159.4
-2,-15,26:159.4
-1,-15,26:100.0
0,-15,26:100.0
1,-15,26:100.0
2,-15,26:82.0
3,-15,26:100.0
4,-15,26:100.0
5,-15,26:100.0
6,-15,26:100.0
7,-15,26:100.0
8,-15,26:100.0
9,-15,26:100.0
10,-15,26:100.0
11,-15,26:100.0
12,-15,26:100.0
13,-15,26:82.0
14,-15,26:82.0
15,-15,26:159.4
16,-15,26:159.4
17,-15,26:159.4
18,-15,26:159.4
19,-15,26:159.4
20,-15,26:159.4
21,-15,26:159.4
-6,-14,26:159.4
-5,-14,26:159.4
-4,-14,26:159.4
-3,-14,26:159.4
-2,-14,26:159.4
-1,-14,26:159.4
0,-14,26:159.4
1,-14,26:159.4
2,-14,26:159.4
3,-14,26:159.4
4,-14,26:159.4
5,-14,26:159.4
6,-14,26:100.0
7,-14,26:100.0
8,-14,26:100.0
9,-14,26:100.0
10,-14,26:100.0
11,-14,26:100.0
12,-14,26:100.0
13,-14,26:100.0
14,-14,26:100.0
15,-14,26:100.0
16,-14,26:159.4
17,-14,26:159.4
18,-14,26:159.4
19,-14,26:159.4
20,-14,26:159.4
21,-14,26:159.4
22,-14,26:159.4
23,-14,26:159.4
24,-14,26:159.4
-6,-13,26:82.0
-5,-13,26:82.0
-4,-13,26:82.0
-3,-13,26:159.4
-2,-13,26:159.4
-1,-13,26:159.4
0,-13,26:159.4
1,-13,26:159.4
2,-13,26:159.4
3,-13,26:159.4
4,-13,26:159.4
5,-13,26:159.4
6,-13,26:159.4
7,-13,26:159.4
10,-13,26:100.0
11,-13,26:100.0
12,-13,26:100.0
13,-13,26:100.0
14,-13,26:100.0
15,-13,26:100.0
16,-13,26:100.0
17,-13,26:100.0
18,-13,26:159.4
19,-13,26:159.4
20,-13,26:159.4
21,-13,26:159.4
22,-13,26:159.4
23,-13,26:159.4
24,-13,26:159.4
25,-13,26:159.4
-7,-12,26:82.0
-6,-12,26:82.0
-5,-12,26:82.0
-4,-12,26:82.0
-3,-12,26:100.0
-2,-12,26:159.4
-1,-12,26:159.4
0,-12,26:159.4
1,-12,26:159.4
2,-12,26:159.4
3,-12,26:159.4
4,-12,26:159.4
5,-12,26:159.4
6,-12,26:159.4
7,-12,26:159.4
8,-12,26:159.4
9,-12,26:159.4
10,-12,26:159.4
11,-12,26:159.4
12,-12,26:159.4
13,-12,26:159.4
14,-12,26:159.4
15,-12,26:159.4
16,-12,26:100.0
17,-12,26:100.0
18,-12,26:100.0
19,-12,26:100.0
20,-12,26:100.0
21,-12,26:159.4
22,-12,26:159.4
23,-12,26:159.4
24,-12,26:159.4
25,-12,26:159.4
-7,-11,26:82.0
-6,-11,26:82.0
-5,-11,26:82.0
-4,-11,26:82.0
-3,-11,26:100.0
-2,-11,26:159.4
-1,-11,26:159.4
0,-11,26:159.4
1,-11,26:159.4
2,-11,26:159.4
3,-11,26:159.4
4,-11,26:159.4
5,-11,26:159.4
6,-11,26:159.4
7,-11,26:159.4
8,-11,26:159.4
9,-11,26:159.4
10,-11,26:159.4
11,-11,26:159.4
12,-11,26:159.4
13,-11,26:159.4
14,-11,26:159.4
15,-11,26:159.4
16,-11,26:159.4
17,-11,26:159.4
18,-11,26:100.0
19,-11,26:100.0
20,-11,26:100.0
21,-11,26:100.0
22,-11,26:100.0
23,-11,26:159.4
24,-11,26:159.4
-7,-10,26:82.0
-6,-10,26:82.0
-5,-10,26:82.0
-4,-10,26:82.0
-3,-10,26:100.0
-2,-10,26:100.0
-1,-10,26:159.4
0,-10,26:159.4
1,-10,26:159.4
2,-10,26:159.4
3,-10,26:159.4
4,-10,26:159.4
5,-10,26:159.4
6,-10,26:159.4
7,-10,26:159.4
8,-10,26:159.4
9,-10,26:159.4
10,-10,26:159.4
11,-10,26:159.4
12,-10,26:159.4
13,-10,26:159.4
14,-10,26:159.4
15,-10,26:159.4
16,-10,26:82.0
17,-10,26:82.0
18,-10,26:82.0
19,-10,26:159.4
20,-10,26:100.0
21,-10,26:100.0
22,-10,26:159.4
23,-10,26:159.4
24,-10,26:159.4
-7,-9,26:159.4
-6,-9,26:82.0
-5,-9,26:82.0
-4,-9,26:100.0
-3,-9,26:100.0
-2,-9,26:100.0
-1,-9,26:159.4
0,-9,26:159.4
1,-9,26:159.4
2,-9,26:159.4
3,-9,26:159.4
4,-9,26:159.4
5,-9,26:159.4
6,-9,26:159.4
7,-9,26:159.4
8,-9,26:159.4
9,-9,26:159.4
10,-9,26:159.4
11,-9,26:159.4
12,-9,26:159.4
13,-9,26:159.4
14,-9,26:159.4
15,-9,26:159.4
16,-9,26:82.0
17,-9,26:82.0
18,-9,26:82.0
19,-9,26:159.4
20,-9,26:100.0
21,-9,26:159.4
22,-9,26:159.4
23,-9,26:159.4
24,-9,26:159.4
-8,-8,26:159.4
-7,-8,26:159.4
-6,-8,26:159.4
-5,-8,26:159.4
-4,-8,26:100.0
-3,-8,26:100.0
-2,-8,26:100.0
-1,-8,26:159.4
0,-8,26:159.4
1,-8,26:159.4
2,-8,26:159.4
3,-8,26:159.4
4,-8,26:159.4
5,-8,26:159.4
6,-8,26:159.4
7,-8,26:159.4
8,-8,26:159.4
9,-8,26:159.4
10,-8,26:159.4
11,-8,26:159.4
12,-8,26:159.4
13,-8,26:159.4
14,-8,26:159.4
15,-8,26:159.4
16,-8,26:82.0
17,-8,26:82.0
18,-8,26:82.0
19,-8,26:159.4
20,-8,26:159.4
21,-8,26:100.0
22,-8,26:159.4
23,-8,26:159.4
24,-8,26:159.4
-8,-7,26:159.4
-7,-7,26:159.4
-6,-7,26:159.4
-5,-7,26:159.4
-4,-7,26:100.0
-3,-7,26:100.0
-2,-7,26:100.0
0,-7,26:159.4
1,-7,26:159.4
2,-7,26:159.4
3,-7,26:159.4
4,-7,26:159.4
5,-7,26:159.4
6,-7,26:159.4
7,-7,26:159.4
8,-7,26:159.4
9,-7,26:159.4
10,-7,26:159.4
11,-7,26:159.4
12,-7,26:159.4
13,-7,26:159.4
14,-7,26:159.4
15,-7,26:159.4
16,-7,26:159.4
17,-7,26:159.4
18,-7,26:159.4
19,-7,26:159.4
20,-7,26:100.0
21,-7,26:159.4
22,-7,26:159.4
23,-7,26:159.4
24,-7,26:159.4
-8,-6,26:159.4
-7,-6,26:159.4
-6,-6,26:159.4
-5,-6,26:159.4
-4,-6,26:100.0
-3,-6,26:100.0
-2,-6,26:100.0
0,-6,26:159.4
1,-6,26:159.4
2,-6,26:159.4
3,-6,26:159.4
4,-6,26:159.4
5,-6,26:159.4
6,-6,26:159.4
7,-6,26:159.4
8,-6,26:17.14
9,-6,26:17.14
10,-6,26:159.4
11,-6,26:159.4
12,-6,26:159.4
13,-6,26:159.4
14,-6,26:159.4
15,-6,26:159.4
16,-6,26:159.4
17,-6,26:159.4
18,-6,26:159.4
19,-6,26:100.0
20,-6,26:100.0
21,-6,26:159.4
22,-6,26:159.4
23,-6,26:82.0
-8,-5,26:159.4
-7,-5,26:159.4
-6,-5,26:159.4
-5,-5,26:159.4
-4,-5,26:100.0
-3,-5,26:100.0
-2,-5,26:100.0
0,-5,26:159.4
1,-5,26:159.4
2,-5,26:159.4
3,-5,26:159.4
4,-5,26:159.4
5,-5,26:159.4
6,-5,26:159.4
7,-5,26:159.4
8,-5,26:159.4
9,-5,26:159.4
10,-5,26:159.4
11,-5,26:159.4
12,-5,26:159.4
13,-5,26:159.4
14,-5,26:159.4
15,-5,26:159.4
16,-5,26:159.4
17,-5,26:159.4
18,-5,26:100.0
19,-5,26:100.0
20,-5,26:100.0
21,-5,26:159.4
22,-5,26:82.0
23,-5,26:82.0
-8,-4,26:159.4
-7,-4,26:159.4
-6,-4,26:159.4
-5,-4,26:159.4
-4,-4,26:100.0
-3,-4,26:100.0
-2,-4,26:100.0
-1,-4,26:159.4
0,-4,26:159.4
1,-4,26:159.4
2,-4,26:159.4
3,-4,26:159.4
4,-4,26:159.4
5,-4,26:159.4
6,-4,26:159.4
7,-4,26:159.4
8,-4,26:159.4
9,-4,26:159.4
10,-4,26:159.4
11,-4,26:159.4
12,-4,26:159.4
13,-4,26:159.4
14,-4,26:159.4
15,-4,26:159.4
16,-4,26:159.4
18,-4,26:100.0
19,-4,26:100.0
20,-4,26:100.0
21,-4,26:159.4
22,-4,26:82.0
23,-4,26:82.0
-8,-3,26:159.4
-7,-3,26:159.4
-6,-3,26:159.4
-5,-3,26:159.4
-4,-3,26:100.0
-3,-3,26:100.0
-2,-3,26:159.4
-1,-3,26:159.4
0,-3,26:159.4
1,-3,26:159.4
2,-3,26:159.4
3,-3,26:159.4
4,-3,26:159.4
5,-3,26:159.4
6,-3,26:159.4
7,-3,26:159.4
8,-3,26:159.4
9,-3,26:159.4
10,-3,26:159.4
11,-3,26:159.4
12,-3,26:159.4
13,-3,26:159.4
14,-3,26:159.4
15,-3,26:159.4
16,-3,26:159.4
18,-3,26:100.0
19,-3,26:100.0
20,-3,26:100.0
21,-3,26:159.4
22,-3,26:82.0
23,-3,26:82.0
-8,-2,26:82.0
-7,-2,26:82.0
-6,-2,26:82.0
-5,-2,26:159.4
-4,-2,26:100.0
-3,-2,26:100.0
-2,-2,26:159.4
-1,-2,26:159.4
0,-2,26:159.4
1,-2,26:159.4
2,-2,26:159.4
3,-2,26:159.4
4,-2,26:159.4
5,-2,26:159.4
6,-2,26:159.4
7,-2,26:159.4
8,-2,26:159.4
9,-2,26:159.4
10,-2,26:159.4
11,-2,26:159.4
12,-2,26:159.4
13,-2,26:159.4
14,-2,26:159.4
15,-2,26:159.4
16,-2,26:159.4
18,-2,26:100.0
19,-2,26:100.0
20,-2,26:159.4
21,-2,26:159.4
22,-2,26:159.4
23,-2,26:82.0
-8,-1,26:82.0
-7,-1,26:82.0
-6,-1,26:82.0
-5,-1,26:82.0
-4,-1,26:100.0
-3,-1,26:159.4
-2,-1,26:159.4
-1,-1,26:159.4
0,-1,26:159.4
1,-1,26:159.4
2,-1,26:159.4
3,-1,26:159.4
4,-1,26:159.4
5,-1,26:159.4
6,-1,26:159.4
7,-1,26:159.4
8,-1,26:159.4
9,-1,26:159.4
10,-1,26:159.4
11,-1,26:159.4
12,-1,26:159.4
13,-1,26:159.4
14,-1,26:159.4
15,-1,26:159.4
16,-1,26:159.4
17,-1,26:159.4
18,-1,26:159.4
19,-1,26:100.0
20,-1,26:159.4
21,-1,26:159.4
22,-1,26:159.4
23,-1,26:159.4
-8,0,26:82.0
-7,0,26:82.0
-6,0,26:82.0
-5,0,26:82.0
-4,0,26:159.4
-3,0,26:159.4
-2,0,26:159.4
-1,0,26:159.4
0,0,26:159.4
1,0,26:159.4
2,0,26:159.4
3,0,26:159.4
4,0,26:159.4
5,0,26:159.4
6,0,26:159.4
7,0,26:159.4
8,0,26:159.4
9,0,26:159.4
10,0,26:159.4
11,0,26:159.4
12,0,26:159.4
13,0,26:159.4
14,0,26:159.4
15,0,26:159.4
16,0,26:159.4
17,0,26:159.4
18,0,26:100.0
19,0,26:100.0
20,0,26:159.4
21,0,26:159.4
22,0,26:159.4
-8,1,26:82.0
-7,1,26:82.0
-6,1,26:82.0
-5,1,26:100.0
-4,1,26:159.4
-3,1,26:159.4
-2,1,26:159.4
-1,1,26:159.4
0,1,26:159.4
1,1,26:159.4
2,1,26:159.4
3,1,26:159.4
4,1,26:159.4
5,1,26:159.4
6,1,26:159.4
7,1,26:159.4
8,1,26:159.4
9,1,26:159.4
10,1,26:159.4
11,1,26:159.4
12,1,26:159.4
13,1,26:159.4
14,1,26:159.4
15,1,26:159.4
16,1,26:159.4
17,1,26:159.4
18,1,26:100.0
19,1,26:100.0
20,1,26:159.4
21,1,26:159.4
22,1,26:159.4
-8,2,26:82.0
-7,2,26:82.0
-6,2,26:82.0
-5,2,26:159.4
-4,2,26:159.4
-3,2,26:159.4
-2,2,26:159.4
-1,2,26:159.4
0,2,26:159.4
1,2,26:159.4
2,2,26:159.4
3,2,26:159.4
4,2,26:159.4
5,2,26:159.4
6,2,26:159.4
7,2,26:159.4
8,2,26:159.4
9,2,26:159.4
10,2,26:159.4
11,2,26:159.4
12,2,26:159.4
13,2,26:159.4
14,2,26:159.4
15,2,26:159.4
16,2,26:159.4
17,2,26:159.4
18,2,26:100.0
19,2,26:100.0
20,2,26:159.4
21,2,26:159.4
22,2,26:159.4
-8,3,26:159.4
-7,3,26:159.4
-6,3,26:159.4
-5,3,26:159.4
-4,3,26:159.4
-3,3,26:159.4
-2,3,26:159.4
-1,3,26:159.4
0,3,26:159.4
1,3,26:159.4
2,3,26:159.4
3,3,26:159.4
4,3,26:159.4
5,3,26:159.4
6,3,26:159.4
7,3,26:159.4
8,3,26:159.4
9,3,26:159.4
10,3,26:159.4
11,3,26:159.4
12,3,26:159.4
13,3,26:159.4
14,3,26:159.4
15,3,26:159.4
16,3,26:159.4
17,3,26:159.4
18,3,26:159.4
19,3,26:100.0
20,3,26:159.4
21,3,26:159.4
-8,4,26:159.4
-7,4,26:159.4
-6,4,26:159.4
-5,4,26:159.4
-4,4,26:159.4
-3,4,26:159.4
-2,4,26:159.4
-1,4,26:159.4
0,4,26:159.4
1,4,26:159.4
2,4,26:159.4
3,4,26:82.0
4,4,26:82.0
5,4,26:82.0
6,4,26:159.4
7,4,26:159.4
8,4,26:159.4
9,4,26:159.4
10,4,26:159.4
11,4,26:159.4
12,4,26:159.4
13,4,26:159.4
14,4,26:159.4
15,4,26:159.4
16,4,26:159.4
17,4,26:159.4
18,4,26:82.0
19,4,26:100.0
20,4,26:159.4
21,4,26:159.4
22,4,26:159.4
-8,5,26:159.4
-7,5,26:159.4
-6,5,26:159.4
-5,5,26:159.4
-4,5,26:159.4
-3,5,26:159.4
-2,5,26:159.4
-1,5,26:159.4
0,5,26:159.4
1,5,26:159.4
2,5,26:100.0
3,5,26:100.0
4,5,26:100.0
5,5,26:100.0
6,5,26:100.0
7,5,26:100.0
8,5,26:100.0
9,5,26:100.0
10,5,26:159.4
11,5,26:159.4
12,5,26:159.4
13,5,26:159.4
14,5,26:159.4
15,5,26:159.4
16,5,26:159.4
17,5,26:82.0
18,5,26:82.0
19,5,26:82.0
20,5,26:159.4
21,5,26:159.4
22,5,26:159.4
-9,6,26:159.4
-8,6,26:159.4
-7,6,26:159.4
-6,6,26:159.4
-5,6,26:159.4
-4,6,26:159.4
-3,6,26:159.4
-2,6,26:159.4
-1,6,26:159.4
0,6,26:159.4
1,6,26:100.0
2,6,26:100.0
3,6,26:100.0
4,6,26:100.0
5,6,26:100.0
6,6,26:100.0
7,6,26:100.0
8,6,26:100.0
9,6,26:100.0
10,6,26:100.0
11,6,26:100.0
12,6,26:159.4
13,6,26:159.4
14,6,26:159.4
15,6,26:159.4
16,6,26:159.4
17,6,26:159.4
18,6,26:82.0
19,6,26:159.4
20,6,26:159.4
21,6,26:82.0
22,6,26:82.0
-8,7,26:159.4
-7,7,26:159.4
-6,7,26:159.4
-5,7,26:159.4
-4,7,26:159.4
-3,7,26:159.4
-2,7,26:159.4
-1,7,26:159.4
0,7,26:159.4
1,7,26:159.4
2,7,26:82.0
3,7,26:82.0
4,7,26:82.0
5,7,26:82.0
6,7,26:100.0
7,7,26:100.0
8,7,26:100.0
9,7,26:100.0
10,7,26:100.0
11,7,26:100.0
12,7,26:100.0
13,7,26:100.0
14,7,26:159.4
15,7,26:159.4
16,7,26:159.4
17,7,26:159.4
18,7,26:159.4
19,7,26:159.4
20,7,26:159.4
21,7,26:82.0
22,7,26:82.0
-5,8,26:159.4
-4,8,26:159.4
-3,8,26:159.4
-2,8,26:159.4
-1,8,26:159.4
0,8,26:159.4
1,8,26:159.4
2,8,26:159.4
3,8,26:82.0
4,8,26:82.0
5,8,26:82.0
6,8,26:159.4
7,8,26:159.4
8,8,26:159.4
9,8,26:159.4
10,8,26:159.4
11,8,26:159.4
12,8,26:159.4
13,8,26:159.4
14,8,26:159.4
15,8,26:159.4
16,8,26:159.4
17,8,26:159.4
18,8,26:159.4
19,8,26:159.4
20,8,26:159.4
21,8,26:82.0
0,9,26:159.4
1,9,26:159.4
2,9,26:159.4
3,9,26:159.4
4,9,26:159.4
5,9,26:159.4
6,9,26:159.4
7,9,26:159.4
8,9,26:159.4
9,9,26:82.0
10,9,26:82.0
11,9,26:82.0
12,9,26:159.4
13,9,26:159.4
14,9,26:159.4
15,9,26:159.4
16,9,26:159.4
17,9,26:159.4
18,9,26:159.4
19,9,26:159.4
4,10,26:159.4
5,10,26:159.4
6,10,26:159.4
7,10,26:159.4
8,10,26:159.4
9,10,26:82.0
10,10,26:82.0
11,10,26:82.0
12,10,26:159.4
13,10,26:159.4
14,10,26:159.4
15,10,26:159.4
16,10,26:159.4
17,10,26:82.0
18,10,26:159.4
-2,-16,27:159.4
-1,-16,27:82.0
0,-16,27:82.0
1,-16,27:82.0
2,-16,27:82.0
3,-16,27:82.0
4,-16,27:159.4
5,-16,27:159.4
6,-16,27:159.4
7,-16,27:159.4
8,-16,27:159.4
9,-16,27:159.4
10,-16,27:159.4
-3,-15,27:159.4
-2,-15,27:159.4
-1,-15,27:159.4
0,-15,27:82.0
1,-15,27:82.0
2,-15,27:82.0
3,-15,27:159.4
4,-15,27:159.4
5,-15,27:159.4
6,-15,27:159.4
7,-15,27:159.4
8,-15,27:159.4
9,-15,27:159.4
10,-15,27:159.4
11,-15,27:159.4
12,-15,27:82.0
13,-15,27:82.0
-3,-14,27:159.4
-2,-14,27:159.4
-1,-14,27:159.4
0,-14,27:159.4
1,-14,27:159.4
2,-14,27:159.4
3,-14,27:159.4
4,-14,27:159.4
5,-14,27:159.4
6,-14,27:159.4
7,-14,27:159.4
8,-14,27:159.4
9,-14,27:159.4
10,-14,27:159.4
11,-14,27:159.4
12,-14,27:159.4
13,-14,27:159.4
14,-14,27:159.4
15,-14,27:159.4
16,-14,27:159.4
-3,-13,27:159.4
-2,-13,27:159.4
-1,-13,27:159.4
0,-13,27:100.0
1,-13,27:100.0
2,-13,27:100.0
3,-13,27:100.0
4,-13,27:100.0
5,-13,27:100.0
6,-13,27:100.0
7,-13,27:100.0
8,-13,27:100.0
9,-13,27:100.0
10,-13,27:159.4
11,-13,27:159.4
12,-13,27:159.4
13,-13,27:159.4
14,-13,27:159.4
15,-13,27:159.4
16,-13,27:159.4
17,-13,27:159.4
18,-13,27:159.4
19,-13,27:159.4
-3,-12,27:82.0
-2,-12,27:159.4
-1,-12,27:159.4
0,-12,27:100.0
1,-12,27:100.0
2,-12,27:100.0
3,-12,27:100.0
4,-12,27:100.0
5,-12,27:100.0
6,-12,27:100.0
7,-12,27:100.0
8,-12,27:100.0
9,-12,27:100.0
10,-12,27:100.0
11,-12,27:100.0
12,-12,27:100.0
13,-12,27:100.0
14,-12,27:159.4
15,-12,27:159.4
16,-12,27:159.4
17,-12,27:159.4
18,-12,27:159.4
19,-12,27:159.4
20,-12,27:159.4
21,-12,27:159.4
-4,-11,27:82.0
-3,-11,27:82.0
-2,-11,27:159.4
-1,-11,27:159.4
0,-11,27:100.0
1,-11,27:100.0
2,-11,27:100.0
3,-11,27:100.0
4,-11,27:100.0
5,-11,27:100.0
6,-11,27:100.0
7,-11,27:100.0
8,-11,27:100.0
9,-11,27:100.0
10,-11,27:100.0
11,-11,27:100.0
12,-11,27:100.0
13,-11,27:100.0
14,-11,27:100.0
15,-11,27:100.0
16,-11,27:100.0
17,-11,27:82.0
18,-11,27:82.0
19,-11,27:159.4
20,-11,27:159.4
21,-11,27:159.4
22,-11,27:159.4
-4,-10,27:82.0
-3,-10,27:82.0
-2,-10,27:159.4
-1,-10,27:159.4
0,-10,27:100.0
1,-10,27:100.0
2,-10,27:100.0
12,-10,27:100.0
13,-10,27:100.0
14,-10,27:100.0
15,-10,27:100.0
16,-10,27:100.0
17,-10,27:100.0
18,-10,27:100.0
19,-10,27:82.0
20,-10,27:159.4
21,-10,27:159.4
-4,-9,27:82.0
-3,-9,27:159.4
-2,-9,27:159.4
-1,-9,27:159.4
0,-9,27:100.0
1,-9,27:100.0
2,-9,27:100.0
15,-9,27:100.0
16,-9,27:100.0
17,-9,27:100.0
18,-9,27:100.0
19,-9,27:82.0
20,-9,27:159.4
21,-9,27:159.4
-4,-8,27:159.4
-3,-8,27:159.4
-2,-8,27:159.4
-1,-8,27:100.0
0,-8,27:100.0
1,-8,27:100.0
2,-8,27:100.0
16,-8,27:100.0
17,-8,27:100.0
18,-8,27:100.0
19,-8,27:82.0
20,-8,27:159.4
21,-8,27:159.4
-5,-7,27:159.4
-4,-7,27:159.4
-3,-7,27:159.4
-2,-7,27:159.4
-1,-7,27:100.0
0,-7,27:100.0
1,-7,27:100.0
8,-7,27:17.14
16,-7,27:100.0
17,-7,27:100.0
18,-7,27:100.0
19,-7,27:159.4
20,-7,27:159.4
21,-7,27:159.4
-5,-6,27:159.4
-4,-6,27:159.4
-3,-6,27:159.4
-2,-6,27:159.4
-1,-6,27:100.0
0,-6,27:100.0
1,-6,27:100.0
8,-6,27:17.14
9,-6,27:17.14
16,-6,27:100.0
17,-6,27:100.0
18,-6,27:159.4
19,-6,27:159.4
20,-6,27:159.4
21,-6,27:159.4
-5,-5,27:159.4
-4,-5,27:159.4
-3,-5,27:159.4
-2,-5,27:159.4
-1,-5,27:100.0
0,-5,27:100.0
1,-5,27:100.0
16,-5,27:100.0
17,-5,27:100.0
18,-5,27:159.4
19,-5,27:159.4
20,-5,27:159.4
-5,-4,27:159.4
-4,-4,27:159.4
-3,-4,27:159.4
-2,-4,27:159.4
-1,-4,27:100.0
0,-4,27:100.0
1,-4,27:100.0
15,-4,27:100.0
16,-4,27:159.4
17,-4,27:100.0
18,-4,27:159.4
19,-4,27:159.4
20,-4,27:159.4
-5,-3,27:159.4
-4,-3,27:159.4
-3,-3,27:159.4
-2,-3,27:159.4
-1,-3,27:100.0
0,-3,27:100.0
1,-3,27:100.0
15,-3,27:100.0
16,-3,27:100.0
17,-3,27:100.0
18,-3,27:159.4
19,-3,27:159.4
20,-3,27:159.4
-5,-2,27:159.4
-4,-2,27:159.4
-3,-2,27:159.4
-2,-2,27:159.4
-1,-2,27:100.0
0,-2,27:100.0
1,-2,27:100.0
15,-2,27:100.0
16,-2,27:100.0
17,-2,27:100.0
18,-2,27:159.4
19,-2,27:159.4
20,-2,27:159.4
-5,-1,27:82.0
-4,-1,27:159.4
-3,-1,27:159.4
-2,-1,27:159.4
-1,-1,27:100.0
0,-1,27:100.0
1,-1,27:100.0
15,-1,27:100.0
16,-1,27:100.0
17,-1,27:100.0
18,-1,27:159.4
19,-1,27:159.4
20,-1,27:159.4
-5,0,27:82.0
-4,0,27:159.4
-3,0,27:159.4
-2,0,27:159.4
-1,0,27:100.0
0,0,27:100.0
1,0,27:100.0
15,0,27:100.0
16,0,27:100.0
17,0,27:100.0
18,0,27:159.4
19,0,27:159.4
20,0,27:159.4
-5,1,27:82.0
-4,1,27:159.4
-3,1,27:159.4
-2,1,27:159.4
-1,1,27:100.0
0,1,27:100.0
1,1,27:100.0
2,1,27:100.0
3,1,27:100.0
4,1,27:100.0
15,1,27:100.0
16,1,27:100.0
17,1,27:159.4
18,1,27:159.4
19,1,27:159.4
20,1,27:159.4
-5,2,27:159.4
-4,2,27:159.4
-3,2,27:159.4
-2,2,27:159.4
-1,2,27:100.0
0,2,27:100.0
1,2,27:100.0
2,2,27:100.0
3,2,27:100.0
4,2,27:100.0
5,2,27:100.0
6,2,27:100.0
7,2,27:100.0
8,2,27:100.0
9,2,27:100.0
10,2,27:100.0
11,2,27:100.0
12,2,27:100.0
13,2,27:100.0
14,2,27:100.0
15,2,27:100.0
16,2,27:100.0
17,2,27:159.4
18,2,27:159.4
19,2,27:159.4
-5,3,27:159.4
-4,3,27:159.4
-3,3,27:159.4
-2,3,27:159.4
-1,3,27:159.4
0,3,27:159.4
1,3,27:100.0
2,3,27:100.0
3,3,27:100.0
4,3,27:100.0
5,3,27:100.0
6,3,27:100.0
7,3,27:100.0
8,3,27:100.0
9,3,27:100.0
10,3,27:100.0
11,3,27:100.0
12,3,27:100.0
13,3,27:100.0
14,3,27:100.0
15,3,27:100.0
16,3,27:100.0
17,3,27:159.4
18,3,27:159.4
19,3,27:159.4
-5,4,27:159.4
-4,4,27:159.4
-3,4,27:159.4
-2,4,27:159.4
-1,4,27:159.4
0,4,27:159.4
1,4,27:159.4
2,4,27:159.4
3,4,27:82.0
4,4,27:82.0
5,4,27:100.0
6,4,27:100.0
7,4,27:100.0
8,4,27:100.0
9,4,27:100.0
10,4,27:100.0
11,4,27:100.0
12,4,27:100.0
13,4,27:100.0
14,4,27:100.0
15,4,27:100.0
16,4,27:159.4
17,4,27:82.0
18,4,27:82.0
19,4,27:82.0
-4,5,27:159.4
-3,5,27:159.4
-2,5,27:159.4
-1,5,27:159.4
0,5,27:159.4
1,5,27:159.4
2,5,27:82.0
3,5,27:82.0
4,5,27:82.0
5,5,27:82.0
6,5,27:82.0
7,5,27:159.4
8,5,27:159.4
9,5,27:159.4
10,5,27:159.4
11,5,27:159.4
12,5,27:159.4
13,5,27:159.4
14,5,27:159.4
15,5,27:159.4
16,5,27:159.4
17,5,27:82.0
18,5,27:82.0
19,5,27:82.0
-1,6,27:159.4
0,6,27:159.4
1,6,27:159.4
2,6,27:82.0
3,6,27:82.0
4,6,27:82.0
5,6,27:82.0
6,6,27:82.0
7,6,27:159.4
8,6,27:159.4
9,6,27:159.4
10,6,27:159.4
11,6,27:159.4
12,6,27:159.4
13,6,27:159.4
14,6,27:159.4
15,6,27:159.4
16,6,27:159.4
17,6,27:82.0
18,6,27:82.0
19,6,27:82.0
3,7,27:82.0
4,7,27:82.0
5,7,27:82.0
6,7,27:82.0
7,7,27:159.4
8,7,27:159.4
9,7,27:159.4
10,7,27:159.4
11,7,27:159.4
12,7,27:159.4
13,7,27:159.4
14,7,27:159.4
15,7,27:159.4
16,7,27:159.4
17,7,27:159.4
18,7,27:159.4
0,-13,28:159.4
1,-13,28:159.4
2,-13,28:159.4
3,-13,28:159.4
4,-13,28:159.4
5,-13,28:159.4
6,-13,28:159.4
7,-13,28:159.4
8,-13,28:159.4
9,-13,28:159.4
10,-13,28:159.4
11,-13,28:159.4
0,-12,28:159.4
1,-12,28:159.4
2,-12,28:159.4
3,-12,28:159.4
4,-12,28:159.4
5,-12,28:159.4
6,-12,28:159.4
7,-12,28:159.4
8,-12,28:159.4
9,-12,28:159.4
10,-12,28:159.4
11,-12,28:159.4
12,-12,28:159.4
13,-12,28:159.4
14,-12,28:159.4
0,-11,28:159.4
1,-11,28:159.4
2,-11,28:159.4
3,-11,28:159.4
4,-11,28:159.4
5,-11,28:159.4
6,-11,28:159.4
7,-11,28:159.4
8,-11,28:159.4
9,-11,28:159.4
10,-11,28:159.4
11,-11,28:159.4
12,-11,28:159.4
13,-11,28:159.4
14,-11,28:159.4
15,-11,28:159.4
16,-11,28:82.0
17,-11,28:82.0
-1,-10,28:159.4
0,-10,28:159.4
1,-10,28:159.4
2,-10,28:159.4
3,-10,28:100.0
4,-10,28:100.0
5,-10,28:100.0
6,-10,28:100.0
7,-10,28:100.0
8,-10,28:100.0
9,-10,28:100.0
10,-10,28:100.0
11,-10,28:100.0
12,-10,28:159.4
13,-10,28:159.4
14,-10,28:159.4
15,-10,28:82.0
16,-10,28:82.0
17,-10,28:82.0
18,-10,28:82.0
-1,-9,28:159.4
0,-9,28:159.4
1,-9,28:159.4
2,-9,28:159.4
3,-9,28:100.0
4,-9,28:100.0
5,-9,28:100.0
6,-9,28:100.0
7,-9,28:100.0
8,-9,28:100.0
9,-9,28:100.0
10,-9,28:100.0
11,-9,28:100.0
12,-9,28:100.0
13,-9,28:100.0
14,-9,28:100.0
15,-9,28:82.0
16,-9,28:82.0
17,-9,28:82.0
18,-9,28:82.0
-1,-8,28:159.4
0,-8,28:159.4
1,-8,28:159.4
2,-8,28:159.4
3,-8,28:100.0
4,-8,28:100.0
5,-8,28:100.0
8,-8,28:100.0
9,-8,28:100.0
10,-8,28:100.0
11,-8,28:100.0
12,-8,28:100.0
13,-8,28:100.0
14,-8,28:100.0
15,-8,28:100.0
16,-8,28:82.0
17,-8,28:82.0
18,-8,28:82.0
-1,-7,28:159.4
0,-7,28:159.4
1,-7,28:159.4
2,-7,28:100.0
3,-7,28:100.0
4,-7,28:100.0
5,-7,28:100.0
13,-7,28:100.0
14,-7,28:100.0
15,-7,28:100.0
16,-7,28:82.0
17,-7,28:82.0
18,-7,28:82.0
-2,-6,28:159.4
-1,-6,28:159.4
0,-6,28:159.4
1,-6,28:159.4
2,-6,28:100.0
3,-6,28:100.0
4,-6,28:100.0
8,-6,28:17.14
13,-6,28:100.0
14,-6,28:100.0
15,-6,28:100.0
16,-6,28:159.4
17,-6,28:159.4
18,-6,28:159.4
-2,-5,28:159.4
-1,-5,28:159.4
0,-5,28:159.4
1,-5,28:159.4
2,-5,28:100.0
3,-5,28:100.0
4,-5,28:100.0
13,-5,28:100.0
14,-5,28:100.0
15,-5,28:100.0
16,-5,28:159.4
17,-5,28:159.4
18,-5,28:159.4
-2,-4,28:159.4
-1,-4,28:159.4
0,-4,28:159.4
1,-4,28:159.4
2,-4,28:100.0
3,-4,28:100.0
4,-4,28:100.0
13,-4,28:100.0
14,-4,28:100.0
15,-4,28:159.4
16,-4,28:159.4
17,-4,28:159.4
18,-4,28:159.4
-2,-3,28:159.4
-1,-3,28:159.4
0,-3,28:82.0
1,-3,28:82.0
2,-3,28:100.0
3,-3,28:100.0
4,-3,28:100.0
13,-3,28:100.0
14,-3,28:100.0
15,-3,28:159.4
16,-3,28:159.4
17,-3,28:159.4
-2,-2,28:159.4
-1,-2,28:82.0
0,-2,28:82.0
1,-2,28:82.0
2,-2,28:100.0
3,-2,28:100.0
4,-2,28:100.0
12,-2,28:100.0
13,-2,28:100.0
14,-2,28:100.0
15,-2,28:159.4
16,-2,28:159.4
17,-2,28:159.4
-2,-1,28:159.4
-1,-1,28:82.0
0,-1,28:82.0
1,-1,28:82.0
2,-1,28:100.0
3,-1,28:100.0
4,-1,28:100.0
5,-1,28:100.0
6,-1,28:100.0
7,-1,28:100.0
8,-1,28:100.0
9,-1,28:100.0
10,-1,28:100.0
11,-1,28:100.0
12,-1,28:100.0
13,-1,28:100.0
14,-1,28:100.0
15,-1,28:159.4
16,-1,28:159.4
17,-1,28:159.4
-2,0,28:159.4
-1,0,28:82.0
0,0,28:82.0
1,0,28:82.0
2,0,28:100.0
3,0,28:100.0
4,0,28:100.0
5,0,28:100.0
6,0,28:100.0
7,0,28:100.0
8,0,28:100.0
9,0,28:100.0
10,0,28:100.0
11,0,28:100.0
12,0,28:100.0
13,0,28:100.0
14,0,28:100.0
15,0,28:159.4
16,0,28:159.4
17,0,28:159.4
-2,1,28:159.4
-1,1,28:159.4
0,1,28:82.0
1,1,28:82.0
2,1,28:82.0
3,1,28:159.4
4,1,28:159.4
5,1,28:100.0
6,1,28:100.0
7,1,28:100.0
8,1,28:100.0
9,1,28:100.0
10,1,28:100.0
11,1,28:100.0
12,1,28:100.0
13,1,28:100.0
14,1,28:100.0
15,1,28:159.4
16,1,28:159.4
17,1,28:159.4
-2,2,28:159.4
-1,2,28:159.4
0,2,28:159.4
1,2,28:159.4
2,2,28:159.4
3,2,28:159.4
4,2,28:159.4
5,2,28:159.4
6,2,28:159.4
7,2,28:159.4
8,2,28:82.0
9,2,28:82.0
10,2,28:82.0
11,2,28:82.0
12,2,28:82.0
13,2,28:159.4
14,2,28:159.4
15,2,28:159.4
16,2,28:159.4
17,2,28:159.4
-2,3,28:159.4
-1,3,28:159.4
0,3,28:159.4
1,3,28:159.4
2,3,28:159.4
3,3,28:159.4
4,3,28:159.4
5,3,28:159.4
6,3,28:159.4
7,3,28:159.4
8,3,28:159.4
9,3,28:82.0
10,3,28:82.0
11,3,28:82.0
12,3,28:159.4
13,3,28:159.4
14,3,28:159.4
15,3,28:159.4
16,3,28:159.4
17,3,28:159.4
3,4,28:82.0
4,4,28:82.0
5,4,28:82.0
6,4,28:159.4
7,4,28:159.4
8,4,28:159.4
9,4,28:159.4
10,4,28:159.4
11,4,28:159.4
12,4,28:159.4
13,4,28:159.4
14,4,28:159.4
15,4,28:159.4
8,5,28:159.4
9,5,28:159.4
10,5,28:159.4
11,5,28:159.4
12,5,28:159.4
13,5,28:159.4
14,5,28:159.4
3,-11,29:159.4
4,-11,29:82.0
5,-11,29:82.0
6,-11,29:82.0
7,-11,29:159.4
8,-11,29:159.4
9,-11,29:159.4
3,-10,29:82.0
4,-10,29:82.0
5,-10,29:82.0
6,-10,29:82.0
7,-10,29:82.0
8,-10,29:159.4
9,-10,29:159.4
10,-10,29:159.4
11,-10,29:159.4
12,-10,29:159.4
2,-9,29:159.4
3,-9,29:82.0
4,-9,29:82.0
5,-9,29:82.0
6,-9,29:82.0
7,-9,29:82.0
8,-9,29:159.4
9,-9,29:159.4
10,-9,29:159.4
11,-9,29:159.4
12,-9,29:159.4
13,-9,29:159.4
14,-9,29:159.4
15,-9,29:82.0
2,-8,29:159.4
3,-8,29:82.0
4,-8,29:82.0
5,-8,29:82.0
6,-8,29:100.0
7,-8,29:100.0
8,-8,29:159.4
9,-8,29:159.4
10,-8,29:159.4
11,-8,29:159.4
12,-8,29:159.4
13,-8,29:159.4
14,-8,29:159.4
15,-8,29:82.0
16,-8,29:82.0
2,-7,29:159.4
3,-7,29:159.4
4,-7,29:82.0
5,-7,29:82.0
6,-7,29:100.0
7,-7,29:100.0
8,-7,29:100.0
9,-7,29:100.0
10,-7,29:100.0
11,-7,29:100.0
12,-7,29:100.0
13,-7,29:159.4
14,-7,29:159.4
15,-7,29:159.4
2,-6,29:159.4
3,-6,29:159.4
4,-6,29:159.4
5,-6,29:100.0
6,-6,29:100.0
7,-6,29:100.0
8,-6,29:17.14
9,-6,29:100.0
10,-6,29:100.0
11,-6,29:100.0
12,-6,29:100.0
13,-6,29:159.4
14,-6,29:159.4
15,-6,29:159.4
2,-5,29:159.4
3,-5,29:159.4
4,-5,29:159.4
5,-5,29:100.0
6,-5,29:100.0
7,-5,29:100.0
10,-5,29:100.0
11,-5,29:100.0
12,-5,29:100.0
13,-5,29:159.4
14,-5,29:159.4
15,-5,29:159.4
1,-4,29:159.4
2,-4,29:159.4
3,-4,29:159.4
4,-4,29:159.4
5,-4,29:100.0
6,-4,29:100.0
7,-4,29:100.0
10,-4,29:100.0
11,-4,29:100.0
12,-4,29:100.0
13,-4,29:159.4
14,-4,29:159.4
15,-4,29:159.4
1,-3,29:82.0
2,-3,29:82.0
3,-3,29:159.4
4,-3,29:159.4
5,-3,29:100.0
6,-3,29:100.0
7,-3,29:100.0
8,-3,29:100.0
9,-3,29:100.0
10,-3,29:100.0
11,-3,29:100.0
12,-3,29:100.0
13,-3,29:159.4
14,-3,29:159.4
15,-3,29:159.4
1,-2,29:82.0
2,-2,29:82.0
3,-2,29:82.0
4,-2,29:159.4
5,-2,29:100.0
6,-2,29:100.0
7,-2,29:100.0
8,-2,29:100.0
9,-2,29:100.0
10,-2,29:100.0
11,-2,29:100.0
12,-2,29:159.4
13,-2,29:159.4
14,-2,29:159.4
15,-2,29:159.4
1,-1,29:82.0
2,-1,29:82.0
3,-1,29:82.0
4,-1,29:159.4
5,-1,29:159.4
6,-1,29:159.4
7,-1,29:159.4
8,-1,29:159.4
9,-1,29:82.0
10,-1,29:82.0
11,-1,29:82.0
12,-1,29:159.4
13,-1,29:159.4
14,-1,29:159.4
1,0,29:82.0
2,0,29:82.0
3,0,29:82.0
4,0,29:159.4
5,0,29:159.4
6,0,29:159.4
7,0,29:159.4
8,0,29:82.0
9,0,29:82.0
10,0,29:82.0
11,0,29:82.0
12,0,29:82.0
13,0,29:159.4
14,0,29:159.4
1,1,29:82.0
2,1,29:82.0
3,1,29:159.4
4,1,29:159.4
5,1,29:159.4
6,1,29:159.4
7,1,29:159.4
8,1,29:82.0
9,1,29:82.0
10,1,29:82.0
11,1,29:82.0
12,1,29:82.0
13,1,29:159.4
14,1,29:159.4
7,2,29:159.4
8,2,29:82.0
9,2,29:82.0
10,2,29:82.0
11,2,29:82.0
12,2,29:82.0
13,2,29:159.4
14,2,29:159.4
3,-10,30:82.0
4,-10,30:82.0
4,-9,30:82.0
5,-9,30:82.0
5,-8,30:82.0
6,-8,30:82.0
7,-8,30:82.0
8,-8,30:159.4
9,-8,30:159.4
10,-8,30:159.4
5,-7,30:82.0
6,-7,30:82.0
7,-7,30:159.4
8,-7,30:159.4
9,-7,30:159.4
10,-7,30:159.4
11,-7,30:159.4
12,-7,30:159.4
5,-6,30:159.4
6,-6,30:159.4
7,-6,30:159.4
8,-6,30:159.4
9,-6,30:159.4
10,-6,30:159.4
11,-6,30:159.4
12,-6,30:159.4
13,-6,30:159.4
5,-5,30:159.4
6,-5,30:159.4
7,-5,30:159.4
8,-5,30:100.0
9,-5,30:100.0
10,-5,30:159.4
11,-5,30:159.4
12,-5,30:159.4
5,-4,30:159.4
6,-4,30:159.4
7,-4,30:159.4
8,-4,30:100.0
9,-4,30:100.0
10,-4,30:159.4
11,-4,30:159.4
12,-4,30:159.4
5,-3,30:159.4
6,-3,30:159.4
7,-3,30:159.4
8,-3,30:159.4
9,-3,30:159.4
10,-3,30:159.4
11,-3,30:159.4
12,-3,30:159.4
5,-2,30:159.4
6,-2,30:159.4
7,-2,30:159.4
8,-2,30:159.4
9,-2,30:159.4
10,-2,30:159.4
11,-2,30:159.4
12,-2,30:159.4
6,-1,30:159.4
7,-1,30:159.4
8,-1,30:159.4
9,-1,30:82.0
10,-1,30:82.0
11,-1,30:82.0
12,-1,30:159.4
12,0,30:82.0
7,-7,31:159.4
7,-6,31:159.4
8,-6,31:159.4
10,-6,31:159.4
8,-5,31:159.4
9,-5,31:159.4
10,-5,31:159.4
7,-4,31:159.4
8,-4,31:159.4
9,-4,31:159.4
10,-4,31:159.4
7,-3,31:159.4
10,-3,31:159.4
