[META]
version=2.0
spawnOnBlockType=2
spawnSunlight=True
spawnDarkness=True
spawnWater=False
spawnLava=False
underFill=False
randomRotation=True
dig=True
tree=False
branch=False
needsFoundation=True
rarity=100
collisionPercentage=20
spawnElevationMin=0
spawnElevationMax=200
spawnInBiome=Custom
[DATA]
1,-2,-6:100.15
2,-2,-6:100.15
2,-1,-6:100.15
1,2,-6:100.15
2,-2,-5:100.15
1,-1,-5:100.15
2,-1,-5:100.15
1,1,-5:100.15
0,2,-5:100.15
1,3,-5:100.15
1,-2,-4:100.15
2,-2,-4:100.15
0,-1,-4:100.15
1,-1,-4:100.15
2,-1,-4:100.15
1,1,-4:100.15
0,2,-4:100.15
1,2,-4:100.15
2,2,-4:100.15
0,3,-4:100.15
1,3,-4:100.15
0,-2,-3:100.15
1,-2,-3:100.15
2,-2,-3:100.15
0,-1,-3:100.15
1,-1,-3:100.15
2,-1,-3:100.15
3,-1,-3:100.15
0,0,-3:100.15
1,0,-3:100.15
2,0,-3:100.15
2,1,-3:100.15
0,2,-3:100.15
1,2,-3:100.15
0,-2,-2:100.15
-1,-1,-2:100.15
0,-1,-2:100.15
1,-1,-2:100.15
-1,0,-2:100.15
0,0,-2:100.15
0,1,-2:100.15
0,2,-2:100.15
1,2,-2:100.15
-1,3,-2:100.15
0,3,-2:100.15
0,-2,-1:100.15
0,-1,-1:100.15
1,-1,-1:100.15
-1,0,-1:100.15
0,0,-1:100.15
1,0,-1:100.15
0,1,-1:100.15
1,1,-1:100.15
0,3,-1:100.15
-1,-2,0:100.15
0,-2,0:100.15
1,-2,0:100.15
-1,-1,0:100.15
0,-1,0:100.15
1,-1,0:100.15
2,-1,0:100.15
-2,0,0:100.15
-1,0,0:100.15
0,0,0:100.15
1,0,0:100.15
-1,1,0:100.15
0,1,0:100.15
1,1,0:100.15
-1,-2,1:100.15
0,-2,1:100.15
1,-2,1:100.15
-1,-1,1:100.15
1,-1,1:100.15
-1,0,1:100.15
1,0,1:100.15
-1,1,1:100.15
0,1,1:100.15
1,1,1:100.15
-1,-2,2:100.15
0,-2,2:100.15
1,-2,2:100.15
-1,-1,2:100.15
1,-1,2:100.15
-1,0,2:100.15
0,0,2:100.15
1,0,2:100.15
0,1,2:100.15
-1,-2,3:100.15
0,-2,3:100.15
1,-2,3:100.15
-1,-1,3:100.15
1,-1,3:100.15
-1,0,3:100.15
0,0,3:100.15
1,0,3:100.15
-1,-2,4:100.15
0,-2,4:100.15
1,-2,4:100.15
-1,-1,4:100.15
1,-1,4:100.15
0,0,4:100.15
1,0,4:100.15
-1,-2,5:100.15
0,-2,5:100.15
1,-2,5:100.15
-1,-1,5:100.15
1,-1,5:100.15
0,0,5:100.15
1,0,5:100.15
0,-2,6:100.15
1,-2,6:100.15
-1,-1,6:100.15
1,-1,6:100.15
0,0,6:100.15
1,0,6:100.15
0,-2,7:100.15
-1,-1,7:100.15
0,-1,7:100.0
1,-1,7:100.15
0,0,7:100.15
1,0,7:100.15
0,-2,8:100.15
-1,-1,8:100.15
0,-1,8:159.4
1,-1,8:100.15
0,0,8:100.15
3,-8,9:100.0
0,-2,9:100.15
0,-1,9:100.15
0,0,9:100.15
3,-9,10:100.0
0,-8,10:100.0
2,-8,10:100.0
3,-8,10:159.4
4,-8,10:100.0
-4,-7,10:100.0
-3,-7,10:100.0
-2,-7,10:100.0
-1,-7,10:100.0
0,-7,10:100.0
1,-7,10:100.0
2,-7,10:100.0
3,-7,10:100.0
-5,-6,10:100.0
-4,-6,10:100.0
-3,-6,10:100.0
-2,-6,10:100.0
-1,-6,10:100.0
0,-6,10:100.0
1,-6,10:100.0
2,-6,10:100.0
3,-6,10:100.0
4,-6,10:100.0
-6,-5,10:100.0
-5,-5,10:100.0
-4,-5,10:100.0
-3,-5,10:100.0
-2,-5,10:100.0
-1,-5,10:100.0
0,-5,10:100.0
1,-5,10:100.0
2,-5,10:100.0
3,-5,10:100.0
4,-5,10:100.0
5,-5,10:100.0
-6,-4,10:100.0
-5,-4,10:100.0
-4,-4,10:100.0
-2,-4,10:100.0
-1,-4,10:100.0
0,-4,10:100.0
1,-4,10:100.0
2,-4,10:100.0
3,-4,10:100.0
4,-4,10:100.0
5,-4,10:100.0
6,-4,10:100.0
-7,-3,10:100.0
-6,-3,10:100.0
-5,-3,10:100.0
1,-3,10:100.0
3,-3,10:100.0
4,-3,10:100.0
5,-3,10:100.0
6,-3,10:100.0
-7,-2,10:100.0
-6,-2,10:100.0
-5,-2,10:100.0
1,-2,10:100.0
4,-2,10:100.0
5,-2,10:100.0
-7,-1,10:100.0
-6,-1,10:100.0
0,-1,10:100.15
5,-1,10:100.0
6,-1,10:100.0
7,-1,10:100.0
-8,0,10:100.0
-7,0,10:100.0
-6,0,10:100.0
0,0,10:100.15
5,0,10:100.0
6,0,10:100.0
7,0,10:100.0
-8,1,10:100.0
-7,1,10:100.0
-6,1,10:100.0
5,1,10:100.0
6,1,10:100.0
7,1,10:100.0
-8,2,10:100.0
-7,2,10:100.0
-6,2,10:100.0
5,2,10:100.0
6,2,10:100.0
7,2,10:100.0
-6,3,10:100.0
4,3,10:100.0
5,3,10:100.0
6,3,10:100.0
-6,4,10:100.0
6,4,10:100.0
-6,5,10:100.0
5,5,10:100.0
6,5,10:100.0
2,6,10:100.0
3,6,10:100.0
4,6,10:100.0
5,6,10:100.0
1,7,10:100.0
2,7,10:100.0
3,7,10:100.0
-4,-8,11:100.0
-3,-8,11:100.0
-2,-8,11:100.0
-1,-8,11:100.0
0,-8,11:159.4
1,-8,11:100.0
2,-8,11:159.4
3,-8,11:159.4
-5,-7,11:100.0
-4,-7,11:159.4
-3,-7,11:159.4
-2,-7,11:159.4
-1,-7,11:159.4
0,-7,11:159.4
1,-7,11:159.4
2,-7,11:159.4
3,-7,11:82.0
4,-7,11:100.0
-6,-6,11:100.0
-5,-6,11:159.4
-4,-6,11:159.4
-3,-6,11:159.4
-2,-6,11:159.4
-1,-6,11:159.4
0,-6,11:159.4
1,-6,11:159.4
2,-6,11:159.4
3,-6,11:82.0
4,-6,11:82.0
5,-6,11:100.0
-7,-5,11:100.0
-6,-5,11:159.4
-5,-5,11:159.4
-4,-5,11:159.4
-3,-5,11:159.4
-2,-5,11:159.4
-1,-5,11:159.4
0,-5,11:159.4
1,-5,11:159.4
2,-5,11:159.4
3,-5,11:159.4
4,-5,11:159.4
5,-5,11:159.4
6,-5,11:100.0
-7,-4,11:100.0
-6,-4,11:159.4
-5,-4,11:159.4
-4,-4,11:159.4
-3,-4,11:100.0
-2,-4,11:159.4
-1,-4,11:159.4
0,-4,11:159.4
1,-4,11:159.4
2,-4,11:159.4
3,-4,11:159.4
4,-4,11:159.4
5,-4,11:159.4
6,-4,11:159.4
7,-4,11:100.0
-8,-3,11:100.0
-7,-3,11:159.4
-6,-3,11:159.4
-5,-3,11:159.4
-4,-3,11:100.0
-3,-3,11:100.0
-2,-3,11:100.0
-1,-3,11:100.0
0,-3,11:100.0
1,-3,11:159.4
2,-3,11:100.0
3,-3,11:159.4
4,-3,11:159.4
5,-3,11:159.4
6,-3,11:159.4
7,-3,11:159.4
8,-3,11:100.0
-8,-2,11:100.0
-7,-2,11:159.4
-6,-2,11:159.4
-5,-2,11:159.4
-3,-2,11:100.0
-2,-2,11:100.0
-1,-2,11:100.0
0,-2,11:100.0
1,-2,11:159.4
2,-2,11:100.0
3,-2,11:100.0
4,-2,11:159.4
5,-2,11:159.4
6,-2,11:100.0
7,-2,11:100.0
8,-2,11:100.0
-8,-1,11:100.0
-7,-1,11:159.4
-6,-1,11:159.4
-5,-1,11:100.0
-4,-1,11:100.0
-3,-1,11:100.0
-2,-1,11:100.0
-1,-1,11:100.0
0,-1,11:100.15
1,-1,11:100.0
2,-1,11:100.0
3,-1,11:100.0
4,-1,11:100.0
5,-1,11:159.4
6,-1,11:159.4
7,-1,11:159.4
8,-1,11:100.0
-9,0,11:100.0
-8,0,11:159.4
-7,0,11:159.4
-6,0,11:159.4
-5,0,11:100.0
-4,0,11:100.0
-3,0,11:100.0
-2,0,11:100.0
-1,0,11:100.0
0,0,11:100.15
1,0,11:100.0
2,0,11:100.0
3,0,11:100.0
4,0,11:100.0
5,0,11:159.4
6,0,11:159.4
7,0,11:159.4
8,0,11:100.0
-9,1,11:100.0
-8,1,11:159.4
-7,1,11:159.4
-6,1,11:159.4
-5,1,11:100.0
-4,1,11:100.0
-3,1,11:100.0
-2,1,11:100.0
0,1,11:100.0
1,1,11:100.0
2,1,11:100.0
3,1,11:100.0
4,1,11:100.0
5,1,11:159.4
6,1,11:159.4
7,1,11:159.4
8,1,11:100.0
-9,2,11:100.0
-8,2,11:159.4
-7,2,11:159.4
-6,2,11:159.4
-5,2,11:100.0
-4,2,11:100.0
-3,2,11:100.0
-2,2,11:100.0
-1,2,11:100.0
0,2,11:100.0
1,2,11:100.0
2,2,11:100.0
3,2,11:100.0
4,2,11:100.0
5,2,11:159.4
6,2,11:159.4
7,2,11:159.4
8,2,11:100.0
-8,3,11:100.0
-6,3,11:159.4
-5,3,11:100.0
-4,3,11:100.0
-3,3,11:100.0
-2,3,11:100.0
-1,3,11:100.0
0,3,11:100.0
1,3,11:100.0
2,3,11:100.0
3,3,11:100.0
4,3,11:159.4
5,3,11:159.4
6,3,11:159.4
7,3,11:100.0
-7,4,11:100.0
-6,4,11:159.4
-5,4,11:100.0
-4,4,11:100.0
-3,4,11:100.0
-2,4,11:100.0
-1,4,11:100.0
0,4,11:100.0
1,4,11:100.0
2,4,11:100.0
3,4,11:100.0
4,4,11:100.0
5,4,11:100.0
6,4,11:159.4
7,4,11:100.0
-7,5,11:100.0
-6,5,11:159.4
-5,5,11:100.0
-4,5,11:100.0
-3,5,11:100.0
-2,5,11:100.0
-1,5,11:100.0
0,5,11:100.0
1,5,11:100.0
2,5,11:100.0
3,5,11:100.0
4,5,11:100.0
5,5,11:159.4
6,5,11:159.4
7,5,11:100.0
-6,6,11:100.0
-5,6,11:100.0
-4,6,11:100.0
-3,6,11:100.0
-2,6,11:100.0
-1,6,11:100.0
0,6,11:100.0
1,6,11:100.0
2,6,11:159.4
3,6,11:159.4
4,6,11:159.4
5,6,11:159.4
6,6,11:100.0
-4,7,11:100.0
-3,7,11:100.0
-2,7,11:100.0
-1,7,11:100.0
0,7,11:100.0
1,7,11:159.4
2,7,11:159.4
3,7,11:159.4
4,7,11:100.0
5,7,11:100.0
0,8,11:100.0
1,8,11:100.0
2,8,11:100.0
3,8,11:100.0
2,-7,12:159.4
-5,-6,12:159.4
-4,-6,12:159.4
-3,-6,12:159.4
-2,-6,12:82.0
-1,-6,12:82.0
0,-6,12:82.0
1,-6,12:159.4
2,-6,12:159.4
-5,-5,12:159.4
-4,-5,12:159.4
-3,-5,12:159.4
-2,-5,12:82.0
-1,-5,12:82.0
0,-5,12:82.0
1,-5,12:159.4
2,-5,12:159.4
3,-5,12:159.4
4,-5,12:159.4
-6,-4,12:159.4
-5,-4,12:159.4
-4,-4,12:159.4
-3,-4,12:159.4
-2,-4,12:82.0
-1,-4,12:82.0
0,-4,12:82.0
1,-4,12:159.4
2,-4,12:159.4
3,-4,12:159.4
4,-4,12:159.4
5,-4,12:159.4
-6,-3,12:82.0
-5,-3,12:82.0
-4,-3,12:82.0
-3,-3,12:159.4
-2,-3,12:159.4
-1,-3,12:159.4
0,-3,12:159.4
1,-3,12:159.4
2,-3,12:159.4
3,-3,12:159.4
4,-3,12:159.4
5,-3,12:159.4
6,-3,12:159.4
-7,-2,12:159.4
-6,-2,12:82.0
-5,-2,12:82.0
-4,-2,12:100.0
-3,-2,12:159.4
-2,-2,12:159.4
-1,-2,12:159.4
0,-2,12:159.4
1,-2,12:159.4
2,-2,12:159.4
3,-2,12:159.4
4,-2,12:159.4
5,-2,12:159.4
6,-2,12:159.4
7,-2,12:159.4
-7,-1,12:159.4
-6,-1,12:82.0
-5,-1,12:82.0
-4,-1,12:82.0
-3,-1,12:159.4
-2,-1,12:159.4
-1,-1,12:159.4
0,-1,12:159.4
1,-1,12:159.4
2,-1,12:159.4
3,-1,12:159.4
4,-1,12:82.0
5,-1,12:82.0
6,-1,12:82.0
7,-1,12:159.4
-7,0,12:159.4
-6,0,12:159.4
-5,0,12:159.4
-4,0,12:159.4
-3,0,12:159.4
-2,0,12:159.4
-1,0,12:159.4
0,0,12:159.4
1,0,12:159.4
2,0,12:159.4
3,0,12:159.4
4,0,12:82.0
5,0,12:82.0
6,0,12:82.0
7,0,12:159.4
-8,1,12:159.4
-7,1,12:159.4
-6,1,12:159.4
-5,1,12:159.4
-4,1,12:159.4
-3,1,12:159.4
-2,1,12:159.4
0,1,12:159.4
1,1,12:159.4
2,1,12:159.4
3,1,12:159.4
4,1,12:82.0
5,1,12:82.0
6,1,12:82.0
-8,2,12:159.4
-7,2,12:159.4
-6,2,12:159.4
-5,2,12:159.4
-4,2,12:159.4
-3,2,12:159.4
-2,2,12:159.4
-1,2,12:159.4
0,2,12:159.4
1,2,12:159.4
2,2,12:159.4
3,2,12:159.4
4,2,12:159.4
5,2,12:159.4
6,2,12:159.4
-6,3,12:159.4
-5,3,12:159.4
-4,3,12:159.4
-3,3,12:159.4
-2,3,12:159.4
-1,3,12:159.4
0,3,12:159.4
1,3,12:159.4
2,3,12:159.4
3,3,12:159.4
4,3,12:159.4
5,3,12:159.4
6,3,12:159.4
-6,4,12:159.4
-5,4,12:159.4
-4,4,12:159.4
-3,4,12:159.4
-2,4,12:159.4
-1,4,12:159.4
0,4,12:159.4
1,4,12:159.4
2,4,12:159.4
3,4,12:159.4
4,4,12:159.4
5,4,12:159.4
-6,5,12:159.4
-5,5,12:159.4
-4,5,12:159.4
-3,5,12:159.4
-2,5,12:159.4
-1,5,12:159.4
0,5,12:159.4
1,5,12:159.4
2,5,12:159.4
3,5,12:159.4
4,5,12:159.4
5,5,12:159.4
-5,6,12:159.4
-4,6,12:159.4
-3,6,12:159.4
-2,6,12:159.4
-1,6,12:159.4
0,6,12:159.4
1,6,12:82.0
2,6,12:82.0
3,6,12:82.0
4,6,12:159.4
5,6,12:159.4
-5,7,12:100.0
-4,7,12:159.4
-3,7,12:159.4
-2,7,12:159.4
-1,7,12:159.4
0,7,12:159.4
1,7,12:82.0
2,7,12:82.0
3,7,12:82.0
-4,8,12:100.0
-3,8,12:100.0
-2,8,12:100.0
-1,8,12:100.0
0,8,12:100.0
2,-7,13:159.4
2,-6,13:159.4
1,-5,13:159.4
2,-5,13:159.4
-3,-4,13:159.4
-2,-4,13:159.4
-1,-4,13:159.4
0,-4,13:159.4
1,-4,13:159.4
2,-4,13:159.4
-4,-3,13:159.4
-3,-3,13:159.4
-2,-3,13:159.4
-1,-3,13:159.4
0,-3,13:159.4
1,-3,13:159.4
2,-3,13:159.4
3,-3,13:159.4
-4,-2,13:159.4
-3,-2,13:159.4
-2,-2,13:159.4
-1,-2,13:100.0
0,-2,13:159.4
1,-2,13:159.4
2,-2,13:159.4
3,-2,13:159.4
4,-2,13:159.4
-5,-1,13:159.4
-4,-1,13:159.4
-3,-1,13:159.4
-2,-1,13:100.0
-1,-1,13:100.0
0,-1,13:159.4
1,-1,13:100.0
2,-1,13:100.0
3,-1,13:159.4
4,-1,13:159.4
5,-1,13:159.4
-7,0,13:159.4
-6,0,13:159.4
-5,0,13:159.4
-4,0,13:159.4
-3,0,13:159.4
-2,0,13:159.4
-1,0,13:159.4
0,0,13:159.4
1,0,13:159.4
2,0,13:100.0
3,0,13:159.4
4,0,13:159.4
-7,1,13:159.4
-6,1,13:159.4
-5,1,13:159.4
-4,1,13:159.4
-3,1,13:159.4
-2,1,13:100.0
0,1,13:100.0
1,1,13:159.4
2,1,13:159.4
3,1,13:159.4
4,1,13:159.4
-5,2,13:82.0
-4,2,13:82.0
-3,2,13:82.0
-2,2,13:159.4
-1,2,13:100.0
0,2,13:100.0
1,2,13:159.4
2,2,13:159.4
3,2,13:159.4
4,2,13:159.4
-4,3,13:82.0
-3,3,13:82.0
-2,3,13:159.4
-1,3,13:159.4
0,3,13:159.4
1,3,13:159.4
2,3,13:159.4
3,3,13:159.4
-3,4,13:82.0
-2,4,13:159.4
-1,4,13:159.4
0,4,13:159.4
1,4,13:159.4
2,4,13:159.4
3,4,13:159.4
4,4,13:159.4
-3,5,13:159.4
-2,5,13:159.4
-1,5,13:159.4
0,5,13:159.4
1,5,13:159.4
4,5,13:159.4
-2,6,13:159.4
-1,-2,14:159.4
0,-2,14:159.4
-2,-1,14:159.4
-1,-1,14:159.4
0,-1,14:159.4
1,-1,14:159.4
2,-1,14:159.4
-3,0,14:159.4
-2,0,14:159.4
-1,0,14:159.4
0,0,14:159.4
1,0,14:159.4
2,0,14:159.4
3,0,14:159.4
-2,1,14:159.4
0,1,14:159.4
1,1,14:159.4
2,1,14:159.4
-2,2,14:159.4
-1,2,14:159.4
0,2,14:159.4
1,2,14:159.4
2,2,14:159.4
3,-4,15:100.0
4,-3,15:100.0
4,-2,15:100.0
-1,-1,15:159.4
0,-1,15:159.4
4,-1,15:100.0
5,-1,15:100.0
0,0,15:159.4
1,0,15:159.4
2,0,15:100.0
3,0,15:100.0
4,0,15:100.0
5,0,15:100.0
0,1,15:159.4
1,1,15:159.4
4,1,15:100.0
-1,2,15:100.0
4,2,15:100.0
-2,3,15:100.0
-1,3,15:100.0
-2,4,15:100.0
-4,-6,16:100.0
-2,-6,16:100.0
0,-6,16:100.0
-3,-5,16:100.0
-2,-5,16:100.0
-1,-5,16:100.0
0,-5,16:100.0
1,-5,16:100.0
2,-5,16:100.0
3,-5,16:100.0
-4,-4,16:100.0
-3,-4,16:100.0
-2,-4,16:100.0
-1,-4,16:100.0
0,-4,16:100.0
1,-4,16:100.0
2,-4,16:100.0
3,-4,16:159.4
4,-4,16:100.0
-4,-3,16:100.0
-3,-3,16:100.0
-2,-3,16:100.0
-1,-3,16:100.0
0,-3,16:100.0
1,-3,16:100.0
2,-3,16:100.0
3,-3,16:100.0
4,-3,16:159.4
5,-3,16:100.0
-5,-2,16:100.0
-4,-2,16:100.0
-3,-2,16:100.0
-2,-2,16:100.0
-1,-2,16:100.0
0,-2,16:100.0
1,-2,16:100.0
2,-2,16:100.0
3,-2,16:100.0
4,-2,16:159.4
5,-2,16:100.0
-5,-1,16:100.0
-4,-1,16:100.0
-3,-1,16:100.0
-2,-1,16:100.0
-1,-1,16:100.0
0,-1,16:159.4
1,-1,16:100.0
2,-1,16:100.0
3,-1,16:100.0
4,-1,16:159.4
5,-1,16:159.4
6,-1,16:100.0
-5,0,16:100.0
-4,0,16:100.0
-3,0,16:100.0
-2,0,16:100.0
-1,0,16:100.0
0,0,16:159.4
1,0,16:159.4
2,0,16:159.4
3,0,16:159.4
4,0,16:159.4
5,0,16:159.4
6,0,16:100.0
-5,1,16:100.0
-4,1,16:100.0
-3,1,16:100.0
-2,1,16:100.0
0,1,16:159.4
1,1,16:100.0
2,1,16:100.0
3,1,16:100.0
4,1,16:159.4
5,1,16:100.0
-5,2,16:100.0
-4,2,16:100.0
-3,2,16:100.0
-2,2,16:100.0
-1,2,16:159.4
0,2,16:100.0
1,2,16:100.0
2,2,16:100.0
3,2,16:100.0
4,2,16:159.4
5,2,16:100.0
-4,3,16:100.0
-3,3,16:100.0
-2,3,16:159.4
-1,3,16:159.4
0,3,16:100.0
1,3,16:100.0
2,3,16:100.0
3,3,16:100.0
4,3,16:100.0
-3,4,16:100.0
-2,4,16:159.4
-1,4,16:100.0
0,4,16:100.0
1,4,16:100.0
2,4,16:100.0
3,4,16:100.0
4,4,16:100.0
-3,5,16:100.0
1,5,16:100.0
2,5,16:100.0
3,5,16:100.0
-3,-6,17:100.0
-2,-6,17:159.4
-1,-6,17:100.0
0,-6,17:159.4
1,-6,17:100.0
2,-6,17:100.0
-4,-5,17:100.0
-3,-5,17:159.4
-2,-5,17:159.4
-1,-5,17:159.4
0,-5,17:159.4
1,-5,17:159.4
2,-5,17:159.4
3,-5,17:159.4
-5,-4,17:100.0
-4,-4,17:159.4
-3,-4,17:159.4
-2,-4,17:159.4
-1,-4,17:159.4
0,-4,17:159.4
1,-4,17:159.4
2,-4,17:159.4
3,-4,17:159.4
-5,-3,17:100.0
-4,-3,17:159.4
-3,-3,17:159.4
-2,-3,17:159.4
-1,-3,17:159.4
0,-3,17:159.4
1,-3,17:159.4
2,-3,17:159.4
3,-3,17:159.4
4,-3,17:159.4
-6,-2,17:100.0
-5,-2,17:159.4
-4,-2,17:159.4
-3,-2,17:159.4
-2,-2,17:159.4
-1,-2,17:159.4
0,-2,17:159.4
1,-2,17:159.4
2,-2,17:159.4
3,-2,17:159.4
4,-2,17:159.4
-6,-1,17:100.0
-5,-1,17:159.4
-4,-1,17:159.4
-3,-1,17:159.4
-2,-1,17:159.4
-1,-1,17:159.4
0,-1,17:159.4
1,-1,17:159.4
2,-1,17:159.4
3,-1,17:159.4
4,-1,17:159.4
5,-1,17:159.4
-6,0,17:100.0
-5,0,17:159.4
-4,0,17:159.4
-3,0,17:159.4
-2,0,17:159.4
-1,0,17:159.4
0,0,17:159.4
1,0,17:159.4
2,0,17:159.4
3,0,17:159.4
4,0,17:159.4
5,0,17:159.4
-6,1,17:100.0
-5,1,17:159.4
-4,1,17:159.4
-3,1,17:159.4
-2,1,17:159.4
0,1,17:159.4
1,1,17:159.4
2,1,17:159.4
3,1,17:159.4
4,1,17:159.4
-6,2,17:100.0
-5,2,17:159.4
-4,2,17:159.4
-3,2,17:159.4
-2,2,17:159.4
-1,2,17:159.4
0,2,17:159.4
1,2,17:159.4
2,2,17:159.4
3,2,17:159.4
4,2,17:159.4
-5,3,17:100.0
-4,3,17:159.4
-3,3,17:159.4
-2,3,17:159.4
-1,3,17:159.4
0,3,17:159.4
1,3,17:159.4
2,3,17:159.4
3,3,17:159.4
4,3,17:159.4
-4,4,17:100.0
-3,4,17:159.4
-2,4,17:159.4
-1,4,17:159.4
0,4,17:159.4
1,4,17:159.4
2,4,17:159.4
3,4,17:159.4
-3,5,17:159.4
-2,5,17:100.0
-1,5,17:100.0
0,5,17:100.0
1,5,17:159.4
2,5,17:159.4
3,5,17:159.4
1,-5,18:159.4
-2,-4,18:159.4
1,-4,18:82.0
-3,-3,18:159.4
-2,-3,18:159.4
-1,-3,18:159.4
0,-3,18:159.4
1,-3,18:82.0
2,-3,18:82.0
-3,-2,18:82.0
-2,-2,18:159.4
-1,-2,18:159.4
0,-2,18:159.4
1,-2,18:82.0
2,-2,18:82.0
-4,-1,18:82.0
-3,-1,18:82.0
-2,-1,18:159.4
-1,-1,18:159.4
0,-1,18:159.4
1,-1,18:159.4
2,-1,18:159.4
3,-1,18:159.4
4,-1,18:159.4
5,-1,18:159.4
-5,0,18:82.0
-4,0,18:82.0
-3,0,18:82.0
-2,0,18:159.4
-1,0,18:100.0
0,0,18:159.4
1,0,18:159.4
2,0,18:159.4
3,0,18:159.4
-4,1,18:159.4
-3,1,18:159.4
-2,1,18:159.4
0,1,18:159.4
1,1,18:159.4
2,1,18:159.4
-3,2,18:159.4
-2,2,18:159.4
-1,2,18:159.4
0,2,18:82.0
1,2,18:82.0
2,2,18:82.0
-2,3,18:159.4
-1,3,18:159.4
0,3,18:82.0
1,3,18:82.0
-2,4,18:159.4
0,-2,19:159.4
-2,-1,19:159.4
-1,-1,19:159.4
0,-1,19:159.4
1,-1,19:159.4
-2,0,19:159.4
-1,0,19:159.4
0,0,19:159.4
1,0,19:159.4
0,1,19:159.4
-2,-4,20:100.0
-1,-4,20:100.0
0,-4,20:100.0
1,-4,20:100.0
-3,-3,20:100.0
-2,-3,20:100.0
-1,-3,20:100.0
0,-3,20:100.0
1,-3,20:100.0
2,-3,20:100.0
-3,-2,20:100.0
-2,-2,20:100.0
-1,-2,20:100.0
0,-2,20:159.4
1,-2,20:100.0
2,-2,20:100.0
3,-2,20:100.0
-4,-1,20:100.0
-3,-1,20:100.0
-2,-1,20:100.0
-1,-1,20:159.4
0,-1,20:159.4
1,-1,20:100.0
2,-1,20:100.0
3,-1,20:100.0
4,-1,20:100.0
-4,0,20:100.0
-3,0,20:100.0
-2,0,20:100.0
-1,0,20:100.0
0,0,20:100.0
1,0,20:100.0
2,0,20:100.0
3,0,20:100.0
4,0,20:100.0
-4,1,20:100.0
-3,1,20:100.0
-2,1,20:100.0
0,1,20:100.0
1,1,20:100.0
2,1,20:100.0
3,1,20:100.0
-3,2,20:100.0
-2,2,20:100.0
-1,2,20:100.0
0,2,20:100.0
1,2,20:100.0
2,2,20:100.0
3,2,20:100.0
-2,3,20:100.0
-1,3,20:100.0
0,3,20:100.0
1,3,20:100.0
2,3,20:100.0
-2,-4,21:159.4
-1,-4,21:159.4
0,-4,21:159.4
1,-4,21:159.4
-3,-3,21:159.4
-2,-3,21:159.4
-1,-3,21:159.4
0,-3,21:159.4
1,-3,21:159.4
2,-3,21:159.4
-3,-2,21:159.4
-2,-2,21:159.4
-1,-2,21:159.4
0,-2,21:159.4
1,-2,21:159.4
2,-2,21:159.4
3,-2,21:159.4
-4,-1,21:159.4
-3,-1,21:159.4
-2,-1,21:159.4
-1,-1,21:159.4
0,-1,21:159.4
1,-1,21:159.4
2,-1,21:159.4
3,-1,21:159.4
4,-1,21:159.4
-4,0,21:159.4
-3,0,21:159.4
-2,0,21:159.4
-1,0,21:159.4
0,0,21:159.4
1,0,21:159.4
2,0,21:159.4
3,0,21:159.4
4,0,21:159.4
-4,1,21:159.4
-3,1,21:159.4
-2,1,21:159.4
-1,1,21:100.0
0,1,21:159.4
1,1,21:159.4
2,1,21:159.4
3,1,21:159.4
-3,2,21:159.4
-2,2,21:159.4
-1,2,21:159.4
0,2,21:159.4
1,2,21:159.4
2,2,21:159.4
3,2,21:159.4
-2,3,21:159.4
-1,3,21:159.4
0,3,21:159.4
1,3,21:159.4
2,3,21:159.4
1,-3,22:159.4
-1,-2,22:159.4
0,-2,22:159.4
1,-2,22:159.4
-3,-1,22:159.4
-2,-1,22:159.4
-1,-1,22:159.4
0,-1,22:82.0
1,-1,22:82.0
2,-1,22:82.0
-2,0,22:159.4
-1,0,22:159.4
0,0,22:82.0
1,0,22:82.0
-1,1,22:159.4
0,1,22:82.0
1,1,22:82.0
2,1,22:82.0
