[META]
version=2.0
spawnOnBlockType=2
spawnSunlight=True
spawnDarkness=True
spawnWater=False
spawnLava=False
underFill=False
randomRotation=True
dig=True
tree=False
branch=False
needsFoundation=True
rarity=100
collisionPercentage=20
spawnElevationMin=0
spawnElevationMax=200
spawnInBiome=Custom
[DATA]
0,-2,-6:100.15
-2,-1,-6:100.15
0,-1,-6:100.15
1,-1,-6:100.15
-1,0,-6:100.15
0,0,-6:100.15
1,0,-6:100.15
2,0,-6:100.15
0,1,-6:100.15
-3,-2,-5:100.15
-2,-2,-5:100.15
-1,-2,-5:100.15
0,-2,-5:100.15
1,-2,-5:100.15
-3,-1,-5:100.15
-2,-1,-5:100.15
1,-1,-5:100.15
2,-1,-5:100.15
-3,0,-5:100.15
-2,0,-5:100.15
-1,0,-5:100.15
0,0,-5:100.15
1,0,-5:100.15
-3,1,-5:100.15
-1,1,-5:100.15
0,1,-5:100.15
-1,2,-5:100.15
1,2,-5:100.15
-4,-3,-4:100.15
-4,-2,-4:100.15
-3,-2,-4:100.15
-1,-2,-4:100.15
0,-2,-4:100.15
1,-2,-4:100.15
-3,-1,-4:100.15
-2,-1,-4:100.15
-1,-1,-4:100.15
0,-1,-4:100.15
1,-1,-4:100.15
2,-1,-4:100.15
3,-1,-4:100.15
-3,0,-4:100.15
-2,0,-4:100.15
-1,0,-4:100.15
0,0,-4:100.15
1,0,-4:100.15
2,0,-4:100.15
-3,1,-4:100.15
-2,1,-4:100.15
-1,1,-4:100.15
0,1,-4:100.15
1,1,-4:100.15
-1,2,-4:100.15
0,2,-4:100.15
2,2,-4:100.15
-2,-4,-3:100.15
-3,-3,-3:100.15
-2,-3,-3:100.15
-4,-2,-3:100.15
-3,-2,-3:100.15
-2,-2,-3:100.15
-1,-2,-3:100.15
0,-2,-3:100.15
1,-2,-3:100.15
-4,-1,-3:100.15
-3,-1,-3:100.15
-2,-1,-3:100.15
-1,-1,-3:100.15
0,-1,-3:100.15
1,-1,-3:100.15
2,-1,-3:100.15
-4,0,-3:100.15
-3,0,-3:100.15
-2,0,-3:100.15
-1,0,-3:100.15
0,0,-3:100.15
1,0,-3:100.15
2,0,-3:100.15
-4,1,-3:100.15
-2,1,-3:100.15
-1,1,-3:100.15
0,1,-3:100.15
1,1,-3:100.15
2,1,-3:100.15
3,1,-3:100.15
-3,2,-3:100.15
-2,2,-3:100.15
-1,2,-3:100.15
0,2,-3:100.15
2,2,-3:100.15
-1,3,-3:100.15
0,3,-3:100.15
1,3,-3:100.15
-3,-4,-2:100.15
-2,-4,-2:100.15
-2,-3,-2:100.15
-1,-3,-2:100.15
-3,-2,-2:100.15
-2,-2,-2:100.15
0,-2,-2:100.15
-4,-1,-2:100.15
-1,-1,-2:100.15
0,-1,-2:100.15
4,-1,-2:100.15
-3,0,-2:100.15
-1,0,-2:100.15
0,0,-2:100.15
1,0,-2:100.15
3,0,-2:100.15
-3,1,-2:100.15
0,1,-2:100.15
1,1,-2:100.15
2,1,-2:100.15
-1,2,-2:100.15
0,2,-2:100.15
1,2,-2:100.15
-1,3,-2:100.15
0,3,-2:100.15
-3,-3,-1:100.15
-2,-3,-1:100.15
-1,-3,-1:100.15
0,-3,-1:100.15
1,-3,-1:100.15
-3,-2,-1:100.15
-2,-2,-1:100.15
-1,-2,-1:100.15
0,-2,-1:100.15
1,-2,-1:100.15
2,-2,-1:100.15
3,-2,-1:100.15
-3,-1,-1:100.15
-2,-1,-1:100.15
-1,-1,-1:100.15
0,-1,-1:100.15
1,-1,-1:100.15
2,-1,-1:100.15
3,-1,-1:100.15
4,-1,-1:100.15
-3,0,-1:100.15
-2,0,-1:100.15
-1,0,-1:100.15
0,0,-1:100.15
1,0,-1:100.15
2,0,-1:100.15
3,0,-1:100.15
-3,1,-1:100.15
-2,1,-1:100.15
-1,1,-1:100.15
1,1,-1:100.15
2,1,-1:100.15
3,1,-1:100.15
-2,2,-1:100.15
-1,2,-1:100.15
0,2,-1:100.15
1,2,-1:100.15
2,2,-1:100.15
3,2,-1:100.15
-2,3,-1:100.15
-1,3,-1:100.15
0,3,-1:100.15
-1,-4,0:159.4
0,-4,0:100.0
-2,-3,0:159.4
-1,-3,0:100.15
0,-3,0:100.15
1,-3,0:100.15
2,-3,0:100.0
3,-3,0:100.0
4,-3,0:100.0
-2,-2,0:100.15
-1,-2,0:100.15
0,-2,0:100.15
1,-2,0:100.15
2,-2,0:100.15
3,-2,0:159.4
4,-2,0:159.4
-2,-1,0:100.15
-1,-1,0:100.15
0,-1,0:159.4
1,-1,0:100.15
2,-1,0:100.15
3,-1,0:100.15
4,-1,0:159.4
-2,0,0:100.15
1,0,0:159.4
2,0,0:100.15
3,0,0:100.15
4,0,0:100.0
5,0,0:100.0
-2,1,0:100.15
-1,1,0:100.15
1,1,0:159.4
2,1,0:159.4
3,1,0:159.4
4,1,0:100.0
-1,2,0:100.15
0,2,0:100.15
1,2,0:100.15
2,2,0:100.15
3,2,0:159.4
-1,3,0:100.15
0,3,0:159.4
1,3,0:100.0
2,-8,1:100.0
2,-7,1:100.0
0,-4,1:159.4
-2,-3,1:159.4
-1,-3,1:159.4
0,-3,1:159.4
1,-3,1:159.4
2,-3,1:159.4
3,-3,1:159.4
4,-3,1:159.4
-2,-2,1:100.15
-1,-2,1:100.15
0,-2,1:159.4
1,-2,1:159.4
2,-2,1:159.4
3,-2,1:159.4
-1,-1,1:100.15
0,-1,1:159.4
1,-1,1:100.15
2,-1,1:159.4
3,-1,1:159.4
4,-1,1:159.4
-2,0,1:100.15
-1,0,1:100.15
1,0,1:159.4
2,0,1:100.15
3,0,1:159.4
4,0,1:159.4
5,0,1:159.4
-1,1,1:100.15
1,1,1:159.4
2,1,1:159.4
3,1,1:159.4
4,1,1:159.4
-1,2,1:100.15
0,2,1:159.4
1,2,1:159.4
2,2,1:159.4
-1,3,1:100.15
0,3,1:159.4
1,3,1:159.4
2,-8,2:100.0
2,-7,2:100.0
0,-3,2:159.4
1,-3,2:159.4
2,-3,2:159.4
-1,-2,2:100.15
0,-2,2:100.15
1,-2,2:159.4
2,-2,2:159.4
-3,-1,2:100.0
-1,-1,2:100.15
0,-1,2:159.4
1,-1,2:100.15
2,-1,2:100.15
3,-1,2:100.15
-1,0,2:100.15
2,0,2:100.15
-1,1,2:100.15
0,1,2:100.15
1,1,2:100.15
2,1,2:100.15
0,2,2:100.15
1,2,2:159.4
2,-8,3:100.0
2,-7,3:100.0
2,-5,3:100.0
-2,-2,3:100.0
0,-2,3:100.15
1,-2,3:100.15
-3,-1,3:100.0
-1,-1,3:100.15
1,-1,3:100.15
2,-1,3:159.4
-1,0,3:100.15
1,0,3:100.15
2,0,3:100.15
-1,1,3:100.15
0,1,3:100.15
1,1,3:100.15
-1,2,3:100.0
-14,4,3:100.0
-1,4,3:100.0
-2,6,3:100.0
-1,7,3:100.0
-3,10,3:100.0
-4,12,3:100.0
4,-14,4:100.0
3,-9,4:100.0
2,-8,4:100.0
2,-7,4:100.0
2,-5,4:100.0
-2,-3,4:100.0
-1,-3,4:100.0
-2,-2,4:100.0
-1,-2,4:100.15
0,-2,4:100.15
1,-2,4:100.15
-3,-1,4:100.0
-1,-1,4:100.15
1,-1,4:100.15
2,-1,4:159.4
5,-1,4:100.0
-3,0,4:100.0
-2,0,4:100.0
-1,0,4:100.15
1,0,4:100.15
2,0,4:159.4
-13,1,4:100.0
-1,1,4:100.15
0,1,4:100.15
1,1,4:100.15
2,1,4:100.0
-13,2,4:100.0
-1,2,4:100.0
0,2,4:100.0
-1,4,4:100.0
-3,6,4:100.0
-2,6,4:100.0
-12,7,4:100.0
-3,7,4:100.0
-2,7,4:100.0
-1,7,4:100.0
0,7,4:100.0
-4,8,4:100.0
-3,8,4:100.0
-2,8,4:100.0
-1,8,4:100.0
0,8,4:100.0
-3,9,4:100.0
-2,9,4:100.0
-3,10,4:100.0
-4,12,4:100.0
1,-15,5:100.0
4,-15,5:100.0
0,-14,5:100.0
4,-14,5:100.0
0,-13,5:100.0
1,-13,5:100.0
2,-13,5:100.0
3,-13,5:100.0
4,-13,5:100.0
7,-13,5:100.0
3,-12,5:100.0
4,-12,5:100.0
3,-11,5:100.0
3,-10,5:100.0
2,-9,5:100.0
3,-9,5:100.0
2,-8,5:100.0
2,-7,5:100.0
2,-6,5:100.0
2,-5,5:100.0
-2,-3,5:100.0
-1,-3,5:100.0
0,-3,5:100.0
1,-3,5:100.0
-2,-2,5:100.0
-1,-2,5:100.15
0,-2,5:100.15
1,-2,5:100.15
2,-2,5:100.0
-15,-1,5:100.0
-3,-1,5:100.0
-1,-1,5:100.15
1,-1,5:100.15
2,-1,5:100.0
4,-1,5:100.0
5,-1,5:100.0
-2,0,5:100.0
-1,0,5:100.15
1,0,5:100.15
2,0,5:100.0
-13,1,5:100.0
-12,1,5:100.0
-11,1,5:100.0
-10,1,5:100.0
-2,1,5:100.0
-1,1,5:100.0
0,1,5:100.15
1,1,5:100.15
2,1,5:100.0
-13,2,5:100.0
-12,2,5:100.0
-10,2,5:100.0
-9,2,5:100.0
-1,2,5:100.0
0,2,5:100.0
1,2,5:100.0
-13,3,5:100.0
3,3,5:100.0
-13,4,5:100.0
-1,4,5:100.0
-15,5,5:159.4
-14,5,5:100.0
-13,5,5:100.0
-4,5,5:100.0
-3,5,5:100.0
-1,5,5:100.0
5,5,5:100.0
-13,6,5:100.0
-11,6,5:100.0
-3,6,5:100.0
-2,6,5:100.0
-3,7,5:100.0
-2,7,5:100.0
-1,7,5:100.0
0,7,5:100.0
1,7,5:100.0
12,7,5:100.0
-4,8,5:100.0
-3,8,5:100.0
-2,8,5:159.4
-1,8,5:100.0
0,8,5:100.0
-4,9,5:100.0
-3,9,5:100.0
-2,9,5:100.0
9,9,5:100.0
-3,10,5:100.0
-2,10,5:100.0
-4,11,5:100.0
-4,12,5:100.0
1,-15,6:159.4
4,-15,6:159.4
5,-15,6:100.0
4,-14,6:100.0
1,-13,6:100.0
2,-13,6:100.0
4,-13,6:100.0
7,-13,6:159.4
8,-13,6:100.0
3,-12,6:100.0
4,-12,6:100.0
3,-11,6:100.0
-9,-10,6:100.0
2,-10,6:100.0
3,-10,6:100.0
-7,-9,6:100.0
1,-9,6:100.0
3,-9,6:100.0
2,-8,6:100.0
3,-8,6:100.0
2,-7,6:100.0
2,-6,6:100.0
2,-5,6:100.0
1,-4,6:100.0
-2,-3,6:100.0
-1,-3,6:100.0
0,-3,6:100.0
1,-3,6:100.0
-2,-2,6:100.0
-1,-2,6:100.15
0,-2,6:100.15
1,-2,6:100.15
2,-2,6:100.0
7,-2,6:100.0
-15,-1,6:159.4
-3,-1,6:100.0
-2,-1,6:100.15
-1,-1,6:100.15
1,-1,6:100.15
2,-1,6:100.0
4,-1,6:100.0
5,-1,6:100.0
-9,0,6:100.0
-8,0,6:100.0
-2,0,6:100.0
-1,0,6:100.15
1,0,6:100.15
2,0,6:100.0
-13,1,6:100.0
-12,1,6:100.0
-11,1,6:100.0
-10,1,6:100.0
-2,1,6:100.0
-1,1,6:100.0
0,1,6:100.15
1,1,6:100.0
2,1,6:100.0
-15,2,6:100.0
-14,2,6:100.0
-13,2,6:100.0
-12,2,6:100.0
-11,2,6:100.0
-10,2,6:100.0
-9,2,6:100.0
-1,2,6:100.0
0,2,6:100.0
1,2,6:100.0
-15,3,6:100.0
-13,3,6:100.0
-12,3,6:100.0
-10,3,6:100.0
-9,3,6:100.0
-1,3,6:100.0
3,3,6:100.0
-14,4,6:100.0
-13,4,6:100.0
-11,4,6:100.0
-10,4,6:100.0
-1,4,6:100.0
-14,5,6:100.0
-12,5,6:100.0
-11,5,6:100.0
-4,5,6:100.0
-3,5,6:100.0
-1,5,6:100.0
5,5,6:100.0
-14,6,6:100.0
-13,6,6:100.0
-12,6,6:100.0
-11,6,6:100.0
-2,6,6:100.0
-10,7,6:100.0
-4,7,6:100.0
-3,7,6:100.0
-2,7,6:159.4
-1,7,6:159.4
0,7,6:100.0
12,7,6:159.4
-3,8,6:100.0
-2,8,6:159.4
0,8,6:100.0
12,8,6:100.0
-5,9,6:100.0
-4,9,6:100.0
-3,9,6:100.0
-2,9,6:100.0
-1,9,6:100.0
9,9,6:100.0
-3,10,6:100.0
10,10,6:100.0
-4,11,6:100.0
10,11,6:100.0
-4,12,6:100.0
-4,13,6:100.0
3,-16,7:100.0
5,-16,7:100.0
0,-15,7:100.0
1,-15,7:159.4
2,-15,7:100.0
4,-15,7:159.4
5,-15,7:159.4
6,-15,7:100.0
-6,-14,7:100.0
-5,-14,7:100.0
1,-14,7:100.0
4,-14,7:100.0
7,-14,7:100.0
-9,-13,7:100.0
1,-13,7:100.0
2,-13,7:100.0
4,-13,7:100.0
7,-13,7:159.4
8,-13,7:159.4
2,-12,7:100.0
3,-12,7:100.0
4,-12,7:100.0
2,-11,7:100.0
3,-11,7:100.0
-12,-10,7:100.0
-9,-10,7:100.0
2,-10,7:100.0
3,-10,7:100.0
-7,-9,7:100.0
3,-9,7:100.0
-13,-8,7:100.0
-7,-8,7:100.0
2,-8,7:100.0
3,-8,7:100.0
12,-8,7:100.0
-6,-7,7:100.0
-5,-7,7:100.0
2,-7,7:100.0
-13,-6,7:100.0
2,-6,7:100.0
2,-5,7:100.0
-14,-4,7:100.0
1,-4,7:100.0
2,-4,7:100.0
-2,-3,7:100.0
-1,-3,7:100.0
0,-3,7:100.0
1,-3,7:100.0
-2,-2,7:100.0
-1,-2,7:100.15
0,-2,7:100.15
1,-2,7:100.15
2,-2,7:100.0
7,-2,7:100.0
15,-2,7:100.0
-15,-1,7:159.4
-3,-1,7:100.0
-2,-1,7:100.15
-1,-1,7:100.15
1,-1,7:100.15
2,-1,7:100.0
3,-1,7:100.0
4,-1,7:100.0
5,-1,7:100.0
-15,0,7:100.0
-9,0,7:100.0
-8,0,7:100.0
-7,0,7:100.0
-6,0,7:100.0
-2,0,7:100.0
-1,0,7:100.15
0,0,7:100.15
1,0,7:100.15
2,0,7:100.0
-15,1,7:100.0
-13,1,7:100.0
-12,1,7:100.0
-11,1,7:100.0
-10,1,7:100.0
-9,1,7:100.0
-2,1,7:100.0
-1,1,7:100.0
0,1,7:100.15
1,1,7:100.0
2,1,7:100.0
14,1,7:100.0
-16,2,7:100.0
-15,2,7:100.0
-14,2,7:100.0
-13,2,7:100.0
-12,2,7:100.0
-11,2,7:100.0
-10,2,7:100.0
-1,2,7:100.0
0,2,7:100.0
1,2,7:100.0
2,2,7:100.0
-16,3,7:100.0
-15,3,7:100.0
-14,3,7:100.0
-10,3,7:100.0
-1,3,7:100.0
3,3,7:100.0
-15,4,7:100.0
-14,4,7:159.4
-13,4,7:159.4
-10,4,7:100.0
-1,4,7:100.0
-15,5,7:159.4
-14,5,7:159.4
-13,5,7:100.0
-10,5,7:100.0
-4,5,7:100.0
-1,5,7:100.0
5,5,7:100.0
-14,6,7:159.4
-13,6,7:159.4
-12,6,7:159.4
-11,6,7:159.4
-4,6,7:100.0
-3,6,7:100.0
-2,6,7:100.0
-1,6,7:100.0
6,6,7:100.0
-11,7,7:100.0
-4,7,7:100.0
-2,7,7:159.4
-1,7,7:159.4
0,7,7:100.0
7,7,7:100.0
12,7,7:159.4
-11,8,7:100.0
-2,8,7:100.0
-1,8,7:100.0
12,8,7:159.4
-5,9,7:100.0
-4,9,7:100.0
-3,9,7:100.0
-2,9,7:100.0
-1,9,7:100.0
0,9,7:100.0
9,9,7:100.0
11,9,7:100.0
-3,10,7:100.0
-2,10,7:100.0
-1,10,7:100.0
10,10,7:100.0
11,10,7:100.0
-9,11,7:100.0
-4,11,7:100.0
10,11,7:159.4
-4,12,7:100.0
8,12,7:100.0
9,12,7:100.0
-7,13,7:100.0
-4,13,7:159.4
4,13,7:100.0
-5,14,7:100.0
-3,14,7:100.0
0,14,7:100.0
3,-16,8:159.4
4,-16,8:100.0
5,-16,8:159.4
0,-15,8:159.4
1,-15,8:159.4
2,-15,8:159.4
4,-15,8:159.4
5,-15,8:159.4
6,-15,8:159.4
-6,-14,8:159.4
-5,-14,8:159.4
-3,-14,8:100.0
-2,-14,8:100.0
1,-14,8:100.0
4,-14,8:100.0
7,-14,8:159.4
-9,-13,8:159.4
4,-13,8:100.0
7,-13,8:159.4
8,-13,8:159.4
4,-12,8:100.0
-10,-11,8:100.0
-9,-11,8:100.0
2,-11,8:100.0
3,-11,8:100.0
9,-11,8:100.0
10,-11,8:100.0
-12,-10,8:159.4
-9,-10,8:100.0
-8,-10,8:100.0
2,-10,8:100.0
3,-10,8:100.0
-7,-9,8:100.0
3,-9,8:100.0
11,-9,8:100.0
-13,-8,8:159.4
-7,-8,8:100.0
-6,-8,8:100.0
2,-8,8:100.0
3,-8,8:100.0
12,-8,8:159.4
-13,-7,8:100.0
-6,-7,8:100.0
-5,-7,8:100.0
2,-7,8:100.0
-13,-6,8:159.4
-5,-6,8:100.0
-4,-6,8:100.0
2,-6,8:100.0
14,-6,8:100.0
-3,-5,8:100.0
2,-5,8:100.0
-14,-4,8:159.4
1,-4,8:100.0
2,-4,8:100.0
-2,-3,8:100.0
-1,-3,8:100.0
0,-3,8:100.0
1,-3,8:100.0
12,-3,8:100.0
-15,-2,8:100.0
-2,-2,8:100.0
-1,-2,8:100.15
0,-2,8:100.15
1,-2,8:100.15
2,-2,8:100.0
7,-2,8:100.0
8,-2,8:100.0
15,-2,8:159.4
-15,-1,8:159.4
-5,-1,8:100.0
-3,-1,8:100.0
-2,-1,8:100.15
1,-1,8:100.15
2,-1,8:100.0
3,-1,8:100.0
4,-1,8:100.0
5,-1,8:100.0
-15,0,8:159.4
-14,0,8:159.4
-8,0,8:100.0
-7,0,8:100.0
-6,0,8:100.0
-5,0,8:100.0
-2,0,8:100.0
-1,0,8:100.15
1,0,8:100.15
2,0,8:100.0
-15,1,8:159.4
-14,1,8:100.0
-12,1,8:100.0
-11,1,8:100.0
-10,1,8:100.0
-9,1,8:100.0
-2,1,8:100.0
-1,1,8:100.15
0,1,8:100.15
1,1,8:100.0
2,1,8:100.0
14,1,8:159.4
-16,2,8:159.4
-15,2,8:100.0
-14,2,8:100.0
-13,2,8:100.0
-12,2,8:100.0
-11,2,8:100.0
-10,2,8:100.0
-1,2,8:100.0
0,2,8:100.0
1,2,8:100.0
2,2,8:100.0
-16,3,8:159.4
-15,3,8:159.4
-14,3,8:100.0
-13,3,8:159.4
-10,3,8:100.0
-1,3,8:100.0
3,3,8:100.0
-15,4,8:159.4
-14,4,8:159.4
-9,4,8:100.0
-1,4,8:100.0
4,4,8:100.0
13,4,8:100.0
-14,5,8:159.4
-13,5,8:159.4
-10,5,8:159.4
-1,5,8:100.0
5,5,8:100.0
13,5,8:100.0
-14,6,8:159.4
-13,6,8:159.4
-12,6,8:159.4
-11,6,8:159.4
-10,6,8:159.4
-2,6,8:100.0
-1,6,8:159.4
6,6,8:100.0
-11,7,8:159.4
-10,7,8:100.0
-4,7,8:100.0
-3,7,8:100.0
-2,7,8:100.0
-1,7,8:100.0
0,7,8:100.0
1,7,8:100.0
7,7,8:100.0
12,7,8:159.4
-11,8,8:159.4
-4,8,8:100.0
-3,8,8:100.0
-2,8,8:100.0
0,8,8:100.0
8,8,8:100.0
12,8,8:159.4
-5,9,8:100.0
-4,9,8:100.0
-3,9,8:100.0
-2,9,8:100.0
-1,9,8:100.0
8,9,8:100.0
9,9,8:100.0
11,9,8:159.4
-10,10,8:100.0
-3,10,8:100.0
9,10,8:100.0
10,10,8:100.0
11,10,8:159.4
-9,11,8:159.4
-4,11,8:100.0
-1,11,8:100.0
10,11,8:100.0
11,11,8:100.0
-4,12,8:100.0
8,12,8:100.0
9,12,8:159.4
10,12,8:100.0
-7,13,8:159.4
-5,13,8:100.0
-4,13,8:159.4
3,13,8:100.0
4,13,8:159.4
-5,14,8:159.4
-3,14,8:159.4
0,14,8:159.4
3,-16,9:159.4
4,-16,9:159.4
5,-16,9:159.4
0,-15,9:159.4
1,-15,9:159.4
2,-15,9:159.4
3,-15,9:100.0
4,-15,9:159.4
5,-15,9:159.4
6,-15,9:159.4
-6,-14,9:159.4
-5,-14,9:159.4
-4,-14,9:100.0
-3,-14,9:159.4
-2,-14,9:159.4
1,-14,9:100.0
4,-14,9:100.0
6,-14,9:100.0
7,-14,9:159.4
-9,-13,9:159.4
1,-13,9:100.0
4,-13,9:100.0
7,-13,9:159.4
8,-13,9:159.4
-11,-12,9:100.0
-10,-12,9:100.0
4,-12,9:100.0
8,-12,9:100.0
-10,-11,9:159.4
-9,-11,9:100.0
1,-11,9:100.0
3,-11,9:100.0
9,-11,9:159.4
10,-11,9:159.4
-12,-10,9:159.4
-9,-10,9:100.0
-8,-10,9:100.0
3,-10,9:100.0
10,-10,9:100.0
-8,-9,9:100.0
-7,-9,9:100.0
3,-9,9:100.0
11,-9,9:159.4
-13,-8,9:159.4
-7,-8,9:100.0
-6,-8,9:100.0
2,-8,9:100.0
3,-8,9:100.0
12,-8,9:159.4
-13,-7,9:159.4
-6,-7,9:100.0
-5,-7,9:100.0
2,-7,9:100.0
-13,-6,9:159.4
-5,-6,9:100.0
-4,-6,9:100.0
2,-6,9:100.0
14,-6,9:159.4
-4,-5,9:100.0
-3,-5,9:100.0
2,-5,9:100.0
-14,-4,9:159.4
-2,-4,9:100.0
1,-4,9:100.0
2,-4,9:100.0
14,-4,9:100.0
-2,-3,9:100.0
-1,-3,9:100.0
0,-3,9:100.0
1,-3,9:100.0
10,-3,9:100.0
12,-3,9:100.0
13,-3,9:100.0
-15,-2,9:159.4
-14,-2,9:100.0
-2,-2,9:100.0
-1,-2,9:100.15
0,-2,9:100.15
1,-2,9:100.15
2,-2,9:100.0
7,-2,9:100.0
8,-2,9:100.0
15,-2,9:159.4
-15,-1,9:159.4
-5,-1,9:100.0
-4,-1,9:100.0
-3,-1,9:100.0
-2,-1,9:100.15
1,-1,9:100.15
2,-1,9:100.0
3,-1,9:100.0
4,-1,9:100.0
5,-1,9:100.0
6,-1,9:100.0
-15,0,9:159.4
-8,0,9:100.0
-7,0,9:100.0
-6,0,9:100.0
-5,0,9:100.0
-2,0,9:100.0
-1,0,9:100.15
1,0,9:100.15
2,0,9:100.0
-15,1,9:159.4
-14,1,9:159.4
-12,1,9:100.0
-11,1,9:100.0
-10,1,9:100.0
-9,1,9:100.0
-8,1,9:100.0
-2,1,9:100.0
-1,1,9:100.15
0,1,9:100.15
1,1,9:100.0
2,1,9:100.0
14,1,9:159.4
-16,2,9:159.4
-15,2,9:159.4
-14,2,9:159.4
-13,2,9:100.0
-12,2,9:100.0
-11,2,9:100.0
-8,2,9:100.0
-7,2,9:100.0
-1,2,9:100.0
0,2,9:100.0
1,2,9:100.0
2,2,9:100.0
-16,3,9:159.4
-15,3,9:159.4
-10,3,9:100.0
-1,3,9:100.0
3,3,9:100.0
-15,4,9:159.4
-14,4,9:159.4
-10,4,9:100.0
-1,4,9:100.0
4,4,9:100.0
13,4,9:159.4
-14,5,9:159.4
-11,5,9:100.0
-10,5,9:159.4
-3,5,9:100.0
-2,5,9:100.0
-1,5,9:100.0
5,5,9:100.0
13,5,9:159.4
-15,6,9:159.4
-14,6,9:159.4
-13,6,9:159.4
-12,6,9:159.4
-2,6,9:100.0
6,6,9:100.0
-11,7,9:159.4
-10,7,9:159.4
-3,7,9:100.0
-2,7,9:100.0
-1,7,9:159.4
0,7,9:100.0
6,7,9:100.0
7,7,9:100.0
12,7,9:159.4
-11,8,9:159.4
-4,8,9:100.0
-3,8,9:100.0
-2,8,9:100.0
-1,8,9:100.0
0,8,9:100.0
7,8,9:100.0
8,8,9:100.0
12,8,9:159.4
-3,9,9:100.0
-2,9,9:100.0
8,9,9:100.0
9,9,9:100.0
11,9,9:159.4
-10,10,9:159.4
-3,10,9:100.0
-2,10,9:100.0
9,10,9:100.0
10,10,9:100.0
11,10,9:159.4
-9,11,9:159.4
-4,11,9:100.0
10,11,9:159.4
11,11,9:159.4
-4,12,9:100.0
6,12,9:159.4
8,12,9:100.0
9,12,9:159.4
10,12,9:159.4
-7,13,9:159.4
-5,13,9:159.4
-4,13,9:159.4
3,13,9:159.4
4,13,9:159.4
-5,14,9:159.4
-3,14,9:159.4
0,14,9:159.4
3,-16,10:159.4
4,-16,10:159.4
5,-16,10:159.4
0,-15,10:159.4
1,-15,10:159.4
2,-15,10:159.4
3,-15,10:159.4
4,-15,10:159.4
5,-15,10:159.4
6,-15,10:159.4
-6,-14,10:159.4
-5,-14,10:159.4
-4,-14,10:159.4
-3,-14,10:159.4
-2,-14,10:159.4
4,-14,10:100.0
6,-14,10:159.4
7,-14,10:159.4
-9,-13,10:159.4
-8,-13,10:100.0
-7,-13,10:100.0
4,-13,10:100.0
7,-13,10:159.4
8,-13,10:159.4
-11,-12,10:159.4
-10,-12,10:159.4
4,-12,10:100.0
8,-12,10:159.4
-10,-11,10:100.0
-9,-11,10:100.0
3,-11,10:100.0
9,-11,10:159.4
10,-11,10:159.4
-12,-10,10:159.4
-9,-10,10:100.0
-8,-10,10:100.0
3,-10,10:100.0
10,-10,10:159.4
-8,-9,10:100.0
-7,-9,10:100.0
3,-9,10:100.0
11,-9,10:159.4
-13,-8,10:159.4
-7,-8,10:100.0
-6,-8,10:100.0
2,-8,10:100.0
3,-8,10:100.0
12,-8,10:159.4
-13,-7,10:159.4
-6,-7,10:100.0
-5,-7,10:100.0
2,-7,10:100.0
-13,-6,10:159.4
-5,-6,10:100.0
-4,-6,10:100.0
2,-6,10:100.0
14,-6,10:159.4
-14,-5,10:100.0
-13,-5,10:159.4
-4,-5,10:100.0
-3,-5,10:100.0
2,-5,10:100.0
-14,-4,10:159.4
-3,-4,10:100.0
-2,-4,10:100.0
1,-4,10:100.0
2,-4,10:100.0
14,-4,10:159.4
15,-4,10:100.0
-14,-3,10:100.0
-2,-3,10:100.0
-1,-3,10:100.0
0,-3,10:100.0
1,-3,10:100.0
10,-3,10:100.0
12,-3,10:100.0
13,-3,10:100.0
-15,-2,10:159.4
-14,-2,10:159.4
-2,-2,10:100.0
-1,-2,10:100.15
0,-2,10:100.15
1,-2,10:100.15
2,-2,10:100.0
7,-2,10:100.0
8,-2,10:100.0
9,-2,10:100.0
10,-2,10:100.0
15,-2,10:159.4
-15,-1,10:159.4
-4,-1,10:100.0
-3,-1,10:100.0
-2,-1,10:100.15
1,-1,10:100.15
2,-1,10:100.0
3,-1,10:100.0
4,-1,10:100.0
5,-1,10:100.0
6,-1,10:100.0
15,-1,10:100.0
-15,0,10:159.4
-14,0,10:159.4
-13,0,10:100.0
-8,0,10:100.0
-7,0,10:100.0
-6,0,10:100.0
-5,0,10:100.0
-2,0,10:100.15
1,0,10:100.15
2,0,10:100.0
14,0,10:100.0
-15,1,10:159.4
-14,1,10:159.4
-13,1,10:100.0
-12,1,10:100.0
-11,1,10:100.0
-10,1,10:100.0
-9,1,10:100.0
-8,1,10:100.0
-2,1,10:100.0
-1,1,10:100.15
0,1,10:100.15
1,1,10:100.15
2,1,10:100.0
14,1,10:159.4
-15,2,10:159.4
-14,2,10:159.4
-13,2,10:159.4
-12,2,10:100.0
-11,2,10:100.0
-10,2,10:100.0
-1,2,10:100.0
0,2,10:100.0
1,2,10:100.0
2,2,10:100.0
-15,3,10:159.4
-14,3,10:159.4
-13,3,10:100.0
-12,3,10:159.4
-11,3,10:100.0
-10,3,10:159.4
-1,3,10:100.0
3,3,10:100.0
13,3,10:100.0
-15,4,10:159.4
-14,4,10:159.4
-13,4,10:100.0
-12,4,10:100.0
-10,4,10:159.4
-9,4,10:100.0
-1,4,10:100.0
4,4,10:100.0
13,4,10:159.4
-14,5,10:159.4
-13,5,10:100.0
-11,5,10:159.4
-2,5,10:100.0
-1,5,10:100.0
5,5,10:100.0
13,5,10:159.4
-13,6,10:159.4
-10,6,10:100.0
-2,6,10:100.0
5,6,10:100.0
6,6,10:100.0
12,6,10:100.0
-12,7,10:100.0
-11,7,10:100.0
-10,7,10:159.4
-3,7,10:100.0
-2,7,10:100.0
-1,7,10:159.4
1,7,10:100.0
6,7,10:100.0
7,7,10:100.0
8,7,10:100.0
12,7,10:159.4
-11,8,10:159.4
-4,8,10:100.0
-3,8,10:100.0
-2,8,10:100.0
0,8,10:100.0
7,8,10:100.0
8,8,10:100.0
9,8,10:100.0
10,8,10:100.0
11,8,10:100.0
12,8,10:159.4
-10,9,10:100.0
-3,9,10:100.0
-2,9,10:100.0
7,9,10:100.0
8,9,10:100.0
9,9,10:100.0
10,9,10:100.0
11,9,10:159.4
-10,10,10:159.4
-9,10,10:100.0
-3,10,10:100.0
-2,10,10:100.0
7,10,10:100.0
8,10,10:100.0
9,10,10:100.0
10,10,10:159.4
11,10,10:159.4
-9,11,10:159.4
-8,11,10:100.0
-4,11,10:100.0
7,11,10:100.0
8,11,10:100.0
9,11,10:100.0
10,11,10:159.4
11,11,10:159.4
-4,12,10:100.0
6,12,10:159.4
8,12,10:159.4
9,12,10:159.4
10,12,10:159.4
-7,13,10:159.4
-5,13,10:159.4
-4,13,10:159.4
2,13,10:100.0
3,13,10:159.4
4,13,10:159.4
5,13,10:100.0
-5,14,10:159.4
-3,14,10:159.4
-1,14,10:100.0
0,14,10:159.4
3,-16,11:159.4
4,-16,11:159.4
5,-16,11:159.4
-2,-15,11:159.4
-1,-15,11:100.0
0,-15,11:159.4
1,-15,11:159.4
2,-15,11:159.4
3,-15,11:159.4
4,-15,11:159.4
5,-15,11:159.4
6,-15,11:82.0
-6,-14,11:159.4
-5,-14,11:159.4
-4,-14,11:159.4
-3,-14,11:159.4
-2,-14,11:159.4
1,-14,11:100.0
2,-14,11:100.0
3,-14,11:100.0
4,-14,11:159.4
5,-14,11:100.0
6,-14,11:82.0
7,-14,11:82.0
-10,-13,11:100.0
-9,-13,11:159.4
-8,-13,11:159.4
-7,-13,11:159.4
1,-13,11:100.0
2,-13,11:100.0
3,-13,11:100.0
4,-13,11:159.4
5,-13,11:100.0
6,-13,11:100.0
7,-13,11:159.4
8,-13,11:159.4
-11,-12,11:159.4
-10,-12,11:159.4
1,-12,11:100.0
2,-12,11:100.0
3,-12,11:100.0
4,-12,11:159.4
5,-12,11:100.0
6,-12,11:100.0
7,-12,11:100.0
8,-12,11:159.4
9,-12,11:159.4
-12,-11,11:100.0
-10,-11,11:159.4
-9,-11,11:100.0
1,-11,11:100.0
2,-11,11:100.0
3,-11,11:100.0
4,-11,11:100.0
5,-11,11:100.0
6,-11,11:100.0
9,-11,11:159.4
-12,-10,11:159.4
-9,-10,11:100.0
-8,-10,11:100.0
1,-10,11:100.0
2,-10,11:100.0
3,-10,11:100.0
4,-10,11:100.0
5,-10,11:100.0
6,-10,11:100.0
10,-10,11:159.4
-8,-9,11:100.0
-7,-9,11:100.0
1,-9,11:100.0
2,-9,11:100.0
3,-9,11:100.0
4,-9,11:100.0
5,-9,11:100.0
11,-9,11:159.4
-13,-8,11:159.4
-7,-8,11:100.0
-6,-8,11:100.0
1,-8,11:100.0
2,-8,11:159.4
3,-8,11:159.4
4,-8,11:100.0
12,-8,11:159.4
-13,-7,11:159.4
-6,-7,11:100.0
-5,-7,11:100.0
1,-7,11:100.0
2,-7,11:159.4
3,-7,11:100.0
4,-7,11:100.0
13,-7,11:100.0
-13,-6,11:159.4
-5,-6,11:100.0
-4,-6,11:100.0
1,-6,11:100.0
2,-6,11:100.0
3,-6,11:100.0
14,-6,11:159.4
-14,-5,11:159.4
-4,-5,11:100.0
-3,-5,11:100.0
1,-5,11:100.0
2,-5,11:100.0
3,-5,11:100.0
15,-5,11:100.0
-14,-4,11:159.4
-13,-4,11:100.0
-12,-4,11:100.0
-3,-4,11:100.0
-2,-4,11:100.0
1,-4,11:100.0
2,-4,11:100.0
14,-4,11:159.4
15,-4,11:159.4
-14,-3,11:159.4
-13,-3,11:100.0
-12,-3,11:100.0
-11,-3,11:100.0
-10,-3,11:100.0
-9,-3,11:100.0
-8,-3,11:100.0
-2,-3,11:100.0
-1,-3,11:100.0
0,-3,11:100.0
1,-3,11:100.0
2,-3,11:100.0
10,-3,11:100.0
11,-3,11:100.0
12,-3,11:100.0
13,-3,11:100.0
15,-3,11:100.0
-14,-2,11:159.4
-13,-2,11:100.0
-12,-2,11:100.0
-11,-2,11:100.0
-10,-2,11:100.0
-9,-2,11:100.0
-8,-2,11:100.0
-7,-2,11:100.0
-6,-2,11:100.0
-5,-2,11:100.0
-4,-2,11:100.0
-2,-2,11:100.0
1,-2,11:100.15
2,-2,11:100.0
6,-2,11:100.0
7,-2,11:100.0
8,-2,11:100.0
9,-2,11:100.0
10,-2,11:100.0
15,-2,11:159.4
-15,-1,11:159.4
-14,-1,11:100.0
-13,-1,11:100.0
-12,-1,11:100.0
-11,-1,11:100.0
-10,-1,11:100.0
-9,-1,11:100.0
-8,-1,11:100.0
-7,-1,11:100.0
-6,-1,11:100.0
-5,-1,11:100.0
-4,-1,11:100.0
-3,-1,11:100.0
-2,-1,11:100.15
2,-1,11:100.15
3,-1,11:100.0
4,-1,11:100.0
5,-1,11:100.0
6,-1,11:100.0
15,-1,11:159.4
-15,0,11:159.4
-13,0,11:159.4
-12,0,11:100.0
-11,0,11:100.0
-10,0,11:100.0
-9,0,11:100.0
-8,0,11:100.0
-7,0,11:100.0
-6,0,11:100.0
-5,0,11:100.0
-4,0,11:100.0
-3,0,11:100.0
-2,0,11:100.0
2,0,11:100.15
14,0,11:159.4
-15,1,11:159.4
-10,1,11:100.0
-9,1,11:100.0
-8,1,11:100.0
-7,1,11:100.0
-6,1,11:100.0
-5,1,11:100.0
-4,1,11:100.0
-3,1,11:100.0
-2,1,11:159.4
-1,1,11:100.15
0,1,11:100.15
1,1,11:100.15
2,1,11:100.0
14,1,11:159.4
-15,2,11:159.4
-12,2,11:159.4
-11,2,11:100.0
-10,2,11:159.4
-9,2,11:100.0
-8,2,11:100.0
-7,2,11:100.0
-6,2,11:100.0
-5,2,11:100.0
-4,2,11:100.0
-3,2,11:100.0
-1,2,11:100.0
0,2,11:100.0
1,2,11:100.0
2,2,11:100.0
3,2,11:100.0
4,2,11:100.0
5,2,11:100.0
-15,3,11:159.4
-13,3,11:159.4
-11,3,11:159.4
-10,3,11:159.4
-9,3,11:100.0
-8,3,11:100.0
-7,3,11:100.0
-5,3,11:100.0
-1,3,11:100.0
2,3,11:100.0
3,3,11:100.0
4,3,11:100.0
5,3,11:100.0
6,3,11:100.0
7,3,11:100.0
8,3,11:100.0
9,3,11:100.0
13,3,11:159.4
-15,4,11:159.4
-14,4,11:159.4
-13,4,11:159.4
-12,4,11:159.4
-11,4,11:100.0
-10,4,11:159.4
-9,4,11:159.4
-8,4,11:100.0
-7,4,11:100.0
-6,4,11:100.0
-1,4,11:100.0
2,4,11:100.0
3,4,11:100.0
4,4,11:100.0
5,4,11:100.0
6,4,11:100.0
7,4,11:100.0
8,4,11:100.0
9,4,11:100.0
10,4,11:100.0
11,4,11:100.0
12,4,11:100.0
13,4,11:159.4
-14,5,11:159.4
-13,5,11:159.4
-12,5,11:159.4
-11,5,11:159.4
-10,5,11:100.0
-9,5,11:100.0
-8,5,11:100.0
-7,5,11:100.0
-1,5,11:100.0
2,5,11:100.0
3,5,11:100.0
4,5,11:100.0
5,5,11:159.4
6,5,11:100.0
7,5,11:100.0
8,5,11:100.0
9,5,11:100.0
10,5,11:100.0
11,5,11:100.0
12,5,11:100.0
13,5,11:159.4
-13,6,11:159.4
-12,6,11:100.0
-11,6,11:159.4
-10,6,11:159.4
-9,6,11:100.0
-8,6,11:100.0
-2,6,11:100.0
2,6,11:100.0
3,6,11:100.0
4,6,11:100.0
5,6,11:159.4
6,6,11:100.0
7,6,11:100.0
8,6,11:100.0
9,6,11:100.0
10,6,11:100.0
11,6,11:100.0
12,6,11:159.4
-12,7,11:159.4
-11,7,11:159.4
-10,7,11:159.4
-9,7,11:100.0
-3,7,11:100.0
-2,7,11:100.0
0,7,11:100.0
2,7,11:100.0
3,7,11:100.0
4,7,11:100.0
5,7,11:100.0
6,7,11:100.0
8,7,11:100.0
9,7,11:100.0
10,7,11:100.0
11,7,11:100.0
12,7,11:159.4
-12,8,11:159.4
-11,8,11:159.4
-3,8,11:100.0
3,8,11:100.0
4,8,11:100.0
5,8,11:100.0
6,8,11:100.0
11,8,11:159.4
12,8,11:159.4
-10,9,11:159.4
-3,9,11:100.0
-2,9,11:100.0
3,9,11:100.0
4,9,11:100.0
5,9,11:100.0
6,9,11:100.0
11,9,11:159.4
-10,10,11:159.4
-9,10,11:159.4
-3,10,11:100.0
3,10,11:100.0
4,10,11:100.0
5,10,11:100.0
6,10,11:100.0
7,10,11:100.0
11,10,11:159.4
-9,11,11:159.4
-8,11,11:159.4
-4,11,11:100.0
3,11,11:100.0
4,11,11:100.0
5,11,11:100.0
6,11,11:100.0
7,11,11:159.4
9,11,11:100.0
10,11,11:159.4
-8,12,11:100.0
-4,12,11:100.0
3,12,11:100.0
4,12,11:100.0
5,12,11:100.0
6,12,11:159.4
8,12,11:159.4
9,12,11:159.4
-7,13,11:159.4
-5,13,11:159.4
-4,13,11:159.4
2,13,11:159.4
3,13,11:159.4
4,13,11:159.4
5,13,11:159.4
-6,14,11:100.0
-5,14,11:159.4
-3,14,11:159.4
-2,14,11:100.0
-1,14,11:159.4
0,14,11:159.4
-4,15,11:100.0
-1,-15,12:159.4
0,-15,12:159.4
1,-15,12:159.4
2,-15,12:159.4
3,-15,12:159.4
4,-15,12:159.4
5,-15,12:82.0
-6,-14,12:159.4
-5,-14,12:159.4
-4,-14,12:159.4
-3,-14,12:159.4
-2,-14,12:159.4
-1,-14,12:100.0
0,-14,12:100.0
6,-14,12:82.0
-10,-13,12:159.4
-9,-13,12:159.4
-8,-13,12:159.4
-7,-13,12:159.4
-5,-13,12:100.0
-4,-13,12:100.0
-3,-13,12:100.0
-2,-13,12:100.0
-1,-13,12:100.0
0,-13,12:100.0
7,-13,12:82.0
8,-13,12:159.4
-11,-12,12:159.4
-10,-12,12:159.4
-5,-12,12:100.0
-4,-12,12:100.0
-3,-12,12:100.0
-2,-12,12:100.0
-1,-12,12:100.0
0,-12,12:100.0
7,-12,12:159.4
8,-12,12:159.4
-12,-11,12:159.4
-10,-11,12:159.4
-9,-11,12:100.0
-5,-11,12:100.0
-4,-11,12:100.0
-3,-11,12:100.0
-2,-11,12:100.0
-1,-11,12:100.0
0,-11,12:100.0
7,-11,12:100.0
8,-11,12:100.0
9,-11,12:159.4
-12,-10,12:159.4
-9,-10,12:100.0
-8,-10,12:100.0
-5,-10,12:100.0
-3,-10,12:100.0
-2,-10,12:100.0
-1,-10,12:100.0
0,-10,12:100.0
6,-10,12:159.4
7,-10,12:100.0
8,-10,12:100.0
9,-10,12:100.0
10,-10,12:159.4
-8,-9,12:100.0
-7,-9,12:100.0
-5,-9,12:100.0
-4,-9,12:100.0
-3,-9,12:100.0
-2,-9,12:100.0
-1,-9,12:100.0
0,-9,12:100.0
1,-9,12:159.4
5,-9,12:159.4
6,-9,12:100.0
7,-9,12:100.0
8,-9,12:100.0
9,-9,12:100.0
10,-9,12:100.0
11,-9,12:159.4
-13,-8,12:159.4
-12,-8,12:100.0
-7,-8,12:100.0
-6,-8,12:100.0
-4,-8,12:100.0
-3,-8,12:100.0
-2,-8,12:100.0
-1,-8,12:100.0
0,-8,12:100.0
1,-8,12:159.4
5,-8,12:100.0
6,-8,12:100.0
7,-8,12:100.0
8,-8,12:100.0
9,-8,12:100.0
10,-8,12:100.0
11,-8,12:100.0
12,-8,12:159.4
-13,-7,12:159.4
-12,-7,12:100.0
-11,-7,12:100.0
-10,-7,12:100.0
-9,-7,12:100.0
-8,-7,12:100.0
-6,-7,12:100.0
-5,-7,12:100.0
-4,-7,12:100.0
-3,-7,12:100.0
-2,-7,12:100.0
-1,-7,12:100.0
0,-7,12:100.0
1,-7,12:159.4
4,-7,12:159.4
5,-7,12:100.0
6,-7,12:100.0
7,-7,12:100.0
8,-7,12:100.0
9,-7,12:100.0
10,-7,12:100.0
13,-7,12:159.4
-13,-6,12:159.4
-12,-6,12:100.0
-11,-6,12:100.0
-10,-6,12:100.0
-9,-6,12:100.0
-8,-6,12:100.0
-7,-6,12:100.0
-6,-6,12:100.0
-5,-6,12:100.0
-4,-6,12:100.0
-3,-6,12:100.0
-2,-6,12:100.0
-1,-6,12:100.0
0,-6,12:100.0
3,-6,12:159.4
4,-6,12:100.0
5,-6,12:100.0
6,-6,12:100.0
7,-6,12:100.0
8,-6,12:100.0
9,-6,12:100.0
14,-6,12:159.4
-13,-5,12:159.4
-12,-5,12:100.0
-11,-5,12:100.0
-10,-5,12:100.0
-9,-5,12:100.0
-8,-5,12:100.0
-7,-5,12:100.0
-6,-5,12:100.0
-5,-5,12:100.0
-4,-5,12:100.0
-3,-5,12:159.4
-2,-5,12:100.0
-1,-5,12:100.0
0,-5,12:100.0
3,-5,12:159.4
4,-5,12:100.0
5,-5,12:100.0
6,-5,12:100.0
7,-5,12:100.0
8,-5,12:100.0
9,-5,12:100.0
14,-5,12:100.0
15,-5,12:159.4
-14,-4,12:159.4
-13,-4,12:159.4
-12,-4,12:159.4
-11,-4,12:100.0
-10,-4,12:100.0
-9,-4,12:100.0
-8,-4,12:100.0
-7,-4,12:100.0
-6,-4,12:100.0
-5,-4,12:100.0
-4,-4,12:100.0
-3,-4,12:100.0
-2,-4,12:100.0
-1,-4,12:100.0
0,-4,12:100.0
3,-4,12:100.0
4,-4,12:100.0
5,-4,12:100.0
6,-4,12:100.0
7,-4,12:100.0
8,-4,12:100.0
14,-4,12:159.4
15,-4,12:159.4
-14,-3,12:159.4
-9,-3,12:159.4
-8,-3,12:159.4
-7,-3,12:100.0
-6,-3,12:100.0
-5,-3,12:100.0
-4,-3,12:100.0
-3,-3,12:100.0
-2,-3,12:100.0
-1,-3,12:100.0
0,-3,12:100.0
2,-3,12:100.0
3,-3,12:100.0
4,-3,12:100.0
5,-3,12:100.0
6,-3,12:100.0
7,-3,12:100.0
10,-3,12:100.0
11,-3,12:100.0
12,-3,12:100.0
13,-3,12:100.0
15,-3,12:159.4
-14,-2,12:159.4
-5,-2,12:100.0
-4,-2,12:100.0
-3,-2,12:100.0
-2,-2,12:100.0
-1,-2,12:100.0
2,-2,12:100.0
3,-2,12:100.0
4,-2,12:100.0
5,-2,12:100.0
6,-2,12:159.4
7,-2,12:100.0
8,-2,12:100.0
9,-2,12:100.0
10,-2,12:100.0
15,-2,12:159.4
-14,-1,12:82.0
0,-1,12:100.0
1,-1,12:100.0
2,-1,12:100.0
3,-1,12:100.0
4,-1,12:100.0
5,-1,12:159.4
6,-1,12:159.4
7,-1,12:100.0
8,-1,12:100.0
9,-1,12:100.0
10,-1,12:100.0
14,-1,12:100.0
15,-1,12:159.4
-15,0,12:82.0
0,0,12:100.0
1,0,12:100.0
2,0,12:159.4
3,0,12:100.0
4,0,12:100.0
5,0,12:100.0
6,0,12:100.0
7,0,12:100.0
8,0,12:100.0
9,0,12:100.0
10,0,12:100.0
11,0,12:100.0
12,0,12:100.0
13,0,12:100.0
14,0,12:159.4
-15,1,12:159.4
-13,1,12:159.4
-2,1,12:100.0
-1,1,12:100.0
0,1,12:100.0
2,1,12:159.4
3,1,12:100.0
4,1,12:100.0
5,1,12:100.0
6,1,12:100.0
7,1,12:100.0
8,1,12:100.0
9,1,12:100.0
10,1,12:100.0
11,1,12:100.0
12,1,12:100.0
13,1,12:100.0
14,1,12:159.4
-15,2,12:159.4
-12,2,12:159.4
-11,2,12:159.4
-3,2,12:159.4
-2,2,12:100.0
-1,2,12:100.0
0,2,12:100.0
1,2,12:100.0
4,2,12:100.0
5,2,12:159.4
6,2,12:100.0
7,2,12:100.0
8,2,12:100.0
9,2,12:100.0
10,2,12:100.0
11,2,12:100.0
12,2,12:100.0
13,2,12:100.0
-15,3,12:159.4
-13,3,12:159.4
-10,3,12:159.4
-9,3,12:159.4
-4,3,12:100.0
-3,3,12:100.0
-2,3,12:100.0
-1,3,12:100.0
0,3,12:100.0
1,3,12:100.0
8,3,12:159.4
9,3,12:159.4
10,3,12:100.0
11,3,12:100.0
12,3,12:100.0
13,3,12:159.4
-15,4,12:159.4
-14,4,12:159.4
-10,4,12:159.4
-5,4,12:100.0
-4,4,12:100.0
-3,4,12:100.0
-2,4,12:100.0
-1,4,12:100.0
1,4,12:100.0
2,4,12:100.0
12,4,12:159.4
13,4,12:159.4
-14,5,12:159.4
-13,5,12:159.4
-10,5,12:159.4
-7,5,12:159.4
-6,5,12:100.0
-5,5,12:100.0
-4,5,12:100.0
-3,5,12:100.0
-2,5,12:100.0
-1,5,12:100.0
0,5,12:100.0
1,5,12:100.0
2,5,12:159.4
12,5,12:159.4
13,5,12:159.4
-13,6,12:159.4
-12,6,12:159.4
-8,6,12:159.4
-7,6,12:100.0
-6,6,12:100.0
-5,6,12:100.0
-4,6,12:100.0
-3,6,12:100.0
-2,6,12:100.0
-1,6,12:100.0
0,6,12:100.0
1,6,12:100.0
2,6,12:159.4
12,6,12:159.4
-12,7,12:159.4
-11,7,12:159.4
-10,7,12:159.4
-9,7,12:159.4
-8,7,12:100.0
-7,7,12:100.0
-6,7,12:100.0
-5,7,12:100.0
-4,7,12:100.0
-3,7,12:100.0
-2,7,12:100.0
-1,7,12:100.0
0,7,12:159.4
1,7,12:100.0
2,7,12:159.4
11,7,12:159.4
12,7,12:159.4
-11,8,12:159.4
-10,8,12:100.0
-9,8,12:100.0
-8,8,12:100.0
-7,8,12:100.0
-6,8,12:100.0
-5,8,12:100.0
-4,8,12:100.0
-3,8,12:100.0
-2,8,12:100.0
-1,8,12:100.0
0,8,12:100.0
1,8,12:100.0
2,8,12:100.0
11,8,12:159.4
-10,9,12:159.4
-9,9,12:100.0
-8,9,12:100.0
-7,9,12:100.0
-6,9,12:100.0
-3,9,12:100.0
-2,9,12:100.0
-1,9,12:100.0
0,9,12:100.0
1,9,12:100.0
2,9,12:100.0
11,9,12:159.4
-9,10,12:159.4
-8,10,12:100.0
-7,10,12:100.0
-4,10,12:100.0
-3,10,12:100.0
-1,10,12:100.0
0,10,12:100.0
1,10,12:100.0
2,10,12:100.0
10,10,12:100.0
11,10,12:159.4
-9,11,12:159.4
-8,11,12:159.4
-4,11,12:100.0
-1,11,12:100.0
0,11,12:100.0
1,11,12:100.0
2,11,12:100.0
3,11,12:159.4
7,11,12:159.4
8,11,12:100.0
9,11,12:159.4
10,11,12:159.4
-8,12,12:159.4
-7,12,12:100.0
-4,12,12:100.0
-1,12,12:100.0
0,12,12:100.0
1,12,12:100.0
2,12,12:100.0
3,12,12:159.4
5,12,12:159.4
6,12,12:159.4
8,12,12:159.4
9,12,12:159.4
-7,13,12:159.4
-5,13,12:159.4
-4,13,12:159.4
-1,13,12:100.0
0,13,12:100.0
2,13,12:159.4
3,13,12:159.4
4,13,12:159.4
-6,14,12:159.4
-5,14,12:159.4
-4,14,12:100.0
-3,14,12:159.4
-2,14,12:159.4
-1,14,12:159.4
0,14,12:159.4
-4,15,12:159.4
0,-15,13:159.4
1,-15,13:159.4
2,-15,13:159.4
3,-15,13:159.4
4,-15,13:159.4
5,-15,13:159.4
-6,-14,13:159.4
-5,-14,13:159.4
-4,-14,13:159.4
-3,-14,13:159.4
-2,-14,13:159.4
-1,-14,13:159.4
0,-14,13:159.4
1,-14,13:100.0
5,-14,13:100.0
6,-14,13:82.0
-10,-13,13:159.4
-9,-13,13:159.4
-8,-13,13:159.4
-7,-13,13:159.4
-6,-13,13:100.0
-5,-13,13:159.4
6,-13,13:100.0
7,-13,13:159.4
-11,-12,13:159.4
-10,-12,13:159.4
-9,-12,13:100.0
-8,-12,13:100.0
-7,-12,13:100.0
-6,-12,13:100.0
-5,-12,13:159.4
7,-12,13:159.4
8,-12,13:159.4
-12,-11,13:159.4
-11,-11,13:100.0
-10,-11,13:159.4
-9,-11,13:159.4
-8,-11,13:100.0
-7,-11,13:100.0
-6,-11,13:100.0
-5,-11,13:159.4
8,-11,13:100.0
9,-11,13:159.4
-12,-10,13:159.4
-11,-10,13:100.0
-10,-10,13:100.0
-9,-10,13:100.0
-8,-10,13:100.0
-7,-10,13:100.0
-6,-10,13:100.0
-5,-10,13:159.4
9,-10,13:100.0
10,-10,13:82.0
-11,-9,13:100.0
-10,-9,13:100.0
-9,-9,13:100.0
-8,-9,13:100.0
-7,-9,13:159.4
-6,-9,13:100.0
-5,-9,13:159.4
10,-9,13:100.0
11,-9,13:159.4
-12,-8,13:159.4
-11,-8,13:100.0
-10,-8,13:100.0
-9,-8,13:100.0
-8,-8,13:100.0
-7,-8,13:100.0
-6,-8,13:100.0
-5,-8,13:100.0
11,-8,13:159.4
12,-8,13:159.4
-13,-7,13:159.4
-9,-7,13:159.4
-8,-7,13:159.4
-7,-7,13:100.0
-6,-7,13:100.0
-5,-7,13:159.4
10,-7,13:159.4
11,-7,13:100.0
12,-7,13:100.0
13,-7,13:159.4
-13,-6,13:159.4
-5,-6,13:159.4
10,-6,13:100.0
11,-6,13:100.0
12,-6,13:100.0
13,-6,13:100.0
14,-6,13:159.4
-13,-5,13:159.4
-4,-5,13:159.4
9,-5,13:159.4
10,-5,13:100.0
11,-5,13:100.0
12,-5,13:100.0
13,-5,13:100.0
14,-5,13:159.4
15,-5,13:159.4
-13,-4,13:159.4
-3,-4,13:100.0
8,-4,13:100.0
9,-4,13:100.0
10,-4,13:100.0
11,-4,13:100.0
12,-4,13:100.0
13,-4,13:100.0
14,-4,13:159.4
15,-4,13:159.4
-14,-3,13:159.4
-2,-3,13:100.0
8,-3,13:100.0
9,-3,13:100.0
10,-3,13:100.0
11,-3,13:100.0
12,-3,13:100.0
13,-3,13:100.0
14,-3,13:100.0
15,-3,13:159.4
-14,-2,13:159.4
-1,-2,13:159.4
5,-2,13:159.4
6,-2,13:159.4
7,-2,13:159.4
8,-2,13:100.0
9,-2,13:100.0
10,-2,13:100.0
11,-2,13:100.0
12,-2,13:100.0
13,-2,13:100.0
14,-2,13:100.0
15,-2,13:159.4
-14,-1,13:82.0
0,-1,13:159.4
1,-1,13:159.4
2,-1,13:159.4
3,-1,13:159.4
4,-1,13:159.4
5,-1,13:159.4
9,-1,13:100.0
10,-1,13:159.4
11,-1,13:100.0
12,-1,13:100.0
13,-1,13:100.0
14,-1,13:159.4
15,-1,13:159.4
-14,0,13:82.0
0,0,13:159.4
1,0,13:159.4
13,0,13:159.4
14,0,13:159.4
-15,1,13:82.0
-14,1,13:100.0
0,1,13:159.4
14,1,13:159.4
-15,2,13:159.4
-11,2,13:159.4
-10,2,13:159.4
-1,2,13:100.0
0,2,13:100.0
13,2,13:159.4
-15,3,13:159.4
-14,3,13:100.0
-1,3,13:100.0
13,3,13:159.4
-14,4,13:159.4
-13,4,13:100.0
-11,4,13:100.0
-1,4,13:159.4
12,4,13:159.4
13,4,13:159.4
-13,5,13:159.4
-2,5,13:82.0
12,5,13:159.4
-13,6,13:159.4
-12,6,13:159.4
-11,6,13:159.4
-2,6,13:100.0
12,6,13:159.4
-12,7,13:159.4
-11,7,13:159.4
-10,7,13:159.4
-3,7,13:100.0
-2,7,13:82.0
11,7,13:159.4
-11,8,13:159.4
-10,8,13:159.4
-4,8,13:159.4
-3,8,13:159.4
-2,8,13:159.4
11,8,13:159.4
-10,9,13:159.4
-5,9,13:100.0
-4,9,13:100.0
-3,9,13:159.4
-2,9,13:100.0
10,9,13:100.0
11,9,13:159.4
-9,10,13:159.4
-7,10,13:100.0
-6,10,13:100.0
-5,10,13:100.0
-4,10,13:100.0
-3,10,13:100.0
-2,10,13:100.0
10,10,13:159.4
-9,11,13:159.4
-8,11,13:159.4
-7,11,13:100.0
-6,11,13:100.0
-5,11,13:100.0
-4,11,13:100.0
-3,11,13:100.0
-2,11,13:100.0
6,11,13:159.4
7,11,13:159.4
8,11,13:82.0
9,11,13:82.0
10,11,13:82.0
-8,12,13:159.4
-7,12,13:159.4
-6,12,13:100.0
-5,12,13:100.0
-4,12,13:100.0
-3,12,13:100.0
-2,12,13:100.0
-1,12,13:100.0
1,12,13:159.4
3,12,13:159.4
4,12,13:159.4
5,12,13:159.4
6,12,13:159.4
8,12,13:159.4
9,12,13:82.0
-7,13,13:159.4
-6,13,13:100.0
-5,13,13:159.4
-4,13,13:159.4
-3,13,13:100.0
-2,13,13:100.0
-1,13,13:100.0
0,13,13:159.4
2,13,13:159.4
3,13,13:159.4
-6,14,13:159.4
-5,14,13:159.4
-4,14,13:159.4
-3,14,13:159.4
-2,14,13:159.4
-1,14,13:159.4
0,14,13:159.4
-5,15,13:159.4
-4,15,13:159.4
3,-15,14:159.4
4,-15,14:159.4
-4,-14,14:159.4
-3,-14,14:159.4
-2,-14,14:159.4
-1,-14,14:159.4
0,-14,14:82.0
1,-14,14:82.0
2,-14,14:82.0
3,-14,14:100.0
5,-14,14:159.4
-10,-13,14:159.4
-9,-13,14:82.0
-8,-13,14:82.0
-7,-13,14:82.0
-6,-13,14:159.4
-5,-13,14:159.4
-4,-13,14:100.0
6,-13,14:159.4
-11,-12,14:159.4
-10,-12,14:159.4
7,-12,14:159.4
8,-12,14:159.4
-11,-11,14:159.4
8,-11,14:159.4
9,-11,14:82.0
-12,-10,14:159.4
-9,-10,14:159.4
9,-10,14:82.0
10,-10,14:82.0
-11,-9,14:159.4
-8,-9,14:159.4
10,-9,14:82.0
11,-9,14:82.0
-12,-8,14:159.4
-7,-8,14:159.4
11,-8,14:159.4
12,-8,14:159.4
-12,-7,14:159.4
-6,-7,14:159.4
12,-7,14:159.4
13,-7,14:159.4
-13,-6,14:159.4
-12,-6,14:100.0
-5,-6,14:159.4
13,-6,14:159.4
14,-6,14:159.4
-13,-5,14:159.4
-4,-5,14:159.4
14,-5,14:159.4
15,-5,14:159.4
-13,-4,14:159.4
-3,-4,14:159.4
15,-4,14:159.4
-13,-3,14:159.4
-2,-3,14:159.4
9,-3,14:100.0
10,-3,14:100.0
11,-3,14:159.4
12,-3,14:159.4
15,-3,14:159.4
-14,-2,14:159.4
-13,-2,14:100.0
-1,-2,14:159.4
5,-2,14:159.4
6,-2,14:159.4
7,-2,14:159.4
8,-2,14:159.4
9,-2,14:100.0
14,-2,14:82.0
15,-2,14:82.0
-14,-1,14:82.0
0,-1,14:159.4
1,-1,14:159.4
2,-1,14:159.4
3,-1,14:159.4
4,-1,14:159.4
5,-1,14:159.4
14,-1,14:82.0
-14,0,14:82.0
0,0,14:159.4
14,0,14:159.4
-14,1,14:82.0
0,1,14:159.4
13,1,14:100.0
14,1,14:159.4
-15,2,14:159.4
-14,2,14:100.0
-1,2,14:159.4
0,2,14:159.4
13,2,14:159.4
-14,3,14:159.4
-1,3,14:159.4
12,3,14:100.0
13,3,14:159.4
-14,4,14:159.4
-13,4,14:159.4
-11,4,14:159.4
-1,4,14:159.4
12,4,14:159.4
-15,5,14:159.4
-13,5,14:159.4
-12,5,14:100.0
-2,5,14:82.0
12,5,14:159.4
-12,6,14:159.4
-2,6,14:82.0
11,6,14:159.4
-11,7,14:159.4
-2,7,14:82.0
11,7,14:159.4
-11,8,14:159.4
-10,8,14:159.4
-3,8,14:159.4
10,8,14:100.0
11,8,14:159.4
-10,9,14:159.4
-9,9,14:100.0
-3,9,14:159.4
10,9,14:159.4
-9,10,14:159.4
-4,10,14:100.0
-3,10,14:159.4
9,10,14:100.0
10,10,14:82.0
-8,11,14:159.4
-4,11,14:100.0
6,11,14:159.4
7,11,14:159.4
8,11,14:82.0
9,11,14:82.0
-8,12,14:159.4
-7,12,14:159.4
-4,12,14:100.0
1,12,14:159.4
2,12,14:100.0
3,12,14:159.4
4,12,14:159.4
5,12,14:159.4
8,12,14:82.0
-7,13,14:159.4
-6,13,14:159.4
-1,13,14:159.4
0,13,14:159.4
2,13,14:159.4
-6,14,14:159.4
-5,14,14:159.4
-4,14,14:159.4
-3,14,14:82.0
-2,14,14:159.4
-1,14,14:159.4
-2,-14,15:159.4
-1,-14,15:159.4
0,-14,15:82.0
1,-14,15:82.0
2,-14,15:82.0
3,-14,15:159.4
4,-14,15:159.4
5,-14,15:159.4
-8,-13,15:82.0
-7,-13,15:82.0
-6,-13,15:159.4
-5,-13,15:159.4
-4,-13,15:159.4
-3,-13,15:159.4
-2,-13,15:100.0
-1,-13,15:100.0
5,-13,15:100.0
6,-13,15:159.4
-11,-12,15:159.4
-10,-12,15:159.4
-9,-12,15:82.0
-8,-12,15:100.0
6,-12,15:100.0
7,-12,15:159.4
-11,-11,15:159.4
7,-11,15:100.0
8,-11,15:159.4
-11,-10,15:159.4
8,-10,15:100.0
9,-10,15:82.0
-11,-9,15:159.4
-8,-9,15:159.4
9,-9,15:100.0
10,-9,15:82.0
-12,-8,15:159.4
-7,-8,15:159.4
10,-8,15:100.0
11,-8,15:159.4
-12,-7,15:159.4
-6,-7,15:159.4
12,-7,15:159.4
-12,-6,15:159.4
-5,-6,15:159.4
13,-6,15:159.4
-13,-5,15:159.4
-12,-5,15:100.0
-4,-5,15:159.4
14,-5,15:159.4
-13,-4,15:159.4
-3,-4,15:159.4
15,-4,15:159.4
-13,-3,15:159.4
-2,-3,15:159.4
9,-3,15:159.4
10,-3,15:159.4
11,-3,15:159.4
12,-3,15:159.4
14,-3,15:100.0
15,-3,15:82.0
-13,-2,15:159.4
-1,-2,15:159.4
5,-2,15:159.4
6,-2,15:159.4
7,-2,15:159.4
8,-2,15:159.4
9,-2,15:159.4
14,-2,15:82.0
-14,-1,15:159.4
-13,-1,15:100.0
-1,-1,15:100.0
0,-1,15:159.4
1,-1,15:159.4
2,-1,15:159.4
3,-1,15:159.4
4,-1,15:159.4
5,-1,15:159.4
14,-1,15:82.0
-14,0,15:159.4
0,0,15:159.4
13,0,15:159.4
-14,1,15:159.4
0,1,15:159.4
13,1,15:159.4
-14,2,15:159.4
-1,2,15:159.4
0,2,15:159.4
13,2,15:159.4
-14,3,15:159.4
-1,3,15:159.4
12,3,15:159.4
-13,4,15:159.4
-1,4,15:159.4
12,4,15:159.4
-14,5,15:159.4
-13,5,15:159.4
-12,5,15:159.4
-2,5,15:159.4
11,5,15:100.0
12,5,15:159.4
-12,6,15:82.0
-11,6,15:100.0
-2,6,15:159.4
11,6,15:159.4
-11,7,15:82.0
-10,7,15:100.0
-3,7,15:159.4
-2,7,15:159.4
10,7,15:100.0
11,7,15:159.4
-10,8,15:159.4
-3,8,15:159.4
10,8,15:159.4
-9,9,15:159.4
-3,9,15:159.4
10,9,15:159.4
-9,10,15:159.4
-8,10,15:100.0
-4,10,15:159.4
-3,10,15:159.4
8,10,15:100.0
9,10,15:82.0
10,10,15:159.4
-8,11,15:82.0
-4,11,15:159.4
5,11,15:159.4
6,11,15:159.4
7,11,15:159.4
8,11,15:82.0
9,11,15:82.0
-7,12,15:159.4
1,12,15:159.4
2,12,15:159.4
3,12,15:159.4
4,12,15:159.4
-6,13,15:159.4
-5,13,15:159.4
-4,13,15:82.0
-3,13,15:82.0
-2,13,15:82.0
-1,13,15:159.4
0,13,15:159.4
-6,14,15:159.4
1,-14,16:82.0
2,-14,16:82.0
3,-14,16:159.4
4,-14,16:159.4
5,-14,16:159.4
-6,-13,16:159.4
-5,-13,16:159.4
-4,-13,16:159.4
-3,-13,16:159.4
-2,-13,16:159.4
-1,-13,16:159.4
0,-13,16:159.4
1,-13,16:100.0
5,-13,16:159.4
6,-13,16:159.4
-11,-12,16:159.4
-10,-12,16:159.4
-9,-12,16:159.4
-8,-12,16:82.0
-7,-12,16:159.4
-6,-12,16:100.0
6,-12,16:159.4
7,-12,16:159.4
-11,-11,16:159.4
-10,-11,16:100.0
7,-11,16:159.4
8,-11,16:159.4
-11,-10,16:159.4
-9,-10,16:100.0
8,-10,16:159.4
9,-10,16:159.4
-11,-9,16:159.4
-8,-9,16:159.4
9,-9,16:159.4
10,-9,16:159.4
-12,-8,16:159.4
-11,-8,16:100.0
-7,-8,16:159.4
10,-8,16:159.4
11,-8,16:159.4
-12,-7,16:82.0
-6,-7,16:159.4
11,-7,16:100.0
12,-7,16:159.4
-12,-6,16:159.4
-5,-6,16:159.4
12,-6,16:100.0
13,-6,16:159.4
-12,-5,16:159.4
-4,-5,16:159.4
13,-5,16:100.0
14,-5,16:159.4
-13,-4,16:159.4
-12,-4,16:100.0
-3,-4,16:159.4
13,-4,16:100.0
14,-4,16:159.4
-13,-3,16:159.4
-2,-3,16:159.4
9,-3,16:159.4
10,-3,16:159.4
11,-3,16:159.4
12,-3,16:159.4
13,-3,16:100.0
14,-3,16:82.0
-13,-2,16:159.4
-1,-2,16:159.4
5,-2,16:82.0
6,-2,16:159.4
7,-2,16:159.4
8,-2,16:159.4
9,-2,16:159.4
14,-2,16:82.0
-13,-1,16:159.4
-1,-1,16:159.4
0,-1,16:159.4
1,-1,16:159.4
2,-1,16:159.4
3,-1,16:159.4
4,-1,16:82.0
5,-1,16:82.0
13,-1,16:100.0
14,-1,16:82.0
-13,0,16:159.4
0,0,16:159.4
13,0,16:159.4
-14,1,16:159.4
0,1,16:159.4
13,1,16:159.4
-14,2,16:159.4
-1,2,16:159.4
0,2,16:159.4
12,2,16:159.4
-14,3,16:159.4
-13,3,16:100.0
-1,3,16:159.4
12,3,16:159.4
-13,4,16:159.4
-12,4,16:100.0
-1,4,16:159.4
11,4,16:100.0
12,4,16:159.4
-12,5,16:82.0
-2,5,16:159.4
11,5,16:159.4
-11,6,16:82.0
-2,6,16:159.4
11,6,16:159.4
-11,7,16:82.0
-10,7,16:82.0
-2,7,16:159.4
10,7,16:159.4
-10,8,16:159.4
-9,8,16:100.0
-3,8,16:159.4
10,8,16:159.4
-9,9,16:159.4
-3,9,16:159.4
9,9,16:100.0
10,9,16:159.4
-8,10,16:82.0
-4,10,16:159.4
7,10,16:100.0
8,10,16:159.4
9,10,16:159.4
-8,11,16:82.0
-7,11,16:100.0
-4,11,16:159.4
3,11,16:100.0
4,11,16:159.4
5,11,16:159.4
6,11,16:159.4
7,11,16:159.4
-7,12,16:82.0
-6,12,16:100.0
-4,12,16:100.0
0,12,16:100.0
1,12,16:159.4
2,12,16:159.4
3,12,16:159.4
-6,13,16:159.4
-5,13,16:159.4
-4,13,16:82.0
-3,13,16:82.0
-2,13,16:82.0
-1,13,16:159.4
0,13,16:159.4
3,-14,17:159.4
4,-14,17:159.4
-4,-13,17:159.4
-3,-13,17:159.4
-2,-13,17:159.4
-1,-13,17:159.4
0,-13,17:159.4
1,-13,17:159.4
2,-13,17:159.4
3,-13,17:100.0
4,-13,17:100.0
5,-13,17:159.4
-11,-12,17:159.4
-10,-12,17:159.4
-9,-12,17:159.4
-8,-12,17:159.4
-7,-12,17:159.4
-6,-12,17:159.4
-5,-12,17:159.4
-4,-12,17:100.0
-3,-12,17:100.0
5,-12,17:100.0
6,-12,17:159.4
-10,-11,17:159.4
-9,-11,17:100.0
6,-11,17:100.0
7,-11,17:159.4
-11,-10,17:159.4
-10,-10,17:100.0
-9,-10,17:159.4
7,-10,17:100.0
8,-10,17:159.4
-11,-9,17:159.4
-8,-9,17:159.4
8,-9,17:100.0
9,-9,17:159.4
-11,-8,17:82.0
-7,-8,17:159.4
10,-8,17:159.4
-11,-7,17:82.0
-6,-7,17:159.4
11,-7,17:159.4
-12,-6,17:82.0
-5,-6,17:159.4
12,-6,17:159.4
-12,-5,17:159.4
-4,-5,17:159.4
13,-5,17:159.4
-12,-4,17:159.4
-3,-4,17:159.4
13,-4,17:159.4
-12,-3,17:159.4
-2,-3,17:159.4
9,-3,17:159.4
10,-3,17:159.4
11,-3,17:159.4
12,-3,17:159.4
13,-3,17:159.4
14,-3,17:159.4
-13,-2,17:159.4
-1,-2,17:159.4
5,-2,17:82.0
6,-2,17:82.0
7,-2,17:159.4
8,-2,17:159.4
9,-2,17:159.4
13,-2,17:100.0
14,-2,17:159.4
-13,-1,17:82.0
-1,-1,17:159.4
0,-1,17:159.4
1,-1,17:159.4
2,-1,17:159.4
3,-1,17:159.4
4,-1,17:82.0
5,-1,17:82.0
13,-1,17:159.4
-13,0,17:82.0
0,0,17:159.4
13,0,17:159.4
-13,1,17:82.0
0,1,17:159.4
12,1,17:100.0
13,1,17:159.4
-14,2,17:159.4
-1,2,17:159.4
12,2,17:159.4
-13,3,17:159.4
-1,3,17:159.4
11,3,17:100.0
12,3,17:159.4
-13,4,17:159.4
-12,4,17:159.4
-1,4,17:159.4
11,4,17:82.0
-12,5,17:159.4
-11,5,17:100.0
-2,5,17:159.4
11,5,17:82.0
-11,6,17:82.0
-2,6,17:159.4
10,6,17:100.0
11,6,17:159.4
-10,7,17:159.4
-3,7,17:100.0
-2,7,17:159.4
10,7,17:159.4
-9,8,17:159.4
-3,8,17:159.4
9,8,17:100.0
10,8,17:159.4
-9,9,17:159.4
-8,9,17:100.0
-3,9,17:159.4
9,9,17:159.4
-8,10,17:82.0
-7,10,17:100.0
-4,10,17:159.4
-3,10,17:100.0
6,10,17:100.0
7,10,17:159.4
8,10,17:159.4
-7,11,17:82.0
-4,11,17:159.4
2,11,17:100.0
3,11,17:159.4
4,11,17:159.4
5,11,17:159.4
6,11,17:159.4
-6,12,17:159.4
-4,12,17:159.4
-1,12,17:100.0
0,12,17:159.4
1,12,17:159.4
2,12,17:159.4
-5,13,17:159.4
-4,13,17:159.4
-3,13,17:159.4
-2,13,17:159.4
-1,13,17:159.4
-2,-13,18:159.4
-1,-13,18:159.4
0,-13,18:159.4
1,-13,18:159.4
2,-13,18:159.4
3,-13,18:159.4
4,-13,18:159.4
5,-13,18:159.4
-10,-12,18:159.4
-8,-12,18:159.4
-7,-12,18:159.4
-6,-12,18:159.4
-5,-12,18:159.4
-4,-12,18:159.4
-3,-12,18:159.4
-2,-12,18:100.0
-1,-12,18:100.0
5,-12,18:159.4
6,-12,18:159.4
-10,-11,18:159.4
-9,-11,18:159.4
-8,-11,18:100.0
-7,-11,18:100.0
6,-11,18:159.4
7,-11,18:159.4
-10,-10,18:159.4
-9,-10,18:159.4
7,-10,18:159.4
8,-10,18:159.4
-11,-9,18:159.4
-10,-9,18:100.0
-8,-9,18:159.4
8,-9,18:159.4
9,-9,18:159.4
-11,-8,18:82.0
-7,-8,18:159.4
9,-8,18:100.0
10,-8,18:159.4
-11,-7,18:82.0
-6,-7,18:159.4
10,-7,18:100.0
11,-7,18:159.4
-11,-6,18:82.0
-5,-6,18:159.4
11,-6,18:100.0
12,-6,18:159.4
-12,-5,18:159.4
-11,-5,18:100.0
-4,-5,18:159.4
12,-5,18:159.4
-12,-4,18:159.4
-3,-4,18:159.4
12,-4,18:159.4
-12,-3,18:159.4
-2,-3,18:159.4
9,-3,18:159.4
10,-3,18:159.4
11,-3,18:159.4
12,-3,18:159.4
-12,-2,18:159.4
-2,-2,18:100.0
-1,-2,18:159.4
5,-2,18:82.0
6,-2,18:159.4
7,-2,18:159.4
8,-2,18:159.4
9,-2,18:159.4
13,-2,18:159.4
-13,-1,18:82.0
-12,-1,18:100.0
-1,-1,18:159.4
0,-1,18:159.4
1,-1,18:159.4
2,-1,18:159.4
3,-1,18:159.4
4,-1,18:82.0
13,-1,18:159.4
-13,0,18:82.0
0,0,18:159.4
12,0,18:100.0
13,0,18:159.4
-13,1,18:82.0
0,1,18:159.4
12,1,18:159.4
-13,2,18:159.4
-1,2,18:159.4
12,2,18:159.4
-13,3,18:159.4
-1,3,18:159.4
11,3,18:82.0
-12,4,18:159.4
-1,4,18:159.4
11,4,18:82.0
-11,5,18:159.4
-2,5,18:159.4
10,5,18:100.0
11,5,18:82.0
-11,6,18:159.4
-10,6,18:100.0
-2,6,18:159.4
10,6,18:159.4
-10,7,18:159.4
-9,7,18:100.0
-3,7,18:159.4
-2,7,18:159.4
10,7,18:159.4
-9,8,18:159.4
-3,8,18:159.4
9,8,18:159.4
-8,9,18:159.4
-3,9,18:159.4
8,9,18:100.0
9,9,18:159.4
-7,10,18:159.4
-4,10,18:159.4
-3,10,18:159.4
5,10,18:159.4
6,10,18:159.4
7,10,18:159.4
8,10,18:159.4
-7,11,18:159.4
-6,11,18:100.0
-4,11,18:159.4
1,11,18:100.0
2,11,18:159.4
3,11,18:159.4
4,11,18:159.4
-6,12,18:159.4
-5,12,18:159.4
-4,12,18:159.4
-3,12,18:100.0
-2,12,18:159.4
-1,12,18:159.4
0,12,18:159.4
1,12,18:159.4
-4,13,18:159.4
-3,13,18:159.4
1,-13,19:159.4
2,-13,19:159.4
3,-13,19:159.4
4,-13,19:159.4
-10,-12,19:159.4
-6,-12,19:159.4
-5,-12,19:159.4
-4,-12,19:159.4
-3,-12,19:159.4
-2,-12,19:159.4
-1,-12,19:82.0
0,-12,19:82.0
1,-12,19:100.0
4,-12,19:100.0
5,-12,19:159.4
-10,-11,19:159.4
-9,-11,19:159.4
-8,-11,19:82.0
-7,-11,19:82.0
-6,-11,19:100.0
-5,-11,19:100.0
5,-11,19:100.0
6,-11,19:159.4
-10,-10,19:159.4
-9,-10,19:159.4
7,-10,19:159.4
-10,-9,19:159.4
-8,-9,19:159.4
8,-9,19:159.4
-11,-8,19:159.4
-10,-8,19:100.0
-7,-8,19:159.4
9,-8,19:159.4
-11,-7,19:159.4
-6,-7,19:159.4
10,-7,19:159.4
-11,-6,19:159.4
-5,-6,19:159.4
11,-6,19:159.4
-11,-5,19:159.4
-4,-5,19:159.4
12,-5,19:82.0
-12,-4,19:159.4
-11,-4,19:100.0
-3,-4,19:159.4
12,-4,19:82.0
-12,-3,19:159.4
-2,-3,19:159.4
9,-3,19:159.4
10,-3,19:159.4
11,-3,19:159.4
12,-3,19:159.4
-12,-2,19:159.4
-2,-2,19:159.4
-1,-2,19:159.4
5,-2,19:159.4
6,-2,19:159.4
7,-2,19:159.4
8,-2,19:159.4
9,-2,19:159.4
13,-2,19:159.4
-12,-1,19:159.4
-1,-1,19:159.4
0,-1,19:159.4
1,-1,19:159.4
2,-1,19:159.4
3,-1,19:159.4
4,-1,19:159.4
12,-1,19:159.4
-13,0,19:82.0
-12,0,19:100.0
0,0,19:159.4
12,0,19:159.4
-13,1,19:82.0
0,1,19:159.4
11,1,19:100.0
12,1,19:159.4
-13,2,19:159.4
-1,2,19:159.4
11,2,19:159.4
-12,3,19:159.4
-1,3,19:159.4
11,3,19:82.0
-12,4,19:159.4
-11,4,19:100.0
-2,4,19:100.0
-1,4,19:159.4
10,4,19:100.0
11,4,19:82.0
-11,5,19:159.4
-2,5,19:159.4
10,5,19:159.4
-10,6,19:159.4
-2,6,19:159.4
10,6,19:159.4
-9,7,19:159.4
-3,7,19:159.4
-2,7,19:159.4
9,7,19:82.0
-9,8,19:159.4
-8,8,19:100.0
-3,8,19:159.4
9,8,19:82.0
-8,9,19:159.4
-7,9,19:100.0
-3,9,19:159.4
7,9,19:100.0
8,9,19:159.4
9,9,19:82.0
-7,10,19:159.4
-6,10,19:100.0
-4,10,19:159.4
4,10,19:82.0
5,10,19:159.4
6,10,19:159.4
7,10,19:159.4
-6,11,19:159.4
-4,11,19:159.4
0,11,19:100.0
1,11,19:159.4
2,11,19:159.4
3,11,19:82.0
-5,12,19:159.4
-4,12,19:159.4
-3,12,19:159.4
-2,12,19:159.4
-1,12,19:159.4
0,12,19:159.4
3,-13,20:159.4
4,-13,20:159.4
-10,-12,20:159.4
-4,-12,20:159.4
-3,-12,20:159.4
-2,-12,20:159.4
-1,-12,20:82.0
0,-12,20:82.0
1,-12,20:82.0
2,-12,20:159.4
3,-12,20:100.0
4,-12,20:159.4
5,-12,20:159.4
-10,-11,20:159.4
-9,-11,20:159.4
-8,-11,20:82.0
-7,-11,20:82.0
-6,-11,20:82.0
-5,-11,20:159.4
-4,-11,20:100.0
-3,-11,20:100.0
5,-11,20:159.4
6,-11,20:82.0
-10,-10,20:159.4
-9,-10,20:159.4
-8,-10,20:82.0
6,-10,20:100.0
7,-10,20:82.0
-10,-9,20:159.4
-8,-9,20:159.4
7,-9,20:100.0
8,-9,20:159.4
-10,-8,20:159.4
-7,-8,20:159.4
8,-8,20:100.0
9,-8,20:159.4
-10,-7,20:159.4
-6,-7,20:159.4
9,-7,20:100.0
10,-7,20:159.4
-11,-6,20:159.4
-10,-6,20:100.0
-5,-6,20:159.4
10,-6,20:100.0
11,-6,20:82.0
-11,-5,20:159.4
-4,-5,20:159.4
11,-5,20:100.0
12,-5,20:82.0
-11,-4,20:159.4
-3,-4,20:159.4
12,-4,20:82.0
-12,-3,20:159.4
-11,-3,20:100.0
-3,-3,20:100.0
-2,-3,20:159.4
9,-3,20:159.4
10,-3,20:159.4
11,-3,20:159.4
12,-3,20:159.4
-12,-2,20:159.4
-2,-2,20:159.4
-1,-2,20:159.4
5,-2,20:159.4
6,-2,20:159.4
7,-2,20:159.4
8,-2,20:159.4
9,-2,20:159.4
12,-2,20:159.4
-12,-1,20:159.4
-1,-1,20:159.4
0,-1,20:159.4
1,-1,20:159.4
2,-1,20:159.4
3,-1,20:159.4
4,-1,20:159.4
12,-1,20:159.4
-12,0,20:159.4
0,0,20:159.4
11,0,20:100.0
12,0,20:159.4
-12,1,20:159.4
0,1,20:159.4
11,1,20:159.4
-13,2,20:159.4
-12,2,20:100.0
-1,2,20:159.4
11,2,20:159.4
-12,3,20:159.4
-1,3,20:159.4
10,3,20:100.0
11,3,20:159.4
-11,4,20:82.0
-2,4,20:159.4
-1,4,20:159.4
10,4,20:159.4
-11,5,20:82.0
-10,5,20:100.0
-2,5,20:159.4
10,5,20:159.4
-10,6,20:159.4
-9,6,20:100.0
-2,6,20:159.4
9,6,20:100.0
10,6,20:159.4
-9,7,20:159.4
-8,7,20:100.0
-3,7,20:159.4
-2,7,20:159.4
9,7,20:82.0
-8,8,20:159.4
-3,8,20:159.4
8,8,20:100.0
9,8,20:82.0
-7,9,20:159.4
-3,9,20:159.4
6,9,20:100.0
7,9,20:159.4
8,9,20:82.0
-6,10,20:159.4
-4,10,20:159.4
2,10,20:100.0
3,10,20:82.0
4,10,20:82.0
5,10,20:159.4
6,10,20:159.4
-6,11,20:159.4
-5,11,20:159.4
-4,11,20:159.4
-2,11,20:100.0
-1,11,20:159.4
0,11,20:159.4
1,11,20:159.4
2,11,20:82.0
-4,12,20:159.4
-3,12,20:159.4
-2,12,20:159.4
-1,-12,21:82.0
0,-12,21:82.0
1,-12,21:82.0
2,-12,21:159.4
3,-12,21:159.4
4,-12,21:159.4
-10,-11,21:159.4
-7,-11,21:82.0
-6,-11,21:82.0
-5,-11,21:159.4
-4,-11,21:159.4
-3,-11,21:159.4
-2,-11,21:159.4
-1,-11,21:100.0
5,-11,21:82.0
-9,-10,21:159.4
-8,-10,21:159.4
-7,-10,21:100.0
6,-10,21:82.0
-10,-9,21:159.4
-9,-9,21:100.0
-8,-9,21:159.4
7,-9,21:82.0
-10,-8,21:159.4
-7,-8,21:159.4
8,-8,21:159.4
-10,-7,21:159.4
-6,-7,21:159.4
9,-7,21:159.4
-10,-6,21:159.4
-5,-6,21:159.4
9,-6,21:100.0
10,-6,21:159.4
-11,-5,21:159.4
-10,-5,21:100.0
-4,-5,21:159.4
10,-5,21:100.0
11,-5,21:82.0
-11,-4,21:159.4
-3,-4,21:159.4
11,-4,21:100.0
12,-4,21:82.0
-11,-3,21:159.4
-3,-3,21:159.4
-2,-3,21:159.4
9,-3,21:159.4
10,-3,21:159.4
11,-3,21:159.4
12,-3,21:159.4
-11,-2,21:159.4
-2,-2,21:159.4
-1,-2,21:159.4
5,-2,21:159.4
6,-2,21:159.4
7,-2,21:159.4
8,-2,21:159.4
12,-2,21:159.4
-12,-1,21:159.4
-1,-1,21:159.4
0,-1,21:159.4
1,-1,21:159.4
2,-1,21:159.4
3,-1,21:159.4
4,-1,21:159.4
11,-1,21:100.0
12,-1,21:159.4
-12,0,21:159.4
0,0,21:159.4
11,0,21:159.4
-12,1,21:159.4
-1,1,21:100.0
0,1,21:159.4
11,1,21:159.4
-12,2,21:159.4
-1,2,21:159.4
10,2,21:100.0
11,2,21:159.4
-12,3,21:82.0
-11,3,21:100.0
-1,3,21:159.4
10,3,21:159.4
-11,4,21:82.0
-2,4,21:159.4
-1,4,21:159.4
10,4,21:159.4
-10,5,21:82.0
-2,5,21:159.4
9,5,21:100.0
10,5,21:159.4
-9,6,21:159.4
-2,6,21:159.4
9,6,21:159.4
-9,7,21:159.4
-8,7,21:159.4
-3,7,21:159.4
-2,7,21:159.4
9,7,21:82.0
-8,8,21:82.0
-7,8,21:100.0
-3,8,21:159.4
8,8,21:82.0
-7,9,21:82.0
-6,9,21:100.0
-3,9,21:159.4
5,9,21:100.0
6,9,21:159.4
7,9,21:159.4
8,9,21:159.4
-6,10,21:159.4
-5,10,21:100.0
-4,10,21:159.4
1,10,21:100.0
2,10,21:82.0
3,10,21:82.0
4,10,21:82.0
5,10,21:159.4
-5,11,21:159.4
-4,11,21:159.4
-3,11,21:159.4
-2,11,21:159.4
-1,11,21:159.4
0,11,21:159.4
1,11,21:159.4
-4,12,21:159.4
1,-12,22:159.4
2,-12,22:159.4
3,-12,22:159.4
4,-12,22:159.4
-5,-11,22:159.4
-4,-11,22:159.4
-3,-11,22:159.4
-2,-11,22:159.4
-1,-11,22:159.4
0,-11,22:159.4
1,-11,22:100.0
4,-11,22:100.0
5,-11,22:159.4
-9,-10,22:159.4
-8,-10,22:159.4
-7,-10,22:159.4
-6,-10,22:159.4
-5,-10,22:159.4
5,-10,22:100.0
6,-10,22:82.0
-9,-9,22:159.4
-8,-9,22:159.4
6,-9,22:100.0
7,-9,22:159.4
-9,-8,22:159.4
-7,-8,22:159.4
7,-8,22:100.0
8,-8,22:159.4
-10,-7,22:159.4
-9,-7,22:100.0
-6,-7,22:159.4
8,-7,22:100.0
9,-7,22:159.4
-10,-6,22:82.0
-5,-6,22:159.4
9,-6,22:159.4
10,-6,22:159.4
-10,-5,22:82.0
-4,-5,22:159.4
10,-5,22:159.4
11,-5,22:159.4
-11,-4,22:159.4
-10,-4,22:100.0
-3,-4,22:159.4
11,-4,22:159.4
12,-4,22:159.4
-11,-3,22:159.4
-3,-3,22:159.4
-2,-3,22:159.4
9,-3,22:159.4
10,-3,22:159.4
11,-3,22:159.4
12,-3,22:159.4
-11,-2,22:159.4
-2,-2,22:159.4
-1,-2,22:159.4
5,-2,22:159.4
6,-2,22:159.4
7,-2,22:159.4
8,-2,22:159.4
11,-2,22:100.0
12,-2,22:159.4
-11,-1,22:159.4
-1,-1,22:159.4
0,-1,22:159.4
1,-1,22:159.4
2,-1,22:159.4
3,-1,22:159.4
4,-1,22:159.4
11,-1,22:159.4
-12,0,22:159.4
-11,0,22:100.0
0,0,22:159.4
11,0,22:159.4
-12,1,22:159.4
-1,1,22:159.4
0,1,22:159.4
10,1,22:100.0
11,1,22:159.4
-12,2,22:159.4
-1,2,22:159.4
10,2,22:159.4
-11,3,22:82.0
-1,3,22:159.4
10,3,22:159.4
-11,4,22:82.0
-10,4,22:100.0
-2,4,22:159.4
-1,4,22:159.4
9,4,22:100.0
10,4,22:159.4
-10,5,22:159.4
-9,5,22:100.0
-2,5,22:159.4
9,5,22:159.4
-9,6,22:159.4
-8,6,22:100.0
-2,6,22:159.4
9,6,22:159.4
-8,7,22:82.0
-7,7,22:100.0
-3,7,22:159.4
-2,7,22:159.4
8,7,22:159.4
-7,8,22:82.0
-3,8,22:159.4
7,8,22:100.0
8,8,22:159.4
-6,9,22:82.0
-3,9,22:159.4
3,9,22:100.0
4,9,22:159.4
5,9,22:159.4
6,9,22:159.4
7,9,22:159.4
-5,10,22:159.4
-4,10,22:159.4
-1,10,22:100.0
0,10,22:159.4
1,10,22:159.4
2,10,22:159.4
3,10,22:159.4
-5,11,22:159.4
-4,11,22:82.0
-3,11,22:82.0
-2,11,22:82.0
-1,11,22:159.4
3,-12,23:159.4
-3,-11,23:159.4
-2,-11,23:159.4
-1,-11,23:159.4
0,-11,23:159.4
1,-11,23:159.4
2,-11,23:159.4
3,-11,23:159.4
4,-11,23:159.4
-8,-10,23:159.4
-7,-10,23:159.4
-6,-10,23:159.4
-5,-10,23:159.4
-3,-10,23:159.4
3,-10,23:100.0
4,-10,23:159.4
5,-10,23:159.4
-9,-9,23:159.4
-8,-9,23:159.4
5,-9,23:100.0
6,-9,23:159.4
-9,-8,23:159.4
-7,-8,23:159.4
6,-8,23:100.0
7,-8,23:159.4
-9,-7,23:159.4
-6,-7,23:159.4
7,-7,23:100.0
8,-7,23:159.4
-10,-6,23:82.0
-9,-6,23:100.0
-5,-6,23:159.4
8,-6,23:100.0
9,-6,23:159.4
-10,-5,23:82.0
-4,-5,23:159.4
9,-5,23:100.0
10,-5,23:159.4
-10,-4,23:82.0
-4,-4,23:100.0
-3,-4,23:159.4
10,-4,23:100.0
11,-4,23:159.4
-10,-3,23:159.4
-3,-3,23:159.4
-2,-3,23:159.4
9,-3,23:159.4
10,-3,23:159.4
11,-3,23:159.4
12,-3,23:159.4
-11,-2,23:159.4
-10,-2,23:100.0
-2,-2,23:159.4
-1,-2,23:159.4
5,-2,23:159.4
6,-2,23:159.4
7,-2,23:159.4
8,-2,23:159.4
11,-2,23:159.4
-11,-1,23:159.4
-1,-1,23:159.4
0,-1,23:159.4
1,-1,23:159.4
2,-1,23:159.4
3,-1,23:159.4
4,-1,23:159.4
11,-1,23:159.4
-11,0,23:159.4
0,0,23:159.4
10,0,23:100.0
11,0,23:159.4
-12,1,23:159.4
-11,1,23:100.0
-1,1,23:159.4
0,1,23:159.4
10,1,23:159.4
-12,2,23:159.4
-11,2,23:100.0
-1,2,23:159.4
9,2,23:100.0
10,2,23:159.4
-11,3,23:159.4
-10,3,23:100.0
-1,3,23:159.4
9,3,23:159.4
-10,4,23:159.4
-9,4,23:100.0
-2,4,23:159.4
-1,4,23:159.4
9,4,23:159.4
-9,5,23:159.4
-2,5,23:159.4
8,5,23:100.0
9,5,23:159.4
-8,6,23:159.4
-2,6,23:159.4
8,6,23:159.4
-8,7,23:159.4
-7,7,23:82.0
-3,7,23:159.4
7,7,23:100.0
8,7,23:159.4
-7,8,23:82.0
-6,8,23:100.0
-3,8,23:159.4
4,8,23:100.0
5,8,23:100.0
6,8,23:159.4
7,8,23:159.4
8,8,23:159.4
-6,9,23:159.4
-5,9,23:100.0
-3,9,23:159.4
1,9,23:100.0
2,9,23:159.4
3,9,23:159.4
4,9,23:159.4
5,9,23:159.4
6,9,23:159.4
-5,10,23:159.4
-4,10,23:82.0
-3,10,23:100.0
-2,10,23:82.0
-1,10,23:159.4
0,10,23:159.4
1,10,23:159.4
-4,11,23:82.0
-3,11,23:82.0
-2,11,23:82.0
-8,-10,24:159.4
-7,-10,24:159.4
-6,-10,24:159.4
-5,-10,24:159.4
-3,-10,24:159.4
-2,-10,24:159.4
-1,-10,24:159.4
0,-10,24:82.0
1,-10,24:159.4
2,-10,24:159.4
3,-10,24:159.4
-8,-9,24:159.4
-7,-9,24:100.0
-6,-9,24:100.0
-5,-9,24:100.0
-4,-9,24:159.4
-3,-9,24:100.0
-2,-9,24:100.0
-1,-9,24:100.0
0,-9,24:100.0
1,-9,24:100.0
2,-9,24:100.0
3,-9,24:159.4
4,-9,24:159.4
5,-9,24:159.4
-9,-8,24:159.4
-8,-8,24:100.0
-7,-8,24:159.4
4,-8,24:159.4
5,-8,24:159.4
6,-8,24:159.4
-9,-7,24:159.4
-8,-7,24:100.0
-6,-7,24:159.4
5,-7,24:100.0
6,-7,24:159.4
7,-7,24:159.4
-9,-6,24:159.4
-5,-6,24:159.4
6,-6,24:100.0
7,-6,24:159.4
8,-6,24:159.4
-9,-5,24:82.0
-4,-5,24:159.4
7,-5,24:100.0
8,-5,24:159.4
9,-5,24:159.4
-10,-4,24:82.0
-9,-4,24:159.4
-4,-4,24:159.4
-3,-4,24:159.4
8,-4,24:100.0
9,-4,24:159.4
10,-4,24:159.4
11,-4,24:159.4
-10,-3,24:159.4
-9,-3,24:159.4
-3,-3,24:159.4
-2,-3,24:159.4
9,-3,24:159.4
10,-3,24:159.4
11,-3,24:159.4
-10,-2,24:159.4
-9,-2,24:100.0
-2,-2,24:159.4
-1,-2,24:159.4
5,-2,24:159.4
6,-2,24:159.4
7,-2,24:159.4
8,-2,24:159.4
10,-2,24:159.4
11,-2,24:159.4
-10,-1,24:159.4
-9,-1,24:100.0
-1,-1,24:159.4
0,-1,24:159.4
1,-1,24:159.4
2,-1,24:159.4
3,-1,24:159.4
4,-1,24:159.4
9,-1,24:100.0
10,-1,24:159.4
-10,0,24:159.4
-9,0,24:100.0
0,0,24:159.4
9,0,24:82.0
10,0,24:159.4
-11,1,24:159.4
-10,1,24:82.0
-9,1,24:100.0
-1,1,24:159.4
0,1,24:159.4
8,1,24:100.0
9,1,24:159.4
10,1,24:159.4
-11,2,24:159.4
-10,2,24:159.4
-9,2,24:100.0
-1,2,24:159.4
8,2,24:159.4
9,2,24:159.4
-10,3,24:159.4
-9,3,24:159.4
-8,3,24:100.0
-1,3,24:159.4
7,3,24:100.0
8,3,24:159.4
9,3,24:159.4
-9,4,24:159.4
-8,4,24:159.4
-7,4,24:100.0
-2,4,24:159.4
7,4,24:159.4
8,4,24:159.4
-8,5,24:159.4
-7,5,24:159.4
-2,5,24:159.4
6,5,24:100.0
7,5,24:159.4
8,5,24:159.4
-8,6,24:159.4
-7,6,24:159.4
-6,6,24:100.0
-2,6,24:159.4
5,6,24:100.0
6,6,24:100.0
7,6,24:159.4
-7,7,24:159.4
-6,7,24:159.4
-5,7,24:100.0
-3,7,24:159.4
3,7,24:100.0
4,7,24:159.4
5,7,24:159.4
6,7,24:159.4
7,7,24:159.4
-6,8,24:159.4
-5,8,24:159.4
-3,8,24:159.4
0,8,24:100.0
1,8,24:159.4
2,8,24:159.4
3,8,24:159.4
4,8,24:159.4
5,8,24:159.4
-5,9,24:159.4
-4,9,24:100.0
-3,9,24:159.4
-2,9,24:159.4
-1,9,24:159.4
0,9,24:159.4
1,9,24:159.4
2,9,24:159.4
-4,10,24:159.4
-3,10,24:82.0
-2,10,24:159.4
-1,10,24:159.4
-8,-9,25:159.4
-7,-9,25:159.4
-6,-9,25:159.4
-5,-9,25:159.4
-4,-9,25:159.4
-3,-9,25:159.4
-2,-9,25:159.4
-1,-9,25:82.0
0,-9,25:82.0
1,-9,25:82.0
2,-9,25:159.4
-8,-8,25:159.4
-7,-8,25:159.4
-6,-8,25:159.4
-5,-8,25:159.4
-4,-8,25:159.4
-3,-8,25:159.4
-2,-8,25:159.4
-1,-8,25:82.0
0,-8,25:82.0
1,-8,25:82.0
2,-8,25:159.4
3,-8,25:159.4
-8,-7,25:159.4
-7,-7,25:159.4
-6,-7,25:159.4
2,-7,25:100.0
3,-7,25:159.4
4,-7,25:159.4
5,-7,25:159.4
-8,-6,25:159.4
-7,-6,25:159.4
-5,-6,25:159.4
4,-6,25:159.4
5,-6,25:159.4
6,-6,25:159.4
-8,-5,25:159.4
-7,-5,25:100.0
-5,-5,25:100.0
-4,-5,25:159.4
5,-5,25:100.0
6,-5,25:82.0
7,-5,25:159.4
-8,-4,25:159.4
-7,-4,25:100.0
-4,-4,25:159.4
-3,-4,25:159.4
6,-4,25:100.0
7,-4,25:82.0
8,-4,25:159.4
-8,-3,25:159.4
-7,-3,25:100.0
-3,-3,25:159.4
-2,-3,25:159.4
7,-3,25:100.0
8,-3,25:159.4
9,-3,25:159.4
10,-3,25:159.4
-9,-2,25:159.4
-8,-2,25:159.4
-7,-2,25:100.0
-2,-2,25:159.4
-1,-2,25:159.4
4,-2,25:100.0
5,-2,25:159.4
6,-2,25:159.4
7,-2,25:159.4
8,-2,25:159.4
9,-2,25:159.4
-9,-1,25:159.4
-8,-1,25:159.4
-1,-1,25:159.4
0,-1,25:159.4
1,-1,25:159.4
2,-1,25:159.4
3,-1,25:159.4
4,-1,25:159.4
7,-1,25:100.0
8,-1,25:82.0
9,-1,25:82.0
-9,0,25:82.0
-8,0,25:82.0
0,0,25:159.4
7,0,25:100.0
8,0,25:82.0
-9,1,25:82.0
-8,1,25:82.0
-1,1,25:159.4
0,1,25:159.4
7,1,25:82.0
8,1,25:82.0
-9,2,25:82.0
-8,2,25:82.0
-7,2,25:100.0
-1,2,25:159.4
6,2,25:100.0
7,2,25:159.4
-8,3,25:159.4
-7,3,25:159.4
-1,3,25:159.4
6,3,25:159.4
7,3,25:159.4
-7,4,25:159.4
-6,4,25:159.4
-2,4,25:159.4
5,4,25:100.0
6,4,25:159.4
-6,5,25:159.4
-5,5,25:159.4
-2,5,25:159.4
4,5,25:100.0
5,5,25:159.4
6,5,25:159.4
-6,6,25:159.4
-5,6,25:159.4
-4,6,25:100.0
-2,6,25:159.4
1,6,25:100.0
2,6,25:100.0
3,6,25:82.0
4,6,25:159.4
5,6,25:159.4
6,6,25:159.4
-5,7,25:159.4
-4,7,25:159.4
-3,7,25:159.4
-2,7,25:100.0
-1,7,25:100.0
0,7,25:159.4
1,7,25:159.4
2,7,25:82.0
3,7,25:159.4
-4,8,25:159.4
-3,8,25:159.4
-2,8,25:159.4
-1,8,25:159.4
0,8,25:159.4
-4,9,25:159.4
-3,9,25:159.4
-6,-7,26:159.4
-5,-7,26:159.4
-4,-7,26:159.4
-3,-7,26:159.4
-2,-7,26:159.4
-1,-7,26:159.4
0,-7,26:159.4
1,-7,26:159.4
2,-7,26:159.4
-6,-6,26:159.4
-5,-6,26:159.4
-4,-6,26:100.0
-3,-6,26:100.0
-2,-6,26:100.0
-1,-6,26:100.0
0,-6,26:100.0
1,-6,26:159.4
2,-6,26:159.4
3,-6,26:159.4
-7,-5,26:159.4
-6,-5,26:159.4
-5,-5,26:159.4
-4,-5,26:159.4
2,-5,26:100.0
3,-5,26:159.4
4,-5,26:159.4
5,-5,26:82.0
-7,-4,26:159.4
-6,-4,26:159.4
-4,-4,26:159.4
-3,-4,26:159.4
4,-4,26:100.0
5,-4,26:82.0
6,-4,26:82.0
-7,-3,26:159.4
-6,-3,26:159.4
-3,-3,26:159.4
-2,-3,26:159.4
5,-3,26:100.0
6,-3,26:82.0
7,-3,26:82.0
-7,-2,26:159.4
-6,-2,26:159.4
-2,-2,26:159.4
-1,-2,26:159.4
4,-2,26:159.4
5,-2,26:159.4
6,-2,26:159.4
7,-2,26:159.4
8,-2,26:159.4
-7,-1,26:159.4
-6,-1,26:159.4
-1,-1,26:159.4
0,-1,26:159.4
1,-1,26:159.4
2,-1,26:159.4
3,-1,26:159.4
4,-1,26:159.4
6,-1,26:159.4
7,-1,26:159.4
-7,0,26:159.4
-6,0,26:100.0
0,0,26:159.4
5,0,26:100.0
6,0,26:159.4
7,0,26:82.0
-7,1,26:159.4
-6,1,26:159.4
-1,1,26:159.4
5,1,26:100.0
6,1,26:159.4
-7,2,26:159.4
-6,2,26:159.4
-5,2,26:100.0
-1,2,26:159.4
4,2,26:100.0
5,2,26:159.4
6,2,26:159.4
-5,3,26:159.4
-4,3,26:100.0
-1,3,26:159.4
4,3,26:100.0
5,3,26:159.4
-5,4,26:159.4
-4,4,26:159.4
-2,4,26:159.4
2,4,26:100.0
3,4,26:100.0
4,4,26:159.4
5,4,26:159.4
-4,5,26:82.0
-3,5,26:100.0
-2,5,26:82.0
-1,5,26:100.0
0,5,26:100.0
1,5,26:82.0
2,5,26:82.0
3,5,26:82.0
4,5,26:159.4
-4,6,26:159.4
-3,6,26:82.0
-2,6,26:159.4
-1,6,26:159.4
0,6,26:159.4
1,6,26:82.0
2,6,26:82.0
-3,7,26:159.4
-2,7,26:159.4
-1,7,26:159.4
-5,-6,27:159.4
-4,-6,27:159.4
-3,-6,27:159.4
-2,-6,27:159.4
-1,-6,27:159.4
0,-6,27:159.4
-5,-5,27:159.4
-4,-5,27:159.4
-3,-5,27:82.0
-2,-5,27:159.4
-1,-5,27:159.4
0,-5,27:159.4
1,-5,27:159.4
2,-5,27:159.4
-5,-4,27:159.4
-4,-4,27:82.0
-3,-4,27:82.0
-2,-4,27:100.0
-1,-4,27:100.0
0,-4,27:100.0
1,-4,27:100.0
2,-4,27:159.4
3,-4,27:159.4
4,-4,27:159.4
-5,-3,27:159.4
-4,-3,27:100.0
-3,-3,27:82.0
-2,-3,27:159.4
3,-3,27:159.4
4,-3,27:159.4
5,-3,27:159.4
-5,-2,27:159.4
-4,-2,27:100.0
-2,-2,27:159.4
-1,-2,27:159.4
4,-2,27:159.4
5,-2,27:159.4
6,-2,27:159.4
7,-2,27:159.4
-5,-1,27:159.4
-4,-1,27:100.0
-1,-1,27:159.4
0,-1,27:159.4
1,-1,27:159.4
2,-1,27:159.4
3,-1,27:159.4
4,-1,27:159.4
5,-1,27:159.4
-6,0,27:159.4
-5,0,27:159.4
-4,0,27:100.0
0,0,27:159.4
4,0,27:159.4
5,0,27:159.4
-5,1,27:159.4
-4,1,27:100.0
-1,1,27:159.4
3,1,27:100.0
4,1,27:159.4
5,1,27:159.4
-5,2,27:159.4
-4,2,27:159.4
-3,2,27:100.0
-1,2,27:159.4
3,2,27:159.4
4,2,27:159.4
-4,3,27:159.4
-3,3,27:159.4
-2,3,27:100.0
-1,3,27:159.4
0,3,27:100.0
1,3,27:100.0
2,3,27:159.4
3,3,27:159.4
4,3,27:159.4
-3,4,27:82.0
-2,4,27:82.0
-1,4,27:159.4
1,4,27:159.4
2,4,27:159.4
3,4,27:159.4
-3,5,27:82.0
-2,5,27:82.0
-1,5,27:159.4
0,5,27:159.4
-2,6,27:82.0
-4,-5,28:82.0
-4,-4,28:82.0
-3,-4,28:82.0
-2,-4,28:82.0
-1,-4,28:159.4
0,-4,28:159.4
1,-4,28:159.4
-4,-3,28:82.0
-3,-3,28:82.0
-2,-3,28:82.0
-1,-3,28:100.0
0,-3,28:100.0
1,-3,28:159.4
2,-3,28:159.4
-4,-2,28:159.4
-3,-2,28:159.4
-2,-2,28:159.4
-1,-2,28:159.4
1,-2,28:100.0
2,-2,28:159.4
3,-2,28:159.4
4,-2,28:159.4
5,-2,28:159.4
-4,-1,28:159.4
-3,-1,28:159.4
-1,-1,28:159.4
0,-1,28:159.4
1,-1,28:159.4
2,-1,28:159.4
3,-1,28:159.4
4,-1,28:159.4
5,-1,28:159.4
-4,0,28:159.4
-3,0,28:159.4
0,0,28:159.4
2,0,28:100.0
3,0,28:159.4
-4,1,28:159.4
-3,1,28:159.4
-2,1,28:100.0
-1,1,28:159.4
1,1,28:100.0
2,1,28:159.4
3,1,28:159.4
-3,2,28:159.4
-2,2,28:159.4
-1,2,28:159.4
0,2,28:159.4
1,2,28:159.4
2,2,28:159.4
-2,3,28:159.4
-1,3,28:159.4
0,3,28:159.4
1,3,28:159.4
-3,-4,29:82.0
-3,-3,29:82.0
-2,-3,29:159.4
-1,-3,29:159.4
0,-3,29:159.4
-2,-2,29:159.4
-1,-2,29:159.4
0,-2,29:159.4
1,-2,29:159.4
-2,-1,29:159.4
-1,-1,29:159.4
0,-1,29:159.4
1,-1,29:159.4
2,-1,29:159.4
3,-1,29:159.4
4,-1,29:159.4
-2,0,29:159.4
-1,0,29:100.0
0,0,29:159.4
1,0,29:159.4
2,0,29:159.4
-2,1,29:159.4
-1,1,29:159.4
0,1,29:159.4
1,1,29:159.4
-1,2,29:159.4
-2,-3,30:159.4
-1,-2,30:159.4
-1,-1,30:159.4
0,-1,30:159.4
1,-1,30:159.4
-1,0,30:159.4
0,0,30:159.4
