[META]
version=2.0
spawnOnBlockType=2
spawnSunlight=True
spawnDarkness=True
spawnWater=False
spawnLava=False
underFill=False
randomRotation=True
dig=True
tree=False
branch=False
needsFoundation=True
rarity=100
collisionPercentage=20
spawnElevationMin=0
spawnElevationMax=200
spawnInBiome=Custom
[DATA]
-3,5,-6:100.15
-2,5,-6:100.15
-4,6,-6:100.15
-5,5,-5:100.15
-4,5,-5:100.15
-3,5,-5:100.15
-2,5,-5:100.15
-5,6,-5:100.15
-2,7,-5:100.15
-3,4,-4:100.15
-5,5,-4:100.15
-4,5,-4:100.15
-3,5,-4:100.15
-2,5,-4:100.15
-1,5,-4:100.15
-3,6,-4:100.15
-2,6,-4:100.15
-1,6,-4:100.15
-4,7,-4:100.15
-3,7,-4:100.15
-2,7,-4:100.15
-4,3,-3:100.15
-3,3,-3:100.15
-2,3,-3:100.15
-5,4,-3:100.15
-5,5,-3:100.15
-4,5,-3:100.15
-3,5,-3:100.15
-2,5,-3:100.15
-1,5,-3:100.15
-5,6,-3:100.15
-4,6,-3:100.15
-3,6,-3:100.15
-2,6,-3:100.15
-3,3,-2:100.15
-3,4,-2:100.15
-2,4,-2:100.15
-4,5,-2:100.15
-3,5,-2:100.15
-2,5,-2:100.15
-5,6,-2:100.15
-4,6,-2:100.15
-2,6,-2:100.15
-4,7,-2:100.15
-2,7,-2:100.15
-5,4,-1:100.15
-3,4,-1:100.15
-2,4,-1:100.15
-4,5,-1:100.15
-3,5,-1:100.15
-2,5,-1:100.15
-1,5,-1:100.15
-4,6,-1:100.15
-3,6,-1:100.15
-2,6,-1:100.15
-1,6,-1:100.15
-3,7,-1:100.15
-2,7,-1:100.15
-4,3,0:100.15
-3,3,0:100.15
-2,3,0:100.15
-5,4,0:100.15
-4,4,0:100.15
-3,4,0:100.15
-1,4,0:100.15
-4,5,0:100.15
-3,5,0:100.15
-3,2,1:100.15
-5,3,1:100.15
-4,3,1:100.15
-3,3,1:100.15
-2,3,1:100.15
-1,3,1:100.15
-5,4,1:100.15
-4,4,1:100.15
-1,4,1:100.15
-4,5,1:100.15
-3,5,1:100.15
-2,5,1:100.15
-1,5,1:100.15
-4,6,1:100.15
-3,6,1:100.15
-2,6,1:100.15
-1,6,1:100.15
-3,7,1:100.15
-2,7,1:100.15
-4,2,2:100.15
-3,2,2:100.15
-2,2,2:100.15
-5,3,2:100.15
-4,3,2:100.15
-2,3,2:100.15
-1,3,2:100.15
-5,4,2:100.15
-4,4,2:100.15
-1,4,2:100.15
-4,5,2:100.15
-2,5,2:100.15
-1,5,2:100.15
-4,6,2:100.15
-3,6,2:100.15
-2,6,2:100.15
-4,1,3:100.15
-3,1,3:100.15
-5,2,3:100.15
-4,2,3:100.15
-3,2,3:100.15
-2,2,3:100.15
-5,3,3:100.15
-2,3,3:100.15
-1,3,3:100.15
-5,4,3:100.15
-4,4,3:100.15
-2,4,3:100.15
-1,4,3:100.15
-4,5,3:100.15
-3,5,3:100.15
-2,5,3:100.15
-3,6,3:100.15
-5,1,4:100.15
-4,1,4:100.15
-3,1,4:100.15
-5,2,4:100.15
-3,2,4:100.15
-2,2,4:100.15
-5,3,4:100.15
-2,3,4:100.15
-5,4,4:100.15
-4,4,4:100.15
-3,4,4:100.15
-2,4,4:100.15
-3,5,4:100.15
-4,-2,5:100.0
-3,-2,5:100.0
-4,-1,5:100.0
-2,-1,5:100.0
-2,0,5:100.0
-5,1,5:100.15
-4,1,5:100.15
-3,1,5:100.15
-5,2,5:100.15
-2,2,5:100.15
-5,3,5:100.15
-4,3,5:100.15
-3,3,5:100.15
-2,3,5:100.15
-4,4,5:100.15
-3,4,5:100.15
-2,5,5:100.0
-2,6,5:100.0
-1,6,5:100.0
-4,7,5:100.0
-2,7,5:100.0
-3,8,5:100.0
-4,-2,6:159.10
-3,-2,6:159.10
-4,-1,6:159.10
-2,-1,6:159.10
-5,0,6:100.15
-4,0,6:100.15
-2,0,6:159.10
-5,1,6:100.15
-3,1,6:100.15
-5,2,6:100.15
-3,2,6:100.15
-2,2,6:100.15
-5,3,6:100.15
-4,3,6:100.15
-3,3,6:100.15
-2,5,6:159.10
-3,6,6:159.10
-2,6,6:159.10
-1,6,6:159.10
-4,7,6:159.10
-3,7,6:159.10
-2,7,6:159.10
-3,8,6:159.10
-3,-1,7:159.10
-5,0,7:100.15
-4,0,7:100.15
-3,0,7:100.15
-5,1,7:100.15
-3,1,7:100.15
-5,2,7:100.15
-4,2,7:100.15
-3,2,7:100.15
-4,3,7:100.15
-2,6,7:159.10
-4,7,7:159.10
-3,7,7:159.10
-2,7,7:159.10
-5,0,8:100.15
-4,0,8:100.15
-3,0,8:100.15
-5,1,8:100.15
-3,1,8:100.15
-5,2,8:100.15
-4,2,8:100.15
-3,2,8:100.15
-5,0,9:100.15
-4,0,9:100.15
-3,0,9:100.15
-5,1,9:100.15
-3,1,9:100.15
-4,2,9:100.15
-3,2,9:100.15
-4,-1,10:100.15
-5,0,10:100.15
-4,0,10:100.15
-3,0,10:100.15
-5,1,10:100.15
-4,1,10:100.15
-3,1,10:100.15
-4,2,10:100.15
-4,-1,11:100.15
-4,0,11:100.15
-3,0,11:100.15
-4,1,11:100.15
-3,1,11:100.15
-4,0,12:100.15
-3,0,12:100.15
-4,1,12:100.15
-3,1,12:100.15
3,5,12:100.0
4,5,12:100.0
5,6,12:100.0
4,7,12:100.0
-3,9,12:100.0
-4,10,12:100.0
-3,10,12:100.0
-2,10,12:100.0
-1,10,12:100.0
-3,-7,13:100.0
-1,-7,13:100.0
-3,-6,13:100.0
-4,0,13:100.15
-3,0,13:100.15
-4,1,13:100.15
-3,1,13:100.15
-4,2,13:100.15
5,2,13:100.0
5,3,13:100.0
-10,4,13:100.0
5,4,13:100.0
-10,5,13:100.0
5,5,13:100.0
-10,6,13:100.0
5,6,13:159.10
6,6,13:100.0
-9,7,13:100.0
-8,7,13:100.0
3,7,13:100.0
4,7,13:159.10
-7,8,13:100.0
-6,8,13:100.0
-2,8,13:100.0
1,8,13:100.0
2,8,13:100.0
-6,9,13:100.0
-5,9,13:100.0
-4,9,13:100.0
-2,9,13:100.0
-1,9,13:100.0
0,9,13:100.0
1,9,13:100.0
-4,10,13:159.10
-3,10,13:159.10
-2,10,13:159.10
-1,10,13:159.10
-2,-8,14:100.0
-4,-7,14:100.0
-3,-7,14:159.10
-2,-7,14:100.0
-1,-7,14:159.10
-6,-6,14:100.0
-5,-6,14:100.0
-2,-6,14:100.0
-1,-6,14:100.0
0,-6,14:100.0
1,-6,14:100.0
1,-5,14:100.0
2,-5,14:100.0
-9,-4,14:100.0
3,-4,14:100.0
4,-4,14:100.0
-10,-3,14:100.0
5,-3,14:100.0
6,-3,14:100.0
-10,-2,14:100.0
-9,-2,14:100.0
5,-2,14:100.0
-10,-1,14:100.0
5,-1,14:100.0
-10,0,14:100.0
-4,0,14:100.15
-3,0,14:100.15
5,0,14:100.0
-10,1,14:100.0
5,1,14:100.0
-10,2,14:100.0
-4,2,14:100.15
5,2,14:159.10
-10,3,14:100.0
5,3,14:159.10
-10,4,14:159.10
5,4,14:159.10
-10,5,14:159.10
5,5,14:159.10
-10,6,14:159.10
-9,6,14:100.0
-2,6,14:100.0
3,6,14:100.0
5,6,14:159.10
6,6,14:159.10
-9,7,14:159.10
-8,7,14:159.10
-2,7,14:159.10
1,7,14:100.0
2,7,14:100.0
3,7,14:159.10
4,7,14:159.10
-7,8,14:159.10
-6,8,14:159.10
-2,8,14:159.10
-1,8,14:100.0
0,8,14:100.0
1,8,14:159.10
2,8,14:159.10
-5,9,14:159.10
-4,9,14:159.10
-3,9,14:82.0
-2,9,14:82.0
-1,9,14:159.10
0,9,14:159.10
-3,10,14:82.0
-2,10,14:82.0
-2,-8,15:159.10
-4,-7,15:159.10
-3,-7,15:159.10
-2,-7,15:159.10
-6,-6,15:159.10
-5,-6,15:159.10
-4,-6,15:100.0
-2,-6,15:159.10
-1,-6,15:159.10
0,-6,15:82.0
1,-6,15:159.10
-7,-5,15:100.0
-6,-5,15:100.0
0,-5,15:82.0
1,-5,15:82.0
2,-5,15:159.10
-9,-4,15:159.10
-8,-4,15:100.0
-7,-4,15:100.0
2,-4,15:100.0
3,-4,15:159.10
4,-4,15:159.10
-10,-3,15:159.10
-9,-3,15:100.0
5,-3,15:159.10
6,-3,15:159.10
-10,-2,15:159.10
5,-2,15:159.10
-10,-1,15:159.10
4,-1,15:82.0
5,-1,15:159.10
-10,0,15:159.10
-3,0,15:100.15
3,0,15:82.0
4,0,15:82.0
5,0,15:82.0
-10,1,15:159.10
-2,1,15:100.15
2,1,15:100.0
3,1,15:100.0
4,1,15:82.0
5,1,15:159.10
-10,2,15:159.10
-4,2,15:100.15
-3,2,15:100.15
1,2,15:100.0
2,2,15:100.0
3,2,15:100.0
4,2,15:100.0
5,2,15:159.10
-10,3,15:159.10
-2,3,15:100.0
1,3,15:100.0
2,3,15:100.0
3,3,15:100.0
4,3,15:100.0
5,3,15:159.10
-10,4,15:159.10
-9,4,15:100.0
-2,4,15:100.0
-1,4,15:100.0
0,4,15:100.0
3,4,15:100.0
4,4,15:100.0
5,4,15:159.10
-10,5,15:159.10
-9,5,15:100.0
-8,5,15:100.0
-7,5,15:100.0
-6,5,15:100.0
-5,5,15:100.0
-4,5,15:100.0
-2,5,15:100.0
-1,5,15:100.0
0,5,15:100.0
1,5,15:100.0
2,5,15:100.0
3,5,15:159.10
4,5,15:159.10
-9,6,15:159.10
-8,6,15:100.0
-7,6,15:100.0
-6,6,15:100.0
-5,6,15:100.0
-4,6,15:100.0
-1,6,15:100.0
0,6,15:100.0
1,6,15:100.0
2,6,15:100.0
3,6,15:159.10
4,6,15:159.10
-9,7,15:159.10
-8,7,15:159.10
-7,7,15:100.0
-6,7,15:100.0
-5,7,15:100.0
-4,7,15:100.0
-3,7,15:100.0
-2,7,15:159.10
-1,7,15:100.0
0,7,15:100.0
1,7,15:159.10
2,7,15:159.10
3,7,15:159.10
-7,8,15:159.10
-6,8,15:159.10
-5,8,15:100.0
-4,8,15:100.0
-3,8,15:100.0
-2,8,15:159.10
-1,8,15:159.10
0,8,15:159.10
1,8,15:159.10
-5,9,15:159.10
-4,9,15:82.0
-3,9,15:82.0
-2,9,15:82.0
-1,9,15:82.0
-3,10,15:82.0
-2,10,15:82.0
-3,-7,16:159.10
-4,-6,16:159.10
-3,-6,16:100.0
-2,-6,16:159.10
-1,-6,16:82.0
-7,-5,16:159.10
-6,-5,16:159.10
-5,-5,16:159.10
-4,-5,16:100.0
-3,-5,16:100.0
-2,-5,16:159.10
-1,-5,16:82.0
0,-5,16:82.0
1,-5,16:82.0
-8,-4,16:159.10
-7,-4,16:159.10
-6,-4,16:100.0
-5,-4,16:100.0
-4,-4,16:100.0
-3,-4,16:100.0
-1,-4,16:82.0
0,-4,16:82.0
1,-4,16:82.0
2,-4,16:159.10
3,-4,16:159.10
-9,-3,16:159.10
-8,-3,16:100.0
-7,-3,16:100.0
-6,-3,16:100.0
-5,-3,16:100.0
-4,-3,16:100.0
-3,-3,16:100.0
-1,-3,16:100.0
0,-3,16:100.0
1,-3,16:100.0
2,-3,16:100.0
3,-3,16:100.0
4,-3,16:159.10
-9,-2,16:159.10
-7,-2,16:100.0
-6,-2,16:100.0
-5,-2,16:100.0
-4,-2,16:100.0
-3,-2,16:100.0
-1,-2,16:100.0
0,-2,16:100.0
1,-2,16:100.0
2,-2,16:100.0
3,-2,16:100.0
4,-2,16:100.0
5,-2,16:159.10
-10,-1,16:159.10
-9,-1,16:100.0
-6,-1,16:100.0
-5,-1,16:100.0
-4,-1,16:100.0
-1,-1,16:100.0
0,-1,16:100.0
1,-1,16:100.0
2,-1,16:100.0
3,-1,16:82.0
4,-1,16:82.0
5,-1,16:82.0
-10,0,16:159.10
-9,0,16:100.0
-8,0,16:100.0
-7,0,16:100.0
-4,0,16:100.0
-1,0,16:100.0
0,0,16:100.0
1,0,16:100.0
2,0,16:100.0
3,0,16:82.0
4,0,16:82.0
-10,1,16:159.10
-9,1,16:100.0
-8,1,16:100.0
-7,1,16:100.0
-6,1,16:100.0
-5,1,16:100.0
-1,1,16:100.0
0,1,16:100.0
1,1,16:100.0
4,1,16:82.0
-9,2,16:82.0
-8,2,16:100.0
-7,2,16:100.0
-6,2,16:100.0
-5,2,16:100.0
-3,2,16:100.15
0,2,16:100.0
4,2,16:159.10
-10,3,16:82.0
-9,3,16:82.0
-8,3,16:82.0
-7,3,16:100.0
-6,3,16:100.0
-5,3,16:100.0
-4,3,16:100.0
4,3,16:159.10
-9,4,16:82.0
-8,4,16:100.0
-7,4,16:100.0
-6,4,16:100.0
-5,4,16:100.0
-4,4,16:100.0
4,4,16:159.10
-9,5,16:159.10
-8,5,16:159.10
-7,5,16:159.10
3,5,16:159.10
-8,6,16:159.10
-7,6,16:159.10
2,6,16:159.10
-8,7,16:159.10
-7,7,16:159.10
-6,7,16:159.10
-5,7,16:159.10
0,7,16:159.10
1,7,16:159.10
2,7,16:159.10
-5,8,16:159.10
-4,8,16:159.10
-3,8,16:159.10
-2,8,16:159.10
-1,8,16:159.10
0,8,16:159.10
-3,9,16:82.0
-2,9,16:82.0
-2,10,16:82.0
-3,-6,17:159.10
-4,-5,17:159.10
-3,-5,17:159.10
-2,-5,17:159.10
-1,-5,17:82.0
0,-5,17:82.0
-6,-4,17:159.10
-5,-4,17:159.10
-1,-4,17:159.10
0,-4,17:82.0
-8,-3,17:159.10
-7,-3,17:159.10
-6,-3,17:159.10
-1,-3,17:159.10
0,-3,17:159.10
1,-3,17:159.10
2,-3,17:159.10
3,-3,17:159.10
3,-2,17:159.10
4,-2,17:159.10
-9,-1,17:159.10
4,-1,17:82.0
-9,0,17:159.10
3,0,17:82.0
4,0,17:82.0
-9,1,17:159.10
-4,1,17:100.15
-3,1,17:100.15
-2,1,17:100.15
3,1,17:100.0
4,1,17:82.0
-9,2,17:82.0
-4,2,17:100.15
-3,2,17:100.15
-2,2,17:100.15
3,2,17:100.0
4,2,17:159.10
-9,3,17:82.0
-8,3,17:82.0
-3,3,17:100.15
3,3,17:159.10
-9,4,17:82.0
-8,4,17:82.0
3,4,17:159.10
-8,5,17:159.10
-7,5,17:159.10
2,5,17:82.0
3,5,17:82.0
-7,6,17:159.10
-6,6,17:100.0
1,6,17:100.0
2,6,17:82.0
-6,7,17:159.10
-5,7,17:159.10
-4,7,17:100.0
-1,7,17:100.0
0,7,17:159.10
1,7,17:159.10
-4,8,17:159.10
-3,8,17:159.10
-2,8,17:159.10
-1,8,17:159.10
-2,9,17:159.10
-4,-5,18:159.10
-3,-5,18:159.10
-2,-5,18:159.10
-5,-4,18:159.10
-4,-4,18:100.0
-2,-4,18:100.0
-1,-4,18:159.10
0,-4,18:159.10
-7,-3,18:159.10
-6,-3,18:159.10
-5,-3,18:100.0
-1,-3,18:159.10
0,-3,18:100.0
1,-3,18:159.10
-8,-2,18:82.0
-7,-2,18:100.0
1,-2,18:100.0
2,-2,18:82.0
-9,-1,18:82.0
-8,-1,18:82.0
2,-1,18:82.0
3,-1,18:82.0
-8,0,18:82.0
2,0,18:82.0
-9,1,18:159.10
-8,1,18:159.10
-3,1,18:100.15
-2,1,18:100.15
3,1,18:159.10
-8,2,18:159.10
-3,2,18:100.15
-2,2,18:100.15
2,2,18:100.0
3,2,18:159.10
-8,3,18:82.0
-3,3,18:100.15
-2,3,18:100.15
2,3,18:100.0
3,3,18:159.10
-8,4,18:159.10
-7,4,18:100.0
2,4,18:82.0
3,4,18:82.0
-7,5,18:82.0
-6,5,18:82.0
1,5,18:82.0
2,5,18:82.0
3,5,18:82.0
-6,6,18:82.0
-5,6,18:159.10
-4,6,18:100.0
-1,6,18:100.0
0,6,18:159.10
1,6,18:82.0
-4,7,18:159.10
-3,7,18:159.10
-2,7,18:100.0
-1,7,18:159.10
-2,8,18:159.10
-2,9,18:159.10
-4,-4,19:82.0
-3,-4,19:159.10
-2,-4,19:159.10
-6,-3,19:159.10
-5,-3,19:82.0
-4,-3,19:82.0
-2,-3,19:100.0
-1,-3,19:159.10
0,-3,19:159.10
-8,-2,19:82.0
-7,-2,19:82.0
-6,-2,19:100.0
-1,-2,19:100.0
0,-2,19:100.0
1,-2,19:82.0
-8,-1,19:82.0
-7,-1,19:82.0
-2,-1,19:100.0
1,-1,19:82.0
2,-1,19:82.0
3,-1,19:82.0
-8,0,19:82.0
-7,0,19:82.0
2,0,19:82.0
-8,1,19:159.10
-7,1,19:100.0
-3,1,19:100.15
-2,1,19:100.15
2,1,19:159.10
-8,2,19:159.10
-7,2,19:100.0
-3,2,19:100.15
-2,2,19:100.15
2,2,19:159.10
-7,3,19:159.10
-3,3,19:100.15
-2,3,19:100.15
2,3,19:159.10
-7,4,19:82.0
-6,4,19:82.0
1,4,19:159.10
2,4,19:82.0
-7,5,19:82.0
-6,5,19:82.0
-5,5,19:82.0
0,5,19:100.0
1,5,19:82.0
-5,6,19:82.0
-4,6,19:159.10
-2,6,19:100.0
-1,6,19:159.10
0,6,19:159.10
-3,7,19:159.10
-2,7,19:159.10
-1,7,19:159.10
-2,8,19:159.10
-3,-4,20:82.0
-4,-3,20:82.0
-3,-3,20:82.0
-2,-3,20:159.10
-6,-2,20:159.10
-5,-2,20:82.0
-4,-2,20:82.0
-2,-2,20:100.0
-1,-2,20:159.10
0,-2,20:159.10
-8,-1,20:82.0
-7,-1,20:82.0
-6,-1,20:100.0
-1,-1,20:100.0
0,-1,20:100.0
1,-1,20:82.0
2,-1,20:82.0
3,-1,20:82.0
-6,0,20:159.10
-2,0,20:100.0
1,0,20:159.10
-7,1,20:159.10
-6,1,20:100.0
-2,1,20:100.15
1,1,20:159.10
-7,2,20:159.10
-6,2,20:100.0
-3,2,20:100.15
-2,2,20:100.15
-1,2,20:100.15
1,2,20:159.10
-7,3,20:159.10
-5,3,20:100.0
-3,3,20:100.15
-2,3,20:100.15
1,3,20:159.10
-6,4,20:82.0
0,4,20:159.10
-7,5,20:82.0
-6,5,20:82.0
-5,5,20:82.0
-4,5,20:159.10
-3,5,20:159.10
-2,5,20:100.0
-1,5,20:100.0
0,5,20:159.10
-3,6,20:159.10
-2,6,20:159.10
-1,6,20:159.10
-2,7,20:159.10
-3,-3,21:82.0
-4,-2,21:82.0
-2,-2,21:159.10
-6,-1,21:159.10
-5,-1,21:159.10
-2,-1,21:159.10
-1,-1,21:159.10
0,-1,21:159.10
-6,0,21:159.10
-2,0,21:159.10
-1,0,21:159.10
0,0,21:159.10
2,0,21:100.0
3,0,21:100.0
-6,1,21:159.10
-2,1,21:159.10
-1,1,21:159.10
0,1,21:100.0
1,1,21:159.10
4,1,21:100.0
-6,2,21:159.10
-3,2,21:100.15
-2,2,21:100.15
-1,2,21:100.15
0,2,21:159.10
4,2,21:100.0
5,2,21:100.0
-7,3,21:159.10
-6,3,21:159.10
-5,3,21:159.10
-4,3,21:100.0
-3,3,21:100.15
-2,3,21:100.15
-1,3,21:100.15
0,3,21:159.10
5,3,21:100.0
-7,4,21:100.0
-5,4,21:159.10
-4,4,21:159.10
-3,4,21:159.10
-2,4,21:100.0
-1,4,21:159.10
0,4,21:159.10
5,4,21:100.0
-7,5,21:100.0
-2,5,21:159.10
-1,5,21:159.10
5,5,21:100.0
5,6,21:100.0
-7,7,21:100.0
-2,7,21:159.10
5,7,21:100.0
-7,8,21:100.0
-6,8,21:100.0
4,8,21:100.0
-5,9,21:100.0
4,9,21:100.0
0,10,21:100.0
1,10,21:100.0
3,10,21:100.0
-3,11,21:100.0
-2,11,21:100.0
-1,11,21:100.0
1,11,21:100.0
-2,-3,22:100.0
-1,-3,22:100.0
0,-3,22:100.0
-6,-2,22:100.0
-5,-2,22:100.0
-3,-2,22:100.0
1,-2,22:100.0
-6,-1,22:159.10
2,-1,22:100.0
-7,0,22:82.0
2,0,22:159.10
3,0,22:159.10
-7,1,22:82.0
-4,1,22:159.10
-3,1,22:159.10
-2,1,22:159.10
3,1,22:100.0
4,1,22:159.10
-7,2,22:82.0
-4,2,22:159.10
-3,2,22:159.10
-2,2,22:100.15
-1,2,22:100.15
5,2,22:159.10
-7,3,22:100.0
-4,3,22:159.10
-3,3,22:159.10
-2,3,22:159.10
-1,3,22:100.15
5,3,22:159.10
-7,4,22:159.10
-3,4,22:159.10
-2,4,22:100.15
-1,4,22:100.15
5,4,22:159.10
-7,5,22:159.10
5,5,22:159.10
-7,6,22:100.0
5,6,22:159.10
-7,7,22:159.10
4,7,22:100.0
5,7,22:159.10
-6,8,22:159.10
4,8,22:159.10
-5,9,22:159.10
4,9,22:159.10
-4,10,22:100.0
0,10,22:159.10
1,10,22:159.10
2,10,22:100.0
3,10,22:159.10
4,10,22:100.0
-3,11,22:82.0
-2,11,22:82.0
-1,11,22:159.10
0,11,22:100.0
-2,-3,23:159.10
-1,-3,23:159.10
0,-3,23:159.10
-6,-2,23:159.10
-5,-2,23:159.10
-4,-2,23:159.10
-3,-2,23:159.10
0,-2,23:100.0
1,-2,23:159.10
-5,-1,23:159.10
1,-1,23:100.0
2,-1,23:159.10
-7,0,23:82.0
-6,0,23:82.0
-1,0,23:100.0
2,0,23:159.10
-7,1,23:82.0
2,1,23:100.0
3,1,23:159.10
-7,2,23:82.0
2,2,23:100.0
3,2,23:82.0
4,2,23:82.0
-7,3,23:159.10
-2,3,23:100.15
-1,3,23:100.15
2,3,23:100.0
3,3,23:100.0
4,3,23:82.0
-6,4,23:159.10
-2,4,23:100.15
-1,4,23:100.15
1,4,23:100.0
2,4,23:100.0
3,4,23:100.0
4,4,23:100.0
5,4,23:159.10
-7,5,23:159.10
-6,5,23:100.0
-5,5,23:100.0
1,5,23:100.0
2,5,23:100.0
3,5,23:100.0
4,5,23:100.0
5,5,23:159.10
-7,6,23:82.0
-6,6,23:100.0
-5,6,23:100.0
-4,6,23:100.0
-2,6,23:100.0
0,6,23:100.0
1,6,23:100.0
2,6,23:100.0
3,6,23:100.0
4,6,23:159.10
-7,7,23:82.0
-6,7,23:82.0
-5,7,23:100.0
-4,7,23:100.0
-3,7,23:100.0
-2,7,23:100.0
-1,7,23:159.10
0,7,23:100.0
1,7,23:100.0
2,7,23:100.0
3,7,23:100.0
4,7,23:159.10
-6,8,23:159.10
-5,8,23:100.0
-4,8,23:100.0
-3,8,23:100.0
-2,8,23:100.0
-1,8,23:100.0
0,8,23:159.10
1,8,23:100.0
2,8,23:100.0
3,8,23:100.0
4,8,23:159.10
-5,9,23:159.10
-4,9,23:100.0
-3,9,23:100.0
-2,9,23:100.0
-1,9,23:82.0
0,9,23:159.10
1,9,23:100.0
2,9,23:100.0
3,9,23:100.0
4,9,23:159.10
-4,10,23:82.0
-3,10,23:82.0
-2,10,23:82.0
-1,10,23:82.0
0,10,23:82.0
1,10,23:159.10
2,10,23:159.10
3,10,23:159.10
4,10,23:159.10
-3,11,23:82.0
-2,11,23:82.0
-1,11,23:82.0
-2,-2,24:82.0
-1,-2,24:159.10
0,-2,24:159.10
-5,-1,24:159.10
-4,-1,24:159.10
-3,-1,24:82.0
-2,-1,24:82.0
-1,-1,24:82.0
0,-1,24:100.0
1,-1,24:159.10
-6,0,24:159.10
-5,0,24:100.0
-4,0,24:100.0
-3,0,24:100.0
-2,0,24:82.0
0,0,24:100.0
1,0,24:100.0
2,0,24:159.10
-6,1,24:82.0
-5,1,24:100.0
-4,1,24:100.0
-3,1,24:100.0
-1,1,24:100.0
0,1,24:100.0
1,1,24:100.0
2,1,24:159.10
3,1,24:82.0
-6,2,24:159.10
-5,2,24:100.0
-4,2,24:100.0
-3,2,24:100.0
-1,2,24:100.0
0,2,24:100.0
1,2,24:100.0
3,2,24:82.0
4,2,24:82.0
-6,3,24:159.10
-5,3,24:100.0
-1,3,24:100.15
0,3,24:100.0
1,3,24:100.0
3,3,24:82.0
4,3,24:82.0
-5,4,24:159.10
-4,4,24:100.0
-3,4,24:100.0
-1,4,24:100.15
0,4,24:100.0
4,4,24:159.10
-6,5,24:159.10
-4,5,24:100.0
-3,5,24:100.0
0,5,24:100.0
4,5,24:159.10
-6,6,24:82.0
3,6,24:159.10
4,6,24:159.10
-7,7,24:82.0
-6,7,24:82.0
-5,7,24:159.10
3,7,24:159.10
4,7,24:159.10
-5,8,24:159.10
-4,8,24:159.10
3,8,24:159.10
-4,9,24:159.10
-3,9,24:159.10
0,9,24:82.0
1,9,24:159.10
2,9,24:159.10
3,9,24:159.10
4,9,24:159.10
-3,10,24:82.0
-2,10,24:82.0
-1,10,24:82.0
0,10,24:82.0
2,10,24:159.10
-3,-1,25:82.0
-2,-1,25:82.0
-1,-1,25:82.0
0,-1,25:159.10
-5,0,25:159.10
-4,0,25:159.10
-3,0,25:82.0
-2,0,25:82.0
-1,0,25:82.0
0,0,25:159.10
1,0,25:159.10
-5,1,25:159.10
0,1,25:159.10
1,1,25:159.10
2,1,25:159.10
-5,2,25:159.10
2,2,25:100.0
3,2,25:82.0
-5,3,25:159.10
2,3,25:100.0
3,3,25:159.10
-5,4,25:159.10
-2,4,25:100.15
-1,4,25:100.15
3,4,25:100.0
4,4,25:159.10
-6,5,25:159.10
-5,5,25:100.0
-2,5,25:100.15
-1,5,25:100.15
3,5,25:100.0
4,5,25:159.10
-6,6,25:159.10
-5,6,25:100.0
3,6,25:159.10
-6,7,25:82.0
-5,7,25:159.10
-4,7,25:100.0
2,7,25:82.0
3,7,25:159.10
-4,8,25:159.10
-3,8,25:100.0
1,8,25:82.0
2,8,25:82.0
3,8,25:82.0
-3,9,25:159.10
-2,9,25:100.0
-1,9,25:82.0
0,9,25:159.10
1,9,25:159.10
3,9,25:159.10
-2,10,25:159.10
-2,0,26:82.0
-1,0,26:159.10
0,0,26:159.10
-4,1,26:159.10
-3,1,26:159.10
-2,1,26:100.0
-1,1,26:100.0
0,1,26:100.0
1,1,26:159.10
-5,2,26:159.10
-4,2,26:100.0
1,2,26:100.0
2,2,26:159.10
-5,3,26:159.10
-4,3,26:100.0
1,3,26:100.0
2,3,26:159.10
-5,4,26:159.10
-4,4,26:100.0
-1,4,26:100.15
2,4,26:100.0
3,4,26:159.10
-5,5,26:159.10
-4,5,26:100.0
-1,5,26:100.15
0,5,26:100.15
2,5,26:100.0
3,5,26:159.10
-5,6,26:159.10
-4,6,26:100.0
2,6,26:100.0
3,6,26:159.10
-4,7,26:159.10
-3,7,26:100.0
2,7,26:82.0
-3,8,26:159.10
-2,8,26:100.0
-1,8,26:100.0
0,8,26:100.0
1,8,26:82.0
2,8,26:82.0
-2,9,26:159.10
-1,9,26:159.10
0,9,26:159.10
-3,1,27:159.10
-2,1,27:159.10
-1,1,27:159.10
0,1,27:159.10
-4,2,27:159.10
-3,2,27:82.0
-2,2,27:100.0
-1,2,27:100.0
0,2,27:100.0
1,2,27:159.10
-4,3,27:82.0
-3,3,27:82.0
0,3,27:100.0
1,3,27:159.10
-4,4,27:159.10
-3,4,27:82.0
1,4,27:100.0
2,4,27:159.10
-4,5,27:159.10
-3,5,27:100.0
-1,5,27:100.15
0,5,27:100.15
2,5,27:159.10
-4,6,27:159.10
-1,6,27:100.15
1,6,27:100.0
2,6,27:159.10
-3,7,27:159.10
-2,7,27:100.0
0,7,27:100.0
1,7,27:100.0
2,7,27:82.0
-2,8,27:159.10
-1,8,27:159.10
0,8,27:159.10
1,8,27:159.10
2,8,27:82.0
-2,2,28:82.0
-1,2,28:159.10
0,2,28:159.10
-3,3,28:82.0
-2,3,28:82.0
-1,3,28:100.0
0,3,28:159.10
-3,4,28:82.0
0,4,28:100.0
1,4,28:159.10
-3,5,28:159.10
-1,5,28:100.15
0,5,28:100.15
1,5,28:100.0
2,5,28:159.10
-3,6,28:159.10
-2,6,28:100.0
-1,6,28:100.15
0,6,28:100.15
1,6,28:159.10
-3,7,28:159.10
-2,7,28:159.10
-1,7,28:100.0
0,7,28:159.10
1,7,28:159.10
-1,8,28:159.10
2,8,28:159.10
-3,3,29:82.0
1,3,29:100.0
-3,4,29:159.10
-2,4,29:100.0
-1,4,29:100.0
-3,5,29:159.10
-2,5,29:100.0
5,5,29:100.0
-3,6,29:159.10
5,6,29:100.0
-1,7,29:159.10
0,7,29:159.10
1,7,29:159.10
-2,9,29:100.0
2,11,29:100.0
0,2,30:159.10
1,2,30:100.0
2,2,30:100.0
-2,3,30:100.0
-1,3,30:159.10
0,3,30:159.10
1,3,30:159.10
3,3,30:100.0
-3,4,30:100.0
-2,4,30:159.10
-1,4,30:159.10
4,4,30:100.0
-4,5,30:100.0
-3,5,30:100.0
-2,5,30:159.10
-1,5,30:100.0
5,5,30:159.10
-3,6,30:159.10
5,6,30:159.10
-4,7,30:100.0
-3,7,30:159.10
0,7,30:159.10
5,7,30:100.0
-4,8,30:100.0
-3,8,30:100.0
5,8,30:100.0
-4,9,30:100.0
-3,9,30:100.0
4,9,30:100.0
5,9,30:100.0
-3,10,30:100.0
-2,10,30:100.0
2,10,30:100.0
4,10,30:100.0
-2,11,30:100.0
-1,11,30:100.0
1,11,30:100.0
2,11,30:159.10
3,11,30:100.0
4,11,30:100.0
-1,2,31:159.10
0,2,31:159.10
1,2,31:159.10
2,2,31:159.10
-2,3,31:159.10
-1,3,31:159.10
2,3,31:100.0
3,3,31:82.0
-3,4,31:159.10
0,4,31:100.0
2,4,31:82.0
3,4,31:82.0
4,4,31:82.0
-4,5,31:159.10
-3,5,31:159.10
-2,5,31:100.0
2,5,31:100.0
3,5,31:82.0
4,5,31:100.0
5,5,31:159.10
-4,6,31:159.10
-3,6,31:159.10
1,6,31:100.0
2,6,31:100.0
3,6,31:100.0
5,6,31:159.10
-4,7,31:159.10
-3,7,31:159.10
-2,7,31:159.10
-1,7,31:159.10
0,7,31:159.10
1,7,31:159.10
2,7,31:100.0
3,7,31:100.0
4,7,31:100.0
5,7,31:159.10
-4,8,31:82.0
-3,8,31:82.0
-2,8,31:100.0
-1,8,31:100.0
0,8,31:100.0
1,8,31:100.0
2,8,31:100.0
3,8,31:100.0
4,8,31:100.0
5,8,31:159.10
-4,9,31:82.0
-3,9,31:82.0
-2,9,31:100.0
-1,9,31:100.0
0,9,31:100.0
1,9,31:100.0
2,9,31:100.0
3,9,31:100.0
4,9,31:159.10
-2,10,31:159.10
-1,10,31:100.0
0,10,31:100.0
1,10,31:100.0
2,10,31:159.10
3,10,31:100.0
4,10,31:159.10
-1,11,31:159.10
0,11,31:100.0
1,11,31:159.10
2,11,31:159.10
3,11,31:159.10
0,3,32:159.10
1,3,32:159.10
2,3,32:82.0
-2,4,32:159.10
-1,4,32:159.10
0,4,32:159.10
2,4,32:82.0
3,4,32:82.0
-2,5,32:159.10
3,5,32:82.0
4,5,32:82.0
-2,6,32:159.10
4,6,32:159.10
-3,7,32:159.10
-2,7,32:159.10
-1,7,32:159.10
0,7,32:100.15
1,7,32:100.15
4,7,32:159.10
-4,8,32:82.0
-3,8,32:159.10
4,8,32:159.10
-3,9,32:82.0
-2,9,32:159.10
-1,9,32:159.10
3,9,32:159.10
4,9,32:159.10
-2,10,32:159.10
-1,10,32:159.10
0,10,32:82.0
1,10,32:82.0
2,10,32:82.0
3,10,32:159.10
4,10,32:159.10
0,11,32:159.10
-1,4,33:159.10
0,4,33:159.10
1,4,33:159.10
2,4,33:82.0
-2,5,33:159.10
-1,5,33:100.0
0,5,33:100.0
2,5,33:100.0
3,5,33:82.0
-2,6,33:159.10
3,6,33:100.0
4,6,33:159.10
-2,7,33:159.10
3,7,33:100.0
4,7,33:159.10
-2,8,33:159.10
1,8,33:100.15
3,8,33:100.0
4,8,33:159.10
-2,9,33:159.10
-1,9,33:159.10
0,9,33:82.0
1,9,33:82.0
2,9,33:82.0
3,9,33:159.10
0,10,33:82.0
1,10,33:82.0
3,10,33:159.10
4,10,33:159.10
1,4,34:159.10
-1,5,34:159.10
0,5,34:159.10
1,5,34:100.0
2,5,34:159.10
-1,6,34:159.10
0,6,34:100.0
2,6,34:100.0
3,6,34:159.10
-1,7,34:159.10
2,7,34:100.0
3,7,34:159.10
-2,8,34:159.10
-1,8,34:159.10
0,8,34:159.10
1,8,34:159.10
2,8,34:100.0
3,8,34:159.10
0,9,34:159.10
1,9,34:82.0
2,9,34:159.10
3,9,34:159.10
3,10,34:159.10
1,5,35:159.10
0,6,35:159.10
1,6,35:100.0
2,6,35:159.10
-1,7,35:159.10
0,7,35:159.10
1,7,35:159.10
2,7,35:159.10
3,7,35:159.10
1,8,35:159.10
2,8,35:159.10
0,9,35:159.10
2,9,35:159.10
1,6,36:159.10
0,7,36:159.10
1,7,36:159.10
2,7,36:159.10
1,8,36:159.10
