[META]
version=2.0
spawnOnBlockType=2
spawnSunlight=True
spawnDarkness=True
spawnWater=False
spawnLava=False
underFill=False
randomRotation=True
dig=True
tree=False
branch=False
needsFoundation=True
rarity=100
collisionPercentage=20
spawnElevationMin=0
spawnElevationMax=200
spawnInBiome=Custom
[DATA]
2,-4,-6:100.15
-4,-3,-6:100.15
-4,-2,-6:100.15
-3,-2,-6:100.15
6,-2,-6:100.15
-3,2,-6:100.15
4,2,-6:100.15
-3,3,-6:100.15
2,-5,-5:100.15
1,-4,-5:100.15
2,-4,-5:100.15
1,-3,-5:100.15
2,-3,-5:100.15
-4,-2,-5:100.15
5,-2,-5:100.15
6,-2,-5:100.15
-4,-1,-5:100.15
5,-1,-5:100.15
6,-1,-5:100.15
7,-1,-5:100.15
7,0,-5:100.15
-3,1,-5:100.15
-2,1,-5:100.15
2,1,-5:100.15
3,1,-5:100.15
-3,2,-5:100.15
-2,2,-5:100.15
-1,2,-5:100.15
1,2,-5:100.15
2,2,-5:100.15
3,2,-5:100.15
-2,3,-5:100.15
2,3,-5:100.15
1,-4,-4:100.15
2,-4,-4:100.15
2,-3,-4:100.15
-5,-2,-4:100.15
-4,-2,-4:100.15
-3,-2,-4:100.15
4,-2,-4:100.15
5,-2,-4:100.15
6,-2,-4:100.15
-4,-1,-4:100.15
4,-1,-4:100.15
5,-1,-4:100.15
6,-1,-4:100.15
7,-1,-4:100.15
4,0,-4:100.15
5,0,-4:100.15
-3,1,-4:100.15
-2,1,-4:100.15
1,1,-4:100.15
4,1,-4:100.15
-2,2,-4:100.15
2,2,-4:100.15
3,2,-4:100.15
4,2,-4:100.15
1,3,-4:100.15
2,-5,-3:100.15
2,-4,-3:100.15
3,-4,-3:100.15
-4,-3,-3:100.15
-2,-3,-3:100.15
0,-3,-3:100.15
1,-3,-3:100.15
2,-3,-3:100.15
3,-3,-3:100.15
-5,-2,-3:100.15
-4,-2,-3:100.15
-3,-2,-3:100.15
-2,-2,-3:100.15
1,-2,-3:100.15
2,-2,-3:100.15
4,-2,-3:100.15
-4,-1,-3:100.15
-3,-1,-3:100.15
4,-1,-3:100.15
5,-1,-3:100.15
6,-1,-3:100.15
3,0,-3:100.15
4,0,-3:100.15
5,0,-3:100.15
-2,1,-3:100.15
3,1,-3:100.15
4,1,-3:100.15
-3,2,-3:100.15
-2,2,-3:100.15
-1,2,-3:100.15
2,2,-3:100.15
3,2,-3:100.15
-2,-4,-2:100.15
0,-4,-2:100.15
1,-4,-2:100.15
-3,-3,-2:100.15
-2,-3,-2:100.15
-1,-3,-2:100.15
0,-3,-2:100.15
1,-3,-2:100.15
2,-3,-2:100.15
-3,-2,-2:100.15
-2,-2,-2:100.15
-1,-2,-2:100.15
2,-2,-2:100.15
5,-2,-2:100.15
-3,-1,-2:100.15
-2,-1,-2:100.15
-1,-1,-2:100.15
4,-1,-2:100.15
6,-1,-2:100.15
2,0,-2:100.15
3,0,-2:100.15
-2,1,-2:100.15
2,1,-2:100.15
3,1,-2:100.15
-2,2,-2:100.15
-1,2,-2:100.15
2,2,-2:100.15
3,2,-2:100.15
-3,3,-2:100.15
-2,3,-2:100.15
2,3,-2:100.15
-3,-4,-1:100.15
-2,-4,-1:100.15
-1,-4,-1:100.15
1,-4,-1:100.15
2,-4,-1:100.15
-2,-3,-1:100.15
-1,-3,-1:100.15
0,-3,-1:100.15
1,-3,-1:100.15
2,-3,-1:100.15
-3,-2,-1:100.15
-2,-2,-1:100.15
-1,-2,-1:100.15
2,-2,-1:100.15
1,0,-1:100.15
2,0,-1:100.15
3,0,-1:100.15
4,0,-1:100.15
-2,1,-1:100.15
2,1,-1:100.15
3,1,-1:100.15
-3,2,-1:100.15
-2,2,-1:100.15
-1,2,-1:100.15
1,2,-1:100.15
2,2,-1:100.15
-3,3,-1:100.15
-1,-5,0:100.15
0,-5,0:100.15
1,-5,0:100.15
-2,-4,0:100.15
-1,-4,0:100.15
0,-4,0:100.15
1,-4,0:100.15
2,-4,0:100.15
3,-4,0:100.15
-3,-3,0:100.15
-2,-3,0:100.15
-1,-3,0:100.15
0,-3,0:100.15
1,-3,0:100.15
2,-3,0:100.15
3,-3,0:100.15
-4,-2,0:100.15
-3,-2,0:100.15
-2,-2,0:100.15
-1,-2,0:100.15
0,-2,0:100.15
1,-2,0:100.15
2,-2,0:100.15
3,-2,0:100.15
4,-2,0:100.15
-4,-1,0:100.15
-3,-1,0:100.15
-2,-1,0:100.15
-1,-1,0:100.15
0,-1,0:100.15
1,-1,0:100.15
2,-1,0:100.15
3,-1,0:100.15
4,-1,0:100.15
-4,0,0:100.15
-3,0,0:100.15
-2,0,0:100.15
-1,0,0:100.15
0,0,0:100.15
1,0,0:100.15
2,0,0:100.15
3,0,0:100.15
4,0,0:100.15
-4,1,0:100.15
-3,1,0:100.15
-2,1,0:100.15
-1,1,0:100.15
0,1,0:100.15
1,1,0:100.15
2,1,0:100.15
3,1,0:100.15
4,1,0:100.15
-3,2,0:100.15
-2,2,0:100.15
-1,2,0:100.15
0,2,0:100.15
1,2,0:100.15
2,2,0:100.15
3,2,0:100.15
-3,3,0:100.15
-2,3,0:100.15
-1,3,0:100.15
0,3,0:100.15
1,3,0:100.15
2,3,0:100.15
-1,4,0:100.15
0,4,0:100.15
1,4,0:100.15
-1,-5,1:100.15
0,-5,1:100.15
1,-5,1:100.15
-2,-4,1:100.15
-1,-4,1:100.15
1,-4,1:100.15
2,-4,1:100.15
3,-4,1:100.15
-3,-3,1:100.15
-2,-3,1:100.15
3,-3,1:100.15
-3,-2,1:100.15
4,-2,1:100.15
5,-2,1:100.15
-4,-1,1:100.15
4,-1,1:100.15
5,-1,1:100.15
-4,0,1:100.15
1,0,1:100.15
4,0,1:100.15
5,0,1:100.15
-3,1,1:100.15
-2,1,1:100.15
0,1,1:100.15
1,1,1:100.15
3,1,1:100.15
4,1,1:100.15
-3,2,1:100.15
-2,2,1:100.15
-1,2,1:100.15
3,2,1:100.15
-3,3,1:100.15
-2,3,1:100.15
-1,3,1:100.15
0,3,1:100.15
2,3,1:100.15
0,4,1:100.15
1,4,1:100.15
-1,-5,2:100.15
0,-5,2:100.15
-2,-4,2:100.15
-1,-4,2:100.15
1,-4,2:100.15
2,-4,2:100.15
3,-4,2:100.15
-2,-3,2:100.15
3,-3,2:100.15
-3,-2,2:100.15
3,-2,2:100.15
4,-2,2:100.15
-4,-1,2:100.15
-3,-1,2:100.15
4,-1,2:100.15
-4,0,2:100.15
-3,0,2:100.15
4,0,2:100.15
-3,1,2:100.15
3,1,2:100.15
4,1,2:100.15
-3,2,2:100.15
-2,2,2:100.15
2,2,2:100.15
3,2,2:100.15
-2,3,2:100.15
-1,3,2:100.15
0,3,2:100.15
1,3,2:100.15
2,3,2:100.15
-1,-4,3:100.15
0,-4,3:100.15
1,-4,3:100.15
2,-4,3:100.15
3,-4,3:100.15
-2,-3,3:100.15
3,-3,3:100.15
-3,-2,3:100.15
-2,-2,3:100.15
3,-2,3:100.15
-3,-1,3:100.15
4,-1,3:100.15
-3,0,3:100.15
4,0,3:100.15
-3,1,3:100.15
-2,1,3:100.15
3,1,3:100.15
-2,2,3:100.15
-1,2,3:100.15
2,2,3:100.15
-1,3,3:100.15
0,3,3:100.15
1,3,3:100.15
2,3,3:100.15
-1,-4,4:100.15
0,-4,4:100.15
1,-4,4:100.15
2,-4,4:100.15
3,-4,4:100.15
-2,-3,4:100.15
3,-3,4:100.15
-3,-2,4:100.15
-2,-2,4:100.15
3,-2,4:100.15
-3,-1,4:100.15
3,-1,4:100.15
4,-1,4:100.15
-3,0,4:100.15
3,0,4:100.15
4,0,4:100.15
-2,1,4:100.15
2,1,4:100.15
3,1,4:100.15
-2,2,4:100.15
-1,2,4:100.15
0,2,4:100.15
1,2,4:100.15
2,2,4:100.15
1,3,4:100.15
-1,-4,5:100.15
0,-4,5:100.15
1,-4,5:100.15
2,-4,5:100.15
-2,-3,5:100.15
-1,-3,5:100.15
3,-3,5:100.15
-2,-2,5:100.15
3,-2,5:100.15
-3,-1,5:100.15
3,-1,5:100.15
-3,0,5:100.15
3,0,5:100.15
-2,1,5:100.15
2,1,5:100.15
3,1,5:100.15
-2,2,5:100.15
-1,2,5:100.15
0,2,5:100.15
1,2,5:100.15
2,2,5:100.15
-1,-4,6:100.15
0,-4,6:100.15
1,-4,6:100.15
-2,-3,6:100.15
-1,-3,6:100.15
1,-3,6:100.15
2,-3,6:100.15
3,-3,6:100.15
-2,-2,6:100.15
3,-2,6:100.15
-3,-1,6:100.15
-2,-1,6:100.15
3,-1,6:100.15
-3,0,6:100.15
-2,0,6:100.15
3,0,6:100.15
-2,1,6:100.15
2,1,6:100.15
3,1,6:100.15
-2,2,6:100.15
-1,2,6:100.15
0,2,6:100.15
1,2,6:100.15
2,2,6:100.15
0,-4,7:100.15
-1,-3,7:100.15
0,-3,7:100.15
1,-3,7:100.15
2,-3,7:100.15
-2,-2,7:100.15
2,-2,7:100.15
3,-2,7:100.15
-3,-1,7:100.15
-2,-1,7:100.15
3,-1,7:100.15
-3,0,7:100.15
-2,0,7:100.15
3,0,7:100.15
-2,1,7:100.15
2,1,7:100.15
3,1,7:100.15
-2,2,7:100.15
-1,2,7:100.15
0,2,7:100.15
1,2,7:100.15
2,2,7:100.15
-1,-3,8:100.15
0,-3,8:100.15
1,-3,8:100.15
2,-3,8:100.15
-2,-2,8:100.15
-1,-2,8:100.15
2,-2,8:100.15
-3,-1,8:100.15
-2,-1,8:100.15
3,-1,8:100.15
-3,0,8:100.15
-2,0,8:100.15
3,0,8:100.15
-2,1,8:100.15
2,1,8:100.15
-2,2,8:100.15
-1,2,8:100.15
0,2,8:100.15
1,2,8:100.15
2,2,8:100.15
-1,-3,9:100.15
0,-3,9:100.15
1,-3,9:100.15
2,-3,9:100.15
-2,-2,9:100.15
-1,-2,9:100.15
2,-2,9:100.15
-2,-1,9:100.15
2,-1,9:100.15
-3,0,9:100.15
-2,0,9:100.15
3,0,9:100.15
-2,1,9:100.15
2,1,9:100.15
-2,2,9:100.15
-1,2,9:100.15
0,2,9:100.15
1,2,9:100.15
-1,-3,10:100.15
0,-3,10:100.15
1,-3,10:100.15
2,-3,10:100.15
-1,-2,10:100.15
2,-2,10:100.15
-2,-1,10:100.15
2,-1,10:100.15
-4,0,10:100.15
-3,0,10:100.15
-2,0,10:100.15
2,0,10:100.15
-3,1,10:100.15
-2,1,10:100.15
2,1,10:100.15
-2,2,10:100.15
-1,2,10:100.15
0,2,10:100.15
1,2,10:100.15
1,-3,11:100.15
-1,-2,11:100.15
0,-2,11:100.15
1,-2,11:100.15
2,-2,11:100.15
-2,-1,11:100.15
-1,-1,11:100.15
2,-1,11:100.15
-5,0,11:100.15
-4,0,11:100.15
-3,0,11:100.15
-2,0,11:100.15
2,0,11:100.15
-5,1,11:100.15
-4,1,11:100.15
-3,1,11:100.15
-2,1,11:100.15
2,1,11:100.15
-3,2,11:100.15
-2,2,11:100.15
-1,2,11:100.15
0,2,11:100.15
1,2,11:100.15
0,-3,12:100.15
1,-3,12:100.15
2,-3,12:100.15
-1,-2,12:100.15
0,-2,12:100.15
1,-2,12:100.15
-4,-1,12:100.15
-1,-1,12:100.15
1,-1,12:100.15
2,-1,12:100.15
-6,0,12:100.15
-5,0,12:100.15
-4,0,12:100.15
-3,0,12:100.15
-2,0,12:100.15
-1,0,12:100.15
1,0,12:100.15
2,0,12:100.15
-6,1,12:100.15
-5,1,12:100.15
-1,1,12:100.15
1,1,12:100.15
2,1,12:100.15
-4,2,12:100.15
-3,2,12:100.15
-2,2,12:100.15
-1,2,12:100.15
0,2,12:100.15
1,2,12:100.15
0,-4,13:100.15
1,-4,13:100.15
2,-4,13:100.15
0,-3,13:100.15
1,-3,13:100.15
2,-3,13:100.15
0,-2,13:100.15
1,-2,13:100.15
-5,-1,13:100.15
0,-1,13:100.15
1,-1,13:100.0
-7,0,13:100.15
-6,0,13:100.15
-5,0,13:100.15
-4,0,13:100.15
-3,0,13:100.15
-2,0,13:100.15
-1,0,13:100.15
0,0,13:100.15
1,0,13:100.15
2,0,13:100.15
-7,1,13:100.15
-6,1,13:100.15
-3,1,13:100.15
-2,1,13:100.15
-1,1,13:100.15
0,1,13:100.15
1,1,13:100.15
2,1,13:100.15
-6,2,13:100.15
-5,2,13:100.15
-4,2,13:100.15
-3,2,13:100.15
0,2,13:100.15
1,2,13:100.15
2,2,13:100.15
1,-5,14:100.15
2,-5,14:100.15
0,-4,14:100.15
1,-4,14:100.15
2,-4,14:100.15
0,-3,14:100.15
1,-3,14:100.15
2,-3,14:100.15
0,-2,14:100.15
1,-2,14:100.15
-6,-1,14:100.15
-5,-1,14:100.15
0,-1,14:100.15
1,-1,14:100.0
-8,0,14:100.15
-7,0,14:100.15
-6,0,14:100.15
-5,0,14:100.15
-4,0,14:100.15
-3,0,14:100.15
-2,0,14:100.15
0,0,14:100.0
-8,1,14:100.15
-7,1,14:100.15
-5,1,14:100.15
-4,1,14:100.15
-3,1,14:100.15
-2,1,14:100.15
-1,1,14:100.15
0,1,14:100.15
1,1,14:100.15
2,1,14:100.15
3,1,14:100.15
-7,2,14:100.15
-6,2,14:100.15
-5,2,14:100.15
-4,2,14:100.15
1,2,14:100.15
2,2,14:100.15
-6,-26,15:100.0
-4,-26,15:100.0
-3,-26,15:100.0
-2,-26,15:100.0
-1,-26,15:100.0
0,-26,15:100.0
1,-26,15:100.0
2,-26,15:100.0
3,-26,15:100.0
4,-26,15:100.0
5,-26,15:100.0
6,-26,15:100.0
7,-26,15:100.0
8,-26,15:100.0
12,-26,15:100.0
-13,-23,15:100.0
-14,-22,15:100.0
16,-22,15:100.0
17,-21,15:100.0
-16,-20,15:100.0
18,-20,15:100.0
-17,-19,15:100.0
-22,-13,15:100.0
26,-7,15:100.0
2,-6,15:100.15
26,-6,15:100.0
1,-5,15:100.15
2,-5,15:100.15
3,-5,15:100.15
26,-5,15:100.0
1,-4,15:100.15
2,-4,15:100.15
1,-3,15:100.15
2,-3,15:100.15
1,-2,15:100.15
-6,-1,15:100.15
-25,0,15:100.0
-9,0,15:100.15
-8,0,15:100.15
-7,0,15:100.15
-6,0,15:100.15
-5,0,15:100.15
-25,1,15:100.0
-8,1,15:100.15
-7,1,15:100.15
-6,1,15:100.15
-5,1,15:100.15
0,1,15:100.15
1,1,15:100.15
2,1,15:100.15
3,1,15:100.15
-25,2,15:100.0
-8,2,15:100.15
-7,2,15:100.15
-6,2,15:100.15
1,2,15:100.15
2,2,15:100.15
3,2,15:100.15
-25,3,15:100.0
2,3,15:100.15
-25,4,15:100.0
-25,5,15:100.0
-25,6,15:100.0
-22,12,15:100.0
-20,15,15:100.0
-18,17,15:100.0
17,17,15:100.0
-17,18,15:100.0
-16,19,15:100.0
14,20,15:100.0
-13,22,15:100.0
-6,23,15:100.0
-5,23,15:100.0
-4,23,15:100.0
-1,23,15:100.0
0,23,15:100.0
1,23,15:100.0
2,23,15:100.0
3,23,15:100.0
4,23,15:100.0
5,23,15:100.0
-6,-26,16:159.10
-4,-26,16:159.10
-3,-26,16:159.10
-2,-26,16:159.10
-1,-26,16:159.10
0,-26,16:159.10
1,-26,16:159.10
2,-26,16:159.10
3,-26,16:159.10
4,-26,16:159.10
5,-26,16:159.10
6,-26,16:159.10
7,-26,16:159.10
8,-26,16:159.10
9,-26,16:100.0
10,-26,16:100.0
11,-26,16:100.0
12,-26,16:159.10
-9,-25,16:100.0
-8,-25,16:100.0
-7,-25,16:100.0
-6,-25,16:100.0
-5,-25,16:100.0
-4,-25,16:100.0
-3,-25,16:100.0
-2,-25,16:100.0
-1,-25,16:100.0
0,-25,16:100.0
13,-25,16:100.0
-11,-24,16:100.0
-10,-24,16:100.0
-9,-24,16:100.0
-8,-24,16:100.0
-7,-24,16:100.0
14,-24,16:100.0
-13,-23,16:159.10
-12,-23,16:100.0
-11,-23,16:100.0
-10,-23,16:100.0
-14,-22,16:159.10
-13,-22,16:100.0
-12,-22,16:100.0
-9,-22,16:100.0
15,-22,16:100.0
16,-22,16:159.10
-15,-21,16:100.0
-14,-21,16:100.0
-13,-21,16:100.0
16,-21,16:100.0
17,-21,16:159.10
-16,-20,16:159.10
-15,-20,16:100.0
-14,-20,16:100.0
17,-20,16:100.0
18,-20,16:159.10
-17,-19,16:159.10
-16,-19,16:100.0
18,-19,16:100.0
19,-19,16:100.0
-17,-18,16:100.0
19,-18,16:100.0
20,-18,16:100.0
21,-18,16:100.0
-18,-17,16:100.0
20,-17,16:100.0
21,-17,16:100.0
-19,-16,16:100.0
20,-16,16:100.0
21,-16,16:100.0
-20,-15,16:100.0
21,-15,16:100.0
22,-15,16:100.0
-21,-14,16:100.0
22,-14,16:100.0
-22,-13,16:159.10
22,-13,16:100.0
-23,-12,16:100.0
22,-12,16:100.0
23,-12,16:100.0
-23,-11,16:100.0
23,-11,16:100.0
24,-11,16:100.0
-24,-10,16:100.0
23,-10,16:100.0
24,-10,16:100.0
-25,-9,16:100.0
24,-9,16:100.0
25,-9,16:100.0
-25,-8,16:100.0
24,-8,16:100.0
25,-8,16:100.0
-25,-7,16:100.0
25,-7,16:100.0
26,-7,16:159.10
-25,-6,16:100.0
2,-6,16:100.15
3,-6,16:100.15
25,-6,16:100.0
26,-6,16:159.10
-25,-5,16:100.0
2,-5,16:100.15
3,-5,16:100.15
25,-5,16:100.0
26,-5,16:159.10
-25,-4,16:100.0
2,-4,16:100.15
26,-4,16:100.0
-25,-3,16:100.0
26,-3,16:100.0
-25,-2,16:100.0
26,-2,16:100.0
-25,-1,16:100.0
26,-1,16:100.0
-25,0,16:159.10
-9,0,16:100.15
-8,0,16:100.15
-7,0,16:100.15
26,0,16:100.0
-25,1,16:159.10
-24,1,16:100.0
-9,1,16:100.15
-8,1,16:100.15
1,1,16:100.15
2,1,16:100.15
3,1,16:100.15
26,1,16:100.0
-25,2,16:159.10
-8,2,16:100.15
1,2,16:100.15
2,2,16:100.15
3,2,16:100.15
4,2,16:100.15
26,2,16:100.0
-25,3,16:159.10
-24,3,16:100.0
2,3,16:100.15
3,3,16:100.15
26,3,16:100.0
-25,4,16:159.10
-24,4,16:100.0
-25,5,16:159.10
-24,5,16:100.0
-25,6,16:159.10
-24,6,16:100.0
-23,6,16:100.0
-24,7,16:100.0
-23,7,16:100.0
26,7,16:100.0
-24,8,16:100.0
-23,8,16:100.0
25,8,16:100.0
-23,9,16:100.0
-22,9,16:100.0
24,9,16:100.0
-23,10,16:100.0
-22,10,16:100.0
-22,11,16:100.0
-21,11,16:100.0
22,11,16:100.0
-22,12,16:159.10
-21,12,16:100.0
21,12,16:100.0
-21,13,16:100.0
-20,13,16:100.0
20,13,16:100.0
-20,14,16:100.0
-19,14,16:100.0
19,14,16:100.0
-20,15,16:159.10
-19,15,16:100.0
17,15,16:100.0
18,15,16:100.0
-18,16,16:100.0
16,16,16:100.0
17,16,16:100.0
-18,17,16:159.10
-17,17,16:100.0
15,17,16:100.0
16,17,16:100.0
17,17,16:159.10
-17,18,16:159.10
-16,18,16:100.0
14,18,16:100.0
15,18,16:100.0
-16,19,16:159.10
-15,19,16:100.0
12,19,16:100.0
13,19,16:100.0
14,19,16:100.0
-14,20,16:100.0
11,20,16:100.0
12,20,16:100.0
13,20,16:100.0
14,20,16:159.10
-14,21,16:159.10
-13,21,16:100.0
-12,21,16:100.0
8,21,16:100.0
9,21,16:100.0
10,21,16:100.0
11,21,16:100.0
-13,22,16:159.10
-12,22,16:100.0
-11,22,16:100.0
-10,22,16:100.0
-9,22,16:100.0
-8,22,16:100.0
-7,22,16:100.0
-6,22,16:100.0
-5,22,16:100.0
-4,22,16:100.0
-3,22,16:100.0
-2,22,16:100.0
-1,22,16:100.0
0,22,16:100.0
1,22,16:100.0
3,22,16:100.0
4,22,16:100.0
5,22,16:100.0
6,22,16:100.0
7,22,16:100.0
8,22,16:100.0
9,22,16:100.0
-6,23,16:159.10
-5,23,16:159.10
-4,23,16:159.10
-1,23,16:159.10
0,23,16:159.10
1,23,16:159.10
2,23,16:159.10
3,23,16:159.10
4,23,16:159.10
5,23,16:159.10
9,-26,17:159.10
10,-26,17:159.10
11,-26,17:159.10
-9,-25,17:159.10
-8,-25,17:159.10
-7,-25,17:159.10
-6,-25,17:159.10
-5,-25,17:159.10
-4,-25,17:159.10
-3,-25,17:159.10
-2,-25,17:100.0
-1,-25,17:100.0
0,-25,17:159.10
1,-25,17:100.0
2,-25,17:100.0
3,-25,17:100.0
4,-25,17:100.0
5,-25,17:100.0
6,-25,17:100.0
7,-25,17:100.0
8,-25,17:100.0
9,-25,17:100.0
10,-25,17:100.0
11,-25,17:100.0
12,-25,17:100.0
13,-25,17:159.10
-11,-24,17:159.10
-10,-24,17:159.10
-9,-24,17:159.10
-8,-24,17:159.10
-7,-24,17:159.10
-6,-24,17:100.0
-5,-24,17:100.0
-4,-24,17:100.0
-3,-24,17:100.0
-2,-24,17:100.0
-1,-24,17:100.0
0,-24,17:100.0
1,-24,17:100.0
2,-24,17:100.0
3,-24,17:100.0
4,-24,17:100.0
5,-24,17:100.0
6,-24,17:100.0
7,-24,17:100.0
12,-24,17:100.0
13,-24,17:100.0
14,-24,17:159.10
-12,-23,17:159.10
-11,-23,17:159.10
-10,-23,17:159.10
-9,-23,17:100.0
-8,-23,17:100.0
-7,-23,17:100.0
-6,-23,17:100.0
-5,-23,17:100.0
-4,-23,17:100.0
-3,-23,17:100.0
-2,-23,17:100.0
-1,-23,17:100.0
0,-23,17:100.0
1,-23,17:100.0
2,-23,17:100.0
13,-23,17:100.0
14,-23,17:100.0
-13,-22,17:159.10
-12,-22,17:159.10
-11,-22,17:100.0
-10,-22,17:100.0
-9,-22,17:159.10
-8,-22,17:100.0
-7,-22,17:100.0
-6,-22,17:100.0
-5,-22,17:100.0
-4,-22,17:100.0
-3,-22,17:100.0
-2,-22,17:100.0
14,-22,17:100.0
15,-22,17:100.0
-14,-21,17:159.10
-13,-21,17:159.10
-12,-21,17:100.0
-11,-21,17:100.0
-10,-21,17:100.0
-9,-21,17:100.0
-8,-21,17:100.0
-7,-21,17:100.0
-6,-21,17:100.0
14,-21,17:100.0
15,-21,17:100.0
16,-21,17:159.10
-15,-20,17:159.10
-14,-20,17:159.10
-13,-20,17:100.0
-12,-20,17:100.0
-11,-20,17:100.0
-10,-20,17:100.0
-9,-20,17:100.0
15,-20,17:100.0
16,-20,17:100.0
17,-20,17:159.10
-16,-19,17:159.10
-15,-19,17:100.0
-14,-19,17:100.0
-13,-19,17:100.0
-12,-19,17:100.0
-11,-19,17:100.0
15,-19,17:100.0
16,-19,17:100.0
17,-19,17:100.0
18,-19,17:159.10
19,-19,17:159.10
-17,-18,17:159.10
-16,-18,17:100.0
-15,-18,17:100.0
-14,-18,17:100.0
-13,-18,17:100.0
-12,-18,17:100.0
16,-18,17:100.0
17,-18,17:100.0
18,-18,17:100.0
19,-18,17:159.10
20,-18,17:159.10
21,-18,17:159.10
-18,-17,17:159.10
-17,-17,17:100.0
-16,-17,17:100.0
-15,-17,17:100.0
-14,-17,17:100.0
-13,-17,17:100.0
16,-17,17:100.0
17,-17,17:100.0
18,-17,17:100.0
19,-17,17:100.0
20,-17,17:159.10
21,-17,17:159.10
-19,-16,17:159.10
-18,-16,17:100.0
-17,-16,17:100.0
-16,-16,17:100.0
-15,-16,17:100.0
17,-16,17:100.0
18,-16,17:100.0
19,-16,17:100.0
20,-16,17:159.10
21,-16,17:159.10
-20,-15,17:159.10
-19,-15,17:100.0
-18,-15,17:100.0
-17,-15,17:100.0
-16,-15,17:100.0
17,-15,17:100.0
18,-15,17:100.0
19,-15,17:100.0
20,-15,17:100.0
21,-15,17:159.10
22,-15,17:159.10
-21,-14,17:159.10
-20,-14,17:100.0
-19,-14,17:100.0
-18,-14,17:100.0
-17,-14,17:100.0
18,-14,17:100.0
19,-14,17:100.0
20,-14,17:100.0
21,-14,17:100.0
22,-14,17:159.10
-21,-13,17:100.0
-20,-13,17:100.0
-19,-13,17:100.0
-18,-13,17:100.0
18,-13,17:100.0
19,-13,17:100.0
20,-13,17:100.0
21,-13,17:100.0
22,-13,17:159.10
-23,-12,17:159.10
-21,-12,17:100.0
-20,-12,17:100.0
-19,-12,17:100.0
-18,-12,17:100.0
19,-12,17:100.0
20,-12,17:100.0
21,-12,17:100.0
22,-12,17:159.10
23,-12,17:159.10
-23,-11,17:159.10
-22,-11,17:100.0
-21,-11,17:100.0
19,-11,17:100.0
20,-11,17:100.0
21,-11,17:100.0
22,-11,17:100.0
23,-11,17:159.10
24,-11,17:159.10
-24,-10,17:159.10
-23,-10,17:100.0
-22,-10,17:100.0
20,-10,17:100.0
21,-10,17:100.0
22,-10,17:100.0
23,-10,17:159.10
24,-10,17:159.10
-25,-9,17:159.10
-24,-9,17:100.0
-23,-9,17:100.0
20,-9,17:100.0
21,-9,17:100.0
22,-9,17:100.0
23,-9,17:100.0
24,-9,17:159.10
25,-9,17:159.10
-25,-8,17:159.10
-24,-8,17:100.0
16,-8,17:100.0
18,-8,17:100.0
19,-8,17:100.0
20,-8,17:100.0
21,-8,17:100.0
22,-8,17:100.0
23,-8,17:100.0
24,-8,17:159.10
25,-8,17:159.10
-25,-7,17:159.10
-24,-7,17:100.0
2,-7,17:100.15
3,-7,17:100.15
15,-7,17:100.0
16,-7,17:100.0
17,-7,17:100.0
18,-7,17:100.0
21,-7,17:100.0
22,-7,17:100.0
23,-7,17:100.0
24,-7,17:100.0
25,-7,17:159.10
-25,-6,17:159.10
-24,-6,17:100.0
-18,-6,17:100.0
-17,-6,17:100.0
-16,-6,17:100.0
2,-6,17:100.15
3,-6,17:100.15
17,-6,17:100.0
22,-6,17:100.0
23,-6,17:100.0
24,-6,17:100.0
25,-6,17:159.10
-25,-5,17:159.10
-24,-5,17:100.0
-15,-5,17:100.0
-14,-5,17:100.0
2,-5,17:100.15
3,-5,17:100.15
17,-5,17:100.0
22,-5,17:100.0
23,-5,17:100.0
24,-5,17:100.0
25,-5,17:159.10
-25,-4,17:159.10
-24,-4,17:100.0
-23,-4,17:100.0
22,-4,17:100.0
23,-4,17:100.0
24,-4,17:100.0
25,-4,17:100.0
26,-4,17:159.10
-25,-3,17:159.10
-24,-3,17:100.0
-23,-3,17:100.0
23,-3,17:100.0
24,-3,17:100.0
25,-3,17:100.0
26,-3,17:159.10
-25,-2,17:159.10
-24,-2,17:100.0
-23,-2,17:100.0
23,-2,17:100.0
24,-2,17:100.0
25,-2,17:100.0
26,-2,17:159.10
-25,-1,17:159.10
-24,-1,17:100.0
-23,-1,17:100.0
-22,-1,17:100.0
23,-1,17:100.0
24,-1,17:100.0
25,-1,17:100.0
26,-1,17:159.10
-24,0,17:100.0
-23,0,17:100.0
-22,0,17:100.0
-10,0,17:100.15
-9,0,17:100.15
-8,0,17:100.15
24,0,17:100.0
25,0,17:100.0
26,0,17:159.10
-24,1,17:159.10
-23,1,17:100.0
-22,1,17:100.0
-10,1,17:100.15
-9,1,17:100.15
24,1,17:100.0
25,1,17:100.0
26,1,17:159.10
-24,2,17:100.0
-23,2,17:100.0
-22,2,17:100.0
-21,2,17:100.0
-9,2,17:100.15
1,2,17:100.15
2,2,17:100.15
3,2,17:100.15
4,2,17:100.15
24,2,17:100.0
26,2,17:159.10
-24,3,17:159.10
-23,3,17:100.0
-22,3,17:100.0
-21,3,17:100.0
2,3,17:100.15
3,3,17:100.15
4,3,17:100.15
25,3,17:100.0
26,3,17:159.10
-24,4,17:159.10
-23,4,17:100.0
-22,4,17:100.0
-21,4,17:100.0
25,4,17:100.0
26,4,17:100.0
-24,5,17:159.10
-22,5,17:100.0
-21,5,17:100.0
25,5,17:100.0
26,5,17:100.0
-24,6,17:159.10
-23,6,17:159.10
-22,6,17:100.0
-21,6,17:100.0
-20,6,17:100.0
25,6,17:100.0
26,6,17:100.0
-24,7,17:159.10
-23,7,17:159.10
-22,7,17:100.0
-21,7,17:100.0
-20,7,17:100.0
24,7,17:100.0
25,7,17:100.0
26,7,17:159.10
-24,8,17:159.10
-23,8,17:159.10
-22,8,17:100.0
-21,8,17:100.0
-20,8,17:100.0
23,8,17:100.0
24,8,17:100.0
25,8,17:159.10
-23,9,17:159.10
-22,9,17:159.10
-21,9,17:100.0
-20,9,17:100.0
-19,9,17:100.0
21,9,17:100.0
22,9,17:100.0
23,9,17:100.0
24,9,17:159.10
-23,10,17:159.10
-22,10,17:159.10
-21,10,17:100.0
-20,10,17:100.0
-19,10,17:100.0
-18,10,17:100.0
20,10,17:100.0
21,10,17:100.0
22,10,17:100.0
-22,11,17:159.10
-21,11,17:159.10
-19,11,17:100.0
-18,11,17:100.0
19,11,17:100.0
20,11,17:100.0
21,11,17:100.0
22,11,17:159.10
-21,12,17:159.10
-20,12,17:100.0
-19,12,17:100.0
-18,12,17:100.0
-17,12,17:100.0
17,12,17:100.0
18,12,17:100.0
19,12,17:100.0
20,12,17:100.0
21,12,17:159.10
-21,13,17:159.10
-20,13,17:159.10
-19,13,17:100.0
-18,13,17:100.0
-17,13,17:100.0
9,13,17:100.0
16,13,17:100.0
17,13,17:100.0
18,13,17:100.0
19,13,17:100.0
20,13,17:159.10
-20,14,17:159.10
-19,14,17:159.10
-18,14,17:100.0
-17,14,17:100.0
-16,14,17:100.0
6,14,17:100.0
7,14,17:100.0
8,14,17:100.0
14,14,17:100.0
15,14,17:100.0
16,14,17:100.0
17,14,17:100.0
18,14,17:100.0
19,14,17:159.10
-19,15,17:82.0
-18,15,17:100.0
-17,15,17:100.0
-16,15,17:100.0
3,15,17:100.0
4,15,17:100.0
5,15,17:100.0
6,15,17:100.0
13,15,17:100.0
14,15,17:100.0
15,15,17:100.0
16,15,17:100.0
17,15,17:159.10
18,15,17:159.10
-18,16,17:82.0
-17,16,17:100.0
-16,16,17:100.0
-15,16,17:100.0
-9,16,17:100.0
12,16,17:100.0
13,16,17:100.0
14,16,17:100.0
15,16,17:100.0
16,16,17:159.10
17,16,17:159.10
-17,17,17:159.10
-16,17,17:100.0
-15,17,17:100.0
10,17,17:100.0
11,17,17:100.0
12,17,17:100.0
13,17,17:100.0
14,17,17:100.0
15,17,17:159.10
16,17,17:159.10
-16,18,17:159.10
-15,18,17:100.0
-14,18,17:100.0
-4,18,17:100.0
9,18,17:100.0
10,18,17:100.0
11,18,17:100.0
12,18,17:100.0
13,18,17:100.0
14,18,17:159.10
15,18,17:159.10
-15,19,17:159.10
-14,19,17:100.0
-4,19,17:100.0
3,19,17:100.0
4,19,17:100.0
5,19,17:100.0
6,19,17:100.0
7,19,17:100.0
8,19,17:100.0
9,19,17:100.0
10,19,17:100.0
11,19,17:100.0
12,19,17:159.10
13,19,17:159.10
14,19,17:159.10
-14,20,17:159.10
-13,20,17:100.0
-12,20,17:100.0
-5,20,17:100.0
-4,20,17:100.0
-3,20,17:100.0
-2,20,17:100.0
-1,20,17:100.0
0,20,17:100.0
1,20,17:100.0
2,20,17:100.0
3,20,17:100.0
4,20,17:100.0
5,20,17:100.0
6,20,17:100.0
7,20,17:100.0
8,20,17:100.0
9,20,17:100.0
10,20,17:100.0
11,20,17:159.10
12,20,17:159.10
13,20,17:159.10
-13,21,17:159.10
-12,21,17:159.10
-11,21,17:100.0
-10,21,17:100.0
-9,21,17:100.0
-8,21,17:100.0
-7,21,17:100.0
-6,21,17:100.0
-5,21,17:100.0
-4,21,17:100.0
-3,21,17:100.0
-2,21,17:100.0
-1,21,17:100.0
0,21,17:100.0
1,21,17:100.0
2,21,17:100.0
3,21,17:100.0
4,21,17:100.0
5,21,17:100.0
6,21,17:100.0
7,21,17:100.0
8,21,17:159.10
9,21,17:159.10
10,21,17:159.10
11,21,17:159.10
-12,22,17:159.10
-11,22,17:159.10
-10,22,17:159.10
-9,22,17:159.10
-8,22,17:159.10
-7,22,17:159.10
-6,22,17:159.10
-5,22,17:159.10
-4,22,17:100.0
-3,22,17:159.10
-2,22,17:159.10
-1,22,17:159.10
0,22,17:159.10
1,22,17:159.10
3,22,17:159.10
4,22,17:159.10
5,22,17:159.10
6,22,17:159.10
7,22,17:159.10
8,22,17:159.10
9,22,17:159.10
-2,-25,18:159.10
-1,-25,18:159.10
1,-25,18:159.10
2,-25,18:159.10
3,-25,18:159.10
4,-25,18:159.10
5,-25,18:159.10
6,-25,18:159.10
7,-25,18:159.10
8,-25,18:159.10
9,-25,18:159.10
10,-25,18:159.10
11,-25,18:159.10
12,-25,18:159.10
-6,-24,18:159.10
-5,-24,18:159.10
-4,-24,18:159.10
-3,-24,18:159.10
-2,-24,18:159.10
-1,-24,18:159.10
0,-24,18:82.0
1,-24,18:82.0
2,-24,18:82.0
3,-24,18:159.10
4,-24,18:159.10
5,-24,18:159.10
6,-24,18:159.10
7,-24,18:159.10
8,-24,18:100.0
9,-24,18:100.0
10,-24,18:100.0
11,-24,18:100.0
12,-24,18:159.10
13,-24,18:159.10
-9,-23,18:159.10
-8,-23,18:159.10
-7,-23,18:159.10
-6,-23,18:159.10
-5,-23,18:159.10
-4,-23,18:159.10
-3,-23,18:159.10
-2,-23,18:159.10
-1,-23,18:159.10
0,-23,18:82.0
1,-23,18:82.0
2,-23,18:82.0
3,-23,18:100.0
4,-23,18:100.0
5,-23,18:100.0
6,-23,18:100.0
7,-23,18:100.0
8,-23,18:100.0
9,-23,18:100.0
10,-23,18:100.0
11,-23,18:100.0
12,-23,18:100.0
13,-23,18:159.10
14,-23,18:159.10
-11,-22,18:159.10
-10,-22,18:159.10
-8,-22,18:159.10
-7,-22,18:159.10
-6,-22,18:159.10
-5,-22,18:159.10
-4,-22,18:159.10
-3,-22,18:159.10
-2,-22,18:159.10
-1,-22,18:100.0
0,-22,18:100.0
1,-22,18:100.0
2,-22,18:100.0
3,-22,18:100.0
4,-22,18:100.0
5,-22,18:100.0
7,-22,18:100.0
8,-22,18:100.0
9,-22,18:100.0
10,-22,18:100.0
11,-22,18:100.0
12,-22,18:100.0
13,-22,18:100.0
14,-22,18:159.10
15,-22,18:159.10
-12,-21,18:159.10
-11,-21,18:159.10
-10,-21,18:159.10
-9,-21,18:159.10
-8,-21,18:159.10
-7,-21,18:82.0
-6,-21,18:82.0
-5,-21,18:100.0
-4,-21,18:100.0
-3,-21,18:100.0
-2,-21,18:100.0
-1,-21,18:100.0
0,-21,18:100.0
1,-21,18:100.0
2,-21,18:100.0
3,-21,18:100.0
4,-21,18:100.0
5,-21,18:100.0
6,-21,18:100.0
7,-21,18:100.0
9,-21,18:100.0
10,-21,18:100.0
11,-21,18:100.0
12,-21,18:100.0
13,-21,18:100.0
14,-21,18:159.10
15,-21,18:159.10
-13,-20,18:159.10
-12,-20,18:159.10
-11,-20,18:159.10
-10,-20,18:159.10
-9,-20,18:159.10
-8,-20,18:100.0
-7,-20,18:100.0
-6,-20,18:100.0
-5,-20,18:100.0
-4,-20,18:100.0
-3,-20,18:100.0
-2,-20,18:100.0
-1,-20,18:100.0
0,-20,18:100.0
1,-20,18:100.0
2,-20,18:100.0
3,-20,18:100.0
9,-20,18:100.0
11,-20,18:100.0
12,-20,18:100.0
13,-20,18:100.0
14,-20,18:100.0
15,-20,18:159.10
16,-20,18:159.10
-15,-19,18:159.10
-14,-19,18:159.10
-13,-19,18:159.10
-12,-19,18:159.10
-11,-19,18:159.10
-10,-19,18:100.0
-9,-19,18:100.0
-8,-19,18:100.0
-7,-19,18:100.0
-6,-19,18:100.0
-5,-19,18:100.0
-4,-19,18:100.0
-3,-19,18:100.0
-2,-19,18:100.0
-1,-19,18:100.0
0,-19,18:100.0
9,-19,18:100.0
12,-19,18:100.0
13,-19,18:100.0
14,-19,18:100.0
15,-19,18:159.10
16,-19,18:159.10
17,-19,18:159.10
-16,-18,18:159.10
-15,-18,18:159.10
-14,-18,18:159.10
-13,-18,18:159.10
-12,-18,18:159.10
-11,-18,18:100.0
-10,-18,18:100.0
-9,-18,18:100.0
-8,-18,18:100.0
-7,-18,18:100.0
-6,-18,18:100.0
-5,-18,18:100.0
-4,-18,18:100.0
-3,-18,18:100.0
-2,-18,18:100.0
-1,-18,18:100.0
8,-18,18:100.0
12,-18,18:100.0
13,-18,18:100.0
14,-18,18:100.0
15,-18,18:100.0
16,-18,18:159.10
17,-18,18:159.10
18,-18,18:159.10
-17,-17,18:159.10
-16,-17,18:159.10
-15,-17,18:159.10
-14,-17,18:159.10
-13,-17,18:159.10
-12,-17,18:100.0
-11,-17,18:100.0
-10,-17,18:100.0
-9,-17,18:100.0
-8,-17,18:100.0
-7,-17,18:100.0
-6,-17,18:100.0
-5,-17,18:100.0
-4,-17,18:100.0
-3,-17,18:100.0
8,-17,18:100.0
13,-17,18:100.0
14,-17,18:100.0
15,-17,18:100.0
16,-17,18:159.10
17,-17,18:159.10
18,-17,18:159.10
19,-17,18:159.10
-18,-16,18:159.10
-17,-16,18:159.10
-16,-16,18:159.10
-15,-16,18:159.10
-14,-16,18:100.0
-13,-16,18:100.0
-12,-16,18:100.0
-11,-16,18:100.0
-10,-16,18:100.0
-9,-16,18:100.0
-8,-16,18:100.0
-7,-16,18:100.0
-6,-16,18:100.0
-5,-16,18:100.0
7,-16,18:100.0
13,-16,18:100.0
14,-16,18:100.0
15,-16,18:100.0
16,-16,18:100.0
17,-16,18:159.10
18,-16,18:159.10
19,-16,18:159.10
-19,-15,18:82.0
-18,-15,18:82.0
-17,-15,18:82.0
-16,-15,18:159.10
-15,-15,18:100.0
-14,-15,18:100.0
-13,-15,18:100.0
-12,-15,18:100.0
-11,-15,18:100.0
-10,-15,18:100.0
-9,-15,18:100.0
-8,-15,18:100.0
-7,-15,18:100.0
14,-15,18:100.0
15,-15,18:100.0
16,-15,18:100.0
17,-15,18:159.10
18,-15,18:159.10
19,-15,18:159.10
20,-15,18:159.10
-20,-14,18:159.10
-19,-14,18:82.0
-18,-14,18:82.0
-17,-14,18:82.0
-16,-14,18:100.0
-15,-14,18:100.0
-14,-14,18:100.0
-13,-14,18:100.0
-12,-14,18:100.0
-11,-14,18:100.0
-10,-14,18:100.0
14,-14,18:100.0
15,-14,18:100.0
16,-14,18:100.0
17,-14,18:100.0
18,-14,18:159.10
19,-14,18:159.10
20,-14,18:159.10
21,-14,18:159.10
-21,-13,18:159.10
-20,-13,18:159.10
-19,-13,18:82.0
-18,-13,18:82.0
-17,-13,18:100.0
-16,-13,18:100.0
-15,-13,18:100.0
-14,-13,18:100.0
-13,-13,18:100.0
-12,-13,18:100.0
15,-13,18:100.0
16,-13,18:100.0
17,-13,18:100.0
18,-13,18:159.10
19,-13,18:159.10
20,-13,18:159.10
21,-13,18:159.10
-21,-12,18:159.10
-20,-12,18:159.10
-19,-12,18:100.0
-18,-12,18:100.0
-17,-12,18:100.0
-16,-12,18:100.0
-15,-12,18:100.0
14,-12,18:100.0
15,-12,18:100.0
16,-12,18:100.0
17,-12,18:100.0
18,-12,18:100.0
19,-12,18:159.10
20,-12,18:159.10
21,-12,18:159.10
-22,-11,18:159.10
-21,-11,18:159.10
-20,-11,18:100.0
-19,-11,18:100.0
-18,-11,18:100.0
-17,-11,18:100.0
-16,-11,18:100.0
15,-11,18:100.0
16,-11,18:100.0
17,-11,18:100.0
18,-11,18:100.0
19,-11,18:159.10
20,-11,18:159.10
21,-11,18:159.10
22,-11,18:159.10
-23,-10,18:159.10
-22,-10,18:159.10
-21,-10,18:100.0
-20,-10,18:100.0
-19,-10,18:100.0
-18,-10,18:100.0
-17,-10,18:100.0
-15,-10,18:100.0
-14,-10,18:100.0
4,-10,18:100.0
15,-10,18:100.0
16,-10,18:100.0
17,-10,18:100.0
18,-10,18:100.0
19,-10,18:100.0
20,-10,18:159.10
21,-10,18:159.10
22,-10,18:159.10
-24,-9,18:159.10
-23,-9,18:159.10
-22,-9,18:100.0
-21,-9,18:100.0
-20,-9,18:100.0
-19,-9,18:100.0
-14,-9,18:100.0
-13,-9,18:100.0
4,-9,18:100.0
15,-9,18:100.0
16,-9,18:100.0
17,-9,18:100.0
18,-9,18:100.0
19,-9,18:100.0
20,-9,18:159.10
21,-9,18:159.10
22,-9,18:159.10
23,-9,18:159.10
-24,-8,18:159.10
-23,-8,18:100.0
-22,-8,18:100.0
-21,-8,18:100.0
-20,-8,18:100.0
4,-8,18:100.0
15,-8,18:100.0
16,-8,18:159.10
17,-8,18:100.0
18,-8,18:100.0
19,-8,18:100.0
20,-8,18:100.0
21,-8,18:159.10
22,-8,18:159.10
23,-8,18:159.10
-24,-7,18:159.10
-23,-7,18:100.0
-22,-7,18:100.0
-21,-7,18:100.0
-20,-7,18:100.0
-19,-7,18:100.0
3,-7,18:100.15
4,-7,18:100.15
15,-7,18:100.0
16,-7,18:159.10
17,-7,18:100.0
18,-7,18:100.0
19,-7,18:100.0
20,-7,18:100.0
21,-7,18:159.10
22,-7,18:82.0
23,-7,18:82.0
24,-7,18:82.0
-24,-6,18:159.10
-23,-6,18:100.0
-22,-6,18:100.0
-21,-6,18:100.0
-18,-6,18:100.0
-17,-6,18:100.0
-16,-6,18:100.0
3,-6,18:100.15
13,-6,18:100.0
14,-6,18:100.0
15,-6,18:100.0
16,-6,18:100.0
17,-6,18:159.10
18,-6,18:100.0
19,-6,18:100.0
20,-6,18:100.0
21,-6,18:100.0
22,-6,18:82.0
23,-6,18:82.0
24,-6,18:82.0
-24,-5,18:159.10
-23,-5,18:100.0
-22,-5,18:100.0
-21,-5,18:100.0
-15,-5,18:100.0
-14,-5,18:100.0
-13,-5,18:100.0
11,-5,18:100.0
12,-5,18:100.0
17,-5,18:159.10
18,-5,18:100.0
19,-5,18:100.0
20,-5,18:100.0
21,-5,18:100.0
22,-5,18:82.0
23,-5,18:82.0
24,-5,18:82.0
-24,-4,18:159.10
-23,-4,18:159.10
-22,-4,18:100.0
-21,-4,18:100.0
-20,-4,18:100.0
-12,-4,18:100.0
18,-4,18:100.0
19,-4,18:100.0
20,-4,18:100.0
21,-4,18:100.0
22,-4,18:159.10
23,-4,18:159.10
24,-4,18:159.10
25,-4,18:159.10
-24,-3,18:159.10
-23,-3,18:159.10
-22,-3,18:100.0
-21,-3,18:100.0
-20,-3,18:100.0
18,-3,18:100.0
19,-3,18:100.0
20,-3,18:100.0
21,-3,18:100.0
22,-3,18:100.0
23,-3,18:159.10
24,-3,18:159.10
25,-3,18:159.10
-24,-2,18:159.10
-23,-2,18:159.10
-22,-2,18:100.0
-21,-2,18:100.0
-20,-2,18:100.0
19,-2,18:100.0
20,-2,18:100.0
21,-2,18:100.0
22,-2,18:100.0
23,-2,18:159.10
24,-2,18:159.10
25,-2,18:159.10
-24,-1,18:159.10
-23,-1,18:159.10
-22,-1,18:159.10
-21,-1,18:100.0
-20,-1,18:100.0
-19,-1,18:100.0
20,-1,18:100.0
21,-1,18:100.0
22,-1,18:100.0
23,-1,18:159.10
24,-1,18:159.10
25,-1,18:159.10
-24,0,18:159.10
-23,0,18:159.10
-22,0,18:82.0
-21,0,18:100.0
-20,0,18:100.0
-18,0,18:100.0
-12,0,18:100.0
-10,0,18:100.15
-9,0,18:100.15
20,0,18:100.0
21,0,18:100.0
22,0,18:100.0
23,0,18:100.0
24,0,18:159.10
25,0,18:159.10
-23,1,18:159.10
-22,1,18:82.0
-21,1,18:100.0
-20,1,18:100.0
-19,1,18:100.0
-18,1,18:100.0
-12,1,18:100.0
-10,1,18:100.15
-9,1,18:100.15
21,1,18:100.0
22,1,18:100.0
23,1,18:100.0
24,1,18:159.10
25,1,18:159.10
-24,2,18:159.10
-23,2,18:159.10
-22,2,18:82.0
-21,2,18:82.0
-20,2,18:100.0
-19,2,18:100.0
-17,2,18:100.0
-11,2,18:100.0
-10,2,18:100.0
2,2,18:100.15
3,2,18:100.15
4,2,18:100.15
21,2,18:100.0
22,2,18:100.0
23,2,18:100.0
24,2,18:159.10
-23,3,18:159.10
-22,3,18:159.10
-21,3,18:82.0
-20,3,18:100.0
-19,3,18:100.0
-18,3,18:100.0
-17,3,18:100.0
-16,3,18:100.0
-11,3,18:100.0
-10,3,18:100.0
3,3,18:100.15
4,3,18:100.15
21,3,18:100.0
22,3,18:100.0
23,3,18:100.0
24,3,18:100.0
25,3,18:159.10
-23,4,18:159.10
-22,4,18:159.10
-21,4,18:159.10
-20,4,18:100.0
-19,4,18:100.0
-18,4,18:100.0
-17,4,18:100.0
-16,4,18:100.0
-11,4,18:100.0
-10,4,18:100.0
-9,4,18:100.0
23,4,18:100.0
24,4,18:100.0
25,4,18:159.10
26,4,18:159.10
-22,5,18:159.10
-21,5,18:159.10
-20,5,18:100.0
-19,5,18:100.0
-18,5,18:100.0
-17,5,18:100.0
-16,5,18:100.0
-15,5,18:100.0
-10,5,18:100.0
20,5,18:100.0
21,5,18:100.0
22,5,18:100.0
23,5,18:100.0
24,5,18:100.0
25,5,18:159.10
26,5,18:159.10
-22,6,18:159.10
-21,6,18:159.10
-20,6,18:159.10
-19,6,18:100.0
-18,6,18:100.0
-17,6,18:100.0
-16,6,18:100.0
-15,6,18:100.0
21,6,18:100.0
22,6,18:100.0
23,6,18:100.0
24,6,18:100.0
25,6,18:82.0
26,6,18:159.10
-22,7,18:159.10
-21,7,18:159.10
-20,7,18:159.10
-19,7,18:100.0
-18,7,18:100.0
-17,7,18:100.0
-16,7,18:100.0
-15,7,18:100.0
-14,7,18:100.0
19,7,18:100.0
20,7,18:100.0
21,7,18:100.0
22,7,18:100.0
23,7,18:100.0
24,7,18:82.0
25,7,18:159.10
-22,8,18:159.10
-21,8,18:159.10
-20,8,18:159.10
-19,8,18:100.0
-18,8,18:100.0
-17,8,18:100.0
-16,8,18:100.0
-15,8,18:100.0
-14,8,18:100.0
18,8,18:100.0
19,8,18:100.0
20,8,18:100.0
21,8,18:100.0
22,8,18:100.0
23,8,18:159.10
24,8,18:159.10
-21,9,18:159.10
-20,9,18:159.10
-19,9,18:159.10
-18,9,18:100.0
-17,9,18:100.0
-16,9,18:100.0
-15,9,18:100.0
-14,9,18:100.0
17,9,18:100.0
18,9,18:100.0
19,9,18:100.0
20,9,18:100.0
21,9,18:159.10
22,9,18:159.10
23,9,18:159.10
-21,10,18:159.10
-20,10,18:159.10
-19,10,18:159.10
-18,10,18:159.10
-17,10,18:100.0
-16,10,18:100.0
-15,10,18:100.0
-14,10,18:100.0
15,10,18:100.0
16,10,18:100.0
17,10,18:100.0
18,10,18:100.0
19,10,18:100.0
20,10,18:159.10
21,10,18:159.10
22,10,18:159.10
-19,11,18:159.10
-18,11,18:159.10
-17,11,18:100.0
-16,11,18:100.0
-15,11,18:100.0
-14,11,18:100.0
-2,11,18:100.0
12,11,18:100.0
13,11,18:100.0
14,11,18:100.0
15,11,18:100.0
16,11,18:100.0
18,11,18:100.0
19,11,18:159.10
20,11,18:159.10
21,11,18:159.10
-20,12,18:159.10
-19,12,18:159.10
-18,12,18:159.10
-17,12,18:159.10
-16,12,18:100.0
-15,12,18:100.0
-14,12,18:100.0
-2,12,18:100.0
10,12,18:100.0
11,12,18:100.0
12,12,18:100.0
13,12,18:100.0
14,12,18:100.0
15,12,18:100.0
16,12,18:100.0
17,12,18:159.10
18,12,18:159.10
19,12,18:159.10
20,12,18:159.10
-19,13,18:159.10
-18,13,18:159.10
-17,13,18:159.10
-16,13,18:100.0
-15,13,18:100.0
-14,13,18:100.0
-13,13,18:100.0
-7,13,18:100.0
7,13,18:100.0
8,13,18:100.0
9,13,18:159.10
10,13,18:100.0
11,13,18:100.0
12,13,18:100.0
13,13,18:100.0
14,13,18:100.0
15,13,18:100.0
16,13,18:159.10
17,13,18:159.10
18,13,18:159.10
19,13,18:159.10
-18,14,18:82.0
-17,14,18:82.0
-16,14,18:159.10
-15,14,18:100.0
-14,14,18:100.0
-13,14,18:100.0
5,14,18:100.0
6,14,18:82.0
7,14,18:82.0
8,14,18:82.0
9,14,18:100.0
10,14,18:100.0
11,14,18:100.0
12,14,18:100.0
13,14,18:100.0
14,14,18:159.10
15,14,18:159.10
16,14,18:159.10
17,14,18:159.10
18,14,18:159.10
-18,15,18:82.0
-17,15,18:82.0
-16,15,18:159.10
-15,15,18:100.0
-14,15,18:100.0
-13,15,18:100.0
-12,15,18:100.0
-9,15,18:100.0
2,15,18:100.0
3,15,18:159.10
4,15,18:159.10
5,15,18:159.10
6,15,18:82.0
7,15,18:100.0
8,15,18:100.0
9,15,18:100.0
10,15,18:100.0
11,15,18:100.0
12,15,18:100.0
13,15,18:159.10
14,15,18:159.10
15,15,18:159.10
16,15,18:159.10
-17,16,18:82.0
-16,16,18:159.10
-15,16,18:159.10
-14,16,18:100.0
-13,16,18:100.0
-12,16,18:100.0
-9,16,18:100.0
0,16,18:100.0
1,16,18:100.0
2,16,18:100.0
3,16,18:100.0
4,16,18:100.0
5,16,18:100.0
6,16,18:100.0
7,16,18:100.0
8,16,18:100.0
9,16,18:100.0
10,16,18:100.0
11,16,18:100.0
12,16,18:82.0
13,16,18:82.0
14,16,18:82.0
15,16,18:159.10
-16,17,18:159.10
-15,17,18:159.10
-14,17,18:100.0
-13,17,18:100.0
-12,17,18:100.0
-11,17,18:100.0
-10,17,18:100.0
-9,17,18:100.0
-2,17,18:100.0
-1,17,18:100.0
0,17,18:100.0
1,17,18:100.0
2,17,18:100.0
3,17,18:100.0
4,17,18:100.0
5,17,18:100.0
7,17,18:100.0
8,17,18:100.0
9,17,18:100.0
10,17,18:159.10
11,17,18:159.10
12,17,18:82.0
13,17,18:82.0
14,17,18:82.0
-15,18,18:159.10
-14,18,18:159.10
-13,18,18:100.0
-12,18,18:100.0
-11,18,18:100.0
-10,18,18:100.0
-9,18,18:100.0
-8,18,18:100.0
-7,18,18:100.0
-6,18,18:100.0
-5,18,18:100.0
-4,18,18:100.0
-3,18,18:100.0
-2,18,18:100.0
-1,18,18:100.0
0,18,18:100.0
1,18,18:100.0
2,18,18:100.0
3,18,18:100.0
4,18,18:100.0
5,18,18:100.0
6,18,18:100.0
7,18,18:100.0
8,18,18:100.0
9,18,18:159.10
10,18,18:159.10
11,18,18:159.10
12,18,18:82.0
13,18,18:82.0
-14,19,18:159.10
-13,19,18:100.0
-12,19,18:100.0
-11,19,18:100.0
-10,19,18:100.0
-9,19,18:100.0
-8,19,18:100.0
-7,19,18:100.0
-6,19,18:100.0
-5,19,18:100.0
-4,19,18:100.0
-3,19,18:100.0
-2,19,18:100.0
-1,19,18:100.0
0,19,18:100.0
1,19,18:100.0
2,19,18:100.0
3,19,18:159.10
4,19,18:159.10
5,19,18:159.10
6,19,18:159.10
7,19,18:159.10
8,19,18:159.10
9,19,18:159.10
10,19,18:159.10
11,19,18:159.10
-13,20,18:159.10
-12,20,18:159.10
-11,20,18:100.0
-10,20,18:100.0
-9,20,18:100.0
-8,20,18:100.0
-7,20,18:100.0
-6,20,18:100.0
-5,20,18:159.10
-4,20,18:100.0
-3,20,18:159.10
-2,20,18:159.10
-1,20,18:159.10
0,20,18:159.10
1,20,18:159.10
2,20,18:159.10
3,20,18:159.10
4,20,18:159.10
5,20,18:159.10
6,20,18:159.10
7,20,18:159.10
8,20,18:159.10
9,20,18:159.10
10,20,18:159.10
-11,21,18:159.10
-10,21,18:159.10
-9,21,18:159.10
-8,21,18:159.10
-7,21,18:159.10
-6,21,18:159.10
-5,21,18:159.10
-4,21,18:100.0
-3,21,18:159.10
-2,21,18:159.10
-1,21,18:159.10
0,21,18:159.10
1,21,18:159.10
2,21,18:159.10
3,21,18:159.10
4,21,18:159.10
5,21,18:159.10
6,21,18:159.10
7,21,18:159.10
-4,22,18:159.10
8,-24,19:159.10
9,-24,19:159.10
10,-24,19:159.10
11,-24,19:159.10
3,-23,19:159.10
4,-23,19:159.10
5,-23,19:159.10
6,-23,19:159.10
7,-23,19:159.10
8,-23,19:159.10
9,-23,19:159.10
10,-23,19:159.10
11,-23,19:159.10
12,-23,19:159.10
-1,-22,19:159.10
0,-22,19:159.10
1,-22,19:82.0
2,-22,19:159.10
3,-22,19:159.10
4,-22,19:159.10
5,-22,19:159.10
7,-22,19:159.10
8,-22,19:159.10
9,-22,19:159.10
10,-22,19:159.10
11,-22,19:159.10
12,-22,19:159.10
13,-22,19:159.10
-5,-21,19:82.0
-4,-21,19:159.10
-3,-21,19:159.10
-2,-21,19:159.10
-1,-21,19:159.10
0,-21,19:159.10
1,-21,19:159.10
2,-21,19:159.10
3,-21,19:159.10
4,-21,19:159.10
5,-21,19:159.10
6,-21,19:159.10
7,-21,19:159.10
8,-21,19:100.0
9,-21,19:100.0
10,-21,19:100.0
11,-21,19:82.0
12,-21,19:159.10
13,-21,19:159.10
-8,-20,19:82.0
-7,-20,19:82.0
-6,-20,19:82.0
-5,-20,19:82.0
-4,-20,19:82.0
-3,-20,19:159.10
-2,-20,19:159.10
-1,-20,19:159.10
0,-20,19:159.10
1,-20,19:159.10
2,-20,19:159.10
3,-20,19:159.10
4,-20,19:100.0
5,-20,19:100.0
6,-20,19:100.0
7,-20,19:100.0
8,-20,19:100.0
9,-20,19:100.0
10,-20,19:100.0
11,-20,19:82.0
12,-20,19:82.0
13,-20,19:159.10
14,-20,19:159.10
-10,-19,19:159.10
-9,-19,19:159.10
-8,-19,19:82.0
-7,-19,19:82.0
-6,-19,19:82.0
-5,-19,19:82.0
-4,-19,19:82.0
-3,-19,19:159.10
-2,-19,19:159.10
-1,-19,19:159.10
0,-19,19:100.0
1,-19,19:100.0
2,-19,19:100.0
3,-19,19:100.0
4,-19,19:100.0
5,-19,19:100.0
6,-19,19:100.0
7,-19,19:100.0
8,-19,19:100.0
9,-19,19:100.0
10,-19,19:100.0
11,-19,19:100.0
12,-19,19:82.0
13,-19,19:159.10
14,-19,19:159.10
-11,-18,19:159.10
-10,-18,19:159.10
-9,-18,19:159.10
-8,-18,19:82.0
-7,-18,19:82.0
-6,-18,19:82.0
-5,-18,19:82.0
-4,-18,19:100.0
-3,-18,19:100.0
-2,-18,19:100.0
-1,-18,19:100.0
0,-18,19:100.0
1,-18,19:100.0
2,-18,19:100.0
3,-18,19:100.0
4,-18,19:100.0
5,-18,19:100.0
6,-18,19:100.0
7,-18,19:100.0
8,-18,19:100.0
9,-18,19:100.0
10,-18,19:100.0
11,-18,19:100.0
12,-18,19:82.0
13,-18,19:159.10
14,-18,19:159.10
15,-18,19:159.10
-12,-17,19:159.10
-11,-17,19:159.10
-10,-17,19:159.10
-9,-17,19:159.10
-8,-17,19:159.10
-7,-17,19:100.0
-6,-17,19:82.0
-5,-17,19:82.0
-4,-17,19:100.0
-3,-17,19:100.0
-2,-17,19:100.0
-1,-17,19:100.0
0,-17,19:100.0
1,-17,19:100.0
2,-17,19:100.0
3,-17,19:100.0
4,-17,19:100.0
5,-17,19:100.0
6,-17,19:100.0
7,-17,19:100.0
8,-17,19:100.0
9,-17,19:100.0
10,-17,19:100.0
11,-17,19:100.0
12,-17,19:100.0
13,-17,19:159.10
14,-17,19:159.10
15,-17,19:159.10
-14,-16,19:159.10
-13,-16,19:159.10
-12,-16,19:159.10
-11,-16,19:159.10
-10,-16,19:159.10
-9,-16,19:100.0
-8,-16,19:159.10
-7,-16,19:159.10
-6,-16,19:159.10
-5,-16,19:100.0
-4,-16,19:100.0
-3,-16,19:100.0
-1,-16,19:100.0
0,-16,19:100.0
1,-16,19:100.0
2,-16,19:100.0
3,-16,19:100.0
4,-16,19:100.0
5,-16,19:100.0
6,-16,19:100.0
7,-16,19:100.0
8,-16,19:100.0
9,-16,19:100.0
10,-16,19:100.0
12,-16,19:100.0
13,-16,19:159.10
14,-16,19:159.10
15,-16,19:159.10
16,-16,19:159.10
-15,-15,19:159.10
-14,-15,19:159.10
-13,-15,19:159.10
-12,-15,19:159.10
-11,-15,19:159.10
-10,-15,19:100.0
-9,-15,19:159.10
-8,-15,19:100.0
-7,-15,19:100.0
-6,-15,19:100.0
-5,-15,19:100.0
-4,-15,19:100.0
-3,-15,19:100.0
-2,-15,19:100.0
-1,-15,19:100.0
0,-15,19:100.0
1,-15,19:100.0
2,-15,19:100.0
3,-15,19:100.0
4,-15,19:100.0
5,-15,19:100.0
6,-15,19:100.0
8,-15,19:100.0
9,-15,19:100.0
10,-15,19:100.0
11,-15,19:100.0
12,-15,19:100.0
13,-15,19:100.0
14,-15,19:159.10
15,-15,19:159.10
16,-15,19:159.10
-16,-14,19:159.10
-15,-14,19:159.10
-14,-14,19:159.10
-13,-14,19:159.10
-12,-14,19:159.10
-11,-14,19:100.0
-10,-14,19:100.0
-9,-14,19:100.0
-8,-14,19:100.0
-7,-14,19:100.0
-6,-14,19:100.0
-5,-14,19:100.0
-4,-14,19:100.0
-3,-14,19:100.0
-2,-14,19:100.0
-1,-14,19:100.0
0,-14,19:100.0
1,-14,19:100.0
2,-14,19:100.0
3,-14,19:100.0
4,-14,19:100.0
6,-14,19:100.0
7,-14,19:100.0
8,-14,19:100.0
9,-14,19:100.0
10,-14,19:100.0
11,-14,19:100.0
12,-14,19:100.0
13,-14,19:100.0
14,-14,19:159.10
15,-14,19:159.10
16,-14,19:159.10
17,-14,19:159.10
-17,-13,19:159.10
-16,-13,19:159.10
-15,-13,19:159.10
-14,-13,19:159.10
-13,-13,19:100.0
-12,-13,19:100.0
-11,-13,19:100.0
-10,-13,19:100.0
-9,-13,19:100.0
-8,-13,19:100.0
-7,-13,19:100.0
-6,-13,19:100.0
-5,-13,19:100.0
-4,-13,19:100.0
-3,-13,19:100.0
-2,-13,19:100.0
-1,-13,19:100.0
0,-13,19:100.0
1,-13,19:100.0
2,-13,19:100.0
3,-13,19:100.0
6,-13,19:100.0
8,-13,19:100.0
9,-13,19:100.0
10,-13,19:100.0
11,-13,19:100.0
12,-13,19:100.0
13,-13,19:100.0
14,-13,19:100.0
15,-13,19:159.10
16,-13,19:159.10
17,-13,19:159.10
-19,-12,19:159.10
-18,-12,19:159.10
-17,-12,19:159.10
-16,-12,19:159.10
-15,-12,19:159.10
-14,-12,19:100.0
-13,-12,19:100.0
-12,-12,19:100.0
-11,-12,19:100.0
-10,-12,19:100.0
-9,-12,19:100.0
-8,-12,19:100.0
-7,-12,19:100.0
-6,-12,19:100.0
-5,-12,19:100.0
-4,-12,19:100.0
-3,-12,19:100.0
-2,-12,19:100.0
-1,-12,19:100.0
0,-12,19:100.0
1,-12,19:100.0
5,-12,19:100.0
6,-12,19:100.0
8,-12,19:100.0
9,-12,19:100.0
10,-12,19:100.0
11,-12,19:100.0
12,-12,19:100.0
13,-12,19:100.0
14,-12,19:100.0
15,-12,19:82.0
16,-12,19:82.0
17,-12,19:159.10
18,-12,19:159.10
-20,-11,19:159.10
-19,-11,19:159.10
-18,-11,19:159.10
-17,-11,19:159.10
-16,-11,19:159.10
-15,-11,19:100.0
-14,-11,19:100.0
-13,-11,19:100.0
-12,-11,19:100.0
-11,-11,19:100.0
-10,-11,19:100.0
-9,-11,19:100.0
-8,-11,19:100.0
-7,-11,19:100.0
-6,-11,19:100.0
-5,-11,19:100.0
-4,-11,19:100.0
-3,-11,19:100.0
-2,-11,19:100.0
-1,-11,19:100.0
5,-11,19:100.0
8,-11,19:100.0
9,-11,19:100.0
10,-11,19:100.0
11,-11,19:100.0
12,-11,19:100.0
13,-11,19:100.0
14,-11,19:100.0
15,-11,19:100.0
16,-11,19:82.0
17,-11,19:159.10
18,-11,19:159.10
-21,-10,19:159.10
-20,-10,19:159.10
-19,-10,19:159.10
-18,-10,19:159.10
-17,-10,19:159.10
-16,-10,19:100.0
-15,-10,19:100.0
-14,-10,19:100.0
-13,-10,19:100.0
-12,-10,19:100.0
-11,-10,19:100.0
-10,-10,19:100.0
-9,-10,19:100.0
-8,-10,19:100.0
-7,-10,19:100.0
-6,-10,19:100.0
-5,-10,19:100.0
-4,-10,19:100.0
-3,-10,19:100.0
5,-10,19:100.0
9,-10,19:100.0
10,-10,19:100.0
11,-10,19:100.0
12,-10,19:100.0
13,-10,19:100.0
14,-10,19:100.0
15,-10,19:82.0
16,-10,19:82.0
17,-10,19:159.10
18,-10,19:159.10
19,-10,19:159.10
-22,-9,19:159.10
-21,-9,19:159.10
-20,-9,19:159.10
-19,-9,19:159.10
-18,-9,19:100.0
-17,-9,19:100.0
-16,-9,19:100.0
-15,-9,19:100.0
-14,-9,19:100.0
-13,-9,19:100.0
-12,-9,19:100.0
-11,-9,19:100.0
-10,-9,19:100.0
-9,-9,19:100.0
-8,-9,19:100.0
-7,-9,19:100.0
-6,-9,19:100.0
-5,-9,19:100.0
4,-9,19:100.0
9,-9,19:100.0
10,-9,19:100.0
11,-9,19:100.0
12,-9,19:100.0
13,-9,19:100.0
14,-9,19:100.0
15,-9,19:100.0
16,-9,19:100.0
17,-9,19:159.10
18,-9,19:159.10
19,-9,19:159.10
-23,-8,19:159.10
-22,-8,19:159.10
-21,-8,19:159.10
-20,-8,19:159.10
-19,-8,19:100.0
-18,-8,19:100.0
-17,-8,19:100.0
-16,-8,19:100.0
-15,-8,19:100.0
-14,-8,19:100.0
-13,-8,19:100.0
-12,-8,19:100.0
-11,-8,19:100.0
-10,-8,19:100.0
-9,-8,19:100.0
-8,-8,19:100.0
3,-8,19:100.15
4,-8,19:100.0
9,-8,19:100.0
10,-8,19:100.0
11,-8,19:100.0
12,-8,19:100.0
13,-8,19:100.0
14,-8,19:100.0
15,-8,19:100.0
16,-8,19:100.0
17,-8,19:100.0
18,-8,19:159.10
19,-8,19:159.10
20,-8,19:159.10
-23,-7,19:159.10
-22,-7,19:159.10
-21,-7,19:159.10
-20,-7,19:100.0
-19,-7,19:100.0
-18,-7,19:100.0
-17,-7,19:100.0
-16,-7,19:100.0
-15,-7,19:100.0
-14,-7,19:100.0
-13,-7,19:100.0
-12,-7,19:100.0
-11,-7,19:100.0
-10,-7,19:100.0
3,-7,19:100.15
4,-7,19:100.15
9,-7,19:100.0
10,-7,19:100.0
11,-7,19:100.0
12,-7,19:100.0
13,-7,19:100.0
14,-7,19:100.0
15,-7,19:100.0
16,-7,19:100.0
17,-7,19:100.0
18,-7,19:159.10
19,-7,19:159.10
20,-7,19:159.10
-23,-6,19:159.10
-22,-6,19:159.10
-21,-6,19:159.10
-20,-6,19:100.0
-19,-6,19:100.0
-18,-6,19:100.0
-17,-6,19:100.0
-16,-6,19:100.0
-15,-6,19:100.0
-14,-6,19:100.0
-13,-6,19:100.0
-9,-6,19:100.0
-8,-6,19:100.0
3,-6,19:100.0
10,-6,19:100.0
11,-6,19:100.0
12,-6,19:100.0
13,-6,19:100.0
14,-6,19:100.0
15,-6,19:100.0
16,-6,19:100.0
17,-6,19:100.0
18,-6,19:159.10
19,-6,19:159.10
20,-6,19:159.10
21,-6,19:159.10
-23,-5,19:159.10
-22,-5,19:159.10
-21,-5,19:159.10
-20,-5,19:100.0
-19,-5,19:100.0
-18,-5,19:100.0
-17,-5,19:100.0
-16,-5,19:100.0
-15,-5,19:100.0
-14,-5,19:100.0
-13,-5,19:100.0
-12,-5,19:100.0
-8,-5,19:100.0
-7,-5,19:100.0
10,-5,19:100.0
11,-5,19:100.0
12,-5,19:100.0
13,-5,19:100.0
14,-5,19:100.0
15,-5,19:100.0
16,-5,19:100.0
17,-5,19:100.0
18,-5,19:100.0
19,-5,19:159.10
20,-5,19:159.10
21,-5,19:159.10
-22,-4,19:159.10
-21,-4,19:159.10
-20,-4,19:159.10
-19,-4,19:100.0
-18,-4,19:100.0
-17,-4,19:100.0
-16,-4,19:100.0
-15,-4,19:100.0
-14,-4,19:100.0
-12,-4,19:100.0
-11,-4,19:100.0
-10,-4,19:100.0
-9,-4,19:100.0
-8,-4,19:100.0
-7,-4,19:100.0
-6,-4,19:100.0
-5,-4,19:100.0
8,-4,19:100.0
9,-4,19:100.0
10,-4,19:100.0
11,-4,19:100.0
12,-4,19:100.0
13,-4,19:100.0
14,-4,19:100.0
15,-4,19:100.0
16,-4,19:100.0
17,-4,19:100.0
18,-4,19:100.0
19,-4,19:159.10
20,-4,19:159.10
21,-4,19:159.10
-22,-3,19:159.10
-21,-3,19:159.10
-20,-3,19:159.10
-19,-3,19:100.0
-18,-3,19:100.0
-17,-3,19:100.0
-16,-3,19:100.0
-15,-3,19:100.0
-14,-3,19:100.0
-13,-3,19:100.0
-10,-3,19:100.0
-9,-3,19:100.0
-8,-3,19:100.0
-7,-3,19:100.0
-6,-3,19:100.0
-5,-3,19:100.0
-4,-3,19:100.0
5,-3,19:100.0
6,-3,19:100.0
7,-3,19:100.0
11,-3,19:100.0
12,-3,19:100.0
13,-3,19:100.0
14,-3,19:100.0
15,-3,19:100.0
16,-3,19:100.0
17,-3,19:100.0
18,-3,19:100.0
19,-3,19:159.10
20,-3,19:159.10
21,-3,19:159.10
22,-3,19:159.10
-22,-2,19:159.10
-21,-2,19:159.10
-20,-2,19:159.10
-19,-2,19:100.0
-18,-2,19:100.0
-17,-2,19:100.0
-16,-2,19:100.0
-15,-2,19:100.0
-14,-2,19:100.0
-13,-2,19:100.0
-12,-2,19:100.0
-9,-2,19:100.0
-8,-2,19:100.0
-7,-2,19:100.0
-6,-2,19:100.0
-5,-2,19:100.0
-4,-2,19:100.0
-3,-2,19:100.0
-2,-2,19:100.0
3,-2,19:100.0
4,-2,19:100.0
5,-2,19:100.0
12,-2,19:100.0
13,-2,19:100.0
14,-2,19:100.0
15,-2,19:100.0
16,-2,19:100.0
17,-2,19:100.0
18,-2,19:100.0
19,-2,19:100.0
20,-2,19:159.10
21,-2,19:159.10
22,-2,19:159.10
-21,-1,19:82.0
-20,-1,19:82.0
-19,-1,19:82.0
-18,-1,19:100.0
-17,-1,19:100.0
-16,-1,19:100.0
-15,-1,19:100.0
-14,-1,19:100.0
-13,-1,19:100.0
-9,-1,19:100.0
-8,-1,19:100.0
-7,-1,19:100.0
-6,-1,19:100.0
-2,-1,19:100.0
-1,-1,19:100.0
0,-1,19:100.0
1,-1,19:100.0
2,-1,19:100.0
12,-1,19:100.0
13,-1,19:100.0
14,-1,19:100.0
15,-1,19:100.0
16,-1,19:100.0
17,-1,19:100.0
18,-1,19:100.0
19,-1,19:100.0
20,-1,19:159.10
21,-1,19:159.10
22,-1,19:159.10
-21,0,19:82.0
-20,0,19:82.0
-18,0,19:82.0
-17,0,19:100.0
-16,0,19:100.0
-15,0,19:100.0
-14,0,19:100.0
-13,0,19:100.0
-12,0,19:159.10
-11,0,19:100.15
-10,0,19:100.15
-9,0,19:100.0
-8,0,19:100.0
-7,0,19:100.0
-6,0,19:100.0
0,0,19:100.0
13,0,19:100.0
14,0,19:100.0
15,0,19:100.0
17,0,19:100.0
18,0,19:100.0
19,0,19:100.0
20,0,19:159.10
21,0,19:159.10
22,0,19:159.10
23,0,19:159.10
-21,1,19:82.0
-20,1,19:82.0
-19,1,19:82.0
-18,1,19:82.0
-17,1,19:100.0
-16,1,19:100.0
-15,1,19:100.0
-14,1,19:100.0
-13,1,19:100.0
-12,1,19:159.10
-11,1,19:100.15
-10,1,19:100.15
-8,1,19:100.0
-7,1,19:100.0
-6,1,19:100.0
0,1,19:100.0
14,1,19:100.0
15,1,19:100.0
16,1,19:100.0
17,1,19:100.0
18,1,19:100.0
19,1,19:100.0
20,1,19:100.0
21,1,19:159.10
22,1,19:159.10
23,1,19:159.10
-20,2,19:82.0
-19,2,19:82.0
-17,2,19:159.10
-16,2,19:100.0
-15,2,19:100.0
-14,2,19:100.0
-13,2,19:100.0
-12,2,19:100.0
-11,2,19:159.10
-10,2,19:159.10
-8,2,19:100.0
-7,2,19:100.0
-1,2,19:100.0
2,2,19:100.15
3,2,19:100.15
4,2,19:100.15
9,2,19:100.0
10,2,19:100.0
11,2,19:100.0
12,2,19:100.0
15,2,19:100.0
16,2,19:100.0
17,2,19:100.0
18,2,19:100.0
19,2,19:100.0
20,2,19:100.0
21,2,19:159.10
22,2,19:159.10
23,2,19:159.10
-20,3,19:82.0
-19,3,19:82.0
-18,3,19:159.10
-17,3,19:159.10
-16,3,19:159.10
-15,3,19:100.0
-14,3,19:100.0
-13,3,19:100.0
-12,3,19:100.0
-11,3,19:159.10
-10,3,19:159.10
-8,3,19:100.0
-7,3,19:100.0
-2,3,19:100.0
-1,3,19:100.0
3,3,19:100.15
4,3,19:100.15
12,3,19:100.0
13,3,19:100.0
14,3,19:100.0
15,3,19:100.0
16,3,19:100.0
17,3,19:100.0
18,3,19:100.0
19,3,19:100.0
20,3,19:100.0
21,3,19:159.10
22,3,19:159.10
23,3,19:159.10
24,3,19:159.10
-20,4,19:159.10
-19,4,19:159.10
-18,4,19:159.10
-17,4,19:159.10
-16,4,19:159.10
-15,4,19:100.0
-14,4,19:100.0
-13,4,19:100.0
-12,4,19:100.0
-11,4,19:159.10
-10,4,19:159.10
-9,4,19:159.10
-2,4,19:100.0
-1,4,19:100.0
4,4,19:100.15
14,4,19:100.0
15,4,19:100.0
16,4,19:100.0
17,4,19:100.0
18,4,19:100.0
19,4,19:100.0
20,4,19:100.0
21,4,19:100.0
23,4,19:159.10
24,4,19:159.10
-20,5,19:159.10
-19,5,19:159.10
-18,5,19:159.10
-17,5,19:159.10
-16,5,19:159.10
-15,5,19:159.10
-14,5,19:100.0
-13,5,19:100.0
-12,5,19:100.0
-11,5,19:100.0
-10,5,19:159.10
-9,5,19:100.0
-2,5,19:100.0
-1,5,19:100.0
11,5,19:100.0
12,5,19:100.0
13,5,19:100.0
14,5,19:100.0
15,5,19:100.0
16,5,19:100.0
17,5,19:100.0
18,5,19:100.0
19,5,19:100.0
20,5,19:100.0
21,5,19:100.0
22,5,19:100.0
23,5,19:82.0
24,5,19:82.0
-19,6,19:159.10
-18,6,19:82.0
-17,6,19:82.0
-16,6,19:82.0
-15,6,19:159.10
-13,6,19:100.0
-12,6,19:100.0
-11,6,19:100.0
-10,6,19:100.0
-9,6,19:100.0
-8,6,19:100.0
-3,6,19:100.0
-1,6,19:100.0
9,6,19:100.0
10,6,19:100.0
11,6,19:100.0
12,6,19:100.0
13,6,19:100.0
14,6,19:100.0
15,6,19:100.0
16,6,19:100.0
17,6,19:100.0
18,6,19:100.0
19,6,19:100.0
20,6,19:100.0
21,6,19:159.10
22,6,19:159.10
23,6,19:82.0
24,6,19:82.0
-19,7,19:159.10
-18,7,19:82.0
-17,7,19:82.0
-16,7,19:82.0
-15,7,19:159.10
-14,7,19:159.10
-13,7,19:100.0
-12,7,19:100.0
-11,7,19:100.0
-10,7,19:100.0
-9,7,19:100.0
-8,7,19:100.0
-4,7,19:100.0
-2,7,19:100.0
-1,7,19:100.0
6,7,19:100.0
7,7,19:100.0
8,7,19:100.0
9,7,19:100.0
10,7,19:100.0
11,7,19:100.0
12,7,19:100.0
13,7,19:100.0
14,7,19:100.0
15,7,19:100.0
16,7,19:100.0
17,7,19:100.0
18,7,19:100.0
19,7,19:159.10
20,7,19:159.10
21,7,19:159.10
22,7,19:159.10
23,7,19:82.0
-19,8,19:159.10
-18,8,19:82.0
-17,8,19:82.0
-16,8,19:82.0
-15,8,19:159.10
-14,8,19:159.10
-13,8,19:100.0
-12,8,19:100.0
-11,8,19:100.0
-10,8,19:100.0
-9,8,19:100.0
-8,8,19:100.0
-5,8,19:100.0
-4,8,19:100.0
-2,8,19:100.0
4,8,19:100.0
5,8,19:100.0
6,8,19:100.0
7,8,19:100.0
8,8,19:100.0
9,8,19:100.0
10,8,19:100.0
11,8,19:100.0
12,8,19:100.0
13,8,19:100.0
14,8,19:100.0
15,8,19:100.0
16,8,19:100.0
17,8,19:100.0
18,8,19:82.0
19,8,19:159.10
20,8,19:159.10
21,8,19:159.10
22,8,19:159.10
-18,9,19:159.10
-17,9,19:159.10
-16,9,19:159.10
-15,9,19:159.10
-14,9,19:159.10
-13,9,19:100.0
-12,9,19:100.0
-11,9,19:100.0
-10,9,19:100.0
-9,9,19:100.0
-8,9,19:100.0
-5,9,19:100.0
-2,9,19:100.0
1,9,19:100.0
2,9,19:100.0
3,9,19:100.0
4,9,19:100.0
5,9,19:100.0
6,9,19:100.0
7,9,19:100.0
8,9,19:100.0
9,9,19:100.0
10,9,19:100.0
11,9,19:100.0
12,9,19:100.0
14,9,19:100.0
15,9,19:100.0
16,9,19:100.0
17,9,19:82.0
18,9,19:82.0
19,9,19:159.10
20,9,19:159.10
-17,10,19:159.10
-16,10,19:159.10
-15,10,19:159.10
-14,10,19:159.10
-13,10,19:100.0
-12,10,19:100.0
-11,10,19:100.0
-10,10,19:100.0
-9,10,19:100.0
-8,10,19:100.0
-6,10,19:100.0
-5,10,19:100.0
-2,10,19:100.0
-1,10,19:100.0
0,10,19:100.0
1,10,19:100.0
2,10,19:100.0
3,10,19:100.0
4,10,19:100.0
5,10,19:100.0
6,10,19:100.0
7,10,19:100.0
8,10,19:100.0
9,10,19:100.0
10,10,19:100.0
11,10,19:100.0
12,10,19:100.0
13,10,19:100.0
14,10,19:100.0
15,10,19:82.0
16,10,19:82.0
17,10,19:82.0
18,10,19:82.0
19,10,19:159.10
-17,11,19:159.10
-16,11,19:159.10
-15,11,19:159.10
-14,11,19:159.10
-13,11,19:100.0
-12,11,19:100.0
-11,11,19:100.0
-10,11,19:100.0
-9,11,19:100.0
-8,11,19:100.0
-7,11,19:100.0
-6,11,19:100.0
-4,11,19:100.0
-3,11,19:100.0
-2,11,19:100.0
-1,11,19:100.0
1,11,19:100.0
2,11,19:100.0
3,11,19:100.0
4,11,19:100.0
5,11,19:100.0
6,11,19:100.0
7,11,19:100.0
8,11,19:100.0
9,11,19:100.0
10,11,19:100.0
11,11,19:100.0
12,11,19:100.0
13,11,19:100.0
14,11,19:159.10
15,11,19:82.0
16,11,19:82.0
18,11,19:159.10
-16,12,19:159.10
-15,12,19:159.10
-14,12,19:159.10
-13,12,19:100.0
-12,12,19:100.0
-11,12,19:100.0
-10,12,19:100.0
-9,12,19:100.0
-8,12,19:100.0
-7,12,19:100.0
-6,12,19:100.0
-5,12,19:100.0
-4,12,19:100.0
-3,12,19:100.0
-2,12,19:100.0
-1,12,19:100.0
0,12,19:100.0
1,12,19:100.0
2,12,19:100.0
3,12,19:100.0
4,12,19:100.0
5,12,19:100.0
6,12,19:100.0
7,12,19:100.0
8,12,19:100.0
9,12,19:100.0
10,12,19:100.0
11,12,19:100.0
12,12,19:159.10
13,12,19:159.10
14,12,19:159.10
15,12,19:159.10
16,12,19:159.10
-16,13,19:159.10
-15,13,19:159.10
-14,13,19:159.10
-13,13,19:159.10
-12,13,19:100.0
-11,13,19:100.0
-10,13,19:100.0
-9,13,19:100.0
-8,13,19:100.0
-7,13,19:159.10
-6,13,19:100.0
-5,13,19:100.0
-4,13,19:100.0
-3,13,19:100.0
-2,13,19:100.0
-1,13,19:100.0
0,13,19:100.0
1,13,19:100.0
2,13,19:100.0
3,13,19:100.0
4,13,19:100.0
5,13,19:100.0
6,13,19:100.0
7,13,19:100.0
8,13,19:100.0
9,13,19:100.0
10,13,19:100.0
11,13,19:159.10
12,13,19:159.10
13,13,19:159.10
14,13,19:159.10
15,13,19:159.10
-15,14,19:159.10
-14,14,19:159.10
-13,14,19:159.10
-12,14,19:100.0
-11,14,19:100.0
-10,14,19:100.0
-9,14,19:100.0
-8,14,19:100.0
-7,14,19:100.0
-6,14,19:100.0
-5,14,19:100.0
-4,14,19:100.0
-3,14,19:100.0
-2,14,19:100.0
-1,14,19:100.0
0,14,19:100.0
1,14,19:100.0
2,14,19:100.0
3,14,19:100.0
4,14,19:100.0
5,14,19:100.0
6,14,19:100.0
7,14,19:100.0
8,14,19:100.0
9,14,19:82.0
10,14,19:159.10
11,14,19:159.10
12,14,19:159.10
13,14,19:159.10
-15,15,19:159.10
-14,15,19:159.10
-13,15,19:159.10
-12,15,19:159.10
-11,15,19:100.0
-10,15,19:100.0
-9,15,19:100.0
-8,15,19:100.0
-7,15,19:100.0
-6,15,19:100.0
-5,15,19:100.0
-4,15,19:100.0
-3,15,19:100.0
-2,15,19:100.0
-1,15,19:100.0
1,15,19:100.0
2,15,19:100.0
3,15,19:100.0
4,15,19:100.0
5,15,19:100.0
6,15,19:100.0
7,15,19:100.0
8,15,19:82.0
9,15,19:82.0
10,15,19:159.10
11,15,19:159.10
12,15,19:159.10
-14,16,19:159.10
-13,16,19:159.10
-12,16,19:159.10
-11,16,19:100.0
-10,16,19:100.0
-9,16,19:100.0
-8,16,19:100.0
-7,16,19:100.0
-6,16,19:100.0
-5,16,19:100.0
-4,16,19:100.0
-3,16,19:100.0
-2,16,19:100.0
-1,16,19:100.0
0,16,19:100.0
1,16,19:100.0
2,16,19:100.0
3,16,19:100.0
4,16,19:159.10
5,16,19:82.0
6,16,19:82.0
7,16,19:82.0
8,16,19:82.0
9,16,19:82.0
10,16,19:159.10
11,16,19:159.10
-14,17,19:159.10
-13,17,19:159.10
-12,17,19:159.10
-11,17,19:159.10
-10,17,19:100.0
-9,17,19:100.0
-8,17,19:100.0
-7,17,19:100.0
-6,17,19:100.0
-5,17,19:100.0
-4,17,19:100.0
-3,17,19:100.0
-2,17,19:159.10
-1,17,19:159.10
0,17,19:82.0
1,17,19:82.0
2,17,19:82.0
3,17,19:159.10
4,17,19:159.10
5,17,19:159.10
7,17,19:82.0
8,17,19:82.0
9,17,19:159.10
-13,18,19:159.10
-12,18,19:159.10
-11,18,19:159.10
-10,18,19:100.0
-9,18,19:82.0
-8,18,19:82.0
-7,18,19:82.0
-6,18,19:82.0
-5,18,19:82.0
-4,18,19:159.10
-3,18,19:159.10
-2,18,19:159.10
-1,18,19:159.10
0,18,19:82.0
1,18,19:82.0
2,18,19:82.0
3,18,19:159.10
4,18,19:159.10
5,18,19:159.10
6,18,19:159.10
7,18,19:159.10
8,18,19:159.10
-13,19,19:159.10
-12,19,19:159.10
-11,19,19:159.10
-10,19,19:159.10
-9,19,19:159.10
-8,19,19:82.0
-7,19,19:82.0
-6,19,19:82.0
-5,19,19:159.10
-4,19,19:159.10
-3,19,19:159.10
-2,19,19:159.10
-1,19,19:159.10
0,19,19:82.0
1,19,19:82.0
2,19,19:82.0
-12,20,19:159.10
-11,20,19:159.10
-10,20,19:159.10
-9,20,19:159.10
-8,20,19:159.10
-7,20,19:159.10
-6,20,19:159.10
-4,20,19:159.10
-4,21,19:159.10
8,-21,20:159.10
9,-21,20:82.0
10,-21,20:82.0
4,-20,20:159.10
5,-20,20:159.10
6,-20,20:159.10
7,-20,20:159.10
8,-20,20:82.0
9,-20,20:82.0
10,-20,20:82.0
0,-19,20:159.10
1,-19,20:159.10
2,-19,20:159.10
3,-19,20:159.10
4,-19,20:159.10
5,-19,20:159.10
6,-19,20:159.10
7,-19,20:159.10
8,-19,20:82.0
9,-19,20:82.0
10,-19,20:82.0
11,-19,20:82.0
-4,-18,20:82.0
-3,-18,20:159.10
-2,-18,20:159.10
-1,-18,20:82.0
0,-18,20:82.0
1,-18,20:82.0
2,-18,20:159.10
3,-18,20:159.10
4,-18,20:159.10
5,-18,20:159.10
6,-18,20:159.10
7,-18,20:159.10
8,-18,20:82.0
9,-18,20:82.0
10,-18,20:82.0
11,-18,20:82.0
-7,-17,20:82.0
-6,-17,20:82.0
-5,-17,20:82.0
-4,-17,20:159.10
-3,-17,20:159.10
-2,-17,20:159.10
-1,-17,20:82.0
0,-17,20:82.0
1,-17,20:82.0
2,-17,20:159.10
3,-17,20:159.10
4,-17,20:159.10
5,-17,20:159.10
6,-17,20:159.10
7,-17,20:159.10
8,-17,20:159.10
9,-17,20:82.0
10,-17,20:82.0
11,-17,20:82.0
12,-17,20:159.10
-9,-16,20:159.10
-8,-16,20:159.10
-7,-16,20:159.10
-6,-16,20:159.10
-5,-16,20:159.10
-4,-16,20:159.10
-3,-16,20:159.10
-1,-16,20:82.0
0,-16,20:82.0
1,-16,20:82.0
2,-16,20:159.10
3,-16,20:159.10
4,-16,20:159.10
5,-16,20:159.10
6,-16,20:159.10
7,-16,20:159.10
8,-16,20:159.10
9,-16,20:159.10
10,-16,20:159.10
12,-16,20:159.10
-10,-15,20:159.10
-9,-15,20:82.0
-8,-15,20:82.0
-7,-15,20:82.0
-6,-15,20:159.10
-5,-15,20:159.10
-4,-15,20:159.10
-3,-15,20:159.10
-2,-15,20:159.10
-1,-15,20:159.10
0,-15,20:159.10
1,-15,20:159.10
2,-15,20:159.10
3,-15,20:159.10
4,-15,20:159.10
5,-15,20:159.10
6,-15,20:100.0
8,-15,20:159.10
9,-15,20:159.10
10,-15,20:159.10
11,-15,20:159.10
12,-15,20:159.10
13,-15,20:159.10
-11,-14,20:159.10
-10,-14,20:159.10
-9,-14,20:82.0
-8,-14,20:82.0
-7,-14,20:82.0
-6,-14,20:159.10
-5,-14,20:159.10
-4,-14,20:159.10
-3,-14,20:159.10
-2,-14,20:159.10
-1,-14,20:159.10
0,-14,20:159.10
1,-14,20:159.10
2,-14,20:159.10
3,-14,20:159.10
4,-14,20:100.0
5,-14,20:100.0
6,-14,20:100.0
7,-14,20:100.0
8,-14,20:159.10
9,-14,20:159.10
10,-14,20:100.0
11,-14,20:159.10
12,-14,20:159.10
13,-14,20:159.10
-13,-13,20:159.10
-12,-13,20:159.10
-11,-13,20:159.10
-10,-13,20:159.10
-9,-13,20:82.0
-8,-13,20:82.0
-7,-13,20:82.0
-6,-13,20:159.10
-5,-13,20:159.10
-4,-13,20:159.10
-3,-13,20:159.10
-2,-13,20:159.10
-1,-13,20:159.10
0,-13,20:159.10
2,-13,20:100.0
3,-13,20:100.0
4,-13,20:100.0
5,-13,20:100.0
6,-13,20:100.0
7,-13,20:100.0
8,-13,20:159.10
9,-13,20:159.10
10,-13,20:159.10
11,-13,20:159.10
12,-13,20:159.10
13,-13,20:159.10
14,-13,20:159.10
-14,-12,20:159.10
-13,-12,20:159.10
-12,-12,20:159.10
-11,-12,20:159.10
-10,-12,20:159.10
-9,-12,20:159.10
-8,-12,20:159.10
-7,-12,20:159.10
-6,-12,20:159.10
-5,-12,20:159.10
-4,-12,20:159.10
0,-12,20:159.10
1,-12,20:159.10
2,-12,20:100.0
4,-12,20:100.0
5,-12,20:100.0
6,-12,20:100.0
7,-12,20:100.0
8,-12,20:100.0
9,-12,20:159.10
10,-12,20:159.10
11,-12,20:100.0
12,-12,20:159.10
13,-12,20:159.10
14,-12,20:159.10
-15,-11,20:159.10
-14,-11,20:159.10
-13,-11,20:159.10
-12,-11,20:159.10
-11,-11,20:159.10
-10,-11,20:159.10
-9,-11,20:159.10
-8,-11,20:159.10
-7,-11,20:159.10
-6,-11,20:159.10
-1,-11,20:159.10
0,-11,20:100.0
1,-11,20:100.0
2,-11,20:100.0
3,-11,20:100.0
4,-11,20:100.0
5,-11,20:100.0
7,-11,20:100.0
8,-11,20:100.0
9,-11,20:159.10
10,-11,20:159.10
11,-11,20:159.10
12,-11,20:159.10
13,-11,20:159.10
14,-11,20:82.0
15,-11,20:82.0
-16,-10,20:159.10
-15,-10,20:159.10
-14,-10,20:159.10
-13,-10,20:159.10
-12,-10,20:159.10
-11,-10,20:159.10
-10,-10,20:159.10
-9,-10,20:19.0
-8,-10,20:19.0
-7,-10,20:159.10
-3,-10,20:159.10
-2,-10,20:100.0
-1,-10,20:100.0
0,-10,20:100.0
1,-10,20:100.0
2,-10,20:100.0
3,-10,20:100.0
4,-10,20:100.0
5,-10,20:100.0
6,-10,20:100.0
7,-10,20:100.0
8,-10,20:100.0
9,-10,20:159.10
10,-10,20:159.10
11,-10,20:159.10
12,-10,20:100.0
13,-10,20:159.10
14,-10,20:159.10
15,-10,20:82.0
-18,-9,20:159.10
-17,-9,20:159.10
-16,-9,20:159.10
-15,-9,20:159.10
-14,-9,20:159.10
-13,-9,20:159.10
-12,-9,20:159.10
-11,-9,20:159.10
-10,-9,20:19.0
-9,-9,20:19.0
-6,-9,20:159.10
-5,-9,20:159.10
-4,-9,20:100.0
-3,-9,20:100.0
-2,-9,20:100.0
-1,-9,20:100.0
0,-9,20:100.0
1,-9,20:100.0
2,-9,20:100.0
3,-9,20:100.0
4,-9,20:100.0
5,-9,20:100.0
6,-9,20:100.0
7,-9,20:100.0
8,-9,20:100.0
10,-9,20:159.10
11,-9,20:159.10
12,-9,20:159.10
13,-9,20:159.10
14,-9,20:159.10
15,-9,20:159.10
16,-9,20:159.10
-19,-8,20:159.10
-18,-8,20:159.10
-17,-8,20:159.10
-16,-8,20:159.10
-15,-8,20:159.10
-14,-8,20:159.10
-13,-8,20:159.10
-12,-8,20:159.10
-11,-8,20:19.0
-10,-8,20:19.0
-8,-8,20:159.10
-7,-8,20:100.0
-6,-8,20:100.0
-5,-8,20:100.0
-4,-8,20:100.0
-3,-8,20:100.0
-2,-8,20:100.0
-1,-8,20:100.0
0,-8,20:100.0
1,-8,20:100.0
2,-8,20:100.0
3,-8,20:100.0
4,-8,20:100.0
5,-8,20:100.0
6,-8,20:100.0
7,-8,20:100.0
8,-8,20:100.0
9,-8,20:100.0
10,-8,20:159.10
11,-8,20:159.10
12,-8,20:159.10
13,-8,20:100.0
14,-8,20:159.10
15,-8,20:159.10
16,-8,20:159.10
17,-8,20:159.10
-20,-7,20:159.10
-19,-7,20:159.10
-18,-7,20:159.10
-17,-7,20:159.10
-16,-7,20:82.0
-15,-7,20:159.10
-14,-7,20:159.10
-13,-7,20:159.10
-12,-7,20:159.10
-11,-7,20:159.10
-10,-7,20:82.0
-9,-7,20:100.0
-8,-7,20:100.0
-7,-7,20:100.0
-6,-7,20:100.0
-5,-7,20:100.0
-4,-7,20:100.0
-3,-7,20:100.0
-2,-7,20:100.0
-1,-7,20:100.0
0,-7,20:100.0
1,-7,20:100.0
2,-7,20:100.0
3,-7,20:100.0
4,-7,20:100.0
5,-7,20:100.0
6,-7,20:100.0
7,-7,20:100.0
8,-7,20:100.0
9,-7,20:100.0
11,-7,20:159.10
12,-7,20:19.0
13,-7,20:159.10
14,-7,20:159.10
15,-7,20:159.10
16,-7,20:159.10
17,-7,20:159.10
-20,-6,20:159.10
-19,-6,20:159.10
-18,-6,20:159.10
-17,-6,20:82.0
-16,-6,20:82.0
-15,-6,20:82.0
-14,-6,20:159.10
-13,-6,20:159.10
-12,-6,20:100.0
-11,-6,20:100.0
-10,-6,20:100.0
-9,-6,20:82.0
-8,-6,20:82.0
-7,-6,20:100.0
-6,-6,20:100.0
-5,-6,20:100.0
-4,-6,20:100.0
-3,-6,20:100.0
-2,-6,20:100.0
-1,-6,20:100.0
0,-6,20:100.0
1,-6,20:100.0
2,-6,20:100.0
3,-6,20:100.0
4,-6,20:100.0
5,-6,20:100.0
6,-6,20:100.0
7,-6,20:100.0
8,-6,20:100.0
9,-6,20:100.0
12,-6,20:19.0
13,-6,20:159.10
14,-6,20:159.10
15,-6,20:159.10
16,-6,20:159.10
17,-6,20:159.10
-20,-5,20:159.10
-19,-5,20:159.10
-18,-5,20:159.10
-17,-5,20:159.10
-16,-5,20:82.0
-15,-5,20:159.10
-14,-5,20:159.10
-13,-5,20:159.10
-12,-5,20:159.10
-11,-5,20:100.0
-10,-5,20:100.0
-9,-5,20:100.0
-8,-5,20:82.0
-7,-5,20:159.10
-6,-5,20:100.0
-5,-5,20:100.0
-4,-5,20:100.0
-3,-5,20:100.0
-2,-5,20:100.0
-1,-5,20:100.0
0,-5,20:100.0
1,-5,20:100.0
2,-5,20:100.0
3,-5,20:100.0
4,-5,20:100.0
5,-5,20:100.0
6,-5,20:100.0
7,-5,20:100.0
8,-5,20:100.0
9,-5,20:100.0
12,-5,20:19.0
13,-5,20:159.10
14,-5,20:100.0
15,-5,20:82.0
16,-5,20:82.0
17,-5,20:159.10
18,-5,20:159.10
-19,-4,20:159.10
-18,-4,20:159.10
-17,-4,20:159.10
-16,-4,20:159.10
-15,-4,20:159.10
-14,-4,20:159.10
-13,-4,20:100.0
-12,-4,20:159.10
-11,-4,20:159.10
-10,-4,20:159.10
-9,-4,20:159.10
-8,-4,20:159.10
-7,-4,20:159.10
-6,-4,20:159.10
-5,-4,20:159.10
-3,-4,20:100.0
-2,-4,20:100.0
-1,-4,20:100.0
2,-4,20:100.0
4,-4,20:100.0
5,-4,20:100.0
6,-4,20:100.0
7,-4,20:100.0
8,-4,20:100.0
9,-4,20:100.0
10,-4,20:100.0
12,-4,20:19.0
13,-4,20:19.0
14,-4,20:100.0
15,-4,20:82.0
16,-4,20:82.0
17,-4,20:82.0
18,-4,20:159.10
-19,-3,20:159.10
-18,-3,20:159.10
-17,-3,20:159.10
-16,-3,20:159.10
-15,-3,20:159.10
-14,-3,20:159.10
-13,-3,20:159.10
-12,-3,20:100.0
-11,-3,20:100.0
-10,-3,20:159.10
-9,-3,20:159.10
-8,-3,20:159.10
-7,-3,20:159.10
-6,-3,20:159.10
-5,-3,20:159.10
-4,-3,20:100.0
-3,-3,20:100.0
4,-3,20:100.0
5,-3,20:100.0
6,-3,20:100.0
7,-3,20:100.0
8,-3,20:100.0
9,-3,20:100.0
10,-3,20:100.0
13,-3,20:19.0
14,-3,20:82.0
15,-3,20:82.0
16,-3,20:82.0
17,-3,20:82.0
18,-3,20:159.10
-19,-2,20:159.10
-18,-2,20:159.10
-17,-2,20:159.10
-16,-2,20:159.10
-15,-2,20:159.10
-14,-2,20:159.10
-13,-2,20:159.10
-12,-2,20:159.10
-11,-2,20:100.0
-10,-2,20:100.0
-9,-2,20:159.10
-8,-2,20:159.10
-7,-2,20:159.10
-6,-2,20:159.10
-5,-2,20:159.10
-4,-2,20:100.0
-3,-2,20:100.0
-2,-2,20:100.0
3,-2,20:100.0
4,-2,20:100.0
5,-2,20:100.0
6,-2,20:100.0
7,-2,20:100.0
8,-2,20:100.0
9,-2,20:100.0
10,-2,20:100.0
11,-2,20:100.0
13,-2,20:19.0
14,-2,20:82.0
15,-2,20:82.0
16,-2,20:82.0
17,-2,20:82.0
18,-2,20:159.10
19,-2,20:159.10
-18,-1,20:159.10
-17,-1,20:159.10
-16,-1,20:159.10
-15,-1,20:159.10
-14,-1,20:159.10
-13,-1,20:159.10
-11,-1,20:100.0
-10,-1,20:100.0
-9,-1,20:159.10
-8,-1,20:159.10
-7,-1,20:159.10
-6,-1,20:159.10
-5,-1,20:100.0
-4,-1,20:100.0
-2,-1,20:100.0
-1,-1,20:100.0
0,-1,20:100.0
1,-1,20:100.0
2,-1,20:100.0
5,-1,20:100.0
6,-1,20:100.0
7,-1,20:100.0
8,-1,20:100.0
9,-1,20:100.0
10,-1,20:100.0
11,-1,20:100.0
12,-1,20:159.10
13,-1,20:19.0
14,-1,20:82.0
15,-1,20:82.0
16,-1,20:82.0
17,-1,20:159.10
18,-1,20:159.10
19,-1,20:159.10
-18,0,20:82.0
-17,0,20:159.10
-16,0,20:159.10
-15,0,20:159.10
-14,0,20:159.10
-13,0,20:159.10
-11,0,20:100.15
-10,0,20:159.10
-9,0,20:159.10
-8,0,20:159.10
-7,0,20:159.10
-6,0,20:159.10
-5,0,20:100.0
-4,0,20:100.0
0,0,20:100.0
3,0,20:100.0
4,0,20:100.0
5,0,20:100.0
6,0,20:100.0
7,0,20:100.0
8,0,20:100.0
9,0,20:100.0
10,0,20:100.0
11,0,20:100.0
12,0,20:100.0
13,0,20:159.10
14,0,20:159.10
15,0,20:159.10
17,0,20:159.10
18,0,20:159.10
19,0,20:159.10
-18,1,20:82.0
-17,1,20:159.10
-16,1,20:159.10
-15,1,20:159.10
-14,1,20:159.10
-13,1,20:159.10
-11,1,20:100.15
-10,1,20:159.10
-9,1,20:100.0
-8,1,20:159.10
-7,1,20:159.10
-6,1,20:159.10
-5,1,20:100.0
-4,1,20:100.0
-3,1,20:100.0
-1,1,20:100.0
0,1,20:100.0
5,1,20:100.0
6,1,20:100.0
7,1,20:100.0
8,1,20:100.0
9,1,20:100.0
10,1,20:100.0
11,1,20:100.0
12,1,20:100.0
13,1,20:100.0
14,1,20:159.10
15,1,20:159.10
16,1,20:159.10
17,1,20:159.10
18,1,20:159.10
19,1,20:159.10
20,1,20:159.10
-17,2,20:159.10
-16,2,20:159.10
-15,2,20:159.10
-14,2,20:159.10
-13,2,20:159.10
-12,2,20:159.10
-9,2,20:100.0
-8,2,20:159.10
-7,2,20:159.10
-6,2,20:100.0
-5,2,20:100.0
-4,2,20:100.0
-3,2,20:100.0
-1,2,20:159.10
3,2,20:100.0
4,2,20:100.0
5,2,20:100.0
6,2,20:100.0
7,2,20:100.0
8,2,20:100.0
9,2,20:159.10
10,2,20:159.10
11,2,20:159.10
12,2,20:159.10
14,2,20:100.0
15,2,20:159.10
16,2,20:159.10
17,2,20:159.10
18,2,20:159.10
19,2,20:159.10
20,2,20:159.10
-17,3,20:159.10
-16,3,20:159.10
-15,3,20:159.10
-14,3,20:159.10
-13,3,20:159.10
-12,3,20:159.10
-8,3,20:159.10
-7,3,20:159.10
-6,3,20:100.0
-5,3,20:100.0
-4,3,20:100.0
-3,3,20:100.0
-2,3,20:159.10
-1,3,20:159.10
0,3,20:100.0
1,3,20:100.0
2,3,20:100.0
3,3,20:100.15
4,3,20:100.15
5,3,20:100.0
6,3,20:100.0
7,3,20:100.0
8,3,20:100.0
9,3,20:100.0
10,3,20:100.0
11,3,20:100.0
12,3,20:159.10
13,3,20:159.10
14,3,20:159.10
15,3,20:159.10
16,3,20:159.10
17,3,20:159.10
18,3,20:159.10
19,3,20:159.10
20,3,20:159.10
-17,4,20:159.10
-16,4,20:159.10
-15,4,20:159.10
-14,4,20:159.10
-13,4,20:159.10
-12,4,20:159.10
-8,4,20:100.0
-7,4,20:100.0
-6,4,20:100.0
-5,4,20:100.0
-4,4,20:100.0
-3,4,20:100.0
-2,4,20:159.10
-1,4,20:159.10
0,4,20:100.0
1,4,20:100.0
2,4,20:100.0
3,4,20:100.0
4,4,20:100.15
5,4,20:100.0
6,4,20:100.0
7,4,20:100.0
8,4,20:100.0
9,4,20:100.0
10,4,20:100.0
11,4,20:100.0
12,4,20:100.0
13,4,20:100.0
14,4,20:159.10
15,4,20:159.10
16,4,20:159.10
17,4,20:159.10
18,4,20:159.10
19,4,20:159.10
20,4,20:159.10
21,4,20:159.10
-17,5,20:159.10
-16,5,20:159.10
-15,5,20:159.10
-14,5,20:159.10
-13,5,20:159.10
-12,5,20:159.10
-11,5,20:159.10
-8,5,20:100.0
-7,5,20:100.0
-6,5,20:100.0
-5,5,20:100.0
-4,5,20:100.0
-2,5,20:159.10
-1,5,20:159.10
0,5,20:100.0
1,5,20:100.0
2,5,20:100.0
3,5,20:100.0
4,5,20:100.0
5,5,20:100.0
6,5,20:100.0
7,5,20:100.0
8,5,20:100.0
9,5,20:100.0
10,5,20:100.0
11,5,20:159.10
12,5,20:159.10
13,5,20:159.10
14,5,20:159.10
15,5,20:159.10
16,5,20:159.10
17,5,20:159.10
18,5,20:159.10
19,5,20:159.10
20,5,20:159.10
21,5,20:159.10
22,5,20:159.10
-16,6,20:159.10
-15,6,20:159.10
-13,6,20:159.10
-12,6,20:159.10
-11,6,20:159.10
-8,6,20:82.0
-7,6,20:100.0
-6,6,20:100.0
-5,6,20:100.0
-4,6,20:100.0
-3,6,20:159.10
-2,6,20:100.0
-1,6,20:159.10
0,6,20:100.0
1,6,20:100.0
2,6,20:100.0
3,6,20:100.0
4,6,20:100.0
5,6,20:100.0
6,6,20:100.0
7,6,20:100.0
8,6,20:100.0
9,6,20:159.10
11,6,20:159.10
12,6,20:159.10
13,6,20:159.10
14,6,20:159.10
15,6,20:159.10
16,6,20:159.10
17,6,20:159.10
18,6,20:159.10
19,6,20:159.10
20,6,20:159.10
-16,7,20:82.0
-15,7,20:159.10
-14,7,20:159.10
-13,7,20:159.10
-12,7,20:159.10
-11,7,20:159.10
-10,7,20:82.0
-8,7,20:82.0
-7,7,20:100.0
-6,7,20:100.0
-5,7,20:100.0
-4,7,20:159.10
-3,7,20:100.0
-2,7,20:159.10
-1,7,20:159.10
0,7,20:100.0
1,7,20:100.0
2,7,20:100.0
3,7,20:100.0
4,7,20:100.0
5,7,20:100.0
6,7,20:159.10
7,7,20:159.10
10,7,20:159.10
11,7,20:159.10
12,7,20:159.10
13,7,20:159.10
14,7,20:159.10
15,7,20:82.0
16,7,20:82.0
17,7,20:82.0
18,7,20:159.10
-15,8,20:159.10
-14,8,20:159.10
-13,8,20:159.10
-12,8,20:159.10
-11,8,20:159.10
-10,8,20:82.0
-9,8,20:82.0
-8,8,20:82.0
-7,8,20:100.0
-6,8,20:100.0
-5,8,20:159.10
-4,8,20:159.10
-3,8,20:100.0
-2,8,20:159.10
-1,8,20:100.0
0,8,20:100.0
1,8,20:100.0
2,8,20:100.0
3,8,20:100.0
4,8,20:159.10
8,8,20:159.10
9,8,20:159.10
10,8,20:159.10
11,8,20:159.10
12,8,20:159.10
13,8,20:159.10
14,8,20:82.0
15,8,20:82.0
16,8,20:82.0
17,8,20:82.0
-15,9,20:159.10
-14,9,20:159.10
-13,9,20:159.10
-12,9,20:159.10
-11,9,20:159.10
-10,9,20:159.10
-9,9,20:159.10
-7,9,20:100.0
-6,9,20:100.0
-5,9,20:159.10
-4,9,20:100.0
-3,9,20:100.0
-2,9,20:159.10
-1,9,20:100.0
0,9,20:100.0
1,9,20:159.10
2,9,20:159.10
7,9,20:159.10
8,9,20:159.10
9,9,20:159.10
10,9,20:159.10
11,9,20:159.10
12,9,20:159.10
14,9,20:82.0
15,9,20:82.0
16,9,20:82.0
-14,10,20:159.10
-13,10,20:159.10
-12,10,20:159.10
-11,10,20:159.10
-10,10,20:159.10
-9,10,20:159.10
-8,10,20:159.10
-7,10,20:100.0
-6,10,20:159.10
-5,10,20:159.10
-4,10,20:100.0
-3,10,20:100.0
-2,10,20:159.10
-1,10,20:159.10
5,10,20:159.10
6,10,20:159.10
7,10,20:159.10
8,10,20:159.10
9,10,20:159.10
10,10,20:159.10
11,10,20:159.10
12,10,20:159.10
13,10,20:159.10
14,10,20:82.0
-14,11,20:159.10
-13,11,20:159.10
-12,11,20:159.10
-11,11,20:159.10
-10,11,20:159.10
-9,11,20:159.10
-8,11,20:159.10
-7,11,20:159.10
-6,11,20:159.10
-5,11,20:100.0
-4,11,20:159.10
-3,11,20:159.10
-2,11,20:159.10
1,11,20:19.0
2,11,20:159.10
3,11,20:159.10
4,11,20:159.10
5,11,20:159.10
6,11,20:159.10
7,11,20:159.10
8,11,20:159.10
9,11,20:159.10
10,11,20:159.10
11,11,20:159.10
12,11,20:159.10
13,11,20:159.10
-13,12,20:159.10
-12,12,20:159.10
-11,12,20:159.10
-10,12,20:159.10
-9,12,20:159.10
-8,12,20:159.10
-7,12,20:159.10
-6,12,20:159.10
-5,12,20:159.10
-4,12,20:159.10
-3,12,20:159.10
-2,12,20:159.10
-1,12,20:159.10
0,12,20:159.10
1,12,20:159.10
2,12,20:159.10
3,12,20:159.10
4,12,20:159.10
5,12,20:159.10
6,12,20:159.10
7,12,20:159.10
8,12,20:159.10
9,12,20:159.10
10,12,20:159.10
11,12,20:159.10
-12,13,20:159.10
-11,13,20:159.10
-10,13,20:159.10
-9,13,20:159.10
-8,13,20:159.10
-6,13,20:159.10
-5,13,20:159.10
-4,13,20:159.10
-3,13,20:159.10
-2,13,20:159.10
-1,13,20:159.10
0,13,20:159.10
1,13,20:159.10
2,13,20:159.10
3,13,20:159.10
4,13,20:159.10
5,13,20:159.10
6,13,20:82.0
7,13,20:82.0
8,13,20:82.0
9,13,20:159.10
10,13,20:159.10
-12,14,20:159.10
-11,14,20:159.10
-10,14,20:159.10
-9,14,20:159.10
-8,14,20:159.10
-7,14,20:159.10
-6,14,20:159.10
-5,14,20:159.10
-4,14,20:159.10
-3,14,20:159.10
-2,14,20:159.10
-1,14,20:159.10
0,14,20:159.10
1,14,20:159.10
2,14,20:159.10
3,14,20:159.10
4,14,20:159.10
5,14,20:82.0
6,14,20:82.0
7,14,20:82.0
8,14,20:82.0
9,14,20:82.0
-11,15,20:159.10
-10,15,20:159.10
-9,15,20:159.10
-8,15,20:82.0
-7,15,20:82.0
-6,15,20:82.0
-5,15,20:159.10
-4,15,20:159.10
-3,15,20:159.10
-2,15,20:159.10
-1,15,20:159.10
1,15,20:159.10
2,15,20:159.10
3,15,20:159.10
4,15,20:159.10
5,15,20:82.0
6,15,20:82.0
7,15,20:82.0
-11,16,20:159.10
-10,16,20:159.10
-9,16,20:82.0
-8,16,20:82.0
-7,16,20:82.0
-6,16,20:82.0
-5,16,20:82.0
-4,16,20:159.10
-3,16,20:159.10
-2,16,20:159.10
-1,16,20:159.10
0,16,20:159.10
1,16,20:159.10
2,16,20:159.10
3,16,20:159.10
-10,17,20:159.10
-9,17,20:82.0
-8,17,20:82.0
-7,17,20:82.0
-6,17,20:82.0
-5,17,20:82.0
-4,17,20:159.10
-3,17,20:159.10
-10,18,20:159.10
8,-18,21:82.0
5,-17,21:159.10
6,-17,21:159.10
7,-17,21:159.10
8,-17,21:159.10
1,-16,21:159.10
2,-16,21:159.10
3,-16,21:159.10
4,-16,21:159.10
5,-16,21:159.10
6,-16,21:159.10
7,-16,21:159.10
8,-16,21:159.10
9,-16,21:159.10
-4,-15,21:159.10
-3,-15,21:159.10
-2,-15,21:159.10
-1,-15,21:159.10
0,-15,21:159.10
1,-15,21:159.10
2,-15,21:159.10
3,-15,21:159.10
4,-15,21:159.10
5,-15,21:159.10
6,-15,21:159.10
8,-15,21:159.10
9,-15,21:159.10
-6,-14,21:159.10
-5,-14,21:159.10
-4,-14,21:159.10
-3,-14,21:159.10
-2,-14,21:159.10
-1,-14,21:159.10
0,-14,21:159.10
1,-14,21:159.10
2,-14,21:159.10
3,-14,21:159.10
4,-14,21:159.10
5,-14,21:159.10
6,-14,21:159.10
7,-14,21:159.10
8,-14,21:159.10
9,-14,21:159.10
10,-14,21:159.10
-8,-13,21:82.0
-7,-13,21:159.10
-6,-13,21:159.10
-5,-13,21:159.10
-4,-13,21:159.10
-3,-13,21:159.10
-2,-13,21:159.10
-1,-13,21:159.10
0,-13,21:159.10
1,-13,21:100.0
2,-13,21:159.10
3,-13,21:159.10
4,-13,21:159.10
5,-13,21:159.10
6,-13,21:159.10
7,-13,21:159.10
8,-13,21:159.10
9,-13,21:159.10
10,-13,21:159.10
-9,-12,21:159.10
-8,-12,21:159.10
-7,-12,21:159.10
-6,-12,21:159.10
-5,-12,21:159.10
-4,-12,21:159.10
-3,-12,21:100.0
-2,-12,21:100.0
2,-12,21:159.10
4,-12,21:159.10
5,-12,21:159.10
6,-12,21:159.10
7,-12,21:159.10
8,-12,21:159.10
9,-12,21:159.10
10,-12,21:159.10
11,-12,21:159.10
-10,-11,21:159.10
-9,-11,21:159.10
-8,-11,21:159.10
-7,-11,21:159.10
-6,-11,21:159.10
-5,-11,21:100.0
0,-11,21:159.10
1,-11,21:159.10
2,-11,21:159.10
3,-11,21:82.0
4,-11,21:82.0
5,-11,21:82.0
7,-11,21:159.10
8,-11,21:159.10
9,-11,21:159.10
10,-11,21:159.10
11,-11,21:159.10
-11,-10,21:159.10
-10,-10,21:159.10
-9,-10,21:159.10
-8,-10,21:159.10
-7,-10,21:159.10
-2,-10,21:159.10
-1,-10,21:159.10
0,-10,21:159.10
1,-10,21:159.10
6,-10,21:159.10
7,-10,21:159.10
8,-10,21:159.10
9,-10,21:159.10
10,-10,21:159.10
11,-10,21:159.10
12,-10,21:159.10
-13,-9,21:159.10
-12,-9,21:159.10
-11,-9,21:159.10
-10,-9,21:159.10
-9,-9,21:159.10
-8,-9,21:100.0
-7,-9,21:100.0
-4,-9,21:19.0
-3,-9,21:159.10
6,-9,21:159.10
7,-9,21:159.10
8,-9,21:159.10
9,-9,21:100.0
10,-9,21:159.10
11,-9,21:159.10
12,-9,21:159.10
-14,-8,21:159.10
-13,-8,21:159.10
-12,-8,21:159.10
-11,-8,21:159.10
-10,-8,21:82.0
-9,-8,21:100.0
-8,-8,21:100.0
-7,-8,21:19.0
-6,-8,21:19.0
-5,-8,21:19.0
7,-8,21:159.10
8,-8,21:159.10
9,-8,21:159.10
10,-8,21:159.10
11,-8,21:159.10
12,-8,21:159.10
13,-8,21:159.10
-15,-7,21:82.0
-14,-7,21:159.10
-13,-7,21:159.10
-12,-7,21:159.10
-11,-7,21:82.0
-10,-7,21:100.0
-9,-7,21:19.0
-8,-7,21:19.0
-7,-7,21:19.0
-6,-7,21:19.0
7,-7,21:159.10
8,-7,21:159.10
9,-7,21:159.10
10,-7,21:100.0
11,-7,21:159.10
12,-7,21:159.10
13,-7,21:159.10
14,-7,21:159.10
-18,-6,21:159.10
-17,-6,21:82.0
-16,-6,21:82.0
-15,-6,21:82.0
-14,-6,21:159.10
-13,-6,21:159.10
-12,-6,21:159.10
-11,-6,21:82.0
-10,-6,21:82.0
-9,-6,21:100.0
-8,-6,21:100.0
2,-6,21:159.10
3,-6,21:159.10
8,-6,21:82.0
9,-6,21:159.10
10,-6,21:100.0
11,-6,21:100.0
12,-6,21:159.10
13,-6,21:159.10
14,-6,21:159.10
-16,-5,21:82.0
-15,-5,21:82.0
-14,-5,21:159.10
-13,-5,21:159.10
-12,-5,21:100.0
-11,-5,21:82.0
-10,-5,21:82.0
-9,-5,21:82.0
1,-5,21:159.10
2,-5,21:159.10
3,-5,21:159.10
8,-5,21:82.0
9,-5,21:82.0
10,-5,21:100.0
11,-5,21:100.0
12,-5,21:159.10
13,-5,21:159.10
14,-5,21:82.0
-16,-4,21:159.10
-15,-4,21:159.10
-14,-4,21:159.10
-13,-4,21:159.10
-12,-4,21:100.0
-1,-4,21:159.10
0,-4,21:100.0
1,-4,21:100.0
2,-4,21:159.10
3,-4,21:159.10
9,-4,21:19.0
10,-4,21:19.0
11,-4,21:100.0
12,-4,21:159.10
13,-4,21:82.0
14,-4,21:82.0
15,-4,21:82.0
-16,-3,21:159.10
-15,-3,21:159.10
-14,-3,21:159.10
-13,-3,21:159.10
-12,-3,21:159.10
-11,-3,21:159.10
-4,-3,21:159.10
-3,-3,21:159.10
-2,-3,21:100.0
-1,-3,21:100.0
0,-3,21:100.0
1,-3,21:100.0
2,-3,21:100.0
3,-3,21:100.0
9,-3,21:19.0
10,-3,21:19.0
11,-3,21:100.0
12,-3,21:100.0
13,-3,21:82.0
14,-3,21:82.0
15,-3,21:82.0
-16,-2,21:159.10
-15,-2,21:159.10
-14,-2,21:159.10
-13,-2,21:159.10
-12,-2,21:100.0
-11,-2,21:159.10
-10,-2,21:159.10
-5,-2,21:159.10
-4,-2,21:159.10
-3,-2,21:159.10
-2,-2,21:159.10
-1,-2,21:100.0
0,-2,21:100.0
1,-2,21:100.0
2,-2,21:100.0
3,-2,21:159.10
4,-2,21:159.10
10,-2,21:19.0
11,-2,21:19.0
12,-2,21:100.0
13,-2,21:82.0
14,-2,21:82.0
15,-2,21:82.0
-15,-1,21:159.10
-14,-1,21:159.10
-13,-1,21:159.10
-11,-1,21:159.10
-10,-1,21:159.10
-4,-1,21:159.10
-3,-1,21:100.0
-2,-1,21:159.10
-1,-1,21:159.10
0,-1,21:159.10
1,-1,21:159.10
2,-1,21:159.10
3,-1,21:100.0
4,-1,21:100.0
10,-1,21:19.0
11,-1,21:19.0
13,-1,21:159.10
14,-1,21:82.0
15,-1,21:82.0
16,-1,21:82.0
-15,0,21:159.10
-14,0,21:159.10
-13,0,21:159.10
-12,0,21:100.0
-11,0,21:100.0
-10,0,21:100.0
-3,0,21:100.0
-2,0,21:100.0
-1,0,21:100.0
0,0,21:159.10
1,0,21:100.0
2,0,21:100.0
3,0,21:159.10
4,0,21:159.10
5,0,21:159.10
10,0,21:19.0
11,0,21:19.0
12,0,21:19.0
13,0,21:159.10
14,0,21:159.10
15,0,21:159.10
-15,1,21:159.10
-14,1,21:159.10
-13,1,21:159.10
-12,1,21:100.0
-11,1,21:100.0
-10,1,21:100.0
-9,1,21:159.10
-3,1,21:159.10
-2,1,21:100.0
-1,1,21:159.10
0,1,21:159.10
1,1,21:100.0
2,1,21:100.0
3,1,21:100.0
4,1,21:100.0
5,1,21:159.10
11,1,21:19.0
12,1,21:19.0
13,1,21:19.0
14,1,21:159.10
15,1,21:159.10
16,1,21:159.10
-14,2,21:159.10
-13,2,21:159.10
-12,2,21:159.10
-11,2,21:100.0
-10,2,21:100.0
-9,2,21:159.10
-2,2,21:100.0
-1,2,21:159.10
0,2,21:100.0
1,2,21:100.0
2,2,21:100.0
3,2,21:159.10
14,2,21:159.10
15,2,21:159.10
16,2,21:159.10
17,2,21:159.10
-14,3,21:159.10
-13,3,21:159.10
-12,3,21:159.10
-11,3,21:100.0
-10,3,21:100.0
-2,3,21:159.10
-1,3,21:159.10
0,3,21:159.10
1,3,21:159.10
4,3,21:100.15
5,3,21:100.15
14,3,21:159.10
15,3,21:159.10
16,3,21:159.10
17,3,21:159.10
-14,4,21:159.10
-13,4,21:159.10
-12,4,21:159.10
-11,4,21:100.0
-10,4,21:100.0
-9,4,21:100.0
-8,4,21:159.10
-2,4,21:159.10
-1,4,21:159.10
4,4,21:100.15
5,4,21:100.15
9,4,21:19.0
10,4,21:19.0
11,4,21:19.0
12,4,21:19.0
13,4,21:159.10
14,4,21:159.10
15,4,21:159.10
16,4,21:159.10
17,4,21:159.10
18,4,21:159.10
-13,5,21:159.10
-12,5,21:159.10
-11,5,21:159.10
-10,5,21:100.0
-9,5,21:100.0
-8,5,21:82.0
8,5,21:19.0
9,5,21:19.0
10,5,21:19.0
12,5,21:159.10
13,5,21:159.10
14,5,21:159.10
15,5,21:159.10
16,5,21:159.10
19,5,21:159.10
-13,6,21:159.10
-12,6,21:159.10
-11,6,21:82.0
-10,6,21:100.0
-9,6,21:100.0
-8,6,21:100.0
-7,6,21:82.0
6,6,21:19.0
7,6,21:19.0
8,6,21:19.0
10,6,21:100.0
11,6,21:159.10
12,6,21:159.10
13,6,21:159.10
14,6,21:159.10
15,6,21:159.10
-12,7,21:159.10
-11,7,21:82.0
-10,7,21:82.0
-9,7,21:100.0
-8,7,21:100.0
-7,7,21:82.0
5,7,21:19.0
9,7,21:100.0
10,7,21:159.10
11,7,21:159.10
12,7,21:159.10
13,7,21:159.10
14,7,21:159.10
-12,8,21:159.10
-11,8,21:82.0
-10,8,21:82.0
-9,8,21:82.0
-8,8,21:100.0
-7,8,21:82.0
-6,8,21:159.10
2,8,21:19.0
3,8,21:19.0
4,8,21:100.0
5,8,21:100.0
6,8,21:100.0
8,8,21:159.10
9,8,21:159.10
10,8,21:159.10
11,8,21:159.10
12,8,21:159.10
-11,9,21:159.10
-10,9,21:82.0
-9,9,21:82.0
-8,9,21:100.0
-7,9,21:159.10
-6,9,21:159.10
-4,9,21:159.10
-3,9,21:159.10
-2,9,21:100.0
-1,9,21:159.10
0,9,21:159.10
1,9,21:100.0
2,9,21:100.0
3,9,21:100.0
4,9,21:100.0
5,9,21:100.0
6,9,21:100.0
7,9,21:159.10
8,9,21:159.10
9,9,21:159.10
10,9,21:159.10
11,9,21:159.10
-11,10,21:159.10
-10,10,21:159.10
-9,10,21:159.10
-8,10,21:159.10
-7,10,21:159.10
-6,10,21:100.0
-5,10,21:100.0
-4,10,21:159.10
-3,10,21:159.10
-2,10,21:100.0
-1,10,21:100.0
0,10,21:100.0
1,10,21:100.0
2,10,21:100.0
3,10,21:100.0
4,10,21:100.0
5,10,21:159.10
6,10,21:159.10
7,10,21:159.10
8,10,21:159.10
9,10,21:159.10
-10,11,21:159.10
-9,11,21:159.10
-8,11,21:159.10
-7,11,21:159.10
-6,11,21:100.0
-5,11,21:159.10
-4,11,21:100.0
-3,11,21:159.10
-2,11,21:159.10
-1,11,21:100.0
1,11,21:159.10
2,11,21:159.10
3,11,21:159.10
4,11,21:159.10
5,11,21:159.10
6,11,21:159.10
7,11,21:159.10
8,11,21:159.10
-10,12,21:159.10
-9,12,21:159.10
-8,12,21:159.10
-7,12,21:159.10
-6,12,21:159.10
-5,12,21:159.10
-4,12,21:159.10
-3,12,21:159.10
-2,12,21:159.10
-1,12,21:159.10
0,12,21:159.10
1,12,21:159.10
2,12,21:159.10
3,12,21:159.10
4,12,21:159.10
5,12,21:159.10
6,12,21:159.10
7,12,21:159.10
-9,13,21:159.10
-8,13,21:159.10
-7,13,21:100.0
-6,13,21:159.10
-5,13,21:159.10
-4,13,21:159.10
-3,13,21:159.10
-2,13,21:159.10
-1,13,21:159.10
0,13,21:159.10
1,13,21:159.10
2,13,21:159.10
3,13,21:159.10
4,13,21:159.10
5,13,21:159.10
-9,14,21:159.10
-8,14,21:159.10
-7,14,21:159.10
-6,14,21:159.10
-5,14,21:159.10
-4,14,21:159.10
-3,14,21:159.10
-2,14,21:159.10
-9,15,21:159.10
-8,15,21:82.0
-9,16,21:82.0
6,-14,22:159.10
1,-13,22:159.10
2,-13,22:159.10
3,-13,22:159.10
4,-13,22:159.10
5,-13,22:159.10
6,-13,22:159.10
7,-13,22:159.10
-3,-12,22:159.10
-2,-12,22:159.10
-1,-12,22:159.10
0,-12,22:159.10
1,-12,22:159.10
2,-12,22:159.10
4,-12,22:82.0
5,-12,22:82.0
6,-12,22:159.10
7,-12,22:159.10
-5,-11,22:159.10
-4,-11,22:159.10
-3,-11,22:159.10
-2,-11,22:159.10
-1,-11,22:159.10
0,-11,22:159.10
1,-11,22:159.10
2,-11,22:82.0
3,-11,22:82.0
4,-11,22:82.0
5,-11,22:82.0
7,-11,22:159.10
8,-11,22:159.10
-6,-10,22:159.10
-5,-10,22:159.10
-4,-10,22:159.10
-3,-10,22:159.10
-2,-10,22:159.10
-1,-10,22:159.10
0,-10,22:159.10
1,-10,22:159.10
2,-10,22:100.0
3,-10,22:100.0
5,-10,22:100.0
6,-10,22:82.0
7,-10,22:159.10
8,-10,22:159.10
-8,-9,22:159.10
-7,-9,22:159.10
-6,-9,22:159.10
-5,-9,22:159.10
-4,-9,22:159.10
-3,-9,22:159.10
-2,-9,22:100.0
-1,-9,22:100.0
6,-9,22:82.0
7,-9,22:159.10
8,-9,22:159.10
9,-9,22:159.10
-9,-8,22:82.0
-8,-8,22:82.0
-7,-8,22:159.10
-6,-8,22:159.10
-5,-8,22:159.10
-4,-8,22:100.0
6,-8,22:100.0
7,-8,22:159.10
8,-8,22:159.10
9,-8,22:159.10
-10,-7,22:82.0
-9,-7,22:82.0
-8,-7,22:82.0
-7,-7,22:82.0
-6,-7,22:159.10
-5,-7,22:100.0
-4,-7,22:100.0
7,-7,22:159.10
8,-7,22:159.10
9,-7,22:159.10
10,-7,22:159.10
-12,-6,22:159.10
-11,-6,22:82.0
-10,-6,22:82.0
-9,-6,22:82.0
-8,-6,22:82.0
-7,-6,22:100.0
-6,-6,22:100.0
-5,-6,22:100.0
-4,-6,22:100.0
7,-6,22:100.0
8,-6,22:82.0
9,-6,22:82.0
10,-6,22:159.10
11,-6,22:159.10
-14,-5,22:159.10
-13,-5,22:159.10
-12,-5,22:159.10
-11,-5,22:82.0
-10,-5,22:82.0
-9,-5,22:82.0
-8,-5,22:100.0
-7,-5,22:100.0
-6,-5,22:100.0
-5,-5,22:100.0
-4,-5,22:100.0
8,-5,22:82.0
9,-5,22:82.0
10,-5,22:159.10
11,-5,22:159.10
-13,-4,22:159.10
-12,-4,22:159.10
-11,-4,22:100.0
-10,-4,22:100.0
-9,-4,22:100.0
-8,-4,22:100.0
-7,-4,22:100.0
-6,-4,22:100.0
-5,-4,22:100.0
8,-4,22:100.0
9,-4,22:82.0
10,-4,22:159.10
11,-4,22:159.10
-13,-3,22:159.10
-12,-3,22:159.10
-11,-3,22:159.10
-10,-3,22:100.0
-9,-3,22:100.0
-8,-3,22:100.0
-7,-3,22:100.0
9,-3,22:159.10
10,-3,22:159.10
11,-3,22:159.10
12,-3,22:159.10
-12,-2,22:159.10
-11,-2,22:159.10
-10,-2,22:159.10
-9,-2,22:100.0
-8,-2,22:100.0
-7,-2,22:100.0
9,-2,22:100.0
10,-2,22:159.10
11,-2,22:159.10
12,-2,22:159.10
-11,-1,22:159.10
-10,-1,22:159.10
-9,-1,22:100.0
-8,-1,22:100.0
10,-1,22:159.10
11,-1,22:159.10
12,-1,22:159.10
-12,0,22:159.10
-11,0,22:159.10
-10,0,22:159.10
-9,0,22:100.0
-8,0,22:100.0
-7,0,22:100.0
10,0,22:159.10
11,0,22:159.10
12,0,22:159.10
13,0,22:159.10
-12,1,22:159.10
-11,1,22:159.10
-10,1,22:159.10
-9,1,22:159.10
-8,1,22:100.0
-7,1,22:100.0
-6,1,22:100.0
10,1,22:100.0
11,1,22:159.10
12,1,22:159.10
13,1,22:159.10
-11,2,22:159.10
-10,2,22:159.10
-9,2,22:159.10
-8,2,22:100.0
-7,2,22:100.0
-6,2,22:100.0
11,2,22:82.0
12,2,22:159.10
13,2,22:159.10
-11,3,22:159.10
-10,3,22:159.10
-8,3,22:100.0
-7,3,22:100.0
-6,3,22:100.0
4,3,22:100.15
10,3,22:100.0
11,3,22:100.0
12,3,22:82.0
13,3,22:159.10
-11,4,22:159.10
-10,4,22:159.10
-9,4,22:159.10
-8,4,22:159.10
-7,4,22:100.0
-6,4,22:100.0
-5,4,22:100.0
8,4,22:100.0
9,4,22:159.10
10,4,22:159.10
11,4,22:82.0
12,4,22:159.10
13,4,22:159.10
-10,5,22:82.0
-9,5,22:82.0
-8,5,22:82.0
-7,5,22:100.0
-6,5,22:100.0
-5,5,22:100.0
7,5,22:100.0
8,5,22:159.10
9,5,22:159.10
10,5,22:159.10
11,5,22:159.10
12,5,22:159.10
-10,6,22:82.0
-9,6,22:82.0
-8,6,22:82.0
-7,6,22:82.0
-6,6,22:100.0
-5,6,22:100.0
6,6,22:159.10
7,6,22:159.10
8,6,22:159.10
9,6,22:159.10
10,6,22:159.10
-9,7,22:82.0
-8,7,22:82.0
-7,7,22:82.0
-6,7,22:100.0
-5,7,22:100.0
-2,7,22:100.0
-1,7,22:100.0
0,7,22:100.0
1,7,22:100.0
2,7,22:100.0
3,7,22:100.0
4,7,22:100.0
5,7,22:159.10
6,7,22:159.10
7,7,22:159.10
8,7,22:159.10
9,7,22:159.10
-8,8,22:82.0
-7,8,22:82.0
-6,8,22:159.10
-5,8,22:100.0
-4,8,22:100.0
-3,8,22:100.0
-2,8,22:100.0
-1,8,22:100.0
0,8,22:100.0
1,8,22:100.0
2,8,22:159.10
3,8,22:159.10
4,8,22:159.10
5,8,22:159.10
6,8,22:159.10
7,8,22:159.10
-8,9,22:82.0
-7,9,22:159.10
-6,9,22:159.10
-5,9,22:100.0
-4,9,22:159.10
-3,9,22:159.10
-2,9,22:159.10
-1,9,22:159.10
0,9,22:159.10
1,9,22:159.10
2,9,22:159.10
3,9,22:159.10
4,9,22:159.10
5,9,22:159.10
6,9,22:159.10
-7,10,22:159.10
-6,10,22:159.10
-5,10,22:159.10
-4,10,22:159.10
-3,10,22:159.10
-2,10,22:159.10
-1,10,22:159.10
0,10,22:159.10
1,10,22:159.10
2,10,22:159.10
3,10,22:159.10
4,10,22:159.10
-7,11,22:159.10
-6,11,22:159.10
-5,11,22:159.10
-4,11,22:159.10
-3,11,22:159.10
-2,11,22:159.10
-1,11,22:159.10
-7,12,22:159.10
-7,13,22:159.10
2,-10,23:82.0
3,-10,23:82.0
4,-10,23:82.0
5,-10,23:82.0
-2,-9,23:159.10
-1,-9,23:159.10
0,-9,23:159.10
1,-9,23:159.10
2,-9,23:82.0
3,-9,23:82.0
4,-9,23:82.0
5,-9,23:82.0
-4,-8,23:159.10
-3,-8,23:159.10
-2,-8,23:159.10
-1,-8,23:159.10
0,-8,23:159.10
1,-8,23:159.10
2,-8,23:159.10
3,-8,23:82.0
4,-8,23:82.0
5,-8,23:82.0
6,-8,23:159.10
-5,-7,23:159.10
-4,-7,23:159.10
-3,-7,23:159.10
-2,-7,23:159.10
-1,-7,23:159.10
0,-7,23:159.10
1,-7,23:159.10
2,-7,23:159.10
3,-7,23:100.0
4,-7,23:159.10
5,-7,23:159.10
6,-7,23:159.10
-7,-6,23:82.0
-6,-6,23:159.10
-5,-6,23:159.10
-4,-6,23:159.10
-3,-6,23:159.10
-2,-6,23:159.10
-1,-6,23:100.0
0,-6,23:100.0
1,-6,23:100.0
2,-6,23:100.0
3,-6,23:100.0
4,-6,23:100.0
5,-6,23:159.10
6,-6,23:159.10
7,-6,23:159.10
-8,-5,23:82.0
-7,-5,23:82.0
-6,-5,23:159.10
-5,-5,23:159.10
-4,-5,23:159.10
-3,-5,23:100.0
1,-5,23:100.0
2,-5,23:100.0
3,-5,23:100.0
4,-5,23:100.0
5,-5,23:159.10
6,-5,23:159.10
7,-5,23:82.0
-11,-4,23:159.10
-10,-4,23:82.0
-9,-4,23:82.0
-8,-4,23:82.0
-7,-4,23:159.10
-6,-4,23:159.10
-5,-4,23:159.10
-3,-4,23:100.0
-2,-4,23:100.0
2,-4,23:100.0
3,-4,23:100.0
4,-4,23:100.0
5,-4,23:159.10
6,-4,23:159.10
7,-4,23:159.10
8,-4,23:82.0
-10,-3,23:159.10
-9,-3,23:159.10
-8,-3,23:159.10
-7,-3,23:159.10
-6,-3,23:100.0
-5,-3,23:100.0
-4,-3,23:100.0
-3,-3,23:100.0
-2,-3,23:100.0
5,-3,23:100.0
6,-3,23:159.10
7,-3,23:159.10
8,-3,23:159.10
-9,-2,23:159.10
-8,-2,23:159.10
-7,-2,23:159.10
-6,-2,23:100.0
-5,-2,23:100.0
-4,-2,23:100.0
-3,-2,23:100.0
6,-2,23:159.10
7,-2,23:159.10
8,-2,23:159.10
9,-2,23:159.10
-9,-1,23:159.10
-8,-1,23:159.10
-7,-1,23:100.0
-6,-1,23:100.0
-5,-1,23:100.0
-4,-1,23:100.0
-3,-1,23:100.0
6,-1,23:100.0
7,-1,23:159.10
8,-1,23:159.10
9,-1,23:159.10
-9,0,23:159.10
-8,0,23:159.10
-7,0,23:159.10
-6,0,23:100.0
-5,0,23:100.0
-4,0,23:100.0
7,0,23:159.10
8,0,23:159.10
9,0,23:159.10
-8,1,23:159.10
-7,1,23:159.10
-6,1,23:159.10
-5,1,23:100.0
-4,1,23:100.0
-3,1,23:100.0
7,1,23:100.0
8,1,23:159.10
9,1,23:159.10
10,1,23:159.10
-8,2,23:159.10
-7,2,23:159.10
-6,2,23:159.10
-5,2,23:100.0
-4,2,23:100.0
-3,2,23:100.0
-2,2,23:100.0
6,2,23:100.0
7,2,23:100.0
8,2,23:100.0
9,2,23:159.10
10,2,23:82.0
-8,3,23:159.10
-7,3,23:159.10
-6,3,23:159.10
-5,3,23:100.0
-4,3,23:100.0
-3,3,23:100.0
5,3,23:100.0
6,3,23:159.10
7,3,23:159.10
8,3,23:159.10
9,3,23:159.10
10,3,23:82.0
11,3,23:82.0
-7,4,23:159.10
-6,4,23:159.10
-5,4,23:159.10
-4,4,23:100.0
4,4,23:159.10
5,4,23:159.10
6,4,23:159.10
7,4,23:159.10
8,4,23:159.10
-7,5,23:159.10
-6,5,23:159.10
-5,5,23:159.10
-4,5,23:159.10
0,5,23:100.0
1,5,23:100.0
2,5,23:100.0
3,5,23:159.10
4,5,23:159.10
5,5,23:159.10
6,5,23:159.10
7,5,23:159.10
-6,6,23:159.10
-5,6,23:159.10
-4,6,23:100.0
-3,6,23:100.0
-2,6,23:159.10
-1,6,23:82.0
0,6,23:82.0
1,6,23:82.0
2,6,23:159.10
3,6,23:159.10
4,6,23:159.10
5,6,23:159.10
-6,7,23:159.10
-5,7,23:159.10
-4,7,23:100.0
-3,7,23:159.10
-2,7,23:159.10
-1,7,23:159.10
0,7,23:159.10
1,7,23:159.10
2,7,23:159.10
3,7,23:159.10
4,7,23:159.10
-5,8,23:159.10
-4,8,23:159.10
-3,8,23:159.10
-2,8,23:159.10
-1,8,23:159.10
0,8,23:159.10
1,8,23:159.10
-5,9,23:159.10
3,-7,24:159.10
-1,-6,24:159.10
0,-6,24:159.10
1,-6,24:159.10
2,-6,24:159.10
3,-6,24:159.10
4,-6,24:159.10
-3,-5,24:159.10
-2,-5,24:159.10
-1,-5,24:159.10
0,-5,24:159.10
1,-5,24:159.10
2,-5,24:159.10
3,-5,24:159.10
4,-5,24:159.10
-3,-4,24:159.10
-2,-4,24:159.10
-1,-4,24:159.10
0,-4,24:159.10
1,-4,24:159.10
2,-4,24:159.10
3,-4,24:159.10
4,-4,24:159.10
-6,-3,24:159.10
-5,-3,24:159.10
-4,-3,24:159.10
-3,-3,24:159.10
-2,-3,24:159.10
-1,-3,24:100.0
0,-3,24:100.0
1,-3,24:100.0
2,-3,24:100.0
3,-3,24:100.0
4,-3,24:159.10
5,-3,24:159.10
-6,-2,24:159.10
-5,-2,24:159.10
-4,-2,24:159.10
-3,-2,24:159.10
-2,-2,24:100.0
-1,-2,24:100.0
0,-2,24:100.0
1,-2,24:100.0
2,-2,24:100.0
3,-2,24:159.10
4,-2,24:159.10
5,-2,24:159.10
-7,-1,24:159.10
-6,-1,24:159.10
-5,-1,24:159.10
-4,-1,24:159.10
-3,-1,24:159.10
-2,-1,24:100.0
-1,-1,24:100.0
0,-1,24:100.0
1,-1,24:100.0
2,-1,24:100.0
3,-1,24:159.10
4,-1,24:159.10
5,-1,24:159.10
6,-1,24:159.10
-6,0,24:159.10
-5,0,24:159.10
-4,0,24:159.10
-3,0,24:100.0
-2,0,24:100.0
-1,0,24:100.0
0,0,24:100.0
1,0,24:100.0
2,0,24:100.0
3,0,24:100.0
4,0,24:159.10
5,0,24:159.10
6,0,24:159.10
-5,1,24:159.10
-4,1,24:159.10
-3,1,24:159.10
-1,1,24:100.0
0,1,24:100.0
1,1,24:100.0
2,1,24:100.0
3,1,24:100.0
4,1,24:159.10
5,1,24:159.10
6,1,24:159.10
7,1,24:159.10
-5,2,24:159.10
-4,2,24:159.10
-3,2,24:159.10
-2,2,24:159.10
0,2,24:100.0
1,2,24:82.0
2,2,24:159.10
3,2,24:159.10
4,2,24:159.10
5,2,24:159.10
6,2,24:159.10
7,2,24:159.10
8,2,24:159.10
-5,3,24:159.10
-4,3,24:159.10
-3,3,24:159.10
-2,3,24:82.0
-1,3,24:82.0
0,3,24:82.0
1,3,24:82.0
2,3,24:82.0
3,3,24:159.10
4,3,24:159.10
5,3,24:159.10
-4,4,24:159.10
-3,4,24:159.10
-2,4,24:82.0
-1,4,24:82.0
0,4,24:82.0
1,4,24:82.0
2,4,24:82.0
3,4,24:159.10
-2,5,24:82.0
-1,5,24:82.0
0,5,24:82.0
1,5,24:82.0
2,5,24:82.0
-4,6,24:159.10
-3,6,24:159.10
-4,7,24:159.10
-1,-3,25:159.10
0,-3,25:159.10
1,-3,25:159.10
2,-3,25:159.10
3,-3,25:159.10
-2,-2,25:159.10
-1,-2,25:159.10
0,-2,25:159.10
1,-2,25:159.10
2,-2,25:159.10
3,-2,25:100.15
-2,-1,25:159.10
-1,-1,25:159.10
0,-1,25:159.10
1,-1,25:159.10
2,-1,25:159.10
-3,0,25:159.10
-2,0,25:159.10
-1,0,25:159.10
0,0,25:159.10
1,0,25:159.10
2,0,25:159.10
3,0,25:159.10
-2,1,25:159.10
-1,1,25:159.10
0,1,25:159.10
1,1,25:159.10
2,1,25:159.10
3,1,25:159.10
-1,2,25:82.0
0,2,25:82.0
0,-2,26:100.15
1,-2,26:100.15
2,-2,26:100.15
0,-1,26:100.15
1,-1,26:100.15
2,-1,26:100.15
-2,0,26:100.15
-1,0,26:100.15
0,0,26:100.15
1,0,26:100.15
2,0,26:100.15
-1,1,26:100.15
0,1,26:100.15
0,-1,27:100.15
1,-1,27:100.15
-1,0,27:100.15
0,0,27:100.15
1,0,27:100.15
0,1,27:100.15
11,-3,28:100.0
0,-2,28:100.15
0,-1,28:100.15
1,-1,28:100.15
-1,0,28:100.15
0,0,28:100.15
-2,-12,29:100.0
-5,-11,29:100.0
-4,-11,29:100.0
-3,-11,29:100.0
-2,-11,29:100.0
-1,-11,29:100.0
0,-11,29:100.0
1,-11,29:100.0
-7,-10,29:100.0
-6,-10,29:100.0
0,-10,29:100.0
1,-10,29:100.0
2,-10,29:100.0
3,-10,29:100.0
4,-10,29:100.0
5,-10,29:100.0
-8,-9,29:100.0
-7,-9,29:100.0
3,-9,29:100.0
4,-9,29:100.0
5,-9,29:100.0
6,-9,29:100.0
7,-9,29:100.0
-9,-8,29:100.0
-8,-8,29:100.0
6,-8,29:100.0
7,-8,29:100.0
8,-8,29:100.0
-9,-7,29:100.0
-8,-7,29:100.0
7,-7,29:100.0
8,-7,29:100.0
-10,-6,29:100.0
-9,-6,29:100.0
3,-6,29:100.0
8,-6,29:100.0
9,-6,29:100.0
-11,-5,29:100.0
-10,-5,29:100.0
5,-5,29:100.0
8,-5,29:100.0
9,-5,29:100.0
-11,-4,29:100.0
9,-4,29:100.0
10,-4,29:100.0
-13,-3,29:100.0
-12,-3,29:100.0
9,-3,29:100.0
10,-3,29:100.0
11,-3,29:159.10
-13,-2,29:100.0
-1,-2,29:100.15
0,-2,29:100.15
1,-2,29:100.15
10,-2,29:100.0
11,-2,29:100.0
-13,-1,29:100.0
-2,-1,29:100.15
-1,-1,29:100.15
0,-1,29:100.15
1,-1,29:100.15
10,-1,29:100.0
11,-1,29:100.0
-13,0,29:100.0
-1,0,29:100.15
0,0,29:100.15
11,0,29:100.0
12,0,29:100.0
-12,1,29:100.0
0,1,29:100.15
12,1,29:100.0
-12,2,29:100.0
12,2,29:100.0
-12,3,29:100.0
11,3,29:100.0
11,4,29:100.0
10,5,29:100.0
11,5,29:100.0
9,6,29:100.0
10,6,29:100.0
8,7,29:100.0
9,7,29:100.0
8,8,29:100.0
7,9,29:100.0
8,9,29:100.0
6,10,29:100.0
7,10,29:100.0
4,11,29:100.0
5,11,29:100.0
-1,12,29:100.0
0,12,29:100.0
1,12,29:100.0
2,12,29:100.0
3,12,29:100.0
4,12,29:100.0
5,12,29:100.0
3,13,29:100.0
4,13,29:100.0
-2,-12,30:159.10
-5,-11,30:159.10
-4,-11,30:159.10
-3,-11,30:159.10
-2,-11,30:82.0
-1,-11,30:159.10
0,-11,30:159.10
1,-11,30:159.10
-7,-10,30:159.10
-6,-10,30:159.10
-5,-10,30:100.0
-4,-10,30:100.0
-3,-10,30:100.0
-2,-10,30:100.0
-1,-10,30:100.0
0,-10,30:159.10
1,-10,30:159.10
2,-10,30:159.10
3,-10,30:159.10
4,-10,30:159.10
5,-10,30:159.10
-8,-9,30:159.10
-7,-9,30:159.10
-6,-9,30:100.0
-5,-9,30:100.0
-4,-9,30:100.0
-3,-9,30:100.0
-2,-9,30:100.0
-1,-9,30:100.0
0,-9,30:100.0
1,-9,30:100.0
2,-9,30:100.0
3,-9,30:159.10
4,-9,30:159.10
5,-9,30:159.10
6,-9,30:159.10
7,-9,30:159.10
-9,-8,30:159.10
-8,-8,30:159.10
-7,-8,30:100.0
-6,-8,30:100.0
-5,-8,30:100.0
-2,-8,30:100.0
-1,-8,30:100.0
0,-8,30:100.0
1,-8,30:100.0
2,-8,30:100.0
3,-8,30:100.0
4,-8,30:100.0
5,-8,30:100.0
6,-8,30:82.0
7,-8,30:82.0
8,-8,30:159.10
-9,-7,30:159.10
-8,-7,30:159.10
-7,-7,30:100.0
-6,-7,30:100.0
0,-7,30:100.0
1,-7,30:100.0
2,-7,30:100.0
3,-7,30:100.0
4,-7,30:100.0
5,-7,30:100.0
6,-7,30:100.0
7,-7,30:82.0
8,-7,30:82.0
-10,-6,30:159.10
-9,-6,30:159.10
-8,-6,30:100.0
-7,-6,30:100.0
-6,-6,30:100.0
2,-6,30:100.0
3,-6,30:159.10
4,-6,30:100.0
5,-6,30:100.0
6,-6,30:100.0
7,-6,30:100.0
8,-6,30:82.0
9,-6,30:159.10
-11,-5,30:159.10
-10,-5,30:159.10
-9,-5,30:100.0
-8,-5,30:100.0
-7,-5,30:100.0
-3,-5,30:100.0
-2,-5,30:100.0
-1,-5,30:100.0
0,-5,30:100.0
1,-5,30:100.0
4,-5,30:100.0
5,-5,30:82.0
6,-5,30:100.0
7,-5,30:100.0
8,-5,30:82.0
9,-5,30:159.10
-11,-4,30:159.10
-10,-4,30:100.0
-9,-4,30:100.0
-8,-4,30:100.0
-3,-4,30:100.0
-2,-4,30:100.0
-1,-4,30:100.0
0,-4,30:100.0
1,-4,30:100.0
2,-4,30:100.0
3,-4,30:100.0
5,-4,30:100.0
6,-4,30:100.0
7,-4,30:100.0
8,-4,30:100.0
9,-4,30:159.10
10,-4,30:159.10
-13,-3,30:159.10
-12,-3,30:159.10
-11,-3,30:100.0
-10,-3,30:100.0
-9,-3,30:100.0
-5,-3,30:100.0
-4,-3,30:100.0
-3,-3,30:100.0
-2,-3,30:100.0
0,-3,30:100.0
1,-3,30:100.0
2,-3,30:100.0
3,-3,30:100.0
4,-3,30:100.0
6,-3,30:100.0
7,-3,30:100.0
8,-3,30:100.0
9,-3,30:159.10
10,-3,30:159.10
-13,-2,30:159.10
-12,-2,30:100.0
-11,-2,30:100.0
-10,-2,30:100.0
-5,-2,30:100.0
-4,-2,30:100.0
-3,-2,30:100.0
-1,-2,30:100.15
0,-2,30:100.15
2,-2,30:100.0
3,-2,30:100.0
4,-2,30:100.0
7,-2,30:100.0
8,-2,30:100.0
9,-2,30:100.0
10,-2,30:159.10
11,-2,30:159.10
-13,-1,30:159.10
-11,-1,30:100.0
-10,-1,30:100.0
-9,-1,30:100.0
-8,-1,30:100.0
-7,-1,30:100.0
-6,-1,30:100.0
-5,-1,30:100.0
-4,-1,30:100.0
-3,-1,30:100.0
-2,-1,30:100.0
-1,-1,30:100.0
0,-1,30:100.0
1,-1,30:100.0
3,-1,30:100.0
4,-1,30:100.0
5,-1,30:100.0
7,-1,30:100.0
8,-1,30:100.0
9,-1,30:100.0
10,-1,30:82.0
11,-1,30:159.10
-13,0,30:159.10
-12,0,30:100.0
-11,0,30:100.0
-10,0,30:100.0
-6,0,30:100.0
-5,0,30:100.0
-1,0,30:100.15
0,0,30:100.0
1,0,30:100.0
3,0,30:100.0
4,0,30:100.0
5,0,30:100.0
8,0,30:100.0
9,0,30:100.0
10,0,30:100.0
11,0,30:82.0
12,0,30:159.10
-12,1,30:159.10
-11,1,30:100.0
-10,1,30:100.0
-6,1,30:100.0
-5,1,30:100.0
0,1,30:100.15
1,1,30:100.0
4,1,30:100.0
5,1,30:100.0
6,1,30:100.0
9,1,30:100.0
10,1,30:100.0
11,1,30:100.0
12,1,30:159.10
-12,2,30:159.10
-11,2,30:100.0
-10,2,30:100.0
-6,2,30:100.0
-5,2,30:100.0
0,2,30:100.15
1,2,30:100.0
3,2,30:100.0
4,2,30:100.0
5,2,30:100.0
9,2,30:100.0
10,2,30:100.0
11,2,30:100.0
12,2,30:159.10
-12,3,30:159.10
-11,3,30:100.0
-10,3,30:100.0
-5,3,30:100.0
2,3,30:100.0
3,3,30:100.0
4,3,30:100.0
9,3,30:100.0
10,3,30:100.0
11,3,30:159.10
-11,4,30:100.0
-10,4,30:100.0
-9,4,30:100.0
-5,4,30:100.0
1,4,30:100.0
2,4,30:100.0
3,4,30:100.0
8,4,30:100.0
9,4,30:100.0
10,4,30:100.0
11,4,30:159.10
-11,5,30:100.0
-10,5,30:100.0
-9,5,30:100.0
-5,5,30:100.0
-2,5,30:100.0
-1,5,30:100.0
0,5,30:100.0
1,5,30:100.0
2,5,30:100.0
3,5,30:100.0
7,5,30:100.0
8,5,30:100.0
9,5,30:100.0
10,5,30:159.10
11,5,30:159.10
-10,6,30:100.0
-9,6,30:100.0
-5,6,30:100.0
-4,6,30:100.0
-3,6,30:100.0
-2,6,30:100.0
-1,6,30:100.0
0,6,30:100.0
1,6,30:100.0
3,6,30:100.0
6,6,30:100.0
7,6,30:100.0
8,6,30:100.0
9,6,30:159.10
10,6,30:159.10
-10,7,30:100.0
-9,7,30:100.0
3,7,30:100.0
6,7,30:100.0
7,7,30:100.0
8,7,30:159.10
9,7,30:159.10
-10,8,30:100.0
-9,8,30:100.0
-8,8,30:100.0
3,8,30:100.0
5,8,30:100.0
6,8,30:100.0
7,8,30:100.0
8,8,30:159.10
-9,9,30:100.0
-8,9,30:100.0
3,9,30:100.0
4,9,30:100.0
5,9,30:100.0
6,9,30:100.0
7,9,30:159.10
8,9,30:159.10
-8,10,30:100.0
-7,10,30:100.0
-6,10,30:100.0
-5,10,30:100.0
-4,10,30:100.0
-3,10,30:100.0
-2,10,30:100.0
-1,10,30:100.0
0,10,30:100.0
1,10,30:100.0
2,10,30:100.0
3,10,30:100.0
4,10,30:100.0
5,10,30:100.0
6,10,30:159.10
7,10,30:159.10
-6,11,30:100.0
-5,11,30:100.0
-4,11,30:100.0
-3,11,30:100.0
-2,11,30:100.0
-1,11,30:100.0
1,11,30:100.0
2,11,30:100.0
3,11,30:100.0
4,11,30:100.0
5,11,30:159.10
-1,12,30:159.10
0,12,30:159.10
1,12,30:159.10
2,12,30:159.10
3,12,30:159.10
4,12,30:159.10
5,12,30:159.10
3,13,30:159.10
4,13,30:159.10
-5,-10,31:159.10
-4,-10,31:159.10
-3,-10,31:82.0
-2,-10,31:82.0
-1,-10,31:82.0
-6,-9,31:159.10
-5,-9,31:159.10
-4,-9,31:159.10
-3,-9,31:82.0
-2,-9,31:82.0
-1,-9,31:82.0
0,-9,31:159.10
1,-9,31:159.10
2,-9,31:159.10
-7,-8,31:159.10
-6,-8,31:159.10
-5,-8,31:159.10
-4,-8,31:100.0
-3,-8,31:100.0
-2,-8,31:159.10
-1,-8,31:159.10
0,-8,31:159.10
1,-8,31:159.10
2,-8,31:159.10
3,-8,31:159.10
4,-8,31:159.10
5,-8,31:82.0
-7,-7,31:159.10
-6,-7,31:159.10
-5,-7,31:100.0
-4,-7,31:100.0
-3,-7,31:100.0
-2,-7,31:100.0
-1,-7,31:100.0
0,-7,31:100.0
1,-7,31:100.0
2,-7,31:159.10
3,-7,31:159.10
4,-7,31:82.0
5,-7,31:82.0
6,-7,31:82.0
-8,-6,31:82.0
-7,-6,31:82.0
-6,-6,31:159.10
-5,-6,31:100.0
-4,-6,31:100.0
-3,-6,31:100.0
-2,-6,31:100.0
-1,-6,31:100.0
0,-6,31:100.0
1,-6,31:100.0
2,-6,31:100.0
3,-6,31:100.0
4,-6,31:82.0
5,-6,31:82.0
6,-6,31:82.0
7,-6,31:82.0
-9,-5,31:82.0
-8,-5,31:82.0
-7,-5,31:82.0
-6,-5,31:100.0
-5,-5,31:100.0
-4,-5,31:100.0
-3,-5,31:159.10
-2,-5,31:159.10
-1,-5,31:159.10
0,-5,31:159.10
1,-5,31:159.10
2,-5,31:100.0
3,-5,31:100.0
4,-5,31:100.0
5,-5,31:100.0
6,-5,31:82.0
7,-5,31:82.0
-10,-4,31:159.10
-9,-4,31:82.0
-8,-4,31:82.0
-7,-4,31:100.0
-6,-4,31:100.0
-5,-4,31:100.0
-3,-4,31:159.10
-2,-4,31:159.10
-1,-4,31:159.10
0,-4,31:159.10
1,-4,31:159.10
2,-4,31:159.10
3,-4,31:100.0
4,-4,31:100.0
5,-4,31:82.0
6,-4,31:82.0
7,-4,31:82.0
8,-4,31:159.10
-11,-3,31:159.10
-10,-3,31:159.10
-9,-3,31:159.10
-8,-3,31:100.0
-7,-3,31:100.0
-6,-3,31:100.0
-5,-3,31:159.10
-4,-3,31:159.10
-3,-3,31:159.10
-2,-3,31:159.10
-1,-3,31:100.0
0,-3,31:159.10
1,-3,31:159.10
2,-3,31:100.0
3,-3,31:100.0
4,-3,31:159.10
5,-3,31:100.0
6,-3,31:159.10
7,-3,31:159.10
8,-3,31:159.10
-12,-2,31:159.10
-11,-2,31:159.10
-10,-2,31:159.10
-9,-2,31:100.0
-8,-2,31:100.0
-7,-2,31:100.0
-6,-2,31:100.0
-5,-2,31:159.10
-4,-2,31:159.10
-3,-2,31:159.10
-2,-2,31:100.0
-1,-2,31:100.0
0,-2,31:100.0
1,-2,31:100.0
2,-2,31:100.0
3,-2,31:159.10
4,-2,31:159.10
5,-2,31:100.0
6,-2,31:100.0
7,-2,31:159.10
8,-2,31:159.10
9,-2,31:159.10
-11,-1,31:159.10
-10,-1,31:159.10
-9,-1,31:159.10
-8,-1,31:159.10
-7,-1,31:100.0
-6,-1,31:100.0
-5,-1,31:100.0
-4,-1,31:100.0
-3,-1,31:100.0
-1,-1,31:100.0
0,-1,31:100.0
1,-1,31:100.0
2,-1,31:100.0
3,-1,31:159.10
4,-1,31:159.10
5,-1,31:159.10
6,-1,31:100.0
7,-1,31:159.10
8,-1,31:159.10
9,-1,31:82.0
-12,0,31:159.10
-11,0,31:159.10
-10,0,31:159.10
-9,0,31:100.0
-8,0,31:100.0
-7,0,31:100.0
-6,0,31:159.10
-5,0,31:82.0
-4,0,31:100.0
-3,0,31:100.0
-1,0,31:100.15
0,0,31:100.0
1,0,31:100.0
2,0,31:100.0
3,0,31:159.10
4,0,31:159.10
5,0,31:159.10
6,0,31:100.0
7,0,31:100.0
8,0,31:159.10
9,0,31:82.0
10,0,31:82.0
-11,1,31:159.10
-10,1,31:159.10
-9,1,31:100.0
-8,1,31:100.0
-7,1,31:100.0
-6,1,31:159.10
-5,1,31:82.0
-4,1,31:100.0
-3,1,31:100.0
2,1,31:100.0
3,1,31:100.0
4,1,31:159.10
5,1,31:159.10
6,1,31:159.10
7,1,31:100.0
8,1,31:100.0
9,1,31:82.0
10,1,31:82.0
11,1,31:82.0
-11,2,31:159.10
-10,2,31:159.10
-9,2,31:100.0
-8,2,31:100.0
-7,2,31:100.0
-6,2,31:159.10
-5,2,31:82.0
-4,2,31:100.0
-3,2,31:100.0
1,2,31:100.0
2,2,31:100.0
3,2,31:159.10
4,2,31:159.10
5,2,31:159.10
6,2,31:100.0
7,2,31:100.0
8,2,31:100.0
9,2,31:159.10
10,2,31:159.10
11,2,31:159.10
-11,3,31:159.10
-10,3,31:159.10
-8,3,31:100.0
-7,3,31:100.0
-6,3,31:100.0
-5,3,31:159.10
-4,3,31:100.0
-3,3,31:100.0
-2,3,31:100.0
-1,3,31:100.0
0,3,31:100.0
2,3,31:100.0
3,3,31:159.10
4,3,31:159.10
5,3,31:100.0
6,3,31:100.0
7,3,31:100.0
8,3,31:100.0
9,3,31:159.10
10,3,31:159.10
-11,4,31:159.10
-10,4,31:159.10
-9,4,31:159.10
-8,4,31:100.0
-7,4,31:100.0
-6,4,31:100.0
-5,4,31:159.10
0,4,31:100.0
1,4,31:159.10
2,4,31:100.0
3,4,31:82.0
4,4,31:100.0
5,4,31:100.0
6,4,31:100.0
7,4,31:100.0
8,4,31:159.10
9,4,31:159.10
10,4,31:159.10
-11,5,31:159.10
-10,5,31:82.0
-9,5,31:82.0
-8,5,31:100.0
-7,5,31:100.0
-6,5,31:100.0
-5,5,31:159.10
-4,5,31:100.0
-2,5,31:159.10
-1,5,31:159.10
0,5,31:159.10
1,5,31:159.10
2,5,31:82.0
3,5,31:82.0
4,5,31:100.0
5,5,31:100.0
6,5,31:100.0
7,5,31:159.10
8,5,31:159.10
9,5,31:159.10
-10,6,31:82.0
-9,6,31:82.0
-8,6,31:100.0
-7,6,31:100.0
-6,6,31:100.0
-5,6,31:159.10
-4,6,31:159.10
-3,6,31:159.10
-2,6,31:159.10
-1,6,31:159.10
0,6,31:159.10
1,6,31:159.10
2,6,31:100.0
3,6,31:82.0
4,6,31:100.0
5,6,31:100.0
6,6,31:82.0
7,6,31:159.10
8,6,31:159.10
-10,7,31:82.0
-9,7,31:82.0
-8,7,31:100.0
-7,7,31:100.0
-6,7,31:100.0
-5,7,31:100.0
-4,7,31:100.0
-3,7,31:100.0
-2,7,31:100.0
-1,7,31:100.0
0,7,31:100.0
1,7,31:100.0
2,7,31:100.0
3,7,31:82.0
4,7,31:100.0
5,7,31:100.0
6,7,31:82.0
7,7,31:159.10
-10,8,31:159.10
-9,8,31:159.10
-8,8,31:159.10
-7,8,31:100.0
-6,8,31:100.0
-5,8,31:100.0
-4,8,31:100.0
-3,8,31:100.0
-2,8,31:100.0
-1,8,31:100.0
0,8,31:100.0
1,8,31:100.0
2,8,31:100.0
3,8,31:82.0
4,8,31:100.0
5,8,31:82.0
6,8,31:159.10
7,8,31:159.10
-9,9,31:159.10
-8,9,31:159.10
-7,9,31:100.0
-6,9,31:100.0
-5,9,31:100.0
-4,9,31:100.0
-3,9,31:100.0
-2,9,31:100.0
-1,9,31:100.0
0,9,31:100.0
1,9,31:100.0
2,9,31:100.0
3,9,31:159.10
4,9,31:159.10
5,9,31:159.10
6,9,31:159.10
-8,10,31:159.10
-7,10,31:159.10
-6,10,31:159.10
-5,10,31:159.10
-4,10,31:159.10
