[META]
version=2.0
spawnOnBlockType=2
spawnSunlight=True
spawnDarkness=True
spawnWater=False
spawnLava=False
underFill=False
randomRotation=True
dig=True
tree=False
branch=False
needsFoundation=True
rarity=100
collisionPercentage=20
spawnElevationMin=0
spawnElevationMax=200
spawnInBiome=Custom
[DATA]
3,-6,-6:100.15
4,-6,-6:100.15
8,-2,-6:100.15
-2,-1,-6:100.15
1,-1,-6:100.15
2,-1,-6:100.15
5,-7,-5:100.15
3,-6,-5:100.15
4,-6,-5:100.15
5,-6,-5:100.15
6,-3,-5:100.15
7,-3,-5:100.15
-3,-2,-5:100.15
-2,-2,-5:100.15
-1,-2,-5:100.15
1,-2,-5:100.15
2,-2,-5:100.15
7,-2,-5:100.15
8,-2,-5:100.15
-2,-1,-5:100.15
-1,-1,-5:100.15
1,-1,-5:100.15
7,-1,-5:100.15
-2,0,-5:100.15
1,0,-5:100.15
4,2,-5:100.15
2,-7,-4:100.15
4,-7,-4:100.15
3,-6,-4:100.15
4,-6,-4:100.15
2,-5,-4:100.15
3,-5,-4:100.15
1,-2,-4:100.15
6,-2,-4:100.15
7,-2,-4:100.15
8,-2,-4:100.15
9,-2,-4:100.15
-3,-1,-4:100.15
-2,-1,-4:100.15
0,-1,-4:100.15
1,-1,-4:100.15
2,-1,-4:100.15
3,-1,-4:100.15
7,-1,-4:100.15
8,-1,-4:100.15
5,1,-4:100.15
6,1,-4:100.15
5,2,-4:100.15
4,3,-4:100.15
5,3,-4:100.15
6,3,-4:100.15
2,-7,-3:100.15
3,-7,-3:100.15
2,-6,-3:100.15
3,-6,-3:100.15
4,-6,-3:100.15
1,-5,-3:100.15
3,-5,-3:100.15
-2,-3,-3:100.15
-1,-3,-3:100.15
1,-3,-3:100.15
7,-3,-3:100.15
8,-3,-3:100.15
-3,-2,-3:100.15
-2,-2,-3:100.15
-1,-2,-3:100.15
0,-2,-3:100.15
2,-2,-3:100.15
7,-2,-3:100.15
8,-2,-3:100.15
9,-2,-3:100.15
-3,-1,-3:100.15
-2,-1,-3:100.15
0,-1,-3:100.15
1,-1,-3:100.15
2,-1,-3:100.15
7,-1,-3:100.15
-2,0,-3:100.15
2,0,-3:100.15
4,1,-3:100.15
5,1,-3:100.15
6,1,-3:100.15
4,2,-3:100.15
5,2,-3:100.15
5,3,-3:100.15
4,-7,-2:100.15
2,-6,-2:100.15
3,-6,-2:100.15
4,-6,-2:100.15
1,-5,-2:100.15
2,-5,-2:100.15
3,-5,-2:100.15
4,-5,-2:100.15
1,-4,-2:100.15
2,-4,-2:100.15
3,-4,-2:100.15
-2,-3,-2:100.15
1,-3,-2:100.15
8,-3,-2:100.15
-3,-2,-2:100.15
-2,-2,-2:100.15
-1,-2,-2:100.15
0,-2,-2:100.15
1,-2,-2:100.15
2,-2,-2:100.15
7,-2,-2:100.15
8,-2,-2:100.15
9,-2,-2:100.15
-2,-1,-2:100.15
-1,-1,-2:100.15
0,-1,-2:100.15
1,-1,-2:100.15
2,-1,-2:100.15
7,-1,-2:100.15
8,-1,-2:100.15
9,-1,-2:100.15
1,0,-2:100.15
4,1,-2:100.15
5,1,-2:100.15
6,1,-2:100.15
6,2,-2:100.15
2,-5,-1:100.15
3,-5,-1:100.15
2,-4,-1:100.15
3,-4,-1:100.15
4,-4,-1:100.15
-1,-3,-1:100.15
1,-3,-1:100.15
2,-3,-1:100.15
8,-3,-1:100.15
-3,-2,-1:100.15
-2,-2,-1:100.15
-1,-2,-1:100.15
0,-2,-1:100.15
1,-2,-1:100.15
2,-2,-1:100.15
7,-2,-1:100.15
8,-2,-1:100.15
9,-2,-1:100.15
-2,-1,-1:100.15
-1,-1,-1:100.15
0,-1,-1:100.15
1,-1,-1:100.15
7,-1,-1:100.15
8,-1,-1:100.15
4,0,-1:100.15
5,0,-1:100.15
8,0,-1:100.15
4,1,-1:100.15
5,1,-1:100.15
6,1,-1:100.15
4,2,-1:100.15
5,2,-1:100.15
6,2,-1:100.15
1,-5,0:100.15
2,-5,0:100.15
3,-5,0:100.15
0,-4,0:100.15
1,-4,0:100.15
2,-4,0:100.15
3,-4,0:100.15
-3,-3,0:100.15
-2,-3,0:100.15
-1,-3,0:100.15
0,-3,0:100.15
1,-3,0:100.15
2,-3,0:100.15
3,-3,0:100.15
4,-3,0:100.15
6,-3,0:100.15
7,-3,0:100.15
8,-3,0:100.15
9,-3,0:100.15
-3,-2,0:100.15
-2,-2,0:100.15
-1,-2,0:100.15
0,-2,0:100.15
1,-2,0:100.15
2,-2,0:100.15
3,-2,0:100.15
4,-2,0:100.15
5,-2,0:100.15
6,-2,0:100.15
7,-2,0:100.15
8,-2,0:100.15
9,-2,0:100.15
-3,-1,0:100.15
-2,-1,0:100.15
-1,-1,0:100.15
0,-1,0:100.15
1,-1,0:100.15
2,-1,0:100.15
3,-1,0:100.15
4,-1,0:100.15
6,-1,0:100.15
7,-1,0:100.15
8,-1,0:100.15
9,-1,0:100.15
-2,0,0:100.15
-1,0,0:100.15
1,0,0:100.15
2,0,0:100.15
3,0,0:100.15
5,0,0:100.15
6,0,0:100.15
7,0,0:100.15
8,0,0:100.15
9,0,0:100.15
4,1,0:100.15
5,1,0:100.15
6,1,0:100.15
4,2,0:100.15
5,2,0:100.15
6,2,0:100.15
0,-4,1:100.15
1,-4,1:100.15
2,-4,1:100.15
3,-4,1:100.15
-3,-3,1:100.15
-2,-3,1:100.15
0,-3,1:100.15
1,-3,1:100.15
3,-3,1:100.15
6,-3,1:100.15
7,-3,1:100.15
8,-3,1:100.15
9,-3,1:100.15
-3,-2,1:100.15
-2,-2,1:100.15
-1,-2,1:100.15
0,-2,1:100.15
1,-2,1:100.15
4,-2,1:100.15
6,-2,1:100.15
9,-2,1:100.15
-2,-1,1:100.15
0,-1,1:100.15
1,-1,1:100.15
2,-1,1:100.15
3,-1,1:100.15
6,-1,1:100.15
8,-1,1:100.15
9,-1,1:100.15
2,0,1:100.15
3,0,1:100.15
4,0,1:100.15
5,0,1:100.15
6,0,1:100.15
7,0,1:100.15
8,0,1:100.15
9,0,1:100.15
4,1,1:100.15
5,1,1:100.15
6,1,1:100.15
4,2,1:100.15
5,2,1:100.15
6,2,1:100.15
1,-4,2:100.15
2,-4,2:100.15
3,-4,2:100.15
-3,-3,2:100.15
-2,-3,2:100.15
0,-3,2:100.15
3,-3,2:100.15
6,-3,2:100.15
7,-3,2:100.15
8,-3,2:100.15
9,-3,2:100.15
-3,-2,2:100.15
-2,-2,2:100.15
0,-2,2:100.15
4,-2,2:100.15
6,-2,2:100.15
9,-2,2:100.15
0,-1,2:100.15
1,-1,2:100.15
2,-1,2:100.15
3,-1,2:100.15
6,-1,2:100.15
9,-1,2:100.15
2,0,2:100.15
3,0,2:100.15
4,0,2:100.15
5,0,2:100.15
6,0,2:100.15
7,0,2:100.15
8,0,2:100.15
4,1,2:100.15
5,1,2:100.15
6,1,2:100.15
4,2,2:100.15
5,2,2:100.15
1,-4,3:100.15
2,-4,3:100.15
3,-4,3:100.15
-4,-3,3:100.0
-3,-3,3:100.15
-2,-3,3:100.15
0,-3,3:100.15
1,-3,3:100.15
3,-3,3:100.15
6,-3,3:100.15
7,-3,3:100.15
8,-3,3:100.15
-3,-2,3:100.15
-2,-2,3:100.15
0,-2,3:100.15
4,-2,3:100.15
6,-2,3:100.15
8,-2,3:100.15
9,-2,3:100.15
1,-1,3:100.15
3,-1,3:100.15
4,-1,3:100.15
6,-1,3:100.15
8,-1,3:100.15
9,-1,3:100.15
2,0,3:100.15
3,0,3:100.15
6,0,3:100.15
7,0,3:100.15
8,0,3:100.15
4,1,3:100.15
5,1,3:100.15
4,2,3:100.15
5,2,3:100.15
2,-4,4:100.15
-4,-3,4:159.10
-3,-3,4:100.15
1,-3,4:100.15
2,-3,4:100.15
3,-3,4:100.15
6,-3,4:100.15
7,-3,4:100.15
8,-3,4:100.15
-4,-2,4:100.0
-3,-2,4:100.15
-2,-2,4:100.15
-1,-2,4:100.0
0,-2,4:100.15
4,-2,4:100.15
6,-2,4:100.15
8,-2,4:100.15
-2,-1,4:100.0
1,-1,4:100.15
3,-1,4:100.15
4,-1,4:100.15
6,-1,4:100.15
8,-1,4:100.15
2,0,4:100.15
3,0,4:100.15
7,0,4:100.15
8,0,4:100.15
4,1,4:100.15
5,1,4:100.15
4,2,4:100.15
-3,-4,5:100.0
-5,-3,5:100.0
-4,-3,5:100.0
-3,-3,5:100.15
1,-3,5:100.15
2,-3,5:100.15
3,-3,5:100.15
6,-3,5:100.15
7,-3,5:100.15
8,-3,5:100.15
-5,-2,5:100.0
-4,-2,5:159.10
-3,-2,5:100.15
-2,-2,5:100.15
-1,-2,5:159.10
0,-2,5:100.15
1,-2,5:100.15
3,-2,5:100.15
4,-2,5:100.15
6,-2,5:100.15
8,-2,5:100.15
-4,-1,5:100.0
-3,-1,5:100.0
-2,-1,5:159.10
-1,-1,5:100.0
1,-1,5:100.15
3,-1,5:100.15
4,-1,5:100.15
6,-1,5:100.15
7,-1,5:100.15
8,-1,5:100.15
-2,0,5:100.0
2,0,5:100.15
3,0,5:100.15
4,1,5:100.15
5,1,5:100.15
4,2,5:100.15
-3,-4,6:159.10
-2,-4,6:100.0
-1,-4,6:100.0
-5,-3,6:159.10
-4,-3,6:159.10
-3,-3,6:159.10
-2,-3,6:100.0
0,-3,6:100.0
1,-3,6:100.15
2,-3,6:100.15
3,-3,6:100.15
6,-3,6:100.15
7,-3,6:100.15
-5,-2,6:159.10
-4,-2,6:159.10
-3,-2,6:100.15
-2,-2,6:159.10
-1,-2,6:159.10
1,-2,6:100.15
3,-2,6:100.15
4,-2,6:100.15
6,-2,6:100.15
8,-2,6:100.15
-4,-1,6:159.10
-3,-1,6:159.10
-1,-1,6:159.10
0,-1,6:100.0
1,-1,6:100.15
3,-1,6:100.15
4,-1,6:100.15
6,-1,6:100.15
7,-1,6:100.15
8,-1,6:100.15
-2,0,6:159.10
0,0,6:100.0
1,0,6:100.0
2,0,6:100.15
3,0,6:100.15
-1,1,6:100.0
2,1,6:100.0
3,1,6:100.0
4,1,6:159.10
5,1,6:100.15
6,1,6:100.0
2,2,6:100.0
3,2,6:100.0
4,2,6:159.10
5,2,6:100.0
3,3,6:100.0
4,3,6:100.0
-2,-4,7:159.10
-1,-4,7:159.10
-3,-3,7:159.10
-2,-3,7:159.10
-1,-3,7:100.0
0,-3,7:159.10
1,-3,7:100.15
2,-3,7:100.15
3,-3,7:100.15
7,-3,7:100.15
-3,-2,7:82.0
-2,-2,7:159.10
-1,-2,7:159.10
0,-2,7:100.0
1,-2,7:100.15
3,-2,7:100.15
6,-2,7:100.15
8,-2,7:100.15
-3,-1,7:82.0
-2,-1,7:100.0
-1,-1,7:159.10
0,-1,7:159.10
1,-1,7:100.15
2,-1,7:100.15
3,-1,7:100.15
5,-1,7:100.0
6,-1,7:100.15
7,-1,7:100.15
8,-1,7:100.15
-2,0,7:159.10
-1,0,7:100.0
0,0,7:159.10
1,0,7:159.10
2,0,7:100.15
3,0,7:159.10
4,0,7:100.0
-1,1,7:159.10
2,1,7:159.10
3,1,7:82.0
4,1,7:159.10
5,1,7:159.10
6,1,7:159.10
7,1,7:100.0
8,1,7:100.0
2,2,7:82.0
3,2,7:82.0
4,2,7:82.0
5,2,7:159.10
6,2,7:100.0
8,2,7:100.0
3,3,7:82.0
4,3,7:159.10
5,3,7:100.0
6,3,7:100.0
7,3,7:100.0
-2,-3,8:159.10
-1,-3,8:159.10
1,-3,8:100.15
2,-3,8:100.15
3,-3,8:100.15
7,-3,8:100.15
-3,-2,8:82.0
-2,-2,8:82.0
-1,-2,8:159.10
0,-2,8:159.10
1,-2,8:100.15
2,-2,8:100.0
3,-2,8:100.15
4,-2,8:100.0
5,-2,8:100.0
6,-2,8:100.15
7,-2,8:100.15
8,-2,8:100.15
-3,-1,8:82.0
-2,-1,8:82.0
-1,-1,8:159.10
0,-1,8:159.10
1,-1,8:100.15
2,-1,8:100.15
3,-1,8:100.15
5,-1,8:159.10
6,-1,8:100.15
7,-1,8:100.15
8,-1,8:100.15
-1,0,8:159.10
4,0,8:159.10
5,0,8:100.0
6,0,8:100.0
7,0,8:100.0
8,0,8:100.0
3,1,8:82.0
4,1,8:82.0
5,1,8:159.10
6,1,8:159.10
7,1,8:159.10
8,1,8:159.10
3,2,8:82.0
4,2,8:82.0
5,2,8:159.10
6,2,8:159.10
7,2,8:100.0
8,2,8:159.10
4,3,8:100.0
5,3,8:159.10
6,3,8:159.10
7,3,8:159.10
1,-3,9:100.15
2,-3,9:100.15
3,-3,9:100.15
-2,-2,9:159.10
-1,-2,9:159.10
0,-2,9:159.10
1,-2,9:100.15
2,-2,9:159.10
3,-2,9:100.15
4,-2,9:159.10
5,-2,9:159.10
6,-2,9:100.15
7,-2,9:100.15
8,-2,9:100.15
1,-1,9:100.15
2,-1,9:100.15
3,-1,9:100.15
6,-1,9:100.15
7,-1,9:100.15
8,-1,9:159.10
4,0,9:159.10
5,0,9:159.10
6,0,9:159.10
7,0,9:159.10
8,0,9:159.10
4,1,9:159.10
5,1,9:159.10
6,1,9:159.10
7,1,9:159.10
4,2,9:82.0
5,2,9:159.10
6,2,9:159.10
7,2,9:159.10
4,3,9:159.10
1,-3,10:100.15
3,-3,10:100.15
1,-2,10:100.15
3,-2,10:100.15
7,-2,10:100.15
8,-2,10:100.15
1,-1,10:100.15
3,-1,10:100.15
7,-1,10:100.15
9,-5,11:100.0
10,-5,11:100.0
9,-4,11:100.0
1,-3,11:100.15
1,-2,11:100.15
3,-2,11:100.15
7,-2,11:100.15
8,-2,11:100.15
1,-1,11:100.15
2,-1,11:100.15
3,-1,11:100.15
7,-1,11:100.15
8,0,11:100.0
7,-11,12:100.0
4,-10,12:100.0
5,-10,12:100.0
6,-10,12:100.0
7,-10,12:100.0
8,-10,12:100.0
9,-10,12:100.0
10,-10,12:100.0
11,-10,12:100.0
12,-10,12:100.0
13,-10,12:100.0
3,-9,12:100.0
4,-9,12:100.0
6,-9,12:100.0
9,-9,12:100.0
10,-9,12:100.0
11,-9,12:100.0
12,-9,12:100.0
13,-9,12:100.0
14,-9,12:100.0
3,-8,12:100.0
5,-8,12:100.0
12,-8,12:100.0
14,-8,12:100.0
15,-8,12:100.0
4,-7,12:100.0
11,-7,12:100.0
15,-7,12:100.0
4,-6,12:100.0
10,-6,12:100.0
11,-6,12:100.0
15,-6,12:100.0
16,-6,12:100.0
9,-5,12:159.10
10,-5,12:159.10
17,-5,12:100.0
9,-4,12:159.10
17,-4,12:100.0
1,-3,12:100.15
2,-3,12:100.15
4,-3,12:100.0
8,-3,12:100.0
9,-3,12:100.0
1,-2,12:100.15
2,-2,12:100.0
3,-2,12:100.15
7,-2,12:100.15
8,-2,12:159.10
1,-1,12:100.0
2,-1,12:100.15
4,-1,12:100.0
7,-1,12:100.15
8,-1,12:100.0
0,0,12:100.0
1,0,12:100.0
4,0,12:100.0
8,0,12:159.10
9,0,12:100.0
0,1,12:100.0
1,1,12:100.0
9,1,12:100.0
17,1,12:100.0
1,2,12:100.0
2,2,12:100.0
10,2,12:100.0
16,2,12:100.0
1,3,12:100.0
2,3,12:100.0
10,3,12:100.0
15,3,12:100.0
16,3,12:100.0
2,4,12:100.0
10,4,12:100.0
11,4,12:100.0
14,4,12:100.0
15,4,12:100.0
2,5,12:100.0
3,5,12:100.0
11,5,12:100.0
13,5,12:100.0
14,5,12:100.0
3,6,12:100.0
4,6,12:100.0
7,6,12:100.0
12,6,12:100.0
13,6,12:100.0
9,7,12:100.0
10,7,12:100.0
11,7,12:100.0
12,7,12:100.0
13,7,12:100.0
9,-14,13:100.0
8,-13,13:100.0
7,-12,13:100.0
8,-12,13:100.0
7,-11,13:159.10
4,-10,13:159.10
5,-10,13:159.10
6,-10,13:159.10
7,-10,13:159.10
8,-10,13:159.10
9,-10,13:159.10
10,-10,13:159.10
11,-10,13:159.10
12,-10,13:159.10
13,-10,13:159.10
3,-9,13:159.10
4,-9,13:159.10
5,-9,13:100.0
6,-9,13:159.10
7,-9,13:100.0
8,-9,13:100.0
9,-9,13:159.10
10,-9,13:159.10
11,-9,13:159.10
12,-9,13:159.10
13,-9,13:159.10
14,-9,13:159.10
3,-8,13:159.10
4,-8,13:100.0
5,-8,13:159.10
6,-8,13:100.0
8,-8,13:100.0
9,-8,13:100.0
10,-8,13:100.0
11,-8,13:100.0
12,-8,13:159.10
13,-8,13:100.0
14,-8,13:159.10
15,-8,13:159.10
4,-7,13:159.10
5,-7,13:100.0
6,-7,13:100.0
7,-7,13:100.0
8,-7,13:100.0
9,-7,13:100.0
11,-7,13:159.10
12,-7,13:100.0
13,-7,13:100.0
14,-7,13:100.0
15,-7,13:159.10
3,-6,13:100.0
4,-6,13:159.10
5,-6,13:100.0
6,-6,13:100.0
10,-6,13:159.10
11,-6,13:159.10
12,-6,13:100.0
13,-6,13:100.0
14,-6,13:100.0
15,-6,13:159.10
16,-6,13:159.10
4,-5,13:100.0
5,-5,13:100.0
10,-5,13:159.10
13,-5,13:100.0
14,-5,13:100.0
15,-5,13:100.0
17,-5,13:159.10
2,-4,13:100.0
3,-4,13:100.0
4,-4,13:100.0
5,-4,13:100.0
7,-4,13:100.0
8,-4,13:100.0
9,-4,13:159.10
14,-4,13:100.0
15,-4,13:100.0
16,-4,13:100.0
17,-4,13:159.10
2,-3,13:159.10
3,-3,13:100.0
4,-3,13:159.10
6,-3,13:100.0
7,-3,13:100.0
8,-3,13:159.10
9,-3,13:159.10
10,-3,13:100.0
11,-3,13:100.0
15,-3,13:100.0
16,-3,13:100.0
17,-3,13:100.0
0,-2,13:100.0
2,-2,13:159.10
4,-2,13:100.0
5,-2,13:100.0
7,-2,13:100.15
8,-2,13:159.10
16,-2,13:100.0
17,-2,13:100.0
1,-1,13:159.10
2,-1,13:159.10
3,-1,13:100.0
4,-1,13:159.10
6,-1,13:100.0
7,-1,13:100.15
8,-1,13:159.10
16,-1,13:100.0
17,-1,13:100.0
0,0,13:159.10
1,0,13:159.10
2,0,13:100.0
3,0,13:100.0
4,0,13:159.10
6,0,13:100.0
7,0,13:100.0
9,0,13:159.10
15,0,13:100.0
16,0,13:100.0
17,0,13:100.0
0,1,13:159.10
1,1,13:159.10
2,1,13:100.0
3,1,13:100.0
4,1,13:100.0
5,1,13:100.0
9,1,13:159.10
14,1,13:100.0
15,1,13:100.0
16,1,13:100.0
17,1,13:159.10
1,2,13:159.10
2,2,13:159.10
3,2,13:100.0
4,2,13:100.0
5,2,13:100.0
10,2,13:159.10
13,2,13:100.0
14,2,13:100.0
15,2,13:100.0
16,2,13:159.10
1,3,13:159.10
2,3,13:159.10
3,3,13:100.0
4,3,13:100.0
5,3,13:100.0
6,3,13:100.0
7,3,13:100.0
8,3,13:100.0
10,3,13:159.10
12,3,13:100.0
13,3,13:100.0
14,3,13:100.0
15,3,13:159.10
16,3,13:159.10
2,4,13:159.10
3,4,13:100.0
4,4,13:100.0
5,4,13:100.0
6,4,13:100.0
7,4,13:100.0
8,4,13:100.0
9,4,13:100.0
10,4,13:159.10
11,4,13:159.10
12,4,13:100.0
13,4,13:100.0
14,4,13:159.10
15,4,13:159.10
2,5,13:159.10
3,5,13:159.10
4,5,13:100.0
5,5,13:100.0
6,5,13:100.0
7,5,13:100.0
8,5,13:100.0
9,5,13:100.0
10,5,13:100.0
11,5,13:82.0
12,5,13:100.0
13,5,13:159.10
14,5,13:159.10
3,6,13:159.10
4,6,13:159.10
5,6,13:100.0
6,6,13:100.0
7,6,13:159.10
8,6,13:100.0
9,6,13:100.0
10,6,13:100.0
11,6,13:100.0
12,6,13:82.0
13,6,13:159.10
5,7,13:100.0
6,7,13:100.0
7,7,13:100.0
8,7,13:100.0
9,7,13:159.10
10,7,13:159.10
11,7,13:82.0
12,7,13:159.10
13,7,13:159.10
6,8,13:100.0
7,8,13:100.0
8,8,13:100.0
5,9,13:100.0
6,9,13:100.0
7,9,13:100.0
3,-15,14:100.0
4,-15,14:100.0
5,-15,14:100.0
7,-14,14:100.0
8,-14,14:100.0
9,-14,14:159.10
8,-13,14:159.10
9,-13,14:100.0
7,-12,14:159.10
8,-12,14:159.10
10,-12,14:100.0
7,-11,14:159.10
10,-11,14:100.0
11,-11,14:100.0
6,-10,14:159.10
10,-10,14:100.0
11,-10,14:100.0
-9,-9,14:100.0
5,-9,14:159.10
6,-9,14:159.10
7,-9,14:159.10
8,-9,14:159.10
11,-9,14:100.0
-10,-8,14:100.0
4,-8,14:159.10
5,-8,14:159.10
6,-8,14:159.10
8,-8,14:159.10
9,-8,14:159.10
10,-8,14:159.10
11,-8,14:159.10
12,-8,14:159.10
13,-8,14:159.10
-10,-7,14:100.0
4,-7,14:159.10
5,-7,14:159.10
6,-7,14:159.10
7,-7,14:159.10
8,-7,14:159.10
9,-7,14:159.10
11,-7,14:159.10
12,-7,14:159.10
13,-7,14:159.10
14,-7,14:159.10
-11,-6,14:100.0
3,-6,14:159.10
4,-6,14:159.10
5,-6,14:159.10
6,-6,14:159.10
7,-6,14:100.0
8,-6,14:100.0
9,-6,14:100.0
10,-6,14:159.10
11,-6,14:159.10
12,-6,14:159.10
13,-6,14:159.10
14,-6,14:159.10
-12,-5,14:100.0
-11,-5,14:100.0
3,-5,14:100.0
4,-5,14:159.10
5,-5,14:159.10
6,-5,14:100.0
7,-5,14:100.0
8,-5,14:100.0
9,-5,14:100.0
10,-5,14:159.10
11,-5,14:100.0
12,-5,14:100.0
13,-5,14:159.10
14,-5,14:159.10
15,-5,14:159.10
-12,-4,14:100.0
2,-4,14:159.10
3,-4,14:159.10
4,-4,14:159.10
5,-4,14:159.10
6,-4,14:100.0
7,-4,14:159.10
8,-4,14:159.10
9,-4,14:159.10
12,-4,14:100.0
13,-4,14:100.0
14,-4,14:82.0
15,-4,14:82.0
16,-4,14:82.0
-11,-3,14:100.0
-2,-3,14:100.0
0,-3,14:100.0
1,-3,14:100.15
2,-3,14:159.10
3,-3,14:159.10
4,-3,14:100.0
5,-3,14:100.0
6,-3,14:159.10
7,-3,14:159.10
8,-3,14:159.10
9,-3,14:159.10
10,-3,14:159.10
11,-3,14:159.10
12,-3,14:100.0
13,-3,14:100.0
14,-3,14:100.0
15,-3,14:82.0
16,-3,14:82.0
17,-3,14:82.0
-11,-2,14:100.0
0,-2,14:159.10
1,-2,14:100.0
2,-2,14:159.10
4,-2,14:159.10
5,-2,14:159.10
6,-2,14:100.0
7,-2,14:159.10
8,-2,14:159.10
9,-2,14:100.0
10,-2,14:100.0
11,-2,14:100.0
12,-2,14:100.0
13,-2,14:100.0
14,-2,14:100.0
15,-2,14:100.0
16,-2,14:82.0
17,-2,14:82.0
-11,-1,14:100.0
-10,-1,14:100.0
2,-1,14:159.10
3,-1,14:159.10
5,-1,14:100.0
6,-1,14:159.10
7,-1,14:159.10
8,-1,14:159.10
9,-1,14:100.0
10,-1,14:100.0
11,-1,14:100.0
12,-1,14:100.0
13,-1,14:100.0
14,-1,14:100.0
15,-1,14:100.0
16,-1,14:82.0
17,-1,14:82.0
-10,0,14:100.0
2,0,14:159.10
3,0,14:159.10
5,0,14:100.0
6,0,14:159.10
7,0,14:159.10
8,0,14:100.0
9,0,14:159.10
10,0,14:100.0
11,0,14:100.0
12,0,14:100.0
13,0,14:100.0
14,0,14:100.0
15,0,14:82.0
16,0,14:82.0
17,0,14:159.10
-10,1,14:100.0
-9,1,14:100.0
2,1,14:159.10
3,1,14:159.10
4,1,14:159.10
5,1,14:159.10
6,1,14:100.0
7,1,14:100.0
8,1,14:100.0
9,1,14:159.10
10,1,14:100.0
11,1,14:100.0
12,1,14:100.0
13,1,14:100.0
14,1,14:159.10
15,1,14:159.10
16,1,14:159.10
-9,2,14:100.0
-8,2,14:100.0
3,2,14:159.10
4,2,14:159.10
5,2,14:159.10
6,2,14:100.0
7,2,14:100.0
8,2,14:100.0
10,2,14:159.10
11,2,14:100.0
12,2,14:100.0
13,2,14:159.10
14,2,14:159.10
15,2,14:159.10
-9,3,14:100.0
-8,3,14:100.0
3,3,14:159.10
4,3,14:159.10
5,3,14:159.10
6,3,14:159.10
7,3,14:159.10
8,3,14:159.10
9,3,14:100.0
10,3,14:159.10
11,3,14:100.0
12,3,14:159.10
13,3,14:159.10
14,3,14:159.10
-8,4,14:100.0
-7,4,14:100.0
1,4,14:100.0
2,4,14:100.0
3,4,14:159.10
4,4,14:159.10
5,4,14:159.10
6,4,14:159.10
7,4,14:159.10
8,4,14:159.10
9,4,14:159.10
10,4,14:159.10
11,4,14:159.10
12,4,14:159.10
13,4,14:159.10
-8,5,14:100.0
-7,5,14:100.0
4,5,14:159.10
5,5,14:159.10
6,5,14:159.10
7,5,14:159.10
8,5,14:159.10
9,5,14:159.10
10,5,14:82.0
11,5,14:82.0
12,5,14:82.0
-7,6,14:100.0
-6,6,14:100.0
5,6,14:159.10
6,6,14:159.10
7,6,14:100.0
8,6,14:159.10
9,6,14:159.10
10,6,14:82.0
11,6,14:82.0
-6,7,14:100.0
-5,7,14:100.0
-4,7,14:100.0
-3,7,14:100.0
-2,7,14:100.0
-1,7,14:100.0
0,7,14:100.0
1,7,14:100.0
2,7,14:100.0
3,7,14:100.0
4,7,14:100.0
5,7,14:159.10
6,7,14:82.0
7,7,14:159.10
8,7,14:159.10
-4,8,14:100.0
-3,8,14:100.0
-2,8,14:100.0
-1,8,14:100.0
0,8,14:100.0
1,8,14:100.0
2,8,14:100.0
3,8,14:100.0
4,8,14:100.0
5,8,14:100.0
6,8,14:82.0
7,8,14:82.0
8,8,14:159.10
5,9,14:159.10
6,9,14:82.0
7,9,14:159.10
-4,-15,15:100.0
-3,-15,15:100.0
-2,-15,15:100.0
-1,-15,15:100.0
0,-15,15:100.0
1,-15,15:100.0
2,-15,15:100.0
3,-15,15:159.10
4,-15,15:159.10
5,-15,15:159.10
-5,-14,15:100.0
-4,-14,15:100.0
-3,-14,15:100.0
-2,-14,15:100.0
-1,-14,15:100.0
0,-14,15:100.0
1,-14,15:100.0
2,-14,15:100.0
3,-14,15:100.0
4,-14,15:100.0
5,-14,15:100.0
6,-14,15:100.0
7,-14,15:159.10
8,-14,15:159.10
9,-14,15:159.10
-6,-13,15:100.0
-5,-13,15:100.0
0,-13,15:100.0
1,-13,15:100.0
2,-13,15:100.0
3,-13,15:100.0
4,-13,15:100.0
5,-13,15:100.0
6,-13,15:100.0
7,-13,15:100.0
8,-13,15:159.10
9,-13,15:159.10
-7,-12,15:100.0
-6,-12,15:100.0
-5,-12,15:100.0
4,-12,15:100.0
5,-12,15:100.0
6,-12,15:100.0
7,-12,15:159.10
8,-12,15:159.10
9,-12,15:100.0
10,-12,15:159.10
-8,-11,15:100.0
-7,-11,15:100.0
-6,-11,15:100.0
7,-11,15:159.10
8,-11,15:100.0
9,-11,15:100.0
10,-11,15:159.10
11,-11,15:159.10
-8,-10,15:100.0
-7,-10,15:100.0
-6,-10,15:100.0
-2,-10,15:100.0
-1,-10,15:100.0
6,-10,15:159.10
8,-10,15:100.0
9,-10,15:100.0
10,-10,15:159.10
11,-10,15:159.10
-9,-9,15:159.10
-8,-9,15:100.0
-7,-9,15:100.0
-2,-9,15:100.0
-1,-9,15:100.0
0,-9,15:100.0
1,-9,15:100.0
2,-9,15:100.0
3,-9,15:100.0
5,-9,15:159.10
6,-9,15:159.10
8,-9,15:159.10
9,-9,15:100.0
10,-9,15:100.0
11,-9,15:159.10
-10,-8,15:159.10
-9,-8,15:100.0
-8,-8,15:100.0
-7,-8,15:100.0
-3,-8,15:100.0
-2,-8,15:100.0
1,-8,15:100.0
2,-8,15:100.0
3,-8,15:100.0
4,-8,15:100.0
5,-8,15:159.10
9,-8,15:159.10
10,-8,15:159.10
11,-8,15:159.10
12,-8,15:159.10
-10,-7,15:159.10
-9,-7,15:100.0
-8,-7,15:100.0
-3,-7,15:100.0
-2,-7,15:100.0
3,-7,15:100.0
4,-7,15:159.10
5,-7,15:159.10
6,-7,15:159.10
9,-7,15:159.10
11,-7,15:159.10
12,-7,15:159.10
-11,-6,15:159.10
-10,-6,15:100.0
-9,-6,15:100.0
-8,-6,15:100.0
-4,-6,15:100.0
4,-6,15:159.10
5,-6,15:159.10
6,-6,15:159.10
7,-6,15:159.10
8,-6,15:159.10
9,-6,15:159.10
10,-6,15:159.10
11,-6,15:159.10
12,-6,15:159.10
13,-6,15:159.10
-12,-5,15:159.10
-11,-5,15:159.10
-10,-5,15:100.0
-9,-5,15:100.0
-4,-5,15:100.0
-3,-5,15:100.0
3,-5,15:159.10
5,-5,15:159.10
6,-5,15:159.10
7,-5,15:159.10
8,-5,15:159.10
9,-5,15:159.10
10,-5,15:159.10
11,-5,15:159.10
12,-5,15:159.10
13,-5,15:159.10
-12,-4,15:159.10
-11,-4,15:100.0
-10,-4,15:100.0
-9,-4,15:100.0
-8,-4,15:100.0
-5,-4,15:100.0
-4,-4,15:100.0
-3,-4,15:100.0
4,-4,15:159.10
5,-4,15:159.10
6,-4,15:159.10
9,-4,15:159.10
10,-4,15:100.0
11,-4,15:100.0
12,-4,15:159.10
13,-4,15:159.10
-12,-3,15:159.10
-11,-3,15:159.10
-10,-3,15:100.0
-9,-3,15:100.0
-7,-3,15:100.0
-6,-3,15:100.0
-5,-3,15:100.0
-4,-3,15:100.0
-3,-3,15:100.0
-2,-3,15:159.10
-1,-3,15:100.0
0,-3,15:159.10
1,-3,15:159.10
2,-3,15:159.10
4,-3,15:159.10
5,-3,15:159.10
6,-3,15:100.0
8,-3,15:159.10
11,-3,15:100.0
12,-3,15:159.10
13,-3,15:82.0
14,-3,15:82.0
-11,-2,15:159.10
-10,-2,15:100.0
-9,-2,15:100.0
-8,-2,15:100.0
-4,-2,15:100.0
-3,-2,15:100.0
-2,-2,15:100.0
1,-2,15:159.10
2,-2,15:159.10
4,-2,15:159.10
5,-2,15:159.10
6,-2,15:159.10
7,-2,15:159.10
8,-2,15:159.10
9,-2,15:159.10
10,-2,15:159.10
11,-2,15:159.10
12,-2,15:159.10
13,-2,15:82.0
14,-2,15:82.0
15,-2,15:82.0
-11,-1,15:159.10
-10,-1,15:159.10
-9,-1,15:100.0
-8,-1,15:100.0
-3,-1,15:100.0
-2,-1,15:100.0
3,-1,15:100.0
4,-1,15:100.0
5,-1,15:159.10
6,-1,15:100.0
8,-1,15:159.10
9,-1,15:159.10
10,-1,15:159.10
11,-1,15:159.10
12,-1,15:159.10
13,-1,15:82.0
14,-1,15:82.0
15,-1,15:82.0
-10,0,15:159.10
-9,0,15:100.0
-8,0,15:100.0
-7,0,15:100.0
-3,0,15:100.0
-2,0,15:100.0
-1,0,15:100.0
0,0,15:100.0
1,0,15:100.0
2,0,15:100.0
3,0,15:159.10
4,0,15:100.0
5,0,15:159.10
8,0,15:159.10
9,0,15:159.10
10,0,15:159.10
11,0,15:159.10
12,0,15:159.10
13,0,15:159.10
14,0,15:82.0
15,0,15:100.0
-10,1,15:159.10
-9,1,15:159.10
-8,1,15:100.0
-7,1,15:100.0
-6,1,15:100.0
-2,1,15:100.0
-1,1,15:100.0
0,1,15:100.0
1,1,15:100.0
2,1,15:100.0
3,1,15:159.10
4,1,15:159.10
5,1,15:159.10
6,1,15:159.10
7,1,15:159.10
8,1,15:159.10
9,1,15:159.10
10,1,15:159.10
11,1,15:159.10
12,1,15:159.10
13,1,15:159.10
-9,2,15:159.10
-8,2,15:159.10
-7,2,15:100.0
-6,2,15:100.0
-2,2,15:100.0
-1,2,15:100.0
1,2,15:100.0
2,2,15:100.0
3,2,15:100.0
4,2,15:159.10
5,2,15:159.10
6,2,15:159.10
7,2,15:159.10
8,2,15:159.10
10,2,15:159.10
11,2,15:159.10
12,2,15:159.10
-9,3,15:159.10
-8,3,15:159.10
-7,3,15:100.0
-6,3,15:100.0
-5,3,15:100.0
3,3,15:159.10
4,3,15:159.10
5,3,15:159.10
6,3,15:159.10
7,3,15:159.10
8,3,15:159.10
9,3,15:159.10
10,3,15:159.10
11,3,15:159.10
-8,4,15:159.10
-7,4,15:159.10
-6,4,15:100.0
-5,4,15:100.0
-3,4,15:100.0
-2,4,15:100.0
-1,4,15:100.0
0,4,15:100.0
1,4,15:159.10
2,4,15:159.10
3,4,15:159.10
4,4,15:159.10
5,4,15:159.10
6,4,15:159.10
7,4,15:159.10
8,4,15:159.10
9,4,15:159.10
10,4,15:159.10
-8,5,15:159.10
-7,5,15:159.10
-6,5,15:100.0
-5,5,15:100.0
-4,5,15:100.0
-3,5,15:100.0
-2,5,15:100.0
-1,5,15:100.0
0,5,15:100.0
1,5,15:100.0
2,5,15:100.0
3,5,15:100.0
4,5,15:159.10
5,5,15:159.10
6,5,15:159.10
7,5,15:159.10
8,5,15:159.10
9,5,15:159.10
10,5,15:159.10
11,5,15:82.0
-7,6,15:159.10
-6,6,15:159.10
-5,6,15:100.0
-4,6,15:100.0
-3,6,15:100.0
-2,6,15:100.0
-1,6,15:100.0
0,6,15:100.0
1,6,15:100.0
2,6,15:100.0
3,6,15:100.0
4,6,15:100.0
5,6,15:159.10
6,6,15:159.10
7,6,15:159.10
8,6,15:159.10
-6,7,15:159.10
-5,7,15:159.10
-4,7,15:159.10
-3,7,15:82.0
-2,7,15:82.0
-1,7,15:82.0
0,7,15:159.10
1,7,15:159.10
2,7,15:159.10
3,7,15:159.10
4,7,15:159.10
5,7,15:82.0
6,7,15:82.0
7,7,15:82.0
-4,8,15:159.10
-3,8,15:159.10
-2,8,15:159.10
-1,8,15:159.10
0,8,15:159.10
1,8,15:159.10
2,8,15:159.10
3,8,15:159.10
4,8,15:159.10
5,8,15:82.0
6,8,15:82.0
-4,-15,16:159.10
-3,-15,16:159.10
-2,-15,16:159.10
-1,-15,16:159.10
0,-15,16:159.10
1,-15,16:159.10
2,-15,16:159.10
-5,-14,16:159.10
-4,-14,16:159.10
-3,-14,16:159.10
-2,-14,16:159.10
-1,-14,16:159.10
0,-14,16:159.10
1,-14,16:159.10
2,-14,16:159.10
3,-14,16:159.10
4,-14,16:159.10
5,-14,16:159.10
6,-14,16:159.10
-6,-13,16:159.10
-5,-13,16:82.0
-4,-13,16:100.0
-3,-13,16:100.0
-2,-13,16:100.0
-1,-13,16:100.0
0,-13,16:159.10
1,-13,16:159.10
2,-13,16:159.10
3,-13,16:159.10
4,-13,16:159.10
5,-13,16:159.10
6,-13,16:159.10
7,-13,16:159.10
8,-13,16:159.10
-7,-12,16:159.10
-6,-12,16:82.0
-5,-12,16:82.0
-4,-12,16:100.0
-3,-12,16:100.0
-2,-12,16:100.0
-1,-12,16:100.0
0,-12,16:100.0
1,-12,16:100.0
2,-12,16:100.0
3,-12,16:100.0
4,-12,16:159.10
5,-12,16:159.10
6,-12,16:159.10
7,-12,16:159.10
8,-12,16:159.10
9,-12,16:159.10
-8,-11,16:159.10
-7,-11,16:159.10
-6,-11,16:82.0
-5,-11,16:100.0
-4,-11,16:100.0
-3,-11,16:100.0
-2,-11,16:100.0
-1,-11,16:100.0
0,-11,16:100.0
1,-11,16:100.0
2,-11,16:100.0
3,-11,16:100.0
4,-11,16:100.0
5,-11,16:100.0
6,-11,16:100.0
7,-11,16:159.10
8,-11,16:159.10
9,-11,16:159.10
-8,-10,16:159.10
-7,-10,16:159.10
-6,-10,16:82.0
-5,-10,16:100.0
-4,-10,16:100.0
-3,-10,16:100.0
-2,-10,16:82.0
-1,-10,16:159.10
0,-10,16:100.0
1,-10,16:100.0
2,-10,16:100.0
3,-10,16:100.0
4,-10,16:100.0
5,-10,16:100.0
6,-10,16:82.0
7,-10,16:100.0
8,-10,16:159.10
9,-10,16:159.10
-8,-9,16:159.10
-7,-9,16:159.10
-6,-9,16:100.0
-5,-9,16:100.0
-4,-9,16:100.0
-3,-9,16:100.0
-2,-9,16:159.10
-1,-9,16:159.10
0,-9,16:159.10
1,-9,16:159.10
2,-9,16:159.10
3,-9,16:159.10
4,-9,16:100.0
5,-9,16:82.0
6,-9,16:82.0
7,-9,16:100.0
8,-9,16:159.10
9,-9,16:159.10
10,-9,16:159.10
-9,-8,16:159.10
-8,-8,16:159.10
-7,-8,16:159.10
-6,-8,16:100.0
-5,-8,16:100.0
-4,-8,16:100.0
-3,-8,16:159.10
-2,-8,16:159.10
0,-8,16:100.0
1,-8,16:159.10
2,-8,16:159.10
3,-8,16:159.10
4,-8,16:82.0
5,-8,16:82.0
6,-8,16:100.0
8,-8,16:100.0
9,-8,16:159.10
10,-8,16:159.10
-9,-7,16:159.10
-8,-7,16:159.10
-7,-7,16:100.0
-6,-7,16:100.0
-5,-7,16:100.0
-4,-7,16:100.0
-3,-7,16:159.10
-2,-7,16:159.10
0,-7,16:100.0
2,-7,16:100.0
3,-7,16:159.10
4,-7,16:159.10
5,-7,16:159.10
6,-7,16:159.10
7,-7,16:100.0
8,-7,16:100.0
9,-7,16:159.10
11,-7,16:159.10
-10,-6,16:159.10
-9,-6,16:159.10
-8,-6,16:159.10
-7,-6,16:100.0
-6,-6,16:100.0
-5,-6,16:100.0
-4,-6,16:159.10
-2,-6,16:100.0
-1,-6,16:100.0
0,-6,16:100.0
1,-6,16:100.0
2,-6,16:100.0
3,-6,16:100.0
4,-6,16:159.10
5,-6,16:159.10
6,-6,16:159.10
7,-6,16:159.10
8,-6,16:159.10
9,-6,16:159.10
10,-6,16:159.10
11,-6,16:159.10
-10,-5,16:159.10
-9,-5,16:82.0
-8,-5,16:100.0
-7,-5,16:100.0
-6,-5,16:100.0
-5,-5,16:100.0
-4,-5,16:159.10
-3,-5,16:159.10
-2,-5,16:100.0
-1,-5,16:100.0
0,-5,16:100.0
1,-5,16:100.0
2,-5,16:100.0
3,-5,16:159.10
4,-5,16:100.0
5,-5,16:159.10
6,-5,16:159.10
7,-5,16:159.10
8,-5,16:159.10
9,-5,16:159.10
10,-5,16:159.10
11,-5,16:159.10
-11,-4,16:159.10
-10,-4,16:82.0
-9,-4,16:82.0
-8,-4,16:82.0
-7,-4,16:100.0
-6,-4,16:100.0
-5,-4,16:159.10
-4,-4,16:159.10
-3,-4,16:159.10
-2,-4,16:100.0
-1,-4,16:100.0
0,-4,16:100.0
1,-4,16:100.0
2,-4,16:100.0
4,-4,16:159.10
5,-4,16:159.10
6,-4,16:159.10
7,-4,16:100.0
8,-4,16:100.0
9,-4,16:159.10
10,-4,16:159.10
11,-4,16:159.10
12,-4,16:159.10
-10,-3,16:82.0
-9,-3,16:82.0
-8,-3,16:100.0
-7,-3,16:82.0
-6,-3,16:82.0
-5,-3,16:159.10
-4,-3,16:159.10
-3,-3,16:159.10
-2,-3,16:159.10
-1,-3,16:159.10
1,-3,16:159.10
2,-3,16:159.10
3,-3,16:100.0
4,-3,16:100.0
5,-3,16:159.10
6,-3,16:159.10
7,-3,16:100.0
8,-3,16:159.10
9,-3,16:100.0
10,-3,16:100.0
11,-3,16:159.10
12,-3,16:159.10
13,-3,16:82.0
-10,-2,16:82.0
-9,-2,16:82.0
-8,-2,16:82.0
-7,-2,16:100.0
-6,-2,16:100.0
-5,-2,16:100.0
-4,-2,16:159.10
-3,-2,16:159.10
-2,-2,16:159.10
-1,-2,16:100.0
0,-2,16:100.0
1,-2,16:159.10
2,-2,16:159.10
4,-2,16:159.10
5,-2,16:159.10
6,-2,16:159.10
7,-2,16:159.10
8,-2,16:159.10
10,-2,16:159.10
11,-2,16:159.10
12,-2,16:159.10
13,-2,16:82.0
-9,-1,16:82.0
-8,-1,16:82.0
-7,-1,16:100.0
-6,-1,16:100.0
-5,-1,16:100.0
-4,-1,16:100.0
-3,-1,16:159.10
-2,-1,16:159.10
-1,-1,16:100.0
0,-1,16:100.0
1,-1,16:100.0
2,-1,16:100.0
3,-1,16:159.10
4,-1,16:159.10
5,-1,16:159.10
6,-1,16:159.10
7,-1,16:100.0
8,-1,16:159.10
9,-1,16:159.10
10,-1,16:159.10
11,-1,16:159.10
12,-1,16:159.10
13,-1,16:82.0
14,-1,16:82.0
-9,0,16:159.10
-8,0,16:159.10
-7,0,16:159.10
-6,0,16:100.0
-5,0,16:100.0
-4,0,16:100.0
-3,0,16:159.10
-2,0,16:159.10
-1,0,16:159.10
0,0,16:159.10
1,0,16:159.10
2,0,16:159.10
3,0,16:159.10
4,0,16:159.10
5,0,16:159.10
6,0,16:100.0
7,0,16:100.0
8,0,16:159.10
9,0,16:159.10
10,0,16:159.10
11,0,16:159.10
15,0,16:82.0
-8,1,16:159.10
-7,1,16:159.10
-6,1,16:159.10
-5,1,16:100.0
-4,1,16:100.0
-3,1,16:100.0
-2,1,16:159.10
-1,1,16:159.10
0,1,16:159.10
1,1,16:159.10
2,1,16:159.10
3,1,16:159.10
4,1,16:159.10
5,1,16:159.10
6,1,16:159.10
7,1,16:159.10
8,1,16:159.10
9,1,16:159.10
10,1,16:159.10
-7,2,16:159.10
-6,2,16:159.10
-5,2,16:100.0
-4,2,16:100.0
-3,2,16:100.0
-2,2,16:159.10
-1,2,16:159.10
1,2,16:159.10
2,2,16:159.10
3,2,16:159.10
4,2,16:159.10
5,2,16:159.10
6,2,16:100.0
7,2,16:159.10
8,2,16:159.10
-7,3,16:159.10
-6,3,16:159.10
-5,3,16:159.10
-4,3,16:100.0
-3,3,16:100.0
-2,3,16:100.0
-1,3,16:100.0
0,3,16:100.0
1,3,16:100.0
2,3,16:100.0
3,3,16:159.10
4,3,16:159.10
5,3,16:100.0
6,3,16:159.10
7,3,16:159.10
8,3,16:159.10
9,3,16:159.10
-6,4,16:159.10
-5,4,16:159.10
-4,4,16:100.0
-3,4,16:82.0
-2,4,16:82.0
-1,4,16:82.0
0,4,16:82.0
1,4,16:100.0
2,4,16:100.0
3,4,16:159.10
4,4,16:159.10
5,4,16:159.10
6,4,16:159.10
7,4,16:159.10
9,4,16:159.10
10,4,16:159.10
-6,5,16:159.10
-5,5,16:159.10
-4,5,16:82.0
-3,5,16:82.0
-2,5,16:82.0
-1,5,16:82.0
0,5,16:82.0
1,5,16:159.10
2,5,16:159.10
3,5,16:159.10
4,5,16:159.10
5,5,16:159.10
6,5,16:159.10
10,5,16:159.10
-5,6,16:159.10
-4,6,16:82.0
-3,6,16:82.0
-2,6,16:82.0
-1,6,16:82.0
0,6,16:82.0
1,6,16:159.10
2,6,16:159.10
3,6,16:159.10
4,6,16:159.10
5,6,16:159.10
6,6,16:159.10
6,7,16:82.0
-4,-13,17:82.0
-3,-13,17:82.0
-2,-13,17:159.10
-1,-13,17:159.10
-4,-12,17:82.0
-3,-12,17:82.0
-2,-12,17:82.0
-1,-12,17:159.10
0,-12,17:159.10
1,-12,17:159.10
2,-12,17:159.10
3,-12,17:159.10
8,-12,17:159.10
-5,-11,17:82.0
-4,-11,17:82.0
-3,-11,17:82.0
-2,-11,17:82.0
-1,-11,17:159.10
0,-11,17:159.10
1,-11,17:159.10
2,-11,17:159.10
3,-11,17:159.10
4,-11,17:82.0
5,-11,17:82.0
6,-11,17:82.0
7,-11,17:159.10
8,-11,17:159.10
-5,-10,17:82.0
-4,-10,17:82.0
-3,-10,17:82.0
-2,-10,17:100.0
-1,-10,17:100.0
0,-10,17:159.10
1,-10,17:159.10
2,-10,17:159.10
3,-10,17:82.0
4,-10,17:82.0
5,-10,17:82.0
6,-10,17:82.0
7,-10,17:82.0
-6,-9,17:159.10
-5,-9,17:82.0
-4,-9,17:82.0
-3,-9,17:82.0
-2,-9,17:100.0
-1,-9,17:100.0
0,-9,17:100.0
1,-9,17:100.0
2,-9,17:100.0
3,-9,17:100.0
4,-9,17:82.0
5,-9,17:82.0
6,-9,17:82.0
7,-9,17:82.0
-6,-8,17:159.10
-5,-8,17:159.10
-4,-8,17:159.10
-3,-8,17:100.0
-2,-8,17:100.0
-1,-8,17:100.0
0,-8,17:159.10
1,-8,17:100.0
2,-8,17:100.0
3,-8,17:100.0
4,-8,17:100.0
5,-8,17:82.0
6,-8,17:82.0
8,-8,17:159.10
-7,-7,17:159.10
-6,-7,17:159.10
-5,-7,17:159.10
-4,-7,17:159.10
-3,-7,17:100.0
-2,-7,17:100.0
-1,-7,17:100.0
0,-7,17:159.10
1,-7,17:100.0
2,-7,17:159.10
3,-7,17:100.0
4,-7,17:82.0
5,-7,17:82.0
6,-7,17:82.0
7,-7,17:159.10
8,-7,17:159.10
-7,-6,17:159.10
-6,-6,17:159.10
-5,-6,17:159.10
-4,-6,17:100.0
-2,-6,17:159.10
-1,-6,17:159.10
0,-6,17:159.10
1,-6,17:159.10
2,-6,17:159.10
3,-6,17:159.10
4,-6,17:159.10
6,-6,17:159.10
7,-6,17:159.10
8,-6,17:159.10
9,-6,17:159.10
11,-6,17:159.10
-8,-5,17:82.0
-7,-5,17:82.0
-6,-5,17:159.10
-5,-5,17:159.10
-4,-5,17:100.0
-3,-5,17:100.0
-2,-5,17:159.10
-1,-5,17:159.10
0,-5,17:159.10
1,-5,17:159.10
2,-5,17:159.10
3,-5,17:159.10
4,-5,17:159.10
7,-5,17:159.10
8,-5,17:159.10
9,-5,17:159.10
10,-5,17:159.10
-9,-4,17:82.0
-8,-4,17:82.0
-7,-4,17:82.0
-6,-4,17:82.0
-5,-4,17:100.0
-4,-4,17:100.0
-3,-4,17:100.0
-2,-4,17:159.10
-1,-4,17:159.10
0,-4,17:159.10
1,-4,17:159.10
2,-4,17:159.10
3,-4,17:100.0
4,-4,17:159.10
7,-4,17:159.10
8,-4,17:159.10
9,-4,17:159.10
10,-4,17:159.10
-8,-3,17:82.0
-7,-3,17:82.0
-6,-3,17:82.0
-5,-3,17:159.10
-4,-3,17:159.10
-3,-3,17:159.10
-2,-3,17:159.10
-1,-3,17:159.10
0,-3,17:100.0
1,-3,17:159.10
2,-3,17:159.10
3,-3,17:159.10
4,-3,17:159.10
7,-3,17:159.10
8,-3,17:159.10
9,-3,17:159.10
10,-3,17:159.10
-7,-2,17:82.0
-6,-2,17:82.0
-5,-2,17:159.10
-4,-2,17:100.0
-3,-2,17:100.0
-1,-2,17:159.10
0,-2,17:159.10
1,-2,17:159.10
2,-2,17:159.10
4,-2,17:159.10
5,-2,17:159.10
6,-2,17:159.10
7,-2,17:159.10
8,-2,17:159.10
9,-2,17:100.0
10,-2,17:159.10
-7,-1,17:82.0
-6,-1,17:159.10
-5,-1,17:159.10
-4,-1,17:159.10
-3,-1,17:100.0
-1,-1,17:159.10
0,-1,17:159.10
1,-1,17:159.10
2,-1,17:159.10
7,-1,17:159.10
8,-1,17:159.10
9,-1,17:159.10
10,-1,17:159.10
11,-1,17:159.10
-6,0,17:159.10
-5,0,17:159.10
-4,0,17:159.10
-3,0,17:100.0
-2,0,17:100.0
3,0,17:159.10
6,0,17:159.10
7,0,17:159.10
8,0,17:159.10
9,0,17:159.10
-6,1,17:159.10
-5,1,17:159.10
-4,1,17:159.10
-3,1,17:159.10
-2,1,17:100.0
-1,1,17:100.0
0,1,17:100.0
1,1,17:100.0
3,1,17:159.10
5,1,17:159.10
6,1,17:159.10
7,1,17:159.10
8,1,17:159.10
-5,2,17:159.10
-4,2,17:159.10
-3,2,17:159.10
-2,2,17:100.0
-1,2,17:100.0
1,2,17:100.0
4,2,17:159.10
5,2,17:159.10
6,2,17:159.10
7,2,17:159.10
8,2,17:159.10
-4,3,17:159.10
-3,3,17:82.0
-2,3,17:82.0
-1,3,17:82.0
0,3,17:159.10
1,3,17:159.10
2,3,17:159.10
3,3,17:159.10
4,3,17:159.10
5,3,17:159.10
6,3,17:159.10
8,3,17:159.10
9,3,17:159.10
-4,4,17:82.0
-3,4,17:82.0
-2,4,17:82.0
-1,4,17:82.0
0,4,17:82.0
1,4,17:159.10
2,4,17:159.10
3,4,17:159.10
4,4,17:159.10
5,4,17:159.10
9,4,17:159.10
-2,-10,18:82.0
-1,-10,18:159.10
0,-10,18:159.10
1,-10,18:159.10
-3,-9,18:82.0
-2,-9,18:159.10
-1,-9,18:159.10
0,-9,18:159.10
1,-9,18:159.10
2,-9,18:159.10
3,-9,18:82.0
4,-9,18:82.0
5,-9,18:82.0
6,-9,18:82.0
-3,-8,18:159.10
-2,-8,18:159.10
-1,-8,18:159.10
0,-8,18:159.10
1,-8,18:159.10
2,-8,18:159.10
3,-8,18:82.0
4,-8,18:82.0
5,-8,18:82.0
6,-8,18:82.0
8,-8,18:159.10
-4,-7,18:159.10
-3,-7,18:159.10
-2,-7,18:159.10
-1,-7,18:159.10
0,-7,18:100.0
1,-7,18:159.10
2,-7,18:159.10
3,-7,18:159.10
4,-7,18:82.0
5,-7,18:82.0
6,-7,18:82.0
7,-7,18:159.10
8,-7,18:159.10
9,-7,18:100.0
11,-7,18:100.0
-4,-6,18:159.10
-2,-6,18:159.10
-1,-6,18:100.0
0,-6,18:100.0
1,-6,18:100.0
2,-6,18:100.0
3,-6,18:100.0
4,-6,18:159.10
5,-6,18:100.0
6,-6,18:159.10
8,-6,18:100.0
9,-6,18:100.0
10,-6,18:100.0
11,-6,18:100.0
12,-6,18:100.0
-5,-5,18:159.10
-4,-5,18:159.10
-3,-5,18:159.10
-2,-5,18:159.10
-1,-5,18:100.0
0,-5,18:100.0
1,-5,18:100.0
2,-5,18:100.0
3,-5,18:159.10
5,-5,18:100.0
6,-5,18:100.0
7,-5,18:159.10
10,-5,18:159.10
12,-5,18:100.0
13,-5,18:100.0
-6,-4,18:82.0
-5,-4,18:159.10
-4,-4,18:159.10
-3,-4,18:159.10
-2,-4,18:100.0
-1,-4,18:100.0
0,-4,18:100.0
2,-4,18:159.10
3,-4,18:159.10
5,-4,18:100.0
6,-4,18:100.0
7,-4,18:159.10
12,-4,18:100.0
13,-4,18:100.0
14,-4,18:100.0
-5,-3,18:159.10
-4,-3,18:159.10
-3,-3,18:159.10
-2,-3,18:159.10
-1,-3,18:159.10
0,-3,18:159.10
1,-3,18:159.10
2,-3,18:159.10
6,-3,18:100.0
7,-3,18:159.10
8,-3,18:159.10
13,-3,18:100.0
14,-3,18:100.0
-5,-2,18:159.10
-4,-2,18:159.10
-3,-2,18:159.10
-2,-2,18:100.0
-1,-2,18:100.0
0,-2,18:100.0
1,-2,18:159.10
2,-2,18:159.10
6,-2,18:159.10
7,-2,18:159.10
8,-2,18:159.10
9,-2,18:159.10
10,-2,18:159.10
13,-2,18:100.0
14,-2,18:100.0
-4,-1,18:159.10
-3,-1,18:159.10
-2,-1,18:100.0
-1,-1,18:100.0
0,-1,18:100.0
1,-1,18:100.0
2,-1,18:159.10
5,-1,18:100.0
6,-1,18:100.0
7,-1,18:159.10
10,-1,18:159.10
11,-1,18:159.10
14,-1,18:100.0
-4,0,18:159.10
-3,0,18:159.10
-2,0,18:82.0
-1,0,18:100.0
0,0,18:100.0
1,0,18:100.0
2,0,18:100.0
3,0,18:159.10
4,0,18:100.0
5,0,18:100.0
6,0,18:159.10
15,0,18:100.0
-3,1,18:159.10
-2,1,18:159.10
-1,1,18:82.0
0,1,18:159.10
1,1,18:159.10
2,1,18:100.0
3,1,18:159.10
4,1,18:100.0
5,1,18:159.10
6,1,18:159.10
13,1,18:100.0
14,1,18:100.0
-3,2,18:159.10
-2,2,18:159.10
-1,2,18:159.10
1,2,18:159.10
2,2,18:100.0
3,2,18:100.0
4,2,18:159.10
5,2,18:82.0
12,2,18:100.0
13,2,18:100.0
-4,3,18:159.10
3,3,18:100.0
4,3,18:159.10
5,3,18:100.0
11,3,18:100.0
12,3,18:100.0
3,4,18:159.10
4,4,18:100.0
8,4,18:100.0
11,4,18:100.0
9,5,18:100.0
10,5,18:100.0
-1,-8,19:159.10
6,-8,19:82.0
-1,-7,19:159.10
0,-7,19:159.10
1,-7,19:159.10
2,-7,19:159.10
5,-7,19:82.0
6,-7,19:82.0
7,-7,19:159.10
8,-7,19:159.10
9,-7,19:159.10
11,-7,19:159.10
-1,-6,19:159.10
0,-6,19:159.10
1,-6,19:159.10
2,-6,19:159.10
3,-6,19:159.10
4,-6,19:159.10
5,-6,19:159.10
6,-6,19:159.10
7,-6,19:100.0
8,-6,19:159.10
9,-6,19:159.10
10,-6,19:159.10
11,-6,19:159.10
12,-6,19:159.10
-2,-5,19:159.10
-1,-5,19:159.10
0,-5,19:159.10
1,-5,19:159.10
2,-5,19:159.10
3,-5,19:159.10
4,-5,19:100.0
5,-5,19:159.10
6,-5,19:159.10
7,-5,19:159.10
8,-5,19:100.0
9,-5,19:100.0
10,-5,19:159.10
11,-5,19:100.0
12,-5,19:82.0
13,-5,19:82.0
-2,-4,19:159.10
-1,-4,19:159.10
0,-4,19:159.10
2,-4,19:159.10
3,-4,19:159.10
4,-4,19:100.0
5,-4,19:159.10
6,-4,19:159.10
7,-4,19:159.10
8,-4,19:100.0
9,-4,19:100.0
10,-4,19:100.0
11,-4,19:100.0
12,-4,19:82.0
13,-4,19:82.0
14,-4,19:82.0
-4,-3,19:159.10
-3,-3,19:159.10
-2,-3,19:159.10
-1,-3,19:159.10
0,-3,19:159.10
1,-3,19:159.10
2,-3,19:159.10
3,-3,19:100.0
4,-3,19:100.0
5,-3,19:100.0
6,-3,19:159.10
7,-3,19:159.10
8,-3,19:159.10
9,-3,19:100.0
10,-3,19:100.0
11,-3,19:100.0
12,-3,19:100.0
13,-3,19:82.0
14,-3,19:82.0
-2,-2,19:159.10
-1,-2,19:159.10
0,-2,19:159.10
1,-2,19:159.10
2,-2,19:159.10
4,-2,19:100.0
5,-2,19:100.0
6,-2,19:159.10
7,-2,19:159.10
8,-2,19:159.10
9,-2,19:159.10
10,-2,19:82.0
11,-2,19:100.0
12,-2,19:100.0
13,-2,19:82.0
14,-2,19:82.0
-2,-1,19:82.0
-1,-1,19:82.0
0,-1,19:82.0
1,-1,19:159.10
2,-1,19:159.10
3,-1,19:100.0
4,-1,19:100.0
5,-1,19:159.10
6,-1,19:159.10
7,-1,19:159.10
8,-1,19:100.0
9,-1,19:100.0
10,-1,19:159.10
11,-1,19:82.0
12,-1,19:100.0
13,-1,19:100.0
14,-1,19:159.10
-1,0,19:82.0
0,0,19:82.0
1,0,19:159.10
2,0,19:159.10
3,0,19:159.10
4,0,19:159.10
5,0,19:159.10
6,0,19:159.10
7,0,19:100.0
8,0,19:100.0
9,0,19:100.0
10,0,19:100.0
11,0,19:100.0
12,0,19:100.0
13,0,19:100.0
15,0,19:159.10
2,1,19:159.10
3,1,19:159.10
4,1,19:159.10
5,1,19:82.0
6,1,19:82.0
7,1,19:100.0
8,1,19:100.0
9,1,19:100.0
10,1,19:100.0
11,1,19:100.0
12,1,19:100.0
13,1,19:159.10
14,1,19:159.10
2,2,19:159.10
3,2,19:159.10
4,2,19:82.0
5,2,19:82.0
6,2,19:100.0
7,2,19:100.0
8,2,19:100.0
10,2,19:100.0
11,2,19:100.0
12,2,19:159.10
13,2,19:159.10
3,3,19:159.10
4,3,19:82.0
5,3,19:82.0
6,3,19:100.0
7,3,19:100.0
8,3,19:100.0
9,3,19:100.0
10,3,19:100.0
11,3,19:159.10
12,3,19:159.10
3,4,19:159.10
4,4,19:82.0
5,4,19:100.0
8,4,19:82.0
9,4,19:100.0
10,4,19:100.0
11,4,19:159.10
9,5,19:159.10
10,5,19:159.10
6,-8,20:82.0
6,-7,20:159.10
5,-6,20:159.10
6,-6,20:159.10
7,-6,20:159.10
4,-5,20:159.10
5,-5,20:159.10
6,-5,20:159.10
7,-5,20:159.10
8,-5,20:159.10
9,-5,20:159.10
10,-5,20:159.10
11,-5,20:82.0
3,-4,20:159.10
4,-4,20:159.10
5,-4,20:159.10
6,-4,20:159.10
7,-4,20:159.10
8,-4,20:159.10
9,-4,20:159.10
10,-4,20:82.0
11,-4,20:82.0
3,-3,20:159.10
4,-3,20:159.10
5,-3,20:159.10
6,-3,20:159.10
7,-3,20:159.10
8,-3,20:159.10
9,-3,20:159.10
10,-3,20:82.0
11,-3,20:82.0
12,-3,20:82.0
4,-2,20:159.10
5,-2,20:159.10
6,-2,20:159.10
7,-2,20:159.10
8,-2,20:159.10
9,-2,20:159.10
10,-2,20:82.0
11,-2,20:82.0
12,-2,20:82.0
2,-1,20:159.10
3,-1,20:159.10
4,-1,20:159.10
5,-1,20:159.10
6,-1,20:159.10
7,-1,20:159.10
8,-1,20:159.10
9,-1,20:159.10
10,-1,20:159.10
11,-1,20:82.0
12,-1,20:82.0
13,-1,20:82.0
3,0,20:159.10
4,0,20:159.10
5,0,20:159.10
6,0,20:159.10
7,0,20:159.10
8,0,20:159.10
9,0,20:159.10
10,0,20:159.10
11,0,20:159.10
12,0,20:159.10
13,0,20:159.10
3,1,20:159.10
4,1,20:159.10
5,1,20:82.0
6,1,20:82.0
7,1,20:82.0
8,1,20:159.10
9,1,20:159.10
10,1,20:159.10
11,1,20:159.10
12,1,20:159.10
4,2,20:82.0
5,2,20:82.0
6,2,20:82.0
7,2,20:82.0
8,2,20:82.0
10,2,20:159.10
11,2,20:159.10
4,3,20:82.0
6,3,20:82.0
7,3,20:82.0
8,3,20:82.0
9,3,20:159.10
10,3,20:159.10
5,4,20:82.0
9,4,20:159.10
10,4,20:159.10
-1,-12,22:100.0
0,-12,22:100.0
1,-12,22:100.0
-2,-11,22:100.0
-1,-11,22:100.0
0,-11,22:100.0
1,-11,22:100.0
2,-11,22:100.0
3,-11,22:100.0
4,-11,22:100.0
5,-11,22:100.0
6,-11,22:100.0
-3,-10,22:100.0
-2,-10,22:100.0
-4,-9,22:100.0
-3,-9,22:100.0
-5,-8,22:100.0
-4,-8,22:100.0
9,-8,22:100.0
-6,-7,22:100.0
-5,-7,22:100.0
9,-7,22:100.0
-6,-6,22:100.0
9,-6,22:100.0
10,-6,22:100.0
-7,-5,22:100.0
-6,-5,22:100.0
10,-5,22:100.0
-7,-4,22:100.0
-6,-4,22:100.0
11,-4,22:100.0
-7,-3,22:100.0
-6,-3,22:100.0
-6,-2,22:100.0
-5,-2,22:100.0
12,-2,22:100.0
-6,-1,22:100.0
-5,-1,22:100.0
-6,0,22:100.0
-5,0,22:100.0
12,0,22:100.0
-5,1,22:100.0
-4,1,22:100.0
11,1,22:100.0
-5,2,22:100.0
-4,2,22:100.0
10,2,22:100.0
-3,3,22:100.0
-2,3,22:100.0
-1,3,22:100.0
6,3,22:100.0
7,3,22:100.0
8,3,22:100.0
9,3,22:100.0
10,3,22:100.0
-3,4,22:100.0
-2,4,22:100.0
-1,4,22:100.0
0,4,22:100.0
1,4,22:100.0
2,4,22:100.0
5,4,22:100.0
6,4,22:100.0
0,5,22:100.0
1,5,22:100.0
2,5,22:100.0
3,5,22:100.0
4,5,22:100.0
5,5,22:100.0
-1,-12,23:159.10
0,-12,23:159.10
1,-12,23:159.10
-2,-11,23:159.10
-1,-11,23:159.10
0,-11,23:159.10
1,-11,23:82.0
2,-11,23:82.0
3,-11,23:82.0
4,-11,23:159.10
5,-11,23:159.10
6,-11,23:159.10
-3,-10,23:159.10
-2,-10,23:159.10
-1,-10,23:100.0
0,-10,23:100.0
1,-10,23:100.0
2,-10,23:100.0
3,-10,23:100.0
4,-10,23:100.0
5,-10,23:100.0
6,-10,23:100.0
7,-10,23:100.0
-4,-9,23:159.10
-3,-9,23:159.10
-2,-9,23:100.0
-1,-9,23:100.0
0,-9,23:100.0
1,-9,23:100.0
2,-9,23:100.0
3,-9,23:100.0
4,-9,23:100.0
5,-9,23:100.0
6,-9,23:100.0
7,-9,23:100.0
8,-9,23:100.0
-5,-8,23:159.10
-4,-8,23:159.10
-3,-8,23:100.0
-2,-8,23:100.0
-1,-8,23:100.0
0,-8,23:100.0
5,-8,23:100.0
6,-8,23:100.0
8,-8,23:100.0
9,-8,23:159.10
-6,-7,23:159.10
-5,-7,23:159.10
-4,-7,23:100.0
-3,-7,23:100.0
-2,-7,23:100.0
-1,-7,23:100.0
0,-7,23:100.0
7,-7,23:100.0
8,-7,23:100.0
9,-7,23:159.10
-6,-6,23:159.10
-5,-6,23:100.0
-4,-6,23:100.0
-2,-6,23:100.0
0,-6,23:100.0
7,-6,23:100.0
8,-6,23:100.0
9,-6,23:159.10
10,-6,23:159.10
-7,-5,23:159.10
-6,-5,23:159.10
-5,-5,23:100.0
-4,-5,23:100.0
-3,-5,23:100.0
0,-5,23:100.0
5,-5,23:100.0
6,-5,23:100.0
7,-5,23:100.0
8,-5,23:100.0
9,-5,23:100.0
10,-5,23:159.10
-7,-4,23:159.10
-6,-4,23:159.10
-5,-4,23:100.0
-4,-4,23:100.0
-3,-4,23:100.0
0,-4,23:100.0
1,-4,23:100.0
2,-4,23:100.0
3,-4,23:100.0
4,-4,23:100.0
5,-4,23:100.0
6,-4,23:100.0
7,-4,23:100.0
8,-4,23:100.0
9,-4,23:100.0
10,-4,23:100.0
11,-4,23:159.10
-7,-3,23:159.10
-6,-3,23:159.10
-5,-3,23:100.0
-4,-3,23:100.0
-3,-3,23:100.0
0,-3,23:100.0
1,-3,23:100.0
2,-3,23:100.0
3,-3,23:100.0
4,-3,23:100.0
5,-3,23:100.0
6,-3,23:100.0
7,-3,23:100.0
8,-3,23:100.0
9,-3,23:100.0
10,-3,23:100.0
11,-3,23:100.0
-6,-2,23:159.10
-5,-2,23:159.10
-4,-2,23:100.0
-3,-2,23:100.0
-2,-2,23:100.0
1,-2,23:100.0
2,-2,23:100.0
4,-2,23:100.0
5,-2,23:100.0
6,-2,23:100.0
7,-2,23:100.0
8,-2,23:100.0
9,-2,23:100.0
10,-2,23:100.0
11,-2,23:100.0
12,-2,23:159.10
-6,-1,23:159.10
-5,-1,23:159.10
-4,-1,23:100.0
-3,-1,23:100.0
-2,-1,23:100.0
-1,-1,23:100.0
0,-1,23:100.0
1,-1,23:100.0
2,-1,23:100.0
3,-1,23:100.0
4,-1,23:100.0
5,-1,23:100.0
6,-1,23:100.0
7,-1,23:100.0
8,-1,23:100.0
9,-1,23:100.0
10,-1,23:100.0
11,-1,23:100.0
12,-1,23:100.0
-6,0,23:159.10
-5,0,23:159.10
-4,0,23:100.0
-3,0,23:100.0
-2,0,23:100.0
-1,0,23:100.0
0,0,23:100.0
3,0,23:100.0
4,0,23:100.0
5,0,23:100.0
6,0,23:100.0
7,0,23:100.0
8,0,23:100.0
9,0,23:100.0
10,0,23:100.0
11,0,23:100.0
12,0,23:159.10
-5,1,23:159.10
-4,1,23:159.10
-3,1,23:100.0
-2,1,23:100.0
-1,1,23:100.0
0,1,23:100.0
1,1,23:100.0
2,1,23:100.0
4,1,23:100.0
5,1,23:100.0
6,1,23:100.0
7,1,23:100.0
8,1,23:100.0
9,1,23:100.0
10,1,23:100.0
11,1,23:159.10
-5,2,23:159.10
-4,2,23:159.10
-3,2,23:100.0
-2,2,23:100.0
-1,2,23:100.0
1,2,23:100.0
2,2,23:100.0
3,2,23:100.0
4,2,23:100.0
5,2,23:100.0
6,2,23:100.0
7,2,23:100.0
8,2,23:100.0
10,2,23:159.10
-4,3,23:100.0
-3,3,23:159.10
-2,3,23:159.10
-1,3,23:159.10
0,3,23:100.0
1,3,23:100.0
2,3,23:100.0
3,3,23:100.0
4,3,23:100.0
5,3,23:100.0
6,3,23:159.10
7,3,23:159.10
8,3,23:159.10
9,3,23:159.10
10,3,23:159.10
-3,4,23:159.10
-2,4,23:159.10
-1,4,23:159.10
0,4,23:82.0
1,4,23:82.0
2,4,23:82.0
3,4,23:100.0
4,4,23:100.0
5,4,23:159.10
6,4,23:159.10
0,5,23:159.10
1,5,23:82.0
2,5,23:82.0
3,5,23:82.0
4,5,23:159.10
5,5,23:159.10
-1,-10,24:159.10
0,-10,24:82.0
1,-10,24:82.0
2,-10,24:82.0
3,-10,24:82.0
4,-10,24:82.0
5,-10,24:159.10
6,-10,24:159.10
7,-10,24:159.10
-2,-9,24:159.10
-1,-9,24:159.10
0,-9,24:82.0
1,-9,24:82.0
2,-9,24:82.0
3,-9,24:82.0
4,-9,24:82.0
5,-9,24:159.10
6,-9,24:159.10
7,-9,24:159.10
8,-9,24:159.10
-3,-8,24:159.10
-2,-8,24:159.10
-1,-8,24:159.10
0,-8,24:82.0
1,-8,24:100.0
2,-8,24:100.0
3,-8,24:100.0
4,-8,24:100.0
5,-8,24:159.10
6,-8,24:159.10
8,-8,24:159.10
-4,-7,24:159.10
-3,-7,24:159.10
-2,-7,24:159.10
-1,-7,24:159.10
0,-7,24:159.10
1,-7,24:100.0
2,-7,24:100.0
3,-7,24:100.0
4,-7,24:100.0
5,-7,24:100.0
6,-7,24:100.0
7,-7,24:159.10
8,-7,24:159.10
-5,-6,24:159.10
-4,-6,24:159.10
-2,-6,24:159.10
-1,-6,24:100.0
0,-6,24:159.10
1,-6,24:100.0
2,-6,24:100.0
3,-6,24:100.0
4,-6,24:100.0
5,-6,24:100.0
6,-6,24:100.0
7,-6,24:159.10
8,-6,24:159.10
-5,-5,24:159.10
-4,-5,24:159.10
-3,-5,24:159.10
-2,-5,24:100.0
-1,-5,24:100.0
0,-5,24:159.10
1,-5,24:100.0
2,-5,24:100.0
3,-5,24:100.0
4,-5,24:100.0
5,-5,24:159.10
6,-5,24:159.10
7,-5,24:159.10
8,-5,24:159.10
9,-5,24:159.10
-5,-4,24:82.0
-4,-4,24:82.0
-3,-4,24:82.0
-2,-4,24:100.0
-1,-4,24:100.0
0,-4,24:159.10
1,-4,24:159.10
2,-4,24:159.10
3,-4,24:159.10
4,-4,24:159.10
5,-4,24:159.10
6,-4,24:159.10
7,-4,24:159.10
8,-4,24:159.10
9,-4,24:159.10
10,-4,24:159.10
-5,-3,24:82.0
-4,-3,24:82.0
-3,-3,24:82.0
-2,-3,24:100.0
-1,-3,24:100.0
0,-3,24:159.10
1,-3,24:159.10
2,-3,24:159.10
3,-3,24:159.10
4,-3,24:159.10
5,-3,24:159.10
6,-3,24:159.10
7,-3,24:159.10
8,-3,24:82.0
9,-3,24:82.0
10,-3,24:82.0
11,-3,24:159.10
-4,-2,24:82.0
-3,-2,24:82.0
-2,-2,24:159.10
-1,-2,24:100.0
0,-2,24:100.0
1,-2,24:159.10
2,-2,24:159.10
4,-2,24:159.10
5,-2,24:159.10
6,-2,24:159.10
7,-2,24:82.0
8,-2,24:82.0
9,-2,24:82.0
10,-2,24:82.0
11,-2,24:82.0
-4,-1,24:159.10
-3,-1,24:159.10
-2,-1,24:159.10
-1,-1,24:159.10
0,-1,24:159.10
1,-1,24:159.10
2,-1,24:159.10
3,-1,24:159.10
4,-1,24:159.10
5,-1,24:159.10
6,-1,24:159.10
7,-1,24:82.0
8,-1,24:82.0
9,-1,24:82.0
10,-1,24:82.0
11,-1,24:82.0
12,-1,24:159.10
-4,0,24:159.10
-3,0,24:159.10
-2,0,24:159.10
-1,0,24:159.10
0,0,24:159.10
1,0,24:100.0
2,0,24:100.0
3,0,24:159.10
4,0,24:159.10
5,0,24:159.10
6,0,24:159.10
7,0,24:82.0
8,0,24:82.0
9,0,24:82.0
10,0,24:82.0
11,0,24:82.0
-3,1,24:159.10
-2,1,24:159.10
-1,1,24:159.10
0,1,24:159.10
1,1,24:82.0
2,1,24:82.0
3,1,24:100.0
4,1,24:159.10
5,1,24:159.10
6,1,24:159.10
7,1,24:159.10
8,1,24:82.0
9,1,24:82.0
10,1,24:82.0
-3,2,24:159.10
-2,2,24:159.10
-1,2,24:159.10
1,2,24:82.0
2,2,24:82.0
3,2,24:82.0
4,2,24:82.0
5,2,24:159.10
6,2,24:159.10
7,2,24:159.10
8,2,24:159.10
-4,3,24:159.10
0,3,24:82.0
1,3,24:82.0
2,3,24:82.0
3,3,24:82.0
4,3,24:82.0
5,3,24:159.10
3,4,24:82.0
4,4,24:82.0
1,-8,25:82.0
2,-8,25:82.0
3,-8,25:82.0
4,-8,25:82.0
-1,-7,25:159.10
0,-7,25:159.10
1,-7,25:82.0
2,-7,25:82.0
3,-7,25:82.0
4,-7,25:159.10
5,-7,25:159.10
6,-7,25:159.10
-2,-6,25:159.10
-1,-6,25:159.10
0,-6,25:159.10
1,-6,25:159.10
2,-6,25:159.10
3,-6,25:159.10
4,-6,25:159.10
5,-6,25:159.10
6,-6,25:159.10
-2,-5,25:159.10
-1,-5,25:159.10
0,-5,25:159.10
1,-5,25:159.10
2,-5,25:159.10
3,-5,25:159.10
4,-5,25:159.10
5,-5,25:159.10
6,-5,25:159.10
-3,-4,25:159.10
-2,-4,25:159.10
-1,-4,25:159.10
1,-4,25:159.10
4,-4,25:159.10
5,-4,25:159.10
6,-4,25:159.10
9,-4,25:159.10
-3,-3,25:82.0
-2,-3,25:159.10
-1,-3,25:159.10
1,-3,25:159.10
4,-3,25:159.10
5,-3,25:159.10
6,-3,25:159.10
8,-3,25:82.0
9,-3,25:82.0
-2,-2,25:159.10
-1,-2,25:159.10
0,-2,25:159.10
1,-2,25:159.10
2,-2,25:159.10
4,-2,25:159.10
5,-2,25:159.10
6,-2,25:159.10
7,-2,25:82.0
8,-2,25:82.0
-2,-1,25:159.10
-1,-1,25:159.10
0,-1,25:159.10
2,-1,25:100.0
3,-1,25:159.10
4,-1,25:159.10
5,-1,25:159.10
6,-1,25:159.10
7,-1,25:82.0
8,-1,25:82.0
9,-1,25:82.0
-2,0,25:159.10
-1,0,25:159.10
0,0,25:159.10
1,0,25:159.10
2,0,25:159.10
3,0,25:159.10
4,0,25:159.10
5,0,25:159.10
7,0,25:82.0
8,0,25:82.0
-2,1,25:159.10
0,1,25:159.10
1,1,25:82.0
2,1,25:82.0
3,1,25:82.0
4,1,25:159.10
8,1,25:82.0
-3,2,25:159.10
3,2,25:82.0
3,-5,26:159.10
2,-4,26:100.15
3,-4,26:100.0
4,-4,26:159.10
1,-3,26:100.15
2,-3,26:100.15
3,-3,26:100.15
4,-3,26:100.15
1,-2,26:100.15
3,-2,26:100.15
2,-1,26:159.10
2,-4,27:100.15
3,-4,27:159.10
2,-3,27:100.15
3,-3,27:100.15
6,2,27:100.0
5,3,27:100.0
-1,-8,28:100.0
0,-8,28:100.0
1,-8,28:100.0
2,-8,28:100.0
3,-8,28:100.0
4,-8,28:100.0
5,-8,28:100.0
6,-8,28:100.0
-2,-7,28:100.0
4,-7,28:100.0
6,-7,28:100.0
-2,-6,28:100.0
6,-6,28:100.0
7,-6,28:100.0
-3,-5,28:100.0
6,-5,28:100.0
7,-5,28:100.0
-4,-4,28:100.0
-3,-4,28:100.0
2,-4,28:100.15
3,-4,28:159.10
6,-4,28:100.0
7,-4,28:100.0
8,-4,28:100.0
-5,-3,28:100.0
-4,-3,28:100.0
-3,-3,28:100.0
-2,-3,28:100.0
2,-3,28:100.15
3,-3,28:100.15
7,-3,28:100.0
8,-3,28:100.0
-4,-2,28:100.0
-3,-2,28:100.0
-1,-2,28:100.0
0,-2,28:100.0
1,-2,28:100.0
2,-2,28:100.0
7,-2,28:100.0
8,-2,28:100.0
-4,-1,28:100.0
-3,-1,28:100.0
3,-1,28:100.0
6,-1,28:100.0
7,-1,28:100.0
8,-1,28:100.0
-3,0,28:100.0
-2,0,28:100.0
3,0,28:100.0
5,0,28:100.0
6,0,28:100.0
7,0,28:100.0
-3,1,28:100.0
-2,1,28:100.0
-1,1,28:100.0
4,1,28:100.0
5,1,28:100.0
6,1,28:100.0
-2,2,28:100.0
-1,2,28:100.0
1,2,28:100.0
2,2,28:100.0
3,2,28:100.0
4,2,28:100.0
5,2,28:100.0
6,2,28:159.10
-1,3,28:100.0
0,3,28:100.0
1,3,28:100.0
2,3,28:100.0
3,3,28:100.0
4,3,28:100.0
5,3,28:159.10
-1,-8,29:159.10
0,-8,29:159.10
1,-8,29:159.10
2,-8,29:159.10
3,-8,29:159.10
4,-8,29:159.10
5,-8,29:159.10
6,-8,29:159.10
-2,-7,29:159.10
-1,-7,29:100.0
0,-7,29:100.0
1,-7,29:100.0
2,-7,29:100.0
3,-7,29:100.0
4,-7,29:159.10
5,-7,29:100.0
6,-7,29:159.10
-2,-6,29:159.10
-1,-6,29:100.0
0,-6,29:100.0
1,-6,29:100.0
2,-6,29:100.0
3,-6,29:100.0
4,-6,29:100.0
5,-6,29:100.0
6,-6,29:159.10
7,-6,29:159.10
-3,-5,29:159.10
-2,-5,29:100.0
-1,-5,29:100.0
0,-5,29:100.0
1,-5,29:100.0
2,-5,29:100.0
3,-5,29:100.0
4,-5,29:100.0
5,-5,29:100.0
6,-5,29:159.10
7,-5,29:159.10
-4,-4,29:159.10
-3,-4,29:159.10
-2,-4,29:100.0
-1,-4,29:100.0
0,-4,29:100.0
2,-4,29:100.15
3,-4,29:159.10
4,-4,29:100.0
5,-4,29:100.0
6,-4,29:159.10
7,-4,29:159.10
8,-4,29:159.10
-5,-3,29:159.10
-4,-3,29:159.10
-3,-3,29:159.10
-2,-3,29:82.0
-1,-3,29:100.0
0,-3,29:100.0
2,-3,29:100.0
3,-3,29:159.10
4,-3,29:100.0
5,-3,29:100.0
6,-3,29:100.0
7,-3,29:159.10
8,-3,29:159.10
-4,-2,29:159.10
-3,-2,29:159.10
-2,-2,29:100.0
-1,-2,29:82.0
0,-2,29:82.0
1,-2,29:82.0
2,-2,29:159.10
4,-2,29:100.0
5,-2,29:100.0
6,-2,29:100.0
7,-2,29:159.10
8,-2,29:159.10
-4,-1,29:159.10
-3,-1,29:159.10
-2,-1,29:100.0
-1,-1,29:100.0
0,-1,29:100.0
1,-1,29:100.0
2,-1,29:100.0
3,-1,29:159.10
4,-1,29:100.0
5,-1,29:100.0
6,-1,29:159.10
7,-1,29:159.10
8,-1,29:159.10
-3,0,29:159.10
-2,0,29:159.10
-1,0,29:100.0
0,0,29:100.0
1,0,29:100.0
2,0,29:100.0
3,0,29:159.10
4,0,29:100.0
5,0,29:159.10
6,0,29:159.10
7,0,29:159.10
-3,1,29:159.10
-2,1,29:159.10
-1,1,29:159.10
0,1,29:100.0
1,1,29:100.0
2,1,29:100.0
3,1,29:100.0
4,1,29:159.10
5,1,29:159.10
6,1,29:159.10
-2,2,29:159.10
-1,2,29:159.10
1,2,29:159.10
2,2,29:159.10
3,2,29:159.10
4,2,29:159.10
5,2,29:159.10
-1,3,29:159.10
0,3,29:159.10
1,3,29:159.10
2,3,29:159.10
3,3,29:159.10
4,3,29:159.10
-1,-7,30:159.10
0,-7,30:159.10
1,-7,30:159.10
2,-7,30:159.10
3,-7,30:159.10
5,-7,30:159.10
-1,-6,30:82.0
0,-6,30:82.0
1,-6,30:82.0
2,-6,30:159.10
3,-6,30:159.10
4,-6,30:159.10
5,-6,30:159.10
-2,-5,30:82.0
-1,-5,30:82.0
0,-5,30:82.0
1,-5,30:82.0
2,-5,30:82.0
3,-5,30:159.10
4,-5,30:159.10
5,-5,30:159.10
-2,-4,30:82.0
-1,-4,30:82.0
0,-4,30:82.0
1,-4,30:100.0
2,-4,30:100.0
3,-4,30:159.10
4,-4,30:159.10
5,-4,30:159.10
-3,-3,30:159.10
-2,-3,30:82.0
-1,-3,30:82.0
0,-3,30:82.0
1,-3,30:100.0
2,-3,30:82.0
3,-3,30:159.10
4,-3,30:159.10
5,-3,30:159.10
6,-3,30:159.10
-2,-2,30:159.10
-1,-2,30:82.0
0,-2,30:82.0
1,-2,30:82.0
2,-2,30:159.10
4,-2,30:159.10
5,-2,30:159.10
6,-2,30:159.10
-2,-1,30:159.10
-1,-1,30:159.10
0,-1,30:159.10
1,-1,30:159.10
2,-1,30:159.10
3,-1,30:159.10
4,-1,30:159.10
5,-1,30:159.10
-1,0,30:159.10
0,0,30:159.10
1,0,30:159.10
2,0,30:159.10
3,0,30:159.10
4,0,30:82.0
0,1,30:159.10
1,1,30:159.10
2,1,30:159.10
3,1,30:82.0
4,1,30:82.0
4,2,30:82.0
5,-6,31:159.10
4,-5,31:159.10
5,-5,31:159.10
1,-4,31:82.0
2,-4,31:82.0
3,-4,31:159.10
4,-4,31:159.10
-2,-3,31:82.0
-1,-3,31:82.0
0,-3,31:82.0
1,-3,31:82.0
2,-3,31:82.0
3,-3,31:159.10
4,-3,31:159.10
0,-2,31:82.0
1,-2,31:82.0
2,-2,31:159.10
4,-2,31:159.10
1,-1,31:159.10
2,-1,31:159.10
3,-1,31:159.10
3,0,31:82.0
4,1,31:82.0
4,2,31:82.0
4,-4,32:159.10
-1,-3,32:82.0
0,-2,32:159.10
