[META]
version=2.0
spawnOnBlockType=2
spawnSunlight=True
spawnDarkness=True
spawnWater=False
spawnLava=False
underFill=False
randomRotation=True
dig=True
tree=False
branch=False
needsFoundation=True
rarity=100
collisionPercentage=20
spawnElevationMin=0
spawnElevationMax=200
spawnInBiome=Custom
[DATA]
2,-10,-6:100.15
3,-10,-6:100.15
0,-9,-6:100.15
1,-9,-6:100.15
2,-9,-6:100.15
4,-9,-6:100.15
-2,-8,-6:100.15
-1,-8,-6:100.15
0,-8,-6:100.15
1,-8,-6:100.15
2,-8,-6:100.15
3,-8,-6:100.15
4,-8,-6:100.15
5,-8,-6:100.15
-2,-7,-6:100.15
-1,-7,-6:100.15
0,-7,-6:100.15
1,-7,-6:100.15
2,-7,-6:100.15
3,-7,-6:100.15
5,-7,-6:100.15
7,-7,-6:100.15
-5,-6,-6:100.15
-4,-6,-6:100.15
-2,-6,-6:100.15
-1,-6,-6:100.15
0,-6,-6:100.15
1,-6,-6:100.15
2,-6,-6:100.15
3,-6,-6:100.15
4,-6,-6:100.15
5,-6,-6:100.15
6,-6,-6:100.15
-6,-5,-6:100.15
-5,-5,-6:100.15
-4,-5,-6:100.15
-3,-5,-6:100.15
-2,-5,-6:100.15
-1,-5,-6:100.15
0,-5,-6:100.15
1,-5,-6:100.15
3,-5,-6:100.15
4,-5,-6:100.15
5,-5,-6:100.15
6,-5,-6:100.15
-7,-4,-6:100.15
-5,-4,-6:100.15
-4,-4,-6:100.15
-3,-4,-6:100.15
-2,-4,-6:100.15
1,-4,-6:100.15
3,-4,-6:100.15
4,-4,-6:100.15
5,-4,-6:100.15
6,-4,-6:100.15
7,-4,-6:100.15
-8,-3,-6:100.15
-6,-3,-6:100.15
-5,-3,-6:100.15
-4,-3,-6:100.15
-3,-3,-6:100.15
2,-3,-6:100.15
3,-3,-6:100.15
4,-3,-6:100.15
5,-3,-6:100.15
-8,-2,-6:100.15
-7,-2,-6:100.15
-6,-2,-6:100.15
-3,-2,-6:100.15
-2,-2,-6:100.15
0,-2,-6:100.15
1,-2,-6:100.15
2,-2,-6:100.15
3,-2,-6:100.15
5,-2,-6:100.15
7,-2,-6:100.15
-6,-1,-6:100.15
-5,-1,-6:100.15
-4,-1,-6:100.15
-3,-1,-6:100.15
-2,-1,-6:100.15
0,-1,-6:100.15
1,-1,-6:100.15
3,-1,-6:100.15
4,-1,-6:100.15
5,-1,-6:100.15
6,-1,-6:100.15
7,-1,-6:100.15
-6,0,-6:100.15
-5,0,-6:100.15
-4,0,-6:100.15
-3,0,-6:100.15
-1,0,-6:100.15
1,0,-6:100.15
6,0,-6:100.15
7,0,-6:100.15
8,0,-6:100.15
-7,1,-6:100.15
-6,1,-6:100.15
-5,1,-6:100.15
-4,1,-6:100.15
-3,1,-6:100.15
-2,1,-6:100.15
1,1,-6:100.15
4,1,-6:100.15
6,1,-6:100.15
7,1,-6:100.15
-5,2,-6:100.15
-4,2,-6:100.15
-3,2,-6:100.15
-1,2,-6:100.15
0,2,-6:100.15
1,2,-6:100.15
2,2,-6:100.15
3,2,-6:100.15
4,2,-6:100.15
6,2,-6:100.15
7,2,-6:100.15
8,2,-6:100.15
9,2,-6:100.15
-5,3,-6:100.15
-4,3,-6:100.15
-3,3,-6:100.15
-2,3,-6:100.15
-1,3,-6:100.15
0,3,-6:100.15
1,3,-6:100.15
2,3,-6:100.15
3,3,-6:100.15
5,3,-6:100.15
7,3,-6:100.15
-4,4,-6:100.15
-3,4,-6:100.15
-2,4,-6:100.15
-1,4,-6:100.15
0,4,-6:100.15
1,4,-6:100.15
2,4,-6:100.15
3,4,-6:100.15
4,4,-6:100.15
5,4,-6:100.15
6,4,-6:100.15
-3,5,-6:100.15
-1,5,-6:100.15
0,5,-6:100.15
1,5,-6:100.15
2,5,-6:100.15
3,5,-6:100.15
4,5,-6:100.15
5,5,-6:100.15
6,5,-6:100.15
-2,6,-6:100.15
-1,6,-6:100.15
0,6,-6:100.15
1,6,-6:100.15
2,6,-6:100.15
-2,7,-6:100.15
-1,7,-6:100.15
0,7,-6:100.15
0,8,-6:100.15
-1,-9,-5:100.15
0,-9,-5:100.15
1,-9,-5:100.15
2,-9,-5:100.15
-2,-8,-5:100.15
-1,-8,-5:100.15
0,-8,-5:100.15
2,-8,-5:100.15
3,-8,-5:100.15
4,-8,-5:100.15
5,-8,-5:100.15
-4,-7,-5:100.15
-2,-7,-5:100.15
-1,-7,-5:100.15
0,-7,-5:100.15
1,-7,-5:100.15
2,-7,-5:100.15
3,-7,-5:100.15
4,-7,-5:100.15
6,-7,-5:100.15
7,-7,-5:100.15
-4,-6,-5:100.15
-3,-6,-5:100.15
-2,-6,-5:100.15
-1,-6,-5:100.15
0,-6,-5:100.15
1,-6,-5:100.15
3,-6,-5:100.15
4,-6,-5:100.15
5,-6,-5:100.15
6,-6,-5:100.15
7,-6,-5:100.15
-5,-5,-5:100.15
-4,-5,-5:100.15
-3,-5,-5:100.15
-2,-5,-5:100.15
-1,-5,-5:100.15
1,-5,-5:100.15
2,-5,-5:100.15
3,-5,-5:100.15
4,-5,-5:100.15
5,-5,-5:100.15
-6,-4,-5:100.15
-5,-4,-5:100.15
-4,-4,-5:100.15
-3,-4,-5:100.15
-2,-4,-5:100.15
-1,-4,-5:100.15
0,-4,-5:100.15
1,-4,-5:100.15
2,-4,-5:100.15
3,-4,-5:100.15
4,-4,-5:100.15
5,-4,-5:100.15
6,-4,-5:100.15
-8,-3,-5:100.15
-7,-3,-5:100.15
-5,-3,-5:100.15
-4,-3,-5:100.15
-3,-3,-5:100.15
0,-3,-5:100.15
1,-3,-5:100.15
2,-3,-5:100.15
3,-3,-5:100.15
4,-3,-5:100.15
5,-3,-5:100.15
6,-3,-5:100.15
7,-3,-5:100.15
-8,-2,-5:100.15
-6,-2,-5:100.15
-5,-2,-5:100.15
-4,-2,-5:100.15
-3,-2,-5:100.15
1,-2,-5:100.15
2,-2,-5:100.15
3,-2,-5:100.15
4,-2,-5:100.15
5,-2,-5:100.15
6,-2,-5:100.15
7,-2,-5:100.15
-8,-1,-5:100.15
-7,-1,-5:100.15
-6,-1,-5:100.15
-5,-1,-5:100.15
-4,-1,-5:100.15
-3,-1,-5:100.15
1,-1,-5:100.15
2,-1,-5:100.15
3,-1,-5:100.15
4,-1,-5:100.15
6,-1,-5:100.15
7,-1,-5:100.15
8,-1,-5:100.15
-7,0,-5:100.15
-5,0,-5:100.15
-4,0,-5:100.15
-3,0,-5:100.15
1,0,-5:100.15
4,0,-5:100.15
5,0,-5:100.15
6,0,-5:100.15
7,0,-5:100.15
8,0,-5:100.15
-7,1,-5:100.15
-6,1,-5:100.15
-4,1,-5:100.15
-2,1,-5:100.15
2,1,-5:100.15
5,1,-5:100.15
6,1,-5:100.15
8,1,-5:100.15
-5,2,-5:100.15
-4,2,-5:100.15
-3,2,-5:100.15
-2,2,-5:100.15
-1,2,-5:100.15
0,2,-5:100.15
1,2,-5:100.15
2,2,-5:100.15
4,2,-5:100.15
5,2,-5:100.15
6,2,-5:100.15
7,2,-5:100.15
8,2,-5:100.15
9,2,-5:100.15
-5,3,-5:100.15
-3,3,-5:100.15
-1,3,-5:100.15
0,3,-5:100.15
1,3,-5:100.15
2,3,-5:100.15
3,3,-5:100.15
4,3,-5:100.15
5,3,-5:100.15
6,3,-5:100.15
7,3,-5:100.15
8,3,-5:100.15
9,3,-5:100.15
-6,4,-5:100.15
-5,4,-5:100.15
-4,4,-5:100.15
-3,4,-5:100.15
-2,4,-5:100.15
-1,4,-5:100.15
0,4,-5:100.15
1,4,-5:100.15
2,4,-5:100.15
3,4,-5:100.15
4,4,-5:100.15
5,4,-5:100.15
6,4,-5:100.15
7,4,-5:100.15
8,4,-5:100.15
-5,5,-5:100.15
-4,5,-5:100.15
-3,5,-5:100.15
-2,5,-5:100.15
-1,5,-5:100.15
1,5,-5:100.15
2,5,-5:100.15
3,5,-5:100.15
5,5,-5:100.15
1,6,-5:100.15
2,6,-5:100.15
0,7,-5:100.15
1,8,-5:100.15
1,-8,-4:100.15
2,-8,-4:100.15
4,-8,-4:100.15
5,-8,-4:100.15
-2,-7,-4:100.15
-1,-7,-4:100.15
0,-7,-4:100.15
1,-7,-4:100.15
3,-7,-4:100.15
-2,-6,-4:100.15
-1,-6,-4:100.15
0,-6,-4:100.15
1,-6,-4:100.15
2,-6,-4:100.15
3,-6,-4:100.15
4,-6,-4:100.15
5,-6,-4:100.15
6,-6,-4:100.15
-5,-5,-4:100.15
-4,-5,-4:100.15
-2,-5,-4:100.15
1,-5,-4:100.15
2,-5,-4:100.15
3,-5,-4:100.15
4,-5,-4:100.15
5,-5,-4:100.15
-6,-4,-4:100.15
-5,-4,-4:100.15
-4,-4,-4:100.15
-2,-4,-4:100.15
3,-4,-4:100.15
4,-4,-4:100.15
5,-4,-4:100.15
-8,-3,-4:100.15
-4,-3,-4:100.15
-2,-3,-4:100.15
0,-3,-4:100.15
1,-3,-4:100.15
2,-3,-4:100.15
3,-3,-4:100.15
-4,-2,-4:100.15
-3,-2,-4:100.15
-2,-2,-4:100.15
0,-2,-4:100.15
1,-2,-4:100.15
3,-2,-4:100.15
5,-2,-4:100.15
7,-2,-4:100.15
-7,-1,-4:100.15
-3,-1,-4:100.15
1,-1,-4:100.15
2,-1,-4:100.15
3,-1,-4:100.15
5,-1,-4:100.15
-7,0,-4:100.15
-6,0,-4:100.15
-4,0,-4:100.15
-3,0,-4:100.15
1,0,-4:100.15
2,0,-4:100.15
3,0,-4:100.15
4,0,-4:100.15
6,0,-4:100.15
8,0,-4:100.15
-2,1,-4:100.15
1,1,-4:100.15
5,1,-4:100.15
6,1,-4:100.15
7,1,-4:100.15
-7,2,-4:100.15
-6,2,-4:100.15
-5,2,-4:100.15
-4,2,-4:100.15
-3,2,-4:100.15
-2,2,-4:100.15
3,2,-4:100.15
4,2,-4:100.15
5,2,-4:100.15
6,2,-4:100.15
9,2,-4:100.15
-5,3,-4:100.15
-4,3,-4:100.15
-3,3,-4:100.15
-1,3,-4:100.15
0,3,-4:100.15
1,3,-4:100.15
2,3,-4:100.15
3,3,-4:100.15
4,3,-4:100.15
5,3,-4:100.15
6,3,-4:100.15
-5,4,-4:100.15
-4,4,-4:100.15
-3,4,-4:100.15
-2,4,-4:100.15
-1,4,-4:100.15
1,4,-4:100.15
2,4,-4:100.15
5,4,-4:100.15
7,4,-4:100.15
-5,5,-4:100.15
-4,5,-4:100.15
-2,5,-4:100.15
-1,5,-4:100.15
0,5,-4:100.15
1,5,-4:100.15
2,5,-4:100.15
0,6,-4:100.15
1,6,-4:100.15
2,6,-4:100.15
-1,7,-4:100.15
0,7,-4:100.15
1,7,-4:100.15
-4,-9,-3:100.15
3,-9,-3:100.15
4,-9,-3:100.15
-5,-8,-3:100.15
-4,-8,-3:100.15
-3,-8,-3:100.15
-2,-8,-3:100.15
-1,-8,-3:100.15
0,-8,-3:100.15
1,-8,-3:100.15
2,-8,-3:100.15
3,-8,-3:100.15
4,-8,-3:100.15
5,-8,-3:100.15
6,-8,-3:100.15
-5,-7,-3:100.15
6,-7,-3:100.15
7,-7,-3:100.15
8,-7,-3:100.15
-5,-6,-3:100.15
5,-6,-3:100.15
7,-6,-3:100.15
8,-6,-3:100.15
-5,-5,-3:100.15
-2,-5,-3:100.15
2,-5,-3:100.15
3,-5,-3:100.15
4,-5,-3:100.15
5,-5,-3:100.15
7,-5,-3:100.15
-6,-4,-3:100.15
-4,-4,-3:100.15
-3,-4,-3:100.15
-2,-4,-3:100.15
1,-4,-3:100.15
3,-4,-3:100.15
4,-4,-3:100.15
5,-4,-3:100.15
6,-4,-3:100.15
7,-4,-3:100.15
-7,-3,-3:100.15
-6,-3,-3:100.15
-5,-3,-3:100.15
-4,-3,-3:100.15
0,-3,-3:100.15
1,-3,-3:100.15
2,-3,-3:100.15
4,-3,-3:100.15
5,-3,-3:100.15
7,-3,-3:100.15
-8,-2,-3:100.15
-7,-2,-3:100.15
-6,-2,-3:100.15
-5,-2,-3:100.15
0,-2,-3:100.15
1,-2,-3:100.15
2,-2,-3:100.15
4,-2,-3:100.15
5,-2,-3:100.15
7,-2,-3:100.15
-9,-1,-3:100.15
-8,-1,-3:100.15
-7,-1,-3:100.15
-6,-1,-3:100.15
-5,-1,-3:100.15
-4,-1,-3:100.15
-3,-1,-3:100.15
-2,-1,-3:100.15
-1,-1,-3:100.15
0,-1,-3:100.15
1,-1,-3:100.15
2,-1,-3:100.15
3,-1,-3:100.15
4,-1,-3:100.15
5,-1,-3:100.15
6,-1,-3:100.15
7,-1,-3:100.15
-8,0,-3:100.15
-7,0,-3:100.15
3,0,-3:100.15
6,0,-3:100.15
7,0,-3:100.15
8,0,-3:100.15
-7,1,-3:100.15
-6,1,-3:100.15
0,1,-3:100.15
1,1,-3:100.15
2,1,-3:100.15
8,1,-3:100.15
-6,2,-3:100.15
-5,2,-3:100.15
1,2,-3:100.15
5,2,-3:100.15
7,2,-3:100.15
8,2,-3:100.15
-6,3,-3:100.15
-5,3,-3:100.15
-4,3,-3:100.15
1,3,-3:100.15
2,3,-3:100.15
4,3,-3:100.15
7,3,-3:100.15
8,3,-3:100.15
9,3,-3:100.15
-6,4,-3:100.15
-5,4,-3:100.15
-4,4,-3:100.15
0,4,-3:100.15
1,4,-3:100.15
2,4,-3:100.15
3,4,-3:100.15
4,4,-3:100.15
5,4,-3:100.15
6,4,-3:100.15
7,4,-3:100.15
8,4,-3:100.15
9,4,-3:100.15
-6,5,-3:100.15
-5,5,-3:100.15
-4,5,-3:100.15
1,5,-3:100.15
2,5,-3:100.15
3,5,-3:100.15
-5,6,-3:100.15
-4,6,-3:100.15
-3,6,-3:100.15
-2,6,-3:100.15
-1,6,-3:100.15
0,6,-3:100.15
1,6,-3:100.15
-1,7,-3:100.15
1,-10,-2:100.0
2,-10,-2:100.0
3,-10,-2:100.0
4,-10,-2:100.0
5,-10,-2:100.0
6,-10,-2:100.0
0,-9,-2:100.0
1,-9,-2:100.0
2,-9,-2:100.0
3,-9,-2:159.10
4,-9,-2:159.10
5,-9,-2:100.0
6,-9,-2:100.0
-5,-8,-2:100.15
-4,-8,-2:100.15
-3,-8,-2:100.15
-2,-8,-2:100.15
-1,-8,-2:100.15
0,-8,-2:100.15
1,-8,-2:100.15
2,-8,-2:100.15
3,-8,-2:100.15
4,-8,-2:159.10
5,-8,-2:100.15
-5,-7,-2:100.15
6,-7,-2:100.15
7,-7,-2:100.15
-5,-6,-2:100.15
7,-6,-2:100.15
-5,-5,-2:100.15
7,-5,-2:100.15
-6,-4,-2:100.15
7,-4,-2:100.15
-7,-3,-2:100.15
-6,-3,-2:100.15
1,-3,-2:100.15
2,-3,-2:100.15
3,-3,-2:100.15
7,-3,-2:100.15
-8,-2,-2:100.15
-7,-2,-2:100.15
2,-2,-2:100.15
3,-2,-2:100.15
7,-2,-2:100.15
-8,-1,-2:100.15
-1,-1,-2:100.15
0,-1,-2:100.15
1,-1,-2:100.15
2,-1,-2:100.15
3,-1,-2:100.15
7,-1,-2:100.15
-7,0,-2:100.15
2,0,-2:100.15
-7,1,-2:100.15
2,1,-2:100.15
7,1,-2:100.15
-6,2,-2:100.15
-5,2,-2:100.15
8,2,-2:159.10
-6,3,-2:100.15
-5,3,-2:100.15
-4,3,-2:100.15
8,3,-2:100.15
-4,4,-2:100.15
-3,4,-2:100.15
2,4,-2:100.15
3,4,-2:100.15
4,4,-2:100.15
5,4,-2:100.15
6,4,-2:100.15
7,4,-2:100.15
8,4,-2:100.15
-4,5,-2:100.15
-3,5,-2:100.15
-2,5,-2:100.15
-1,5,-2:100.15
0,5,-2:100.15
1,5,-2:100.15
2,5,-2:159.10
3,5,-2:159.10
4,5,-2:100.15
5,5,-2:100.0
6,5,-2:100.0
-3,6,-2:100.0
-2,6,-2:100.15
-1,6,-2:100.15
0,6,-2:100.15
1,6,-2:159.10
2,6,-2:100.0
3,6,-2:100.0
4,6,-2:100.0
5,6,-2:100.0
2,7,-2:100.0
3,7,-2:100.0
4,7,-2:100.0
2,8,-2:100.0
3,8,-2:100.0
4,8,-2:100.0
2,-10,-1:159.10
3,-10,-1:82.0
4,-10,-1:159.10
0,-9,-1:159.10
1,-9,-1:159.10
2,-9,-1:82.0
3,-9,-1:82.0
4,-9,-1:82.0
5,-9,-1:159.10
6,-9,-1:159.10
-5,-8,-1:100.15
-4,-8,-1:100.15
-3,-8,-1:100.15
-2,-8,-1:100.15
-1,-8,-1:100.15
0,-8,-1:100.15
1,-8,-1:100.15
2,-8,-1:100.15
3,-8,-1:100.15
4,-8,-1:100.15
5,-8,-1:100.15
-5,-7,-1:100.15
0,-7,-1:100.15
5,-7,-1:100.15
6,-7,-1:100.15
7,-7,-1:100.15
-5,-6,-1:100.15
7,-6,-1:100.15
-5,-5,-1:100.15
7,-5,-1:100.15
9,-5,-1:100.0
-6,-4,-1:100.15
-5,-4,-1:100.15
7,-4,-1:100.15
9,-4,-1:100.0
-6,-3,-1:100.15
6,-3,-1:100.15
7,-3,-1:100.15
8,-3,-1:100.0
9,-3,-1:100.0
-7,-2,-1:100.15
6,-2,-1:100.15
7,-2,-1:100.15
8,-2,-1:100.0
9,-2,-1:100.0
-9,-1,-1:100.0
-8,-1,-1:100.15
-7,-1,-1:100.15
1,-1,-1:100.15
7,-1,-1:100.15
8,-1,-1:100.0
9,-1,-1:100.0
10,-1,-1:100.0
-9,0,-1:100.0
-8,0,-1:100.0
-7,0,-1:100.15
2,0,-1:100.15
7,0,-1:100.0
8,0,-1:100.0
9,0,-1:100.0
-9,1,-1:100.0
-8,1,-1:100.0
-7,1,-1:159.10
-6,1,-1:100.15
7,1,-1:100.15
8,1,-1:100.0
9,1,-1:100.0
-6,2,-1:159.10
-5,2,-1:100.15
7,2,-1:100.15
8,2,-1:159.10
9,2,-1:100.0
10,2,-1:100.0
-9,3,-1:100.0
-7,3,-1:100.0
-6,3,-1:159.10
-5,3,-1:159.10
-4,3,-1:100.15
-3,3,-1:100.15
5,3,-1:100.15
6,3,-1:100.15
7,3,-1:100.15
8,3,-1:159.10
9,3,-1:100.0
10,3,-1:100.0
-9,4,-1:100.0
-8,4,-1:100.0
-7,4,-1:100.0
-6,4,-1:100.0
-4,4,-1:159.10
-3,4,-1:100.15
-2,4,-1:100.15
-1,4,-1:100.15
1,4,-1:100.15
2,4,-1:100.15
3,4,-1:100.15
4,4,-1:100.15
5,4,-1:100.15
10,4,-1:100.0
-6,5,-1:100.0
-5,5,-1:100.0
-4,5,-1:159.10
-3,5,-1:159.10
-2,5,-1:100.15
-1,5,-1:100.15
0,5,-1:100.15
1,5,-1:100.15
2,5,-1:159.10
3,5,-1:100.15
4,5,-1:100.15
5,5,-1:159.10
-6,6,-1:100.0
-5,6,-1:100.0
-4,6,-1:100.0
-3,6,-1:159.10
-2,6,-1:159.10
1,6,-1:159.10
2,6,-1:159.10
3,6,-1:159.10
4,6,-1:159.10
1,7,-1:100.0
2,7,-1:159.10
3,7,-1:159.10
3,8,-1:159.10
4,8,-1:159.10
3,-10,0:82.0
2,-9,0:82.0
3,-9,0:82.0
4,-9,0:82.0
-4,-8,0:100.15
-3,-8,0:100.15
0,-8,0:100.15
1,-8,0:100.15
2,-8,0:100.15
3,-8,0:100.15
4,-8,0:82.0
-5,-7,0:100.15
-4,-7,0:100.15
-3,-7,0:100.15
-2,-7,0:100.15
-1,-7,0:100.15
4,-7,0:100.15
5,-7,0:100.15
6,-7,0:100.15
-5,-6,0:100.15
-4,-6,0:100.15
6,-6,0:100.15
7,-6,0:100.15
-5,-5,0:100.15
6,-5,0:100.15
7,-5,0:100.15
-5,-4,0:100.15
6,-4,0:100.15
-6,-3,0:100.15
-5,-3,0:100.15
6,-3,0:100.15
8,-3,0:159.10
9,-3,0:159.10
-7,-2,0:100.15
-6,-2,0:100.15
6,-2,0:100.15
7,-2,0:100.15
8,-2,0:82.0
9,-2,0:82.0
-7,-1,0:100.15
-6,-1,0:100.15
7,-1,0:100.15
8,-1,0:82.0
9,-1,0:82.0
10,-1,0:159.10
-10,0,0:100.0
-7,0,0:100.15
-6,0,0:100.15
7,0,0:100.15
8,0,0:82.0
9,0,0:82.0
-9,1,0:159.10
-8,1,0:159.10
-7,1,0:159.10
-6,1,0:100.15
7,1,0:100.15
8,1,0:159.10
-9,2,0:100.0
-7,2,0:100.0
-6,2,0:100.15
-5,2,0:100.15
-4,2,0:100.15
7,2,0:100.15
8,2,0:159.10
9,2,0:159.10
-9,3,0:159.10
-8,3,0:100.0
-7,3,0:159.10
-6,3,0:159.10
-4,3,0:100.15
-3,3,0:100.15
4,3,0:100.15
5,3,0:100.15
6,3,0:100.15
7,3,0:100.15
9,3,0:159.10
-9,4,0:159.10
-8,4,0:159.10
-7,4,0:159.10
-6,4,0:159.10
-2,4,0:100.15
-1,4,0:100.15
0,4,0:100.15
1,4,0:100.15
2,4,0:100.15
3,4,0:100.15
-6,5,0:159.10
-5,5,0:159.10
-4,5,0:159.10
-3,5,0:159.10
0,5,0:100.15
2,5,0:100.15
3,5,0:100.15
-3,6,0:159.10
-2,6,0:159.10
2,6,0:159.10
3,6,0:159.10
1,7,0:159.10
2,7,0:159.10
-1,-8,1:100.15
0,-8,1:100.15
1,-8,1:100.15
2,-8,1:100.15
-3,-7,1:100.15
-2,-7,1:100.15
-1,-7,1:100.15
2,-7,1:100.15
3,-7,1:100.15
4,-7,1:100.15
-4,-6,1:100.15
-3,-6,1:100.15
4,-6,1:100.15
5,-6,1:100.15
6,-6,1:100.15
-5,-5,1:100.15
-4,-5,1:100.15
6,-5,1:100.15
-5,-4,1:100.15
6,-4,1:100.15
-5,-3,1:100.15
6,-3,1:100.15
-6,-2,1:100.15
-5,-2,1:100.15
6,-2,1:100.15
7,-2,1:100.15
-6,-1,1:100.15
-5,-1,1:100.15
6,-1,1:100.15
7,-1,1:100.15
-10,0,1:159.10
-9,0,1:100.0
-6,0,1:100.15
-5,0,1:100.15
6,0,1:100.15
7,0,1:100.15
-9,1,1:159.10
-8,1,1:159.10
-7,1,1:159.10
-6,1,1:159.10
-5,1,1:100.15
6,1,1:100.15
-8,2,1:100.0
-7,2,1:159.10
-5,2,1:100.15
-4,2,1:100.15
5,2,1:100.15
6,2,1:100.15
-9,3,1:159.10
-8,3,1:159.10
-7,3,1:159.10
-6,3,1:159.10
-4,3,1:100.15
-3,3,1:100.15
-2,3,1:100.15
3,3,1:100.15
4,3,1:100.15
5,3,1:100.15
-9,4,1:159.10
-6,4,1:159.10
-2,4,1:100.15
-1,4,1:100.15
0,4,1:100.15
1,4,1:100.15
2,4,1:100.15
3,4,1:100.15
-5,5,1:159.10
-3,5,1:159.10
1,5,1:100.15
2,5,1:100.15
0,6,1:100.15
1,6,1:100.15
0,7,1:100.15
0,8,1:100.15
0,9,1:100.15
1,10,1:100.15
1,11,1:100.15
-1,-8,2:100.15
0,-8,2:100.15
1,-8,2:100.15
2,-8,2:100.15
-3,-7,2:100.15
-2,-7,2:100.15
-1,-7,2:100.15
2,-7,2:100.15
3,-7,2:100.15
4,-7,2:100.15
-4,-6,2:100.15
-3,-6,2:100.15
4,-6,2:100.15
5,-6,2:100.15
-5,-5,2:100.15
6,-5,2:100.15
-5,-4,2:100.15
6,-4,2:100.15
-5,-3,2:100.15
6,-3,2:100.15
-5,-2,2:100.15
6,-2,2:100.15
-5,-1,2:100.15
6,-1,2:100.15
-9,0,2:159.10
-5,0,2:100.15
6,0,2:100.15
-5,1,2:100.15
5,1,2:100.15
6,1,2:100.15
-8,2,2:159.10
-5,2,2:100.15
4,2,2:100.15
5,2,2:100.15
-9,3,2:159.10
-4,3,2:100.15
2,3,2:100.15
3,3,2:100.15
4,3,2:100.15
-3,4,2:100.15
-2,4,2:100.15
-1,4,2:100.15
0,4,2:100.15
1,4,2:100.15
2,4,2:100.15
-1,5,2:100.0
0,5,2:100.0
1,5,2:159.10
-3,6,2:100.0
-2,6,2:100.0
-1,6,2:100.0
0,6,2:159.10
1,6,2:159.10
2,6,2:100.0
-4,7,2:100.0
-3,7,2:100.0
-2,7,2:100.0
0,7,2:159.10
1,7,2:100.0
2,7,2:100.0
3,7,2:100.0
-4,8,2:100.0
-3,8,2:100.0
-2,8,2:100.0
-1,8,2:100.0
0,8,2:159.10
1,8,2:100.0
2,8,2:100.0
3,8,2:100.0
-4,9,2:100.0
-3,9,2:100.0
-2,9,2:100.0
-1,9,2:100.0
0,9,2:100.15
2,9,2:100.0
3,9,2:100.0
-4,10,2:100.0
-3,10,2:100.0
-2,10,2:100.15
-1,10,2:100.0
0,10,2:100.0
1,10,2:159.10
2,10,2:100.0
3,10,2:100.0
-5,11,2:100.0
-4,11,2:100.0
-3,11,2:100.0
-1,11,2:100.0
1,11,2:100.15
2,11,2:100.0
-4,12,2:100.0
-3,12,2:100.0
-2,12,2:100.0
-1,12,2:100.0
0,12,2:100.0
1,12,2:100.0
2,12,2:100.0
-3,13,2:100.0
-2,13,2:100.0
-1,13,2:100.0
0,13,2:100.0
-1,-8,3:100.15
0,-8,3:100.15
1,-8,3:100.15
-3,-7,3:100.15
-2,-7,3:100.15
-1,-7,3:100.15
2,-7,3:100.15
3,-7,3:100.15
4,-7,3:100.15
-4,-6,3:100.15
-3,-6,3:100.15
4,-6,3:100.15
5,-6,3:100.15
-5,-5,3:100.15
5,-5,3:100.15
6,-5,3:100.15
-5,-4,3:100.15
6,-4,3:100.15
-5,-3,3:100.15
6,-3,3:100.15
-5,-2,3:100.15
6,-2,3:100.15
-6,-1,3:100.15
-5,-1,3:100.15
6,-1,3:100.15
-6,0,3:100.15
-5,0,3:100.15
5,0,3:100.15
6,0,3:100.15
-6,1,3:100.15
5,1,3:100.15
-6,2,3:100.15
-5,2,3:100.15
3,2,3:100.15
4,2,3:100.15
-4,3,3:100.15
-3,3,3:100.15
1,3,3:100.15
2,3,3:100.15
3,3,3:100.15
-3,4,3:100.15
-2,4,3:100.15
-1,4,3:100.15
0,4,3:100.15
0,5,3:159.10
-2,6,3:159.10
-1,6,3:159.10
0,6,3:159.10
1,6,3:159.10
-3,7,3:159.10
-2,7,3:159.10
-1,7,3:100.0
0,7,3:159.10
1,7,3:159.10
2,7,3:159.10
3,7,3:159.10
-3,8,3:159.10
-2,8,3:159.10
-1,8,3:159.10
0,8,3:159.10
1,8,3:159.10
2,8,3:159.10
-4,9,3:159.10
-3,9,3:159.10
-2,9,3:159.10
-1,9,3:159.10
0,9,3:159.10
1,9,3:100.0
2,9,3:159.10
-4,10,3:159.10
-3,10,3:159.10
-2,10,3:159.10
-1,10,3:159.10
0,10,3:159.10
1,10,3:159.10
2,10,3:159.10
-4,11,3:159.10
-3,11,3:159.10
-2,11,3:100.0
-1,11,3:159.10
0,11,3:100.0
1,11,3:159.10
2,11,3:159.10
-3,12,3:159.10
-2,12,3:159.10
-1,12,3:159.10
0,12,3:159.10
-2,13,3:159.10
0,-8,4:100.15
1,-8,4:100.15
-2,-7,4:100.15
-1,-7,4:100.15
2,-7,4:100.15
3,-7,4:100.15
-4,-6,4:100.15
-3,-6,4:100.15
-2,-6,4:100.15
4,-6,4:100.15
5,-6,4:100.15
-5,-5,4:100.15
-4,-5,4:100.15
5,-5,4:100.15
-5,-4,4:100.15
5,-4,4:100.15
6,-4,4:100.15
-5,-3,4:100.15
6,-3,4:100.15
-6,-2,4:100.15
6,-2,4:100.15
-6,-1,4:100.15
-5,-1,4:100.15
6,-1,4:100.15
-7,0,4:100.15
-6,0,4:100.15
-5,0,4:100.15
5,0,4:100.15
6,0,4:100.15
-8,1,4:100.15
-7,1,4:100.15
3,1,4:100.15
4,1,4:100.15
5,1,4:100.15
-8,2,4:100.15
-7,2,4:100.15
-6,2,4:100.15
1,2,4:100.15
2,2,4:100.15
3,2,4:100.15
4,2,4:100.15
-8,3,4:100.15
-7,3,4:100.15
-6,3,4:100.15
-5,3,4:100.15
-4,3,4:100.15
-3,3,4:100.15
0,3,4:100.15
1,3,4:100.15
2,3,4:100.15
-3,4,4:100.15
-2,4,4:100.15
-1,4,4:100.15
0,4,4:100.15
-2,8,4:159.10
-1,8,4:159.10
0,8,4:159.10
1,8,4:159.10
-2,9,4:159.10
-1,9,4:159.10
0,9,4:82.0
-4,10,4:100.0
-3,10,4:100.0
-2,10,4:159.10
-1,10,4:82.0
0,10,4:82.0
-4,11,4:100.0
-3,11,4:159.10
-2,11,4:100.0
-1,11,4:100.15
0,11,4:100.0
-5,12,4:100.0
-4,12,4:100.0
-3,12,4:159.10
-2,12,4:159.10
-1,12,4:100.15
0,12,4:100.15
1,12,4:100.0
-4,13,4:100.0
-3,13,4:100.15
-2,13,4:100.15
-1,13,4:100.0
0,13,4:100.0
-4,14,4:100.15
-3,14,4:100.0
-2,14,4:100.0
-1,14,4:100.0
0,14,4:100.0
-4,15,4:100.0
-2,15,4:100.0
0,-8,5:100.15
1,-8,5:100.15
-1,-7,5:100.15
1,-7,5:100.15
2,-7,5:100.15
3,-7,5:100.15
-3,-6,5:100.15
-2,-6,5:100.15
3,-6,5:100.15
4,-6,5:100.15
-5,-5,5:100.15
-4,-5,5:100.15
-3,-5,5:100.15
-2,-5,5:100.15
4,-5,5:100.15
-6,-4,5:100.15
-5,-4,5:100.15
3,-4,5:100.15
4,-4,5:100.15
5,-4,5:100.15
-6,-3,5:100.15
4,-3,5:100.15
5,-3,5:100.15
6,-3,5:100.15
-6,-2,5:100.15
-5,-2,5:100.15
-4,-2,5:100.15
6,-2,5:100.15
-5,-1,5:100.15
-4,-1,5:100.15
-3,-1,5:100.15
-2,-1,5:100.15
5,-1,5:100.15
6,-1,5:100.15
-5,0,5:100.15
-4,0,5:100.15
-3,0,5:100.15
-2,0,5:100.15
0,0,5:100.15
1,0,5:100.15
2,0,5:100.15
3,0,5:100.15
4,0,5:100.15
5,0,5:100.15
-8,1,5:100.15
-7,1,5:100.15
-6,1,5:100.15
-5,1,5:100.15
-4,1,5:100.15
-3,1,5:100.15
-2,1,5:100.15
0,1,5:100.15
1,1,5:100.15
2,1,5:100.15
3,1,5:100.15
4,1,5:100.15
-9,2,5:100.15
-8,2,5:100.15
-7,2,5:100.15
-6,2,5:100.15
-5,2,5:100.15
-4,2,5:100.15
-3,2,5:100.15
-2,2,5:100.15
0,2,5:100.15
1,2,5:100.15
-9,3,5:100.15
-8,3,5:100.15
-7,3,5:100.15
-6,3,5:100.15
-5,3,5:100.15
-2,3,5:100.15
0,3,5:100.15
-2,4,5:100.15
-1,4,5:100.15
0,4,5:100.15
-4,10,5:159.10
-3,10,5:159.10
-2,10,5:159.10
-1,10,5:82.0
0,10,5:82.0
-5,11,5:100.0
-4,11,5:159.10
-3,11,5:159.10
-2,11,5:159.10
-1,11,5:82.0
0,11,5:82.0
-5,12,5:159.10
-4,12,5:159.10
-3,12,5:159.10
-2,12,5:159.10
-1,12,5:159.10
0,12,5:159.10
-5,13,5:100.0
-4,13,5:159.10
-3,13,5:159.10
-2,13,5:159.10
-1,13,5:159.10
0,13,5:159.10
1,13,5:100.0
-4,14,5:100.0
-3,14,5:159.10
-2,14,5:159.10
-1,14,5:159.10
0,14,5:159.10
1,14,5:100.0
-3,15,5:100.0
-2,15,5:159.10
-1,15,5:100.0
0,15,5:100.0
-2,16,5:100.0
4,-10,6:100.0
-5,-9,6:100.15
-4,-9,6:100.15
-4,-8,6:100.15
0,-8,6:100.15
1,-8,6:100.15
-1,-7,6:100.15
0,-7,6:100.15
1,-7,6:100.15
2,-7,6:100.15
3,-7,6:100.15
-2,-6,6:100.15
-1,-6,6:100.15
3,-6,6:100.15
-3,-5,6:100.15
-2,-5,6:100.15
-1,-5,6:100.15
3,-5,6:100.15
-7,-4,6:100.15
-6,-4,6:100.15
-5,-4,6:100.15
-4,-4,6:100.15
-3,-4,6:100.15
-2,-4,6:100.15
-1,-4,6:100.15
0,-4,6:100.15
2,-4,6:100.15
3,-4,6:100.15
-7,-3,6:100.15
-6,-3,6:100.15
-4,-3,6:100.15
-3,-3,6:100.15
-2,-3,6:100.15
-1,-3,6:100.15
0,-3,6:100.15
1,-3,6:100.15
2,-3,6:100.15
3,-3,6:100.15
4,-3,6:100.15
5,-3,6:100.15
6,-3,6:100.15
-12,-2,6:100.0
-11,-2,6:100.0
-10,-2,6:100.0
-6,-2,6:100.15
-5,-2,6:100.15
-4,-2,6:100.15
-3,-2,6:100.15
-2,-2,6:100.15
-1,-2,6:100.15
0,-2,6:100.15
1,-2,6:100.15
2,-2,6:100.15
3,-2,6:100.15
4,-2,6:100.15
6,-2,6:100.15
-13,-1,6:100.0
-12,-1,6:100.0
-11,-1,6:100.0
-10,-1,6:100.0
-9,-1,6:100.0
-8,-1,6:100.0
-7,-1,6:100.0
-4,-1,6:100.15
-3,-1,6:100.15
-2,-1,6:100.15
-1,-1,6:100.15
0,-1,6:100.15
1,-1,6:100.15
2,-1,6:100.15
3,-1,6:100.15
4,-1,6:100.15
5,-1,6:100.15
6,-1,6:100.15
-14,0,6:100.0
-13,0,6:100.0
-12,0,6:100.0
-9,0,6:100.0
-8,0,6:100.0
-7,0,6:100.0
-6,0,6:100.0
-5,0,6:100.15
-4,0,6:100.15
-3,0,6:100.15
-1,0,6:100.15
0,0,6:100.15
1,0,6:100.15
2,0,6:100.15
3,0,6:100.15
-15,1,6:100.0
-14,1,6:100.0
-13,1,6:100.0
-12,1,6:100.0
-11,1,6:100.0
-7,1,6:159.10
-6,1,6:159.10
-2,1,6:100.15
-1,1,6:100.15
0,1,6:100.15
1,1,6:100.15
-15,2,6:100.0
-14,2,6:100.0
-12,2,6:100.0
-11,2,6:100.0
-10,2,6:100.0
-9,2,6:100.15
-8,2,6:100.15
-7,2,6:159.10
-6,2,6:159.10
-5,2,6:159.10
-2,2,6:100.15
-1,2,6:100.15
0,2,6:100.15
-15,3,6:100.0
-14,3,6:100.0
-10,3,6:100.15
-9,3,6:100.15
-8,3,6:100.15
-7,3,6:159.10
-6,3,6:159.10
-5,3,6:159.10
-4,3,6:159.10
-2,3,6:100.15
-1,3,6:100.15
0,3,6:100.15
-15,4,6:100.0
-14,4,6:100.0
-13,4,6:100.0
-9,4,6:100.0
-7,4,6:100.0
-6,4,6:100.0
-4,4,6:100.0
-2,4,6:100.15
-1,4,6:100.15
0,4,6:100.15
-15,5,6:100.0
-14,5,6:100.0
-13,5,6:100.0
-11,5,6:100.0
-9,5,6:100.0
-7,5,6:100.0
-6,5,6:100.0
-5,5,6:100.0
-14,6,6:100.0
-13,6,6:100.0
-12,6,6:100.0
-11,6,6:100.0
-10,6,6:100.0
-9,6,6:100.0
-8,6,6:100.0
-7,6,6:100.0
-6,6,6:100.0
-14,7,6:100.0
-13,7,6:100.0
-12,7,6:100.0
-11,7,6:100.0
-10,7,6:100.0
-9,7,6:100.0
-8,7,6:100.0
-7,7,6:100.0
-10,8,6:100.0
-9,8,6:100.0
-8,8,6:100.0
-3,11,6:159.10
-2,11,6:159.10
-1,11,6:159.10
-3,12,6:159.10
-2,12,6:159.10
-1,12,6:159.10
-3,13,6:159.10
-2,13,6:159.10
-1,13,6:159.10
-2,14,6:159.10
-11,-13,7:100.0
3,-11,7:100.0
4,-10,7:159.10
-9,-9,7:100.0
-8,-9,7:100.0
-6,-9,7:100.15
-5,-9,7:100.15
-4,-9,7:100.15
1,-9,7:100.15
2,-9,7:100.15
3,-9,7:100.15
-5,-8,7:100.15
-4,-8,7:100.15
-3,-8,7:100.15
0,-8,7:100.15
1,-8,7:100.15
2,-8,7:100.15
3,-8,7:100.15
-4,-7,7:100.15
-3,-7,7:100.15
-2,-7,7:100.0
0,-7,7:100.15
2,-7,7:100.15
-3,-6,7:100.15
-2,-6,7:100.15
-1,-6,7:100.15
0,-6,7:100.15
2,-6,7:100.15
-8,-5,7:100.15
-7,-5,7:100.15
-3,-5,7:100.15
-2,-5,7:100.15
-1,-5,7:100.15
0,-5,7:100.15
1,-5,7:100.15
2,-5,7:100.15
-9,-4,7:100.15
-8,-4,7:100.15
-7,-4,7:100.15
-6,-4,7:100.15
-5,-4,7:100.15
-2,-4,7:100.15
-1,-4,7:100.15
0,-4,7:100.15
1,-4,7:100.15
2,-4,7:100.15
3,-4,7:100.15
5,-4,7:100.15
6,-4,7:100.15
7,-4,7:100.15
-7,-3,7:100.15
-6,-3,7:100.15
-5,-3,7:100.15
-4,-3,7:100.15
-1,-3,7:100.15
0,-3,7:100.15
1,-3,7:100.15
2,-3,7:100.15
3,-3,7:100.15
4,-3,7:100.15
5,-3,7:100.15
7,-3,7:100.15
-6,-2,7:100.15
-5,-2,7:100.15
-4,-2,7:100.15
3,-2,7:100.15
4,-2,7:100.15
5,-2,7:100.15
6,-2,7:100.15
-12,-1,7:159.10
-11,-1,7:159.10
-10,-1,7:159.10
-9,-1,7:159.10
-5,-1,7:100.15
-4,-1,7:100.15
4,-1,7:100.15
5,-1,7:100.15
-13,0,7:159.10
-12,0,7:159.10
-11,0,7:100.0
-10,0,7:100.0
-9,0,7:159.10
-8,0,7:159.10
-7,0,7:159.10
-6,0,7:159.10
-5,0,7:100.15
-4,0,7:100.15
-14,1,7:159.10
-13,1,7:159.10
-12,1,7:159.10
-11,1,7:159.10
-10,1,7:100.0
-9,1,7:100.0
-8,1,7:100.0
-7,1,7:159.10
-6,1,7:159.10
1,1,7:100.15
2,1,7:100.15
-15,2,7:159.10
-14,2,7:159.10
-13,2,7:100.0
-12,2,7:159.10
-11,2,7:159.10
-10,2,7:159.10
-9,2,7:159.10
-8,2,7:159.10
-7,2,7:159.10
-6,2,7:159.10
1,2,7:100.15
2,2,7:100.15
-14,3,7:159.10
-13,3,7:100.0
-12,3,7:100.0
-11,3,7:100.0
-10,3,7:100.15
-9,3,7:100.15
-8,3,7:159.10
-7,3,7:159.10
-6,3,7:159.10
-1,3,7:100.15
0,3,7:100.15
-14,4,7:159.10
-13,4,7:159.10
-12,4,7:100.0
-11,4,7:100.0
-10,4,7:100.0
-9,4,7:159.10
-8,4,7:100.0
-7,4,7:159.10
-6,4,7:159.10
-2,4,7:100.15
-1,4,7:100.15
0,4,7:100.15
-14,5,7:159.10
-13,5,7:159.10
-12,5,7:100.0
-11,5,7:159.10
-10,5,7:100.0
-9,5,7:159.10
-8,5,7:100.0
-7,5,7:159.10
-6,5,7:159.10
-1,5,7:100.15
0,5,7:100.15
-13,6,7:159.10
-12,6,7:159.10
-11,6,7:159.10
-10,6,7:159.10
-9,6,7:159.10
-8,6,7:159.10
-7,6,7:159.10
-11,7,7:159.10
-10,7,7:159.10
-9,7,7:159.10
-8,7,7:159.10
-8,8,7:159.10
-9,-14,8:100.0
-8,-14,8:100.0
-11,-13,8:159.10
-10,-13,8:100.0
-9,-13,8:100.0
-8,-13,8:100.0
-7,-13,8:100.0
-6,-13,8:100.0
-12,-12,8:100.0
-11,-12,8:100.0
-10,-12,8:100.0
-9,-12,8:100.0
-8,-12,8:100.0
-7,-12,8:100.0
-6,-12,8:100.0
-5,-12,8:100.0
-4,-12,8:100.0
-13,-11,8:100.0
-12,-11,8:100.0
-11,-11,8:100.0
-10,-11,8:100.0
-9,-11,8:100.0
-8,-11,8:100.0
-7,-11,8:100.0
-6,-11,8:100.0
-5,-11,8:100.0
-4,-11,8:100.0
-3,-11,8:100.0
-14,-10,8:100.0
-13,-10,8:100.0
-12,-10,8:100.0
-11,-10,8:100.0
-10,-10,8:100.0
-9,-10,8:100.0
-8,-10,8:100.0
-7,-10,8:100.0
-6,-10,8:100.0
-5,-10,8:100.0
-4,-10,8:100.0
-3,-10,8:100.0
1,-10,8:100.15
2,-10,8:100.15
3,-10,8:100.15
-14,-9,8:100.0
-13,-9,8:100.0
-12,-9,8:100.0
-11,-9,8:100.0
-10,-9,8:100.0
-9,-9,8:159.10
-8,-9,8:159.10
-6,-9,8:100.15
-5,-9,8:159.10
-4,-9,8:159.10
-3,-9,8:100.0
1,-9,8:100.15
3,-9,8:100.15
-14,-8,8:100.0
-13,-8,8:100.0
-12,-8,8:100.0
-11,-8,8:100.0
-5,-8,8:159.10
-4,-8,8:159.10
-3,-8,8:159.10
-2,-8,8:100.0
0,-8,8:100.15
1,-8,8:100.15
2,-8,8:100.15
-14,-7,8:100.0
-13,-7,8:100.0
-12,-7,8:100.0
-11,-7,8:100.0
-5,-7,8:100.0
-4,-7,8:159.10
-3,-7,8:159.10
-2,-7,8:159.10
0,-7,8:100.15
1,-7,8:100.15
2,-7,8:100.15
-14,-6,8:100.0
-13,-6,8:100.0
-12,-6,8:100.0
-11,-6,8:100.0
-8,-6,8:100.15
-7,-6,8:100.15
-6,-6,8:100.0
-5,-6,8:100.0
-4,-6,8:100.0
-3,-6,8:159.10
-2,-6,8:159.10
0,-6,8:100.15
1,-6,8:100.15
2,-6,8:100.15
-14,-5,8:100.0
-13,-5,8:100.0
-12,-5,8:100.0
-11,-5,8:100.0
-10,-5,8:100.0
-9,-5,8:100.0
-8,-5,8:100.15
-7,-5,8:100.15
-6,-5,8:100.0
-5,-5,8:100.0
-4,-5,8:100.0
-3,-5,8:159.10
-2,-5,8:159.10
-13,-4,8:100.0
-12,-4,8:100.0
-11,-4,8:100.0
-10,-4,8:100.0
-9,-4,8:100.15
-8,-4,8:100.15
-7,-4,8:100.15
-6,-4,8:159.10
-5,-4,8:159.10
-4,-4,8:100.0
-3,-4,8:100.0
2,-4,8:100.15
3,-4,8:100.15
6,-4,8:100.15
7,-4,8:100.15
8,-4,8:100.15
-13,-3,8:100.0
-12,-3,8:100.0
-11,-3,8:100.0
-10,-3,8:100.0
-9,-3,8:100.0
-8,-3,8:100.0
-7,-3,8:159.10
-6,-3,8:159.10
-5,-3,8:159.10
-4,-3,8:159.10
2,-3,8:100.15
5,-3,8:100.15
6,-3,8:100.15
7,-3,8:100.15
-11,-2,8:100.0
-10,-2,8:100.0
-9,-2,8:100.0
-8,-2,8:100.0
-7,-2,8:100.0
-6,-2,8:159.10
-1,-2,8:100.0
0,-2,8:100.0
1,-2,8:100.0
2,-2,8:100.0
3,-2,8:159.10
4,-2,8:159.10
5,-2,8:100.15
6,-2,8:100.15
7,-2,8:100.15
-11,-1,8:159.10
-7,-1,8:100.0
-5,-1,8:159.10
-4,-1,8:159.10
3,-1,8:100.0
4,-1,8:159.10
5,-1,8:159.10
6,-1,8:100.0
-11,0,8:159.10
-10,0,8:159.10
-6,0,8:100.15
-5,0,8:100.15
6,0,8:100.0
-12,1,8:159.10
-11,1,8:159.10
-10,1,8:159.10
-9,1,8:159.10
-8,1,8:159.10
-7,1,8:159.10
-6,1,8:159.10
-5,1,8:100.0
1,1,8:100.15
2,1,8:100.15
6,1,8:100.0
7,1,8:100.0
-14,2,8:159.10
-13,2,8:159.10
-12,2,8:82.0
-11,2,8:159.10
-10,2,8:100.0
-9,2,8:159.10
-8,2,8:159.10
-7,2,8:159.10
-6,2,8:100.0
1,2,8:100.15
2,2,8:159.10
7,2,8:100.0
-13,3,8:82.0
-12,3,8:82.0
-11,3,8:82.0
-10,3,8:100.15
-9,3,8:159.10
-8,3,8:159.10
-7,3,8:159.10
-6,3,8:100.0
-1,3,8:100.15
3,3,8:100.0
7,3,8:100.0
-12,4,8:82.0
-11,4,8:159.10
-10,4,8:100.15
-9,4,8:159.10
-8,4,8:159.10
-7,4,8:159.10
-6,4,8:159.10
-1,4,8:100.15
0,4,8:100.15
4,4,8:100.0
7,4,8:100.0
-12,5,8:159.10
-11,5,8:159.10
-10,5,8:159.10
-9,5,8:159.10
-8,5,8:159.10
-1,5,8:100.15
0,5,8:100.15
7,5,8:100.0
-13,6,8:159.10
-12,6,8:159.10
-9,6,8:159.10
-8,6,8:82.0
0,6,8:100.0
8,6,8:100.0
-8,7,8:82.0
-7,7,8:100.0
-6,7,8:100.0
-5,7,8:100.0
-1,7,8:100.0
8,7,8:100.0
-8,8,8:82.0
-7,8,8:100.0
-6,8,8:100.0
-5,8,8:100.0
-1,8,8:100.0
-7,9,8:100.0
-6,9,8:100.0
-5,9,8:100.0
-1,9,8:100.0
3,9,8:100.0
7,9,8:100.0
-7,10,8:100.0
-6,10,8:100.0
-5,10,8:100.0
-4,10,8:100.0
-3,10,8:100.0
-1,10,8:100.0
2,10,8:100.0
3,10,8:100.0
4,10,8:100.0
6,10,8:100.0
7,10,8:100.0
-7,11,8:100.0
-6,11,8:100.0
-5,11,8:100.0
-4,11,8:100.0
-3,11,8:100.0
-2,11,8:100.0
-1,11,8:100.0
0,11,8:100.0
1,11,8:100.0
2,11,8:100.0
3,11,8:100.0
4,11,8:100.0
5,11,8:100.0
6,11,8:100.0
-6,12,8:100.0
-5,12,8:100.0
-4,12,8:100.0
-3,12,8:100.0
-2,12,8:100.0
-1,12,8:100.0
0,12,8:100.0
1,12,8:100.0
2,12,8:100.0
3,12,8:100.0
5,12,8:100.0
-5,13,8:100.0
-4,13,8:100.0
-3,13,8:100.0
-2,13,8:100.0
-1,13,8:100.0
0,13,8:100.0
1,13,8:100.0
2,13,8:100.0
3,13,8:100.0
4,13,8:100.0
-1,14,8:100.0
0,14,8:100.0
1,14,8:100.0
2,14,8:100.0
3,14,8:100.0
5,-15,9:100.0
-9,-13,9:159.10
7,-13,9:100.0
-10,-12,9:159.10
-9,-12,9:159.10
-8,-12,9:159.10
-7,-12,9:159.10
-11,-11,9:159.10
-10,-11,9:159.10
-9,-11,9:159.10
-8,-11,9:159.10
-7,-11,9:82.0
-6,-11,9:159.10
-5,-11,9:159.10
-4,-11,9:159.10
-12,-10,9:159.10
-11,-10,9:82.0
-10,-10,9:159.10
-9,-10,9:159.10
-8,-10,9:82.0
-7,-10,9:82.0
-6,-10,9:82.0
-5,-10,9:159.10
-4,-10,9:159.10
2,-10,9:100.15
3,-10,9:100.15
4,-10,9:100.0
5,-10,9:100.0
-14,-9,9:159.10
-13,-9,9:159.10
-12,-9,9:82.0
-11,-9,9:82.0
-10,-9,9:82.0
-9,-9,9:159.10
-8,-9,9:159.10
-7,-9,9:100.15
-6,-9,9:159.10
-5,-9,9:159.10
-4,-9,9:159.10
1,-9,9:100.15
2,-9,9:100.15
3,-9,9:100.15
-13,-8,9:159.10
-12,-8,9:159.10
-11,-8,9:82.0
-10,-8,9:100.0
-9,-8,9:100.0
-8,-8,9:100.0
-6,-8,9:100.0
-5,-8,9:159.10
-4,-8,9:159.10
-13,-7,9:159.10
-12,-7,9:159.10
-11,-7,9:159.10
-10,-7,9:100.0
-9,-7,9:100.0
-8,-7,9:100.0
-7,-7,9:100.0
-5,-7,9:159.10
-4,-7,9:159.10
-12,-6,9:159.10
-11,-6,9:159.10
-10,-6,9:100.0
-9,-6,9:100.0
-8,-6,9:100.15
-7,-6,9:159.10
-6,-6,9:159.10
-5,-6,9:159.10
-4,-6,9:159.10
-3,-6,9:159.10
-12,-5,9:159.10
-11,-5,9:159.10
-10,-5,9:159.10
-9,-5,9:159.10
-8,-5,9:159.10
-7,-5,9:159.10
-6,-5,9:159.10
-5,-5,9:159.10
-4,-5,9:159.10
-3,-5,9:159.10
3,-5,9:100.15
-12,-4,9:159.10
-11,-4,9:159.10
-10,-4,9:159.10
-9,-4,9:159.10
-8,-4,9:159.10
-7,-4,9:159.10
-6,-4,9:159.10
-5,-4,9:159.10
2,-4,9:100.15
3,-4,9:100.15
7,-4,9:100.15
8,-4,9:100.15
-11,-3,9:100.15
-10,-3,9:100.15
-9,-3,9:159.10
-8,-3,9:159.10
-7,-3,9:159.10
-6,-3,9:159.10
7,-3,9:100.15
8,-3,9:100.15
-7,-2,9:159.10
-3,-2,9:100.0
-2,-2,9:100.0
-1,-2,9:159.10
0,-2,9:159.10
9,-2,9:100.0
-4,-1,9:159.10
-3,-1,9:100.0
-2,-1,9:100.0
-1,-1,9:100.0
0,-1,9:100.0
1,-1,9:100.0
2,-1,9:100.0
3,-1,9:159.10
4,-1,9:159.10
9,-1,9:100.0
10,-1,9:100.0
-11,0,9:159.10
-6,0,9:100.15
-5,0,9:100.15
-4,0,9:100.0
-3,0,9:100.0
-2,0,9:100.0
-1,0,9:100.0
0,0,9:100.0
1,0,9:100.0
2,0,9:100.0
3,0,9:100.0
4,0,9:100.0
5,0,9:100.0
10,0,9:100.0
-10,1,9:159.10
-6,1,9:159.10
-5,1,9:159.10
-4,1,9:100.0
-3,1,9:100.0
-1,1,9:100.0
0,1,9:100.0
1,1,9:159.10
2,1,9:159.10
3,1,9:100.0
4,1,9:100.0
5,1,9:100.0
6,1,9:159.10
-13,2,9:82.0
-11,2,9:82.0
-10,2,9:159.10
-9,2,9:159.10
-8,2,9:159.10
-7,2,9:159.10
-6,2,9:159.10
-5,2,9:100.0
-4,2,9:100.0
1,2,9:100.15
2,2,9:159.10
3,2,9:100.0
4,2,9:100.0
5,2,9:100.0
6,2,9:100.0
-12,3,9:82.0
-11,3,9:82.0
-10,3,9:159.10
-9,3,9:159.10
-8,3,9:159.10
-7,3,9:159.10
-6,3,9:159.10
-5,3,9:100.0
3,3,9:159.10
4,3,9:100.0
5,3,9:100.0
6,3,9:100.0
-11,4,9:82.0
-10,4,9:159.10
-9,4,9:159.10
-8,4,9:159.10
-7,4,9:159.10
-6,4,9:159.10
-1,4,9:100.15
0,4,9:100.15
4,4,9:159.10
5,4,9:100.0
6,4,9:100.0
7,4,9:159.10
-12,5,9:159.10
-9,5,9:159.10
-8,5,9:159.10
-7,5,9:100.0
-6,5,9:100.0
-1,5,9:100.15
0,5,9:100.15
4,5,9:100.0
5,5,9:100.0
6,5,9:100.0
7,5,9:159.10
-8,6,9:82.0
-7,6,9:100.0
-6,6,9:100.0
-1,6,9:100.15
0,6,9:100.15
5,6,9:100.0
6,6,9:100.0
7,6,9:100.0
-8,7,9:82.0
-7,7,9:82.0
-6,7,9:159.10
-5,7,9:159.10
-1,7,9:159.10
5,7,9:100.0
6,7,9:100.0
7,7,9:100.0
8,7,9:159.10
-7,8,9:82.0
-6,8,9:159.10
-5,8,9:159.10
-1,8,9:159.10
4,8,9:100.0
5,8,9:100.0
6,8,9:100.0
7,8,9:100.0
8,8,9:100.0
-7,9,9:159.10
-6,9,9:159.10
-5,9,9:159.10
-1,9,9:159.10
3,9,9:159.10
4,9,9:100.0
5,9,9:100.0
6,9,9:100.0
7,9,9:159.10
-7,10,9:159.10
-6,10,9:159.10
-5,10,9:159.10
-4,10,9:159.10
-3,10,9:159.10
-1,10,9:159.10
2,10,9:82.0
3,10,9:159.10
4,10,9:159.10
5,10,9:100.0
6,10,9:159.10
-6,11,9:159.10
-5,11,9:159.10
-4,11,9:159.10
-3,11,9:159.10
-2,11,9:159.10
-1,11,9:82.0
0,11,9:82.0
1,11,9:82.0
2,11,9:82.0
3,11,9:82.0
4,11,9:159.10
5,11,9:159.10
-6,12,9:159.10
-5,12,9:159.10
-4,12,9:159.10
-3,12,9:159.10
-2,12,9:159.10
-1,12,9:82.0
0,12,9:82.0
1,12,9:82.0
2,12,9:82.0
3,12,9:82.0
-4,13,9:159.10
-3,13,9:159.10
-2,13,9:159.10
-1,13,9:82.0
0,13,9:82.0
1,13,9:82.0
2,13,9:82.0
3,13,9:82.0
1,14,9:82.0
2,14,9:82.0
4,-14,10:100.0
5,-14,10:100.0
6,-14,10:100.0
7,-14,10:100.0
8,-14,10:100.0
9,-14,10:100.0
3,-13,10:100.0
4,-13,10:100.0
5,-13,10:100.0
6,-13,10:100.0
7,-13,10:159.10
8,-13,10:100.0
9,-13,10:100.0
10,-13,10:100.0
-9,-12,10:159.10
-1,-12,10:100.0
0,-12,10:100.0
1,-12,10:100.0
2,-12,10:100.0
3,-12,10:100.0
4,-12,10:100.0
8,-12,10:100.0
9,-12,10:100.0
10,-12,10:100.0
-9,-11,10:159.10
-4,-11,10:159.10
-2,-11,10:100.0
-1,-11,10:100.0
3,-11,10:100.15
9,-11,10:100.0
10,-11,10:100.0
11,-11,10:100.0
-10,-10,10:82.0
-9,-10,10:159.10
-8,-10,10:82.0
-7,-10,10:82.0
-6,-10,10:82.0
-5,-10,10:159.10
-2,-10,10:100.0
-1,-10,10:100.0
0,-10,10:100.0
1,-10,10:100.0
2,-10,10:100.15
3,-10,10:100.15
4,-10,10:100.15
5,-10,10:159.10
6,-10,10:100.0
7,-10,10:100.0
8,-10,10:100.0
10,-10,10:100.0
11,-10,10:100.0
-13,-9,10:159.10
-12,-9,10:82.0
-11,-9,10:82.0
-10,-9,10:82.0
-9,-9,10:159.10
-8,-9,10:82.0
-6,-9,10:82.0
-2,-9,10:100.0
-1,-9,10:100.0
0,-9,10:100.0
1,-9,10:100.0
2,-9,10:100.0
3,-9,10:159.10
11,-9,10:100.0
12,-9,10:100.0
-12,-8,10:82.0
-11,-8,10:82.0
-10,-8,10:82.0
-8,-8,10:100.0
-6,-8,10:159.10
-5,-8,10:159.10
-3,-8,10:100.0
-2,-8,10:100.0
-1,-8,10:100.0
0,-8,10:100.0
1,-8,10:100.0
3,-8,10:100.0
12,-8,10:100.0
13,-8,10:100.0
-13,-7,10:159.10
-12,-7,10:159.10
-11,-7,10:159.10
-10,-7,10:159.10
-9,-7,10:100.15
-8,-7,10:100.15
-7,-7,10:100.0
-5,-7,10:159.10
-4,-7,10:159.10
-3,-7,10:100.0
-2,-7,10:100.0
-1,-7,10:100.0
0,-7,10:100.0
1,-7,10:100.0
13,-7,10:100.0
-11,-6,10:159.10
-10,-6,10:159.10
-9,-6,10:159.10
-8,-6,10:100.15
-7,-6,10:159.10
-6,-6,10:159.10
-5,-6,10:159.10
-4,-6,10:159.10
-3,-6,10:159.10
-2,-6,10:100.0
-1,-6,10:100.0
0,-6,10:100.0
13,-6,10:100.0
-11,-5,10:159.10
-10,-5,10:159.10
-9,-5,10:159.10
-8,-5,10:159.10
-7,-5,10:159.10
-6,-5,10:159.10
-4,-5,10:159.10
-3,-5,10:159.10
-2,-5,10:100.0
-1,-5,10:100.0
0,-5,10:100.0
3,-5,10:100.15
8,-5,10:100.15
12,-5,10:100.0
13,-5,10:100.0
-12,-4,10:159.10
-11,-4,10:100.15
-10,-4,10:159.10
-8,-4,10:159.10
-7,-4,10:82.0
-4,-4,10:100.0
-3,-4,10:100.0
-2,-4,10:100.0
1,-4,10:100.0
3,-4,10:100.15
7,-4,10:100.15
8,-4,10:100.15
12,-4,10:100.0
-11,-3,10:100.15
-10,-3,10:159.10
-7,-3,10:82.0
-3,-3,10:100.0
-2,-3,10:100.0
1,-3,10:100.0
7,-3,10:100.15
8,-3,10:100.15
11,-3,10:100.0
12,-3,10:100.0
-8,-2,10:100.0
-7,-2,10:100.0
-3,-2,10:159.10
-2,-2,10:159.10
-1,-2,10:159.10
2,-2,10:100.0
8,-2,10:100.0
9,-2,10:159.10
11,-2,10:100.0
12,-2,10:100.0
-8,-1,10:100.0
-2,-1,10:159.10
-1,-1,10:159.10
0,-1,10:159.10
1,-1,10:100.0
2,-1,10:100.0
9,-1,10:159.10
10,-1,10:159.10
11,-1,10:100.0
12,-1,10:100.0
-6,0,10:100.15
-5,0,10:100.15
-3,0,10:159.10
-2,0,10:159.10
-1,0,10:159.10
0,0,10:159.10
1,0,10:159.10
2,0,10:159.10
10,0,10:159.10
11,0,10:100.0
12,0,10:100.0
-5,1,10:159.10
-4,1,10:159.10
-3,1,10:159.10
-2,1,10:100.0
-1,1,10:159.10
0,1,10:159.10
1,1,10:159.10
2,1,10:159.10
3,1,10:159.10
4,1,10:159.10
8,1,10:100.0
9,1,10:100.0
10,1,10:100.0
11,1,10:100.0
-5,2,10:159.10
-4,2,10:159.10
-3,2,10:100.0
-2,2,10:100.0
-1,2,10:100.0
0,2,10:100.0
1,2,10:159.10
2,2,10:159.10
3,2,10:159.10
4,2,10:159.10
5,2,10:159.10
6,2,10:159.10
7,2,10:100.0
8,2,10:100.0
9,2,10:100.0
10,2,10:100.0
-10,3,10:159.10
-9,3,10:159.10
-6,3,10:159.10
-5,3,10:159.10
-4,3,10:100.0
-3,3,10:100.0
-2,3,10:100.0
-1,3,10:100.0
0,3,10:100.0
1,3,10:100.0
2,3,10:100.0
3,3,10:159.10
4,3,10:159.10
5,3,10:159.10
-10,4,10:159.10
-8,4,10:159.10
-7,4,10:159.10
-6,4,10:159.10
-4,4,10:100.0
-3,4,10:100.0
-2,4,10:100.0
-1,4,10:100.15
0,4,10:100.15
1,4,10:100.0
2,4,10:100.0
3,4,10:100.0
4,4,10:82.0
5,4,10:82.0
-7,5,10:159.10
-6,5,10:159.10
-5,5,10:100.0
-4,5,10:100.0
-3,5,10:100.0
2,5,10:100.0
3,5,10:100.0
4,5,10:82.0
5,5,10:82.0
-7,6,10:159.10
-6,6,10:159.10
-5,6,10:100.0
-4,6,10:100.0
-3,6,10:100.0
-1,6,10:100.15
0,6,10:100.15
2,6,10:100.0
3,6,10:100.0
4,6,10:100.0
5,6,10:82.0
6,6,10:82.0
-6,7,10:159.10
-5,7,10:159.10
-4,7,10:100.0
-3,7,10:100.0
-1,7,10:159.10
0,7,10:100.15
1,7,10:100.0
2,7,10:100.0
3,7,10:100.0
4,7,10:100.0
5,7,10:159.10
6,7,10:159.10
7,7,10:159.10
-6,8,10:159.10
-5,8,10:159.10
-4,8,10:100.0
-3,8,10:100.0
-2,8,10:100.0
-1,8,10:159.10
0,8,10:100.0
1,8,10:100.0
2,8,10:100.0
3,8,10:100.0
4,8,10:159.10
5,8,10:159.10
6,8,10:159.10
7,8,10:159.10
8,8,10:159.10
-6,9,10:159.10
-5,9,10:159.10
-4,9,10:100.0
-3,9,10:100.0
-2,9,10:100.0
-1,9,10:159.10
0,9,10:100.0
1,9,10:100.0
2,9,10:100.0
3,9,10:159.10
4,9,10:159.10
5,9,10:159.10
-5,10,10:159.10
-4,10,10:159.10
-3,10,10:159.10
-2,10,10:100.0
-1,10,10:159.10
0,10,10:100.0
1,10,10:100.0
2,10,10:82.0
3,10,10:159.10
4,10,10:159.10
-6,11,10:159.10
-5,11,10:159.10
-4,11,10:159.10
-3,11,10:159.10
-2,11,10:159.10
-1,11,10:82.0
0,11,10:82.0
1,11,10:82.0
2,11,10:82.0
3,11,10:82.0
-6,12,10:159.10
-1,12,10:82.0
0,12,10:82.0
1,12,10:82.0
2,12,10:82.0
2,13,10:82.0
2,14,10:82.0
4,-13,11:159.10
5,-13,11:159.10
6,-13,11:82.0
7,-13,11:82.0
8,-13,11:82.0
3,-12,11:159.10
4,-12,11:159.10
5,-12,11:100.0
7,-12,11:100.0
8,-12,11:159.10
9,-12,11:159.10
-9,-11,11:159.10
-2,-11,11:159.10
-1,-11,11:159.10
0,-11,11:100.0
1,-11,11:100.0
2,-11,11:100.0
3,-11,11:159.10
4,-11,11:100.0
5,-11,11:100.0
6,-11,11:100.0
7,-11,11:100.0
8,-11,11:100.0
9,-11,11:159.10
10,-11,11:159.10
-9,-10,11:159.10
-1,-10,11:159.10
0,-10,11:159.10
1,-10,11:159.10
2,-10,11:159.10
3,-10,11:100.15
4,-10,11:100.15
5,-10,11:82.0
6,-10,11:159.10
7,-10,11:159.10
8,-10,11:159.10
9,-10,11:100.0
10,-10,11:159.10
-14,-9,11:100.0
-13,-9,11:159.10
-12,-9,11:82.0
-11,-9,11:82.0
-9,-9,11:159.10
-8,-9,11:159.10
-6,-9,11:159.10
-1,-9,11:159.10
0,-9,11:159.10
1,-9,11:159.10
2,-9,11:159.10
3,-9,11:82.0
4,-9,11:100.0
8,-9,11:100.0
9,-9,11:100.0
10,-9,11:100.0
11,-9,11:159.10
-14,-8,11:100.0
-13,-8,11:100.0
-12,-8,11:100.0
-11,-8,11:82.0
-10,-8,11:159.10
-9,-8,11:100.0
-8,-8,11:159.10
-2,-8,11:159.10
-1,-8,11:159.10
0,-8,11:159.10
1,-8,11:159.10
4,-8,11:100.0
8,-8,11:100.0
9,-8,11:100.0
10,-8,11:100.0
11,-8,11:100.0
12,-8,11:159.10
-15,-7,11:100.0
-14,-7,11:100.0
-13,-7,11:159.10
-12,-7,11:159.10
-11,-7,11:100.0
-10,-7,11:159.10
-9,-7,11:159.10
-8,-7,11:159.10
-7,-7,11:159.10
-2,-7,11:159.10
-1,-7,11:159.10
0,-7,11:159.10
1,-7,11:159.10
4,-7,11:100.0
9,-7,11:100.0
10,-7,11:100.0
11,-7,11:100.0
12,-7,11:100.0
13,-7,11:159.10
-16,-6,11:100.0
-15,-6,11:100.0
-14,-6,11:100.0
-13,-6,11:100.0
-12,-6,11:100.0
-11,-6,11:100.0
-10,-6,11:159.10
-9,-6,11:159.10
-8,-6,11:159.10
-7,-6,11:159.10
-6,-6,11:159.10
-5,-6,11:159.10
-4,-6,11:159.10
-3,-6,11:159.10
-2,-6,11:159.10
-1,-6,11:159.10
0,-6,11:159.10
1,-6,11:100.0
2,-6,11:100.0
9,-6,11:100.15
10,-6,11:100.0
11,-6,11:100.0
12,-6,11:100.0
13,-6,11:159.10
-16,-5,11:100.0
-15,-5,11:100.0
-14,-5,11:100.0
-13,-5,11:100.0
-12,-5,11:100.0
-11,-5,11:159.10
-10,-5,11:159.10
-9,-5,11:100.0
-8,-5,11:159.10
-7,-5,11:159.10
-3,-5,11:159.10
-2,-5,11:159.10
-1,-5,11:82.0
0,-5,11:159.10
1,-5,11:100.0
2,-5,11:100.0
3,-5,11:100.15
8,-5,11:100.15
9,-5,11:100.15
10,-5,11:100.0
11,-5,11:100.0
12,-5,11:159.10
-16,-4,11:100.0
-15,-4,11:100.0
-14,-4,11:100.0
-13,-4,11:100.0
-12,-4,11:100.15
-11,-4,11:100.15
-10,-4,11:159.10
-9,-4,11:100.0
-8,-4,11:82.0
-7,-4,11:82.0
-4,-4,11:100.0
-3,-4,11:159.10
-2,-4,11:82.0
-1,-4,11:82.0
0,-4,11:82.0
1,-4,11:159.10
2,-4,11:100.0
9,-4,11:100.0
10,-4,11:100.0
11,-4,11:100.0
12,-4,11:159.10
-16,-3,11:100.0
-15,-3,11:100.0
-14,-3,11:100.0
-13,-3,11:100.0
-12,-3,11:100.0
-11,-3,11:159.10
-10,-3,11:159.10
-9,-3,11:100.0
-8,-3,11:100.0
-7,-3,11:82.0
-2,-3,11:159.10
-1,-3,11:82.0
0,-3,11:159.10
1,-3,11:159.10
2,-3,11:100.0
7,-3,11:100.15
8,-3,11:100.15
9,-3,11:100.0
10,-3,11:100.0
11,-3,11:159.10
-16,-2,11:100.0
-15,-2,11:100.0
-14,-2,11:100.0
-13,-2,11:100.0
-12,-2,11:100.0
-11,-2,11:100.0
-10,-2,11:100.0
-9,-2,11:100.0
-8,-2,11:82.0
-7,-2,11:82.0
-1,-2,11:159.10
0,-2,11:100.0
1,-2,11:100.0
2,-2,11:159.10
3,-2,11:100.0
4,-2,11:100.0
8,-2,11:159.10
9,-2,11:159.10
10,-2,11:100.0
11,-2,11:159.10
-15,-1,11:100.0
-14,-1,11:100.0
-13,-1,11:100.0
-12,-1,11:100.0
-11,-1,11:100.0
-10,-1,11:100.0
-9,-1,11:100.0
-8,-1,11:159.10
-1,-1,11:159.10
0,-1,11:159.10
1,-1,11:159.10
2,-1,11:159.10
3,-1,11:100.0
4,-1,11:100.0
5,-1,11:100.0
6,-1,11:100.0
7,-1,11:100.0
8,-1,11:100.0
9,-1,11:159.10
10,-1,11:159.10
11,-1,11:159.10
-14,0,11:100.0
-13,0,11:100.0
-12,0,11:100.0
-11,0,11:100.0
-10,0,11:100.0
-6,0,11:100.15
0,0,11:159.10
1,0,11:159.10
2,0,11:159.10
3,0,11:100.0
4,0,11:100.0
5,0,11:100.0
6,0,11:100.0
7,0,11:100.0
8,0,11:100.0
9,0,11:100.0
10,0,11:159.10
-11,1,11:100.0
-6,1,11:100.15
-5,1,11:159.10
-2,1,11:159.10
-1,1,11:159.10
0,1,11:159.10
1,1,11:159.10
2,1,11:159.10
3,1,11:159.10
4,1,11:159.10
5,1,11:100.0
6,1,11:100.0
7,1,11:100.0
8,1,11:159.10
9,1,11:159.10
10,1,11:159.10
-4,2,11:159.10
-3,2,11:159.10
-2,2,11:159.10
-1,2,11:159.10
0,2,11:159.10
1,2,11:159.10
2,2,11:159.10
3,2,11:159.10
4,2,11:159.10
-4,3,11:159.10
-3,3,11:159.10
-2,3,11:159.10
-1,3,11:100.0
0,3,11:100.0
1,3,11:159.10
2,3,11:159.10
3,3,11:159.10
-7,4,11:159.10
-6,4,11:159.10
-4,4,11:159.10
-3,4,11:159.10
-2,4,11:159.10
-1,4,11:159.10
0,4,11:159.10
1,4,11:159.10
2,4,11:159.10
3,4,11:159.10
4,4,11:159.10
-6,5,11:159.10
-5,5,11:159.10
-4,5,11:159.10
-3,5,11:100.0
-2,5,11:100.0
-1,5,11:100.0
0,5,11:100.0
1,5,11:100.0
2,5,11:100.0
3,5,11:159.10
4,5,11:82.0
-5,6,11:159.10
-4,6,11:159.10
-3,6,11:100.0
-2,6,11:100.0
-1,6,11:159.10
0,6,11:159.10
1,6,11:100.0
2,6,11:100.0
3,6,11:159.10
4,6,11:159.10
-5,7,11:159.10
-4,7,11:159.10
-3,7,11:100.0
-2,7,11:100.0
-1,7,11:159.10
0,7,11:159.10
1,7,11:159.10
2,7,11:100.0
3,7,11:159.10
4,7,11:159.10
5,7,11:159.10
6,7,11:159.10
-4,8,11:159.10
-3,8,11:159.10
-2,8,11:100.0
-1,8,11:159.10
0,8,11:159.10
1,8,11:100.0
2,8,11:159.10
3,8,11:159.10
4,8,11:159.10
-4,9,11:159.10
-3,9,11:159.10
-2,9,11:159.10
-1,9,11:159.10
0,9,11:159.10
1,9,11:159.10
2,9,11:159.10
3,9,11:159.10
-5,10,11:159.10
-4,10,11:159.10
-3,10,11:159.10
-2,10,11:159.10
-1,10,11:159.10
0,10,11:82.0
1,10,11:82.0
2,10,11:82.0
-5,11,11:159.10
1,11,11:82.0
1,12,11:82.0
2,12,11:82.0
2,13,11:82.0
6,-13,12:82.0
7,-13,12:82.0
8,-13,12:82.0
3,-12,12:159.10
4,-12,12:159.10
5,-12,12:159.10
7,-12,12:82.0
8,-12,12:82.0
-5,-11,12:100.0
-2,-11,12:159.10
-1,-11,12:159.10
0,-11,12:159.10
1,-11,12:159.10
2,-11,12:159.10
3,-11,12:82.0
4,-11,12:82.0
5,-11,12:82.0
6,-11,12:159.10
7,-11,12:159.10
8,-11,12:159.10
-10,-10,12:100.0
-9,-10,12:100.0
-8,-10,12:100.0
-7,-10,12:100.0
-6,-10,12:100.0
-5,-10,12:100.0
0,-10,12:159.10
1,-10,12:159.10
2,-10,12:82.0
3,-10,12:82.0
4,-10,12:82.0
5,-10,12:82.0
6,-10,12:82.0
7,-10,12:159.10
8,-10,12:159.10
9,-10,12:159.10
-13,-9,12:159.10
-11,-9,12:100.0
-10,-9,12:100.0
-9,-9,12:100.0
-8,-9,12:159.10
-6,-9,12:100.0
-5,-9,12:100.0
-4,-9,12:100.0
0,-9,12:159.10
1,-9,12:159.10
2,-9,12:82.0
3,-9,12:82.0
4,-9,12:82.0
5,-9,12:100.0
6,-9,12:100.0
7,-9,12:100.0
8,-9,12:159.10
9,-9,12:159.10
-13,-8,12:159.10
-12,-8,12:159.10
-11,-8,12:159.10
-10,-8,12:159.10
-9,-8,12:159.10
-8,-8,12:159.10
-6,-8,12:100.0
-5,-8,12:100.0
0,-8,12:159.10
1,-8,12:159.10
2,-8,12:100.0
3,-8,12:100.0
4,-8,12:82.0
5,-8,12:100.0
6,-8,12:100.0
7,-8,12:100.0
8,-8,12:159.10
9,-8,12:159.10
10,-8,12:159.10
-14,-7,12:159.10
-13,-7,12:159.10
-12,-7,12:159.10
-11,-7,12:159.10
-10,-7,12:159.10
-9,-7,12:159.10
-8,-7,12:159.10
-7,-7,12:159.10
-5,-7,12:100.0
-1,-7,12:159.10
0,-7,12:159.10
1,-7,12:159.10
2,-7,12:100.0
3,-7,12:100.0
4,-7,12:82.0
5,-7,12:100.0
6,-7,12:100.0
7,-7,12:100.0
8,-7,12:100.0
9,-7,12:159.10
10,-7,12:159.10
11,-7,12:159.10
12,-7,12:159.10
13,-7,12:159.10
-16,-6,12:159.10
-15,-6,12:159.10
-14,-6,12:82.0
-13,-6,12:159.10
-12,-6,12:159.10
-11,-6,12:159.10
-10,-6,12:159.10
-9,-6,12:159.10
-8,-6,12:159.10
-7,-6,12:100.0
-6,-6,12:100.0
-1,-6,12:159.10
0,-6,12:159.10
1,-6,12:159.10
2,-6,12:159.10
3,-6,12:100.0
7,-6,12:100.0
8,-6,12:100.0
9,-6,12:100.15
10,-6,12:159.10
11,-6,12:159.10
-15,-5,12:82.0
-14,-5,12:82.0
-13,-5,12:82.0
-12,-5,12:159.10
-11,-5,12:159.10
-10,-5,12:159.10
-9,-5,12:159.10
-8,-5,12:159.10
-7,-5,12:100.0
-6,-5,12:100.0
-2,-5,12:82.0
-1,-5,12:82.0
0,-5,12:82.0
1,-5,12:159.10
2,-5,12:159.10
3,-5,12:159.10
7,-5,12:100.0
8,-5,12:159.10
9,-5,12:159.10
10,-5,12:159.10
11,-5,12:159.10
-15,-4,12:159.10
-14,-4,12:82.0
-13,-4,12:159.10
-12,-4,12:100.15
-11,-4,12:159.10
-10,-4,12:159.10
-9,-4,12:159.10
-8,-4,12:159.10
-7,-4,12:100.0
-4,-4,12:159.10
-3,-4,12:159.10
-2,-4,12:82.0
-1,-4,12:82.0
0,-4,12:82.0
1,-4,12:159.10
2,-4,12:159.10
3,-4,12:100.0
4,-4,12:100.0
5,-4,12:100.0
6,-4,12:100.0
9,-4,12:159.10
10,-4,12:159.10
-15,-3,12:159.10
-14,-3,12:159.10
-13,-3,12:159.10
-12,-3,12:159.10
-11,-3,12:159.10
-10,-3,12:159.10
-9,-3,12:159.10
-8,-3,12:82.0
0,-3,12:82.0
1,-3,12:159.10
2,-3,12:159.10
3,-3,12:100.0
4,-3,12:100.0
5,-3,12:100.0
6,-3,12:100.0
7,-3,12:159.10
8,-3,12:100.15
9,-3,12:159.10
10,-3,12:159.10
-15,-2,12:159.10
-14,-2,12:159.10
-13,-2,12:159.10
-12,-2,12:159.10
-11,-2,12:159.10
-10,-2,12:159.10
-9,-2,12:82.0
-8,-2,12:82.0
-7,-2,12:100.0
0,-2,12:159.10
1,-2,12:159.10
2,-2,12:159.10
3,-2,12:159.10
4,-2,12:159.10
5,-2,12:100.0
6,-2,12:100.0
7,-2,12:100.0
8,-2,12:159.10
9,-2,12:159.10
10,-2,12:159.10
-15,-1,12:159.10
-13,-1,12:159.10
-12,-1,12:159.10
-11,-1,12:159.10
-10,-1,12:159.10
-7,-1,12:100.0
-6,-1,12:100.0
-5,-1,12:100.0
1,-1,12:159.10
2,-1,12:159.10
3,-1,12:159.10
4,-1,12:159.10
5,-1,12:159.10
6,-1,12:159.10
7,-1,12:159.10
8,-1,12:159.10
9,-1,12:159.10
-11,0,12:159.10
-7,0,12:100.15
-6,0,12:159.10
-5,0,12:100.0
-4,0,12:100.0
-3,0,12:100.0
2,0,12:159.10
3,0,12:159.10
4,0,12:159.10
5,0,12:159.10
6,0,12:159.10
7,0,12:159.10
8,0,12:159.10
9,0,12:159.10
10,0,12:159.10
-12,1,12:100.0
-11,1,12:159.10
-7,1,12:100.15
-6,1,12:100.15
-5,1,12:159.10
-2,1,12:100.0
2,1,12:159.10
10,1,12:159.10
-12,2,12:100.0
-4,2,12:159.10
-2,2,12:100.0
-1,2,12:100.0
2,2,12:159.10
-13,3,12:100.0
-2,3,12:159.10
-1,3,12:159.10
0,3,12:159.10
1,3,12:159.10
2,3,12:159.10
-13,4,12:100.0
-12,4,12:100.0
-3,4,12:159.10
-2,4,12:159.10
-1,4,12:159.10
0,4,12:159.10
1,4,12:159.10
2,4,12:159.10
-13,5,12:100.0
-12,5,12:100.0
-6,5,12:159.10
-5,5,12:159.10
-4,5,12:159.10
-3,5,12:159.10
-2,5,12:159.10
-1,5,12:100.0
0,5,12:100.0
1,5,12:159.10
2,5,12:159.10
-12,6,12:100.0
-6,6,12:100.0
-5,6,12:159.10
-4,6,12:159.10
-3,6,12:159.10
-2,6,12:100.0
-1,6,12:100.0
0,6,12:100.0
1,6,12:159.10
2,6,12:159.10
3,6,12:159.10
-12,7,12:100.0
-3,7,12:159.10
-2,7,12:159.10
-1,7,12:100.0
0,7,12:100.0
1,7,12:159.10
2,7,12:159.10
3,7,12:159.10
4,7,12:159.10
5,7,12:159.10
-12,8,12:100.0
-3,8,12:159.10
-2,8,12:159.10
-1,8,12:159.10
0,8,12:159.10
1,8,12:159.10
2,8,12:159.10
-4,9,12:159.10
-3,9,12:159.10
-2,9,12:159.10
-1,9,12:159.10
0,9,12:159.10
1,9,12:159.10
-5,10,12:159.10
-4,10,12:159.10
1,10,12:159.10
1,11,12:82.0
1,12,12:82.0
8,-13,13:82.0
3,-12,13:159.10
4,-12,13:159.10
7,-12,13:82.0
8,-12,13:159.10
-9,-11,13:100.0
-8,-11,13:100.0
-7,-11,13:100.0
-6,-11,13:100.0
-5,-11,13:159.10
1,-11,13:159.10
7,-11,13:159.10
-10,-10,13:159.10
-9,-10,13:159.10
-8,-10,13:159.10
-7,-10,13:159.10
-6,-10,13:159.10
-5,-10,13:159.10
-4,-10,13:100.0
1,-10,13:159.10
2,-10,13:82.0
5,-10,13:82.0
6,-10,13:82.0
7,-10,13:159.10
-13,-9,13:159.10
-11,-9,13:159.10
-10,-9,13:159.10
-9,-9,13:82.0
-8,-9,13:159.10
-6,-9,13:159.10
-5,-9,13:159.10
-4,-9,13:159.10
2,-9,13:82.0
3,-9,13:82.0
4,-9,13:82.0
5,-9,13:82.0
6,-9,13:82.0
7,-9,13:159.10
8,-9,13:159.10
-13,-8,13:159.10
-11,-8,13:159.10
-10,-8,13:82.0
-9,-8,13:82.0
-8,-8,13:82.0
-6,-8,13:159.10
-5,-8,13:159.10
-4,-8,13:100.0
1,-8,13:159.10
2,-8,13:82.0
3,-8,13:82.0
4,-8,13:82.0
5,-8,13:100.0
7,-8,13:159.10
8,-8,13:159.10
-13,-7,13:159.10
-12,-7,13:159.10
-11,-7,13:159.10
-10,-7,13:159.10
-9,-7,13:82.0
-8,-7,13:159.10
-7,-7,13:159.10
-5,-7,13:159.10
-4,-7,13:100.0
1,-7,13:159.10
2,-7,13:159.10
3,-7,13:100.0
4,-7,13:82.0
5,-7,13:82.0
7,-7,13:100.0
8,-7,13:159.10
9,-7,13:159.10
-14,-6,13:82.0
-13,-6,13:82.0
-12,-6,13:159.10
-11,-6,13:159.10
-10,-6,13:159.10
-9,-6,13:159.10
-8,-6,13:159.10
-7,-6,13:159.10
-6,-6,13:159.10
-5,-6,13:100.0
1,-6,13:159.10
2,-6,13:159.10
3,-6,13:100.0
4,-6,13:100.0
5,-6,13:100.0
6,-6,13:100.0
8,-6,13:159.10
9,-6,13:159.10
10,-6,13:159.10
11,-6,13:159.10
-15,-5,13:82.0
-14,-5,13:82.0
-13,-5,13:82.0
-12,-5,13:100.0
-11,-5,13:159.10
-10,-5,13:159.10
-9,-5,13:159.10
-8,-5,13:159.10
-7,-5,13:159.10
-6,-5,13:159.10
-2,-5,13:159.10
-1,-5,13:82.0
0,-5,13:159.10
1,-5,13:159.10
2,-5,13:159.10
3,-5,13:159.10
4,-5,13:100.0
5,-5,13:100.0
6,-5,13:100.0
8,-5,13:159.10
9,-5,13:159.10
-14,-4,13:82.0
-12,-4,13:100.0
-11,-4,13:100.0
-10,-4,13:159.10
-9,-4,13:159.10
-8,-4,13:159.10
-7,-4,13:159.10
-2,-4,13:82.0
1,-4,13:159.10
2,-4,13:159.10
3,-4,13:100.0
4,-4,13:159.10
5,-4,13:159.10
6,-4,13:159.10
9,-4,13:159.10
-14,-3,13:159.10
-13,-3,13:159.10
-12,-3,13:159.10
-11,-3,13:159.10
-10,-3,13:159.10
-9,-3,13:82.0
-8,-3,13:82.0
1,-3,13:159.10
2,-3,13:159.10
3,-3,13:159.10
7,-3,13:159.10
8,-3,13:159.10
-15,-2,13:159.10
-14,-2,13:159.10
-13,-2,13:159.10
-12,-2,13:159.10
-11,-2,13:159.10
-8,-2,13:82.0
-7,-2,13:82.0
2,-2,13:159.10
3,-2,13:159.10
4,-2,13:159.10
5,-2,13:159.10
6,-2,13:159.10
7,-2,13:159.10
8,-2,13:159.10
9,-2,13:159.10
10,-2,13:159.10
-12,-1,13:159.10
-11,-1,13:159.10
-9,-1,13:100.0
-8,-1,13:100.0
-7,-1,13:82.0
-6,-1,13:159.10
-5,-1,13:82.0
-4,-1,13:159.10
-3,-1,13:159.10
3,-1,13:159.10
4,-1,13:159.10
5,-1,13:159.10
6,-1,13:159.10
8,-1,13:159.10
9,-1,13:159.10
-11,0,13:159.10
-10,0,13:100.0
-9,0,13:100.0
-8,0,13:100.0
-7,0,13:159.10
-6,0,13:82.0
-5,0,13:82.0
-4,0,13:82.0
-3,0,13:159.10
-2,0,13:159.10
3,0,13:159.10
5,0,13:159.10
9,0,13:159.10
-11,1,13:159.10
-10,1,13:100.0
-9,1,13:100.0
-8,1,13:100.15
-7,1,13:100.15
-6,1,13:100.0
-5,1,13:82.0
-4,1,13:100.0
-3,1,13:100.0
-2,1,13:159.10
-1,1,13:159.10
2,1,13:159.10
6,1,13:100.0
-12,2,13:159.10
-11,2,13:100.0
-10,2,13:100.0
-9,2,13:100.15
-8,2,13:100.15
-7,2,13:100.0
-6,2,13:100.0
-5,2,13:100.0
-4,2,13:159.10
-3,2,13:100.0
-2,2,13:159.10
-1,2,13:159.10
-13,3,13:159.10
-12,3,13:100.0
-11,3,13:100.0
-8,3,13:100.0
-7,3,13:100.0
-6,3,13:100.0
-5,3,13:100.0
-4,3,13:100.0
-3,3,13:100.0
-2,3,13:100.0
-1,3,13:159.10
-13,4,13:159.10
-12,4,13:159.10
-11,4,13:100.0
-10,4,13:100.0
-9,4,13:100.0
-8,4,13:100.0
-7,4,13:100.0
-6,4,13:100.0
-4,4,13:100.0
-3,4,13:100.0
-2,4,13:100.0
-1,4,13:159.10
0,4,13:159.10
-12,5,13:159.10
-11,5,13:100.0
-10,5,13:100.0
-9,5,13:100.0
-8,5,13:100.0
-7,5,13:100.0
-6,5,13:100.0
-5,5,13:159.10
-4,5,13:82.0
-3,5,13:82.0
-2,5,13:82.0
-1,5,13:159.10
0,5,13:159.10
1,5,13:159.10
-12,6,13:159.10
-11,6,13:100.0
-10,6,13:100.0
-9,6,13:100.0
-8,6,13:100.0
-7,6,13:100.0
-6,6,13:159.10
-5,6,13:159.10
-4,6,13:100.0
-3,6,13:100.0
-2,6,13:82.0
-1,6,13:159.10
0,6,13:159.10
1,6,13:159.10
2,6,13:159.10
-12,7,13:159.10
-11,7,13:100.0
-10,7,13:100.0
-9,7,13:100.0
-8,7,13:100.0
-7,7,13:100.0
-6,7,13:100.0
-5,7,13:100.0
-4,7,13:100.0
-3,7,13:100.0
-2,7,13:82.0
-1,7,13:159.10
0,7,13:159.10
3,7,13:159.10
-11,8,13:100.0
-10,8,13:100.0
-9,8,13:100.0
-8,8,13:100.0
-7,8,13:100.0
-6,8,13:100.0
-5,8,13:100.0
-4,8,13:100.0
-3,8,13:159.10
-2,8,13:159.10
0,8,13:159.10
-11,9,13:100.0
-10,9,13:100.0
-9,9,13:100.0
-8,9,13:100.0
-7,9,13:100.0
-6,9,13:100.0
-5,9,13:100.0
-4,9,13:159.10
-3,9,13:159.10
0,9,13:159.10
-9,10,13:100.0
-8,10,13:100.0
-7,10,13:100.0
-6,10,13:100.0
-5,10,13:159.10
-4,10,13:159.10
-3,10,13:100.0
1,10,13:159.10
-6,11,13:100.0
-5,11,13:100.0
1,11,13:159.10
-8,-11,14:159.10
7,-11,14:159.10
-8,-10,14:159.10
-7,-10,14:159.10
-6,-10,14:159.10
-5,-10,14:159.10
1,-10,14:159.10
2,-10,14:82.0
7,-10,14:159.10
-10,-9,14:82.0
-9,-9,14:82.0
-8,-9,14:82.0
-6,-9,14:159.10
2,-9,14:82.0
6,-9,14:82.0
-9,-8,14:82.0
-8,-8,14:100.0
-6,-8,14:159.10
-5,-8,14:159.10
3,-8,14:82.0
4,-8,14:82.0
5,-8,14:82.0
6,-8,14:100.0
7,-8,14:159.10
-13,-7,14:159.10
-9,-7,14:82.0
-8,-7,14:82.0
-7,-7,14:159.10
3,-7,14:82.0
4,-7,14:82.0
5,-7,14:82.0
6,-7,14:100.0
7,-7,14:159.10
-12,-6,14:159.10
-9,-6,14:159.10
-8,-6,14:159.10
-7,-6,14:159.10
2,-6,14:159.10
3,-6,14:159.10
4,-6,14:100.0
5,-6,14:159.10
7,-6,14:100.0
8,-6,14:159.10
9,-6,14:159.10
10,-6,14:159.10
-14,-5,14:82.0
-13,-5,14:82.0
-12,-5,14:159.10
-11,-5,14:159.10
-7,-5,14:159.10
-1,-5,14:159.10
0,-5,14:159.10
1,-5,14:159.10
2,-5,14:159.10
3,-5,14:159.10
7,-5,14:100.0
8,-5,14:159.10
13,-5,14:100.0
-13,-4,14:159.10
-12,-4,14:159.10
-11,-4,14:159.10
2,-4,14:159.10
3,-4,14:159.10
4,-4,14:159.10
5,-4,14:159.10
6,-4,14:159.10
-14,-3,14:159.10
-13,-3,14:159.10
-12,-3,14:159.10
-11,-3,14:159.10
-10,-3,14:159.10
-9,-3,14:159.10
3,-3,14:159.10
4,-3,14:100.0
5,-3,14:100.0
6,-3,14:100.0
7,-3,14:159.10
8,-3,14:100.15
-12,-2,14:159.10
4,-2,14:159.10
8,-2,14:159.10
9,-2,14:159.10
10,-2,14:159.10
11,-2,14:100.0
12,-2,14:100.0
-9,-1,14:159.10
-8,-1,14:82.0
3,-1,14:159.10
5,-1,14:159.10
8,-1,14:159.10
-9,0,14:159.10
-8,0,14:159.10
-7,0,14:159.10
-6,0,14:82.0
-5,0,14:82.0
-4,0,14:82.0
-3,0,14:159.10
3,0,14:159.10
5,0,14:159.10
-10,1,14:159.10
-9,1,14:159.10
-8,1,14:159.10
-7,1,14:159.10
-6,1,14:82.0
-5,1,14:82.0
-4,1,14:82.0
-3,1,14:159.10
6,1,14:159.10
-11,2,14:159.10
-10,2,14:159.10
-9,2,14:159.10
-8,2,14:159.10
-7,2,14:159.10
-6,2,14:159.10
-5,2,14:159.10
-4,2,14:159.10
-3,2,14:159.10
-2,2,14:159.10
3,2,14:100.0
6,2,14:100.0
-12,3,14:159.10
-11,3,14:159.10
-10,3,14:100.0
-9,3,14:100.15
-8,3,14:159.10
-7,3,14:159.10
-6,3,14:159.10
-5,3,14:159.10
-4,3,14:159.10
-3,3,14:159.10
-2,3,14:159.10
4,3,14:100.0
6,3,14:100.0
13,3,14:100.0
-12,4,14:159.10
-11,4,14:159.10
-10,4,14:82.0
-9,4,14:82.0
-8,4,14:82.0
-7,4,14:159.10
-6,4,14:159.10
-4,4,14:82.0
-3,4,14:82.0
-2,4,14:82.0
-1,4,14:159.10
5,4,14:100.0
12,4,14:100.0
13,4,14:100.0
-11,5,14:159.10
-10,5,14:82.0
-9,5,14:82.0
-8,5,14:82.0
-7,5,14:159.10
-6,5,14:159.10
-5,5,14:82.0
-4,5,14:82.0
-3,5,14:82.0
-2,5,14:82.0
-1,5,14:82.0
6,5,14:100.0
7,5,14:100.0
8,5,14:100.0
9,5,14:100.0
10,5,14:100.0
11,5,14:100.0
12,5,14:100.0
13,5,14:100.0
-11,6,14:159.10
-10,6,14:82.0
-9,6,14:82.0
-8,6,14:82.0
-7,6,14:159.10
-6,6,14:159.10
-5,6,14:82.0
-4,6,14:82.0
-3,6,14:82.0
-2,6,14:82.0
-1,6,14:82.0
0,6,14:159.10
-11,7,14:159.10
-10,7,14:159.10
-9,7,14:159.10
-8,7,14:159.10
-7,7,14:159.10
-6,7,14:159.10
-5,7,14:82.0
-4,7,14:82.0
-3,7,14:82.0
-2,7,14:82.0
-11,8,14:159.10
-10,8,14:159.10
-9,8,14:159.10
-8,8,14:159.10
-7,8,14:159.10
-6,8,14:159.10
-5,8,14:159.10
-4,8,14:82.0
-3,8,14:82.0
-11,9,14:159.10
-8,9,14:159.10
-7,9,14:159.10
-6,9,14:159.10
-5,9,14:159.10
-4,9,14:159.10
-5,10,14:159.10
-8,-9,15:159.10
-6,-9,15:159.10
6,-9,15:159.10
-8,-8,15:82.0
3,-8,15:82.0
6,-8,15:159.10
-7,-7,15:159.10
4,-7,15:159.10
5,-7,15:159.10
6,-7,15:159.10
9,-7,15:100.0
10,-7,15:100.0
11,-7,15:100.0
-7,-6,15:159.10
3,-6,15:100.0
4,-6,15:159.10
5,-6,15:159.10
6,-6,15:100.0
7,-6,15:159.10
8,-6,15:159.10
9,-6,15:159.10
10,-6,15:159.10
11,-6,15:100.0
12,-6,15:159.10
1,-5,15:159.10
2,-5,15:159.10
3,-5,15:159.10
4,-5,15:100.0
5,-5,15:100.0
6,-5,15:100.0
7,-5,15:159.10
8,-5,15:100.0
11,-5,15:100.0
12,-5,15:159.10
13,-5,15:159.10
-12,-4,15:159.10
4,-4,15:159.10
5,-4,15:159.10
6,-4,15:159.10
9,-4,15:100.0
12,-4,15:100.0
13,-4,15:159.10
4,-3,15:159.10
5,-3,15:100.0
6,-3,15:100.0
7,-3,15:159.10
8,-3,15:100.15
12,-3,15:100.0
13,-3,15:100.0
3,-2,15:100.0
4,-2,15:159.10
5,-2,15:100.0
6,-2,15:100.0
7,-2,15:100.0
8,-2,15:159.10
9,-2,15:159.10
10,-2,15:159.10
11,-2,15:159.10
12,-2,15:159.10
13,-2,15:100.0
-9,-1,15:159.10
3,-1,15:159.10
4,-1,15:100.0
5,-1,15:100.0
6,-1,15:100.0
7,-1,15:100.0
12,-1,15:100.0
13,-1,15:100.0
-8,0,15:159.10
-3,0,15:159.10
2,0,15:100.0
3,0,15:159.10
4,0,15:100.0
5,0,15:159.10
12,0,15:100.0
13,0,15:100.0
-8,1,15:159.10
-7,1,15:159.10
-6,1,15:159.10
-5,1,15:82.0
-4,1,15:159.10
3,1,15:159.10
4,1,15:100.0
6,1,15:159.10
11,1,15:100.0
12,1,15:100.0
13,1,15:100.0
-9,2,15:159.10
-8,2,15:159.10
-7,2,15:159.10
-6,2,15:159.10
-5,2,15:159.10
-4,2,15:159.10
3,2,15:159.10
4,2,15:159.10
5,2,15:100.0
6,2,15:159.10
9,2,15:100.0
10,2,15:100.0
11,2,15:100.0
12,2,15:100.0
13,2,15:159.10
-12,3,15:159.10
-11,3,15:159.10
-10,3,15:82.0
-9,3,15:82.0
-8,3,15:100.0
-7,3,15:100.0
-6,3,15:100.0
-5,3,15:159.10
-4,3,15:159.10
-3,3,15:159.10
4,3,15:159.10
5,3,15:159.10
6,3,15:82.0
7,3,15:100.0
8,3,15:100.0
9,3,15:100.0
10,3,15:100.0
11,3,15:100.0
12,3,15:100.0
13,3,15:159.10
-10,4,15:82.0
-9,4,15:100.0
-6,4,15:100.0
-4,4,15:82.0
-3,4,15:82.0
5,4,15:82.0
6,4,15:82.0
7,4,15:100.0
8,4,15:100.0
9,4,15:100.0
10,4,15:159.10
11,4,15:159.10
12,4,15:159.10
13,4,15:159.10
-10,5,15:82.0
-9,5,15:82.0
-8,5,15:100.0
-6,5,15:100.0
-5,5,15:100.0
-4,5,15:82.0
-3,5,15:82.0
-2,5,15:82.0
6,5,15:82.0
7,5,15:82.0
8,5,15:82.0
9,5,15:82.0
-10,6,15:82.0
-9,6,15:82.0
-8,6,15:100.0
-7,6,15:100.0
-6,6,15:100.0
-5,6,15:82.0
-4,6,15:82.0
-3,6,15:82.0
-2,6,15:82.0
-1,6,15:82.0
-10,7,15:82.0
-9,7,15:82.0
-8,7,15:82.0
-7,7,15:159.10
-6,7,15:159.10
-5,7,15:82.0
-4,7,15:82.0
-10,8,15:159.10
-8,8,15:159.10
-7,8,15:159.10
-6,8,15:159.10
-5,8,15:159.10
-6,9,15:159.10
-5,9,15:159.10
-5,10,15:159.10
0,-9,16:100.0
0,-8,16:100.0
8,-8,16:100.0
6,-7,16:159.10
3,-6,16:159.10
5,-6,16:159.10
6,-6,16:159.10
7,-6,16:100.0
9,-6,16:159.10
11,-6,16:159.10
1,-5,16:100.0
2,-5,16:100.0
3,-5,16:100.0
4,-5,16:159.10
5,-5,16:159.10
6,-5,16:159.10
7,-5,16:159.10
8,-5,16:159.10
9,-5,16:100.0
10,-5,16:159.10
11,-5,16:159.10
2,-4,16:100.0
3,-4,16:100.0
4,-4,16:100.0
5,-4,16:159.10
6,-4,16:159.10
9,-4,16:82.0
10,-4,16:100.0
11,-4,16:100.0
12,-4,16:159.10
3,-3,16:100.0
4,-3,16:100.0
5,-3,16:159.10
6,-3,16:159.10
7,-3,16:159.10
8,-3,16:100.15
9,-3,16:82.0
10,-3,16:100.0
11,-3,16:100.0
12,-3,16:159.10
13,-3,16:159.10
2,-2,16:100.0
3,-2,16:100.0
4,-2,16:159.10
5,-2,16:159.10
6,-2,16:159.10
7,-2,16:159.10
8,-2,16:159.10
9,-2,16:82.0
10,-2,16:82.0
11,-2,16:82.0
12,-2,16:159.10
13,-2,16:159.10
4,-1,16:159.10
5,-1,16:159.10
6,-1,16:159.10
7,-1,16:159.10
8,-1,16:159.10
9,-1,16:159.10
10,-1,16:159.10
11,-1,16:100.0
12,-1,16:159.10
13,-1,16:159.10
-8,0,16:159.10
4,0,16:159.10
5,0,16:159.10
6,0,16:100.0
7,0,16:159.10
8,0,16:159.10
9,0,16:159.10
10,0,16:159.10
11,0,16:100.0
12,0,16:159.10
13,0,16:159.10
-8,1,16:159.10
-4,1,16:159.10
4,1,16:159.10
5,1,16:159.10
6,1,16:159.10
7,1,16:100.0
8,1,16:159.10
9,1,16:159.10
10,1,16:159.10
11,1,16:159.10
12,1,16:159.10
13,1,16:159.10
-8,2,16:159.10
-7,2,16:159.10
-6,2,16:159.10
-5,2,16:159.10
5,2,16:159.10
6,2,16:159.10
7,2,16:100.0
8,2,16:100.0
9,2,16:159.10
10,2,16:159.10
12,2,16:159.10
-11,3,16:159.10
-9,3,16:82.0
-8,3,16:82.0
-7,3,16:159.10
-6,3,16:159.10
-5,3,16:159.10
6,3,16:82.0
7,3,16:82.0
8,3,16:82.0
9,3,16:159.10
10,3,16:159.10
11,3,16:159.10
12,3,16:159.10
-10,4,16:82.0
-9,4,16:82.0
-8,4,16:100.0
-7,4,16:100.0
-6,4,16:159.10
7,4,16:82.0
8,4,16:82.0
9,4,16:82.0
12,4,16:159.10
13,4,16:159.10
-9,5,16:82.0
-8,5,16:82.0
-7,5,16:100.0
-6,5,16:159.10
-5,5,16:82.0
-4,5,16:82.0
-3,5,16:82.0
-2,5,16:82.0
7,5,16:82.0
-9,6,16:82.0
-8,6,16:82.0
-7,6,16:82.0
-6,6,16:159.10
-5,6,16:82.0
-10,7,16:82.0
-9,7,16:82.0
-7,7,16:159.10
-6,7,16:159.10
-6,8,16:159.10
-6,9,16:159.10
4,-11,17:100.0
5,-11,17:100.0
1,-10,17:100.0
2,-10,17:100.0
3,-10,17:100.0
4,-10,17:100.0
5,-10,17:100.0
6,-10,17:100.0
0,-9,17:159.10
1,-9,17:100.0
2,-9,17:100.0
3,-9,17:100.0
4,-9,17:100.0
5,-9,17:100.0
6,-9,17:100.0
7,-9,17:100.0
0,-8,17:159.10
1,-8,17:100.0
2,-8,17:100.0
3,-8,17:100.0
4,-8,17:100.0
5,-8,17:100.0
6,-8,17:100.0
7,-8,17:100.0
8,-8,17:159.10
0,-7,17:100.0
1,-7,17:100.0
2,-7,17:100.0
3,-7,17:100.0
5,-7,17:100.0
6,-7,17:159.10
7,-7,17:100.0
8,-7,17:100.0
9,-7,17:100.0
0,-6,17:100.0
1,-6,17:100.0
2,-6,17:100.0
3,-6,17:159.10
4,-6,17:100.0
5,-6,17:159.10
6,-6,17:159.10
7,-6,17:159.10
8,-6,17:100.0
9,-6,17:159.10
11,-6,17:159.10
0,-5,17:100.0
1,-5,17:159.10
2,-5,17:159.10
3,-5,17:159.10
4,-5,17:159.10
5,-5,17:159.10
6,-5,17:159.10
7,-5,17:159.10
8,-5,17:159.10
9,-5,17:82.0
11,-5,17:82.0
1,-4,17:100.0
2,-4,17:159.10
3,-4,17:159.10
4,-4,17:159.10
5,-4,17:159.10
6,-4,17:159.10
9,-4,17:82.0
10,-4,17:82.0
11,-4,17:82.0
2,-3,17:100.0
3,-3,17:159.10
4,-3,17:159.10
5,-3,17:159.10
6,-3,17:159.10
7,-3,17:159.10
8,-3,17:82.0
9,-3,17:82.0
10,-3,17:82.0
11,-3,17:82.0
2,-2,17:159.10
3,-2,17:159.10
4,-2,17:159.10
5,-2,17:159.10
6,-2,17:159.10
7,-2,17:159.10
8,-2,17:82.0
11,-2,17:82.0
12,-2,17:82.0
6,-1,17:159.10
7,-1,17:159.10
11,-1,17:82.0
12,-1,17:159.10
13,-1,17:159.10
5,0,17:159.10
6,0,17:159.10
11,0,17:159.10
12,0,17:159.10
6,1,17:159.10
7,1,17:159.10
11,1,17:159.10
12,1,17:159.10
-8,2,17:159.10
-5,2,17:159.10
7,2,17:159.10
8,2,17:159.10
9,2,17:159.10
10,2,17:159.10
11,2,17:100.0
-8,3,17:82.0
-7,3,17:159.10
-6,3,17:159.10
8,3,17:82.0
9,3,17:159.10
11,3,17:159.10
12,3,17:159.10
-9,4,17:82.0
-8,4,17:82.0
-7,4,17:82.0
-6,4,17:159.10
7,4,17:82.0
8,4,17:82.0
-8,5,17:82.0
-7,5,17:82.0
-6,5,17:159.10
-5,5,17:159.10
-4,5,17:82.0
-9,6,17:82.0
-7,6,17:82.0
-6,7,17:159.10
-6,8,17:159.10
1,-10,18:159.10
5,-10,18:159.10
2,-9,18:82.0
3,-9,18:82.0
4,-9,18:82.0
5,-9,18:82.0
6,-9,18:159.10
1,-8,18:82.0
2,-8,18:82.0
3,-8,18:82.0
4,-8,18:100.0
5,-8,18:82.0
6,-8,18:159.10
1,-7,18:82.0
2,-7,18:82.0
3,-7,18:100.0
4,-7,18:100.0
5,-7,18:82.0
6,-7,18:159.10
7,-7,18:159.10
8,-7,18:159.10
9,-7,18:159.10
0,-6,18:159.10
1,-6,18:159.10
2,-6,18:82.0
3,-6,18:82.0
4,-6,18:82.0
5,-6,18:159.10
6,-6,18:159.10
7,-6,18:159.10
2,-5,18:159.10
3,-5,18:159.10
4,-5,18:100.0
5,-5,18:100.0
6,-5,18:159.10
7,-5,18:159.10
11,-5,18:82.0
2,-4,18:159.10
3,-4,18:159.10
4,-4,18:159.10
5,-4,18:159.10
6,-4,18:159.10
11,-4,18:82.0
3,-3,18:159.10
4,-3,18:159.10
5,-3,18:159.10
6,-3,18:159.10
7,-3,18:159.10
10,-3,18:82.0
3,-2,18:159.10
7,-2,18:159.10
8,-2,18:82.0
9,-2,18:82.0
10,-2,18:82.0
7,-1,18:159.10
8,-1,18:100.0
9,-1,18:82.0
10,-1,18:82.0
11,-1,18:82.0
12,-1,18:159.10
13,-1,18:159.10
7,0,18:159.10
8,0,18:100.0
10,0,18:100.0
11,0,18:159.10
7,1,18:159.10
8,1,18:159.10
9,1,18:100.0
10,1,18:100.0
11,1,18:159.10
8,2,18:159.10
9,2,18:159.10
10,2,18:159.10
11,2,18:159.10
8,3,18:159.10
11,3,18:159.10
-7,4,18:159.10
2,-9,19:82.0
5,-9,19:82.0
3,-8,19:82.0
4,-8,19:82.0
5,-8,19:82.0
2,-7,19:82.0
3,-7,19:82.0
4,-7,19:82.0
5,-7,19:82.0
6,-7,19:159.10
7,-7,19:159.10
8,-7,19:159.10
1,-6,19:159.10
2,-6,19:82.0
3,-6,19:82.0
4,-6,19:82.0
5,-6,19:159.10
6,-6,19:159.10
3,-5,19:159.10
4,-5,19:159.10
5,-5,19:159.10
6,-5,19:159.10
3,-4,19:159.10
3,-3,19:159.10
10,-3,19:82.0
8,-2,19:82.0
10,-2,19:82.0
8,-1,19:159.10
9,-1,19:82.0
10,-1,19:82.0
8,0,19:159.10
9,0,19:159.10
10,0,19:159.10
11,0,19:159.10
9,1,19:159.10
10,1,19:159.10
