[META]
version=2.0
spawnOnBlockType=2
spawnSunlight=True
spawnDarkness=True
spawnWater=False
spawnLava=False
underFill=False
randomRotation=True
dig=True
tree=False
branch=False
needsFoundation=True
rarity=100
collisionPercentage=20
spawnElevationMin=0
spawnElevationMax=200
spawnInBiome=Custom
[DATA]
-11,6,-6:100.15
-10,6,-6:100.15
-12,7,-6:100.15
-11,7,-6:100.15
-5,7,-6:100.15
-11,8,-6:100.15
-6,8,-6:100.15
-8,1,-5:100.15
-7,1,-5:100.15
-10,5,-5:100.15
-7,5,-5:100.15
-6,5,-5:100.15
-11,6,-5:100.15
-8,6,-5:100.15
-6,6,-5:100.15
-7,7,-5:100.15
-6,7,-5:100.15
-5,7,-5:100.15
-4,7,-5:100.15
-10,8,-5:100.15
-8,8,-5:100.15
-11,9,-5:100.15
-6,9,-5:100.15
-5,9,-5:100.15
-8,-1,-4:100.15
-6,-1,-4:100.15
-7,0,-4:100.15
-6,0,-4:100.15
-5,0,-4:100.15
-8,1,-4:100.15
-7,1,-4:100.15
-5,1,-4:100.15
-9,2,-4:100.15
-8,2,-4:100.15
-7,2,-4:100.15
-6,2,-4:100.15
-11,3,-4:100.15
-9,3,-4:100.15
-8,3,-4:100.15
-7,3,-4:100.15
-11,4,-4:100.15
-10,4,-4:100.15
-9,4,-4:100.15
-8,4,-4:100.15
-7,4,-4:100.15
-6,4,-4:100.15
-4,4,-4:100.15
-12,5,-4:100.15
-11,5,-4:100.15
-10,5,-4:100.15
-9,5,-4:100.15
-8,5,-4:100.15
-7,5,-4:100.15
-6,5,-4:100.15
-12,6,-4:100.15
-11,6,-4:100.15
-10,6,-4:100.15
-9,6,-4:100.15
-8,6,-4:100.15
-6,6,-4:100.15
-5,6,-4:100.15
-4,6,-4:100.15
-13,7,-4:100.15
-12,7,-4:100.15
-11,7,-4:100.15
-10,7,-4:100.15
-9,7,-4:100.15
-8,7,-4:100.15
-7,7,-4:100.15
-6,7,-4:100.15
-5,7,-4:100.15
-4,7,-4:100.15
-11,8,-4:100.15
-9,8,-4:100.15
-8,8,-4:100.15
-7,8,-4:100.15
-6,8,-4:100.15
-11,9,-4:100.15
-7,9,-4:100.15
-6,-2,-3:100.15
-5,-2,-3:100.15
-4,-2,-3:100.15
-7,-1,-3:100.15
-6,-1,-3:100.15
-5,-1,-3:100.15
-10,0,-3:100.15
-8,0,-3:100.15
-7,0,-3:100.15
-6,0,-3:100.15
-5,0,-3:100.15
-8,1,-3:100.15
-6,1,-3:100.15
-5,1,-3:100.15
-4,1,-3:100.15
-12,2,-3:100.15
-11,2,-3:100.15
-9,2,-3:100.15
-8,2,-3:100.15
-7,2,-3:100.15
-6,2,-3:100.15
-5,2,-3:100.15
-4,2,-3:100.15
-9,3,-3:100.15
-8,3,-3:100.15
-7,3,-3:100.15
-6,3,-3:100.15
-5,3,-3:100.15
-13,4,-3:100.15
-12,4,-3:100.15
-10,4,-3:100.15
-9,4,-3:100.15
-8,4,-3:100.15
-7,4,-3:100.15
-6,4,-3:100.15
-5,4,-3:100.15
-12,5,-3:100.15
-11,5,-3:100.15
-10,5,-3:100.15
-8,5,-3:100.15
-7,5,-3:100.15
-6,5,-3:100.15
-4,5,-3:100.15
-12,6,-3:100.15
-11,6,-3:100.15
-10,6,-3:100.15
-9,6,-3:100.15
-8,6,-3:100.15
-7,6,-3:100.15
-6,6,-3:100.15
-5,6,-3:100.15
-4,6,-3:100.15
-13,7,-3:100.15
-12,7,-3:100.15
-11,7,-3:100.15
-10,7,-3:100.15
-9,7,-3:100.15
-8,7,-3:100.15
-7,7,-3:100.15
-6,7,-3:100.15
-5,7,-3:100.15
-4,7,-3:100.15
-11,8,-3:100.15
-10,8,-3:100.15
-9,8,-3:100.15
-8,8,-3:100.15
-6,8,-3:100.15
-5,8,-3:100.15
-4,8,-3:100.15
-11,9,-3:100.15
-7,9,-3:100.15
-6,9,-3:100.15
-10,10,-3:100.15
-9,10,-3:100.15
-4,-2,-2:100.15
-8,-1,-2:100.15
-6,-1,-2:100.15
-5,-1,-2:100.15
-4,-1,-2:100.15
-10,0,-2:100.15
-9,0,-2:100.15
-8,0,-2:100.15
-7,0,-2:100.15
-6,0,-2:100.15
-5,0,-2:100.15
-3,0,-2:100.15
-9,1,-2:100.15
-8,1,-2:100.15
-7,1,-2:100.15
-5,1,-2:100.15
-4,1,-2:100.15
-11,2,-2:100.15
-10,2,-2:100.15
-9,2,-2:100.15
-8,2,-2:100.15
-7,2,-2:100.15
-6,2,-2:100.15
-5,2,-2:100.15
-4,2,-2:100.15
-11,3,-2:100.15
-10,3,-2:100.15
-9,3,-2:100.15
-8,3,-2:100.15
-7,3,-2:100.15
-6,3,-2:100.15
-5,3,-2:100.15
-4,3,-2:100.15
-13,4,-2:100.15
-12,4,-2:100.15
-11,4,-2:100.15
-10,4,-2:100.15
-9,4,-2:100.15
-8,4,-2:100.15
-7,4,-2:100.15
-6,4,-2:100.15
-5,4,-2:100.15
-4,4,-2:100.15
-3,4,-2:100.15
-2,4,-2:100.15
-12,5,-2:100.15
-11,5,-2:100.15
-10,5,-2:100.15
-9,5,-2:100.15
-8,5,-2:100.15
-7,5,-2:100.15
-6,5,-2:100.15
-5,5,-2:100.15
-4,5,-2:100.15
-3,5,-2:100.15
-12,6,-2:100.15
-11,6,-2:100.15
-10,6,-2:100.15
-9,6,-2:100.15
-8,6,-2:100.15
-7,6,-2:100.15
-6,6,-2:100.15
-5,6,-2:100.15
-4,6,-2:100.15
-3,6,-2:100.15
-12,7,-2:100.15
-11,7,-2:100.15
-10,7,-2:100.15
-9,7,-2:100.15
-8,7,-2:100.15
-7,7,-2:100.15
-6,7,-2:100.15
-5,7,-2:100.15
-12,8,-2:100.15
-11,8,-2:100.15
-10,8,-2:100.15
-9,8,-2:100.15
-8,8,-2:100.15
-7,8,-2:100.15
-6,8,-2:100.15
-11,9,-2:100.15
-10,9,-2:100.15
-9,9,-2:100.15
-8,9,-2:100.15
-7,9,-2:100.15
-10,10,-2:100.15
-9,10,-2:100.15
-4,-2,-1:100.15
-10,-1,-1:100.15
-7,-1,-1:100.15
-6,-1,-1:100.15
-10,0,-1:100.15
-9,0,-1:100.15
-8,0,-1:100.15
-7,0,-1:100.15
-6,0,-1:100.15
-5,0,-1:100.15
-4,0,-1:100.15
-12,1,-1:100.15
-10,1,-1:100.15
-9,1,-1:100.15
-8,1,-1:100.15
-7,1,-1:100.15
-6,1,-1:100.15
-5,1,-1:100.15
-4,1,-1:100.15
-10,2,-1:100.15
-9,2,-1:100.15
-8,2,-1:100.15
-7,2,-1:100.15
-6,2,-1:100.15
-5,2,-1:100.15
-4,2,-1:100.15
-12,3,-1:100.15
-11,3,-1:100.15
-9,3,-1:100.15
-8,3,-1:100.15
-7,3,-1:100.15
-6,3,-1:100.15
-5,3,-1:100.15
-4,3,-1:100.15
-2,3,-1:100.15
-12,4,-1:100.15
-10,4,-1:100.15
-9,4,-1:100.15
-8,4,-1:100.15
-7,4,-1:100.15
-6,4,-1:100.15
-5,4,-1:100.15
-4,4,-1:100.15
-12,5,-1:100.15
-11,5,-1:100.15
-10,5,-1:100.15
-8,5,-1:100.15
-7,5,-1:100.15
-6,5,-1:100.15
-4,5,-1:100.15
-3,5,-1:100.15
-12,6,-1:100.15
-11,6,-1:100.15
-10,6,-1:100.15
-9,6,-1:100.15
-8,6,-1:100.15
-7,6,-1:100.15
-6,6,-1:100.15
-5,6,-1:100.15
-4,6,-1:100.15
-3,6,-1:100.15
-11,7,-1:100.15
-10,7,-1:100.15
-9,7,-1:100.15
-8,7,-1:100.15
-7,7,-1:100.15
-5,7,-1:100.15
-10,8,-1:100.15
-7,8,-1:100.15
-4,8,-1:100.15
-11,9,-1:100.15
-10,9,-1:100.15
-9,10,-1:100.15
-8,10,-1:100.15
-7,-2,0:100.15
-6,-2,0:100.15
-10,-1,0:100.15
-9,-1,0:100.15
-8,-1,0:100.15
-7,-1,0:100.15
-6,-1,0:100.15
-5,-1,0:100.15
-11,0,0:100.15
-10,0,0:100.15
-9,0,0:100.15
-7,0,0:100.15
-6,0,0:100.15
-5,0,0:100.15
-4,0,0:100.15
-12,1,0:100.15
-11,1,0:100.15
-9,1,0:100.15
-8,1,0:100.15
-7,1,0:100.15
-6,1,0:100.15
-5,1,0:100.15
-3,1,0:100.15
-12,2,0:100.15
-10,2,0:100.15
-9,2,0:100.15
-7,2,0:100.15
-6,2,0:100.15
-5,2,0:100.15
-3,2,0:100.15
-2,2,0:100.15
-12,3,0:100.15
-10,3,0:100.15
-9,3,0:100.15
-8,3,0:100.15
-7,3,0:100.15
-6,3,0:100.15
-5,3,0:100.15
-4,3,0:100.15
-2,3,0:100.15
-12,4,0:100.15
-11,4,0:100.15
-10,4,0:100.15
-9,4,0:100.15
-8,4,0:100.15
-7,4,0:100.15
-3,4,0:100.15
-2,4,0:100.15
-12,5,0:100.15
-10,5,0:100.15
-9,5,0:100.15
-8,5,0:100.15
-7,5,0:100.15
-6,5,0:100.15
-5,5,0:100.15
-4,5,0:100.15
-3,5,0:100.15
-12,6,0:100.15
-11,6,0:100.15
-10,6,0:100.15
-9,6,0:100.15
-7,6,0:100.15
-6,6,0:100.15
-5,6,0:100.15
-4,6,0:100.15
-3,6,0:100.15
-12,7,0:100.15
-10,7,0:100.15
-9,7,0:100.15
-7,7,0:100.15
-6,7,0:100.15
-5,7,0:100.15
-4,7,0:100.15
-12,8,0:100.15
-9,8,0:100.15
-7,8,0:100.15
-4,8,0:100.15
-12,9,0:100.15
-11,9,0:100.15
-9,9,0:100.15
-7,9,0:100.15
-6,9,0:100.15
-5,9,0:100.15
-4,9,0:100.15
-11,10,0:100.15
-10,10,0:100.15
-9,10,0:100.15
-8,10,0:100.15
-7,10,0:100.15
-6,10,0:100.15
-9,-1,1:100.15
-8,-1,1:100.15
-7,-1,1:100.15
-6,-1,1:100.15
-5,-1,1:100.15
-11,0,1:100.15
-10,0,1:100.15
-9,0,1:100.15
-5,0,1:100.15
-4,0,1:100.15
-11,1,1:100.15
-10,1,1:100.15
-8,1,1:100.15
-7,1,1:100.15
-3,1,1:100.15
-11,2,1:100.15
-8,2,1:100.15
-6,2,1:100.15
-3,2,1:100.15
-2,2,1:100.15
-12,3,1:100.15
-8,3,1:100.15
-7,3,1:100.15
-6,3,1:100.15
-3,3,1:100.15
-2,3,1:100.15
-12,4,1:100.15
-7,4,1:100.15
-6,4,1:100.15
-3,4,1:100.15
-12,5,1:100.15
-11,5,1:100.15
-4,5,1:100.15
-3,5,1:100.15
-12,6,1:100.15
-11,6,1:100.15
-4,6,1:100.15
-12,7,1:100.15
-11,7,1:100.15
-4,7,1:100.15
-12,8,1:100.15
-11,8,1:100.15
-5,8,1:100.15
-4,8,1:100.15
-11,9,1:100.15
-10,9,1:100.15
-9,9,1:100.15
-8,9,1:100.15
-7,9,1:100.15
-6,9,1:100.15
-5,9,1:100.15
-9,10,1:100.15
-8,10,1:100.15
-8,-1,2:100.15
-7,-1,2:100.15
-6,-1,2:100.15
-5,-1,2:100.15
-10,0,2:100.15
-9,0,2:100.15
-8,0,2:100.15
-5,0,2:100.15
-4,0,2:100.15
-10,1,2:100.15
-4,1,2:100.15
-3,1,2:100.15
-11,2,2:100.15
-10,2,2:100.15
-3,2,2:100.15
-11,3,2:100.15
-3,3,2:100.15
-11,4,2:100.15
-4,4,2:100.15
-3,4,2:100.15
-11,5,2:100.15
-10,5,2:100.15
-4,5,2:100.15
-11,6,2:100.15
-10,6,2:100.15
-4,6,2:100.15
-11,7,2:100.15
-5,7,2:100.15
-4,7,2:100.15
-11,8,2:100.15
-10,8,2:100.15
-9,8,2:100.15
-7,8,2:100.15
-6,8,2:100.15
-5,8,2:100.15
-9,9,2:100.15
-8,9,2:100.15
-7,9,2:100.15
-7,-1,3:100.15
-6,-1,3:100.15
-5,-1,3:100.15
-9,0,3:100.15
-8,0,3:100.15
-7,0,3:100.15
-6,0,3:100.15
-5,0,3:100.15
-4,0,3:100.15
-3,0,3:100.15
-10,1,3:100.15
-9,1,3:100.15
-3,1,3:100.15
-2,1,3:100.15
-11,2,3:100.15
-10,2,3:100.15
-3,2,3:100.15
-2,2,3:100.15
-11,3,3:100.15
-10,3,3:100.15
-3,3,3:100.15
-10,4,3:100.15
-4,4,3:100.15
-3,4,3:100.15
-10,5,3:100.15
-4,5,3:100.15
-10,6,3:100.15
-5,6,3:100.15
-4,6,3:100.15
-10,7,3:100.15
-9,7,3:100.15
-7,7,3:100.15
-6,7,3:100.15
-5,7,3:100.15
-9,8,3:100.15
-8,8,3:100.15
-7,8,3:100.15
-6,8,3:100.15
-8,0,4:100.15
-7,0,4:100.15
-6,0,4:100.15
-5,0,4:100.15
-4,0,4:100.15
-3,0,4:100.15
-9,1,4:100.15
-8,1,4:100.15
-7,1,4:100.15
-2,1,4:100.15
-1,1,4:100.15
-10,2,4:100.15
-9,2,4:100.15
-2,2,4:100.15
-1,2,4:100.15
-10,3,4:100.15
-9,3,4:100.15
-2,3,4:100.15
-1,3,4:100.15
-9,4,4:100.15
-3,4,4:100.15
-2,4,4:100.15
-9,5,4:100.15
-4,5,4:100.15
-3,5,4:100.15
-10,6,4:100.15
-9,6,4:100.15
-6,6,4:100.15
-5,6,4:100.15
-4,6,4:100.15
-9,7,4:100.15
-8,7,4:100.15
-7,7,4:100.15
-6,7,4:100.15
-5,0,5:100.15
-4,0,5:100.15
-3,0,5:100.15
-2,0,5:100.15
-1,0,5:100.15
-8,1,5:100.15
-7,1,5:100.15
-6,1,5:100.15
-5,1,5:100.15
-4,1,5:100.15
-2,1,5:100.15
-1,1,5:100.15
0,1,5:100.15
-9,2,5:100.15
-8,2,5:100.15
-7,2,5:100.15
-1,2,5:100.15
0,2,5:100.15
-9,3,5:100.15
-8,3,5:100.15
-7,3,5:100.15
-1,3,5:100.15
-9,4,5:100.15
-8,4,5:100.15
-7,4,5:100.15
-3,4,5:100.15
-2,4,5:100.15
-1,4,5:100.15
-9,5,5:100.15
-8,5,5:100.15
-7,5,5:100.15
-6,5,5:100.15
-5,5,5:100.15
-4,5,5:100.15
-3,5,5:100.15
-8,6,5:100.15
-7,6,5:100.15
-6,6,5:100.15
-5,6,5:100.15
-3,0,6:100.15
-2,0,6:100.15
-1,0,6:100.15
0,0,6:100.15
-6,1,6:100.15
-5,1,6:100.15
-4,1,6:100.15
0,1,6:100.15
-7,2,6:100.15
-6,2,6:100.15
-5,2,6:100.15
-1,2,6:100.15
0,2,6:100.15
-6,3,6:100.15
-5,3,6:100.15
-1,3,6:100.15
-6,4,6:100.15
-5,4,6:100.15
-4,4,6:100.15
-3,4,6:100.15
-2,4,6:100.15
-1,4,6:100.15
-7,5,6:100.15
-6,5,6:100.15
-5,5,6:100.15
-4,5,6:100.15
-3,0,7:100.15
-2,0,7:100.15
-1,0,7:100.15
0,0,7:100.15
1,0,7:100.15
-5,1,7:100.15
-4,1,7:100.15
0,1,7:100.15
1,1,7:100.15
-4,2,7:100.15
-1,2,7:100.15
0,2,7:100.15
-4,3,7:100.15
-3,3,7:100.15
-2,3,7:100.15
-1,3,7:100.15
-4,4,7:100.15
-3,4,7:100.15
-2,4,7:100.15
0,-1,8:100.15
-3,0,8:100.15
-2,0,8:100.15
-1,0,8:100.15
0,0,8:100.15
1,0,8:100.15
-4,1,8:100.15
-3,1,8:100.15
1,1,8:100.15
-3,2,8:100.15
-1,2,8:100.15
0,2,8:100.15
-3,3,8:100.15
-2,3,8:100.15
-1,3,8:100.15
4,-8,9:100.15
3,-7,9:100.15
4,-7,9:100.15
3,-3,9:100.15
4,-3,9:100.15
2,-2,9:100.15
3,-2,9:100.15
4,-2,9:100.15
-2,-1,9:100.15
-1,-1,9:100.15
0,-1,9:100.15
1,-1,9:100.15
2,-1,9:100.15
3,-1,9:100.15
-3,0,9:100.15
-2,0,9:100.15
-1,0,9:100.15
1,0,9:100.15
-3,1,9:100.15
1,1,9:100.15
-3,2,9:100.15
0,2,9:100.15
1,2,9:100.15
-2,3,9:100.15
-1,3,9:100.15
0,3,9:100.15
4,-7,10:100.15
5,-7,10:100.15
4,-6,10:100.15
3,-5,10:100.15
4,-5,10:100.15
3,-4,10:100.15
4,-4,10:100.15
5,-4,10:100.15
2,-3,10:100.15
3,-3,10:100.15
4,-3,10:100.15
5,-3,10:100.15
-2,-2,10:100.15
-1,-2,10:100.15
1,-2,10:100.15
2,-2,10:100.15
3,-2,10:100.15
4,-2,10:100.15
-3,-1,10:100.15
-2,-1,10:100.15
-1,-1,10:100.15
0,-1,10:100.15
1,-1,10:100.15
2,-1,10:100.15
3,-1,10:100.15
-4,0,10:100.15
-3,0,10:100.15
1,0,10:100.15
2,0,10:100.15
-4,1,10:100.15
-3,1,10:100.15
1,1,10:100.15
2,1,10:100.15
-4,2,10:100.15
-3,2,10:100.15
0,2,10:100.15
1,2,10:100.15
-3,3,10:100.15
-2,3,10:100.15
-1,3,10:100.15
0,3,10:100.15
-1,4,10:100.15
5,-9,11:100.0
6,-9,11:100.0
3,-8,11:100.0
6,-8,11:100.15
2,-7,11:100.0
3,-7,11:100.0
4,-7,11:159.10
5,-7,11:100.15
7,-7,11:100.0
2,-6,11:100.0
3,-6,11:100.0
5,-6,11:100.0
6,-6,11:100.0
2,-5,11:100.0
3,-5,11:159.10
4,-5,11:159.10
5,-5,11:100.0
6,-5,11:100.0
7,-5,11:100.0
8,-5,11:100.0
2,-4,11:100.0
4,-4,11:100.15
5,-4,11:100.15
6,-4,11:100.0
-2,-3,11:100.15
-1,-3,11:100.15
2,-3,11:159.10
4,-3,11:159.10
5,-3,11:159.10
6,-3,11:100.0
-2,-2,11:100.15
-1,-2,11:100.15
0,-2,11:100.15
1,-2,11:100.15
-3,-1,11:100.15
-2,-1,11:100.15
0,-1,11:100.15
1,-1,11:100.15
2,-1,11:100.15
-4,0,11:100.15
-3,0,11:100.15
0,0,11:100.15
1,0,11:100.15
2,0,11:100.15
3,0,11:100.15
-4,1,11:100.15
1,1,11:100.15
2,1,11:100.15
-4,2,11:100.15
1,2,11:100.15
-4,3,11:100.15
-3,3,11:100.15
-2,3,11:100.15
0,3,11:100.15
1,3,11:100.15
-2,4,11:100.15
-1,4,11:100.15
0,4,11:100.15
3,-9,12:100.0
4,-9,12:100.0
5,-9,12:159.10
6,-9,12:159.10
7,-9,12:100.0
8,-9,12:100.0
3,-8,12:159.10
4,-8,12:100.0
5,-8,12:100.0
6,-8,12:159.10
7,-8,12:100.0
8,-8,12:100.0
9,-8,12:100.0
2,-7,12:159.10
3,-7,12:159.10
4,-7,12:159.10
5,-7,12:159.10
6,-7,12:100.0
7,-7,12:159.10
8,-7,12:100.0
9,-7,12:100.0
10,-7,12:100.0
2,-6,12:159.10
3,-6,12:159.10
4,-6,12:100.0
5,-6,12:159.10
6,-6,12:159.10
7,-6,12:100.0
8,-6,12:100.0
9,-6,12:100.0
10,-6,12:100.0
2,-5,12:159.10
3,-5,12:159.10
4,-5,12:159.10
5,-5,12:159.10
6,-5,12:159.10
7,-5,12:159.10
8,-5,12:159.10
9,-5,12:100.0
10,-5,12:100.0
-2,-4,12:100.15
2,-4,12:159.10
3,-4,12:100.0
4,-4,12:159.10
5,-4,12:159.10
6,-4,12:159.10
7,-4,12:100.0
8,-4,12:100.0
9,-4,12:100.0
10,-4,12:100.0
-2,-3,12:100.15
-1,-3,12:100.15
2,-3,12:159.10
4,-3,12:159.10
5,-3,12:159.10
6,-3,12:159.10
8,-3,12:100.0
9,-3,12:100.0
10,-3,12:100.0
-2,-2,12:100.15
-1,-2,12:100.15
2,-2,12:100.0
3,-2,12:100.0
4,-2,12:100.0
5,-2,12:100.0
6,-2,12:100.0
7,-2,12:100.0
8,-2,12:100.0
9,-2,12:100.0
-3,-1,12:100.15
-2,-1,12:100.15
-1,-1,12:100.15
3,-1,12:100.0
4,-1,12:100.0
5,-1,12:100.0
6,-1,12:100.0
7,-1,12:100.0
8,-1,12:100.0
-4,0,12:100.15
-3,0,12:100.15
-2,0,12:100.15
-1,0,12:100.15
0,0,12:100.15
1,0,12:100.15
2,0,12:100.15
3,0,12:100.15
5,0,12:100.0
6,0,12:100.0
-5,1,12:100.15
-4,1,12:100.15
-3,1,12:100.15
-2,1,12:100.15
-1,1,12:100.15
0,1,12:100.15
1,1,12:100.15
2,1,12:100.15
3,1,12:100.15
4,1,12:100.15
5,1,12:100.15
-6,2,12:100.15
-5,2,12:100.15
-4,2,12:100.15
-3,2,12:100.15
-2,2,12:100.15
0,2,12:100.15
1,2,12:100.15
2,2,12:100.15
3,2,12:100.15
4,2,12:100.15
-5,3,12:100.15
-3,3,12:100.15
0,3,12:100.15
-2,4,12:100.15
-1,4,12:100.15
0,4,12:100.15
-1,5,12:100.15
8,-9,13:159.10
4,-8,13:159.10
5,-8,13:159.10
6,-8,13:159.10
7,-8,13:159.10
8,-8,13:159.10
4,-7,13:159.10
5,-7,13:159.10
6,-7,13:159.10
7,-7,13:159.10
8,-7,13:159.10
2,-6,13:100.0
3,-6,13:82.0
4,-6,13:82.0
5,-6,13:100.0
6,-6,13:100.0
7,-6,13:159.10
8,-6,13:159.10
9,-6,13:159.10
1,-5,13:100.0
2,-5,13:159.10
3,-5,13:82.0
4,-5,13:82.0
5,-5,13:82.0
6,-5,13:100.0
7,-5,13:100.0
8,-5,13:159.10
9,-5,13:159.10
10,-5,13:159.10
-2,-4,13:100.15
2,-4,13:159.10
3,-4,13:82.0
4,-4,13:82.0
5,-4,13:82.0
6,-4,13:159.10
7,-4,13:159.10
8,-4,13:159.10
9,-4,13:159.10
-3,-3,13:100.0
-2,-3,13:100.15
-1,-3,13:100.15
1,-3,13:100.0
2,-3,13:100.0
4,-3,13:159.10
5,-3,13:159.10
6,-3,13:159.10
8,-3,13:159.10
9,-3,13:159.10
-3,-2,13:100.0
1,-2,13:100.0
2,-2,13:100.0
3,-2,13:100.0
4,-2,13:159.10
5,-2,13:159.10
6,-2,13:159.10
7,-2,13:159.10
8,-2,13:159.10
9,-2,13:100.0
10,-2,13:100.0
0,-1,13:100.0
2,-1,13:100.0
3,-1,13:159.10
4,-1,13:159.10
5,-1,13:100.0
6,-1,13:159.10
7,-1,13:159.10
8,-1,13:159.10
9,-1,13:100.0
10,-1,13:100.0
4,0,13:100.0
7,0,13:100.0
8,0,13:100.15
9,0,13:100.15
10,0,13:100.15
-5,1,13:100.15
-4,1,13:100.15
-1,1,13:100.15
1,1,13:100.15
2,1,13:100.15
3,1,13:100.15
4,1,13:100.15
5,1,13:100.15
6,1,13:100.15
7,1,13:100.15
-6,2,13:100.15
-5,2,13:100.15
-4,2,13:100.15
-2,2,13:100.15
-1,2,13:100.15
0,2,13:100.15
3,2,13:100.15
4,2,13:100.15
5,2,13:100.15
-6,3,13:100.15
-5,3,13:100.15
-2,3,13:100.15
-1,3,13:100.15
0,3,13:100.15
-6,4,13:100.15
-2,4,13:100.15
-1,4,13:100.15
0,4,13:100.15
-2,5,13:100.15
-1,5,13:100.15
0,5,13:100.15
-2,6,13:100.15
-1,6,13:100.15
6,6,13:100.0
6,7,13:100.0
-3,-12,14:100.0
-2,-12,14:100.0
-6,-11,14:100.0
-5,-11,14:100.0
-4,-11,14:100.0
-3,-11,14:100.0
-2,-11,14:100.0
-1,-11,14:100.0
0,-11,14:100.0
1,-11,14:100.0
-8,-10,14:100.0
-7,-10,14:100.0
-6,-10,14:100.0
-5,-10,14:100.0
-4,-10,14:100.0
-3,-10,14:100.0
-2,-10,14:100.0
-1,-10,14:100.0
0,-10,14:100.0
1,-10,14:100.0
2,-10,14:100.0
-9,-9,14:100.0
-8,-9,14:100.0
-7,-9,14:100.0
-6,-9,14:100.0
-5,-9,14:100.0
-4,-9,14:100.0
-3,-9,14:100.0
-2,-9,14:100.0
-1,-9,14:100.0
0,-9,14:100.0
1,-9,14:100.0
2,-9,14:100.0
3,-9,14:100.0
4,-9,14:100.0
-10,-8,14:100.0
-9,-8,14:100.0
-8,-8,14:100.0
-7,-8,14:100.0
-6,-8,14:100.0
-5,-8,14:100.0
-4,-8,14:100.0
-3,-8,14:100.0
-2,-8,14:100.0
-1,-8,14:100.0
0,-8,14:100.0
1,-8,14:100.0
2,-8,14:100.0
3,-8,14:100.0
4,-8,14:159.10
5,-8,14:100.0
8,-8,14:159.10
-10,-7,14:100.0
-9,-7,14:100.0
-8,-7,14:100.0
-7,-7,14:100.0
-6,-7,14:100.0
-5,-7,14:100.0
-4,-7,14:100.0
-3,-7,14:100.0
-2,-7,14:100.0
-1,-7,14:100.0
0,-7,14:100.0
1,-7,14:100.0
2,-7,14:100.0
3,-7,14:100.0
4,-7,14:82.0
5,-7,14:82.0
7,-7,14:159.10
-10,-6,14:100.0
-9,-6,14:100.0
-8,-6,14:100.0
-7,-6,14:100.0
-6,-6,14:100.0
-5,-6,14:100.0
-4,-6,14:100.0
-3,-6,14:100.0
-2,-6,14:100.0
-1,-6,14:100.0
0,-6,14:100.0
1,-6,14:100.0
2,-6,14:82.0
3,-6,14:82.0
4,-6,14:82.0
5,-6,14:82.0
6,-6,14:82.0
7,-6,14:159.10
-10,-5,14:100.0
-9,-5,14:100.0
-8,-5,14:100.0
-7,-5,14:100.0
-6,-5,14:100.0
-5,-5,14:100.0
-4,-5,14:100.0
-3,-5,14:100.0
-2,-5,14:100.0
0,-5,14:100.0
1,-5,14:159.10
2,-5,14:82.0
3,-5,14:82.0
4,-5,14:82.0
5,-5,14:82.0
6,-5,14:82.0
7,-5,14:159.10
8,-5,14:159.10
9,-5,14:159.10
-10,-4,14:100.0
-9,-4,14:100.0
-8,-4,14:100.0
-7,-4,14:100.0
-6,-4,14:100.0
-5,-4,14:100.0
-4,-4,14:100.0
-3,-4,14:100.0
-2,-4,14:100.15
-1,-4,14:100.0
0,-4,14:100.0
1,-4,14:100.0
2,-4,14:100.0
3,-4,14:82.0
4,-4,14:82.0
5,-4,14:82.0
6,-4,14:82.0
7,-4,14:159.10
8,-4,14:159.10
-10,-3,14:100.0
-9,-3,14:100.0
-8,-3,14:100.0
-7,-3,14:100.0
-6,-3,14:100.0
-5,-3,14:100.0
-4,-3,14:100.0
-3,-3,14:159.10
-2,-3,14:159.10
-1,-3,14:159.10
0,-3,14:100.0
1,-3,14:159.10
2,-3,14:159.10
4,-3,14:82.0
5,-3,14:82.0
6,-3,14:159.10
8,-3,14:159.10
9,-3,14:159.10
-10,-2,14:100.0
-9,-2,14:100.0
-8,-2,14:100.0
-7,-2,14:100.0
-6,-2,14:100.0
-5,-2,14:100.0
-4,-2,14:100.0
-3,-2,14:159.10
-1,-2,14:100.0
0,-2,14:100.0
1,-2,14:159.10
2,-2,14:159.10
3,-2,14:159.10
4,-2,14:159.10
5,-2,14:159.10
6,-2,14:159.10
7,-2,14:159.10
8,-2,14:159.10
9,-2,14:159.10
10,-2,14:159.10
-10,-1,14:100.0
-9,-1,14:100.0
-8,-1,14:100.0
-7,-1,14:100.0
-6,-1,14:100.0
-5,-1,14:100.0
-4,-1,14:100.0
-3,-1,14:100.0
0,-1,14:159.10
1,-1,14:100.0
2,-1,14:159.10
3,-1,14:159.10
4,-1,14:159.10
5,-1,14:159.10
6,-1,14:159.10
7,-1,14:159.10
8,-1,14:159.10
9,-1,14:82.0
10,-1,14:159.10
11,-1,14:100.0
-10,0,14:100.0
-9,0,14:100.0
-8,0,14:100.0
-7,0,14:100.0
-6,0,14:100.0
0,0,14:100.0
1,0,14:100.0
2,0,14:100.0
3,0,14:100.0
4,0,14:159.10
5,0,14:100.15
6,0,14:100.15
7,0,14:159.10
8,0,14:82.0
9,0,14:82.0
10,0,14:82.0
11,0,14:100.0
-3,1,14:100.0
0,1,14:100.0
1,1,14:159.10
2,1,14:159.10
3,1,14:159.10
5,1,14:100.15
8,1,14:100.0
9,1,14:100.0
10,1,14:100.0
11,1,14:100.0
-7,2,14:100.0
-6,2,14:100.15
-5,2,14:159.10
-3,2,14:100.0
0,2,14:159.10
1,2,14:100.0
2,2,14:100.0
3,2,14:159.10
5,2,14:100.15
8,2,14:100.0
9,2,14:100.0
10,2,14:100.0
11,2,14:100.0
-7,3,14:100.0
-6,3,14:100.15
-5,3,14:159.10
0,3,14:159.10
1,3,14:100.0
2,3,14:100.0
3,3,14:100.0
5,3,14:100.15
8,3,14:100.0
9,3,14:100.0
10,3,14:100.0
-6,4,14:100.15
-2,4,14:159.10
-1,4,14:100.15
0,4,14:159.10
1,4,14:100.0
2,4,14:100.0
3,4,14:100.0
5,4,14:100.0
6,4,14:100.0
7,4,14:100.0
8,4,14:100.0
9,4,14:100.0
10,4,14:100.0
-2,5,14:100.15
-1,5,14:100.15
1,5,14:100.0
2,5,14:100.0
3,5,14:100.0
4,5,14:100.0
5,5,14:100.0
6,5,14:100.0
7,5,14:100.0
8,5,14:100.0
9,5,14:100.0
-4,6,14:100.0
-3,6,14:100.0
-2,6,14:100.15
-1,6,14:100.15
2,6,14:100.0
3,6,14:100.0
4,6,14:100.0
5,6,14:100.0
6,6,14:159.10
7,6,14:100.0
8,6,14:100.0
-3,7,14:100.0
-2,7,14:100.15
-1,7,14:100.15
5,7,14:100.0
6,7,14:159.10
-5,11,14:100.0
-2,-12,15:159.10
-3,-11,15:159.10
-2,-11,15:159.10
-5,-10,15:159.10
-4,-10,15:159.10
-3,-10,15:159.10
-2,-10,15:159.10
-1,-10,15:159.10
0,-10,15:159.10
-7,-9,15:159.10
-6,-9,15:159.10
-5,-9,15:159.10
-4,-9,15:159.10
-3,-9,15:159.10
-2,-9,15:159.10
-1,-9,15:159.10
0,-9,15:159.10
1,-9,15:159.10
2,-9,15:159.10
-10,-8,15:159.10
-9,-8,15:159.10
-8,-8,15:159.10
-7,-8,15:159.10
-6,-8,15:159.10
-5,-8,15:159.10
-4,-8,15:159.10
-3,-8,15:159.10
-2,-8,15:159.10
-1,-8,15:159.10
0,-8,15:159.10
1,-8,15:159.10
2,-8,15:159.10
3,-8,15:159.10
4,-8,15:159.10
5,-8,15:159.10
-9,-7,15:159.10
-8,-7,15:159.10
-7,-7,15:159.10
-6,-7,15:159.10
-5,-7,15:159.10
-4,-7,15:159.10
-3,-7,15:159.10
-2,-7,15:159.10
-1,-7,15:159.10
0,-7,15:159.10
1,-7,15:159.10
2,-7,15:159.10
3,-7,15:82.0
4,-7,15:82.0
7,-7,15:159.10
-9,-6,15:159.10
-8,-6,15:159.10
-7,-6,15:159.10
-6,-6,15:159.10
-5,-6,15:159.10
-4,-6,15:159.10
-3,-6,15:159.10
-2,-6,15:159.10
-1,-6,15:159.10
0,-6,15:159.10
1,-6,15:159.10
2,-6,15:82.0
3,-6,15:82.0
4,-6,15:82.0
5,-6,15:82.0
6,-6,15:82.0
7,-6,15:159.10
-9,-5,15:159.10
-8,-5,15:159.10
-7,-5,15:159.10
-6,-5,15:159.10
-5,-5,15:159.10
-4,-5,15:159.10
-3,-5,15:159.10
-2,-5,15:159.10
0,-5,15:159.10
1,-5,15:159.10
2,-5,15:82.0
3,-5,15:82.0
4,-5,15:82.0
5,-5,15:82.0
6,-5,15:82.0
7,-5,15:159.10
8,-5,15:159.10
-9,-4,15:159.10
-8,-4,15:159.10
-7,-4,15:159.10
-6,-4,15:159.10
-5,-4,15:159.10
-4,-4,15:159.10
-3,-4,15:159.10
-2,-4,15:159.10
-1,-4,15:159.10
0,-4,15:159.10
1,-4,15:159.10
2,-4,15:82.0
3,-4,15:82.0
4,-4,15:82.0
5,-4,15:82.0
6,-4,15:82.0
-9,-3,15:159.10
-8,-3,15:82.0
-7,-3,15:82.0
-6,-3,15:82.0
-5,-3,15:159.10
-4,-3,15:159.10
-3,-3,15:159.10
-2,-3,15:159.10
-1,-3,15:159.10
0,-3,15:159.10
1,-3,15:159.10
2,-3,15:159.10
4,-3,15:82.0
5,-3,15:82.0
6,-3,15:159.10
-9,-2,15:159.10
-8,-2,15:82.0
-7,-2,15:82.0
-6,-2,15:82.0
-5,-2,15:159.10
-4,-2,15:159.10
-3,-2,15:159.10
-2,-2,15:100.0
-1,-2,15:159.10
0,-2,15:159.10
1,-2,15:159.10
2,-2,15:159.10
3,-2,15:159.10
4,-2,15:159.10
5,-2,15:159.10
6,-2,15:159.10
7,-2,15:159.10
8,-2,15:159.10
10,-2,15:159.10
-9,-1,15:159.10
-8,-1,15:82.0
-7,-1,15:82.0
-6,-1,15:82.0
-5,-1,15:159.10
-4,-1,15:159.10
-3,-1,15:159.10
-2,-1,15:100.0
-1,-1,15:100.0
0,-1,15:159.10
1,-1,15:159.10
2,-1,15:159.10
3,-1,15:159.10
4,-1,15:159.10
5,-1,15:100.0
6,-1,15:159.10
7,-1,15:159.10
8,-1,15:82.0
9,-1,15:82.0
10,-1,15:82.0
-10,0,15:159.10
-9,0,15:159.10
-8,0,15:159.10
-7,0,15:159.10
-6,0,15:159.10
-5,0,15:100.0
-4,0,15:100.0
-2,0,15:100.0
-1,0,15:100.0
0,0,15:159.10
1,0,15:159.10
2,0,15:159.10
3,0,15:159.10
4,0,15:159.10
5,0,15:159.10
6,0,15:159.10
7,0,15:159.10
8,0,15:82.0
9,0,15:82.0
-8,1,15:100.0
-7,1,15:100.0
-6,1,15:100.0
-5,1,15:100.0
-4,1,15:100.0
-3,1,15:159.10
-2,1,15:100.0
-1,1,15:100.0
0,1,15:159.10
1,1,15:159.10
2,1,15:159.10
3,1,15:159.10
4,1,15:100.0
5,1,15:159.10
6,1,15:100.0
7,1,15:100.0
8,1,15:82.0
9,1,15:82.0
-7,2,15:159.10
-6,2,15:159.10
-5,2,15:159.10
-4,2,15:100.0
-3,2,15:159.10
-2,2,15:100.0
-1,2,15:100.0
0,2,15:159.10
1,2,15:159.10
2,2,15:159.10
3,2,15:159.10
5,2,15:159.10
6,2,15:100.0
7,2,15:100.0
8,2,15:159.10
9,2,15:159.10
-7,3,15:100.15
-6,3,15:100.15
-5,3,15:159.10
-4,3,15:100.0
-3,3,15:100.0
-2,3,15:100.0
-1,3,15:100.0
0,3,15:159.10
1,3,15:159.10
2,3,15:159.10
3,3,15:159.10
4,3,15:100.0
5,3,15:100.15
6,3,15:100.0
7,3,15:100.0
8,3,15:159.10
9,3,15:159.10
-7,4,15:100.0
-6,4,15:159.10
-5,4,15:100.0
-4,4,15:100.0
-3,4,15:100.0
-2,4,15:159.10
-1,4,15:159.10
0,4,15:159.10
1,4,15:159.10
2,4,15:159.10
3,4,15:159.10
4,4,15:100.0
5,4,15:82.0
6,4,15:82.0
7,4,15:159.10
8,4,15:159.10
9,4,15:159.10
10,4,15:159.10
-7,5,15:100.0
-6,5,15:100.0
-5,5,15:100.0
-4,5,15:100.0
-3,5,15:100.0
-2,5,15:159.10
-1,5,15:159.10
0,5,15:100.0
1,5,15:159.10
2,5,15:159.10
3,5,15:159.10
4,5,15:159.10
5,5,15:82.0
6,5,15:159.10
7,5,15:159.10
-8,6,15:100.0
-7,6,15:100.0
-6,6,15:100.0
-5,6,15:100.0
-4,6,15:159.10
-3,6,15:159.10
-2,6,15:159.10
-1,6,15:159.10
0,6,15:100.0
1,6,15:100.0
2,6,15:100.0
3,6,15:159.10
5,6,15:159.10
-8,7,15:100.0
-7,7,15:100.0
-6,7,15:100.0
-5,7,15:100.0
-3,7,15:159.10
-2,7,15:159.10
-1,7,15:159.10
0,7,15:100.0
1,7,15:100.0
2,7,15:100.0
3,7,15:100.0
4,7,15:100.0
5,7,15:159.10
-8,8,15:100.0
-7,8,15:100.0
-6,8,15:100.0
-5,8,15:100.0
-4,8,15:100.0
-3,8,15:100.0
-2,8,15:100.0
-1,8,15:100.0
0,8,15:100.0
1,8,15:100.0
2,8,15:100.0
3,8,15:100.0
4,8,15:100.0
-7,9,15:100.0
-6,9,15:100.0
-5,9,15:100.0
-4,9,15:100.0
-3,9,15:100.0
-2,9,15:100.0
-1,9,15:100.0
0,9,15:100.0
1,9,15:100.0
2,9,15:100.0
3,9,15:100.0
-7,10,15:100.0
-6,10,15:100.0
-5,10,15:100.0
-4,10,15:100.0
-3,10,15:100.0
-2,10,15:100.0
-1,10,15:100.0
0,10,15:100.0
1,10,15:100.0
2,10,15:100.0
3,10,15:100.0
-6,11,15:100.0
-5,11,15:159.10
-4,11,15:100.0
-3,11,15:100.0
-2,11,15:100.0
-1,11,15:100.0
0,11,15:100.0
1,11,15:100.0
2,11,15:100.0
3,11,15:100.0
-5,12,15:100.0
-4,12,15:100.0
-3,12,15:100.0
-2,12,15:100.0
-1,12,15:100.0
0,12,15:100.0
1,12,15:100.0
-3,13,15:100.0
-1,13,15:100.0
-2,-11,16:159.10
-2,-10,16:159.10
-4,-9,16:82.0
-3,-9,16:82.0
-2,-9,16:82.0
-9,-8,16:159.10
-5,-8,16:159.10
-4,-8,16:82.0
-3,-8,16:82.0
-2,-8,16:82.0
-1,-8,16:159.10
0,-8,16:159.10
4,-8,16:159.10
-8,-7,16:159.10
-7,-7,16:159.10
-6,-7,16:159.10
-5,-7,16:159.10
-4,-7,16:82.0
-3,-7,16:100.0
-2,-7,16:82.0
-1,-7,16:159.10
0,-7,16:159.10
1,-7,16:159.10
2,-7,16:159.10
3,-7,16:82.0
-7,-6,16:159.10
-6,-6,16:159.10
-5,-6,16:100.0
-4,-6,16:100.0
-3,-6,16:100.0
-2,-6,16:100.0
-1,-6,16:100.0
0,-6,16:159.10
1,-6,16:159.10
2,-6,16:82.0
-7,-5,16:159.10
-6,-5,16:159.10
-5,-5,16:100.0
-4,-5,16:100.0
-3,-5,16:159.10
0,-5,16:100.0
1,-5,16:159.10
2,-5,16:82.0
-7,-4,16:82.0
-6,-4,16:82.0
-5,-4,16:100.0
-4,-4,16:159.10
-3,-4,16:159.10
-2,-4,16:159.10
-1,-4,16:159.10
0,-4,16:100.0
1,-4,16:159.10
2,-4,16:82.0
-10,-3,16:100.0
-9,-3,16:100.0
-8,-3,16:82.0
-7,-3,16:82.0
-6,-3,16:82.0
-5,-3,16:82.0
-4,-3,16:159.10
-3,-3,16:159.10
-2,-3,16:159.10
-1,-3,16:159.10
0,-3,16:100.0
1,-3,16:159.10
2,-3,16:159.10
-11,-2,16:100.0
-10,-2,16:100.0
-9,-2,16:100.0
-8,-2,16:82.0
-7,-2,16:82.0
-6,-2,16:82.0
-5,-2,16:100.0
-4,-2,16:159.10
-3,-2,16:159.10
-2,-2,16:159.10
-1,-2,16:159.10
0,-2,16:159.10
1,-2,16:159.10
2,-2,16:159.10
5,-2,16:159.10
-12,-1,16:100.0
-11,-1,16:100.0
-10,-1,16:100.0
-9,-1,16:82.0
-8,-1,16:82.0
-7,-1,16:82.0
-6,-1,16:82.0
-5,-1,16:82.0
-4,-1,16:159.10
-3,-1,16:159.10
-2,-1,16:159.10
-1,-1,16:159.10
0,-1,16:159.10
1,-1,16:159.10
2,-1,16:159.10
3,-1,16:159.10
4,-1,16:159.10
5,-1,16:159.10
6,-1,16:159.10
7,-1,16:159.10
8,-1,16:159.10
-12,0,16:100.0
-11,0,16:100.0
-10,0,16:100.0
-9,0,16:100.0
-8,0,16:82.0
-7,0,16:100.0
-6,0,16:82.0
-5,0,16:159.10
-4,0,16:159.10
-2,0,16:159.10
-1,0,16:159.10
0,0,16:159.10
1,0,16:159.10
3,0,16:159.10
4,0,16:159.10
5,0,16:159.10
6,0,16:159.10
7,0,16:159.10
-11,1,16:100.0
-10,1,16:100.0
-9,1,16:100.0
-8,1,16:159.10
-7,1,16:100.0
-6,1,16:100.0
-5,1,16:159.10
-4,1,16:159.10
-3,1,16:82.0
-2,1,16:82.0
-1,1,16:82.0
0,1,16:159.10
3,1,16:159.10
4,1,16:159.10
5,1,16:159.10
6,1,16:159.10
7,1,16:159.10
-11,2,16:100.0
-9,2,16:100.0
-8,2,16:100.0
-6,2,16:159.10
-5,2,16:159.10
-4,2,16:100.0
-3,2,16:82.0
-2,2,16:82.0
-1,2,16:100.0
0,2,16:100.0
2,2,16:159.10
3,2,16:159.10
5,2,16:159.10
6,2,16:159.10
7,2,16:159.10
-11,3,16:100.0
-10,3,16:100.0
-9,3,16:100.0
-8,3,16:100.0
-7,3,16:159.10
-6,3,16:100.15
-4,3,16:159.10
-3,3,16:82.0
-2,3,16:82.0
-1,3,16:82.0
0,3,16:159.10
4,3,16:82.0
5,3,16:82.0
6,3,16:82.0
8,3,16:159.10
-8,4,16:100.0
-7,4,16:159.10
-6,4,16:159.10
-5,4,16:159.10
-4,4,16:159.10
-3,4,16:159.10
-2,4,16:159.10
-1,4,16:159.10
0,4,16:159.10
1,4,16:159.10
4,4,16:82.0
5,4,16:82.0
-8,5,16:100.0
-6,5,16:159.10
-5,5,16:159.10
-4,5,16:159.10
-3,5,16:159.10
-2,5,16:159.10
-1,5,16:159.10
0,5,16:159.10
1,5,16:159.10
2,5,16:159.10
3,5,16:159.10
5,5,16:82.0
-8,6,16:159.10
-6,6,16:159.10
-5,6,16:159.10
-4,6,16:159.10
-3,6,16:159.10
-2,6,16:159.10
-1,6,16:159.10
0,6,16:159.10
1,6,16:82.0
2,6,16:159.10
3,6,16:159.10
-6,7,16:159.10
-5,7,16:159.10
-4,7,16:100.0
-3,7,16:159.10
-2,7,16:159.10
-1,7,16:159.10
0,7,16:82.0
1,7,16:82.0
2,7,16:82.0
3,7,16:159.10
-6,8,16:159.10
-5,8,16:159.10
-4,8,16:159.10
-3,8,16:159.10
-2,8,16:159.10
-1,8,16:159.10
0,8,16:159.10
1,8,16:82.0
2,8,16:159.10
3,8,16:159.10
-7,9,16:159.10
-6,9,16:159.10
-5,9,16:159.10
-4,9,16:82.0
-3,9,16:82.0
-2,9,16:82.0
-1,9,16:159.10
0,9,16:159.10
1,9,16:159.10
2,9,16:159.10
3,9,16:159.10
-7,10,16:159.10
-6,10,16:159.10
-5,10,16:159.10
-4,10,16:82.0
-3,10,16:82.0
-2,10,16:82.0
-1,10,16:159.10
0,10,16:159.10
1,10,16:159.10
2,10,16:159.10
3,10,16:159.10
-5,11,16:159.10
-4,11,16:82.0
-3,11,16:82.0
-2,11,16:82.0
-1,11,16:159.10
0,11,16:159.10
1,11,16:159.10
2,11,16:159.10
3,11,16:159.10
-4,12,16:159.10
-3,12,16:159.10
-2,12,16:159.10
-1,12,16:159.10
0,12,16:159.10
-3,13,16:159.10
-2,-9,17:82.0
-3,-8,17:82.0
-7,-7,17:159.10
-4,-7,17:82.0
-3,-7,17:82.0
-2,-7,17:82.0
2,-7,17:159.10
-6,-6,17:159.10
-5,-6,17:159.10
-4,-6,17:82.0
-3,-6,17:82.0
-2,-6,17:82.0
-1,-6,17:159.10
0,-6,17:159.10
1,-6,17:159.10
-6,-5,17:159.10
-5,-5,17:159.10
-4,-5,17:159.10
-3,-5,17:100.0
-2,-5,17:100.0
0,-5,17:159.10
-6,-4,17:82.0
-5,-4,17:159.10
-4,-4,17:100.0
-3,-4,17:100.0
-2,-4,17:100.0
-1,-4,17:159.10
0,-4,17:159.10
-10,-3,17:159.10
-9,-3,17:82.0
-8,-3,17:82.0
-7,-3,17:82.0
-6,-3,17:82.0
-5,-3,17:82.0
-4,-3,17:159.10
-3,-3,17:100.0
-2,-3,17:159.10
-1,-3,17:159.10
0,-3,17:159.10
-10,-2,17:159.10
-9,-2,17:82.0
-8,-2,17:82.0
-7,-2,17:82.0
-6,-2,17:82.0
-5,-2,17:82.0
-4,-2,17:159.10
-3,-2,17:159.10
-2,-2,17:159.10
-1,-2,17:159.10
0,-2,17:159.10
1,-2,17:159.10
-11,-1,17:159.10
-10,-1,17:159.10
-9,-1,17:82.0
-8,-1,17:82.0
-7,-1,17:82.0
-6,-1,17:82.0
-5,-1,17:82.0
-4,-1,17:159.10
-3,-1,17:159.10
-2,-1,17:159.10
-1,-1,17:159.10
1,-1,17:159.10
2,-1,17:159.10
-12,0,17:159.10
-11,0,17:159.10
-10,0,17:159.10
-9,0,17:159.10
-8,0,17:82.0
-7,0,17:82.0
-6,0,17:82.0
-5,0,17:159.10
-4,0,17:159.10
-2,0,17:82.0
-1,0,17:82.0
5,0,17:159.10
6,0,17:159.10
-13,1,17:100.0
-12,1,17:100.0
-11,1,17:159.10
-10,1,17:159.10
-9,1,17:159.10
-8,1,17:159.10
-7,1,17:159.10
-6,1,17:159.10
-5,1,17:159.10
-4,1,17:82.0
-3,1,17:82.0
-2,1,17:82.0
-1,1,17:82.0
4,1,17:159.10
5,1,17:159.10
-13,2,17:100.0
-11,2,17:159.10
-9,2,17:159.10
-8,2,17:159.10
-7,2,17:100.0
-6,2,17:159.10
-5,2,17:159.10
-4,2,17:82.0
-3,2,17:82.0
-2,2,17:82.0
-1,2,17:82.0
0,2,17:82.0
5,2,17:159.10
-13,3,17:100.0
-12,3,17:100.0
-11,3,17:159.10
-10,3,17:159.10
-9,3,17:159.10
-8,3,17:159.10
-7,3,17:159.10
-6,3,17:159.10
-5,3,17:100.0
-4,3,17:100.0
-3,3,17:82.0
-2,3,17:82.0
-1,3,17:82.0
0,3,17:82.0
5,3,17:82.0
-13,4,17:100.0
-12,4,17:100.0
-11,4,17:100.0
-10,4,17:100.0
-9,4,17:100.0
-8,4,17:159.10
-7,4,17:159.10
-6,4,17:159.10
-5,4,17:159.10
-4,4,17:159.10
-3,4,17:82.0
-2,4,17:82.0
-1,4,17:82.0
0,4,17:159.10
-13,5,17:100.0
-12,5,17:100.0
-11,5,17:100.0
-10,5,17:100.0
-9,5,17:100.0
-8,5,17:159.10
-7,5,17:100.15
-6,5,17:159.10
-5,5,17:159.10
-4,5,17:159.10
-3,5,17:159.10
-2,5,17:159.10
-1,5,17:159.10
0,5,17:159.10
1,5,17:159.10
2,5,17:159.10
-13,6,17:100.0
-12,6,17:100.0
-11,6,17:100.0
-10,6,17:100.0
-9,6,17:100.0
-8,6,17:159.10
-7,6,17:100.0
-6,6,17:159.10
-5,6,17:159.10
-4,6,17:159.10
-3,6,17:159.10
-2,6,17:159.10
-1,6,17:159.10
0,6,17:82.0
1,6,17:82.0
-12,7,17:100.0
-11,7,17:100.0
-10,7,17:100.0
-9,7,17:100.0
-8,7,17:100.0
-7,7,17:100.0
-6,7,17:100.0
-5,7,17:159.10
-4,7,17:159.10
-3,7,17:159.10
-2,7,17:159.10
-1,7,17:159.10
0,7,17:82.0
1,7,17:82.0
-11,8,17:100.0
-10,8,17:100.0
-9,8,17:100.0
-8,8,17:100.0
-7,8,17:100.0
-6,8,17:159.10
-5,8,17:159.10
-4,8,17:82.0
-3,8,17:82.0
-2,8,17:82.0
-1,8,17:159.10
0,8,17:82.0
1,8,17:82.0
-11,9,17:100.0
-10,9,17:100.0
-9,9,17:100.0
-8,9,17:100.0
-7,9,17:159.10
-6,9,17:159.10
-5,9,17:82.0
-4,9,17:82.0
-3,9,17:82.0
-2,9,17:82.0
-1,9,17:82.0
0,9,17:159.10
1,9,17:159.10
-8,10,17:100.0
-7,10,17:159.10
-6,10,17:159.10
-4,10,17:82.0
-3,10,17:82.0
-2,10,17:82.0
-1,10,17:82.0
2,10,17:159.10
-3,11,17:82.0
-3,12,17:82.0
-3,-8,18:82.0
-3,-7,18:82.0
-6,-6,18:159.10
-5,-6,18:159.10
-3,-6,18:82.0
-1,-6,18:159.10
0,-6,18:159.10
-5,-5,18:159.10
-4,-5,18:159.10
-3,-5,18:159.10
-2,-5,18:159.10
-4,-4,18:159.10
-3,-4,18:159.10
-2,-4,18:159.10
-10,-3,18:159.10
-6,-3,18:82.0
-5,-3,18:82.0
-4,-3,18:159.10
-3,-3,18:159.10
-2,-3,18:159.10
-1,-3,18:159.10
-9,-2,18:82.0
-4,-2,18:159.10
-3,-2,18:159.10
0,-2,18:159.10
1,-2,18:159.10
-9,-1,18:82.0
-8,-1,18:82.0
-7,-1,18:82.0
-6,-1,18:82.0
-5,-1,18:82.0
-4,-1,18:159.10
-3,-1,18:159.10
-10,0,18:159.10
-9,0,18:159.10
-8,0,18:82.0
-7,0,18:82.0
-6,0,18:82.0
-5,0,18:159.10
-4,0,18:159.10
-11,1,18:159.10
-10,1,18:159.10
-9,1,18:159.10
-8,1,18:159.10
-7,1,18:159.10
-6,1,18:159.10
-5,1,18:159.10
-4,1,18:82.0
-3,1,18:82.0
-11,2,18:159.10
-9,2,18:159.10
-8,2,18:159.10
-7,2,18:159.10
-6,2,18:159.10
-5,2,18:159.10
-4,2,18:82.0
-3,2,18:82.0
-2,2,18:82.0
-13,3,18:159.10
-12,3,18:159.10
-11,3,18:159.10
-10,3,18:159.10
-9,3,18:159.10
-8,3,18:159.10
-7,3,18:159.10
-6,3,18:159.10
-5,3,18:159.10
-4,3,18:82.0
-3,3,18:82.0
-2,3,18:82.0
-12,4,18:159.10
-11,4,18:159.10
-10,4,18:159.10
-9,4,18:159.10
-8,4,18:159.10
-7,4,18:159.10
-6,4,18:159.10
-5,4,18:159.10
-4,4,18:159.10
-3,4,18:82.0
-2,4,18:82.0
-1,4,18:82.0
0,4,18:159.10
-11,5,18:159.10
-10,5,18:159.10
-9,5,18:159.10
-8,5,18:159.10
-7,5,18:159.10
-6,5,18:159.10
-5,5,18:159.10
-4,5,18:159.10
-3,5,18:159.10
-2,5,18:159.10
-11,6,18:159.10
-10,6,18:159.10
-9,6,18:159.10
-8,6,18:82.0
-7,6,18:82.0
-6,6,18:82.0
-5,6,18:159.10
-4,6,18:159.10
-3,6,18:159.10
-2,6,18:159.10
-1,6,18:159.10
0,6,18:159.10
-10,7,18:159.10
-9,7,18:159.10
-8,7,18:82.0
-7,7,18:82.0
-6,7,18:82.0
-5,7,18:159.10
-4,7,18:159.10
-3,7,18:159.10
-2,7,18:159.10
-1,7,18:159.10
-10,8,18:159.10
-9,8,18:159.10
-8,8,18:82.0
-7,8,18:82.0
-6,8,18:82.0
-5,8,18:159.10
-4,8,18:82.0
-3,8,18:82.0
-2,8,18:82.0
-1,8,18:159.10
-11,9,18:159.10
-6,9,18:159.10
-5,9,18:82.0
-4,9,18:82.0
-2,9,18:82.0
0,9,18:159.10
-3,10,18:82.0
-9,-2,19:159.10
-4,-2,19:159.10
-9,-1,19:159.10
-4,-1,19:159.10
-9,0,19:159.10
-8,0,19:159.10
-5,0,19:159.10
-9,1,19:159.10
-8,1,19:159.10
-7,1,19:159.10
-6,1,19:159.10
-5,1,19:159.10
-9,2,19:159.10
-8,2,19:159.10
-7,2,19:159.10
-6,2,19:159.10
-5,2,19:159.10
-4,2,19:82.0
-12,3,19:82.0
-11,3,19:82.0
-10,3,19:82.0
-9,3,19:159.10
-8,3,19:159.10
-7,3,19:100.0
-6,3,19:159.10
-5,3,19:159.10
-4,3,19:82.0
-3,3,19:82.0
-10,4,19:159.10
-9,4,19:159.10
-8,4,19:159.10
-7,4,19:100.0
-6,4,19:159.10
-5,4,19:159.10
-4,4,19:159.10
-2,4,19:82.0
-1,4,19:82.0
0,4,19:159.10
-9,5,19:159.10
-8,5,19:159.10
-7,5,19:159.10
-6,5,19:159.10
-5,5,19:159.10
-4,5,19:159.10
-9,6,19:159.10
-8,6,19:159.10
-7,6,19:82.0
-6,6,19:159.10
-5,6,19:159.10
-10,7,19:159.10
-9,7,19:159.10
-5,7,19:159.10
-10,8,19:159.10
-5,8,19:159.10
-11,9,19:159.10
-4,9,19:82.0
-8,0,20:159.10
-5,0,20:159.10
-8,1,20:159.10
-6,1,20:159.10
-8,2,20:159.10
-7,2,20:159.10
-6,2,20:159.10
-11,3,20:82.0
-10,3,20:82.0
-9,3,20:159.10
-8,3,20:159.10
-7,3,20:159.10
-6,3,20:159.10
-5,3,20:159.10
-4,3,20:159.10
-3,3,20:82.0
-8,4,20:159.10
-7,4,20:159.10
-6,4,20:159.10
-8,5,20:159.10
-6,5,20:159.10
-9,6,20:159.10
-6,6,20:159.10
-5,7,20:159.10
-6,6,21:159.10
