[META]
version=2.0
spawnOnBlockType=2
spawnSunlight=True
spawnDarkness=True
spawnWater=False
spawnLava=False
underFill=False
randomRotation=True
dig=True
tree=False
branch=False
needsFoundation=True
rarity=100
collisionPercentage=20
spawnElevationMin=0
spawnElevationMax=200
spawnInBiome=Custom
[DATA]
-2,1,-6:100.15
-1,1,-6:100.15
-1,2,-6:100.15
-2,3,-6:100.15
0,3,-6:100.15
-1,0,-5:100.15
-2,1,-5:100.15
0,1,-5:100.15
-3,2,-5:100.15
-1,2,-5:100.15
1,2,-5:100.15
-2,4,-5:100.15
1,-1,-4:100.15
-5,0,-4:100.15
-4,0,-4:100.15
-2,0,-4:100.15
-1,0,-4:100.15
-5,1,-4:100.15
-2,1,-4:100.15
-1,1,-4:100.15
0,1,-4:100.15
1,1,-4:100.15
-5,2,-4:100.15
-3,2,-4:100.15
-2,2,-4:100.15
-1,2,-4:100.15
0,2,-4:100.15
3,2,-4:100.15
-3,3,-4:100.15
-2,3,-4:100.15
-1,3,-4:100.15
0,3,-4:100.15
2,3,-4:100.15
-5,4,-4:100.15
-4,4,-4:100.15
-3,4,-4:100.15
-1,4,-4:100.15
0,4,-4:100.15
1,4,-4:100.15
-4,5,-4:100.15
-3,5,-4:100.15
-2,5,-4:100.15
-5,6,-4:100.15
-4,6,-4:100.15
-3,6,-4:100.15
-2,6,-4:100.15
-1,6,-4:100.15
-3,7,-4:100.15
-1,7,-4:100.15
-4,-2,-3:100.15
0,-2,-3:100.15
-6,-1,-3:100.15
-5,-1,-3:100.15
-4,-1,-3:100.15
-3,-1,-3:100.15
-1,-1,-3:100.15
0,-1,-3:100.15
2,-1,-3:100.15
3,-1,-3:100.15
-5,0,-3:100.15
-4,0,-3:100.15
-2,0,-3:100.15
0,0,-3:100.15
2,0,-3:100.15
3,0,-3:100.15
-7,1,-3:100.15
-5,1,-3:100.15
-2,1,-3:100.15
-1,1,-3:100.15
0,1,-3:100.15
1,1,-3:100.15
-5,2,-3:100.15
-4,2,-3:100.15
-3,2,-3:100.15
-2,2,-3:100.15
-1,2,-3:100.15
0,2,-3:100.15
1,2,-3:100.15
2,2,-3:100.15
3,2,-3:100.15
-6,3,-3:100.15
-5,3,-3:100.15
-4,3,-3:100.15
-2,3,-3:100.15
-1,3,-3:100.15
0,3,-3:100.15
1,3,-3:100.15
2,3,-3:100.15
3,3,-3:100.15
4,3,-3:100.15
-4,4,-3:100.15
-3,4,-3:100.15
-2,4,-3:100.15
-1,4,-3:100.15
0,4,-3:100.15
1,4,-3:100.15
2,4,-3:100.15
4,4,-3:100.15
-6,5,-3:100.15
-5,5,-3:100.15
-4,5,-3:100.15
-3,5,-3:100.15
-2,5,-3:100.15
1,5,-3:100.15
-5,6,-3:100.15
-4,6,-3:100.15
-3,6,-3:100.15
-4,7,-3:100.15
-3,7,-3:100.15
-2,7,-3:100.15
-2,8,-3:100.15
-1,8,-3:100.15
-5,-3,-2:100.15
-4,-3,-2:100.15
-4,-2,-2:100.15
0,-2,-2:100.15
1,-2,-2:100.15
3,-2,-2:100.15
4,-2,-2:100.15
-4,-1,-2:100.15
-2,-1,-2:100.15
-1,-1,-2:100.15
0,-1,-2:100.15
1,-1,-2:100.15
2,-1,-2:100.15
3,-1,-2:100.15
-7,0,-2:100.15
-6,0,-2:100.15
-5,0,-2:100.15
-4,0,-2:100.15
-3,0,-2:100.15
-2,0,-2:100.15
-1,0,-2:100.15
0,0,-2:100.15
1,0,-2:100.15
2,0,-2:100.15
3,0,-2:100.15
-7,1,-2:100.15
-5,1,-2:100.15
-4,1,-2:100.15
-3,1,-2:100.15
-2,1,-2:100.15
-1,1,-2:100.15
0,1,-2:100.15
1,1,-2:100.15
2,1,-2:100.15
3,1,-2:100.15
-7,2,-2:100.15
-6,2,-2:100.15
-5,2,-2:100.15
-4,2,-2:100.15
-3,2,-2:100.15
-2,2,-2:100.15
-1,2,-2:100.15
0,2,-2:100.15
1,2,-2:100.15
2,2,-2:100.15
3,2,-2:100.15
4,2,-2:100.15
-6,3,-2:100.15
-5,3,-2:100.15
-4,3,-2:100.15
-3,3,-2:100.15
-2,3,-2:100.15
-1,3,-2:100.15
0,3,-2:100.15
1,3,-2:100.15
2,3,-2:100.15
3,3,-2:100.15
-4,4,-2:100.15
-3,4,-2:100.15
-2,4,-2:100.15
-1,4,-2:100.15
0,4,-2:100.15
1,4,-2:100.15
-6,5,-2:100.15
-4,5,-2:100.15
-3,5,-2:100.15
-2,5,-2:100.15
0,5,-2:100.15
1,5,-2:100.15
2,5,-2:100.15
3,5,-2:100.15
-6,6,-2:100.15
-5,6,-2:100.15
-4,6,-2:100.15
-3,6,-2:100.15
-2,6,-2:100.15
-1,6,-2:100.15
0,6,-2:100.15
-5,7,-2:100.15
-4,7,-2:100.15
-3,7,-2:100.15
-2,7,-2:100.15
0,7,-2:100.15
-2,8,-2:100.15
-1,8,-2:100.15
-4,-3,-1:100.15
-3,-3,-1:100.15
-5,-2,-1:100.15
-4,-2,-1:100.15
1,-2,-1:100.15
2,-2,-1:100.15
-6,-1,-1:100.15
-5,-1,-1:100.15
-4,-1,-1:100.15
-3,-1,-1:100.15
-2,-1,-1:100.15
-1,-1,-1:100.15
2,-1,-1:100.15
3,-1,-1:100.15
4,-1,-1:100.15
-5,0,-1:100.15
-4,0,-1:100.15
-3,0,-1:100.15
-2,0,-1:100.15
-1,0,-1:100.15
0,0,-1:100.15
1,0,-1:100.15
2,0,-1:100.15
3,0,-1:100.15
-7,1,-1:100.15
-6,1,-1:100.15
-5,1,-1:100.15
-4,1,-1:100.15
-3,1,-1:100.15
-2,1,-1:100.15
-1,1,-1:100.15
0,1,-1:100.15
1,1,-1:100.15
-6,2,-1:100.15
-3,2,-1:100.15
-2,2,-1:100.15
-1,2,-1:100.15
0,2,-1:100.15
1,2,-1:100.15
2,2,-1:100.15
-3,3,-1:100.15
-1,3,-1:100.15
0,3,-1:100.15
1,3,-1:100.15
2,3,-1:100.15
4,3,-1:100.15
-4,4,-1:100.15
-2,4,-1:100.15
-1,4,-1:100.15
0,4,-1:100.15
2,4,-1:100.15
-6,5,-1:100.15
-4,5,-1:100.15
-3,5,-1:100.15
-1,5,-1:100.15
0,5,-1:100.15
1,5,-1:100.15
2,5,-1:100.15
-5,6,-1:100.15
-4,6,-1:100.15
-2,6,-1:100.15
-1,6,-1:100.15
-4,7,-1:100.15
-3,7,-1:100.15
-1,7,-1:100.15
-2,8,-1:100.15
-3,-4,0:100.15
-2,-4,0:100.15
-3,-3,0:100.15
-2,-3,0:100.15
-1,-3,0:100.15
1,-3,0:100.15
2,-3,0:100.15
-4,-2,0:100.15
-3,-2,0:100.15
-2,-2,0:100.15
-1,-2,0:100.15
0,-2,0:100.15
1,-2,0:100.15
2,-2,0:100.15
3,-2,0:100.15
4,-2,0:100.15
-7,-1,0:100.15
-6,-1,0:100.15
-5,-1,0:100.15
-4,-1,0:100.15
-2,-1,0:100.15
0,-1,0:100.15
1,-1,0:100.15
2,-1,0:100.15
3,-1,0:100.15
4,-1,0:100.15
5,-1,0:100.15
-8,0,0:100.15
-7,0,0:100.15
-4,0,0:100.15
-3,0,0:100.15
-1,0,0:100.15
0,0,0:100.15
3,0,0:100.15
4,0,0:100.15
-7,1,0:100.15
-6,1,0:100.15
-5,1,0:100.15
-4,1,0:100.15
-3,1,0:100.15
-2,1,0:100.15
-1,1,0:100.15
0,1,0:100.15
2,1,0:100.15
-6,2,0:100.15
-5,2,0:100.15
-4,2,0:100.15
-3,2,0:100.15
-2,2,0:100.15
-1,2,0:100.15
0,2,0:100.15
1,2,0:100.15
2,2,0:100.15
-6,3,0:100.15
-5,3,0:100.15
-3,3,0:100.15
-2,3,0:100.15
-1,3,0:100.15
1,3,0:100.15
2,3,0:100.15
3,3,0:100.15
-7,4,0:100.15
-6,4,0:100.15
-5,4,0:100.15
-4,4,0:100.15
-3,4,0:100.15
-1,4,0:100.15
1,4,0:100.15
2,4,0:100.15
3,4,0:100.15
-6,5,0:100.15
-5,5,0:100.15
-4,5,0:100.15
-3,5,0:100.15
0,5,0:100.15
1,5,0:100.15
2,5,0:100.15
3,5,0:100.15
-5,6,0:100.15
-4,6,0:100.15
-1,6,0:100.15
-3,7,0:100.15
-2,7,0:100.15
-1,7,0:100.15
-3,8,0:100.15
-2,8,0:100.15
-2,9,0:100.15
-3,-3,1:100.15
-2,-3,1:100.15
-3,-2,1:100.15
-2,-2,1:100.15
-1,-2,1:100.15
2,-2,1:100.15
3,-2,1:100.15
-7,-1,1:100.15
-6,-1,1:100.15
-5,-1,1:100.15
-4,-1,1:100.15
-3,-1,1:100.15
-1,-1,1:100.15
0,-1,1:100.15
1,-1,1:100.15
2,-1,1:100.15
3,-1,1:100.15
4,-1,1:100.15
-8,0,1:100.15
-7,0,1:100.15
-3,0,1:100.15
-2,0,1:100.15
-1,0,1:100.15
1,0,1:100.0
2,0,1:100.15
3,0,1:100.15
-7,1,1:100.15
-6,1,1:100.15
-5,1,1:100.15
-3,1,1:100.15
-2,1,1:100.15
2,1,1:100.15
-5,2,1:100.15
-2,2,1:100.15
-1,2,1:100.15
0,2,1:100.15
2,2,1:100.15
-6,3,1:100.15
-5,3,1:100.15
-1,3,1:100.15
0,3,1:100.15
2,3,1:100.15
3,3,1:100.15
-6,4,1:100.15
-5,4,1:100.15
-4,4,1:100.15
2,4,1:100.15
3,4,1:100.15
-6,5,1:100.15
-5,5,1:100.15
-4,5,1:100.15
-3,5,1:100.15
-1,5,1:100.15
0,5,1:100.15
1,5,1:100.15
2,5,1:100.15
-6,6,1:100.0
-4,6,1:100.15
-3,6,1:100.15
-2,6,1:100.15
-1,6,1:100.15
-5,7,1:100.0
-4,7,1:100.0
-3,7,1:100.15
-2,7,1:100.15
-1,7,1:100.15
-3,8,1:100.15
-2,8,1:100.15
-6,-2,2:100.0
-5,-2,2:100.0
-4,-2,2:100.0
-3,-2,2:100.0
-2,-2,2:100.15
-1,-2,2:100.15
0,-2,2:100.0
1,-2,2:100.0
-7,-1,2:100.15
-6,-1,2:100.0
-5,-1,2:100.0
-4,-1,2:100.0
-3,-1,2:100.0
-2,-1,2:100.0
-1,-1,2:100.15
0,-1,2:100.0
1,-1,2:100.0
2,-1,2:100.15
3,-1,2:100.15
4,-1,2:100.15
-7,0,2:100.0
-6,0,2:100.0
-4,0,2:100.15
-3,0,2:100.0
-2,0,2:100.0
0,0,2:100.0
1,0,2:100.0
2,0,2:100.0
3,0,2:100.0
-7,1,2:159.10
-6,1,2:100.0
-5,1,2:100.0
-4,1,2:100.0
2,1,2:100.0
3,1,2:100.0
-7,2,2:100.0
-6,2,2:100.0
-5,2,2:100.0
-4,2,2:100.0
0,2,2:100.0
3,2,2:100.0
-6,3,2:159.10
-5,3,2:100.0
-4,3,2:100.0
1,3,2:100.0
2,3,2:100.15
-6,4,2:159.10
-5,4,2:159.10
-4,4,2:100.15
-3,4,2:100.0
1,4,2:100.15
2,4,2:100.15
-6,5,2:159.10
-5,5,2:100.0
-4,5,2:100.0
-3,5,2:100.15
-2,5,2:100.15
-1,5,2:100.0
0,5,2:100.0
-6,6,2:159.10
-3,6,2:100.0
-2,6,2:100.15
-1,6,2:100.0
1,6,2:100.0
-5,7,2:159.10
-4,7,2:100.0
-3,7,2:100.15
-2,7,2:100.15
-1,7,2:100.0
-3,8,2:159.10
-2,8,2:100.15
-6,-2,3:159.10
-5,-2,3:100.0
-4,-2,3:100.0
-3,-2,3:159.10
-1,-2,3:159.10
0,-2,3:159.10
1,-2,3:159.10
-7,-1,3:100.15
-6,-1,3:100.0
-5,-1,3:100.0
-4,-1,3:100.0
-3,-1,3:100.0
-2,-1,3:100.0
-1,-1,3:100.15
0,-1,3:100.0
1,-1,3:159.10
2,-1,3:100.15
3,-1,3:100.15
-7,0,3:100.15
-6,0,3:100.15
-5,0,3:100.15
-4,0,3:100.15
-3,0,3:100.15
-2,0,3:100.0
0,0,3:100.0
1,0,3:100.15
2,0,3:100.15
3,0,3:159.10
-6,1,3:100.0
-5,1,3:100.0
-4,1,3:100.15
0,1,3:100.0
1,1,3:100.0
2,1,3:100.0
3,1,3:159.10
-7,2,3:159.10
-6,2,3:100.0
-5,2,3:100.0
-4,2,3:100.15
0,2,3:159.10
1,2,3:100.0
2,2,3:100.0
3,2,3:100.0
-6,3,3:159.10
-5,3,3:159.10
-4,3,3:100.15
0,3,3:100.0
1,3,3:100.0
2,3,3:100.0
3,3,3:100.0
-6,4,3:159.10
-5,4,3:159.10
-4,4,3:100.15
-3,4,3:100.15
0,4,3:100.15
1,4,3:100.15
2,4,3:100.0
3,4,3:100.0
-5,5,3:159.10
-4,5,3:159.10
-3,5,3:159.10
-2,5,3:100.15
-1,5,3:100.15
0,5,3:100.0
1,5,3:100.0
2,5,3:159.10
-4,6,3:159.10
-3,6,3:159.10
-2,6,3:100.15
-1,6,3:100.0
0,6,3:100.0
1,6,3:100.0
-4,7,3:159.10
-3,7,3:159.10
-2,7,3:159.10
-1,7,3:159.10
0,7,3:100.0
-5,-2,4:159.10
-4,-2,4:159.10
-6,-1,4:159.10
-5,-1,4:159.10
-4,-1,4:159.10
-3,-1,4:159.10
-2,-1,4:100.15
-1,-1,4:100.15
0,-1,4:159.10
-4,0,4:100.15
-3,0,4:100.15
-2,0,4:100.15
-1,0,4:100.15
0,0,4:100.15
1,0,4:100.0
2,0,4:100.15
-6,1,4:159.10
-5,1,4:159.10
-4,1,4:100.15
0,1,4:100.0
1,1,4:100.0
2,1,4:159.10
-6,2,4:159.10
-5,2,4:100.0
-4,2,4:100.15
1,2,4:100.0
2,2,4:159.10
3,2,4:159.10
-6,3,4:159.10
-4,3,4:100.15
0,3,4:100.0
1,3,4:100.15
2,3,4:159.10
3,3,4:159.10
-3,4,4:100.15
-2,4,4:100.15
-1,4,4:100.15
0,4,4:100.15
1,4,4:100.15
2,4,4:159.10
3,4,4:159.10
-2,5,4:100.15
-1,5,4:100.15
0,5,4:159.10
1,5,4:159.10
-1,6,4:159.10
0,6,4:159.10
1,6,4:159.10
0,7,4:159.10
-2,17,4:100.0
3,17,4:100.0
-5,19,4:100.0
-19,-2,5:100.0
14,-2,5:100.0
-2,-1,5:100.15
-4,0,5:100.15
-3,0,5:100.15
-1,0,5:100.15
0,0,5:100.15
1,0,5:100.0
-4,1,5:100.15
0,1,5:100.0
1,1,5:100.15
-5,2,5:100.0
-4,2,5:100.15
0,2,5:100.15
1,2,5:100.15
-4,3,5:100.15
0,3,5:100.15
1,3,5:100.15
-3,4,5:100.15
-2,4,5:100.15
-1,4,5:100.15
0,4,5:100.15
-2,5,5:100.15
-19,6,5:100.0
14,6,5:100.0
-19,7,5:100.0
-2,7,5:100.0
-15,8,5:100.0
-1,10,5:100.0
-1,12,5:100.0
-15,13,5:100.0
10,13,5:100.0
-14,14,5:100.0
-2,16,5:100.0
-2,17,5:100.0
3,17,5:100.0
-5,19,5:100.0
0,19,5:100.0
-14,-11,6:100.0
9,-11,6:100.0
-16,-9,6:100.0
-16,-7,6:100.0
-16,-6,6:100.0
-19,-5,6:100.0
-19,-2,6:100.0
14,-2,6:100.0
-4,-1,6:100.0
-3,-1,6:100.15
-2,-1,6:100.15
-1,-1,6:100.0
-4,0,6:100.15
-3,0,6:100.15
-1,0,6:100.15
0,0,6:100.15
1,0,6:100.0
2,0,6:100.0
-5,1,6:100.0
-4,1,6:100.15
0,1,6:100.15
-5,2,6:100.0
-4,2,6:100.15
0,2,6:100.15
-19,3,6:100.0
-5,3,6:100.0
-4,3,6:100.15
-3,3,6:100.15
0,3,6:100.15
1,3,6:100.0
-3,4,6:100.15
-2,4,6:100.15
-1,4,6:100.15
-19,6,6:100.0
-12,6,6:100.0
14,6,6:100.0
-19,7,6:100.0
-2,7,6:100.0
-15,8,6:100.0
-14,8,6:100.0
-16,9,6:100.0
-15,9,6:100.0
12,9,6:100.0
-17,10,6:100.0
-1,10,6:100.0
-1,11,6:100.0
-1,12,6:100.0
-15,13,6:100.0
-2,13,6:100.0
10,13,6:100.0
-14,14,6:100.0
-2,14,6:100.0
7,15,6:100.0
-2,16,6:100.0
-9,17,6:100.0
-8,17,6:100.0
-2,17,6:100.0
3,17,6:100.0
-7,18,6:100.0
-2,18,6:100.0
-5,19,6:100.0
0,19,6:100.0
-2,-16,7:100.0
-7,-15,7:100.0
-6,-15,7:100.0
1,-15,7:100.0
2,-15,7:100.0
7,-12,7:100.0
-14,-11,7:100.0
-13,-11,7:100.0
9,-11,7:100.0
11,-10,7:100.0
-17,-9,7:100.0
-16,-9,7:100.0
12,-9,7:100.0
-18,-7,7:100.0
-17,-7,7:100.0
-16,-7,7:100.0
-16,-6,7:100.0
11,-6,7:100.0
-19,-5,7:100.0
-13,-5,7:100.0
-12,-5,7:100.0
-10,-4,7:100.0
6,-3,7:100.0
-19,-2,7:100.0
14,-2,7:100.0
-19,-1,7:100.0
-4,-1,7:100.0
-3,-1,7:100.0
-2,-1,7:100.0
-1,-1,7:100.0
3,-1,7:100.0
-19,0,7:100.0
-4,0,7:100.15
-3,0,7:100.15
-2,0,7:100.15
-1,0,7:100.15
0,0,7:100.0
1,0,7:100.0
2,0,7:100.0
14,0,7:100.0
-5,1,7:100.0
-4,1,7:100.15
0,1,7:100.0
-5,2,7:100.0
-4,2,7:100.15
0,2,7:100.15
-19,3,7:100.0
-7,3,7:100.0
-5,3,7:100.0
-4,3,7:100.15
-3,3,7:100.15
-1,3,7:100.15
0,3,7:100.0
1,3,7:100.0
14,3,7:100.0
-9,4,7:100.0
-3,4,7:100.0
-2,4,7:100.0
-1,4,7:100.0
2,4,7:100.0
3,4,7:100.0
-11,5,7:100.0
-10,5,7:100.0
14,5,7:100.0
-19,6,7:100.0
-12,6,7:100.0
-11,6,7:100.0
6,6,7:100.0
14,6,7:100.0
-19,7,7:100.0
-2,7,7:100.0
8,7,7:100.0
14,7,7:100.0
-19,8,7:100.0
-15,8,7:100.0
-14,8,7:100.0
-2,8,7:100.0
10,8,7:100.0
14,8,7:100.0
-19,9,7:100.0
-16,9,7:100.0
-15,9,7:100.0
-1,9,7:100.0
12,9,7:100.0
14,9,7:100.0
-19,10,7:100.0
-18,10,7:100.0
-17,10,7:100.0
-1,10,7:100.0
12,10,7:100.0
13,10,7:100.0
14,10,7:100.0
-18,11,7:100.0
-2,11,7:100.0
-1,11,7:100.0
-17,12,7:100.0
-2,12,7:100.0
12,12,7:100.0
-16,13,7:100.0
-15,13,7:100.0
-2,13,7:100.0
10,13,7:100.0
11,13,7:100.0
-14,14,7:100.0
-2,14,7:100.0
9,14,7:100.0
-11,15,7:100.0
7,15,7:100.0
-2,16,7:100.0
-9,17,7:100.0
-8,17,7:159.10
-2,17,7:100.0
3,17,7:100.0
-7,18,7:100.0
-2,18,7:100.0
-5,19,7:100.0
-4,19,7:100.0
0,19,7:100.0
-2,20,7:100.0
-2,-17,8:100.0
-2,-16,8:100.0
-1,-16,8:100.0
0,-16,8:100.0
-7,-15,8:159.10
-6,-15,8:100.0
1,-15,8:100.0
2,-15,8:100.0
5,-13,8:100.0
-12,-12,8:100.0
7,-12,8:100.0
-14,-11,8:100.0
-13,-11,8:100.0
8,-11,8:100.0
9,-11,8:100.0
11,-10,8:100.0
-17,-9,8:159.10
-16,-9,8:100.0
12,-9,8:100.0
-18,-7,8:100.0
-17,-7,8:100.0
-16,-7,8:100.0
11,-7,8:100.0
12,-7,8:100.0
-16,-6,8:100.0
-14,-6,8:100.0
11,-6,8:100.0
-19,-5,8:100.0
-14,-5,8:100.0
-13,-5,8:100.0
-12,-5,8:100.0
10,-5,8:100.0
14,-5,8:100.0
-12,-4,8:100.0
-11,-4,8:100.0
-10,-4,8:100.0
8,-4,8:100.0
-10,-3,8:100.0
-8,-3,8:100.0
6,-3,8:100.0
-19,-2,8:100.0
-8,-2,8:100.0
-7,-2,8:100.0
14,-2,8:100.0
-19,-1,8:100.0
-6,-1,8:100.0
-4,-1,8:100.0
-3,-1,8:100.0
-2,-1,8:100.0
-1,-1,8:100.0
3,-1,8:100.0
4,-1,8:100.0
14,-1,8:100.0
-19,0,8:100.0
-4,0,8:100.15
-2,0,8:100.15
-1,0,8:100.15
0,0,8:100.0
1,0,8:100.0
2,0,8:100.0
14,0,8:100.0
-5,1,8:100.0
-1,1,8:100.15
0,1,8:100.0
1,1,8:100.0
-19,2,8:100.0
-5,2,8:100.0
-4,2,8:100.15
-1,2,8:100.15
0,2,8:100.0
14,2,8:100.0
-19,3,8:100.0
-7,3,8:100.0
-5,3,8:100.0
-4,3,8:100.0
-3,3,8:100.15
-2,3,8:100.15
-1,3,8:100.15
0,3,8:100.0
1,3,8:100.0
14,3,8:100.0
-9,4,8:100.0
-8,4,8:100.0
-3,4,8:100.0
-2,4,8:100.0
-1,4,8:100.0
1,4,8:100.0
2,4,8:100.0
3,4,8:100.0
-10,5,8:100.0
-9,5,8:100.0
-2,5,8:100.0
3,5,8:100.0
4,5,8:100.0
14,5,8:100.0
-19,6,8:100.0
-12,6,8:100.0
-11,6,8:100.0
-2,6,8:100.0
6,6,8:100.0
14,6,8:100.0
-19,7,8:159.10
-13,7,8:100.0
-12,7,8:100.0
-2,7,8:100.0
-1,7,8:100.0
7,7,8:100.0
8,7,8:100.0
14,7,8:100.0
-19,8,8:100.0
-15,8,8:100.0
-14,8,8:100.0
-1,8,8:100.0
9,8,8:100.0
10,8,8:100.0
-19,9,8:100.0
-16,9,8:100.0
-15,9,8:100.0
-2,9,8:100.0
-1,9,8:100.0
11,9,8:100.0
12,9,8:100.0
-19,10,8:100.0
-18,10,8:100.0
-17,10,8:100.0
-2,10,8:100.0
12,10,8:100.0
13,10,8:100.0
14,10,8:159.10
-19,11,8:100.0
-18,11,8:100.0
-2,11,8:100.0
13,11,8:100.0
-18,12,8:100.0
-17,12,8:100.0
-2,12,8:100.0
12,12,8:100.0
-15,13,8:100.0
-2,13,8:100.0
10,13,8:100.0
11,13,8:159.10
-14,14,8:159.10
-2,14,8:100.0
9,14,8:100.0
-12,15,8:100.0
-11,15,8:100.0
-2,15,8:100.0
6,15,8:100.0
7,15,8:100.0
-11,16,8:100.0
-2,16,8:100.0
5,16,8:100.0
-9,17,8:159.10
-8,17,8:159.10
-2,17,8:100.0
3,17,8:100.0
4,17,8:159.10
-7,18,8:100.0
-2,18,8:100.0
-5,19,8:100.0
-4,19,8:100.0
0,19,8:100.0
-3,20,8:100.0
-2,20,8:100.0
-4,-17,9:100.0
-3,-17,9:100.0
-2,-17,9:100.0
-1,-17,9:100.0
-5,-16,9:100.0
-4,-16,9:100.0
-2,-16,9:100.0
-1,-16,9:100.0
0,-16,9:100.0
-7,-15,9:159.10
-6,-15,9:100.0
-2,-15,9:100.0
1,-15,9:100.0
2,-15,9:159.10
-2,-14,9:100.0
-10,-13,9:100.0
-9,-13,9:100.0
-2,-13,9:100.0
5,-13,9:100.0
-12,-12,9:100.0
-11,-12,9:100.0
-2,-12,9:100.0
7,-12,9:100.0
-14,-11,9:100.0
-13,-11,9:159.10
-12,-11,9:100.0
-2,-11,9:100.0
8,-11,9:100.0
9,-11,9:159.10
-14,-10,9:100.0
-2,-10,9:100.0
11,-10,9:100.0
-17,-9,9:159.10
-16,-9,9:100.0
-2,-9,9:100.0
-18,-8,9:100.0
-2,-8,9:100.0
-18,-7,9:100.0
-17,-7,9:100.0
-16,-7,9:100.0
12,-7,9:100.0
13,-7,9:100.0
-16,-6,9:100.0
-15,-6,9:100.0
-14,-6,9:100.0
10,-6,9:100.0
11,-6,9:100.0
12,-6,9:100.0
13,-6,9:100.0
14,-6,9:100.0
-19,-5,9:100.0
-14,-5,9:100.0
-13,-5,9:100.0
-12,-5,9:100.0
9,-5,9:100.0
10,-5,9:100.0
14,-5,9:100.0
-19,-4,9:100.0
-12,-4,9:100.0
-11,-4,9:100.0
-10,-4,9:100.0
7,-4,9:100.0
8,-4,9:100.0
-19,-3,9:100.0
-10,-3,9:100.0
-8,-3,9:100.0
6,-3,9:100.0
7,-3,9:100.0
14,-3,9:100.0
-19,-2,9:100.0
-8,-2,9:100.0
-7,-2,9:100.0
-6,-2,9:100.0
5,-2,9:100.0
14,-2,9:100.0
-19,-1,9:159.10
-6,-1,9:100.0
-5,-1,9:100.0
-4,-1,9:100.0
-3,-1,9:100.0
-2,-1,9:100.15
-1,-1,9:100.0
3,-1,9:100.0
4,-1,9:100.0
14,-1,9:159.10
-19,0,9:100.0
-4,0,9:100.15
-3,0,9:100.15
-2,0,9:100.15
-1,0,9:100.15
0,0,9:100.0
1,0,9:100.0
2,0,9:100.0
14,0,9:100.0
-19,1,9:100.0
-5,1,9:100.0
0,1,9:100.0
1,1,9:100.0
14,1,9:100.0
-19,2,9:159.10
-5,2,9:100.0
-1,2,9:100.15
0,2,9:100.0
14,2,9:100.0
-19,3,9:100.0
-7,3,9:100.0
-6,3,9:100.0
-5,3,9:100.0
-4,3,9:100.15
-3,3,9:100.15
-1,3,9:100.15
0,3,9:100.0
1,3,9:100.0
14,3,9:100.0
-9,4,9:100.0
-8,4,9:100.0
-3,4,9:100.0
-2,4,9:100.0
-1,4,9:100.0
1,4,9:100.0
2,4,9:100.0
3,4,9:100.0
4,4,9:100.0
-19,5,9:100.0
-10,5,9:100.0
-9,5,9:100.0
-2,5,9:100.0
3,5,9:100.0
4,5,9:100.0
14,5,9:100.0
-19,6,9:159.10
-12,6,9:100.0
-11,6,9:100.0
-2,6,9:100.0
-1,6,9:100.0
5,6,9:100.0
6,6,9:100.0
14,6,9:159.10
-19,7,9:159.10
-13,7,9:100.0
-12,7,9:100.0
-2,7,9:100.0
-1,7,9:100.0
7,7,9:100.0
8,7,9:100.0
14,7,9:100.0
-19,8,9:159.10
-15,8,9:100.0
-14,8,9:100.0
-2,8,9:100.0
9,8,9:100.0
10,8,9:100.0
14,8,9:100.0
-19,9,9:159.10
-16,9,9:100.0
-15,9,9:100.0
-2,9,9:100.0
10,9,9:100.0
11,9,9:100.0
12,9,9:100.0
14,9,9:159.10
-19,10,9:100.0
-18,10,9:100.0
-17,10,9:100.0
-2,10,9:100.0
12,10,9:100.0
13,10,9:100.0
14,10,9:159.10
-19,11,9:159.10
-18,11,9:100.0
-2,11,9:100.0
11,11,9:100.0
12,11,9:100.0
13,11,9:100.0
-18,12,9:159.10
-17,12,9:100.0
-16,12,9:100.0
-2,12,9:100.0
11,12,9:100.0
12,12,9:159.10
-16,13,9:100.0
-15,13,9:159.10
-2,13,9:100.0
10,13,9:159.10
11,13,9:159.10
-14,14,9:159.10
-13,14,9:100.0
-2,14,9:100.0
9,14,9:100.0
-12,15,9:100.0
-11,15,9:100.0
-2,15,9:100.0
6,15,9:100.0
7,15,9:159.10
-11,16,9:159.10
-10,16,9:100.0
-9,16,9:100.0
-2,16,9:100.0
5,16,9:100.0
6,16,9:100.0
-9,17,9:159.10
-8,17,9:159.10
-2,17,9:100.0
3,17,9:159.10
4,17,9:159.10
-7,18,9:159.10
-6,18,9:100.0
-2,18,9:100.0
2,18,9:100.0
-5,19,9:159.10
-4,19,9:100.0
0,19,9:159.10
-3,20,9:100.0
-2,20,9:159.10
-1,20,9:100.0
-4,-17,10:159.10
-3,-17,10:100.0
-2,-17,10:159.10
-1,-17,10:159.10
-5,-16,10:100.0
-4,-16,10:100.0
-3,-16,10:100.0
-2,-16,10:100.0
-1,-16,10:100.0
0,-16,10:100.0
-7,-15,10:159.10
-6,-15,10:159.10
-5,-15,10:100.0
-4,-15,10:100.0
-3,-15,10:100.0
-2,-15,10:159.10
-1,-15,10:100.0
0,-15,10:100.0
1,-15,10:159.10
2,-15,10:159.10
-8,-14,10:100.0
-7,-14,10:100.0
-5,-14,10:100.0
-4,-14,10:100.0
-3,-14,10:100.0
-2,-14,10:159.10
-1,-14,10:100.0
0,-14,10:100.0
3,-14,10:100.0
4,-14,10:100.0
-10,-13,10:100.0
-9,-13,10:100.0
-4,-13,10:100.0
-3,-13,10:100.0
-2,-13,10:159.10
-1,-13,10:100.0
0,-13,10:100.0
4,-13,10:100.0
5,-13,10:100.0
6,-13,10:100.0
-12,-12,10:159.10
-11,-12,10:100.0
-4,-12,10:100.0
-3,-12,10:100.0
-2,-12,10:159.10
-1,-12,10:100.0
7,-12,10:100.0
-14,-11,10:100.0
-13,-11,10:159.10
-12,-11,10:100.0
-11,-11,10:100.0
-3,-11,10:100.0
-2,-11,10:159.10
-1,-11,10:100.0
8,-11,10:100.0
9,-11,10:159.10
-15,-10,10:100.0
-14,-10,10:100.0
-3,-10,10:100.0
-2,-10,10:159.10
-1,-10,10:100.0
10,-10,10:100.0
11,-10,10:100.0
-17,-9,10:82.0
-16,-9,10:100.0
-3,-9,10:100.0
-2,-9,10:159.10
-1,-9,10:100.0
-19,-8,10:100.0
-18,-8,10:82.0
-17,-8,10:82.0
-3,-8,10:100.0
-2,-8,10:100.0
-1,-8,10:100.0
-19,-7,10:100.0
-18,-7,10:100.0
-17,-7,10:100.0
-16,-7,10:100.0
-2,-7,10:100.0
12,-7,10:100.0
13,-7,10:159.10
-19,-6,10:100.0
-16,-6,10:100.0
-15,-6,10:100.0
-14,-6,10:100.0
-3,-6,10:100.0
-2,-6,10:100.0
10,-6,10:100.0
11,-6,10:100.0
14,-6,10:100.0
-19,-5,10:159.10
-14,-5,10:100.0
-13,-5,10:100.0
-12,-5,10:100.0
-2,-5,10:100.0
9,-5,10:100.0
10,-5,10:100.0
14,-5,10:100.0
-19,-4,10:159.10
-12,-4,10:100.0
-11,-4,10:100.0
-10,-4,10:100.0
-2,-4,10:100.0
7,-4,10:100.0
8,-4,10:100.0
14,-4,10:100.0
-19,-3,10:159.10
-10,-3,10:100.0
-8,-3,10:100.0
-2,-3,10:100.0
6,-3,10:100.0
7,-3,10:100.0
14,-3,10:100.0
-19,-2,10:100.0
-8,-2,10:100.0
-7,-2,10:100.0
-6,-2,10:100.0
-2,-2,10:100.0
4,-2,10:100.0
5,-2,10:100.0
14,-2,10:159.10
-19,-1,10:159.10
-6,-1,10:100.0
-5,-1,10:100.0
-4,-1,10:100.0
-3,-1,10:100.15
-2,-1,10:100.15
-1,-1,10:100.0
3,-1,10:100.0
4,-1,10:100.0
14,-1,10:159.10
-19,0,10:159.10
-4,0,10:100.15
-1,0,10:100.15
0,0,10:100.0
1,0,10:100.0
2,0,10:100.0
14,0,10:159.10
-19,1,10:100.0
-5,1,10:100.0
0,1,10:100.15
1,1,10:100.0
14,1,10:159.10
-19,2,10:159.10
-6,2,10:100.0
-5,2,10:100.0
0,2,10:100.15
1,2,10:100.0
14,2,10:100.0
-19,3,10:159.10
-14,3,10:100.0
-13,3,10:100.0
-12,3,10:100.0
-11,3,10:100.0
-10,3,10:100.0
-9,3,10:100.0
-8,3,10:100.0
-7,3,10:100.0
-6,3,10:100.0
-5,3,10:100.0
-4,3,10:100.0
-3,3,10:100.0
-1,3,10:100.15
0,3,10:100.0
1,3,10:100.0
13,3,10:100.0
14,3,10:100.0
-19,4,10:159.10
-18,4,10:100.0
-17,4,10:100.0
-16,4,10:100.0
-15,4,10:100.0
-14,4,10:100.0
-13,4,10:100.0
-12,4,10:100.0
-11,4,10:100.0
-10,4,10:100.0
-9,4,10:100.0
-8,4,10:100.0
-7,4,10:100.0
-6,4,10:100.0
-3,4,10:100.0
-2,4,10:100.0
-1,4,10:100.0
1,4,10:100.0
2,4,10:100.0
3,4,10:100.0
4,4,10:100.0
5,4,10:100.0
6,4,10:100.0
7,4,10:100.0
8,4,10:100.0
9,4,10:100.0
10,4,10:100.0
11,4,10:100.0
12,4,10:100.0
13,4,10:100.0
14,4,10:100.0
-19,5,10:159.10
-18,5,10:100.0
-17,5,10:100.0
-16,5,10:100.0
-15,5,10:100.0
-14,5,10:100.0
-13,5,10:100.0
-12,5,10:100.0
-11,5,10:100.0
-10,5,10:100.0
-9,5,10:100.0
-8,5,10:100.0
-7,5,10:100.0
-6,5,10:100.0
-2,5,10:100.0
2,5,10:100.0
3,5,10:100.0
4,5,10:100.0
5,5,10:100.0
6,5,10:100.0
7,5,10:100.0
8,5,10:100.0
9,5,10:100.0
10,5,10:100.0
11,5,10:100.0
12,5,10:100.0
13,5,10:100.0
14,5,10:159.10
-19,6,10:159.10
-18,6,10:100.0
-16,6,10:100.0
-15,6,10:100.0
-14,6,10:100.0
-13,6,10:100.0
-12,6,10:159.10
-11,6,10:100.0
-10,6,10:100.0
-9,6,10:100.0
-8,6,10:100.0
-7,6,10:100.0
-2,6,10:100.0
-1,6,10:100.0
3,6,10:100.0
4,6,10:100.0
5,6,10:100.0
6,6,10:100.0
7,6,10:100.0
8,6,10:100.0
9,6,10:100.0
10,6,10:100.0
11,6,10:100.0
12,6,10:100.0
13,6,10:100.0
14,6,10:159.10
-19,7,10:159.10
-18,7,10:100.0
-17,7,10:100.0
-16,7,10:100.0
-15,7,10:100.0
-14,7,10:100.0
-13,7,10:159.10
-12,7,10:159.10
-11,7,10:100.0
-10,7,10:100.0
-9,7,10:100.0
-8,7,10:100.0
-7,7,10:100.0
-2,7,10:100.0
4,7,10:100.0
5,7,10:100.0
6,7,10:100.0
7,7,10:159.10
8,7,10:159.10
9,7,10:100.0
10,7,10:100.0
11,7,10:100.0
12,7,10:100.0
13,7,10:100.0
14,7,10:100.0
-19,8,10:159.10
-18,8,10:100.0
-17,8,10:100.0
-16,8,10:100.0
-15,8,10:159.10
-14,8,10:159.10
-13,8,10:100.0
-12,8,10:100.0
-11,8,10:100.0
-10,8,10:100.0
-9,8,10:100.0
-8,8,10:100.0
-2,8,10:100.0
4,8,10:100.0
5,8,10:100.0
6,8,10:100.0
7,8,10:100.0
8,8,10:100.0
9,8,10:159.10
10,8,10:159.10
11,8,10:100.0
12,8,10:100.0
13,8,10:100.0
14,8,10:159.10
-19,9,10:159.10
-18,9,10:100.0
-16,9,10:159.10
-15,9,10:159.10
-14,9,10:100.0
-13,9,10:100.0
-12,9,10:100.0
-11,9,10:100.0
-10,9,10:100.0
-9,9,10:100.0
-2,9,10:100.0
5,9,10:100.0
7,9,10:100.0
8,9,10:100.0
9,9,10:100.0
10,9,10:159.10
11,9,10:100.0
12,9,10:100.0
13,9,10:100.0
14,9,10:159.10
-19,10,10:159.10
-18,10,10:100.0
-17,10,10:100.0
-16,10,10:100.0
-15,10,10:100.0
-14,10,10:100.0
-13,10,10:100.0
-12,10,10:100.0
-11,10,10:100.0
-10,10,10:100.0
-9,10,10:100.0
-2,10,10:100.0
5,10,10:100.0
6,10,10:100.0
7,10,10:100.0
9,10,10:100.0
10,10,10:100.0
11,10,10:100.0
12,10,10:159.10
13,10,10:100.0
14,10,10:159.10
-18,11,10:159.10
-17,11,10:100.0
-16,11,10:100.0
-15,11,10:100.0
-14,11,10:100.0
-13,11,10:100.0
-12,11,10:100.0
-11,11,10:100.0
-10,11,10:100.0
-2,11,10:100.0
6,11,10:100.0
7,11,10:100.0
8,11,10:100.0
9,11,10:100.0
10,11,10:100.0
11,11,10:100.0
12,11,10:100.0
13,11,10:100.0
-17,12,10:159.10
-16,12,10:100.0
-15,12,10:100.0
-14,12,10:100.0
-13,12,10:100.0
-12,12,10:100.0
-11,12,10:100.0
-10,12,10:100.0
-2,12,10:100.0
6,12,10:100.0
7,12,10:100.0
8,12,10:100.0
9,12,10:100.0
10,12,10:100.0
11,12,10:100.0
12,12,10:159.10
-16,13,10:159.10
-15,13,10:159.10
-14,13,10:100.0
-13,13,10:100.0
-12,13,10:100.0
-11,13,10:100.0
-2,13,10:100.0
7,13,10:100.0
8,13,10:100.0
9,13,10:100.0
10,13,10:159.10
11,13,10:159.10
-14,14,10:159.10
-13,14,10:100.0
-12,14,10:100.0
-2,14,10:100.0
7,14,10:100.0
8,14,10:100.0
9,14,10:100.0
-12,15,10:159.10
-11,15,10:100.0
-2,15,10:100.0
6,15,10:100.0
7,15,10:159.10
-11,16,10:159.10
-10,16,10:100.0
-9,16,10:100.0
-2,16,10:100.0
5,16,10:100.0
6,16,10:159.10
-9,17,10:159.10
-8,17,10:159.10
-2,17,10:100.0
3,17,10:159.10
4,17,10:159.10
-7,18,10:159.10
-6,18,10:100.0
-2,18,10:100.0
1,18,10:100.0
2,18,10:100.0
-5,19,10:159.10
-4,19,10:100.0
-1,19,10:100.0
0,19,10:159.10
1,19,10:159.10
-4,20,10:100.0
-3,20,10:159.10
-2,20,10:159.10
-1,20,10:100.0
-3,-17,11:159.10
-2,-17,11:159.10
-5,-16,11:159.10
-4,-16,11:159.10
-3,-16,11:159.10
-2,-16,11:100.0
-1,-16,11:159.10
0,-16,11:159.10
-7,-15,11:159.10
-6,-15,11:159.10
-5,-15,11:100.0
-4,-15,11:100.0
-1,-15,11:100.0
0,-15,11:100.0
1,-15,11:159.10
2,-15,11:159.10
-8,-14,11:159.10
-7,-14,11:100.0
-6,-14,11:100.0
-5,-14,11:100.0
0,-14,11:100.0
1,-14,11:100.0
2,-14,11:100.0
3,-14,11:82.0
4,-14,11:82.0
-10,-13,11:159.10
-9,-13,11:100.0
-7,-13,11:100.0
-6,-13,11:100.0
-5,-13,11:100.0
0,-13,11:159.10
1,-13,11:100.0
2,-13,11:100.0
3,-13,11:100.0
4,-13,11:100.0
5,-13,11:159.10
6,-13,11:159.10
-12,-12,11:82.0
-11,-12,11:82.0
-10,-12,11:100.0
-9,-12,11:100.0
-8,-12,11:100.0
-7,-12,11:100.0
-6,-12,11:100.0
-5,-12,11:100.0
-4,-12,11:159.10
0,-12,11:100.0
1,-12,11:100.0
2,-12,11:100.0
3,-12,11:100.0
4,-12,11:100.0
5,-12,11:100.0
6,-12,11:100.0
7,-12,11:159.10
8,-12,11:159.10
-14,-11,11:159.10
-13,-11,11:159.10
-12,-11,11:100.0
-11,-11,11:100.0
-10,-11,11:100.0
-9,-11,11:100.0
-8,-11,11:100.0
-7,-11,11:100.0
-6,-11,11:100.0
-5,-11,11:100.0
-4,-11,11:100.0
0,-11,11:100.0
1,-11,11:100.0
2,-11,11:100.0
3,-11,11:100.0
4,-11,11:100.0
5,-11,11:100.0
6,-11,11:100.0
7,-11,11:100.0
8,-11,11:100.0
9,-11,11:159.10
-15,-10,11:100.0
-14,-10,11:100.0
-13,-10,11:100.0
-12,-10,11:100.0
-11,-10,11:100.0
-10,-10,11:100.0
-9,-10,11:100.0
-8,-10,11:100.0
-7,-10,11:100.0
-6,-10,11:100.0
-5,-10,11:100.0
-4,-10,11:100.0
-1,-10,11:159.10
0,-10,11:100.0
1,-10,11:100.0
2,-10,11:100.0
3,-10,11:100.0
4,-10,11:100.0
5,-10,11:100.0
6,-10,11:100.0
7,-10,11:100.0
8,-10,11:100.0
9,-10,11:100.0
10,-10,11:100.0
11,-10,11:159.10
-17,-9,11:82.0
-16,-9,11:159.10
-15,-9,11:100.0
-14,-9,11:100.0
-13,-9,11:100.0
-12,-9,11:100.0
-11,-9,11:100.0
-10,-9,11:100.0
-9,-9,11:100.0
-8,-9,11:100.0
-7,-9,11:100.0
-6,-9,11:100.0
-5,-9,11:100.0
-4,-9,11:100.0
-3,-9,11:159.10
-1,-9,11:159.10
0,-9,11:100.0
1,-9,11:100.0
2,-9,11:100.0
3,-9,11:100.0
4,-9,11:100.0
5,-9,11:100.0
6,-9,11:100.0
7,-9,11:100.0
8,-9,11:100.0
9,-9,11:100.0
10,-9,11:100.0
11,-9,11:100.0
-19,-8,11:82.0
-18,-8,11:82.0
-17,-8,11:100.0
-16,-8,11:100.0
-15,-8,11:100.0
-14,-8,11:100.0
-13,-8,11:100.0
-12,-8,11:100.0
-10,-8,11:100.0
-9,-8,11:100.0
-8,-8,11:100.0
-7,-8,11:100.0
-6,-8,11:100.0
-5,-8,11:100.0
-4,-8,11:100.0
-3,-8,11:100.0
-1,-8,11:159.10
0,-8,11:100.0
1,-8,11:100.0
2,-8,11:100.0
3,-8,11:100.0
4,-8,11:100.0
5,-8,11:100.0
6,-8,11:100.0
7,-8,11:100.0
8,-8,11:100.0
9,-8,11:100.0
10,-8,11:100.0
11,-8,11:100.0
-19,-7,11:100.0
-18,-7,11:100.0
-17,-7,11:100.0
-16,-7,11:100.0
-15,-7,11:100.0
-14,-7,11:100.0
-13,-7,11:100.0
-12,-7,11:100.0
-11,-7,11:100.0
-10,-7,11:100.0
-9,-7,11:100.0
-8,-7,11:100.0
-7,-7,11:100.0
-6,-7,11:100.0
-5,-7,11:100.0
-4,-7,11:100.0
-3,-7,11:100.0
-2,-7,11:100.0
-1,-7,11:100.0
0,-7,11:100.0
1,-7,11:100.0
2,-7,11:100.0
3,-7,11:100.0
4,-7,11:100.0
5,-7,11:100.0
6,-7,11:100.0
7,-7,11:100.0
8,-7,11:100.0
9,-7,11:100.0
10,-7,11:100.0
11,-7,11:100.0
12,-7,11:159.10
13,-7,11:159.10
14,-7,11:100.0
-19,-6,11:82.0
-18,-6,11:100.0
-17,-6,11:100.0
-16,-6,11:100.0
-15,-6,11:100.0
-14,-6,11:100.0
-13,-6,11:100.0
-12,-6,11:100.0
-11,-6,11:100.0
-10,-6,11:100.0
-9,-6,11:100.0
-8,-6,11:100.0
-7,-6,11:100.0
-6,-6,11:100.0
-5,-6,11:100.0
-4,-6,11:100.0
-3,-6,11:100.0
-2,-6,11:100.0
-1,-6,11:100.0
0,-6,11:100.0
1,-6,11:100.0
2,-6,11:100.0
3,-6,11:100.0
4,-6,11:100.0
5,-6,11:100.0
6,-6,11:100.0
7,-6,11:100.0
8,-6,11:100.0
9,-6,11:100.0
10,-6,11:100.0
11,-6,11:100.0
12,-6,11:100.0
13,-6,11:100.0
14,-6,11:100.0
-19,-5,11:159.10
-18,-5,11:100.0
-17,-5,11:100.0
-16,-5,11:100.0
-15,-5,11:100.0
-14,-5,11:100.0
-13,-5,11:100.0
-12,-5,11:100.0
-11,-5,11:100.0
-10,-5,11:100.0
-9,-5,11:100.0
-8,-5,11:100.0
-6,-5,11:100.0
-5,-5,11:100.0
-4,-5,11:100.0
-3,-5,11:100.0
-2,-5,11:100.0
-1,-5,11:100.0
0,-5,11:100.0
1,-5,11:100.0
2,-5,11:100.0
3,-5,11:100.0
4,-5,11:100.0
5,-5,11:100.0
6,-5,11:100.0
7,-5,11:100.0
8,-5,11:100.0
9,-5,11:100.0
10,-5,11:159.10
11,-5,11:100.0
12,-5,11:100.0
13,-5,11:100.0
14,-5,11:100.0
-19,-4,11:159.10
-18,-4,11:100.0
-17,-4,11:100.0
-16,-4,11:100.0
-15,-4,11:100.0
-14,-4,11:100.0
-13,-4,11:100.0
-12,-4,11:100.0
-11,-4,11:100.0
-10,-4,11:159.10
-9,-4,11:100.0
-8,-4,11:100.0
-7,-4,11:100.0
-6,-4,11:100.0
-5,-4,11:100.0
-4,-4,11:100.0
-3,-4,11:100.0
-2,-4,11:100.0
-1,-4,11:100.0
0,-4,11:100.0
1,-4,11:100.0
2,-4,11:100.0
3,-4,11:100.0
4,-4,11:100.0
5,-4,11:100.0
6,-4,11:100.0
7,-4,11:100.0
8,-4,11:100.0
9,-4,11:100.0
10,-4,11:100.0
11,-4,11:100.0
12,-4,11:100.0
13,-4,11:100.0
14,-4,11:159.10
-19,-3,11:159.10
-18,-3,11:100.0
-17,-3,11:100.0
-16,-3,11:100.0
-15,-3,11:100.0
-14,-3,11:100.0
-13,-3,11:100.0
-12,-3,11:100.0
-11,-3,11:100.0
-10,-3,11:100.0
-8,-3,11:100.0
-7,-3,11:100.0
-6,-3,11:100.0
-5,-3,11:100.0
-4,-3,11:100.0
-3,-3,11:100.0
-2,-3,11:100.0
-1,-3,11:100.0
0,-3,11:100.0
1,-3,11:100.0
2,-3,11:100.0
3,-3,11:100.0
4,-3,11:100.0
5,-3,11:100.0
6,-3,11:100.0
7,-3,11:159.10
8,-3,11:100.0
9,-3,11:100.0
10,-3,11:100.0
11,-3,11:100.0
12,-3,11:100.0
13,-3,11:100.0
14,-3,11:159.10
-19,-2,11:159.10
-18,-2,11:100.0
-17,-2,11:100.0
-16,-2,11:100.0
-15,-2,11:100.0
-14,-2,11:100.0
-13,-2,11:100.0
-12,-2,11:100.0
-11,-2,11:100.0
-10,-2,11:100.0
-9,-2,11:100.0
-8,-2,11:100.0
-7,-2,11:100.0
-6,-2,11:100.0
-5,-2,11:100.0
-4,-2,11:100.0
-3,-2,11:100.0
-2,-2,11:100.0
-1,-2,11:100.0
0,-2,11:100.0
1,-2,11:100.0
2,-2,11:100.0
3,-2,11:100.0
4,-2,11:100.0
5,-2,11:100.0
6,-2,11:100.0
7,-2,11:100.0
8,-2,11:100.0
9,-2,11:100.0
10,-2,11:100.0
11,-2,11:100.0
12,-2,11:100.0
13,-2,11:100.0
14,-2,11:159.10
-19,-1,11:159.10
-18,-1,11:100.0
-17,-1,11:100.0
-16,-1,11:100.0
-15,-1,11:100.0
-14,-1,11:100.0
-13,-1,11:100.0
-12,-1,11:100.0
-11,-1,11:100.0
-10,-1,11:100.0
-9,-1,11:100.0
-8,-1,11:100.0
-7,-1,11:100.0
-6,-1,11:100.0
-5,-1,11:100.0
-4,-1,11:100.15
-3,-1,11:100.15
-2,-1,11:100.15
-1,-1,11:100.15
0,-1,11:100.0
1,-1,11:100.0
2,-1,11:100.0
3,-1,11:100.0
4,-1,11:100.0
5,-1,11:100.0
6,-1,11:100.0
7,-1,11:100.0
8,-1,11:100.0
9,-1,11:100.0
10,-1,11:100.0
11,-1,11:100.0
12,-1,11:100.0
13,-1,11:100.0
14,-1,11:159.10
-19,0,11:159.10
-18,0,11:100.0
-17,0,11:100.0
-16,0,11:100.0
-15,0,11:100.0
-14,0,11:100.0
-13,0,11:100.0
-12,0,11:100.0
-11,0,11:100.0
-10,0,11:100.0
-9,0,11:100.0
-8,0,11:100.0
-7,0,11:100.0
-6,0,11:100.0
-4,0,11:100.0
-1,0,11:100.15
0,0,11:100.0
1,0,11:100.0
2,0,11:100.0
3,0,11:100.0
4,0,11:100.0
5,0,11:100.0
6,0,11:100.0
7,0,11:100.0
8,0,11:100.0
9,0,11:100.0
10,0,11:100.0
11,0,11:100.0
12,0,11:100.0
13,0,11:100.0
14,0,11:82.0
-19,1,11:159.10
-18,1,11:100.0
-17,1,11:100.0
-16,1,11:100.0
-15,1,11:100.0
-14,1,11:100.0
-13,1,11:100.0
-12,1,11:100.0
-11,1,11:100.0
-10,1,11:100.0
-9,1,11:100.0
-8,1,11:100.0
-7,1,11:100.0
-6,1,11:100.0
-5,1,11:100.15
-3,1,11:100.0
-2,1,11:100.0
-1,1,11:100.0
0,1,11:100.15
1,1,11:100.0
2,1,11:100.0
3,1,11:100.0
4,1,11:100.0
5,1,11:100.0
6,1,11:100.0
7,1,11:100.0
8,1,11:100.0
9,1,11:100.0
10,1,11:100.0
11,1,11:100.0
12,1,11:100.0
13,1,11:100.0
14,1,11:82.0
-19,2,11:159.10
-18,2,11:100.0
-17,2,11:100.0
-16,2,11:100.0
-15,2,11:100.0
-14,2,11:100.0
-13,2,11:100.0
-12,2,11:100.0
-11,2,11:100.0
-10,2,11:100.0
-9,2,11:100.0
-8,2,11:100.0
-7,2,11:100.0
-6,2,11:100.0
-5,2,11:100.15
-2,2,11:100.0
0,2,11:100.15
1,2,11:100.0
2,2,11:100.0
3,2,11:100.0
4,2,11:100.0
5,2,11:100.0
6,2,11:100.0
7,2,11:100.0
8,2,11:100.0
9,2,11:100.0
10,2,11:100.0
11,2,11:100.0
12,2,11:100.0
13,2,11:100.0
14,2,11:82.0
-18,3,11:159.10
-17,3,11:100.0
-16,3,11:100.0
-15,3,11:100.0
-14,3,11:159.10
-13,3,11:159.10
-12,3,11:159.10
-11,3,11:159.10
-10,3,11:100.0
-9,3,11:100.0
-8,3,11:100.0
-5,3,11:100.0
-4,3,11:100.15
-3,3,11:100.15
-2,3,11:100.0
-1,3,11:100.15
0,3,11:100.15
1,3,11:100.0
2,3,11:100.0
3,3,11:100.0
4,3,11:100.0
5,3,11:100.0
6,3,11:100.0
7,3,11:100.0
8,3,11:100.0
9,3,11:100.0
10,3,11:100.0
11,3,11:100.0
12,3,11:100.0
13,3,11:100.0
14,3,11:159.10
-18,4,11:159.10
-6,4,11:100.0
-5,4,11:100.0
-4,4,11:100.0
-3,4,11:100.0
-2,4,11:100.15
-1,4,11:100.15
0,4,11:100.0
1,4,11:100.0
5,4,11:100.0
13,4,11:100.0
14,4,11:159.10
-18,5,11:159.10
-17,5,11:159.10
-6,5,11:100.0
-5,5,11:100.0
-4,5,11:100.0
-3,5,11:100.0
-2,5,11:100.0
-1,5,11:100.0
0,5,11:100.0
1,5,11:100.0
2,5,11:100.0
13,5,11:100.0
14,5,11:159.10
-18,6,11:159.10
-16,6,11:159.10
-6,6,11:100.0
-5,6,11:100.0
-4,6,11:100.0
-3,6,11:100.0
-2,6,11:100.0
-1,6,11:100.0
0,6,11:100.0
1,6,11:100.0
2,6,11:100.0
3,6,11:100.0
13,6,11:100.0
14,6,11:159.10
-18,7,11:159.10
-17,7,11:159.10
-7,7,11:100.0
-6,7,11:100.0
-5,7,11:100.0
-4,7,11:100.0
-3,7,11:100.0
-2,7,11:100.0
-1,7,11:100.0
0,7,11:100.0
1,7,11:100.0
2,7,11:100.0
3,7,11:100.0
13,7,11:100.0
14,7,11:159.10
-18,8,11:159.10
-17,8,11:159.10
-7,8,11:100.0
-6,8,11:100.0
-5,8,11:100.0
-4,8,11:100.0
-3,8,11:100.0
-2,8,11:100.0
-1,8,11:100.0
0,8,11:100.0
1,8,11:100.0
2,8,11:100.0
3,8,11:100.0
4,8,11:100.0
6,8,11:159.10
13,8,11:159.10
-18,9,11:159.10
-16,9,11:159.10
-8,9,11:100.0
-7,9,11:100.0
-6,9,11:100.0
-5,9,11:100.0
-4,9,11:100.0
-3,9,11:100.0
-2,9,11:100.0
-1,9,11:100.0
0,9,11:100.0
1,9,11:100.0
2,9,11:100.0
3,9,11:100.0
4,9,11:100.0
5,9,11:159.10
7,9,11:159.10
8,9,11:159.10
11,9,11:100.0
12,9,11:100.0
13,9,11:159.10
-18,10,11:159.10
-17,10,11:100.0
-9,10,11:159.10
-8,10,11:100.0
-7,10,11:100.0
-6,10,11:100.0
-5,10,11:100.0
-4,10,11:100.0
-3,10,11:100.0
-2,10,11:100.0
-1,10,11:100.0
0,10,11:100.0
1,10,11:100.0
2,10,11:100.0
3,10,11:100.0
4,10,11:100.0
5,10,11:159.10
6,10,11:159.10
7,10,11:159.10
9,10,11:82.0
10,10,11:100.0
13,10,11:159.10
-18,11,11:159.10
-17,11,11:159.10
-16,11,11:100.0
-9,11,11:100.0
-8,11,11:100.0
-7,11,11:100.0
-6,11,11:100.0
-5,11,11:100.0
-4,11,11:100.0
-3,11,11:100.0
-2,11,11:100.0
-1,11,11:100.0
0,11,11:100.0
1,11,11:100.0
2,11,11:100.0
3,11,11:100.0
4,11,11:100.0
5,11,11:100.0
8,11,11:159.10
10,11,11:100.0
11,11,11:100.0
12,11,11:159.10
13,11,11:159.10
-16,12,11:159.10
-15,12,11:100.0
-10,12,11:159.10
-9,12,11:100.0
-8,12,11:100.0
-7,12,11:100.0
-6,12,11:100.0
-5,12,11:100.0
-4,12,11:100.0
-3,12,11:100.0
-2,12,11:100.0
-1,12,11:100.0
0,12,11:100.0
1,12,11:100.0
2,12,11:100.0
3,12,11:100.0
4,12,11:100.0
5,12,11:100.0
6,12,11:159.10
10,12,11:100.0
11,12,11:82.0
-15,13,11:159.10
-14,13,11:159.10
-13,13,11:100.0
-11,13,11:159.10
-10,13,11:100.0
-9,13,11:100.0
-8,13,11:100.0
-7,13,11:100.0
-6,13,11:100.0
-5,13,11:100.0
-4,13,11:100.0
-3,13,11:100.0
-2,13,11:100.0
-1,13,11:100.0
0,13,11:100.0
1,13,11:100.0
2,13,11:100.0
3,13,11:100.0
4,13,11:100.0
5,13,11:100.0
6,13,11:100.0
9,13,11:100.0
10,13,11:159.10
-13,14,11:159.10
-12,14,11:100.0
-11,14,11:100.0
-10,14,11:100.0
-9,14,11:100.0
-8,14,11:100.0
-7,14,11:100.0
-6,14,11:100.0
-5,14,11:100.0
-4,14,11:100.0
-3,14,11:100.0
-2,14,11:100.0
-1,14,11:100.0
0,14,11:100.0
1,14,11:100.0
2,14,11:100.0
3,14,11:100.0
4,14,11:100.0
5,14,11:100.0
6,14,11:100.0
7,14,11:100.0
8,14,11:159.10
9,14,11:159.10
-12,15,11:159.10
-11,15,11:159.10
-10,15,11:100.0
-9,15,11:100.0
-8,15,11:100.0
-7,15,11:100.0
-6,15,11:100.0
-5,15,11:100.0
-4,15,11:100.0
-3,15,11:100.0
-2,15,11:100.0
-1,15,11:100.0
0,15,11:100.0
1,15,11:100.0
2,15,11:100.0
3,15,11:100.0
4,15,11:100.0
5,15,11:100.0
6,15,11:159.10
7,15,11:159.10
-10,16,11:159.10
-9,16,11:100.0
-8,16,11:100.0
-7,16,11:100.0
-6,16,11:100.0
-5,16,11:100.0
-4,16,11:100.0
-3,16,11:100.0
-2,16,11:100.0
-1,16,11:100.0
0,16,11:100.0
1,16,11:100.0
2,16,11:100.0
3,16,11:100.0
4,16,11:100.0
5,16,11:159.10
-9,17,11:159.10
-8,17,11:159.10
-7,17,11:100.0
-6,17,11:100.0
-5,17,11:100.0
-4,17,11:100.0
-3,17,11:100.0
-2,17,11:100.0
-1,17,11:100.0
0,17,11:100.0
1,17,11:100.0
2,17,11:100.0
3,17,11:159.10
4,17,11:159.10
-7,18,11:159.10
-6,18,11:159.10
-5,18,11:100.0
-4,18,11:100.0
-3,18,11:100.0
-2,18,11:100.0
-1,18,11:100.0
0,18,11:100.0
1,18,11:100.0
2,18,11:159.10
-5,19,11:159.10
-4,19,11:100.0
-1,19,11:100.0
0,19,11:159.10
1,19,11:159.10
-4,20,11:159.10
-3,20,11:159.10
-2,20,11:159.10
-1,20,11:159.10
-2,-16,12:159.10
-5,-15,12:159.10
-4,-15,12:159.10
-3,-15,12:159.10
-2,-15,12:100.0
-1,-15,12:159.10
0,-15,12:159.10
-7,-14,12:159.10
-6,-14,12:159.10
-5,-14,12:100.0
0,-14,12:100.0
1,-14,12:82.0
2,-14,12:82.0
-9,-13,12:159.10
-8,-13,12:159.10
-7,-13,12:100.0
-6,-13,12:100.0
2,-13,12:100.0
3,-13,12:82.0
4,-13,12:82.0
-10,-12,12:82.0
-9,-12,12:100.0
4,-12,12:100.0
5,-12,12:82.0
6,-12,12:159.10
-13,-11,12:82.0
-12,-11,12:82.0
-11,-11,12:82.0
6,-11,12:100.0
7,-11,12:159.10
8,-11,12:159.10
-15,-10,12:159.10
-14,-10,12:159.10
-13,-10,12:100.0
8,-10,12:100.0
9,-10,12:159.10
10,-10,12:159.10
11,-10,12:159.10
-17,-9,12:82.0
-16,-9,12:159.10
-15,-9,12:100.0
-11,-9,12:82.0
10,-9,12:100.0
11,-9,12:100.0
12,-9,12:159.10
-18,-8,12:82.0
-17,-8,12:100.0
-16,-8,12:100.0
-12,-8,12:159.10
-10,-8,12:159.10
11,-8,12:100.0
12,-8,12:159.10
13,-8,12:100.0
14,-8,12:100.0
-19,-7,12:82.0
-18,-7,12:100.0
-17,-7,12:100.0
-16,-7,12:159.10
-11,-7,12:159.10
11,-7,12:100.0
12,-7,12:100.0
13,-7,12:100.0
14,-7,12:159.10
-19,-6,12:82.0
-18,-6,12:100.0
-17,-6,12:100.0
-16,-6,12:100.0
-15,-6,12:100.0
10,-6,12:100.0
11,-6,12:100.0
12,-6,12:100.0
13,-6,12:100.0
14,-6,12:159.10
-19,-5,12:159.10
-18,-5,12:100.0
-14,-5,12:100.0
-13,-5,12:100.0
8,-5,12:100.0
9,-5,12:100.0
13,-5,12:100.0
14,-5,12:159.10
-18,-4,12:159.10
-13,-4,12:100.0
-12,-4,12:100.0
-11,-4,12:100.0
7,-4,12:100.0
8,-4,12:100.0
13,-4,12:159.10
-18,-3,12:159.10
-11,-3,12:100.0
-10,-3,12:100.0
5,-3,12:100.0
6,-3,12:100.0
13,-3,12:159.10
-18,-2,12:159.10
-9,-2,12:100.0
-8,-2,12:100.0
3,-2,12:100.0
4,-2,12:100.0
5,-2,12:100.0
13,-2,12:159.10
-18,-1,12:159.10
-7,-1,12:100.0
-6,-1,12:100.0
-3,-1,12:100.15
-2,-1,12:100.15
2,-1,12:100.0
3,-1,12:100.0
13,-1,12:82.0
-18,0,12:159.10
-4,0,12:100.15
-3,0,12:100.15
-1,0,12:100.15
0,0,12:100.0
1,0,12:100.0
13,0,12:82.0
-18,1,12:159.10
-5,1,12:100.15
-4,1,12:100.15
-3,1,12:100.0
-2,1,12:100.0
-1,1,12:100.0
0,1,12:100.15
13,1,12:82.0
-18,2,12:159.10
-5,2,12:100.15
-4,2,12:100.15
-2,2,12:100.0
0,2,12:100.15
13,2,12:82.0
-18,3,12:159.10
-17,3,12:100.0
-4,3,12:100.15
-3,3,12:100.15
-2,3,12:100.0
-1,3,12:100.15
0,3,12:100.15
13,3,12:82.0
-18,4,12:159.10
-17,4,12:100.0
-2,4,12:100.15
-1,4,12:100.15
13,4,12:159.10
-18,5,12:159.10
-17,5,12:159.10
-2,5,12:100.0
13,5,12:159.10
-18,6,12:159.10
-16,6,12:159.10
-2,6,12:159.10
13,6,12:159.10
-17,7,12:159.10
-2,7,12:100.0
12,7,12:100.0
13,7,12:159.10
-17,8,12:159.10
-2,8,12:100.0
6,8,12:159.10
12,8,12:100.0
13,8,12:159.10
-16,9,12:159.10
-2,9,12:100.0
5,9,12:159.10
7,9,12:159.10
8,9,12:159.10
9,9,12:100.0
10,9,12:100.0
11,9,12:100.0
12,9,12:100.0
13,9,12:159.10
-17,10,12:159.10
-2,10,12:100.0
6,10,12:159.10
7,10,12:159.10
9,10,12:82.0
10,10,12:100.0
12,10,12:100.0
13,10,12:159.10
-17,11,12:159.10
-16,11,12:159.10
-15,11,12:100.0
-2,11,12:100.0
8,11,12:82.0
10,11,12:100.0
11,11,12:82.0
12,11,12:82.0
-15,12,12:159.10
-14,12,12:100.0
-2,12,12:100.0
9,12,12:100.0
10,12,12:82.0
-14,13,12:159.10
-13,13,12:159.10
-12,13,12:100.0
-2,13,12:100.0
7,13,12:100.0
8,13,12:159.10
9,13,12:82.0
-12,14,12:159.10
-11,14,12:100.0
-2,14,12:100.0
6,14,12:100.0
7,14,12:159.10
-11,15,12:159.10
-10,15,12:159.10
-9,15,12:100.0
-2,15,12:100.0
4,15,12:100.0
5,15,12:159.10
6,15,12:159.10
-9,16,12:159.10
-8,16,12:100.0
-2,16,12:100.0
3,16,12:100.0
4,16,12:159.10
-8,17,12:159.10
-7,17,12:159.10
-6,17,12:100.0
-2,17,12:100.0
2,17,12:159.10
3,17,12:159.10
-6,18,12:82.0
-5,18,12:100.0
-3,18,12:100.0
-2,18,12:100.0
0,18,12:100.0
1,18,12:159.10
-5,19,12:159.10
-4,19,12:159.10
-3,19,12:159.10
-1,19,12:100.0
0,19,12:159.10
-3,20,12:159.10
-2,20,12:159.10
-1,20,12:159.10
-3,-15,13:159.10
-2,-15,13:159.10
-5,-14,13:159.10
-4,-14,13:159.10
-3,-14,13:100.0
-2,-14,13:100.0
-1,-14,13:159.10
0,-14,13:159.10
-7,-13,13:159.10
-6,-13,13:159.10
-5,-13,13:100.0
0,-13,13:100.0
1,-13,13:82.0
2,-13,13:82.0
3,-13,13:82.0
-9,-12,13:82.0
-8,-12,13:159.10
-7,-12,13:100.0
-6,-12,13:100.0
2,-12,13:100.0
3,-12,13:100.0
4,-12,13:82.0
5,-12,13:82.0
-11,-11,13:82.0
-10,-11,13:82.0
-9,-11,13:100.0
4,-11,13:100.0
5,-11,13:100.0
6,-11,13:159.10
7,-11,13:159.10
-13,-10,13:82.0
-12,-10,13:82.0
-11,-10,13:100.0
6,-10,13:100.0
7,-10,13:100.0
8,-10,13:159.10
-15,-9,13:159.10
-14,-9,13:159.10
-13,-9,13:100.0
-11,-9,13:82.0
9,-9,13:159.10
10,-9,13:159.10
11,-9,13:159.10
-17,-8,13:159.10
-16,-8,13:159.10
-15,-8,13:100.0
-12,-8,13:159.10
-10,-8,13:159.10
11,-8,13:100.0
12,-8,13:159.10
13,-8,13:159.10
14,-8,13:159.10
-18,-7,13:82.0
-17,-7,13:100.0
-11,-7,13:159.10
11,-7,13:100.0
12,-7,13:100.0
13,-7,13:159.10
-18,-6,13:159.10
-17,-6,13:100.0
-16,-6,13:100.0
-15,-6,13:100.0
10,-6,13:100.0
11,-6,13:100.0
12,-6,13:100.0
13,-6,13:159.10
-18,-5,13:159.10
-17,-5,13:100.0
-15,-5,13:100.0
-14,-5,13:100.0
-13,-5,13:100.0
8,-5,13:100.0
9,-5,13:100.0
12,-5,13:100.0
13,-5,13:159.10
-18,-4,13:159.10
-17,-4,13:100.0
-13,-4,13:100.0
-12,-4,13:100.0
-11,-4,13:100.0
7,-4,13:100.0
8,-4,13:100.0
12,-4,13:100.0
13,-4,13:159.10
-17,-3,13:159.10
-11,-3,13:100.0
-10,-3,13:100.0
5,-3,13:100.0
6,-3,13:100.0
12,-3,13:100.0
13,-3,13:159.10
-18,-2,13:159.10
-17,-2,13:100.0
-9,-2,13:100.0
-8,-2,13:100.0
3,-2,13:100.0
4,-2,13:100.0
5,-2,13:159.10
12,-2,13:100.0
13,-2,13:159.10
-17,-1,13:159.10
-7,-1,13:100.0
-6,-1,13:100.0
-2,-1,13:100.15
2,-1,13:100.0
3,-1,13:100.0
12,-1,13:100.0
13,-1,13:82.0
-17,0,13:159.10
-4,0,13:100.15
-3,0,13:100.15
-2,0,13:100.15
-1,0,13:100.15
0,0,13:100.0
1,0,13:100.0
12,0,13:100.0
13,0,13:82.0
-17,1,13:159.10
-4,1,13:100.15
-3,1,13:100.0
-2,1,13:100.0
-1,1,13:100.0
0,1,13:100.15
12,1,13:100.0
13,1,13:82.0
-17,2,13:82.0
-4,2,13:100.15
-2,2,13:100.0
-1,2,13:100.15
12,2,13:82.0
-17,3,13:82.0
-3,3,13:100.15
-2,3,13:100.15
-1,3,13:100.15
12,3,13:82.0
-17,4,13:82.0
-2,4,13:100.0
12,4,13:159.10
-17,5,13:159.10
-2,5,13:100.0
12,5,13:159.10
-16,6,13:159.10
-2,6,13:100.0
12,6,13:159.10
-17,7,13:159.10
-16,7,13:100.0
-2,7,13:100.0
12,7,13:159.10
-17,8,13:159.10
-16,8,13:100.0
-2,8,13:100.0
6,8,13:159.10
12,8,13:159.10
-16,9,13:159.10
-2,9,13:100.0
5,9,13:159.10
7,9,13:159.10
8,9,13:159.10
9,9,13:82.0
10,9,13:100.0
11,9,13:100.0
12,9,13:159.10
-17,10,13:159.10
-16,10,13:159.10
-15,10,13:100.0
-2,10,13:100.0
6,10,13:159.10
7,10,13:159.10
9,10,13:82.0
10,10,13:100.0
11,10,13:82.0
12,10,13:82.0
-15,11,13:159.10
-14,11,13:100.0
-2,11,13:100.0
8,11,13:82.0
9,11,13:100.0
10,11,13:82.0
11,11,13:82.0
-14,12,13:159.10
-13,12,13:82.0
-12,12,13:100.0
-2,12,13:100.0
7,12,13:100.0
8,12,13:100.0
9,12,13:82.0
-12,13,13:159.10
-11,13,13:100.0
-2,13,13:100.0
6,13,13:100.0
7,13,13:159.10
8,13,13:159.10
-11,14,13:159.10
-10,14,13:159.10
-9,14,13:100.0
-2,14,13:100.0
5,14,13:100.0
6,14,13:159.10
-9,15,13:159.10
-8,15,13:100.0
-2,15,13:100.0
3,15,13:100.0
4,15,13:159.10
5,15,13:159.10
-8,16,13:159.10
-7,16,13:82.0
-6,16,13:100.0
-2,16,13:100.0
2,16,13:100.0
3,16,13:159.10
-6,17,13:82.0
-5,17,13:100.0
-2,17,13:100.0
0,17,13:100.0
1,17,13:159.10
2,17,13:159.10
-5,18,13:82.0
-4,18,13:82.0
-3,18,13:82.0
-2,18,13:159.10
-1,18,13:100.0
0,18,13:159.10
-1,19,13:159.10
-4,-14,14:159.10
-3,-14,14:159.10
-2,-14,14:159.10
-1,-14,14:159.10
-5,-13,14:159.10
-4,-13,14:100.0
-3,-13,14:100.0
-2,-13,14:100.0
-1,-13,14:100.0
0,-13,14:159.10
1,-13,14:82.0
-7,-12,14:159.10
-6,-12,14:159.10
-5,-12,14:100.0
0,-12,14:100.0
1,-12,14:100.0
2,-12,14:82.0
3,-12,14:82.0
-9,-11,14:82.0
-8,-11,14:159.10
-7,-11,14:100.0
2,-11,14:100.0
3,-11,14:100.0
4,-11,14:82.0
5,-11,14:159.10
-11,-10,14:82.0
-10,-10,14:82.0
-9,-10,14:100.0
4,-10,14:100.0
5,-10,14:100.0
6,-10,14:159.10
7,-10,14:159.10
-13,-9,14:159.10
-12,-9,14:82.0
-11,-9,14:82.0
7,-9,14:100.0
8,-9,14:159.10
9,-9,14:159.10
-15,-8,14:159.10
-14,-8,14:159.10
-13,-8,14:100.0
-12,-8,14:159.10
-10,-8,14:159.10
9,-8,14:100.0
10,-8,14:159.10
11,-8,14:159.10
-17,-7,14:159.10
-16,-7,14:159.10
-15,-7,14:100.0
-11,-7,14:159.10
11,-7,14:100.0
12,-7,14:159.10
-17,-6,14:159.10
-16,-6,14:100.0
-15,-6,14:100.0
10,-6,14:100.0
11,-6,14:100.0
12,-6,14:159.10
-17,-5,14:159.10
-15,-5,14:100.0
-14,-5,14:100.0
-13,-5,14:100.0
8,-5,14:100.0
9,-5,14:100.0
12,-5,14:159.10
-17,-4,14:159.10
-16,-4,14:100.0
-13,-4,14:100.0
-12,-4,14:100.0
-11,-4,14:100.0
7,-4,14:100.0
8,-4,14:100.0
12,-4,14:159.10
-17,-3,14:159.10
-16,-3,14:100.0
-11,-3,14:100.0
-10,-3,14:100.0
5,-3,14:100.0
6,-3,14:100.0
12,-3,14:159.10
-17,-2,14:159.10
-16,-2,14:100.0
-9,-2,14:100.0
-8,-2,14:100.0
3,-2,14:100.0
4,-2,14:100.0
11,-2,14:100.0
12,-2,14:159.10
-17,-1,14:159.10
-16,-1,14:100.0
-7,-1,14:100.0
-6,-1,14:100.0
2,-1,14:100.0
3,-1,14:100.0
11,-1,14:100.0
12,-1,14:82.0
-17,0,14:159.10
-16,0,14:100.0
-4,0,14:100.0
-3,0,14:100.15
-2,0,14:100.15
-1,0,14:100.15
0,0,14:100.0
1,0,14:100.0
11,0,14:100.0
12,0,14:82.0
-17,1,14:82.0
-16,1,14:100.0
-4,1,14:100.15
-3,1,14:100.0
-2,1,14:100.0
-1,1,14:100.15
0,1,14:100.0
11,1,14:100.0
12,1,14:82.0
-17,2,14:82.0
-16,2,14:100.0
-4,2,14:100.15
-3,2,14:100.15
-2,2,14:100.0
-1,2,14:100.15
11,2,14:100.0
12,2,14:82.0
-16,3,14:82.0
-3,3,14:100.15
-2,3,14:100.15
-1,3,14:100.15
11,3,14:100.0
12,3,14:82.0
-16,4,14:82.0
-2,4,14:100.0
11,4,14:100.0
12,4,14:159.10
-16,5,14:82.0
-2,5,14:100.0
11,5,14:100.0
12,5,14:159.10
-16,6,14:159.10
-2,6,14:100.0
11,6,14:100.0
12,6,14:159.10
-16,7,14:159.10
-2,7,14:100.0
11,7,14:159.10
-16,8,14:159.10
-2,8,14:100.0
6,8,14:159.10
11,8,14:159.10
-16,9,14:159.10
-15,9,14:100.0
-2,9,14:100.0
5,9,14:159.10
7,9,14:159.10
8,9,14:159.10
10,9,14:100.0
11,9,14:82.0
-16,10,14:159.10
-15,10,14:159.10
-14,10,14:100.0
-2,10,14:100.0
6,10,14:159.10
7,10,14:159.10
9,10,14:82.0
10,10,14:82.0
-14,11,14:82.0
-13,11,14:100.0
-2,11,14:100.0
8,11,14:82.0
9,11,14:82.0
-13,12,14:82.0
-12,12,14:82.0
-11,12,14:100.0
-2,12,14:100.0
6,12,14:100.0
7,12,14:159.10
8,12,14:82.0
-11,13,14:82.0
-10,13,14:100.0
-2,13,14:100.0
5,13,14:100.0
6,13,14:159.10
-10,14,14:159.10
-9,14,14:159.10
-8,14,14:100.0
-2,14,14:100.0
3,14,14:100.0
4,14,14:159.10
5,14,14:159.10
-8,15,14:159.10
-7,15,14:100.0
-6,15,14:100.0
-2,15,14:100.0
2,15,14:100.0
3,15,14:159.10
-7,16,14:82.0
-6,16,14:82.0
-5,16,14:100.0
-2,16,14:100.0
0,16,14:100.0
1,16,14:159.10
2,16,14:159.10
-5,17,14:82.0
-4,17,14:82.0
-3,17,14:100.0
-2,17,14:100.0
-1,17,14:100.0
0,17,14:159.10
-3,18,14:82.0
-2,18,14:159.10
-1,18,14:159.10
-4,-13,15:159.10
-3,-13,15:159.10
-2,-13,15:159.10
-1,-13,15:159.10
-6,-12,15:159.10
-5,-12,15:159.10
-4,-12,15:100.0
-3,-12,15:100.0
-2,-12,15:100.0
-1,-12,15:100.0
0,-12,15:159.10
1,-12,15:159.10
-8,-11,15:159.10
-7,-11,15:159.10
-6,-11,15:100.0
-5,-11,15:100.0
-4,-11,15:100.0
-1,-11,15:100.0
0,-11,15:100.0
1,-11,15:100.0
2,-11,15:159.10
3,-11,15:159.10
-10,-10,15:82.0
-9,-10,15:159.10
-8,-10,15:100.0
-7,-10,15:100.0
2,-10,15:100.0
3,-10,15:100.0
4,-10,15:159.10
5,-10,15:159.10
-11,-9,15:159.10
-10,-9,15:100.0
-9,-9,15:100.0
4,-9,15:100.0
5,-9,15:100.0
6,-9,15:159.10
7,-9,15:159.10
-13,-8,15:159.10
-12,-8,15:159.10
-10,-8,15:159.10
7,-8,15:100.0
8,-8,15:159.10
9,-8,15:82.0
-15,-7,15:159.10
-14,-7,15:159.10
-13,-7,15:100.0
-11,-7,15:159.10
9,-7,15:100.0
10,-7,15:82.0
11,-7,15:82.0
-16,-6,15:159.10
-15,-6,15:100.0
10,-6,15:100.0
11,-6,15:82.0
-16,-5,15:159.10
-15,-5,15:100.0
-14,-5,15:100.0
-13,-5,15:100.0
8,-5,15:100.0
9,-5,15:100.0
11,-5,15:82.0
-16,-4,15:159.10
-13,-4,15:100.0
-12,-4,15:100.0
-11,-4,15:100.0
7,-4,15:100.0
8,-4,15:100.0
11,-4,15:82.0
-16,-3,15:159.10
-11,-3,15:100.0
-10,-3,15:100.0
5,-3,15:100.0
6,-3,15:100.0
11,-3,15:159.10
-16,-2,15:159.10
-9,-2,15:100.0
-8,-2,15:100.0
3,-2,15:100.0
4,-2,15:100.0
11,-2,15:159.10
-16,-1,15:159.10
-15,-1,15:100.0
-7,-1,15:100.0
-6,-1,15:100.0
2,-1,15:100.0
3,-1,15:100.0
11,-1,15:159.10
-16,0,15:159.10
-15,0,15:100.0
-4,0,15:100.0
-3,0,15:100.15
-2,0,15:100.15
0,0,15:100.0
1,0,15:100.0
11,0,15:159.10
-16,1,15:82.0
-15,1,15:100.0
-4,1,15:100.15
-3,1,15:100.0
-2,1,15:100.0
-1,1,15:100.0
0,1,15:159.10
11,1,15:159.10
-16,2,15:82.0
-15,2,15:100.0
-4,2,15:100.15
-3,2,15:100.15
-2,2,15:100.0
-1,2,15:100.15
11,2,15:159.10
-16,3,15:82.0
-15,3,15:100.0
-2,3,15:100.15
10,3,15:100.0
11,3,15:159.10
-16,4,15:82.0
-15,4,15:100.0
-2,4,15:100.0
10,4,15:100.0
11,4,15:159.10
-16,5,15:82.0
-15,5,15:100.0
-2,5,15:100.0
10,5,15:100.0
11,5,15:159.10
-15,6,15:159.10
-2,6,15:100.0
10,6,15:100.0
11,6,15:159.10
-15,7,15:159.10
-2,7,15:100.0
10,7,15:100.0
11,7,15:159.10
-15,8,15:159.10
-2,8,15:100.0
6,8,15:159.10
9,8,15:100.0
10,8,15:100.0
11,8,15:159.10
-15,9,15:159.10
-14,9,15:100.0
-2,9,15:100.0
5,9,15:159.10
7,9,15:159.10
8,9,15:159.10
9,9,15:100.0
10,9,15:100.0
11,9,15:159.10
-14,10,15:82.0
-13,10,15:100.0
-2,10,15:100.0
6,10,15:159.10
7,10,15:159.10
9,10,15:82.0
10,10,15:82.0
-13,11,15:82.0
-12,11,15:82.0
-11,11,15:100.0
-2,11,15:100.0
6,11,15:100.0
7,11,15:159.10
8,11,15:159.10
-11,12,15:82.0
-10,12,15:100.0
-2,12,15:100.0
5,12,15:100.0
6,12,15:159.10
-10,13,15:159.10
-9,13,15:159.10
-8,13,15:100.0
-2,13,15:100.0
3,13,15:100.0
4,13,15:159.10
5,13,15:159.10
-8,14,15:159.10
-7,14,15:100.0
-6,14,15:100.0
-2,14,15:100.0
2,14,15:100.0
3,14,15:159.10
-7,15,15:159.10
-6,15,15:82.0
-5,15,15:100.0
-2,15,15:100.0
0,15,15:100.0
1,15,15:159.10
2,15,15:159.10
-5,16,15:82.0
-4,16,15:82.0
-3,16,15:100.0
-2,16,15:100.0
-1,16,15:100.0
0,16,15:159.10
-3,17,15:82.0
-2,17,15:159.10
-1,17,15:159.10
-4,-12,16:159.10
-3,-12,16:159.10
-2,-12,16:159.10
-1,-12,16:159.10
-6,-11,16:159.10
-5,-11,16:159.10
-4,-11,16:159.10
-3,-11,16:100.0
-2,-11,16:100.0
-1,-11,16:159.10
0,-11,16:159.10
1,-11,16:159.10
-8,-10,16:159.10
-7,-10,16:159.10
-6,-10,16:100.0
-4,-10,16:100.0
-3,-10,16:100.0
-2,-10,16:100.0
-1,-10,16:100.0
0,-10,16:100.0
1,-10,16:100.0
2,-10,16:159.10
3,-10,16:159.10
-10,-9,16:159.10
-9,-9,16:159.10
-8,-9,16:100.0
-4,-9,16:100.0
-3,-9,16:100.0
-1,-9,16:100.0
0,-9,16:100.0
1,-9,16:100.0
2,-9,16:100.0
3,-9,16:100.0
4,-9,16:159.10
5,-9,16:159.10
-12,-8,16:159.10
-10,-8,16:159.10
-1,-8,16:100.0
0,-8,16:100.0
1,-8,16:100.0
2,-8,16:100.0
3,-8,16:100.0
5,-8,16:100.0
6,-8,16:159.10
7,-8,16:159.10
-14,-7,16:159.10
-13,-7,16:159.10
-12,-7,16:100.0
-11,-7,16:159.10
2,-7,16:100.0
7,-7,16:100.0
8,-7,16:82.0
9,-7,16:82.0
-15,-6,16:159.10
-14,-6,16:159.10
-13,-6,16:100.0
9,-6,16:100.0
10,-6,16:82.0
-15,-5,16:159.10
-14,-5,16:100.0
-13,-5,16:100.0
8,-5,16:100.0
9,-5,16:100.0
10,-5,16:82.0
-15,-4,16:159.10
-13,-4,16:100.0
-12,-4,16:100.0
-11,-4,16:82.0
6,-4,16:100.0
7,-4,16:100.0
8,-4,16:100.0
10,-4,16:82.0
-15,-3,16:159.10
-11,-3,16:100.0
-10,-3,16:100.0
5,-3,16:100.0
6,-3,16:100.0
10,-3,16:159.10
-15,-2,16:159.10
-9,-2,16:100.0
-8,-2,16:100.0
3,-2,16:100.0
4,-2,16:100.0
10,-2,16:159.10
-15,-1,16:159.10
-7,-1,16:100.0
-6,-1,16:100.0
2,-1,16:100.0
3,-1,16:100.0
10,-1,16:159.10
-15,0,16:159.10
-4,0,16:100.0
-3,0,16:100.15
-2,0,16:100.15
0,0,16:100.0
1,0,16:100.0
10,0,16:159.10
-15,1,16:82.0
-4,1,16:100.0
-3,1,16:100.15
-2,1,16:100.15
-1,1,16:100.0
10,1,16:159.10
-15,2,16:82.0
-4,2,16:100.15
-3,2,16:100.15
-2,2,16:100.15
10,2,16:159.10
-15,3,16:82.0
-14,3,16:100.0
-2,3,16:100.0
7,3,16:100.0
8,3,16:100.0
10,3,16:159.10
-15,4,16:82.0
-14,4,16:100.0
-2,4,16:100.0
7,4,16:100.0
8,4,16:100.0
9,4,16:100.0
10,4,16:159.10
-15,5,16:82.0
-14,5,16:100.0
-2,5,16:100.0
7,5,16:100.0
8,5,16:100.0
9,5,16:100.0
10,5,16:159.10
-15,6,16:159.10
-14,6,16:100.0
-2,6,16:100.0
7,6,16:100.0
8,6,16:100.0
9,6,16:100.0
10,6,16:159.10
-15,7,16:159.10
-14,7,16:100.0
-2,7,16:100.0
6,7,16:100.0
7,7,16:100.0
8,7,16:100.0
9,7,16:100.0
10,7,16:159.10
-15,8,16:159.10
-14,8,16:159.10
-2,8,16:100.0
6,8,16:159.10
9,8,16:159.10
10,8,16:159.10
-15,9,16:159.10
-14,9,16:159.10
-13,9,16:100.0
-2,9,16:100.0
5,9,16:159.10
7,9,16:159.10
8,9,16:159.10
9,9,16:159.10
10,9,16:159.10
-13,10,16:82.0
-12,10,16:82.0
-11,10,16:100.0
-2,10,16:100.0
6,10,16:159.10
7,10,16:159.10
-12,11,16:82.0
-11,11,16:82.0
-10,11,16:100.0
-2,11,16:100.0
5,11,16:100.0
6,11,16:159.10
7,11,16:159.10
-10,12,16:82.0
-9,12,16:159.10
-8,12,16:100.0
-2,12,16:100.0
3,12,16:100.0
4,12,16:159.10
5,12,16:159.10
-8,13,16:159.10
-7,13,16:159.10
-6,13,16:100.0
-2,13,16:100.0
1,13,16:100.0
2,13,16:100.0
3,13,16:159.10
-7,14,16:159.10
-6,14,16:159.10
-5,14,16:100.0
-2,14,16:100.0
0,14,16:100.0
1,14,16:82.0
2,14,16:82.0
-5,15,16:159.10
-4,15,16:159.10
-3,15,16:100.0
-2,15,16:100.0
-1,15,16:82.0
0,15,16:82.0
-3,16,16:159.10
-2,16,16:159.10
-1,16,16:159.10
-3,-11,17:159.10
-2,-11,17:159.10
-6,-10,17:159.10
-5,-10,17:159.10
-4,-10,17:159.10
-3,-10,17:82.0
-2,-10,17:82.0
-1,-10,17:82.0
0,-10,17:159.10
1,-10,17:159.10
-8,-9,17:159.10
-7,-9,17:159.10
-6,-9,17:159.10
-5,-9,17:159.10
-4,-9,17:82.0
-3,-9,17:82.0
-2,-9,17:100.0
-1,-9,17:82.0
0,-9,17:82.0
1,-9,17:159.10
2,-9,17:159.10
3,-9,17:159.10
-10,-8,17:159.10
-9,-8,17:159.10
-8,-8,17:159.10
-7,-8,17:159.10
-6,-8,17:159.10
-5,-8,17:159.10
-4,-8,17:82.0
-3,-8,17:100.0
-2,-8,17:100.0
-1,-8,17:82.0
0,-8,17:82.0
1,-8,17:159.10
2,-8,17:159.10
3,-8,17:159.10
4,-8,17:159.10
5,-8,17:159.10
-12,-7,17:159.10
-11,-7,17:159.10
-10,-7,17:159.10
-9,-7,17:159.10
-8,-7,17:159.10
-7,-7,17:159.10
-6,-7,17:100.0
0,-7,17:100.0
1,-7,17:100.0
2,-7,17:159.10
3,-7,17:159.10
4,-7,17:159.10
5,-7,17:159.10
6,-7,17:159.10
7,-7,17:159.10
-13,-6,17:159.10
-12,-6,17:159.10
-11,-6,17:159.10
-10,-6,17:159.10
-9,-6,17:100.0
-8,-6,17:100.0
3,-6,17:100.0
4,-6,17:159.10
5,-6,17:159.10
6,-6,17:159.10
7,-6,17:159.10
8,-6,17:82.0
9,-6,17:82.0
-14,-5,17:159.10
-13,-5,17:159.10
-12,-5,17:159.10
-11,-5,17:100.0
-1,-5,17:100.0
0,-5,17:100.0
1,-5,17:100.0
5,-5,17:100.0
6,-5,17:100.0
7,-5,17:159.10
8,-5,17:82.0
9,-5,17:82.0
-14,-4,17:159.10
-13,-4,17:159.10
-12,-4,17:100.0
2,-4,17:100.0
6,-4,17:100.0
7,-4,17:100.0
8,-4,17:159.10
9,-4,17:82.0
-14,-3,17:159.10
-13,-3,17:159.10
-11,-3,17:100.0
-10,-3,17:100.0
5,-3,17:100.0
6,-3,17:100.0
7,-3,17:100.0
8,-3,17:159.10
9,-3,17:159.10
-14,-2,17:159.10
-13,-2,17:159.10
-9,-2,17:100.0
-8,-2,17:100.0
3,-2,17:100.0
4,-2,17:100.0
7,-2,17:100.0
8,-2,17:159.10
9,-2,17:159.10
-14,-1,17:159.10
-13,-1,17:159.10
-7,-1,17:100.0
-6,-1,17:100.0
1,-1,17:100.0
2,-1,17:100.0
3,-1,17:100.0
7,-1,17:100.0
8,-1,17:159.10
9,-1,17:159.10
-14,0,17:159.10
-13,0,17:159.10
-12,0,17:100.0
-6,0,17:100.0
-4,0,17:100.0
0,0,17:100.0
1,0,17:100.0
7,0,17:100.0
8,0,17:159.10
9,0,17:159.10
-14,1,17:159.10
-13,1,17:159.10
-12,1,17:100.0
-4,1,17:100.0
-3,1,17:100.15
-2,1,17:100.15
-1,1,17:100.0
7,1,17:100.0
8,1,17:159.10
9,1,17:159.10
-14,2,17:159.10
-13,2,17:159.10
-12,2,17:100.0
-3,2,17:100.15
-2,2,17:100.15
7,2,17:100.0
8,2,17:159.10
9,2,17:159.10
-14,3,17:159.10
-13,3,17:159.10
-12,3,17:159.10
-2,3,17:100.0
7,3,17:159.10
8,3,17:159.10
9,3,17:159.10
-14,4,17:159.10
-13,4,17:159.10
-12,4,17:159.10
-2,4,17:100.0
7,4,17:159.10
8,4,17:159.10
9,4,17:159.10
-14,5,17:159.10
-13,5,17:159.10
-12,5,17:159.10
-2,5,17:100.0
7,5,17:159.10
8,5,17:159.10
9,5,17:159.10
-14,6,17:159.10
-13,6,17:159.10
-12,6,17:159.10
-11,6,17:100.0
-2,6,17:100.0
7,6,17:159.10
8,6,17:159.10
9,6,17:159.10
-14,7,17:159.10
-13,7,17:159.10
-12,7,17:100.0
-11,7,17:100.0
-2,7,17:100.0
6,7,17:159.10
7,7,17:159.10
8,7,17:159.10
9,7,17:159.10
-13,8,17:159.10
-12,8,17:159.10
-11,8,17:159.10
-10,8,17:159.10
-9,8,17:100.0
-2,8,17:100.0
4,8,17:100.0
5,8,17:159.10
6,8,17:159.10
7,8,17:159.10
8,8,17:159.10
-13,9,17:159.10
-12,9,17:159.10
-11,9,17:159.10
-10,9,17:159.10
-9,9,17:159.10
-8,9,17:100.0
-2,9,17:100.0
3,9,17:100.0
4,9,17:159.10
5,9,17:159.10
7,9,17:159.10
8,9,17:159.10
-11,10,17:82.0
-10,10,17:159.10
-9,10,17:159.10
-8,10,17:159.10
-7,10,17:159.10
-6,10,17:100.0
-2,10,17:100.0
2,10,17:159.10
3,10,17:159.10
4,10,17:159.10
5,10,17:159.10
6,10,17:159.10
-10,11,17:159.10
-9,11,17:159.10
-8,11,17:159.10
-7,11,17:159.10
-6,11,17:159.10
-5,11,17:100.0
-2,11,17:100.0
0,11,17:100.0
1,11,17:82.0
2,11,17:159.10
3,11,17:159.10
4,11,17:159.10
5,11,17:159.10
-8,12,17:159.10
-7,12,17:159.10
-6,12,17:159.10
-5,12,17:159.10
-4,12,17:159.10
-3,12,17:100.0
-2,12,17:100.0
-1,12,17:100.0
0,12,17:82.0
1,12,17:82.0
2,12,17:82.0
3,12,17:159.10
-6,13,17:159.10
-5,13,17:159.10
-4,13,17:159.10
-3,13,17:159.10
-2,13,17:82.0
-1,13,17:82.0
0,13,17:82.0
1,13,17:82.0
2,13,17:82.0
-5,14,17:159.10
-4,14,17:159.10
-3,14,17:159.10
-2,14,17:82.0
-1,14,17:82.0
0,14,17:82.0
-3,15,17:159.10
-2,15,17:159.10
-2,-9,18:82.0
-3,-8,18:82.0
-2,-8,18:82.0
-6,-7,18:159.10
-5,-7,18:159.10
-4,-7,18:82.0
-3,-7,18:82.0
-2,-7,18:82.0
-1,-7,18:82.0
0,-7,18:82.0
1,-7,18:159.10
-9,-6,18:159.10
-8,-6,18:159.10
-7,-6,18:159.10
-6,-6,18:159.10
-5,-6,18:159.10
-4,-6,18:159.10
-3,-6,18:82.0
-2,-6,18:100.0
-1,-6,18:82.0
0,-6,18:159.10
1,-6,18:159.10
2,-6,18:159.10
3,-6,18:159.10
-11,-5,18:82.0
-10,-5,18:82.0
-9,-5,18:82.0
-8,-5,18:159.10
-6,-5,18:159.10
-5,-5,18:159.10
-4,-5,18:159.10
-3,-5,18:100.0
-2,-5,18:100.0
-1,-5,18:159.10
0,-5,18:159.10
1,-5,18:159.10
2,-5,18:159.10
3,-5,18:159.10
4,-5,18:159.10
5,-5,18:159.10
6,-5,18:159.10
-12,-4,18:82.0
-11,-4,18:82.0
-10,-4,18:82.0
-9,-4,18:82.0
-8,-4,18:82.0
-7,-4,18:159.10
-6,-4,18:100.0
-5,-4,18:100.0
0,-4,18:100.0
1,-4,18:100.0
2,-4,18:159.10
3,-4,18:159.10
4,-4,18:159.10
5,-4,18:159.10
6,-4,18:159.10
7,-4,18:159.10
-12,-3,18:82.0
-11,-3,18:82.0
-10,-3,18:82.0
-8,-3,18:100.0
3,-3,18:100.0
4,-3,18:159.10
5,-3,18:159.10
6,-3,18:159.10
7,-3,18:159.10
-12,-2,18:82.0
-11,-2,18:82.0
-10,-2,18:82.0
-9,-2,18:100.0
-8,-2,18:100.0
3,-2,18:100.0
4,-2,18:100.0
5,-2,18:159.10
6,-2,18:159.10
7,-2,18:159.10
-12,-1,18:159.10
-11,-1,18:82.0
-10,-1,18:82.0
-8,-1,18:100.0
-7,-1,18:100.0
-6,-1,18:100.0
1,-1,18:100.0
2,-1,18:100.0
3,-1,18:100.0
4,-1,18:100.0
5,-1,18:159.10
6,-1,18:159.10
7,-1,18:159.10
-12,0,18:159.10
-11,0,18:159.10
-10,0,18:159.10
-9,0,18:100.0
-6,0,18:100.0
-4,0,18:100.0
0,0,18:100.0
1,0,18:100.0
4,0,18:100.0
5,0,18:159.10
6,0,18:159.10
7,0,18:159.10
-12,1,18:159.10
-11,1,18:159.10
-10,1,18:159.10
-9,1,18:100.0
-4,1,18:100.0
-3,1,18:100.0
-2,1,18:100.0
-1,1,18:100.0
4,1,18:100.0
5,1,18:82.0
6,1,18:159.10
7,1,18:159.10
-12,2,18:159.10
-11,2,18:159.10
-10,2,18:159.10
-9,2,18:100.0
-3,2,18:100.15
-2,2,18:100.0
4,2,18:100.0
5,2,18:82.0
6,2,18:159.10
7,2,18:159.10
-11,3,18:159.10
-10,3,18:159.10
-9,3,18:82.0
-2,3,18:100.0
4,3,18:100.0
5,3,18:82.0
6,3,18:159.10
-11,4,18:159.10
-10,4,18:82.0
-9,4,18:82.0
-2,4,18:100.0
4,4,18:82.0
5,4,18:159.10
6,4,18:159.10
-11,5,18:159.10
-10,5,18:82.0
-9,5,18:82.0
-8,5,18:100.0
-2,5,18:100.0
4,5,18:159.10
5,5,18:159.10
6,5,18:159.10
-11,6,18:159.10
-10,6,18:82.0
-9,6,18:82.0
-8,6,18:82.0
-7,6,18:100.0
-2,6,18:100.0
2,6,18:100.0
3,6,18:159.10
4,6,18:159.10
5,6,18:159.10
6,6,18:159.10
-12,7,18:159.10
-11,7,18:159.10
-10,7,18:159.10
-9,7,18:82.0
-8,7,18:82.0
-7,7,18:82.0
-6,7,18:159.10
-2,7,18:100.0
1,7,18:100.0
2,7,18:159.10
3,7,18:159.10
4,7,18:159.10
5,7,18:159.10
-9,8,18:159.10
-8,8,18:159.10
-7,8,18:159.10
-6,8,18:159.10
-5,8,18:159.10
-4,8,18:100.0
-2,8,18:100.0
-1,8,18:100.0
0,8,18:159.10
1,8,18:159.10
2,8,18:159.10
3,8,18:159.10
4,8,18:159.10
-8,9,18:159.10
-7,9,18:159.10
-6,9,18:159.10
-5,9,18:159.10
-4,9,18:159.10
-3,9,18:100.0
-2,9,18:100.0
-1,9,18:159.10
0,9,18:159.10
1,9,18:159.10
2,9,18:159.10
3,9,18:159.10
-6,10,18:159.10
-5,10,18:159.10
-4,10,18:159.10
-3,10,18:159.10
-2,10,18:159.10
-1,10,18:159.10
0,10,18:159.10
1,10,18:159.10
-5,11,18:159.10
-4,11,18:159.10
-3,11,18:159.10
-2,11,18:159.10
-1,11,18:82.0
0,11,18:82.0
-3,12,18:159.10
-2,12,18:82.0
-1,12,18:82.0
-2,-6,19:82.0
-3,-5,19:159.10
-2,-5,19:159.10
-6,-4,19:159.10
-5,-4,19:159.10
-4,-4,19:159.10
-3,-4,19:159.10
-2,-4,19:159.10
-1,-4,19:159.10
0,-4,19:159.10
1,-4,19:159.10
-8,-3,19:82.0
-7,-3,19:159.10
-6,-3,19:159.10
-5,-3,19:159.10
-4,-3,19:159.10
-3,-3,19:159.10
-2,-3,19:100.0
-1,-3,19:159.10
0,-3,19:159.10
1,-3,19:159.10
2,-3,19:159.10
3,-3,19:159.10
-9,-2,19:82.0
-8,-2,19:100.0
-7,-2,19:159.10
-6,-2,19:159.10
-5,-2,19:159.10
-4,-2,19:159.10
-3,-2,19:100.0
-2,-2,19:100.0
-1,-2,19:159.10
0,-2,19:159.10
1,-2,19:159.10
2,-2,19:159.10
3,-2,19:159.10
4,-2,19:159.10
-9,-1,19:82.0
-8,-1,19:159.10
-7,-1,19:100.0
-6,-1,19:100.0
-5,-1,19:100.0
0,-1,19:100.0
1,-1,19:100.0
2,-1,19:159.10
3,-1,19:159.10
4,-1,19:159.10
-9,0,19:159.10
-8,0,19:159.10
-7,0,19:159.10
-6,0,19:100.0
-4,0,19:100.0
0,0,19:100.0
1,0,19:100.0
2,0,19:82.0
3,0,19:82.0
4,0,19:82.0
-9,1,19:159.10
-8,1,19:159.10
-7,1,19:159.10
-6,1,19:100.0
-4,1,19:100.0
-3,1,19:100.0
-2,1,19:100.0
-1,1,19:100.0
1,1,19:100.0
2,1,19:82.0
3,1,19:82.0
4,1,19:82.0
-9,2,19:159.10
-8,2,19:159.10
-7,2,19:159.10
-6,2,19:100.0
-2,2,19:100.0
1,2,19:100.0
2,2,19:82.0
3,2,19:82.0
4,2,19:82.0
-8,3,19:82.0
-7,3,19:82.0
-6,3,19:159.10
-2,3,19:100.0
1,3,19:100.0
2,3,19:82.0
3,3,19:82.0
4,3,19:82.0
-8,4,19:82.0
-7,4,19:82.0
-6,4,19:100.0
-5,4,19:100.0
-2,4,19:100.0
0,4,19:100.0
1,4,19:159.10
2,4,19:82.0
3,4,19:82.0
-8,5,19:82.0
-7,5,19:82.0
-6,5,19:82.0
-5,5,19:159.10
-4,5,19:159.10
-3,5,19:100.0
-2,5,19:100.0
-1,5,19:100.0
0,5,19:159.10
1,5,19:159.10
2,5,19:159.10
3,5,19:159.10
-7,6,19:82.0
-6,6,19:82.0
-5,6,19:159.10
-4,6,19:159.10
-3,6,19:159.10
-2,6,19:100.0
-1,6,19:159.10
0,6,19:159.10
1,6,19:159.10
2,6,19:159.10
-5,7,19:159.10
-4,7,19:159.10
-3,7,19:159.10
-2,7,19:159.10
-1,7,19:159.10
0,7,19:159.10
1,7,19:159.10
-4,8,19:159.10
-3,8,19:159.10
-2,8,19:159.10
-1,8,19:159.10
-3,9,19:159.10
-2,9,19:159.10
-2,-3,20:159.10
-8,-2,20:159.10
-3,-2,20:159.10
-2,-2,20:159.10
-7,-1,20:159.10
-6,-1,20:159.10
-5,-1,20:159.10
-4,-1,20:159.10
-3,-1,20:159.10
-2,-1,20:159.10
-1,-1,20:159.10
0,-1,20:159.10
1,-1,20:159.10
-6,0,20:159.10
-4,0,20:159.10
-3,0,20:159.10
-2,0,20:159.10
-1,0,20:159.10
0,0,20:159.10
1,0,20:159.10
-6,1,20:159.10
-5,1,20:159.10
-4,1,20:159.10
-3,1,20:100.0
-2,1,20:100.0
-1,1,20:159.10
0,1,20:159.10
1,1,20:82.0
-6,2,20:159.10
-5,2,20:159.10
-4,2,20:159.10
-3,2,20:100.0
-2,2,20:100.0
-1,2,20:159.10
0,2,20:159.10
1,2,20:82.0
-5,3,20:159.10
-4,3,20:159.10
-3,3,20:159.10
-2,3,20:159.10
-1,3,20:159.10
0,3,20:159.10
1,3,20:82.0
-6,4,20:82.0
-5,4,20:159.10
-4,4,20:159.10
-3,4,20:159.10
-2,4,20:159.10
-1,4,20:159.10
0,4,20:159.10
-3,5,20:159.10
-2,5,20:159.10
-1,5,20:159.10
-2,6,20:159.10
-3,1,21:159.10
-2,1,21:159.10
-3,2,21:159.10
-2,2,21:159.10
