[META]
version=2.0
spawnOnBlockType=2
spawnSunlight=True
spawnDarkness=True
spawnWater=False
spawnLava=False
underFill=False
randomRotation=True
dig=True
tree=False
branch=False
needsFoundation=True
rarity=100
collisionPercentage=20
spawnElevationMin=0
spawnElevationMax=200
spawnInBiome=Custom
[DATA]
0,-2,-6:100.15
1,-2,-6:100.15
2,-2,-6:100.15
1,-1,-6:100.15
0,0,-6:100.15
1,0,-6:100.15
0,-3,-5:100.15
1,-3,-5:100.15
0,-2,-5:100.15
-1,-1,-5:100.15
3,-1,-5:100.15
-1,-2,-4:100.15
0,-2,-4:100.15
1,-2,-4:100.15
2,-2,-4:100.15
-1,-1,-4:100.15
0,-1,-4:100.15
1,-1,-4:100.15
2,-1,-4:100.15
3,-1,-4:100.15
-1,0,-4:100.15
0,0,-4:100.15
1,0,-4:100.15
2,0,-4:100.15
1,-3,-3:100.15
0,-2,-3:100.15
1,-2,-3:100.15
2,-2,-3:100.15
3,-2,-3:100.15
-1,-1,-3:100.15
0,-1,-3:100.15
1,-1,-3:100.15
2,-1,-3:100.15
3,-1,-3:100.15
0,0,-3:100.15
1,0,-3:100.15
3,0,-3:100.15
0,1,-3:100.15
1,1,-3:100.15
2,1,-3:100.15
1,-3,-2:100.15
-1,-2,-2:100.15
0,-2,-2:100.15
1,-2,-2:100.15
2,-2,-2:100.15
3,-2,-2:100.15
0,-1,-2:100.15
1,-1,-2:100.15
-1,0,-2:100.15
0,0,-2:100.15
1,0,-2:100.15
2,0,-2:100.15
0,1,-2:100.15
1,1,-2:100.15
0,-2,-1:100.15
1,-2,-1:100.15
2,-2,-1:100.15
1,-1,-1:100.15
3,-1,-1:100.15
0,0,-1:100.15
2,0,-1:100.15
0,-3,0:100.15
2,-3,0:100.15
0,-2,0:100.15
-1,-1,0:100.15
0,-1,0:100.15
1,-1,0:100.15
2,-1,0:100.15
0,0,0:100.15
1,0,0:100.15
2,0,0:100.15
0,-3,1:100.15
1,-3,1:100.15
0,-2,1:100.15
2,-2,1:100.15
3,-2,1:100.15
-1,-1,1:100.15
0,-1,1:100.15
3,-1,1:100.0
0,0,1:100.15
1,0,1:100.15
2,0,1:159.13
-1,-5,2:100.0
0,-3,2:17.2
1,-3,2:159.13
2,-3,2:159.13
3,-3,2:159.13
1,-2,2:100.15
2,-2,2:159.13
3,-2,2:159.13
-1,-1,2:17.2
0,-1,2:17.2
1,-1,2:159.13
2,-1,2:159.13
3,-1,2:159.13
1,0,2:17.2
2,0,2:159.13
3,0,2:159.13
3,2,2:100.0
4,3,2:100.0
-2,-7,3:100.0
-2,-6,3:100.0
-1,-5,3:100.0
0,-4,3:100.0
0,-3,3:17.2
1,-3,3:159.13
2,-3,3:159.13
1,-2,3:100.15
2,-2,3:100.15
3,-2,3:159.13
-1,-1,3:17.2
0,-1,3:17.2
1,-1,3:100.15
2,-1,3:100.15
1,0,3:17.2
2,0,3:100.0
2,1,3:100.0
3,2,3:100.0
4,3,3:100.0
5,4,3:100.0
5,5,3:100.0
-3,-8,4:100.0
5,-8,4:100.0
-2,-7,4:100.0
5,-7,4:100.0
7,-7,4:100.0
-2,-6,4:100.0
-1,-5,4:100.0
4,-5,4:100.0
-1,-4,4:100.0
0,-4,4:100.0
0,-3,4:100.0
2,-3,4:100.0
1,-2,4:100.15
2,-2,4:100.15
-6,-1,4:100.0
-3,-1,4:100.0
-1,-1,4:100.0
0,-1,4:100.0
1,-1,4:100.15
2,-1,4:100.15
-7,0,4:100.0
0,0,4:100.0
1,0,4:100.0
2,0,4:100.0
2,1,4:100.0
3,1,4:100.0
3,2,4:100.0
4,3,4:100.0
4,4,4:100.0
5,4,4:100.0
7,4,4:100.0
5,5,4:159.13
-3,-9,5:100.0
-2,-9,5:100.0
0,-9,5:100.0
3,-9,5:100.0
4,-9,5:100.0
5,-9,5:100.0
6,-9,5:100.0
-3,-8,5:159.13
-2,-8,5:100.0
5,-8,5:82.0
6,-8,5:100.0
7,-8,5:100.0
-5,-7,5:100.0
-2,-7,5:100.0
5,-7,5:100.0
7,-7,5:159.13
-2,-6,5:100.0
4,-6,5:100.0
-6,-5,5:100.0
-1,-5,5:100.0
4,-5,5:100.0
-6,-4,5:100.0
-1,-4,5:100.0
0,-4,5:100.0
3,-4,5:100.0
-7,-3,5:100.0
0,-3,5:100.0
2,-3,5:100.0
-7,-2,5:100.0
-1,-2,5:100.0
1,-2,5:100.15
2,-2,5:100.15
-7,-1,5:159.13
-6,-1,5:100.0
-5,-1,5:100.0
-4,-1,5:100.0
-3,-1,5:100.0
-1,-1,5:100.0
0,-1,5:100.0
1,-1,5:100.15
2,-1,5:100.15
6,-1,5:100.0
7,-1,5:100.0
8,-1,5:100.0
-7,0,5:159.13
0,0,5:100.0
1,0,5:100.0
2,0,5:100.0
-6,1,5:100.0
0,1,5:100.0
2,1,5:100.0
3,1,5:100.0
9,1,5:100.0
-6,2,5:100.0
-1,2,5:100.0
3,2,5:100.0
4,3,5:100.0
-5,4,5:100.0
4,4,5:100.0
5,4,5:100.0
7,4,5:159.13
5,5,5:82.0
6,5,5:100.0
0,6,5:100.0
3,6,5:100.0
4,6,5:100.0
5,6,5:100.0
6,6,5:100.0
-5,-9,6:100.0
-3,-9,6:159.13
-2,-9,6:159.13
0,-9,6:159.13
1,-9,6:100.0
2,-9,6:100.0
3,-9,6:159.13
4,-9,6:82.0
5,-9,6:82.0
6,-9,6:82.0
-4,-8,6:100.0
-3,-8,6:159.13
-2,-8,6:100.0
5,-8,6:82.0
6,-8,6:82.0
7,-8,6:159.13
-5,-7,6:159.13
-2,-7,6:100.0
4,-7,6:100.0
5,-7,6:159.13
7,-7,6:159.13
-5,-6,6:100.0
-2,-6,6:100.0
-1,-6,6:100.0
4,-6,6:100.0
8,-6,6:100.0
-6,-5,6:159.13
-1,-5,6:100.0
3,-5,6:100.0
4,-5,6:100.0
8,-5,6:100.0
-6,-4,6:159.13
-1,-4,6:100.0
0,-4,6:100.0
3,-4,6:100.0
9,-4,6:100.0
-7,-3,6:82.0
0,-3,6:100.0
1,-3,6:100.0
2,-3,6:100.0
3,-3,6:100.0
-8,-2,6:82.0
-7,-2,6:82.0
-6,-2,6:100.0
-5,-2,6:100.0
-4,-2,6:100.0
-3,-2,6:100.0
-2,-2,6:100.0
-1,-2,6:100.0
1,-2,6:100.15
2,-2,6:100.15
9,-2,6:100.0
-6,-1,6:159.13
-5,-1,6:100.0
-4,-1,6:100.0
-3,-1,6:100.0
0,-1,6:100.0
1,-1,6:100.15
2,-1,6:100.15
3,-1,6:100.0
4,-1,6:100.0
5,-1,6:100.0
6,-1,6:100.0
7,-1,6:100.0
8,-1,6:100.0
9,-1,6:159.13
-7,0,6:159.13
0,0,6:100.0
1,0,6:100.0
2,0,6:100.0
-6,1,6:159.13
-3,1,6:100.0
-1,1,6:100.0
0,1,6:100.0
3,1,6:100.0
8,1,6:100.0
9,1,6:159.13
-6,2,6:159.13
-1,2,6:100.0
3,2,6:100.0
8,2,6:100.0
-5,3,6:100.0
-2,3,6:100.0
4,3,6:100.0
8,3,6:100.0
-5,4,6:159.13
-2,4,6:100.0
4,4,6:100.0
5,4,6:100.0
7,4,6:159.13
-4,5,6:100.0
-3,5,6:100.0
-2,5,6:100.0
5,5,6:82.0
6,5,6:82.0
-2,6,6:100.0
0,6,6:159.13
1,6,6:100.0
2,6,6:100.0
3,6,6:159.13
4,6,6:82.0
5,6,6:82.0
6,6,6:82.0
-5,-9,7:159.13
-4,-9,7:100.0
-3,-9,7:159.13
-2,-9,7:159.13
-1,-9,7:100.0
0,-9,7:159.13
1,-9,7:159.13
2,-9,7:159.13
3,-9,7:159.13
4,-9,7:82.0
5,-9,7:82.0
6,-9,7:82.0
-4,-8,7:159.13
-3,-8,7:159.13
-2,-8,7:100.0
1,-8,7:100.0
2,-8,7:100.0
3,-8,7:100.0
4,-8,7:100.0
5,-8,7:82.0
6,-8,7:159.13
7,-8,7:159.13
-5,-7,7:159.13
-4,-7,7:100.0
-2,-7,7:100.0
1,-7,7:100.0
2,-7,7:100.0
3,-7,7:100.0
4,-7,7:159.13
5,-7,7:159.13
6,-7,7:100.0
7,-7,7:159.13
-5,-6,7:159.13
-2,-6,7:100.0
-1,-6,7:100.0
1,-6,7:100.0
2,-6,7:100.0
3,-6,7:100.0
4,-6,7:100.0
6,-6,7:100.0
7,-6,7:100.0
8,-6,7:159.13
-6,-5,7:159.13
-5,-5,7:100.0
-4,-5,7:100.0
-1,-5,7:100.0
1,-5,7:100.0
2,-5,7:100.0
3,-5,7:159.13
4,-5,7:159.13
5,-5,7:100.0
6,-5,7:100.0
8,-5,7:159.13
-6,-4,7:159.13
-5,-4,7:100.0
-4,-4,7:100.0
-3,-4,7:100.0
-1,-4,7:100.0
0,-4,7:100.0
1,-4,7:100.0
2,-4,7:100.0
3,-4,7:159.13
4,-4,7:100.0
9,-4,7:159.13
-7,-3,7:82.0
-6,-3,7:100.0
-5,-3,7:100.0
-4,-3,7:100.0
-3,-3,7:100.0
-2,-3,7:100.0
0,-3,7:100.0
1,-3,7:159.13
2,-3,7:159.13
3,-3,7:100.0
9,-3,7:100.0
-7,-2,7:82.0
-6,-2,7:82.0
-5,-2,7:159.13
-4,-2,7:159.13
-3,-2,7:159.13
-2,-2,7:159.13
-1,-2,7:159.13
1,-2,7:100.15
2,-2,7:100.15
9,-2,7:159.13
10,-2,7:100.0
-6,-1,7:82.0
-5,-1,7:159.13
-4,-1,7:159.13
-3,-1,7:159.13
-2,-1,7:100.0
-1,-1,7:100.0
0,-1,7:159.13
1,-1,7:100.15
2,-1,7:100.15
3,-1,7:100.0
4,-1,7:100.0
5,-1,7:100.0
6,-1,7:100.0
7,-1,7:100.0
8,-1,7:100.0
10,-1,7:100.0
-7,0,7:159.13
-6,0,7:100.0
-5,0,7:100.0
-4,0,7:100.0
-3,0,7:100.0
-2,0,7:100.0
0,0,7:100.0
1,0,7:100.0
2,0,7:100.0
9,0,7:100.0
-6,1,7:159.13
-5,1,7:100.0
-4,1,7:100.0
-3,1,7:100.0
-1,1,7:100.0
0,1,7:100.0
2,1,7:100.0
3,1,7:100.0
8,1,7:159.13
9,1,7:159.13
-6,2,7:159.13
-5,2,7:100.0
-1,2,7:100.0
3,2,7:100.0
8,2,7:159.13
-5,3,7:159.13
-2,3,7:100.0
3,3,7:100.0
4,3,7:100.0
7,3,7:100.0
8,3,7:159.13
-5,4,7:159.13
-4,4,7:100.0
-2,4,7:100.0
4,4,7:100.0
5,4,7:100.0
7,4,7:159.13
-4,5,7:159.13
-3,5,7:159.13
-2,5,7:100.0
4,5,7:100.0
5,5,7:82.0
6,5,7:159.13
-3,6,7:100.0
-2,6,7:159.13
-1,6,7:100.0
0,6,7:159.13
1,6,7:159.13
2,6,7:159.13
3,6,7:159.13
4,6,7:82.0
5,6,7:82.0
6,6,7:82.0
-5,-9,8:159.13
-4,-9,8:159.13
-3,-9,8:159.13
-2,-9,8:159.13
-1,-9,8:159.13
0,-9,8:159.13
1,-9,8:159.13
2,-9,8:159.13
3,-9,8:159.13
4,-9,8:159.13
5,-9,8:159.13
6,-9,8:159.13
-4,-8,8:159.13
-3,-8,8:159.13
-2,-8,8:159.13
-1,-8,8:100.0
0,-8,8:100.0
1,-8,8:159.13
6,-8,8:159.13
-5,-7,8:159.13
-4,-7,8:159.13
-3,-7,8:100.0
-2,-7,8:159.13
-1,-7,8:100.0
0,-7,8:100.0
1,-7,8:159.13
6,-7,8:159.13
7,-7,8:159.13
-5,-6,8:159.13
-4,-6,8:100.0
-3,-6,8:100.0
-2,-6,8:159.13
-1,-6,8:159.13
0,-6,8:100.0
1,-6,8:159.13
7,-6,8:159.13
8,-6,8:159.13
-6,-5,8:159.13
-5,-5,8:159.13
-4,-5,8:159.13
-3,-5,8:100.0
-2,-5,8:100.0
-1,-5,8:159.13
0,-5,8:100.0
1,-5,8:159.13
6,-5,8:159.13
7,-5,8:100.0
8,-5,8:159.13
-6,-4,8:159.13
-3,-4,8:159.13
-2,-4,8:100.0
-1,-4,8:159.13
0,-4,8:159.13
1,-4,8:159.13
5,-4,8:100.0
6,-4,8:100.0
7,-4,8:100.0
8,-4,8:100.0
9,-4,8:159.13
-7,-3,8:82.0
-6,-3,8:159.13
-2,-3,8:159.13
-1,-3,8:100.0
0,-3,8:159.13
1,-3,8:159.13
3,-3,8:159.13
4,-3,8:100.0
5,-3,8:100.0
6,-3,8:100.0
7,-3,8:100.0
8,-3,8:100.0
9,-3,8:159.13
-7,-2,8:82.0
1,-2,8:159.13
3,-2,8:100.0
4,-2,8:100.0
5,-2,8:100.0
6,-2,8:100.0
7,-2,8:100.0
8,-2,8:100.0
9,-2,8:159.13
10,-2,8:159.13
-6,-1,8:159.13
0,-1,8:159.13
1,-1,8:159.13
2,-1,8:159.13
3,-1,8:159.13
4,-1,8:159.13
5,-1,8:159.13
6,-1,8:159.13
7,-1,8:159.13
8,-1,8:159.13
9,-1,8:100.0
10,-1,8:159.13
-7,0,8:159.13
-6,0,8:159.13
-2,0,8:159.13
-1,0,8:100.0
0,0,8:159.13
1,0,8:159.13
2,0,8:159.13
3,0,8:100.0
4,0,8:100.0
5,0,8:100.0
6,0,8:100.0
7,0,8:100.0
8,0,8:100.0
9,0,8:159.13
-6,1,8:159.13
-3,1,8:159.13
-2,1,8:100.0
-1,1,8:159.13
0,1,8:159.13
1,1,8:100.0
2,1,8:159.13
3,1,8:159.13
4,1,8:100.0
5,1,8:100.0
6,1,8:100.0
7,1,8:100.0
8,1,8:159.13
9,1,8:159.13
-6,2,8:159.13
-5,2,8:159.13
-4,2,8:100.0
-3,2,8:100.0
-2,2,8:100.0
-1,2,8:159.13
0,2,8:100.0
1,2,8:100.0
2,2,8:100.0
5,2,8:100.0
6,2,8:100.0
7,2,8:100.0
8,2,8:159.13
-5,3,8:159.13
-4,3,8:100.0
-3,3,8:100.0
-2,3,8:159.13
-1,3,8:100.0
0,3,8:100.0
1,3,8:100.0
2,3,8:100.0
3,3,8:159.13
5,3,8:100.0
6,3,8:100.0
7,3,8:159.13
-5,4,8:159.13
-4,4,8:159.13
-3,4,8:100.0
-2,4,8:159.13
-1,4,8:100.0
0,4,8:100.0
1,4,8:100.0
2,4,8:100.0
3,4,8:100.0
6,4,8:100.0
7,4,8:159.13
-4,5,8:159.13
-3,5,8:82.0
-2,5,8:159.13
-1,5,8:100.0
0,5,8:100.0
1,5,8:100.0
2,5,8:100.0
3,5,8:100.0
6,5,8:159.13
-3,6,8:82.0
-2,6,8:82.0
-1,6,8:159.13
0,6,8:159.13
1,6,8:159.13
2,6,8:159.13
3,6,8:159.13
4,6,8:159.13
5,6,8:159.13
6,6,8:159.13
-5,-9,9:159.13
-4,-9,9:159.13
-3,-9,9:159.13
-2,-9,9:159.13
-1,-9,9:159.13
0,-9,9:159.13
1,-9,9:82.0
2,-9,9:82.0
3,-9,9:82.0
4,-9,9:159.13
5,-9,9:159.13
-4,-8,9:82.0
5,-8,9:100.0
6,-8,9:159.13
-4,-7,9:82.0
-2,-7,9:159.13
6,-7,9:159.13
7,-7,9:159.13
-5,-6,9:159.13
-2,-6,9:159.13
-1,-6,9:159.13
7,-6,9:159.13
-5,-5,9:159.13
-1,-5,9:159.13
7,-5,9:159.13
8,-5,9:159.13
-6,-4,9:159.13
-1,-4,9:159.13
0,-4,9:159.13
8,-4,9:159.13
9,-4,9:159.13
-6,-3,9:159.13
0,-3,9:159.13
9,-3,9:159.13
-7,-2,9:159.13
-6,-2,9:100.0
1,-2,9:159.13
4,-2,9:159.13
5,-2,9:159.13
6,-2,9:159.13
7,-2,9:159.13
8,-2,9:159.13
9,-2,9:159.13
10,-2,9:159.13
-6,-1,9:159.13
0,-1,9:159.13
1,-1,9:159.13
2,-1,9:159.13
3,-1,9:159.13
4,-1,9:159.13
8,-1,9:159.13
9,-1,9:159.13
10,-1,9:159.13
-6,0,9:159.13
0,0,9:159.13
9,0,9:159.13
-6,1,9:159.13
-5,1,9:100.0
-1,1,9:159.13
0,1,9:159.13
8,1,9:159.13
-5,2,9:159.13
-1,2,9:159.13
7,2,9:159.13
8,2,9:159.13
-5,3,9:159.13
-4,3,9:159.13
-2,3,9:159.13
-1,3,9:159.13
7,3,9:159.13
-4,4,9:159.13
-2,4,9:159.13
6,4,9:159.13
-4,5,9:82.0
-3,5,9:82.0
5,5,9:100.0
6,5,9:159.13
-3,6,9:82.0
-2,6,9:82.0
-1,6,9:159.13
0,6,9:159.13
1,6,9:159.13
2,6,9:159.13
3,6,9:159.13
4,6,9:159.13
5,6,9:159.13
-4,-9,10:159.13
-3,-9,10:159.13
-2,-9,10:159.13
-1,-9,10:159.13
0,-9,10:159.13
1,-9,10:82.0
2,-9,10:82.0
-4,-8,10:82.0
-3,-8,10:100.0
-2,-8,10:100.0
1,-8,10:100.0
2,-8,10:100.0
3,-8,10:82.0
4,-8,10:159.13
5,-8,10:159.13
-4,-7,10:82.0
-2,-7,10:159.13
6,-7,10:82.0
-5,-6,10:82.0
-4,-6,10:100.0
-2,-6,10:159.13
-1,-6,10:159.13
6,-6,10:100.0
7,-6,10:159.13
-5,-5,10:159.13
-1,-5,10:159.13
7,-5,10:159.13
8,-5,10:159.13
-6,-4,10:159.13
-5,-4,10:100.0
-1,-4,10:159.13
0,-4,10:159.13
8,-4,10:159.13
-6,-3,10:159.13
0,-3,10:159.13
8,-3,10:100.0
9,-3,10:159.13
-6,-2,10:159.13
1,-2,10:159.13
4,-2,10:159.13
5,-2,10:159.13
6,-2,10:159.13
7,-2,10:159.13
8,-2,10:159.13
9,-2,10:82.0
10,-2,10:159.13
-6,-1,10:159.13
0,-1,10:159.13
1,-1,10:159.13
2,-1,10:159.13
3,-1,10:159.13
9,-1,10:82.0
-6,0,10:159.13
0,0,10:159.13
8,0,10:100.0
9,0,10:82.0
-5,1,10:159.13
-1,1,10:159.13
0,1,10:159.13
8,1,10:159.13
-5,2,10:159.13
-1,2,10:159.13
7,2,10:159.13
-4,3,10:159.13
-2,3,10:159.13
-1,3,10:159.13
6,3,10:100.0
7,3,10:159.13
-4,4,10:159.13
-2,4,10:159.13
6,4,10:159.13
-3,5,10:82.0
-2,5,10:100.0
-1,5,10:100.0
0,5,10:100.0
1,5,10:100.0
2,5,10:159.13
3,5,10:159.13
4,5,10:159.13
5,5,10:159.13
-2,6,10:82.0
-1,6,10:159.13
0,6,10:159.13
1,6,10:159.13
-3,-9,11:159.13
-3,-8,11:159.13
-2,-8,11:159.13
-1,-8,11:159.13
0,-8,11:159.13
1,-8,11:159.13
2,-8,11:82.0
3,-8,11:159.13
4,-8,11:159.13
5,-8,11:82.0
-4,-7,11:82.0
-3,-7,11:100.0
-2,-7,11:159.13
5,-7,11:100.0
6,-7,11:82.0
-4,-6,11:82.0
-2,-6,11:159.13
-1,-6,11:159.13
6,-6,11:82.0
-5,-5,11:159.13
-4,-5,11:100.0
-1,-5,11:159.13
7,-5,11:159.13
-5,-4,11:159.13
-1,-4,11:159.13
0,-4,11:159.13
7,-4,11:100.0
8,-4,11:159.13
-6,-3,11:159.13
-5,-3,11:100.0
0,-3,11:159.13
8,-3,11:159.13
-6,-2,11:159.13
1,-2,11:159.13
2,-2,11:100.0
3,-2,11:100.0
4,-2,11:159.13
5,-2,11:159.13
6,-2,11:159.13
7,-2,11:159.13
8,-2,11:82.0
9,-2,11:82.0
-6,-1,11:159.13
0,-1,11:159.13
1,-1,11:159.13
2,-1,11:159.13
8,-1,11:100.0
9,-1,11:82.0
-6,0,11:159.13
-5,0,11:100.0
0,0,11:159.13
8,0,11:82.0
-5,1,11:159.13
-1,1,11:159.13
0,1,11:159.13
7,1,11:100.0
8,1,11:159.13
-5,2,11:159.13
-4,2,11:100.0
-1,2,11:159.13
6,2,11:100.0
7,2,11:159.13
-4,3,11:159.13
-2,3,11:159.13
-1,3,11:159.13
6,3,11:159.13
-4,4,11:159.13
-3,4,11:100.0
-2,4,11:159.13
5,4,11:100.0
6,4,11:82.0
-3,5,11:159.13
-2,5,11:159.13
-1,5,11:159.13
0,5,11:159.13
1,5,11:159.13
2,5,11:159.13
3,5,11:159.13
4,5,11:159.13
5,5,11:82.0
-3,-8,12:159.13
-2,-8,12:159.13
-1,-8,12:159.13
0,-8,12:159.13
1,-8,12:159.13
2,-8,12:159.13
3,-8,12:159.13
4,-8,12:159.13
5,-8,12:159.13
-3,-7,12:159.13
-2,-7,12:159.13
5,-7,12:82.0
-4,-6,12:159.13
-3,-6,12:100.0
-2,-6,12:159.13
-1,-6,12:159.13
6,-6,12:82.0
-4,-5,12:159.13
-1,-5,12:159.13
6,-5,12:100.0
7,-5,12:159.13
-5,-4,12:159.13
-1,-4,12:159.13
0,-4,12:159.13
7,-4,12:159.13
-5,-3,12:159.13
0,-3,12:159.13
8,-3,12:159.13
-6,-2,12:82.0
1,-2,12:159.13
2,-2,12:159.13
3,-2,12:159.13
4,-2,12:159.13
5,-2,12:159.13
6,-2,12:159.13
7,-2,12:159.13
8,-2,12:159.13
9,-2,12:82.0
-6,-1,12:82.0
-5,-1,12:100.0
0,-1,12:159.13
1,-1,12:159.13
8,-1,12:82.0
-5,0,12:159.13
0,0,12:159.13
7,0,12:100.0
8,0,12:159.13
-5,1,12:159.13
-4,1,12:100.0
-1,1,12:159.13
0,1,12:159.13
7,1,12:159.13
-4,2,12:159.13
-1,2,12:159.13
6,2,12:159.13
-4,3,12:82.0
-3,3,12:100.0
-2,3,12:82.0
-1,3,12:159.13
5,3,12:100.0
6,3,12:82.0
-3,4,12:82.0
-2,4,12:159.13
4,4,12:100.0
5,4,12:82.0
-2,5,12:159.13
-1,5,12:159.13
0,5,12:159.13
1,5,12:159.13
2,5,12:159.13
3,5,12:159.13
4,5,12:82.0
-3,-8,13:159.13
-2,-8,13:159.13
-1,-8,13:159.13
0,-8,13:159.13
1,-8,13:159.13
2,-8,13:159.13
3,-8,13:159.13
4,-8,13:159.13
-3,-7,13:159.13
-2,-7,13:159.13
1,-7,13:100.0
2,-7,13:100.0
3,-7,13:100.0
4,-7,13:100.0
5,-7,13:159.13
-3,-6,13:159.13
-2,-6,13:159.13
-1,-6,13:159.13
6,-6,13:159.13
-4,-5,13:159.13
-1,-5,13:159.13
6,-5,13:159.13
-5,-4,13:159.13
-4,-4,13:100.0
-1,-4,13:159.13
0,-4,13:159.13
6,-4,13:100.0
7,-4,13:159.13
-5,-3,13:82.0
0,-3,13:159.13
7,-3,13:100.0
8,-3,13:159.13
-6,-2,13:82.0
-5,-2,13:100.0
1,-2,13:159.13
2,-2,13:159.13
3,-2,13:159.13
4,-2,13:159.13
5,-2,13:159.13
6,-2,13:159.13
7,-2,13:159.13
8,-2,13:159.13
-5,-1,13:82.0
0,-1,13:159.13
1,-1,13:159.13
8,-1,13:159.13
-5,0,13:159.13
0,0,13:159.13
7,0,13:159.13
-4,1,13:159.13
-1,1,13:159.13
0,1,13:159.13
6,1,13:100.0
7,1,13:159.13
-4,2,13:82.0
-1,2,13:159.13
6,2,13:159.13
-3,3,13:82.0
-2,3,13:82.0
-1,3,13:159.13
5,3,13:82.0
-3,4,13:82.0
-2,4,13:82.0
-1,4,13:100.0
0,4,13:159.13
1,4,13:159.13
2,4,13:159.13
3,4,13:159.13
4,4,13:82.0
5,4,13:82.0
-2,5,13:159.13
-1,5,13:159.13
-3,-7,14:159.13
-1,-7,14:82.0
0,-7,14:159.13
1,-7,14:159.13
2,-7,14:159.13
3,-7,14:159.13
4,-7,14:159.13
-3,-6,14:159.13
-2,-6,14:82.0
-1,-6,14:82.0
4,-6,14:159.13
-4,-5,14:159.13
-3,-5,14:159.13
-1,-5,14:82.0
5,-5,14:159.13
6,-5,14:159.13
-4,-4,14:159.13
-3,-4,14:100.0
-1,-4,14:159.13
0,-4,14:159.13
6,-4,14:159.13
-5,-3,14:159.13
-4,-3,14:159.13
0,-3,14:159.13
7,-3,14:159.13
-5,-2,14:82.0
-4,-2,14:100.0
1,-2,14:159.13
2,-2,14:159.13
3,-2,14:159.13
4,-2,14:159.13
5,-2,14:159.13
6,-2,14:159.13
7,-2,14:159.13
8,-2,14:159.13
-5,-1,14:159.13
-4,-1,14:100.0
0,-1,14:159.13
1,-1,14:159.13
7,-1,14:100.0
8,-1,14:159.13
-4,0,14:159.13
0,0,14:159.13
6,0,14:100.0
7,0,14:159.13
-4,1,14:159.13
-3,1,14:100.0
-1,1,14:159.13
0,1,14:159.13
6,1,14:159.13
-3,2,14:82.0
-1,2,14:159.13
5,2,14:159.13
6,2,14:159.13
-3,3,14:82.0
-2,3,14:82.0
-1,3,14:159.13
0,3,14:100.0
1,3,14:100.0
2,3,14:100.0
3,3,14:100.0
4,3,14:159.13
5,3,14:159.13
-2,4,14:159.13
-1,4,14:159.13
0,4,14:159.13
1,4,14:159.13
2,4,14:82.0
3,4,14:159.13
4,4,14:159.13
-2,-6,15:82.0
-1,-6,15:82.0
0,-6,15:82.0
1,-6,15:159.13
2,-6,15:159.13
3,-6,15:159.13
4,-6,15:159.13
-2,-5,15:82.0
-1,-5,15:82.0
0,-5,15:100.0
1,-5,15:100.0
2,-5,15:100.0
3,-5,15:82.0
4,-5,15:159.13
5,-5,15:159.13
-3,-4,15:159.13
-2,-4,15:159.13
-1,-4,15:159.13
0,-4,15:159.13
4,-4,15:82.0
5,-4,15:159.13
6,-4,15:159.13
-3,-3,15:159.13
-2,-3,15:100.0
0,-3,15:159.13
5,-3,15:159.13
6,-3,15:159.13
7,-3,15:159.13
-4,-2,15:159.13
-3,-2,15:159.13
-2,-2,15:100.0
1,-2,15:159.13
2,-2,15:159.13
3,-2,15:159.13
4,-2,15:159.13
5,-2,15:159.13
6,-2,15:159.13
7,-2,15:159.13
-4,-1,15:159.13
-3,-1,15:159.13
-2,-1,15:100.0
0,-1,15:159.13
1,-1,15:159.13
5,-1,15:100.0
6,-1,15:159.13
7,-1,15:159.13
-3,0,15:159.13
-2,0,15:100.0
0,0,15:159.13
4,0,15:100.0
5,0,15:159.13
6,0,15:159.13
-3,1,15:159.13
-2,1,15:159.13
-1,1,15:159.13
0,1,15:159.13
3,1,15:100.0
4,1,15:159.13
5,1,15:159.13
-2,2,15:159.13
-1,2,15:159.13
0,2,15:159.13
1,2,15:82.0
2,2,15:82.0
3,2,15:82.0
-2,3,15:159.13
-1,3,15:159.13
0,3,15:159.13
1,3,15:82.0
2,3,15:82.0
3,3,15:82.0
-1,-5,16:82.0
0,-5,16:159.13
1,-5,16:159.13
2,-5,16:82.0
-1,-4,16:159.13
0,-4,16:159.13
1,-4,16:159.13
2,-4,16:82.0
3,-4,16:82.0
-2,-3,16:159.13
-1,-3,16:159.13
0,-3,16:159.13
2,-3,16:100.0
3,-3,16:82.0
4,-3,16:82.0
-2,-2,16:159.13
-1,-2,16:100.0
1,-2,16:159.13
2,-2,16:159.13
3,-2,16:159.13
4,-2,16:159.13
5,-2,16:159.13
6,-2,16:159.13
-2,-1,16:159.13
-1,-1,16:159.13
0,-1,16:159.13
1,-1,16:159.13
3,-1,16:100.0
4,-1,16:159.13
5,-1,16:159.13
-2,0,16:159.13
-1,0,16:159.13
0,0,16:159.13
1,0,16:100.0
2,0,16:100.0
3,0,16:159.13
4,0,16:159.13
-1,1,16:159.13
0,1,16:159.13
1,1,16:159.13
2,1,16:159.13
3,1,16:159.13
0,-3,17:159.13
1,-3,17:159.13
2,-3,17:159.13
-1,-2,17:159.13
1,-2,17:159.13
2,-2,17:159.13
3,-2,17:159.13
4,-2,17:159.13
0,-1,17:159.13
1,-1,17:159.13
2,-1,17:159.13
3,-1,17:159.13
0,0,17:159.13
1,0,17:159.13
2,0,17:159.13
1,-2,18:159.13
